Workbook

Sheet Scenarios
A1: House Sale Scenarios + Probability of Sale — 537 Duchart Ln, Fuquay-Varina NC
A3: DEAL INPUTS (edit yellow) | N3: PROBABILITY MODEL (edit yellow)
A4: Purchase price (sold Mar 18 2024) | B4: 405700 | N4: Est. current market value | O4: 410000
A5: Down payment (her contribution) | B5: 48000 | N5: Base monthly sale chance (h0) | O5: 0.25
A6: Current mortgage balance / payoff | B6: 356149.76 | N6: Price sensitivity (k) | O6: 7
A7: Excise/transfer tax rate (NC) | B7: 0.002 | N7: Exposure: full-service agent | O7: 1.1
A8: Other closing costs (flat $) | B8: 2000 | N8: Exposure: typical agent | O8: 1.05
A9: HER recovery share — Option A | B9: 0.8 | N9: Exposure: FSBO + buyer agent 3% | O9: 0.9
A10: HER recovery share — Option B | B10: 0.7 | N10: Exposure: FSBO + buyer agent 2.5% | O10: 0.85
N11: Season — Jul 2026 | O11: 1.05
N12: Season — Aug 2026 | O12: 0.95
N13: Season — Sep 2026 | O13: 0.85
N14: Season — Oct 2026 | O14: 0.75
A18: Sale price | B18: Selling option | C18: Comm % | D18: Comm $ | E18: Other closing $ | F18: Total sell costs | G18: NET proceeds (money back) | H18: Shortfall vs $48k | I18: YOUR pay @80% | J18: YOUR pay @70% | K18: Her total @80% | L18: Her total @70% | M18: Price factor | N18: Exposure factor | O18: P(sold by end Jul) | P18: P(sold by end Aug) | Q18: P(sold by end Sep) | R18: P(sold by end Oct) | S18: ★ RECOMMENDATION
A19: 390000 | B19: Full-service agent (6%) | C19: 0.06 | D19: =A19*C19 | E19: =A19*$B$7+$B$8 | F19: =D19+E19 | G19: =A19-$B$6-F19 | H19: =MAX(0,$B$5-G19) | I19: =H19*$B$9 | J19: =H19*$B$10 | K19: =G19+I19 | L19: =G19+J19 | M19: =EXP(-$O$6*(A19-$O$4)/$O$4) | N19: =$O$7 | O19: =MIN(0.95,$O$5*M19*N19*$O$11) | P19: =1-(1-O19)*(1-MIN(0.95,$O$5*M19*N19*$O$12)) | Q19: =1-(1-P19)*(1-MIN(0.95,$O$5*M19*N19*$O$13)) | R19: =1-(1-Q19)*(1-MIN(0.95,$O$5*M19*N19*$O$14))
A20: 390000 | B20: Typical agent (5.5%) | C20: 0.055 | D20: =A20*C20 | E20: =A20*$B$7+$B$8 | F20: =D20+E20 | G20: =A20-$B$6-F20 | H20: =MAX(0,$B$5-G20) | I20: =H20*$B$9 | J20: =H20*$B$10 | K20: =G20+I20 | L20: =G20+J20 | M20: =EXP(-$O$6*(A20-$O$4)/$O$4) | N20: =$O$8 | O20: =MIN(0.95,$O$5*M20*N20*$O$11) | P20: =1-(1-O20)*(1-MIN(0.95,$O$5*M20*N20*$O$12)) | Q20: =1-(1-P20)*(1-MIN(0.95,$O$5*M20*N20*$O$13)) | R20: =1-(1-Q20)*(1-MIN(0.95,$O$5*M20*N20*$O$14))
A21: 390000 | B21: FSBO + buyer agent (3%) | C21: 0.03 | D21: =A21*C21 | E21: =A21*$B$7+$B$8 | F21: =D21+E21 | G21: =A21-$B$6-F21 | H21: =MAX(0,$B$5-G21) | I21: =H21*$B$9 | J21: =H21*$B$10 | K21: =G21+I21 | L21: =G21+J21 | M21: =EXP(-$O$6*(A21-$O$4)/$O$4) | N21: =$O$9 | O21: =MIN(0.95,$O$5*M21*N21*$O$11) | P21: =1-(1-O21)*(1-MIN(0.95,$O$5*M21*N21*$O$12)) | Q21: =1-(1-P21)*(1-MIN(0.95,$O$5*M21*N21*$O$13)) | R21: =1-(1-Q21)*(1-MIN(0.95,$O$5*M21*N21*$O$14))
A22: 390000 | B22: FSBO + buyer agent (2.5%) | C22: 0.025 | D22: =A22*C22 | E22: =A22*$B$7+$B$8 | F22: =D22+E22 | G22: =A22-$B$6-F22 | H22: =MAX(0,$B$5-G22) | I22: =H22*$B$9 | J22: =H22*$B$10 | K22: =G22+I22 | L22: =G22+J22 | M22: =EXP(-$O$6*(A22-$O$4)/$O$4) | N22: =$O$10 | O22: =MIN(0.95,$O$5*M22*N22*$O$11) | P22: =1-(1-O22)*(1-MIN(0.95,$O$5*M22*N22*$O$12)) | Q22: =1-(1-P22)*(1-MIN(0.95,$O$5*M22*N22*$O$13)) | R22: =1-(1-Q22)*(1-MIN(0.95,$O$5*M22*N22*$O$14))
A23: 395000 | B23: Full-service agent (6%) | C23: 0.06 | D23: =A23*C23 | E23: =A23*$B$7+$B$8 | F23: =D23+E23 | G23: =A23-$B$6-F23 | H23: =MAX(0,$B$5-G23) | I23: =H23*$B$9 | J23: =H23*$B$10 | K23: =G23+I23 | L23: =G23+J23 | M23: =EXP(-$O$6*(A23-$O$4)/$O$4) | N23: =$O$7 | O23: =MIN(0.95,$O$5*M23*N23*$O$11) | P23: =1-(1-O23)*(1-MIN(0.95,$O$5*M23*N23*$O$12)) | Q23: =1-(1-P23)*(1-MIN(0.95,$O$5*M23*N23*$O$13)) | R23: =1-(1-Q23)*(1-MIN(0.95,$O$5*M23*N23*$O$14))
A24: 395000 | B24: Typical agent (5.5%) | C24: 0.055 | D24: =A24*C24 | E24: =A24*$B$7+$B$8 | F24: =D24+E24 | G24: =A24-$B$6-F24 | H24: =MAX(0,$B$5-G24) | I24: =H24*$B$9 | J24: =H24*$B$10 | K24: =G24+I24 | L24: =G24+J24 | M24: =EXP(-$O$6*(A24-$O$4)/$O$4) | N24: =$O$8 | O24: =MIN(0.95,$O$5*M24*N24*$O$11) | P24: =1-(1-O24)*(1-MIN(0.95,$O$5*M24*N24*$O$12)) | Q24: =1-(1-P24)*(1-MIN(0.95,$O$5*M24*N24*$O$13)) | R24: =1-(1-Q24)*(1-MIN(0.95,$O$5*M24*N24*$O$14))
A25: 395000 | B25: FSBO + buyer agent (3%) | C25: 0.03 | D25: =A25*C25 | E25: =A25*$B$7+$B$8 | F25: =D25+E25 | G25: =A25-$B$6-F25 | H25: =MAX(0,$B$5-G25) | I25: =H25*$B$9 | J25: =H25*$B$10 | K25: =G25+I25 | L25: =G25+J25 | M25: =EXP(-$O$6*(A25-$O$4)/$O$4) | N25: =$O$9 | O25: =MIN(0.95,$O$5*M25*N25*$O$11) | P25: =1-(1-O25)*(1-MIN(0.95,$O$5*M25*N25*$O$12)) | Q25: =1-(1-P25)*(1-MIN(0.95,$O$5*M25*N25*$O$13)) | R25: =1-(1-Q25)*(1-MIN(0.95,$O$5*M25*N25*$O$14))
A26: 395000 | B26: FSBO + buyer agent (2.5%) | C26: 0.025 | D26: =A26*C26 | E26: =A26*$B$7+$B$8 | F26: =D26+E26 | G26: =A26-$B$6-F26 | H26: =MAX(0,$B$5-G26) | I26: =H26*$B$9 | J26: =H26*$B$10 | K26: =G26+I26 | L26: =G26+J26 | M26: =EXP(-$O$6*(A26-$O$4)/$O$4) | N26: =$O$10 | O26: =MIN(0.95,$O$5*M26*N26*$O$11) | P26: =1-(1-O26)*(1-MIN(0.95,$O$5*M26*N26*$O$12)) | Q26: =1-(1-P26)*(1-MIN(0.95,$O$5*M26*N26*$O$13)) | R26: =1-(1-Q26)*(1-MIN(0.95,$O$5*M26*N26*$O$14))
A27: 399000 | B27: Full-service agent (6%) | C27: 0.06 | D27: =A27*C27 | E27: =A27*$B$7+$B$8 | F27: =D27+E27 | G27: =A27-$B$6-F27 | H27: =MAX(0,$B$5-G27) | I27: =H27*$B$9 | J27: =H27*$B$10 | K27: =G27+I27 | L27: =G27+J27 | M27: =EXP(-$O$6*(A27-$O$4)/$O$4) | N27: =$O$7 | O27: =MIN(0.95,$O$5*M27*N27*$O$11) | P27: =1-(1-O27)*(1-MIN(0.95,$O$5*M27*N27*$O$12)) | Q27: =1-(1-P27)*(1-MIN(0.95,$O$5*M27*N27*$O$13)) | R27: =1-(1-Q27)*(1-MIN(0.95,$O$5*M27*N27*$O$14))
A28: 399000 | B28: Typical agent (5.5%) | C28: 0.055 | D28: =A28*C28 | E28: =A28*$B$7+$B$8 | F28: =D28+E28 | G28: =A28-$B$6-F28 | H28: =MAX(0,$B$5-G28) | I28: =H28*$B$9 | J28: =H28*$B$10 | K28: =G28+I28 | L28: =G28+J28 | M28: =EXP(-$O$6*(A28-$O$4)/$O$4) | N28: =$O$8 | O28: =MIN(0.95,$O$5*M28*N28*$O$11) | P28: =1-(1-O28)*(1-MIN(0.95,$O$5*M28*N28*$O$12)) | Q28: =1-(1-P28)*(1-MIN(0.95,$O$5*M28*N28*$O$13)) | R28: =1-(1-Q28)*(1-MIN(0.95,$O$5*M28*N28*$O$14)) | S28: ★ BEST ODDS / hands-off if you want it sold
A29: 399000 | B29: FSBO + buyer agent (3%) | C29: 0.03 | D29: =A29*C29 | E29: =A29*$B$7+$B$8 | F29: =D29+E29 | G29: =A29-$B$6-F29 | H29: =MAX(0,$B$5-G29) | I29: =H29*$B$9 | J29: =H29*$B$10 | K29: =G29+I29 | L29: =G29+J29 | M29: =EXP(-$O$6*(A29-$O$4)/$O$4) | N29: =$O$9 | O29: =MIN(0.95,$O$5*M29*N29*$O$11) | P29: =1-(1-O29)*(1-MIN(0.95,$O$5*M29*N29*$O$12)) | Q29: =1-(1-P29)*(1-MIN(0.95,$O$5*M29*N29*$O$13)) | R29: =1-(1-Q29)*(1-MIN(0.95,$O$5*M29*N29*$O$14))
A30: 399000 | B30: FSBO + buyer agent (2.5%) | C30: 0.025 | D30: =A30*C30 | E30: =A30*$B$7+$B$8 | F30: =D30+E30 | G30: =A30-$B$6-F30 | H30: =MAX(0,$B$5-G30) | I30: =H30*$B$9 | J30: =H30*$B$10 | K30: =G30+I30 | L30: =G30+J30 | M30: =EXP(-$O$6*(A30-$O$4)/$O$4) | N30: =$O$10 | O30: =MIN(0.95,$O$5*M30*N30*$O$11) | P30: =1-(1-O30)*(1-MIN(0.95,$O$5*M30*N30*$O$12)) | Q30: =1-(1-P30)*(1-MIN(0.95,$O$5*M30*N30*$O$13)) | R30: =1-(1-Q30)*(1-MIN(0.95,$O$5*M30*N30*$O$14))
A31: 405000 | B31: Full-service agent (6%) | C31: 0.06 | D31: =A31*C31 | E31: =A31*$B$7+$B$8 | F31: =D31+E31 | G31: =A31-$B$6-F31 | H31: =MAX(0,$B$5-G31) | I31: =H31*$B$9 | J31: =H31*$B$10 | K31: =G31+I31 | L31: =G31+J31 | M31: =EXP(-$O$6*(A31-$O$4)/$O$4) | N31: =$O$7 | O31: =MIN(0.95,$O$5*M31*N31*$O$11) | P31: =1-(1-O31)*(1-MIN(0.95,$O$5*M31*N31*$O$12)) | Q31: =1-(1-P31)*(1-MIN(0.95,$O$5*M31*N31*$O$13)) | R31: =1-(1-Q31)*(1-MIN(0.95,$O$5*M31*N31*$O$14))
A32: 405000 | B32: Typical agent (5.5%) | C32: 0.055 | D32: =A32*C32 | E32: =A32*$B$7+$B$8 | F32: =D32+E32 | G32: =A32-$B$6-F32 | H32: =MAX(0,$B$5-G32) | I32: =H32*$B$9 | J32: =H32*$B$10 | K32: =G32+I32 | L32: =G32+J32 | M32: =EXP(-$O$6*(A32-$O$4)/$O$4) | N32: =$O$8 | O32: =MIN(0.95,$O$5*M32*N32*$O$11) | P32: =1-(1-O32)*(1-MIN(0.95,$O$5*M32*N32*$O$12)) | Q32: =1-(1-P32)*(1-MIN(0.95,$O$5*M32*N32*$O$13)) | R32: =1-(1-Q32)*(1-MIN(0.95,$O$5*M32*N32*$O$14))
A33: 405000 | B33: FSBO + buyer agent (3%) | C33: 0.03 | D33: =A33*C33 | E33: =A33*$B$7+$B$8 | F33: =D33+E33 | G33: =A33-$B$6-F33 | H33: =MAX(0,$B$5-G33) | I33: =H33*$B$9 | J33: =H33*$B$10 | K33: =G33+I33 | L33: =G33+J33 | M33: =EXP(-$O$6*(A33-$O$4)/$O$4) | N33: =$O$9 | O33: =MIN(0.95,$O$5*M33*N33*$O$11) | P33: =1-(1-O33)*(1-MIN(0.95,$O$5*M33*N33*$O$12)) | Q33: =1-(1-P33)*(1-MIN(0.95,$O$5*M33*N33*$O$13)) | R33: =1-(1-Q33)*(1-MIN(0.95,$O$5*M33*N33*$O$14))
A34: 405000 | B34: FSBO + buyer agent (2.5%) | C34: 0.025 | D34: =A34*C34 | E34: =A34*$B$7+$B$8 | F34: =D34+E34 | G34: =A34-$B$6-F34 | H34: =MAX(0,$B$5-G34) | I34: =H34*$B$9 | J34: =H34*$B$10 | K34: =G34+I34 | L34: =G34+J34 | M34: =EXP(-$O$6*(A34-$O$4)/$O$4) | N34: =$O$10 | O34: =MIN(0.95,$O$5*M34*N34*$O$11) | P34: =1-(1-O34)*(1-MIN(0.95,$O$5*M34*N34*$O$12)) | Q34: =1-(1-P34)*(1-MIN(0.95,$O$5*M34*N34*$O$13)) | R34: =1-(1-Q34)*(1-MIN(0.95,$O$5*M34*N34*$O$14)) | S34: ★ BEST VALUE — low cost to Oscar + decent odds
A35: 409900 | B35: Full-service agent (6%) | C35: 0.06 | D35: =A35*C35 | E35: =A35*$B$7+$B$8 | F35: =D35+E35 | G35: =A35-$B$6-F35 | H35: =MAX(0,$B$5-G35) | I35: =H35*$B$9 | J35: =H35*$B$10 | K35: =G35+I35 | L35: =G35+J35 | M35: =EXP(-$O$6*(A35-$O$4)/$O$4) | N35: =$O$7 | O35: =MIN(0.95,$O$5*M35*N35*$O$11) | P35: =1-(1-O35)*(1-MIN(0.95,$O$5*M35*N35*$O$12)) | Q35: =1-(1-P35)*(1-MIN(0.95,$O$5*M35*N35*$O$13)) | R35: =1-(1-Q35)*(1-MIN(0.95,$O$5*M35*N35*$O$14))
A36: 409900 | B36: Typical agent (5.5%) | C36: 0.055 | D36: =A36*C36 | E36: =A36*$B$7+$B$8 | F36: =D36+E36 | G36: =A36-$B$6-F36 | H36: =MAX(0,$B$5-G36) | I36: =H36*$B$9 | J36: =H36*$B$10 | K36: =G36+I36 | L36: =G36+J36 | M36: =EXP(-$O$6*(A36-$O$4)/$O$4) | N36: =$O$8 | O36: =MIN(0.95,$O$5*M36*N36*$O$11) | P36: =1-(1-O36)*(1-MIN(0.95,$O$5*M36*N36*$O$12)) | Q36: =1-(1-P36)*(1-MIN(0.95,$O$5*M36*N36*$O$13)) | R36: =1-(1-Q36)*(1-MIN(0.95,$O$5*M36*N36*$O$14))
A37: 409900 | B37: FSBO + buyer agent (3%) | C37: 0.03 | D37: =A37*C37 | E37: =A37*$B$7+$B$8 | F37: =D37+E37 | G37: =A37-$B$6-F37 | H37: =MAX(0,$B$5-G37) | I37: =H37*$B$9 | J37: =H37*$B$10 | K37: =G37+I37 | L37: =G37+J37 | M37: =EXP(-$O$6*(A37-$O$4)/$O$4) | N37: =$O$9 | O37: =MIN(0.95,$O$5*M37*N37*$O$11) | P37: =1-(1-O37)*(1-MIN(0.95,$O$5*M37*N37*$O$12)) | Q37: =1-(1-P37)*(1-MIN(0.95,$O$5*M37*N37*$O$13)) | R37: =1-(1-Q37)*(1-MIN(0.95,$O$5*M37*N37*$O$14))
A38: 409900 | B38: FSBO + buyer agent (2.5%) | C38: 0.025 | D38: =A38*C38 | E38: =A38*$B$7+$B$8 | F38: =D38+E38 | G38: =A38-$B$6-F38 | H38: =MAX(0,$B$5-G38) | I38: =H38*$B$9 | J38: =H38*$B$10 | K38: =G38+I38 | L38: =G38+J38 | M38: =EXP(-$O$6*(A38-$O$4)/$O$4) | N38: =$O$10 | O38: =MIN(0.95,$O$5*M38*N38*$O$11) | P38: =1-(1-O38)*(1-MIN(0.95,$O$5*M38*N38*$O$12)) | Q38: =1-(1-P38)*(1-MIN(0.95,$O$5*M38*N38*$O$13)) | R38: =1-(1-Q38)*(1-MIN(0.95,$O$5*M38*N38*$O$14)) | S38: ★ CHEAPEST for Oscar — list high, cut later if needed
A40: AVERAGE ACROSS ALL 20 SCENARIOS (equal weight)
A41: Average loss of Francie's $48k capital (shortfall) | G41: =AVERAGE(H19:H38)
A42: Average she keeps of the $48k | G42: =$B$5-AVERAGE(H19:H38)
A43: Average COST TO OSCAR @ 80% | G43: =AVERAGE(I19:I38)
A44: Average COST TO OSCAR @ 70% | G44: =AVERAGE(J19:J38)
A46: AVERAGE COST TO OSCAR BY ROUTE (across the 5 prices)
...

Sheet Notes & Assumptions
A1: House Sale Scenarios + Probability of Sale — Notes
A3: PROPERTY (verified online)
A4: • 537 Duchart Ln, Fuquay-Varina, NC 27526 — 3bd/2.5ba, 2,216 sqft, Lakestone Village.
A5: • Recorded sale: Mar 18, 2024 for $405,700. Currently listed $409,900.
A7: MORTGAGE (from your screenshot, loan *5990)
A8: • Payoff used: $356,149.76. Payment $3,050.77/mo. Get an official payoff quote — true payoff
A9: runs a bit higher (per-day interest). Only ~$1,550 principal paid since 2024 (normal this early).
A11: DEAL MATH (unchanged from v1)
A12: • NET proceeds = Sale price − payoff − selling costs = 'money back' toward her $48,000.
A13: • Shortfall = $48,000 − NET proceeds. YOUR payment = Shortfall × 80% (or 70%).
A15: CURRENT MARKET — Fuquay-Varina (June 2026)
A16: • Median days on market ≈ 85 days (flat vs a year ago) — a slow, normalizing market.
... A75: • Closing costs: ListWithClever, Houzeo, Bankrate, Redfin (NC seller costs & transfer tax).

Sheet Chart — Cost vs Odds
A1: Trade-off: what Oscar pays (@80%) vs. odds the house is sold by end of October
A3: All options | D3: ★ Recommended picks
A4: P(sold by Oct) | B4: Oscar pay @80% | D4: P(sold by Oct) | E4: Oscar pay @80% | F4: Label
A5: =Scenarios!R19 | B5: =Scenarios!I19 | D5: =Scenarios!R34 | E5: =Scenarios!I34 | F5: BEST VALUE ($405k FSBO 2.5%)
A6: =Scenarios!R20 | B6: =Scenarios!I20 | D6: =Scenarios!R38 | E6: =Scenarios!I38 | F6: CHEAPEST ($409.9k FSBO 2.5%)
A7: =Scenarios!R21 | B7: =Scenarios!I21 | D7: =Scenarios!R28 | E7: =Scenarios!I28 | F7: BEST ODDS ($399k agent 5.5%)
A8: =Scenarios!R22 | B8: =Scenarios!I22
A9: =Scenarios!R23 | B9: =Scenarios!I23
A10: =Scenarios!R24 | B10: =Scenarios!I24
A11: =Scenarios!R25 | B11: =Scenarios!I25
A12: =Scenarios!R26 | B12: =Scenarios!I26
A13: =Scenarios!R27 | B13: =Scenarios!I27
A14: =Scenarios!R28 | B14: =Scenarios!I28
A15: =Scenarios!R29 | B15: =Scenarios!I29
A16: =Scenarios!R30 | B16: =Scenarios!I30
A17: =Scenarios!R31 | B17: =Scenarios!I31
A18: =Scenarios!R32 | B18: =Scenarios!I32
A19: =Scenarios!R33 | B19: =Scenarios!I33
... A21: =Scenarios!R35 | B21: =Scenarios!I35
A22: Read it like this: down-and-to-the-right is ideal (cheap for Oscar AND likely to sell). | B22: =Scenarios!I36
A23: The ★ stars are the tagged picks. Points up high cost Oscar the most; points to the left are least likely to sell. | B23: =Scenarios!I37
A24: =Scenarios!R38 | B24: =Scenarios!I38
