Workbook

Sheet Defect Trends- ATM
A1: Defect Trends by Slaughterhouse (ATM post-freeze inspection)
A2: Defect-centric view: how each canonical defect category behaves over time at each slaughterhouse. Within Martins, male (666540) and female (666541) parts are combined — the per-part breakdown lives in the Defect Pivot sheets. All counts pull via SUMIFS from Master Data, so editing Master Data will propagate here.
A4: MARTINS — defect counts over time
A5: Defect (canonical) | B5: 2026-02-09 | C5: 2026-02-23 | D5: 2026-03-02 | E5: 2026-03-09 | F5: 2026-03-16 | G5: 2026-03-23 | H5: 2026-03-30 | I5: 2026-04-06 | J5: 2026-04-13 | K5: 2026-04-20 | L5: 2026-05-04 | M5: 2026-05-11 | N5: 2026-05-28 | O5: Total
A6: Critical Mesentery Hole/Laceration (>0.5") | B6: =SUMIFS('Master Data'!I:I,'Master Data'!A:A,"2026-02-09",'Master Data'!E:E,"Martins",'Master Data'!H:H,A6) -> 1 | C6: =SUMIFS('Master Data'!I:I,'Master Data'!A:A,"2026-02-23",'Master Data'!E:E,"Martins",'Master Data'!H:H,A6) -> 17 | D6: =SUMIFS('Master Data'!I:I,'Master Data'!A:A,"2026-03-02",'Master Data'!E:E,"Martins",'Master Data'!H:H,A6) -> 45 | E6: =SUMIFS('Master Data'!I:I,'Master Data'!A:A,"2026-03-09",'Master Data'!E:E,"Martins",'Master Data'!H:H,A6) -> 6 | F6: =SUMIFS('Master Data'!I:I,'Master Data'!A:A,"2026-03-16",'Master Data'!E:E,"Martins",'Master Data'!H:H,A6) -> 22 | G6: =SUMIFS('Master Data'!I:I,'Master Data'!A:A,"2026-03-23",'Master Data'!E:E,"Martins",'Master Data'!H:H,A6) -> 26 | H6: =SUMIFS('Master Data'!I:I,'Master Data'!A:A,"2026-03-30",'Master Data'!E:E,"Martins",'Master Data'!H:H,A6) -> 12 | I6: =SUMIFS('Master Data'!I:I,'Master Data'!A:A,"2026-04-06",'Master Data'!E:E,"Martins",'Master Data'!H:H,A6) -> 12 | J6: =SUMIFS('Master Data'!I:I,'Master Data'!A:A,"2026-04-13",'Master Data'!E:E,"Martins",'Master Data'!H:H,A6) -> 6 | K6: =SUMIFS('Master Data'!I:I,'Master Data'!A:A,"2026-04-20",'Master Data'!E:E,"Martins",'Master Data'!H:H,A6) -> 18 | L6: =SUMIFS('Master Data'!I:I,'Master Data'!A:A,"2026-05-04",'Master Data'!E:E,"Martins",'Master Data'!H:H,A6) -> 4 | M6: =SUMIFS('Master Data'!I:I,'Master Data'!A:A,"2026-05-11",'Master Data'!E:E,"Martins",'Master Data'!H:H,A6) -> 1 | N6: =SUMIFS('Master Data'!I:I,'Master Data'!A:A,"2026-05-28",'Master Data'!E:E,"Martins",'Master Data'!H:H,A6) -> 1 | O6: =SUM(B6:N6) -> 171
A7: Non-Critical Mesentery Hole (>1.5") | B7: =SUMIFS('Master Data'!I:I,'Master Data'!A:A,"2026-02-09",'Master Data'!E:E,"Martins",'Master Data'!H:H,A7) -> 0 | C7: =SUMIFS('Master Data'!I:I,'Master Data'!A:A,"2026-02-23",'Master Data'!E:E,"Martins",'Master Data'!H:H,A7) -> 0 | D7: =SUMIFS('Master Data'!I:I,'Master Data'!A:A,"2026-03-02",'Master Data'!E:E,"Martins",'Master Data'!H:H,A7) -> 0 | E7: =SUMIFS('Master Data'!I:I,'Master Data'!A:A,"2026-03-09",'Master Data'!E:E,"Martins",'Master Data'!H:H,A7) -> 0 | F7: =SUMIFS('Master Data'!I:I,'Master Data'!A:A,"2026-03-16",'Master Data'!E:E,"Martins",'Master Data'!H:H,A7) -> 0 | G7: =SUMIFS('Master Data'!I:I,'Master Data'!A:A,"2026-03-23",'Master Data'!E:E,"Martins",'Master Data'!H:H,A7) -> 0 | H7: =SUMIFS('Master Data'!I:I,'Master Data'!A:A,"2026-03-30",'Master Data'!E:E,"Martins",'Master Data'!H:H,A7) -> 0 | I7: =SUMIFS('Master Data'!I:I,'Master Data'!A:A,"2026-04-06",'Master Data'!E:E,"Martins",'Master Data'!H:H,A7) -> 0 | J7: =SUMIFS('Master Data'!I:I,'Master Data'!A:A,"2026-04-13",'Master Data'!E:E,"Martins",'Master Data'!H:H,A7) -> 0 | K7: =SUMIFS('Master Data'!I:I,'Master Data'!A:A,"2026-04-20",'Master Data'!E:E,"Martins",'Master Data'!H:H,A7) -> 0 | L7: =SUMIFS('Master Data'!I:I,'Master Data'!A:A,"2026-05-04",'Master Data'!E:E,"Martins",'Master Data'!H:H,A7) -> 0 | M7: =SUMIFS('Master Data'!I:I,'Master Data'!A:A,"2026-05-11",'Master Data'!E:E,"Martins",'Master Data'!H:H,A7) -> 0 | N7: =SUMIFS('Master Data'!I:I,'Master Data'!A:A,"2026-05-28",'Master Data'!E:E,"Martins",'Master Data'!H:H,A7) -> 0 | O7: =SUM(B7:N7) -> 0
A8: Blood Clot | B8: =SUMIFS('Master Data'!I:I,'Master Data'!A:A,"2026-02-09",'Master Data'!E:E,"Martins",'Master Data'!H:H,A8) -> 1 | C8: =SUMIFS('Master Data'!I:I,'Master Data'!A:A,"2026-02-23",'Master Data'!E:E,"Martins",'Master Data'!H:H,A8) -> 10 | D8: =SUMIFS('Master Data'!I:I,'Master Data'!A:A,"2026-03-02",'Master Data'!E:E,"Martins",'Master Data'!H:H,A8) -> 10 | E8: =SUMIFS('Master Data'!I:I,'Master Data'!A:A,"2026-03-09",'Master Data'!E:E,"Martins",'Master Data'!H:H,A8) -> 9 | F8: =SUMIFS('Master Data'!I:I,'Master Data'!A:A,"2026-03-16",'Master Data'!E:E,"Martins",'Master Data'!H:H,A8) -> 4 | G8: =SUMIFS('Master Data'!I:I,'Master Data'!A:A,"2026-03-23",'Master Data'!E:E,"Martins",'Master Data'!H:H,A8) -> 2 | H8: =SUMIFS('Master Data'!I:I,'Master Data'!A:A,"2026-03-30",'Master Data'!E:E,"Martins",'Master Data'!H:H,A8) -> 5 | I8: =SUMIFS('Master Data'!I:I,'Master Data'!A:A,"2026-04-06",'Master Data'!E:E,"Martins",'Master Data'!H:H,A8) -> 5 | J8: =SUMIFS('Master Data'!I:I,'Master Data'!A:A,"2026-04-13",'Master Data'!E:E,"Martins",'Master Data'!H:H,A8) -> 4 | K8: =SUMIFS('Master Data'!I:I,'Master Data'!A:A,"2026-04-20",'Master Data'!E:E,"Martins",'Master Data'!H:H,A8) -> 6 | L8: =SUMIFS('Master Data'!I:I,'Master Data'!A:A,"2026-05-04",'Master Data'!E:E,"Martins",'Master Data'!H:H,A8) -> 3 | M8: =SUMIFS('Master Data'!I:I,'Master Data'!A:A,"2026-05-11",'Master Data'!E:E,"Martins",'Master Data'!H:H,A8) -> 1 | N8: =SUMIFS('Master Data'!I:I,'Master Data'!A:A,"2026-05-28",'Master Data'!E:E,"Martins",'Master Data'!H:H,A8) -> 0 | O8: =SUM(B8:N8) -> 60
A9: Bladder Length Oversize (>5.5") | B9: =SUMIFS('Master Data'!I:I,'Master Data'!A:A,"2026-02-09",'Master Data'!E:E,"Martins",'Master Data'!H:H,A9) -> 0 | C9: =SUMIFS('Master Data'!I:I,'Master Data'!A:A,"2026-02-23",'Master Data'!E:E,"Martins",'Master Data'!H:H,A9) -> 1 | D9: =SUMIFS('Master Data'!I:I,'Master Data'!A:A,"2026-03-02",'Master Data'!E:E,"Martins",'Master Data'!H:H,A9) -> 0 | E9: =SUMIFS('Master Data'!I:I,'Master Data'!A:A,"2026-03-09",'Master Data'!E:E,"Martins",'Master Data'!H:H,A9) -> 0 | F9: =SUMIFS('Master Data'!I:I,'Master Data'!A:A,"2026-03-16",'Master Data'!E:E,"Martins",'Master Data'!H:H,A9) -> 0 | G9: =SUMIFS('Master Data'!I:I,'Master Data'!A:A,"2026-03-23",'Master Data'!E:E,"Martins",'Master Data'!H:H,A9) -> 0 | H9: =SUMIFS('Master Data'!I:I,'Master Data'!A:A,"2026-03-30",'Master Data'!E:E,"Martins",'Master Data'!H:H,A9) -> 0 | I9: =SUMIFS('Master Data'!I:I,'Master Data'!A:A,"2026-04-06",'Master Data'!E:E,"Martins",'Master Data'!H:H,A9) -> 0 | J9: =SUMIFS('Master Data'!I:I,'Master Data'!A:A,"2026-04-13",'Master Data'!E:E,"Martins",'Master Data'!H:H,A9) -> 0 | K9: =SUMIFS('Master Data'!I:I,'Master Data'!A:A,"2026-04-20",'Master Data'!E:E,"Martins",'Master Data'!H:H,A9) -> 0 | L9: =SUMIFS('Master Data'!I:I,'Master Data'!A:A,"2026-05-04",'Master Data'!E:E,"Martins",'Master Data'!H:H,A9) -> 0 | M9: =SUMIFS('Master Data'!I:I,'Master Data'!A:A,"2026-05-11",'Master Data'!E:E,"Martins",'Master Data'!H:H,A9) -> 0 | N9: =SUMIFS('Master Data'!I:I,'Master Data'!A:A,"2026-05-28",'Master Data'!E:E,"Martins",'Master Data'!H:H,A9) -> 0 | O9: =SUM(B9:N9) -> 1
A10: Bladder Length Undersize | B10: =SUMIFS('Master Data'!I:I,'Master Data'!A:A,"2026-02-09",'Master Data'!E:E,"Martins",'Master Data'!H:H,A10) -> 8 | C10: =SUMIFS('Master Data'!I:I,'Master Data'!A:A,"2026-02-23",'Master Data'!E:E,"Martins",'Master Data'!H:H,A10) -> 5 | D10: =SUMIFS('Master Data'!I:I,'Master Data'!A:A,"2026-03-02",'Master Data'!E:E,"Martins",'Master Data'!H:H,A10) -> 20 | E10: =SUMIFS('Master Data'!I:I,'Master Data'!A:A,"2026-03-09",'Master Data'!E:E,"Martins",'Master Data'!H:H,A10) -> 9 | F10: =SUMIFS('Master Data'!I:I,'Master Data'!A:A,"2026-03-16",'Master Data'!E:E,"Martins",'Master Data'!H:H,A10) -> 0 | G10: =SUMIFS('Master Data'!I:I,'Master Data'!A:A,"2026-03-23",'Master Data'!E:E,"Martins",'Master Data'!H:H,A10) -> 0 | H10: =SUMIFS('Master Data'!I:I,'Master Data'!A:A,"2026-03-30",'Master Data'!E:E,"Martins",'Master Data'!H:H,A10) -> 0 | I10: =SUMIFS('Master Data'!I:I,'Master Data'!A:A,"2026-04-06",'Master Data'!E:E,"Martins",'Master Data'!H:H,A10) -> 0 | J10: =SUMIFS('Master Data'!I:I,'Master Data'!A:A,"2026-04-13",'Master Data'!E:E,"Martins",'Master Data'!H:H,A10) -> 0 | K10: =SUMIFS('Master Data'!I:I,'Master Data'!A:A,"2026-04-20",'Master Data'!E:E,"Martins",'Master Data'!H:H,A10) -> 0 | L10: =SUMIFS('Master Data'!I:I,'Master Data'!A:A,"2026-05-04",'Master Data'!E:E,"Martins",'Master Data'!H:H,A10) -> 0 | M10: =SUMIFS('Master Data'!I:I,'Master Data'!A:A,"2026-05-11",'Master Data'!E:E,"Martins",'Master Data'!H:H,A10) -> 0 | N10: =SUMIFS('Master Data'!I:I,'Master Data'!A:A,"2026-05-28",'Master Data'!E:E,"Martins",'Master Data'!H:H,A10) -> 0 | O10: =SUM(B10:N10) -> 42
A11: Urethra Laceration (exposing internal) | B11: =SUMIFS('Master Data'!I:I,'Master Data'!A:A,"2026-02-09",'Master Data'!E:E,"Martins",'Master Data'!H:H,A11) -> 5 | C11: =SUMIFS('Master Data'!I:I,'Master Data'!A:A,"2026-02-23",'Master Data'!E:E,"Martins",'Master Data'!H:H,A11) -> 6 | D11: =SUMIFS('Master Data'!I:I,'Master Data'!A:A,"2026-03-02",'Master Data'!E:E,"Martins",'Master Data'!H:H,A11) -> 19 | E11: =SUMIFS('Master Data'!I:I,'Master Data'!A:A,"2026-03-09",'Master Data'!E:E,"Martins",'Master Data'!H:H,A11) -> 9 | F11: =SUMIFS('Master Data'!I:I,'Master Data'!A:A,"2026-03-16",'Master Data'!E:E,"Martins",'Master Data'!H:H,A11) -> 2 | G11: =SUMIFS('Master Data'!I:I,'Master Data'!A:A,"2026-03-23",'Master Data'!E:E,"Martins",'Master Data'!H:H,A11) -> 10 | H11: =SUMIFS('Master Data'!I:I,'Master Data'!A:A,"2026-03-30",'Master Data'!E:E,"Martins",'Master Data'!H:H,A11) -> 4 | I11: =SUMIFS('Master Data'!I:I,'Master Data'!A:A,"2026-04-06",'Master Data'!E:E,"Martins",'Master Data'!H:H,A11) -> 0 | J11: =SUMIFS('Master Data'!I:I,'Master Data'!A:A,"2026-04-13",'Master Data'!E:E,"Martins",'Master Data'!H:H,A11) -> 0 | K11: =SUMIFS('Master Data'!I:I,'Master Data'!A:A,"2026-04-20",'Master Data'!E:E,"Martins",'Master Data'!H:H,A11) -> 0 | L11: =SUMIFS('Master Data'!I:I,'Master Data'!A:A,"2026-05-04",'Master Data'!E:E,"Martins",'Master Data'!H:H,A11) -> 6 | M11: =SUMIFS('Master Data'!I:I,'Master Data'!A:A,"2026-05-11",'Master Data'!E:E,"Martins",'Master Data'!H:H,A11) -> 1 | N11: =SUMIFS('Master Data'!I:I,'Master Data'!A:A,"2026-05-28",'Master Data'!E:E,"Martins",'Master Data'!H:H,A11) -> 4 | O11: =SUM(B11:N11) -> 66
A12: Bladder Laceration (exposing internal) | B12: =SUMIFS('Master Data'!I:I,'Master Data'!A:A,"2026-02-09",'Master Data'!E:E,"Martins",'Master Data'!H:H,A12) -> 3 | C12: =SUMIFS('Master Data'!I:I,'Master Data'!A:A,"2026-02-23",'Master Data'!E:E,"Martins",'Master Data'!H:H,A12) -> 2 | D12: =SUMIFS('Master Data'!I:I,'Master Data'!A:A,"2026-03-02",'Master Data'!E:E,"Martins",'Master Data'!H:H,A12) -> 4 | E12: =SUMIFS('Master Data'!I:I,'Master Data'!A:A,"2026-03-09",'Master Data'!E:E,"Martins",'Master Data'!H:H,A12) -> 4 | F12: =SUMIFS('Master Data'!I:I,'Master Data'!A:A,"2026-03-16",'Master Data'!E:E,"Martins",'Master Data'!H:H,A12) -> 5 | G12: =SUMIFS('Master Data'!I:I,'Master Data'!A:A,"2026-03-23",'Master Data'!E:E,"Martins",'Master Data'!H:H,A12) -> 0 | H12: =SUMIFS('Master Data'!I:I,'Master Data'!A:A,"2026-03-30",'Master Data'!E:E,"Martins",'Master Data'!H:H,A12) -> 0 | I12: =SUMIFS('Master Data'!I:I,'Master Data'!A:A,"2026-04-06",'Master Data'!E:E,"Martins",'Master Data'!H:H,A12) -> 2 | J12: =SUMIFS('Master Data'!I:I,'Master Data'!A:A,"2026-04-13",'Master Data'!E:E,"Martins",'Master Data'!H:H,A12) -> 0 | K12: =SUMIFS('Master Data'!I:I,'Master Data'!A:A,"2026-04-20",'Master Data'!E:E,"Martins",'Master Data'!H:H,A12) -> 0 | L12: =SUMIFS('Master Data'!I:I,'Master Data'!A:A,"2026-05-04",'Master Data'!E:E,"Martins",'Master Data'!H:H,A12) -> 0 | M12: =SUMIFS('Master Data'!I:I,'Master Data'!A:A,"2026-05-11",'Master Data'!E:E,"Martins",'Master Data'!H:H,A12) -> 0 | N12: =SUMIFS('Master Data'!I:I,'Master Data'!A:A,"2026-05-28",'Master Data'!E:E,"Martins",'Master Data'!H:H,A12) -> 0 | O12: =SUM(B12:N12) -> 20
A13: Exposed Ureters | B13: =SUMIFS('Master Data'!I:I,'Master Data'!A:A,"2026-02-09",'Master Data'!E:E,"Martins",'Master Data'!H:H,A13) -> 1 | C13: =SUMIFS('Master Data'!I:I,'Master Data'!A:A,"2026-02-23",'Master Data'!E:E,"Martins",'Master Data'!H:H,A13) -> 2 | D13: =SUMIFS('Master Data'!I:I,'Master Data'!A:A,"2026-03-02",'Master Data'!E:E,"Martins",'Master Data'!H:H,A13) -> 0 | E13: =SUMIFS('Master Data'!I:I,'Master Data'!A:A,"2026-03-09",'Master Data'!E:E,"Martins",'Master Data'!H:H,A13) -> 0 | F13: =SUMIFS('Master Data'!I:I,'Master Data'!A:A,"2026-03-16",'Master Data'!E:E,"Martins",'Master Data'!H:H,A13) -> 0 | G13: =SUMIFS('Master Data'!I:I,'Master Data'!A:A,"2026-03-23",'Master Data'!E:E,"Martins",'Master Data'!H:H,A13) -> 0 | H13: =SUMIFS('Master Data'!I:I,'Master Data'!A:A,"2026-03-30",'Master Data'!E:E,"Martins",'Master Data'!H:H,A13) -> 0 | I13: =SUMIFS('Master Data'!I:I,'Master Data'!A:A,"2026-04-06",'Master Data'!E:E,"Martins",'Master Data'!H:H,A13) -> 0 | J13: =SUMIFS('Master Data'!I:I,'Master Data'!A:A,"2026-04-13",'Master Data'!E:E,"Martins",'Master Data'!H:H,A13) -> 0 | K13: =SUMIFS('Master Data'!I:I,'Master Data'!A:A,"2026-04-20",'Master Data'!E:E,"Martins",'Master Data'!H:H,A13) -> 0 | L13: =SUMIFS('Master Data'!I:I,'Master Data'!A:A,"2026-05-04",'Master Data'!E:E,"Martins",'Master Data'!H:H,A13) -> 0 | M13: =SUMIFS('Master Data'!I:I,'Master Data'!A:A,"2026-05-11",'Master Data'!E:E,"Martins",'Master Data'!H:H,A13) -> 0 | N13: =SUMIFS('Master Data'!I:I,'Master Data'!A:A,"2026-05-28",'Master Data'!E:E,"Martins",'Master Data'!H:H,A13) -> 0 | O13: =SUM(B13:N13) -> 3
A14: Spoilage | B14: =SUMIFS('Master Data'!I:I,'Master Data'!A:A,"2026-02-09",'Master Data'!E:E,"Martins",'Master Data'!H:H,A14) -> 0 | C14: =SUMIFS('Master Data'!I:I,'Master Data'!A:A,"2026-02-23",'Master Data'!E:E,"Martins",'Master Data'!H:H,A14) -> 0 | D14: =SUMIFS('Master Data'!I:I,'Master Data'!A:A,"2026-03-02",'Master Data'!E:E,"Martins",'Master Data'!H:H,A14) -> 3 | E14: =SUMIFS('Master Data'!I:I,'Master Data'!A:A,"2026-03-09",'Master Data'!E:E,"Martins",'Master Data'!H:H,A14) -> 0 | F14: =SUMIFS('Master Data'!I:I,'Master Data'!A:A,"2026-03-16",'Master Data'!E:E,"Martins",'Master Data'!H:H,A14) -> 0 | G14: =SUMIFS('Master Data'!I:I,'Master Data'!A:A,"2026-03-23",'Master Data'!E:E,"Martins",'Master Data'!H:H,A14) -> 0 | H14: =SUMIFS('Master Data'!I:I,'Master Data'!A:A,"2026-03-30",'Master Data'!E:E,"Martins",'Master Data'!H:H,A14) -> 0 | I14: =SUMIFS('Master Data'!I:I,'Master Data'!A:A,"2026-04-06",'Master Data'!E:E,"Martins",'Master Data'!H:H,A14) -> 1 | J14: =SUMIFS('Master Data'!I:I,'Master Data'!A:A,"2026-04-13",'Master Data'!E:E,"Martins",'Master Data'!H:H,A14) -> 0 | K14: =SUMIFS('Master Data'!I:I,'Master Data'!A:A,"2026-04-20",'Master Data'!E:E,"Martins",'Master Data'!H:H,A14) -> 0 | L14: =SUMIFS('Master Data'!I:I,'Master Data'!A:A,"2026-05-04",'Master Data'!E:E,"Martins",'Master Data'!H:H,A14) -> 1 | M14: =SUMIFS('Master Data'!I:I,'Master Data'!A:A,"2026-05-11",'Master Data'!E:E,"Martins",'Master Data'!H:H,A14) -> 0 | N14: =SUMIFS('Master Data'!I:I,'Master Data'!A:A,"2026-05-28",'Master Data'!E:E,"Martins",'Master Data'!H:H,A14) -> 0 | O14: =SUM(B14:N14) -> 5
A15: Mesentery Length from Bladder Neck (≤7") | B15: =SUMIFS('Master Data'!I:I,'Master Data'!A:A,"2026-02-09",'Master Data'!E:E,"Martins",'Master Data'!H:H,A15) -> 0 | C15: =SUMIFS('Master Data'!I:I,'Master Data'!A:A,"2026-02-23",'Master Data'!E:E,"Martins",'Master Data'!H:H,A15) -> 0 | D15: =SUMIFS('Master Data'!I:I,'Master Data'!A:A,"2026-03-02",'Master Data'!E:E,"Martins",'Master Data'!H:H,A15) -> 0 | E15: =SUMIFS('Master Data'!I:I,'Master Data'!A:A,"2026-03-09",'Master Data'!E:E,"Martins",'Master Data'!H:H,A15) -> 0 | F15: =SUMIFS('Master Data'!I:I,'Master Data'!A:A,"2026-03-16",'Master Data'!E:E,"Martins",'Master Data'!H:H,A15) -> 0 | G15: =SUMIFS('Master Data'!I:I,'Master Data'!A:A,"2026-03-23",'Master Data'!E:E,"Martins",'Master Data'!H:H,A15) -> 0 | H15: =SUMIFS('Master Data'!I:I,'Master Data'!A:A,"2026-03-30",'Master Data'!E:E,"Martins",'Master Data'!H:H,A15) -> 0 | I15: =SUMIFS('Master Data'!I:I,'Master Data'!A:A,"2026-04-06",'Master Data'!E:E,"Martins",'Master Data'!H:H,A15) -> 0 | J15: =SUMIFS('Master Data'!I:I,'Master Data'!A:A,"2026-04-13",'Master Data'!E:E,"Martins",'Master Data'!H:H,A15) -> 0 | K15: =SUMIFS('Master Data'!I:I,'Master Data'!A:A,"2026-04-20",'Master Data'!E:E,"Martins",'Master Data'!H:H,A15) -> 0 | L15: =SUMIFS('Master Data'!I:I,'Master Data'!A:A,"2026-05-04",'Master Data'!E:E,"Martins",'Master Data'!H:H,A15) -> 0 | M15: =SUMIFS('Master Data'!I:I,'Master Data'!A:A,"2026-05-11",'Master Data'!E:E,"Martins",'Master Data'!H:H,A15) -> 0 | N15: =SUMIFS('Master Data'!I:I,'Master Data'!A:A,"2026-05-28",'Master Data'!E:E,"Martins",'Master Data'!H:H,A15) -> 0 | O15: =SUM(B15:N15) -> 0
A16: Units Received | B16: =SUMIFS('Receipt Summary'!F:F,'Receipt Summary'!A:A,"2026-02-09",'Receipt Summary'!D:D,"Martins") -> 150 | C16: =SUMIFS('Receipt Summary'!F:F,'Receipt Summary'!A:A,"2026-02-23",'Receipt Summary'!D:D,"Martins") -> 181 | D16: =SUMIFS('Receipt Summary'!F:F,'Receipt Summary'!A:A,"2026-03-02",'Receipt Summary'!D:D,"Martins") -> 353 | E16: =SUMIFS('Receipt Summary'!F:F,'Receipt Summary'!A:A,"2026-03-09",'Receipt Summary'!D:D,"Martins") -> 221 | F16: =SUMIFS('Receipt Summary'!F:F,'Receipt Summary'!A:A,"2026-03-16",'Receipt Summary'!D:D,"Martins") -> 220 | G16: =SUMIFS('Receipt Summary'!F:F,'Receipt Summary'!A:A,"2026-03-23",'Receipt Summary'!D:D,"Martins") -> 209 | H16: =SUMIFS('Receipt Summary'!F:F,'Receipt Summary'!A:A,"2026-03-30",'Receipt Summary'!D:D,"Martins") -> 227 | I16: =SUMIFS('Receipt Summary'!F:F,'Receipt Summary'!A:A,"2026-04-06",'Receipt Summary'!D:D,"Martins") -> 180 | J16: =SUMIFS('Receipt Summary'!F:F,'Receipt Summary'!A:A,"2026-04-13",'Receipt Summary'!D:D,"Martins") -> 200 | K16: =SUMIFS('Receipt Summary'!F:F,'Receipt Summary'!A:A,"2026-04-20",'Receipt Summary'!D:D,"Martins") -> 170 | L16: =SUMIFS('Receipt Summary'!F:F,'Receipt Summary'!A:A,"2026-05-04",'Receipt Summary'!D:D,"Martins") -> 270 | M16: =SUMIFS('Receipt Summary'!F:F,'Receipt Summary'!A:A,"2026-05-11",'Receipt Summary'!D:D,"Martins") -> 100 | N16: =SUMIFS('Receipt Summary'!F:F,'Receipt Summary'!A:A,"2026-05-28",'Receipt Summary'!D:D,"Martins") -> 270 | O16: =SUM(B16:N16) -> 2751
A17: Units Scrapped | B17: =SUMIFS('Receipt Summary'!H:H,'Receipt Summary'!A:A,"2026-02-09",'Receipt Summary'!D:D,"Martins") -> 19 | C17: =SUMIFS('Receipt Summary'!H:H,'Receipt Summary'!A:A,"2026-02-23",'Receipt Summary'!D:D,"Martins") -> 43 | D17: =SUMIFS('Receipt Summary'!H:H,'Receipt Summary'!A:A,"2026-03-02",'Receipt Summary'!D:D,"Martins") -> 100 | E17: =SUMIFS('Receipt Summary'!H:H,'Receipt Summary'!A:A,"2026-03-09",'Receipt Summary'!D:D,"Martins") -> 37 | F17: =SUMIFS('Receipt Summary'!H:H,'Receipt Summary'!A:A,"2026-03-16",'Receipt Summary'!D:D,"Martins") -> 33 | G17: =SUMIFS('Receipt Summary'!H:H,'Receipt Summary'!A:A,"2026-03-23",'Receipt Summary'!D:D,"Martins") -> 38 | H17: =SUMIFS('Receipt Summary'!H:H,'Receipt Summary'!A:A,"2026-03-30",'Receipt Summary'!D:D,"Martins") -> 21 | I17: =SUMIFS('Receipt Summary'!H:H,'Receipt Summary'!A:A,"2026-04-06",'Receipt Summary'!D:D,"Martins") -> 20 | J17: =SUMIFS('Receipt Summary'!H:H,'Receipt Summary'!A:A,"2026-04-13",'Receipt Summary'!D:D,"Martins") -> 10 | K17: =SUMIFS('Receipt Summary'!H:H,'Receipt Summary'!A:A,"2026-04-20",'Receipt Summary'!D:D,"Martins") -> 24 | L17: =SUMIFS('Receipt Summary'!H:H,'Receipt Summary'!A:A,"2026-05-04",'Receipt Summary'!D:D,"Martins") -> 14 | M17: =SUMIFS('Receipt Summary'!H:H,'Receipt Summary'!A:A,"2026-05-11",'Receipt Summary'!D:D,"Martins") -> 3 | N17: =SUMIFS('Receipt Summary'!H:H,'Receipt Summary'!A:A,"2026-05-28",'Receipt Summary'!D:D,"Martins") -> 5 | O17: =SUM(B17:N17) -> 367
A18: Rejection % | B18: =IFERROR(B17/B16,0) -> 0.12666667 | C18: =IFERROR(C17/C16,0) -> 0.23756906 | D18: =IFERROR(D17/D16,0) -> 0.28328612 | E18: =IFERROR(E17/E16,0) -> 0.16742081 | F18: =IFERROR(F17/F16,0) -> 0.15 | G18: =IFERROR(G17/G16,0) -> 0.18181818 | H18: =IFERROR(H17/H16,0) -> 0.092511013 | I18: =IFERROR(I17/I16,0) -> 0.11111111 | ... O18: =IFERROR(O17/O16,0) -> 0.13340603
A21: PARKS — defect counts over time
A22: Defect (canonical) | B22: 2026-03-09 | C22: 2026-03-23 | D22: 2026-03-30 | E22: 2026-04-20 | F22: 2026-05-04 | G22: 2026-05-11 | H22: 2026-05-28 | I22: Total
A23: Critical Mesentery Hole/Laceration (>0.5") | B23: =SUMIFS('Master Data'!I:I,'Master Data'!A:A,"2026-03-09",'Master Data'!E:E,"Parks",'Master Data'!H:H,A23) -> 1 | C23: =SUMIFS('Master Data'!I:I,'Master Data'!A:A,"2026-03-23",'Master Data'!E:E,"Parks",'Master Data'!H:H,A23) -> 4 | D23: =SUMIFS('Master Data'!I:I,'Master Data'!A:A,"2026-03-30",'Master Data'!E:E,"Parks",'Master Data'!H:H,A23) -> 2 | E23: =SUMIFS('Master Data'!I:I,'Master Data'!A:A,"2026-04-20",'Master Data'!E:E,"Parks",'Master Data'!H:H,A23) -> 22 | F23: =SUMIFS('Master Data'!I:I,'Master Data'!A:A,"2026-05-04",'Master Data'!E:E,"Parks",'Master Data'!H:H,A23) -> 2 | G23: =SUMIFS('Master Data'!I:I,'Master Data'!A:A,"2026-05-11",'Master Data'!E:E,"Parks",'Master Data'!H:H,A23) -> 187 | H23: =SUMIFS('Master Data'!I:I,'Master Data'!A:A,"2026-05-28",'Master Data'!E:E,"Parks",'Master Data'!H:H,A23) -> 0 | I23: =SUM(B23:H23) -> 218
A24: Non-Critical Mesentery Hole (>1.5") | B24: =SUMIFS('Master Data'!I:I,'Master Data'!A:A,"2026-03-09",'Master Data'!E:E,"Parks",'Master Data'!H:H,A24) -> 0 | C24: =SUMIFS('Master Data'!I:I,'Master Data'!A:A,"2026-03-23",'Master Data'!E:E,"Parks",'Master Data'!H:H,A24) -> 0 | D24: =SUMIFS('Master Data'!I:I,'Master Data'!A:A,"2026-03-30",'Master Data'!E:E,"Parks",'Master Data'!H:H,A24) -> 0 | E24: =SUMIFS('Master Data'!I:I,'Master Data'!A:A,"2026-04-20",'Master Data'!E:E,"Parks",'Master Data'!H:H,A24) -> 0 | F24: =SUMIFS('Master Data'!I:I,'Master Data'!A:A,"2026-05-04",'Master Data'!E:E,"Parks",'Master Data'!H:H,A24) -> 0 | G24: =SUMIFS('Master Data'!I:I,'Master Data'!A:A,"2026-05-11",'Master Data'!E:E,"Parks",'Master Data'!H:H,A24) -> 0 | H24: =SUMIFS('Master Data'!I:I,'Master Data'!A:A,"2026-05-28",'Master Data'!E:E,"Parks",'Master Data'!H:H,A24) -> 0 | I24: =SUM(B24:H24) -> 0
A25: Blood Clot | B25: =SUMIFS('Master Data'!I:I,'Master Data'!A:A,"2026-03-09",'Master Data'!E:E,"Parks",'Master Data'!H:H,A25) -> 1 | C25: =SUMIFS('Master Data'!I:I,'Master Data'!A:A,"2026-03-23",'Master Data'!E:E,"Parks",'Master Data'!H:H,A25) -> 0 | D25: =SUMIFS('Master Data'!I:I,'Master Data'!A:A,"2026-03-30",'Master Data'!E:E,"Parks",'Master Data'!H:H,A25) -> 0 | E25: =SUMIFS('Master Data'!I:I,'Master Data'!A:A,"2026-04-20",'Master Data'!E:E,"Parks",'Master Data'!H:H,A25) -> 0 | F25: =SUMIFS('Master Data'!I:I,'Master Data'!A:A,"2026-05-04",'Master Data'!E:E,"Parks",'Master Data'!H:H,A25) -> 0 | G25: =SUMIFS('Master Data'!I:I,'Master Data'!A:A,"2026-05-11",'Master Data'!E:E,"Parks",'Master Data'!H:H,A25) -> 0 | H25: =SUMIFS('Master Data'!I:I,'Master Data'!A:A,"2026-05-28",'Master Data'!E:E,"Parks",'Master Data'!H:H,A25) -> 0 | I25: =SUM(B25:H25) -> 1
A26: Bladder Length Oversize (>5.5") | B26: =SUMIFS('Master Data'!I:I,'Master Data'!A:A,"2026-03-09",'Master Data'!E:E,"Parks",'Master Data'!H:H,A26) -> 0 | C26: =SUMIFS('Master Data'!I:I,'Master Data'!A:A,"2026-03-23",'Master Data'!E:E,"Parks",'Master Data'!H:H,A26) -> 0 | D26: =SUMIFS('Master Data'!I:I,'Master Data'!A:A,"2026-03-30",'Master Data'!E:E,"Parks",'Master Data'!H:H,A26) -> 1 | E26: =SUMIFS('Master Data'!I:I,'Master Data'!A:A,"2026-04-20",'Master Data'!E:E,"Parks",'Master Data'!H:H,A26) -> 4 | F26: =SUMIFS('Master Data'!I:I,'Master Data'!A:A,"2026-05-04",'Master Data'!E:E,"Parks",'Master Data'!H:H,A26) -> 0 | G26: =SUMIFS('Master Data'!I:I,'Master Data'!A:A,"2026-05-11",'Master Data'!E:E,"Parks",'Master Data'!H:H,A26) -> 0 | H26: =SUMIFS('Master Data'!I:I,'Master Data'!A:A,"2026-05-28",'Master Data'!E:E,"Parks",'Master Data'!H:H,A26) -> 0 | I26: =SUM(B26:H26) -> 5
A27: Bladder Length Undersize | B27: =SUMIFS('Master Data'!I:I,'Master Data'!A:A,"2026-03-09",'Master Data'!E:E,"Parks",'Master Data'!H:H,A27) -> 0 | C27: =SUMIFS('Master Data'!I:I,'Master Data'!A:A,"2026-03-23",'Master Data'!E:E,"Parks",'Master Data'!H:H,A27) -> 0 | D27: =SUMIFS('Master Data'!I:I,'Master Data'!A:A,"2026-03-30",'Master Data'!E:E,"Parks",'Master Data'!H:H,A27) -> 0 | E27: =SUMIFS('Master Data'!I:I,'Master Data'!A:A,"2026-04-20",'Master Data'!E:E,"Parks",'Master Data'!H:H,A27) -> 0 | F27: =SUMIFS('Master Data'!I:I,'Master Data'!A:A,"2026-05-04",'Master Data'!E:E,"Parks",'Master Data'!H:H,A27) -> 0 | G27: =SUMIFS('Master Data'!I:I,'Master Data'!A:A,"2026-05-11",'Master Data'!E:E,"Parks",'Master Data'!H:H,A27) -> 0 | H27: =SUMIFS('Master Data'!I:I,'Master Data'!A:A,"2026-05-28",'Master Data'!E:E,"Parks",'Master Data'!H:H,A27) -> 0 | I27: =SUM(B27:H27) -> 0
A28: Urethra Laceration (exposing internal) | B28: =SUMIFS('Master Data'!I:I,'Master Data'!A:A,"2026-03-09",'Master Data'!E:E,"Parks",'Master Data'!H:H,A28) -> 0 | C28: =SUMIFS('Master Data'!I:I,'Master Data'!A:A,"2026-03-23",'Master Data'!E:E,"Parks",'Master Data'!H:H,A28) -> 2 | D28: =SUMIFS('Master Data'!I:I,'Master Data'!A:A,"2026-03-30",'Master Data'!E:E,"Parks",'Master Data'!H:H,A28) -> 2 | E28: =SUMIFS('Master Data'!I:I,'Master Data'!A:A,"2026-04-20",'Master Data'!E:E,"Parks",'Master Data'!H:H,A28) -> 3 | F28: =SUMIFS('Master Data'!I:I,'Master Data'!A:A,"2026-05-04",'Master Data'!E:E,"Parks",'Master Data'!H:H,A28) -> 0 | G28: =SUMIFS('Master Data'!I:I,'Master Data'!A:A,"2026-05-11",'Master Data'!E:E,"Parks",'Master Data'!H:H,A28) -> 2 | H28: =SUMIFS('Master Data'!I:I,'Master Data'!A:A,"2026-05-28",'Master Data'!E:E,"Parks",'Master Data'!H:H,A28) -> 0 | I28: =SUM(B28:H28) -> 9
A29: Bladder Laceration (exposing internal) | B29: =SUMIFS('Master Data'!I:I,'Master Data'!A:A,"2026-03-09",'Master Data'!E:E,"Parks",'Master Data'!H:H,A29) -> 0 | C29: =SUMIFS('Master Data'!I:I,'Master Data'!A:A,"2026-03-23",'Master Data'!E:E,"Parks",'Master Data'!H:H,A29) -> 0 | D29: =SUMIFS('Master Data'!I:I,'Master Data'!A:A,"2026-03-30",'Master Data'!E:E,"Parks",'Master Data'!H:H,A29) -> 0 | E29: =SUMIFS('Master Data'!I:I,'Master Data'!A:A,"2026-04-20",'Master Data'!E:E,"Parks",'Master Data'!H:H,A29) -> 0 | F29: =SUMIFS('Master Data'!I:I,'Master Data'!A:A,"2026-05-04",'Master Data'!E:E,"Parks",'Master Data'!H:H,A29) -> 0 | G29: =SUMIFS('Master Data'!I:I,'Master Data'!A:A,"2026-05-11",'Master Data'!E:E,"Parks",'Master Data'!H:H,A29) -> 0 | H29: =SUMIFS('Master Data'!I:I,'Master Data'!A:A,"2026-05-28",'Master Data'!E:E,"Parks",'Master Data'!H:H,A29) -> 0 | I29: =SUM(B29:H29) -> 0
A30: Exposed Ureters | B30: =SUMIFS('Master Data'!I:I,'Master Data'!A:A,"2026-03-09",'Master Data'!E:E,"Parks",'Master Data'!H:H,A30) -> 0 | C30: =SUMIFS('Master Data'!I:I,'Master Data'!A:A,"2026-03-23",'Master Data'!E:E,"Parks",'Master Data'!H:H,A30) -> 0 | D30: =SUMIFS('Master Data'!I:I,'Master Data'!A:A,"2026-03-30",'Master Data'!E:E,"Parks",'Master Data'!H:H,A30) -> 0 | E30: =SUMIFS('Master Data'!I:I,'Master Data'!A:A,"2026-04-20",'Master Data'!E:E,"Parks",'Master Data'!H:H,A30) -> 0 | F30: =SUMIFS('Master Data'!I:I,'Master Data'!A:A,"2026-05-04",'Master Data'!E:E,"Parks",'Master Data'!H:H,A30) -> 0 | G30: =SUMIFS('Master Data'!I:I,'Master Data'!A:A,"2026-05-11",'Master Data'!E:E,"Parks",'Master Data'!H:H,A30) -> 0 | H30: =SUMIFS('Master Data'!I:I,'Master Data'!A:A,"2026-05-28",'Master Data'!E:E,"Parks",'Master Data'!H:H,A30) -> 0 | I30: =SUM(B30:H30) -> 0
A31: Spoilage | B31: =SUMIFS('Master Data'!I:I,'Master Data'!A:A,"2026-03-09",'Master Data'!E:E,"Parks",'Master Data'!H:H,A31) -> 0 | C31: =SUMIFS('Master Data'!I:I,'Master Data'!A:A,"2026-03-23",'Master Data'!E:E,"Parks",'Master Data'!H:H,A31) -> 0 | D31: =SUMIFS('Master Data'!I:I,'Master Data'!A:A,"2026-03-30",'Master Data'!E:E,"Parks",'Master Data'!H:H,A31) -> 0 | E31: =SUMIFS('Master Data'!I:I,'Master Data'!A:A,"2026-04-20",'Master Data'!E:E,"Parks",'Master Data'!H:H,A31) -> 0 | F31: =SUMIFS('Master Data'!I:I,'Master Data'!A:A,"2026-05-04",'Master Data'!E:E,"Parks",'Master Data'!H:H,A31) -> 0 | G31: =SUMIFS('Master Data'!I:I,'Master Data'!A:A,"2026-05-11",'Master Data'!E:E,"Parks",'Master Data'!H:H,A31) -> 0 | H31: =SUMIFS('Master Data'!I:I,'Master Data'!A:A,"2026-05-28",'Master Data'!E:E,"Parks",'Master Data'!H:H,A31) -> 0 | I31: =SUM(B31:H31) -> 0
A32: Mesentery Length from Bladder Neck (≤7") | B32: =SUMIFS('Master Data'!I:I,'Master Data'!A:A,"2026-03-09",'Master Data'!E:E,"Parks",'Master Data'!H:H,A32) -> 0 | C32: =SUMIFS('Master Data'!I:I,'Master Data'!A:A,"2026-03-23",'Master Data'!E:E,"Parks",'Master Data'!H:H,A32) -> 0 | D32: =SUMIFS('Master Data'!I:I,'Master Data'!A:A,"2026-03-30",'Master Data'!E:E,"Parks",'Master Data'!H:H,A32) -> 2 | E32: =SUMIFS('Master Data'!I:I,'Master Data'!A:A,"2026-04-20",'Master Data'!E:E,"Parks",'Master Data'!H:H,A32) -> 10 | F32: =SUMIFS('Master Data'!I:I,'Master Data'!A:A,"2026-05-04",'Master Data'!E:E,"Parks",'Master Data'!H:H,A32) -> 2 | G32: =SUMIFS('Master Data'!I:I,'Master Data'!A:A,"2026-05-11",'Master Data'!E:E,"Parks",'Master Data'!H:H,A32) -> 6 | H32: =SUMIFS('Master Data'!I:I,'Master Data'!A:A,"2026-05-28",'Master Data'!E:E,"Parks",'Master Data'!H:H,A32) -> 0 | I32: =SUM(B32:H32) -> 20
A33: Units Received | B33: =SUMIFS('Receipt Summary'!F:F,'Receipt Summary'!A:A,"2026-03-09",'Receipt Summary'!D:D,"Parks") -> 15 | C33: =SUMIFS('Receipt Summary'!F:F,'Receipt Summary'!A:A,"2026-03-23",'Receipt Summary'!D:D,"Parks") -> 22 | D33: =SUMIFS('Receipt Summary'!F:F,'Receipt Summary'!A:A,"2026-03-30",'Receipt Summary'!D:D,"Parks") -> 15 | E33: =SUMIFS('Receipt Summary'!F:F,'Receipt Summary'!A:A,"2026-04-20",'Receipt Summary'!D:D,"Parks") -> 118 | F33: =SUMIFS('Receipt Summary'!F:F,'Receipt Summary'!A:A,"2026-05-04",'Receipt Summary'!D:D,"Parks") -> 30 | G33: =SUMIFS('Receipt Summary'!F:F,'Receipt Summary'!A:A,"2026-05-11",'Receipt Summary'!D:D,"Parks") -> 220 | H33: =SUMIFS('Receipt Summary'!F:F,'Receipt Summary'!A:A,"2026-05-28",'Receipt Summary'!D:D,"Parks") -> 7 | I33: =SUM(B33:H33) -> 427
A34: Units Scrapped | B34: =SUMIFS('Receipt Summary'!H:H,'Receipt Summary'!A:A,"2026-03-09",'Receipt Summary'!D:D,"Parks") -> 2 | C34: =SUMIFS('Receipt Summary'!H:H,'Receipt Summary'!A:A,"2026-03-23",'Receipt Summary'!D:D,"Parks") -> 6 | D34: =SUMIFS('Receipt Summary'!H:H,'Receipt Summary'!A:A,"2026-03-30",'Receipt Summary'!D:D,"Parks") -> 7 | E34: =SUMIFS('Receipt Summary'!H:H,'Receipt Summary'!A:A,"2026-04-20",'Receipt Summary'!D:D,"Parks") -> 39 | F34: =SUMIFS('Receipt Summary'!H:H,'Receipt Summary'!A:A,"2026-05-04",'Receipt Summary'!D:D,"Parks") -> 4 | G34: =SUMIFS('Receipt Summary'!H:H,'Receipt Summary'!A:A,"2026-05-11",'Receipt Summary'!D:D,"Parks") -> 195 | H34: =SUMIFS('Receipt Summary'!H:H,'Receipt Summary'!A:A,"2026-05-28",'Receipt Summary'!D:D,"Parks") -> 0 | I34: =SUM(B34:H34) -> 253
A35: Rejection % | B35: =IFERROR(B34/B33,0) -> 0.13333333 | C35: =IFERROR(C34/C33,0) -> 0.27272727 | D35: =IFERROR(D34/D33,0) -> 0.46666667 | E35: =IFERROR(E34/E33,0) -> 0.33050847 | F35: =IFERROR(F34/F33,0) -> 0.13333333 | G35: =IFERROR(G34/G33,0) -> 0.88636364 | H35: =IFERROR(H34/H33,0) -> 0 | I35: =IFERROR(I34/I33,0) -> 0.59250585
A38: TOP 5 MOST RECURRING DEFECTS (by total count, all parts combined)
A39: Rank | B39: Defect (canonical) | C39: Martins count | D39: Parks count | E39: Total count | F39: % of all scrap
A40: 1 | B40: Critical Mesentery Hole/Laceration (>0.5") | C40: =SUMIFS('Master Data'!I:I,'Master Data'!E:E,"Martins",'Master Data'!H:H,B40) -> 171 | D40: =SUMIFS('Master Data'!I:I,'Master Data'!E:E,"Parks",'Master Data'!H:H,B40) -> 218 | E40: =C40+D40 -> 389 | F40: =IFERROR(E40/SUMIFS('Master Data'!I:I,'Master Data'!H:H,"<>(no defects recorded)"),0) -> 0.62640902
A41: 2 | B41: Urethra Laceration (exposing internal) | C41: =SUMIFS('Master Data'!I:I,'Master Data'!E:E,"Martins",'Master Data'!H:H,B41) -> 66 | D41: =SUMIFS('Master Data'!I:I,'Master Data'!E:E,"Parks",'Master Data'!H:H,B41) -> 9 | E41: =C41+D41 -> 75 | F41: =IFERROR(E41/SUMIFS('Master Data'!I:I,'Master Data'!H:H,"<>(no defects recorded)"),0) -> 0.12077295
A42: 3 | B42: Blood Clot | C42: =SUMIFS('Master Data'!I:I,'Master Data'!E:E,"Martins",'Master Data'!H:H,B42) -> 60 | D42: =SUMIFS('Master Data'!I:I,'Master Data'!E:E,"Parks",'Master Data'!H:H,B42) -> 1 | E42: =C42+D42 -> 61 | F42: =IFERROR(E42/SUMIFS('Master Data'!I:I,'Master Data'!H:H,"<>(no defects recorded)"),0) -> 0.098228663
A43: 4 | B43: Bladder Length Undersize | C43: =SUMIFS('Master Data'!I:I,'Master Data'!E:E,"Martins",'Master Data'!H:H,B43) -> 42 | D43: =SUMIFS('Master Data'!I:I,'Master Data'!E:E,"Parks",'Master Data'!H:H,B43) -> 0 | E43: =C43+D43 -> 42 | F43: =IFERROR(E43/SUMIFS('Master Data'!I:I,'Master Data'!H:H,"<>(no defects recorded)"),0) -> 0.06763285
A44: 5 | B44: Bladder Laceration (exposing internal) | C44: =SUMIFS('Master Data'!I:I,'Master Data'!E:E,"Martins",'Master Data'!H:H,B44) -> 20 | D44: =SUMIFS('Master Data'!I:I,'Master Data'!E:E,"Parks",'Master Data'!H:H,B44) -> 0 | E44: =C44+D44 -> 20 | F44: =IFERROR(E44/SUMIFS('Master Data'!I:I,'Master Data'!H:H,"<>(no defects recorded)"),0) -> 0.032206119
A46: Note: 'Mesentery Length from Bladder Neck (≤7")' is a NEW SPEC effective 2026-03-30 and a dominant Parks defect — trajectory matters more than cumulative count.

Sheet Slaughterhouse IQC
A1: Slaughterhouse IQC — Post-Harvest / Pre-Freeze Inspections
A2: Post-harvest inspections performed at the slaughterhouse by an ATM inspector, BEFORE freeze. These are the earliest quality gate in the tissue supply chain. The ATM receipt inspections (every other sheet in this workbook) happen AFTER freeze/thaw and capture a superset of damage modes. Batch/lot numbers shown here correspond — not always exactly — to lots that appear later in the ATM data. See 'SH → ATM Yield Comparison' section below for stage-to-stage reconciliation.
A4: INSPECTION METADATA
A5: Visit | B5: Harvest dates | C5: Slaughterhouse | D5: Inspector | E5: SH Tech | F5: Intact lot | G5: Non-intact lot | H5: Intact PN | I5: Non-intact PN
A6: Visit 1 | B6: 2026-04-13 & 2026-04-15 | C6: Martins | D6: Toni Cruz | E6: Jesus | F6: 5502378434 | G6: 5502378430 | H6: 666541 | I6: 666506
A7: Visit 2 | B7: 2026-04-20 & 2026-04-22 | C7: Martins | D7: Toni Cruz | E7: Jesus | F7: 5502391862 | G7: 5502391858 | H7: 666541 | I7: 666506
A8: Visit 3 | B8: 2026-05-04 & 2026-05-06 | C8: Martins | D8: Toni Cruz | E8: Jesus | F8: 5502404928 | G8: 5502404924 | H8: 666541 | I8: 666506
A9: Visit 4 | B9: 2026-05-18 & 2026-05-21 | C9: Martins | D9: Toni Cruz | E9: Jesus | F9: 5502421192 | G9: 5502421188 | H9: 666541 | I9: 666506
A10: Visit 5 | B10: 2026-05-27 | C10: Martins | D10: Toni Cruz | E10: Jesus | F10: 5502421192 | G10: (none collected) | H10: 666541 | I10: —
A11: Visit 6 | B11: 2026-05-28 | C11: Parks Family Meats | D11: Rasmin Mujanovic | E11: Natalie | F11: (no batch data) | G11: — | H11: 666518 | I11: —
A12: Visit 7 | B12: 2026-06-01 & 2026-06-03 | C12: Martins | D12: Toni Cruz | E12: Jesus | F12: 5502428786 | G12: 5502428782 | H12: 666541 | I12: 666506
A13: Visit 8 | B13: 2026-06-02 | C13: Parks Family Meats | D13: Rasmin Mujanovic | E13: Natalie | F13: (no batch data) | G13: — | H13: 666518 | I13: —
A14: Visit 9 | B14: 2026-06-08 | C14: Martins | D14: Toni Cruz | E14: Jesus | F14: 5502428786 | G14: 5502428782 | H14: 666541 | I14: 666506
A15: Visit 10 | B15: 2026-06-15 | C15: Martins | D15: Toni Cruz | E15: Jesus | F15: 5502462845 | G15: 5502462842 | H15: 666541 | I15: 666506
A16: Visit 11 | B16: 2026-06-16 | C16: Parks Family Meats | D16: Rasmin Mujanovic | E16: Natalie | F16: (no batch data) | G16: — | H16: 666518 | I16: —
... A24: Visit 19 | B24: 2026-07-13 | C24: Parks Family Meats | D24: Rasmin Mujanovic | E24: Natalie | F24: (no batch data) | G24: — | H24: 666518 | I24: —
A26: RAW INSPECTION DATA (per harvest date × lot × condition)
A27: Harvest Date | B27: Slaughterhouse | C27: Lot | D27: PN | E27: Condition | F27: Part Description | G27: # Inspected | H27: # Pass | I27: # Fail | J27: First Pass Yield | K27: Scrap Reason | L27: Inspector / SH Tech
A28: 2026-04-13 | B28: Martins | C28: 5502378434 | D28: 666541 | E28: Intact | F28: Tiss, porcine, fem, Pelvic block, intact | G28: 48 | H28: 47 | I28: 1 | J28: =IFERROR(H28/G28,0) | K28: 1 hole in bowel; 1 label marked for thin area in bowel | L28: Toni Cruz / Jesus
A29: 2026-04-15 | B29: Martins | C29: 5502378434 | D29: 666541 | E29: Intact | F29: Tiss, porcine, fem, Pelvic block, intact | G29: 17 | H29: 13 | I29: 4 | J29: =IFERROR(H29/G29,0) | K29: 2 blood clots (moved to non-intact); 2 scrapped for cut in urethra | L29: Toni Cruz / Jesus
A30: 2026-04-13 | B30: Martins | C30: 5502378430 | D30: 666506 | E30: Non-intact | F30: Tiss, porcine, fem, Pelvic block, non-intact | G30: 3 | H30: 3 | I30: 0 | J30: =IFERROR(H30/G30,0) | K30: 3 labels used for thin area in bowel (ran out of labels) | L30: Toni Cruz / Jesus
A31: 2026-04-15 | B31: Martins | C31: 5502378430 | D31: 666506 | E31: Non-intact | F31: Tiss, porcine, fem, Pelvic block, non-intact | G31: 4 | H31: 4 | I31: 0 | J31: =IFERROR(H31/G31,0) | L31: Toni Cruz / Jesus
A32: 2026-04-20 | B32: Martins | C32: 5502391862 | D32: 666541 | E32: Intact | F32: Tiss, porcine, fem, Pelvic block, intact | G32: 0 | H32: 0 | I32: 0 | J32: =IFERROR(H32/G32,0) | K32: Ran out of time (bagging set for later; SH tech start time changed to 8:00–4:30 PM) | L32: Toni Cruz / Jesus
A33: 2026-04-22 | B33: Martins | C33: 5502391862 | D33: 666541 | E33: Intact | F33: Tiss, porcine, fem, Pelvic block, intact | G33: 57 | H33: 56 | I33: 1 | J33: =IFERROR(H33/G33,0) | K33: 1 damaged bowel | L33: Toni Cruz / Jesus
A34: 2026-04-20 | B34: Martins | C34: 5502391858 | D34: 666506 | E34: Non-intact | F34: Tiss, porcine, fem, Pelvic block, non-intact | G34: 31 | H34: 29 | I34: 2 | J34: =IFERROR(H34/G34,0) | K34: 2 damaged after cleaning | L34: Toni Cruz / Jesus
A35: 2026-04-22 | B35: Martins | C35: 5502391858 | D35: 666506 | E35: Non-intact | F35: Tiss, porcine, fem, Pelvic block, non-intact | G35: 21 | H35: 19 | I35: 2 | J35: =IFERROR(H35/G35,0) | K35: 2 damaged bowel | L35: Toni Cruz / Jesus
A36: 2026-05-04 | B36: Martins | C36: 5502404928 | D36: 666541 | E36: Intact | F36: Tiss, porcine, fem, Pelvic block, intact | G36: 37 | H36: 36 | I36: 1 | J36: =IFERROR(H36/G36,0) | K36: 1 damaged urethra | L36: Toni Cruz / Jesus
A37: 2026-05-06 | B37: Martins | C37: 5502404928 | D37: 666541 | E37: Intact | F37: Tiss, porcine, fem, Pelvic block, intact | G37: 25 | H37: 22 | I37: 3 | J37: =IFERROR(H37/G37,0) | K37: 3 damaged urethra | L37: Toni Cruz / Jesus
A38: 2026-05-04 | B38: Martins | C38: 5502404924 | D38: 666506 | E38: Non-intact | F38: Tiss, porcine, fem, Pelvic block, non-intact | G38: 16 | H38: 13 | I38: 3 | J38: =IFERROR(H38/G38,0) | K38: 3 damaged urethra | L38: Toni Cruz / Jesus
A39: 2026-05-06 | B39: Martins | C39: 5502404924 | D39: 666506 | E39: Non-intact | F39: Tiss, porcine, fem, Pelvic block, non-intact | G39: 29 | H39: 28 | I39: 1 | J39: =IFERROR(H39/G39,0) | K39: 1 small bladder | L39: Toni Cruz / Jesus
A40: 2026-05-18 | B40: Martins | C40: 5502421192 | D40: 666541 | E40: Intact | F40: Tiss, porcine, fem, Pelvic block, intact | G40: 62 | H40: 58 | I40: 4 | J40: =IFERROR(H40/G40,0) | K40: 3 cut urethra; 1 short block | L40: Toni Cruz / Jesus
A41: 2026-05-21 | B41: Martins | C41: 5502421192 | D41: 666541 | E41: Intact | F41: Tiss, porcine, fem, Pelvic block, intact | G41: 31 | H41: 29 | I41: 2 | J41: =IFERROR(H41/G41,0) | K41: 2 cut urethra | L41: Toni Cruz / Jesus
A42: 2026-05-18 | B42: Martins | C42: 5502421188 | D42: 666506 | E42: Non-intact | F42: Tiss, porcine, fem, Pelvic block, non-intact | G42: 43 | H42: 42 | I42: 1 | J42: =IFERROR(H42/G42,0) | K42: 1 deformed ligaments clumped together | L42: Toni Cruz / Jesus
A43: 2026-05-21 | B43: Martins | C43: 5502421188 | D43: 666506 | E43: Non-intact | F43: Tiss, porcine, fem, Pelvic block, non-intact | G43: 30 | H43: 29 | I43: 1 | J43: =IFERROR(H43/G43,0) | K43: 1 damaged membrane and ureter | L43: Toni Cruz / Jesus
... A45: 2026-05-28 | B45: Parks Family Meats | C45: (no batch data) | D45: 666518 | E45: Intact | F45: Tiss, porcine, fem, Pelvic block, intact, SM | G45: 16 | H45: 11 | I45: 5 | J45: =IFERROR(H45/G45,0) | K45: 4 mesentery length too short in critical zone; 1 bladder damage (internals exposed) | L45: Rasmin Mujanovic / Natalie
A46: 2026-06-01 | B46: Martins | C46: 5502428786 | D46: 666541 | E46: Intact | F46: Tiss, porcine, fem, Pelvic block, intact | G46: 9 | H46: 9 | I46: 0 | J46: =IFERROR(H46/G46,0) | L46: Toni Cruz / Jesus
A47: 2026-06-03 | B47: Martins | C47: 5502428786 | D47: 666541 | E47: Intact | F47: Tiss, porcine, fem, Pelvic block, intact | G47: 45 | H47: 43 | I47: 2 | J47: =IFERROR(H47/G47,0) | K47: 2 scrapped urethra | L47: Toni Cruz / Jesus
A48: 2026-06-01 | B48: Martins | C48: 5502428782 | D48: 666506 | E48: Non-intact | F48: Tiss, porcine, fem, Pelvic block, non-intact | G48: 7 | H48: 7 | I48: 0 | J48: =IFERROR(H48/G48,0) | L48: Toni Cruz / Jesus
A49: 2026-06-03 | B49: Martins | C49: 5502428782 | D49: 666506 | E49: Non-intact | F49: Tiss, porcine, fem, Pelvic block, non-intact | G49: 29 | H49: 29 | I49: 0 | J49: =IFERROR(H49/G49,0) | L49: Toni Cruz / Jesus
A50: 2026-06-02 | B50: Parks Family Meats | C50: (no batch data) | D50: 666518 | E50: Intact | F50: Tiss, porcine, fem, Pelvic block, intact, SM | G50: 7 | H50: 7 | I50: 0 | J50: =IFERROR(H50/G50,0) | L50: Rasmin Mujanovic / Natalie
...

Sheet SmartAssessment
A1: SmartAssessment — Pelvic Block Quality (Claude analysis)
A2: Author: Claude · Compiled 2026-06-26 · Scope: Slaughterhouse IQC visits 1–14 + ATM receipt data. These are working analyst notes and interpretation — verify with Quality before any external/supplier use.
A4: 1. OBJECTIVE (as understood)
A5: Root-cause pelvic-block defects to their point of origin UPSTREAM — before the harvesting tech consolidates the pelvic block, and ideally back to slaughter/evisceration (handling of the main tissue block and GI). Goal: raise HARVESTING FIRST-PASS YIELD = successful pelvic blocks consolidated ÷ main tissue blocks the harvesting tech receives. Active at BOTH suppliers: Parks (already engaged) and Martins (sampling defective pelvics and bringing them to ATM for evaluation/root-cause). This is a yield-improvement / root-cause program, not a supplier down-select.
A7: 2. THE QUALITY PIPELINE — WHERE YIELD IS LOST
A8: Stage model
A9: Stage 0 Upstream: slaughter + evisceration; handling of the main tissue block / GI. Stage 1 Harvesting: SH tech consolidates the pelvic block ← first major yield loss, today largely UNMEASURED. Stage 2 SH-floor IQC: our ATM inspector, PRE-freeze — this is the current '# Inspected / Pass / Fail'. Stage 3 Freeze. Stage 4 ATM receipt: POST-freeze — the gate tied to performance goals.
A10: Key gap
A11: The tally sheets only count blocks that REACH our SH inspector. Blocks lost during harvesting (miscuts before presentation) are NOT in the pass/fail counts. See Parks Visit 11 (06/16): '~100 pigs slaughtered, the majority of blocks failed BEFORE reaching IQC due to miscuts during block removal.' That upstream loss IS the harvesting first-pass yield this program targets — and it is currently invisible. RECOMMEND adding two fields to the tally template: (a) main blocks received by harvesting tech, (b) blocks rejected at harvesting before IQC. Then harvesting FPY can be computed instead of inferred from a note.
A13: 3. PARKS 05/11 CRITICAL-MESENTERY EVENT — ROOT-CAUSE SUCCESS STORY
A14: ATM receipt 05/11 (PN 666518): 220 received, 195 scrapped (88.6% rejection), of which 187 were critical mesentery holes/lacerations. This ONE event is 187 of Parks's 218 total critical-mesentery defects across the entire record — it dominates the Parks picture.
A15: Confirmed REAL (per Quality). Root cause: a harvesting cut that was dividing the mesentery from the block, plus bowel-area handling issues the slaughterhouse was unaware of. Corrected via training + monitoring; monthly verification calls ongoing.
... A37: 1. Add harvesting-FPY capture to the tally template (main blocks received; blocks rejected pre-IQC) so upstream loss is measured, not inferred. 2. Tag ATM scrap by stage-of-origin (harvesting vs freeze/thaw vs spec-drift); keep freeze/thaw small-lacerations out of the harvesting-FPY denominator. 3. Build a matched-lot SH→ATM tracker as more lots gain both stages — prioritize post-intervention Parks lots to verify the 05/11 fix holds through freeze/thaw. 4. Reconcile the 666506 / 'non-intact' naming vs the tighter-spec definition; once confirmed, update IQC note 1 and the README. 5. Continue monthly supplier calls; trend the residual Parks 'short block' / critical-zone signal and the Martins sampled-defect root-causes. 6. When Tableau ATM data lands, link defect categories to stage-of-origin in the new batch-less sheet.

Sheet ATM_Scrap_TableuData
A1: ATM Scrap — Tableau Data (post-freeze / thaw)
A2: Source: Tableau “Top 5 Part” scrap views, June 2026. ATM = receipt inspection AFTER freeze/thaw (product sits frozen ~1–1.5 months), so this month reflects SH harvest from roughly late-April to late-May. No batch/lot numbers in the ATM feed, so cross-stage links are by time-window + part only. Values read from the two charts.
A4: WEEKLY SCRAP % TREND — JUNE 2026
A5: Week (ATM receipt) | B5: 666541 Scrap % | C5: 666506 Scrap % | D5: Goal
A6: 5/25 | B6: 0.25 | D6: 0.05
A7: 6/1 | B7: 0.063 | C7: 0 | D7: 0.05
A8: 6/8 | B8: 0.074 | C8: 0 | D8: 0.05
A9: 6/15 | B9: 0.032 | C9: 0 | D9: 0.05
A10: 6/22 | B10: 0.032 | C10: 0.014 | D10: 0.05
A11: 6/29 | B11: 0 | C11: 0 | D11: 0.05
A13: OVERALL SCRAP % BY PART — JUNE 2026
A14: Part | B14: Description | C14: June Scrap % | D14: vs 5% Goal
A15: 666541 | B15: DV Tech Pelvic Block (F), intact — performance-goal part | C15: 0.046 | D15: Under (0.4 pt below goal)
A16: 666506 | B16: Pelvic Block, non-intact — tighter spec | C16: 0.004 | D16: Under
A18: STAGE-TO-STAGE LAG CORRELATION (ATM week ← SH harvest ~4–6 weeks earlier)
A19: Directional only: ATM is weekly, SH visits are sporadic, and there is no lot linkage. SH 666541 scrap below is from the Martins intact rows on the Slaughterhouse IQC tab for the matching harvest window.
A20: ATM week | B20: ATM 666541 scrap | C20: SH harvest window | D20: SH 666541 scrap (Martins)
A21: 5/25 | B21: 0.25 | C21: ~4/13–4/22 | D21: 4.9% blended — 4/15 visit spiked to 23.5%
A22: 6/1 | B22: 0.063 | C22: ~4/20–4/29 | D22: 1.8% (4/22)
A23: 6/8 | B23: 0.074 | C23: ~4/27–5/6 | D23: 6.5% (5/4 + 5/6; 5/6 = 12.0%)
A24: 6/15 | B24: 0.032 | C24: ~5/4–5/13 | D24: 6.5% (5/6 = 12.0%)
A25: 6/22 | B25: 0.032 | C25: ~5/11–5/20 | D25: 6.5% (5/18)
A26: 6/29 | B26: 0 | C26: ~5/18–5/27 | D26: 6.8% (5/18–5/27)
A28: KEY TAKEAWAYS
A29: • 666541 (the performance-goal part) fell 25% → 0% across June and finished the month at 4.6% overall — just under the 5% goal. One early spike (25% on the 5/25 receipt) drove most of the month; it is the part to watch.
A30: • 666506 (tighter spec) held ~0% all month (0.4% overall) — well controlled through freeze/thaw.
A31: • Lag alignment: the 25% ATM spike (5/25) lands ~5–6 weeks after the roughest SH visit (4/15, 23.5% scrap) — consistent with the ~1–1.5-month freeze dwell and with defects originating upstream at harvest.
A32: • Both parts trend down into summer, matching the harvesting-training improvements at the slaughterhouses.
A34: NOTES & ASSUMPTIONS
A35: Line→part mapping (dark = 666541, light = 666506) inferred from the overall-by-part chart. Lag band = 4–6 weeks (≈1–1.5-month freeze dwell). These June charts are Martins parts; Parks 666518 is not in this top-5 view.
A36: Original Tableau screenshots are not embedded here — the image files were not available to paste. Drop the two screenshots beside these tables if you want the visuals inline. Refresh monthly as new Tableau months arrive.

Sheet Receipt Summary
A1: Date | B1: Part Number | C1: Description | D1: Slaughterhouse | E1: Lot # | F1: Received | G1: Accepted | H1: Scrap | I1: Rejection %
A2: 2026-02-09 | B2: 666541 | C2: DV Tech Pelvic Block (F) | D2: Martins | E2: (not recorded) | F2: 150 | G2: 131 | H2: 19 | I2: =IFERROR(H2/F2,0) -> 0.12666667
A3: 2026-02-23 | B3: 666541 | C3: DV Tech Pelvic Block (F) | D3: Martins | E3: (not recorded) | F3: 181 | G3: 138 | H3: 43 | I3: =IFERROR(H3/F3,0) -> 0.23756906
A4: 2026-03-02 | B4: 666540 | C4: DV Tech Pelvic Block (M) | D4: Martins | E4: 5502273661 | F4: 15 | G4: 10 | H4: 5 | I4: =IFERROR(H4/F4,0) -> 0.33333333
A5: 2026-03-02 | B5: 666540 | C5: DV Tech Pelvic Block (M) | D5: Martins | E5: 5502291196 | F5: 35 | G5: 28 | H5: 7 | I5: =IFERROR(H5/F5,0) -> 0.2
A6: 2026-03-02 | B6: 666540 | C6: DV Tech Pelvic Block (M) | D6: Martins | E6: 5502250634 | F6: 36 | G6: 24 | H6: 12 | I6: =IFERROR(H6/F6,0) -> 0.33333333
A7: 2026-03-02 | B7: 666540 | C7: DV Tech Pelvic Block (M) | D7: Martins | E7: 5502223712 | F7: 57 | G7: 38 | H7: 19 | I7: =IFERROR(H7/F7,0) -> 0.33333333
A8: 2026-03-02 | B8: 666541 | C8: DV Tech Pelvic Block (F) | D8: Martins | E8: (batch A) | F8: 160 | G8: 126 | H8: 34 | I8: =IFERROR(H8/F8,0) -> 0.2125
A9: 2026-03-02 | B9: 666541 | C9: DV Tech Pelvic Block (F) | D9: Martins | E9: 5502291197 | F9: 50 | G9: 27 | H9: 23 | I9: =IFERROR(H9/F9,0) -> 0.46
A10: 2026-03-09 | B10: 666518 | C10: DV Tech Pelvic Block (F) | D10: Parks | E10: 5502327700 | F10: 15 | G10: 13 | H10: 2 | I10: =IFERROR(H10/F10,0) -> 0.13333333
A11: 2026-03-09 | B11: 666541 | C11: DV Tech Pelvic Block (F) | D11: Martins | E11: 5502291197 | F11: 127 | G11: 106 | H11: 21 | I11: =IFERROR(H11/F11,0) -> 0.16535433
A12: 2026-03-09 | B12: 666541 | C12: DV Tech Pelvic Block (F) | D12: Martins | E12: 5502314191 | F12: 94 | G12: 78 | H12: 16 | I12: =IFERROR(H12/F12,0) -> 0.17021277
A13: 2026-03-16 | B13: 666540 | C13: DV Tech Pelvic Block (M) | D13: Martins | E13: 5502250634 | F13: 20 | G13: 13 | H13: 7 | I13: =IFERROR(H13/F13,0) -> 0.35
... A41: 2026-05-28 | B41: 666518 | C41: DV Tech Pelvic Block (F) | D41: Parks | E41: 5502428883 | F41: 7 | G41: 7 | H41: 0 | I41: =IFERROR(H41/F41,0) -> 0
A42: GRAND TOTAL | F42: =SUM(F2:F41) -> 3178 | G42: =SUM(G2:G41) -> 2558 | H42: =SUM(H2:H41) -> 620 | I42: =IFERROR(H42/F42,0) -> 0.19509125

Sheet Master Data
A1: Date | B1: Part Number | C1: Part Description | D1: Sex | E1: Slaughterhouse | F1: Lot # | G1: Defect (as recorded) | H1: Defect (canonical) | I1: Count | J1: Lot Received | K1: Lot Accepted | L1: Lot Scrap
A2: 2026-02-09 | B2: 666541 | C2: DV Tech Pelvic Block (F) | D2: Female | E2: Martins | F2: (not recorded) | G2: Hole in critical Mesentery greater than 0.5" | H2: Critical Mesentery Hole/Laceration (>0.5") | I2: 1 | J2: 150 | K2: 131 | L2: 19
A3: 2026-02-09 | B3: 666541 | C3: DV Tech Pelvic Block (F) | D3: Female | E3: Martins | F3: (not recorded) | G3: Bood Clot | H3: Blood Clot | I3: 1 | J3: 150 | K3: 131 | L3: 19
A4: 2026-02-09 | B4: 666541 | C4: DV Tech Pelvic Block (F) | D4: Female | E4: Martins | F4: (not recorded) | G4: Bladder Length less than 3" | H4: Bladder Length Undersize | I4: 8 | J4: 150 | K4: 131 | L4: 19
A5: 2026-02-09 | B5: 666541 | C5: DV Tech Pelvic Block (F) | D5: Female | E5: Martins | F5: (not recorded) | G5: Damage to Urethra | H5: Urethra Laceration (exposing internal) | I5: 5 | J5: 150 | K5: 131 | L5: 19
A6: 2026-02-09 | B6: 666541 | C6: DV Tech Pelvic Block (F) | D6: Female | E6: Martins | F6: (not recorded) | G6: Damage to Bladder | H6: Bladder Laceration (exposing internal) | I6: 3 | J6: 150 | K6: 131 | L6: 19
A7: 2026-02-09 | B7: 666541 | C7: DV Tech Pelvic Block (F) | D7: Female | E7: Martins | F7: (not recorded) | G7: Exposed Ureters | H7: Exposed Ureters | I7: 1 | J7: 150 | K7: 131 | L7: 19
A8: 2026-02-23 | B8: 666541 | C8: DV Tech Pelvic Block (F) | D8: Female | E8: Martins | F8: (not recorded) | G8: Hole in critical Mesentery greater than 0.5" | H8: Critical Mesentery Hole/Laceration (>0.5") | I8: 17 | J8: 181 | K8: 138 | L8: 43
A9: 2026-02-23 | B9: 666541 | C9: DV Tech Pelvic Block (F) | D9: Female | E9: Martins | F9: (not recorded) | G9: Bood Clot | H9: Blood Clot | I9: 10 | J9: 181 | K9: 138 | L9: 43
A10: 2026-02-23 | B10: 666541 | C10: DV Tech Pelvic Block (F) | D10: Female | E10: Martins | F10: (not recorded) | G10: Bladder Length greater than 5.5" | H10: Bladder Length Oversize (>5.5") | I10: 1 | J10: 181 | K10: 138 | L10: 43
A11: 2026-02-23 | B11: 666541 | C11: DV Tech Pelvic Block (F) | D11: Female | E11: Martins | F11: (not recorded) | G11: Bladder Length less than 3" | H11: Bladder Length Undersize | I11: 5 | J11: 181 | K11: 138 | L11: 43
A12: 2026-02-23 | B12: 666541 | C12: DV Tech Pelvic Block (F) | D12: Female | E12: Martins | F12: (not recorded) | G12: Lacerations on Urethra | H12: Urethra Laceration (exposing internal) | I12: 6 | J12: 181 | K12: 138 | L12: 43
A13: 2026-02-23 | B13: 666541 | C13: DV Tech Pelvic Block (F) | D13: Female | E13: Martins | F13: (not recorded) | G13: Lacerations on Bladder | H13: Bladder Laceration (exposing internal) | I13: 2 | J13: 181 | K13: 138 | L13: 43
... A118: 2026-05-28 | B118: 666518 | C118: DV Tech Pelvic Block (F) | D118: Female | E118: Parks | F118: 5502428883 | G118: (no defects recorded) | H118: (no defects recorded) | I118: 0 | J118: 7 | K118: 7 | L118: 0

Sheet Defect Pivot 666541-F
A1: 666541 DV Tech Pelvic Block (Female) — Martins
A3: Defect (canonical) | B3: 2026-02-09 | C3: 2026-02-23 | D3: 2026-03-02 | E3: 2026-03-09 | F3: 2026-03-16 | G3: 2026-03-23 | H3: 2026-03-30 | I3: 2026-04-06 | J3: 2026-04-13 | K3: 2026-04-20 | L3: 2026-05-04 | M3: 2026-05-11 | N3: Total
A4: Critical Mesentery Hole/Laceration (>0.5") | B4: 1 | C4: 17 | D4: 24 | E4: 6 | F4: 18 | G4: 22 | H4: 12 | I4: 12 | J4: 6 | K4: 18 | L4: 4 | M4: 1 | N4: =SUM(B4:M4) -> 141
A5: Non-Critical Mesentery Hole (>1.5") | B5: 0 | C5: 0 | D5: 0 | E5: 0 | F5: 0 | G5: 0 | H5: 0 | I5: 0 | J5: 0 | K5: 0 | L5: 0 | M5: 0 | N5: =SUM(B5:M5) -> 0
A6: Blood Clot | B6: 1 | C6: 10 | D6: 7 | E6: 9 | F6: 3 | G6: 2 | H6: 5 | I6: 5 | J6: 4 | K6: 6 | L6: 3 | M6: 1 | N6: =SUM(B6:M6) -> 56
A7: Bladder Length Oversize (>5.5") | B7: 0 | C7: 1 | D7: 0 | E7: 0 | F7: 0 | G7: 0 | H7: 0 | I7: 0 | J7: 0 | K7: 0 | L7: 0 | M7: 0 | N7: =SUM(B7:M7) -> 1
A8: Bladder Length Undersize | B8: 8 | C8: 5 | D8: 15 | E8: 9 | F8: 0 | G8: 0 | H8: 0 | I8: 0 | J8: 0 | K8: 0 | L8: 0 | M8: 0 | N8: =SUM(B8:M8) -> 37
A9: Urethra Laceration (exposing internal) | B9: 5 | C9: 6 | D9: 7 | E9: 9 | F9: 0 | G9: 9 | H9: 4 | I9: 0 | J9: 0 | K9: 0 | L9: 6 | M9: 1 | N9: =SUM(B9:M9) -> 47
A10: Bladder Laceration (exposing internal) | B10: 3 | C10: 2 | D10: 1 | E10: 4 | F10: 5 | G10: 0 | H10: 0 | I10: 2 | J10: 0 | K10: 0 | L10: 0 | M10: 0 | N10: =SUM(B10:M10) -> 17
A11: Exposed Ureters | B11: 1 | C11: 2 | D11: 0 | E11: 0 | F11: 0 | G11: 0 | H11: 0 | I11: 0 | J11: 0 | K11: 0 | L11: 0 | M11: 0 | N11: =SUM(B11:M11) -> 3
A12: Spoilage | B12: 0 | C12: 0 | D12: 3 | E12: 0 | F12: 0 | G12: 0 | H12: 0 | I12: 1 | J12: 0 | K12: 0 | L12: 1 | M12: 0 | N12: =SUM(B12:M12) -> 5
A13: Mesentery Length from Bladder Neck (≤7") | B13: 0 | C13: 0 | D13: 0 | E13: 0 | F13: 0 | G13: 0 | H13: 0 | I13: 0 | J13: 0 | K13: 0 | L13: 0 | M13: 0 | N13: =SUM(B13:M13) -> 0
A14: TOTAL DEFECTS | B14: =SUM(B4:B13) -> 19 | C14: =SUM(C4:C13) -> 43 | D14: =SUM(D4:D13) -> 57 | E14: =SUM(E4:E13) -> 37 | F14: =SUM(F4:F13) -> 26 | G14: =SUM(G4:G13) -> 33 | H14: =SUM(H4:H13) -> 21 | I14: =SUM(I4:I13) -> 20 | ... M14: =SUM(M4:M13) -> 3 | N14: =SUM(B14:M14) -> 307
A15: Units Received | B15: 150 | C15: 181 | D15: 210 | E15: 221 | F15: 200 | G15: 200 | H15: 227 | I15: 180 | J15: 200 | K15: 170 | L15: 270 | M15: 100 | N15: =SUM(B15:M15) -> 2309
A16: Units Scrapped | B16: 19 | C16: 43 | D16: 57 | E16: 37 | F16: 26 | G16: 33 | H16: 21 | I16: 20 | J16: 10 | K16: 24 | L16: 14 | M16: 3 | N16: =SUM(B16:M16) -> 307
A17: Rejection % | B17: =IFERROR(B16/B15,0) -> 0.12666667 | C17: =IFERROR(C16/C15,0) -> 0.23756906 | D17: =IFERROR(D16/D15,0) -> 0.27142857 | E17: =IFERROR(E16/E15,0) -> 0.16742081 | F17: =IFERROR(F16/F15,0) -> 0.13 | G17: =IFERROR(G16/G15,0) -> 0.165 | H17: =IFERROR(H16/H15,0) -> 0.092511013 | I17: =IFERROR(I16/I15,0) -> 0.11111111 | ... N17: =IFERROR(N16/N15,0) -> 0.13295799

Sheet Defect Pivot 666540-M
A1: 666540 DV Tech Pelvic Block (Male) — Martins
A3: Defect (canonical) | B3: 2026-03-02 | C3: 2026-03-16 | D3: 2026-03-23 | E3: Total
A4: Critical Mesentery Hole/Laceration (>0.5") | B4: 21 | C4: 4 | D4: 4 | E4: =SUM(B4:D4) -> 29
A5: Non-Critical Mesentery Hole (>1.5") | B5: 0 | C5: 0 | D5: 0 | E5: =SUM(B5:D5) -> 0
A6: Blood Clot | B6: 3 | C6: 1 | D6: 0 | E6: =SUM(B6:D6) -> 4
A7: Bladder Length Oversize (>5.5") | B7: 0 | C7: 0 | D7: 0 | E7: =SUM(B7:D7) -> 0
A8: Bladder Length Undersize | B8: 5 | C8: 0 | D8: 0 | E8: =SUM(B8:D8) -> 5
A9: Urethra Laceration (exposing internal) | B9: 12 | C9: 2 | D9: 1 | E9: =SUM(B9:D9) -> 15
A10: Bladder Laceration (exposing internal) | B10: 3 | C10: 0 | D10: 0 | E10: =SUM(B10:D10) -> 3
A11: Exposed Ureters | B11: 0 | C11: 0 | D11: 0 | E11: =SUM(B11:D11) -> 0
A12: Spoilage | B12: 0 | C12: 0 | D12: 0 | E12: =SUM(B12:D12) -> 0
A13: Mesentery Length from Bladder Neck (≤7") | B13: 0 | C13: 0 | D13: 0 | E13: =SUM(B13:D13) -> 0
A14: TOTAL DEFECTS | B14: =SUM(B4:B13) -> 44 | C14: =SUM(C4:C13) -> 7 | D14: =SUM(D4:D13) -> 5 | E14: =SUM(B14:D14) -> 56
A15: Units Received | B15: 143 | C15: 20 | D15: 9 | E15: =SUM(B15:D15) -> 172
A16: Units Scrapped | B16: 43 | C16: 7 | D16: 5 | E16: =SUM(B16:D16) -> 55
A17: Rejection % | B17: =IFERROR(B16/B15,0) -> 0.3006993 | C17: =IFERROR(C16/C15,0) -> 0.35 | D17: =IFERROR(D16/D15,0) -> 0.55555556 | E17: =IFERROR(E16/E15,0) -> 0.31976744

Sheet Defect Pivot 666518-F
A1: 666518 DV Tech Pelvic Block (Female) — Parks
A3: Defect (canonical) | B3: 2026-03-09 | C3: 2026-03-23 | D3: 2026-03-30 | E3: 2026-04-20 | F3: 2026-05-04 | G3: 2026-05-11 | H3: Total
A4: Critical Mesentery Hole/Laceration (>0.5") | B4: 1 | C4: 4 | D4: 2 | E4: 22 | F4: 2 | G4: 187 | H4: =SUM(B4:G4) -> 218
A5: Non-Critical Mesentery Hole (>1.5") | B5: 0 | C5: 0 | D5: 0 | E5: 0 | F5: 0 | G5: 0 | H5: =SUM(B5:G5) -> 0
A6: Blood Clot | B6: 1 | C6: 0 | D6: 0 | E6: 0 | F6: 0 | G6: 0 | H6: =SUM(B6:G6) -> 1
A7: Bladder Length Oversize (>5.5") | B7: 0 | C7: 0 | D7: 1 | E7: 4 | F7: 0 | G7: 0 | H7: =SUM(B7:G7) -> 5
A8: Bladder Length Undersize | B8: 0 | C8: 0 | D8: 0 | E8: 0 | F8: 0 | G8: 0 | H8: =SUM(B8:G8) -> 0
A9: Urethra Laceration (exposing internal) | B9: 0 | C9: 2 | D9: 2 | E9: 3 | F9: 0 | G9: 2 | H9: =SUM(B9:G9) -> 9
A10: Bladder Laceration (exposing internal) | B10: 0 | C10: 0 | D10: 0 | E10: 0 | F10: 0 | G10: 0 | H10: =SUM(B10:G10) -> 0
A11: Exposed Ureters | B11: 0 | C11: 0 | D11: 0 | E11: 0 | F11: 0 | G11: 0 | H11: =SUM(B11:G11) -> 0
A12: Spoilage | B12: 0 | C12: 0 | D12: 0 | E12: 0 | F12: 0 | G12: 0 | H12: =SUM(B12:G12) -> 0
A13: Mesentery Length from Bladder Neck (≤7") | B13: 0 | C13: 0 | D13: 2 | E13: 10 | F13: 2 | G13: 6 | H13: =SUM(B13:G13) -> 20
A14: TOTAL DEFECTS | B14: =SUM(B4:B13) -> 2 | C14: =SUM(C4:C13) -> 6 | D14: =SUM(D4:D13) -> 7 | E14: =SUM(E4:E13) -> 39 | F14: =SUM(F4:F13) -> 4 | G14: =SUM(G4:G13) -> 195 | H14: =SUM(B14:G14) -> 253
A15: Units Received | B15: 15 | C15: 22 | D15: 15 | E15: 118 | F15: 30 | G15: 220 | H15: =SUM(B15:G15) -> 420
A16: Units Scrapped | B16: 2 | C16: 6 | D16: 7 | E16: 39 | F16: 4 | G16: 195 | H16: =SUM(B16:G16) -> 253
A17: Rejection % | B17: =IFERROR(B16/B15,0) -> 0.13333333 | C17: =IFERROR(C16/C15,0) -> 0.27272727 | D17: =IFERROR(D16/D15,0) -> 0.46666667 | E17: =IFERROR(E16/E15,0) -> 0.33050847 | F17: =IFERROR(F16/F15,0) -> 0.13333333 | G17: =IFERROR(G16/G15,0) -> 0.88636364 | H17: =IFERROR(H16/H15,0) -> 0.60238095

Sheet Supplier Comparison
A1: Supplier Comparison — Martins vs Parks
A3: Metric | B3: Martins | C3: Parks
A4: Receipt events | B4: 15 | C4: 6
A5: Lots inspected | B5: 26 | C5: 11
A6: Units received | B6: 2481 | C6: 420
A7: Units accepted | B7: 2119 | C7: 167
