Workbook

Sheet Slaughterhouse IQC
A1: SH IQC Inspections — Slaughterhouse-Floor Incoming Quality
A2: Post-harvest, pre-freeze inspections at the slaughterhouse — all tissue types and parts. 59 part-inspections across 39 visit-days · 3 slaughterhouses (Martins, Parks, Nahunta) · Apr 13 – Aug 19, 2026. One row per part per harvest date.
A4: INSPECTION LOG
A5: Harvest Date | B5: Slaughterhouse | C5: Inspector | D5: SH Tech | E5: Tissue Type | F5: Part # | G5: Description | H5: Lot | I5: # Inspected | J5: # Pass | K5: # Fail | L5: First-Pass Yield | M5: Scrap reason / notes
A6: 2026-04-13 | B6: Martins | C6: Toni | D6: Jesus | E6: Pelvic | F6: 666506 | G6: Non-intact | H6: 5502378430 | I6: 3 | J6: 3 | K6: 0 | L6: =IFERROR(J6/I6,0) -> 1 | M6: 3 labels used for thin area in bowel (ran out of labels)
A7: 2026-04-13 | B7: Martins | C7: Toni | D7: Jesus | E7: Pelvic | F7: 666541 | G7: Intact | H7: 5502378434 | I7: 48 | J7: 47 | K7: 1 | L7: =IFERROR(J7/I7,0) -> 0.97916667 | M7: 1 hole in bowel; 1 label marked for thin area in bowel
A8: 2026-04-15 | B8: Martins | C8: Toni | D8: Jesus | E8: Pelvic | F8: 666506 | G8: Non-intact | H8: 5502378430 | I8: 4 | J8: 4 | K8: 0 | L8: =IFERROR(J8/I8,0) -> 1
A9: 2026-04-15 | B9: Martins | C9: Toni | D9: Jesus | E9: Pelvic | F9: 666541 | G9: Intact | H9: 5502378434 | I9: 17 | J9: 13 | K9: 4 | L9: =IFERROR(J9/I9,0) -> 0.76470588 | M9: 2 blood clots (moved to non-intact); 2 scrapped for cut in urethra
A10: 2026-04-20 | B10: Martins | C10: Toni | D10: Jesus | E10: Pelvic | F10: 666506 | G10: Non-intact | H10: 5502391858 | I10: 31 | J10: 29 | K10: 2 | L10: =IFERROR(J10/I10,0) -> 0.93548387 | M10: 2 damaged after cleaning
A11: 2026-04-20 | B11: Martins | C11: Toni | D11: Jesus | E11: Pelvic | F11: 666541 | G11: Intact | H11: 5502391862 | I11: 0 | J11: 0 | K11: 0 | L11: =IFERROR(J11/I11,0) -> 0 | M11: Ran out of time (bagging set for later; SH tech start time changed to 8:00–4:30 PM)
A12: 2026-04-22 | B12: Martins | C12: Toni | D12: Jesus | E12: Pelvic | F12: 666506 | G12: Non-intact | H12: 5502391858 | I12: 21 | J12: 19 | K12: 2 | L12: =IFERROR(J12/I12,0) -> 0.9047619 | M12: 2 damaged bowel
A13: 2026-04-22 | B13: Martins | C13: Toni | D13: Jesus | E13: Pelvic | F13: 666541 | G13: Intact | H13: 5502391862 | I13: 57 | J13: 56 | K13: 1 | L13: =IFERROR(J13/I13,0) -> 0.98245614 | M13: 1 damaged bowel
A14: 2026-05-04 | B14: Martins | C14: Toni | D14: Jesus | E14: Pelvic | F14: 666506 | G14: Non-intact | H14: 5502404924 | I14: 16 | J14: 13 | K14: 3 | L14: =IFERROR(J14/I14,0) -> 0.8125 | M14: 3 damaged urethra
A15: 2026-05-04 | B15: Martins | C15: Toni | D15: Jesus | E15: Pelvic | F15: 666541 | G15: Intact | H15: 5502404928 | I15: 37 | J15: 36 | K15: 1 | L15: =IFERROR(J15/I15,0) -> 0.97297297 | M15: 1 damaged urethra
A16: 2026-05-06 | B16: Martins | C16: Toni | D16: Jesus | E16: Pelvic | F16: 666506 | G16: Non-intact | H16: 5502404924 | I16: 29 | J16: 28 | K16: 1 | L16: =IFERROR(J16/I16,0) -> 0.96551724 | M16: 1 small bladder
A17: 2026-05-06 | B17: Martins | C17: Toni | D17: Jesus | E17: Pelvic | F17: 666541 | G17: Intact | H17: 5502404928 | I17: 25 | J17: 22 | K17: 3 | L17: =IFERROR(J17/I17,0) -> 0.88 | M17: 3 damaged urethra
A18: 2026-05-18 | B18: Martins | C18: Toni | D18: Jesus | E18: Pelvic | F18: 666506 | G18: Non-intact | H18: 5502421188 | I18: 43 | J18: 42 | K18: 1 | L18: =IFERROR(J18/I18,0) -> 0.97674419 | M18: 1 deformed ligaments clumped together
A19: 2026-05-18 | B19: Martins | C19: Toni | D19: Jesus | E19: Pelvic | F19: 666541 | G19: Intact | H19: 5502421192 | I19: 62 | J19: 58 | K19: 4 | L19: =IFERROR(J19/I19,0) -> 0.93548387 | M19: 3 cut urethra; 1 short block
A20: 2026-05-21 | B20: Martins | C20: Toni | D20: Jesus | E20: Pelvic | F20: 666506 | G20: Non-intact | H20: 5502421188 | I20: 30 | J20: 29 | K20: 1 | L20: =IFERROR(J20/I20,0) -> 0.96666667 | M20: 1 damaged membrane and ureter
... A23: 2026-05-28 | B23: Parks Family Meats | C23: Rasmin | D23: Natalie | E23: Pelvic | F23: 666518 | G23: Intact (SM) | H23: (no batch data) | I23: 16 | J23: 11 | K23: 5 | L23: =IFERROR(J23/I23,0) -> 0.6875 | M23: 4 mesentery length too short in critical zone; 1 bladder damage (internals exposed)
A24: 2026-06-01 | B24: Martins | C24: Toni | D24: Jesus | E24: Pelvic | F24: 666506 | G24: Non-intact | H24: 5502428782 | I24: 7 | J24: 7 | K24: 0 | L24: =IFERROR(J24/I24,0) -> 1
A25: 2026-06-01 | B25: Martins | C25: Toni | D25: Jesus | E25: Pelvic | F25: 666541 | G25: Intact | H25: 5502428786 | I25: 9 | J25: 9 | K25: 0 | L25: =IFERROR(J25/I25,0) -> 1
A26: 2026-06-02 | B26: Parks Family Meats | C26: Rasmin | D26: Natalie | E26: Pelvic | F26: 666518 | G26: Intact (SM) | H26: (no batch data) | I26: 7 | J26: 7 | K26: 0 | L26: =IFERROR(J26/I26,0) -> 1
A27: 2026-06-03 | B27: Martins | C27: Toni | D27: Jesus | E27: Pelvic | F27: 666506 | G27: Non-intact | H27: 5502428782 | I27: 29 | J27: 29 | K27: 0 | L27: =IFERROR(J27/I27,0) -> 1
A28: 2026-06-03 | B28: Martins | C28: Toni | D28: Jesus | E28: Pelvic | F28: 666541 | G28: Intact | H28: 5502428786 | I28: 45 | J28: 43 | K28: 2 | L28: =IFERROR(J28/I28,0) -> 0.95555556 | M28: 2 scrapped urethra
A29: 2026-06-08 | B29: Martins | C29: Toni | D29: Jesus | E29: Pelvic | F29: 666506 | G29: Non-intact | H29: 5502428782 | I29: 13 | J29: 12 | K29: 1 | L29: =IFERROR(J29/I29,0) -> 0.92307692 | M29: 1 short block
A30: 2026-06-08 | B30: Martins | C30: Toni | D30: Jesus | E30: Pelvic | F30: 666541 | G30: Intact | H30: 5502428786 | I30: 17 | J30: 16 | K30: 1 | L30: =IFERROR(J30/I30,0) -> 0.94117647 | M30: 1 cut urethra
A31: 2026-06-15 | B31: Martins | C31: Toni | D31: Jesus | E31: Pelvic | F31: 666541 | G31: Intact | H31: 5502462845 | I31: 31 | J31: 30 | K31: 1 | L31: =IFERROR(J31/I31,0) -> 0.96774194 | M31: 1 damaged bowel (source had two intact tally lines: 13/12/1 + 18/18/0, combined here)
A32: 2026-06-16 | B32: Parks Family Meats | C32: Rasmin | D32: Natalie | E32: Pelvic | F32: 666518 | G32: Intact (SM) | H32: (no batch data) | I32: 16 | J32: 14 | K32: 2 | L32: =IFERROR(J32/I32,0) -> 0.875 | M32: 1 bladder hole; 1 ureter damage (many blocks failed upstream from miscuts during removal — see notes)
A33: 2026-06-22 | B33: Parks Family Meats | C33: Rasmin | D33: Natalie | E33: Pelvic | F33: 666518 | G33: Intact (SM) | H33: (no batch data) | I33: 36 | J33: 31 | K33: 5 | L33: =IFERROR(J33/I33,0) -> 0.86111111 | M33: 1 bladder hole; 2 critical-area lacerations; 2 short blocks
A34: 2026-06-24 | B34: Martins | C34: Toni | D34: Jesus | E34: Pelvic | F34: 666541 | G34: Intact | H34: 5502462845 | I34: 34 | J34: 30 | K34: 4 | L34: =IFERROR(J34/I34,0) -> 0.88235294 | M34: 1 damaged bladder; 3 damaged membrane
A35: 2026-06-25 | B35: Parks Family Meats | C35: Rasmin | D35: Natalie | E35: Pelvic | F35: 666518 | G35: Intact (SM) | H35: (no batch data) | I35: 19 | J35: 16 | K35: 3 | L35: =IFERROR(J35/I35,0) -> 0.84210526 | M35: 1 bladder hole; 1 ureter laceration; 1 short block
A36: 2026-06-29 | B36: Martins | C36: Toni | D36: Jesus | E36: Pelvic | F36: 666506 | G36: Non-intact | H36: 5502471457 | I36: 4 | J36: 4 | K36: 0 | L36: =IFERROR(J36/I36,0) -> 1
A37: 2026-06-29 | B37: Parks Family Meats | C37: Rasmin | D37: Natalie | E37: Pelvic | F37: 666518 | G37: Intact (SM) | H37: (no batch data) | I37: 50 | J37: 38 | K37: 12 | L37: =IFERROR(J37/I37,0) -> 0.76 | M37: 2 damaged during bowel cleaning (bowel blockage burst); 2 short blocks; 1 critical-area laceration; 7 urethra/bladder lacerations (cuts near template edge)
A38: 2026-06-29 | B38: Martins | C38: Toni | D38: Jesus | E38: Pelvic | F38: 666541 | G38: Intact | H38: 5502471460 | I38: 16 | J38: 16 | K38: 0 | L38: =IFERROR(J38/I38,0) -> 1
A39: 2026-07-06 | B39: Martins | C39: Toni | D39: Jesus | E39: Pelvic | F39: 666506 | G39: Non-intact | H39: 5502471457 | I39: 10 | J39: 9 | K39: 1 | L39: =IFERROR(J39/I39,0) -> 0.9 | M39: 1 membrane damage larger than 1.5"
A40: 2026-07-06 | B40: Martins | C40: Toni | D40: Jesus | E40: Pelvic | F40: 666541 | G40: Intact | H40: 5502471460 | I40: 12 | J40: 11 | K40: 1 | L40: =IFERROR(J40/I40,0) -> 0.91666667 | M40: 1 damaged urethra
A41: 2026-07-13 | B41: Martins | C41: Toni | D41: Jesus | E41: Pelvic | F41: 666506 | G41: Non-intact | H41: 5502495104 | I41: 14 | J41: 14 | K41: 0 | L41: =IFERROR(J41/I41,0) -> 1
A42: 2026-07-13 | B42: Parks Family Meats | C42: Rasmin | D42: Natalie | E42: Pelvic | F42: 666518 | G42: Intact (SM) | H42: (no batch data) | I42: 34 | J42: 29 | K42: 5 | L42: =IFERROR(J42/I42,0) -> 0.85294118 | M42: 2 damaged during bowel cleaning (bowel blockage burst); 3 short blocks (smaller pigs)
A43: 2026-07-13 | B43: Martins | C43: Toni | D43: Jesus | E43: Pelvic | F43: 666541 | G43: Intact | H43: 5502495107 | I43: 38 | J43: 36 | K43: 2 | L43: =IFERROR(J43/I43,0) -> 0.94736842 | M43: 1 damaged membrane; 1 damaged bladder
...

Sheet Quality Dashboard
A1: Quality Dashboard — by Tissue Type, Part & Slaughterhouse
A2: First-pass yield across all SH-floor incoming inspections (pre-freeze), Apr–Aug 2026. Live from the Inspection Log on the Slaughterhouse IQC tab. FPY = Pass / Inspected; Scrap % = Fail / Inspected.
A4: BY TISSUE TYPE
A5: Tissue Type | B5: # Inspected | C5: # Pass | D5: # Fail | E5: First-Pass Yield | F5: Scrap %
A6: Pelvic | B6: =SUMIF('Slaughterhouse IQC'!$E$6:$E$64,"Pelvic",'Slaughterhouse IQC'!$I$6:$I$64) -> 1392 | C6: =SUMIF('Slaughterhouse IQC'!$E$6:$E$64,"Pelvic",'Slaughterhouse IQC'!$J$6:$J$64) -> 1288 | D6: =SUMIF('Slaughterhouse IQC'!$E$6:$E$64,"Pelvic",'Slaughterhouse IQC'!$K$6:$K$64) -> 104 | E6: =IFERROR(C6/B6,0) -> 0.92528736 | F6: =IFERROR(D6/B6,0) -> 0.074712644
A7: Thoracic | B7: =SUMIF('Slaughterhouse IQC'!$E$6:$E$64,"Thoracic",'Slaughterhouse IQC'!$I$6:$I$64) -> 76 | C7: =SUMIF('Slaughterhouse IQC'!$E$6:$E$64,"Thoracic",'Slaughterhouse IQC'!$J$6:$J$64) -> 14 | D7: =SUMIF('Slaughterhouse IQC'!$E$6:$E$64,"Thoracic",'Slaughterhouse IQC'!$K$6:$K$64) -> 62 | E7: =IFERROR(C7/B7,0) -> 0.18421053 | F7: =IFERROR(D7/B7,0) -> 0.81578947
A8: GRAND TOTAL | B8: =SUM(B6:B7) -> 1468 | C8: =SUM(C6:C7) -> 1302 | D8: =SUM(D6:D7) -> 166 | E8: =IFERROR(C8/B8,0) -> 0.88692098 | F8: =IFERROR(D8/B8,0) -> 0.11307902
A10: BY PART
A11: Part # | B11: Description | C11: Slaughterhouse | D11: # Inspected | E11: # Pass | F11: # Fail | G11: First-Pass Yield | H11: Scrap % | I11: Date span
A12: 666541 | B12: Pelvic block, intact | C12: Martins / Parks / Nahunta | D12: =SUMIF('Slaughterhouse IQC'!$F$6:$F$64,"666541",'Slaughterhouse IQC'!$I$6:$I$64) -> 813 | E12: =SUMIF('Slaughterhouse IQC'!$F$6:$F$64,"666541",'Slaughterhouse IQC'!$J$6:$J$64) -> 762 | F12: =SUMIF('Slaughterhouse IQC'!$F$6:$F$64,"666541",'Slaughterhouse IQC'!$K$6:$K$64) -> 51 | G12: =IFERROR(E12/D12,0) -> 0.93726937 | H12: =IFERROR(F12/D12,0) -> 0.062730627 | I12: 4/13 – 8/17
A13: 666506 | B13: Pelvic block, non-intact | C13: Martins | D13: =SUMIF('Slaughterhouse IQC'!$F$6:$F$64,"666506",'Slaughterhouse IQC'!$I$6:$I$64) -> 322 | E13: =SUMIF('Slaughterhouse IQC'!$F$6:$F$64,"666506",'Slaughterhouse IQC'!$J$6:$J$64) -> 309 | F13: =SUMIF('Slaughterhouse IQC'!$F$6:$F$64,"666506",'Slaughterhouse IQC'!$K$6:$K$64) -> 13 | G13: =IFERROR(E13/D13,0) -> 0.95962733 | H13: =IFERROR(F13/D13,0) -> 0.040372671 | I13: 4/13 – 8/17
A14: 666518 | B14: Pelvic block, intact (SM) | C14: Parks | D14: =SUMIF('Slaughterhouse IQC'!$F$6:$F$64,"666518",'Slaughterhouse IQC'!$I$6:$I$64) -> 257 | E14: =SUMIF('Slaughterhouse IQC'!$F$6:$F$64,"666518",'Slaughterhouse IQC'!$J$6:$J$64) -> 217 | F14: =SUMIF('Slaughterhouse IQC'!$F$6:$F$64,"666518",'Slaughterhouse IQC'!$K$6:$K$64) -> 40 | G14: =IFERROR(E14/D14,0) -> 0.84435798 | H14: =IFERROR(F14/D14,0) -> 0.15564202 | I14: 5/28 – 7/30
A15: 666521 | B15: Thoracic (lung / heart) | C15: Nahunta | D15: =SUMIF('Slaughterhouse IQC'!$F$6:$F$64,"666521",'Slaughterhouse IQC'!$I$6:$I$64) -> 76 | E15: =SUMIF('Slaughterhouse IQC'!$F$6:$F$64,"666521",'Slaughterhouse IQC'!$J$6:$J$64) -> 14 | F15: =SUMIF('Slaughterhouse IQC'!$F$6:$F$64,"666521",'Slaughterhouse IQC'!$K$6:$K$64) -> 62 | G15: =IFERROR(E15/D15,0) -> 0.18421053 | H15: =IFERROR(F15/D15,0) -> 0.81578947 | I15: 7/29 – 8/19
A17: BY SLAUGHTERHOUSE
A18: Slaughterhouse | B18: Tissue / parts | C18: # Inspected | D18: # Pass | E18: # Fail | F18: First-Pass Yield | G18: Scrap %
A19: Martins | B19: Pelvic 541 / 506 | C19: =SUMIF('Slaughterhouse IQC'!$B$6:$B$64,"Martins",'Slaughterhouse IQC'!$I$6:$I$64) -> 1088 | D19: =SUMIF('Slaughterhouse IQC'!$B$6:$B$64,"Martins",'Slaughterhouse IQC'!$J$6:$J$64) -> 1037 | E19: =SUMIF('Slaughterhouse IQC'!$B$6:$B$64,"Martins",'Slaughterhouse IQC'!$K$6:$K$64) -> 51 | F19: =IFERROR(D19/C19,0) -> 0.953125 | G19: =IFERROR(E19/C19,0) -> 0.046875
A20: Parks Family Meats | B20: Pelvic 518 → 541 | C20: =SUMIF('Slaughterhouse IQC'!$B$6:$B$64,"Parks Family Meats",'Slaughterhouse IQC'!$I$6:$I$64) -> 290 | D20: =SUMIF('Slaughterhouse IQC'!$B$6:$B$64,"Parks Family Meats",'Slaughterhouse IQC'!$J$6:$J$64) -> 249 | E20: =SUMIF('Slaughterhouse IQC'!$B$6:$B$64,"Parks Family Meats",'Slaughterhouse IQC'!$K$6:$K$64) -> 41 | F20: =IFERROR(D20/C20,0) -> 0.85862069 | G20: =IFERROR(E20/C20,0) -> 0.14137931
A21: Nahunta | B21: Thoracic 521 + pelvic 541 | C21: =SUMIF('Slaughterhouse IQC'!$B$6:$B$64,"Nahunta",'Slaughterhouse IQC'!$I$6:$I$64) -> 90 | D21: =SUMIF('Slaughterhouse IQC'!$B$6:$B$64,"Nahunta",'Slaughterhouse IQC'!$J$6:$J$64) -> 16 | E21: =SUMIF('Slaughterhouse IQC'!$B$6:$B$64,"Nahunta",'Slaughterhouse IQC'!$K$6:$K$64) -> 74 | F21: =IFERROR(D21/C21,0) -> 0.17777778 | G21: =IFERROR(E21/C21,0) -> 0.82222222
A23: TISSUE / PART READ
A24: 666541 — Pelvic, intact · ~94% FPY (Martins / Parks / Nahunta)
A25: Performance-goal part. Steady ~95% at Martins; Parks now runs 666541 too (from 08/10). A provisional Nahunta 8/12 pelvic line (13/1/12) drags the average — see note 25. Rejects: urethra/bladder & membrane damage, short blocks.
A26: 666506 — Pelvic, non-intact · ~96% FPY (Martins)
A27: Tighter spec, best yield of the group. Rejects: membrane/urethra damage, a couple early blood clots.
A28: 666518 — Pelvic, intact SM · ~84% FPY (Parks)
A29: Batch-less Parks pelvic; Parks transitioned to 666541 by mid-August. Through 07/30 ~84%, driven by short blocks and mesentery/ureter damage. See the Parks deep-dive deck.
A30: 666521 — Thoracic · ~18% FPY (Nahunta) — WORSENING
A31: Thoracic at Nahunta, declining: 32% (7/29) → 0% (8/5) → 15% (8/12) → 21% (8/19). Right-lung perimeter and now heart lacerations, harvesting-side. Escalated with Ricardo; heart lacerations (inspector-side) now the main gap.

Sheet Monthly Breakdown
A1: Monthly Breakdown — Inspections by Tissue × Slaughterhouse
A2: Month-by-month view of every tissue-type / slaughterhouse / part combination: volumes, first-pass yield, and the issues found (scrap reasons normalized into standard defect categories). Apr–Aug 2026. Volume rows are live formulas over the Inspection Log; defect counts are analyst-categorized from the scrap notes (see notes at bottom).
A4: OVERVIEW — FIRST-PASS YIELD BY MONTH
A5: Tissue @ SH · Part | B5: April | C5: May | D5: June | E5: July | F5: August | G5: Total
A6: Pelvic @ Martins · 666541 | B6: =IF(SUMPRODUCT((LEFT('Slaughterhouse IQC'!$A$6:$A$64,7)="2026-04")*('Slaughterhouse IQC'!$B$6:$B$64="Martins")*('Slaughterhouse IQC'!$F$6:$F$64="666541")*'Slaughterhouse IQC'!$I$6:$I$64)=0,"",SUMPRODUCT((LEFT('Slaughterhouse IQC'!$A$6:$A$64,7)="2026-04")*('Slaughterhouse IQC'!$B$6:$B$64="Martins")*('Slaughterhouse IQC'!$F$6:$F$64="666541")*'Slaughterhouse IQC'!$J$6:$J$64)/SUMPRODUCT((LEFT('Slaughterhouse IQC'!$A$6:$A$64,7)="2026-04")*('Slaughterhouse IQC'!$B$6:$B$64="Martins")*('Slaughterhouse IQC'!$F$6:$F$64="666541")*'Slaughterhouse IQC'!$I$6:$I$64)) -> 0.95081967 | C6: =IF(SUMPRODUCT((LEFT('Slaughterhouse IQC'!$A$6:$A$64,7)="2026-05")*('Slaughterhouse IQC'!$B$6:$B$64="Martins")*('Slaughterhouse IQC'!$F$6:$F$64="666541")*'Slaughterhouse IQC'!$I$6:$I$64)=0,"",SUMPRODUCT((LEFT('Slaughterhouse IQC'!$A$6:$A$64,7)="2026-05")*('Slaughterhouse IQC'!$B$6:$B$64="Martins")*('Slaughterhouse IQC'!$F$6:$F$64="666541")*'Slaughterhouse IQC'!$J$6:$J$64)/SUMPRODUCT((LEFT('Slaughterhouse IQC'!$A$6:$A$64,7)="2026-05")*('Slaughterhouse IQC'!$B$6:$B$64="Martins")*('Slaughterhouse IQC'!$F$6:$F$64="666541")*'Slaughterhouse IQC'!$I$6:$I$64)) -> 0.93298969 | D6: =IF(SUMPRODUCT((LEFT('Slaughterhouse IQC'!$A$6:$A$64,7)="2026-06")*('Slaughterhouse IQC'!$B$6:$B$64="Martins")*('Slaughterhouse IQC'!$F$6:$F$64="666541")*'Slaughterhouse IQC'!$I$6:$I$64)=0,"",SUMPRODUCT((LEFT('Slaughterhouse IQC'!$A$6:$A$64,7)="2026-06")*('Slaughterhouse IQC'!$B$6:$B$64="Martins")*('Slaughterhouse IQC'!$F$6:$F$64="666541")*'Slaughterhouse IQC'!$J$6:$J$64)/SUMPRODUCT((LEFT('Slaughterhouse IQC'!$A$6:$A$64,7)="2026-06")*('Slaughterhouse IQC'!$B$6:$B$64="Martins")*('Slaughterhouse IQC'!$F$6:$F$64="666541")*'Slaughterhouse IQC'!$I$6:$I$64)) -> 0.94736842 | E6: =IF(SUMPRODUCT((LEFT('Slaughterhouse IQC'!$A$6:$A$64,7)="2026-07")*('Slaughterhouse IQC'!$B$6:$B$64="Martins")*('Slaughterhouse IQC'!$F$6:$F$64="666541")*'Slaughterhouse IQC'!$I$6:$I$64)=0,"",SUMPRODUCT((LEFT('Slaughterhouse IQC'!$A$6:$A$64,7)="2026-07")*('Slaughterhouse IQC'!$B$6:$B$64="Martins")*('Slaughterhouse IQC'!$F$6:$F$64="666541")*'Slaughterhouse IQC'!$J$6:$J$64)/SUMPRODUCT((LEFT('Slaughterhouse IQC'!$A$6:$A$64,7)="2026-07")*('Slaughterhouse IQC'!$B$6:$B$64="Martins")*('Slaughterhouse IQC'!$F$6:$F$64="666541")*'Slaughterhouse IQC'!$I$6:$I$64)) -> 0.96273292 | F6: =IF(SUMPRODUCT((LEFT('Slaughterhouse IQC'!$A$6:$A$64,7)="2026-08")*('Slaughterhouse IQC'!$B$6:$B$64="Martins")*('Slaughterhouse IQC'!$F$6:$F$64="666541")*'Slaughterhouse IQC'!$I$6:$I$64)=0,"",SUMPRODUCT((LEFT('Slaughterhouse IQC'!$A$6:$A$64,7)="2026-08")*('Slaughterhouse IQC'!$B$6:$B$64="Martins")*('Slaughterhouse IQC'!$F$6:$F$64="666541")*'Slaughterhouse IQC'!$J$6:$J$64)/SUMPRODUCT((LEFT('Slaughterhouse IQC'!$A$6:$A$64,7)="2026-08")*('Slaughterhouse IQC'!$B$6:$B$64="Martins")*('Slaughterhouse IQC'!$F$6:$F$64="666541")*'Slaughterhouse IQC'!$I$6:$I$64)) -> 0.96350365 | G6: =IF(SUMPRODUCT(('Slaughterhouse IQC'!$B$6:$B$64="Martins")*('Slaughterhouse IQC'!$F$6:$F$64="666541")*'Slaughterhouse IQC'!$I$6:$I$64)=0,"",SUMPRODUCT(('Slaughterhouse IQC'!$B$6:$B$64="Martins")*('Slaughterhouse IQC'!$F$6:$F$64="666541")*'Slaughterhouse IQC'!$J$6:$J$64)/SUMPRODUCT(('Slaughterhouse IQC'!$B$6:$B$64="Martins")*('Slaughterhouse IQC'!$F$6:$F$64="666541")*'Slaughterhouse IQC'!$I$6:$I$64)) -> 0.95039164
A7: Pelvic @ Martins · 666506 | B7: =IF(SUMPRODUCT((LEFT('Slaughterhouse IQC'!$A$6:$A$64,7)="2026-04")*('Slaughterhouse IQC'!$B$6:$B$64="Martins")*('Slaughterhouse IQC'!$F$6:$F$64="666506")*'Slaughterhouse IQC'!$I$6:$I$64)=0,"",SUMPRODUCT((LEFT('Slaughterhouse IQC'!$A$6:$A$64,7)="2026-04")*('Slaughterhouse IQC'!$B$6:$B$64="Martins")*('Slaughterhouse IQC'!$F$6:$F$64="666506")*'Slaughterhouse IQC'!$J$6:$J$64)/SUMPRODUCT((LEFT('Slaughterhouse IQC'!$A$6:$A$64,7)="2026-04")*('Slaughterhouse IQC'!$B$6:$B$64="Martins")*('Slaughterhouse IQC'!$F$6:$F$64="666506")*'Slaughterhouse IQC'!$I$6:$I$64)) -> 0.93220339 | C7: =IF(SUMPRODUCT((LEFT('Slaughterhouse IQC'!$A$6:$A$64,7)="2026-05")*('Slaughterhouse IQC'!$B$6:$B$64="Martins")*('Slaughterhouse IQC'!$F$6:$F$64="666506")*'Slaughterhouse IQC'!$I$6:$I$64)=0,"",SUMPRODUCT((LEFT('Slaughterhouse IQC'!$A$6:$A$64,7)="2026-05")*('Slaughterhouse IQC'!$B$6:$B$64="Martins")*('Slaughterhouse IQC'!$F$6:$F$64="666506")*'Slaughterhouse IQC'!$J$6:$J$64)/SUMPRODUCT((LEFT('Slaughterhouse IQC'!$A$6:$A$64,7)="2026-05")*('Slaughterhouse IQC'!$B$6:$B$64="Martins")*('Slaughterhouse IQC'!$F$6:$F$64="666506")*'Slaughterhouse IQC'!$I$6:$I$64)) -> 0.94915254 | D7: =IF(SUMPRODUCT((LEFT('Slaughterhouse IQC'!$A$6:$A$64,7)="2026-06")*('Slaughterhouse IQC'!$B$6:$B$64="Martins")*('Slaughterhouse IQC'!$F$6:$F$64="666506")*'Slaughterhouse IQC'!$I$6:$I$64)=0,"",SUMPRODUCT((LEFT('Slaughterhouse IQC'!$A$6:$A$64,7)="2026-06")*('Slaughterhouse IQC'!$B$6:$B$64="Martins")*('Slaughterhouse IQC'!$F$6:$F$64="666506")*'Slaughterhouse IQC'!$J$6:$J$64)/SUMPRODUCT((LEFT('Slaughterhouse IQC'!$A$6:$A$64,7)="2026-06")*('Slaughterhouse IQC'!$B$6:$B$64="Martins")*('Slaughterhouse IQC'!$F$6:$F$64="666506")*'Slaughterhouse IQC'!$I$6:$I$64)) -> 0.98113208 | E7: =IF(SUMPRODUCT((LEFT('Slaughterhouse IQC'!$A$6:$A$64,7)="2026-07")*('Slaughterhouse IQC'!$B$6:$B$64="Martins")*('Slaughterhouse IQC'!$F$6:$F$64="666506")*'Slaughterhouse IQC'!$I$6:$I$64)=0,"",SUMPRODUCT((LEFT('Slaughterhouse IQC'!$A$6:$A$64,7)="2026-07")*('Slaughterhouse IQC'!$B$6:$B$64="Martins")*('Slaughterhouse IQC'!$F$6:$F$64="666506")*'Slaughterhouse IQC'!$J$6:$J$64)/SUMPRODUCT((LEFT('Slaughterhouse IQC'!$A$6:$A$64,7)="2026-07")*('Slaughterhouse IQC'!$B$6:$B$64="Martins")*('Slaughterhouse IQC'!$F$6:$F$64="666506")*'Slaughterhouse IQC'!$I$6:$I$64)) -> 0.97468354 | F7: =IF(SUMPRODUCT((LEFT('Slaughterhouse IQC'!$A$6:$A$64,7)="2026-08")*('Slaughterhouse IQC'!$B$6:$B$64="Martins")*('Slaughterhouse IQC'!$F$6:$F$64="666506")*'Slaughterhouse IQC'!$I$6:$I$64)=0,"",SUMPRODUCT((LEFT('Slaughterhouse IQC'!$A$6:$A$64,7)="2026-08")*('Slaughterhouse IQC'!$B$6:$B$64="Martins")*('Slaughterhouse IQC'!$F$6:$F$64="666506")*'Slaughterhouse IQC'!$J$6:$J$64)/SUMPRODUCT((LEFT('Slaughterhouse IQC'!$A$6:$A$64,7)="2026-08")*('Slaughterhouse IQC'!$B$6:$B$64="Martins")*('Slaughterhouse IQC'!$F$6:$F$64="666506")*'Slaughterhouse IQC'!$I$6:$I$64)) -> 1 | G7: =IF(SUMPRODUCT(('Slaughterhouse IQC'!$B$6:$B$64="Martins")*('Slaughterhouse IQC'!$F$6:$F$64="666506")*'Slaughterhouse IQC'!$I$6:$I$64)=0,"",SUMPRODUCT(('Slaughterhouse IQC'!$B$6:$B$64="Martins")*('Slaughterhouse IQC'!$F$6:$F$64="666506")*'Slaughterhouse IQC'!$J$6:$J$64)/SUMPRODUCT(('Slaughterhouse IQC'!$B$6:$B$64="Martins")*('Slaughterhouse IQC'!$F$6:$F$64="666506")*'Slaughterhouse IQC'!$I$6:$I$64)) -> 0.95962733
A8: Pelvic @ Parks · 666518 | B8: =IF(SUMPRODUCT((LEFT('Slaughterhouse IQC'!$A$6:$A$64,7)="2026-04")*('Slaughterhouse IQC'!$B$6:$B$64="Parks Family Meats")*('Slaughterhouse IQC'!$F$6:$F$64="666518")*'Slaughterhouse IQC'!$I$6:$I$64)=0,"",SUMPRODUCT((LEFT('Slaughterhouse IQC'!$A$6:$A$64,7)="2026-04")*('Slaughterhouse IQC'!$B$6:$B$64="Parks Family Meats")*('Slaughterhouse IQC'!$F$6:$F$64="666518")*'Slaughterhouse IQC'!$J$6:$J$64)/SUMPRODUCT((LEFT('Slaughterhouse IQC'!$A$6:$A$64,7)="2026-04")*('Slaughterhouse IQC'!$B$6:$B$64="Parks Family Meats")*('Slaughterhouse IQC'!$F$6:$F$64="666518")*'Slaughterhouse IQC'!$I$6:$I$64)) | C8: =IF(SUMPRODUCT((LEFT('Slaughterhouse IQC'!$A$6:$A$64,7)="2026-05")*('Slaughterhouse IQC'!$B$6:$B$64="Parks Family Meats")*('Slaughterhouse IQC'!$F$6:$F$64="666518")*'Slaughterhouse IQC'!$I$6:$I$64)=0,"",SUMPRODUCT((LEFT('Slaughterhouse IQC'!$A$6:$A$64,7)="2026-05")*('Slaughterhouse IQC'!$B$6:$B$64="Parks Family Meats")*('Slaughterhouse IQC'!$F$6:$F$64="666518")*'Slaughterhouse IQC'!$J$6:$J$64)/SUMPRODUCT((LEFT('Slaughterhouse IQC'!$A$6:$A$64,7)="2026-05")*('Slaughterhouse IQC'!$B$6:$B$64="Parks Family Meats")*('Slaughterhouse IQC'!$F$6:$F$64="666518")*'Slaughterhouse IQC'!$I$6:$I$64)) -> 0.6875 | D8: =IF(SUMPRODUCT((LEFT('Slaughterhouse IQC'!$A$6:$A$64,7)="2026-06")*('Slaughterhouse IQC'!$B$6:$B$64="Parks Family Meats")*('Slaughterhouse IQC'!$F$6:$F$64="666518")*'Slaughterhouse IQC'!$I$6:$I$64)=0,"",SUMPRODUCT((LEFT('Slaughterhouse IQC'!$A$6:$A$64,7)="2026-06")*('Slaughterhouse IQC'!$B$6:$B$64="Parks Family Meats")*('Slaughterhouse IQC'!$F$6:$F$64="666518")*'Slaughterhouse IQC'!$J$6:$J$64)/SUMPRODUCT((LEFT('Slaughterhouse IQC'!$A$6:$A$64,7)="2026-06")*('Slaughterhouse IQC'!$B$6:$B$64="Parks Family Meats")*('Slaughterhouse IQC'!$F$6:$F$64="666518")*'Slaughterhouse IQC'!$I$6:$I$64)) -> 0.828125 | E8: =IF(SUMPRODUCT((LEFT('Slaughterhouse IQC'!$A$6:$A$64,7)="2026-07")*('Slaughterhouse IQC'!$B$6:$B$64="Parks Family Meats")*('Slaughterhouse IQC'!$F$6:$F$64="666518")*'Slaughterhouse IQC'!$I$6:$I$64)=0,"",SUMPRODUCT((LEFT('Slaughterhouse IQC'!$A$6:$A$64,7)="2026-07")*('Slaughterhouse IQC'!$B$6:$B$64="Parks Family Meats")*('Slaughterhouse IQC'!$F$6:$F$64="666518")*'Slaughterhouse IQC'!$J$6:$J$64)/SUMPRODUCT((LEFT('Slaughterhouse IQC'!$A$6:$A$64,7)="2026-07")*('Slaughterhouse IQC'!$B$6:$B$64="Parks Family Meats")*('Slaughterhouse IQC'!$F$6:$F$64="666518")*'Slaughterhouse IQC'!$I$6:$I$64)) -> 0.88495575 | F8: =IF(SUMPRODUCT((LEFT('Slaughterhouse IQC'!$A$6:$A$64,7)="2026-08")*('Slaughterhouse IQC'!$B$6:$B$64="Parks Family Meats")*('Slaughterhouse IQC'!$F$6:$F$64="666518")*'Slaughterhouse IQC'!$I$6:$I$64)=0,"",SUMPRODUCT((LEFT('Slaughterhouse IQC'!$A$6:$A$64,7)="2026-08")*('Slaughterhouse IQC'!$B$6:$B$64="Parks Family Meats")*('Slaughterhouse IQC'!$F$6:$F$64="666518")*'Slaughterhouse IQC'!$J$6:$J$64)/SUMPRODUCT((LEFT('Slaughterhouse IQC'!$A$6:$A$64,7)="2026-08")*('Slaughterhouse IQC'!$B$6:$B$64="Parks Family Meats")*('Slaughterhouse IQC'!$F$6:$F$64="666518")*'Slaughterhouse IQC'!$I$6:$I$64)) | G8: =IF(SUMPRODUCT(('Slaughterhouse IQC'!$B$6:$B$64="Parks Family Meats")*('Slaughterhouse IQC'!$F$6:$F$64="666518")*'Slaughterhouse IQC'!$I$6:$I$64)=0,"",SUMPRODUCT(('Slaughterhouse IQC'!$B$6:$B$64="Parks Family Meats")*('Slaughterhouse IQC'!$F$6:$F$64="666518")*'Slaughterhouse IQC'!$J$6:$J$64)/SUMPRODUCT(('Slaughterhouse IQC'!$B$6:$B$64="Parks Family Meats")*('Slaughterhouse IQC'!$F$6:$F$64="666518")*'Slaughterhouse IQC'!$I$6:$I$64)) -> 0.84435798
A9: Pelvic @ Parks · 666541 | B9: =IF(SUMPRODUCT((LEFT('Slaughterhouse IQC'!$A$6:$A$64,7)="2026-04")*('Slaughterhouse IQC'!$B$6:$B$64="Parks Family Meats")*('Slaughterhouse IQC'!$F$6:$F$64="666541")*'Slaughterhouse IQC'!$I$6:$I$64)=0,"",SUMPRODUCT((LEFT('Slaughterhouse IQC'!$A$6:$A$64,7)="2026-04")*('Slaughterhouse IQC'!$B$6:$B$64="Parks Family Meats")*('Slaughterhouse IQC'!$F$6:$F$64="666541")*'Slaughterhouse IQC'!$J$6:$J$64)/SUMPRODUCT((LEFT('Slaughterhouse IQC'!$A$6:$A$64,7)="2026-04")*('Slaughterhouse IQC'!$B$6:$B$64="Parks Family Meats")*('Slaughterhouse IQC'!$F$6:$F$64="666541")*'Slaughterhouse IQC'!$I$6:$I$64)) | C9: =IF(SUMPRODUCT((LEFT('Slaughterhouse IQC'!$A$6:$A$64,7)="2026-05")*('Slaughterhouse IQC'!$B$6:$B$64="Parks Family Meats")*('Slaughterhouse IQC'!$F$6:$F$64="666541")*'Slaughterhouse IQC'!$I$6:$I$64)=0,"",SUMPRODUCT((LEFT('Slaughterhouse IQC'!$A$6:$A$64,7)="2026-05")*('Slaughterhouse IQC'!$B$6:$B$64="Parks Family Meats")*('Slaughterhouse IQC'!$F$6:$F$64="666541")*'Slaughterhouse IQC'!$J$6:$J$64)/SUMPRODUCT((LEFT('Slaughterhouse IQC'!$A$6:$A$64,7)="2026-05")*('Slaughterhouse IQC'!$B$6:$B$64="Parks Family Meats")*('Slaughterhouse IQC'!$F$6:$F$64="666541")*'Slaughterhouse IQC'!$I$6:$I$64)) | D9: =IF(SUMPRODUCT((LEFT('Slaughterhouse IQC'!$A$6:$A$64,7)="2026-06")*('Slaughterhouse IQC'!$B$6:$B$64="Parks Family Meats")*('Slaughterhouse IQC'!$F$6:$F$64="666541")*'Slaughterhouse IQC'!$I$6:$I$64)=0,"",SUMPRODUCT((LEFT('Slaughterhouse IQC'!$A$6:$A$64,7)="2026-06")*('Slaughterhouse IQC'!$B$6:$B$64="Parks Family Meats")*('Slaughterhouse IQC'!$F$6:$F$64="666541")*'Slaughterhouse IQC'!$J$6:$J$64)/SUMPRODUCT((LEFT('Slaughterhouse IQC'!$A$6:$A$64,7)="2026-06")*('Slaughterhouse IQC'!$B$6:$B$64="Parks Family Meats")*('Slaughterhouse IQC'!$F$6:$F$64="666541")*'Slaughterhouse IQC'!$I$6:$I$64)) | E9: =IF(SUMPRODUCT((LEFT('Slaughterhouse IQC'!$A$6:$A$64,7)="2026-07")*('Slaughterhouse IQC'!$B$6:$B$64="Parks Family Meats")*('Slaughterhouse IQC'!$F$6:$F$64="666541")*'Slaughterhouse IQC'!$I$6:$I$64)=0,"",SUMPRODUCT((LEFT('Slaughterhouse IQC'!$A$6:$A$64,7)="2026-07")*('Slaughterhouse IQC'!$B$6:$B$64="Parks Family Meats")*('Slaughterhouse IQC'!$F$6:$F$64="666541")*'Slaughterhouse IQC'!$J$6:$J$64)/SUMPRODUCT((LEFT('Slaughterhouse IQC'!$A$6:$A$64,7)="2026-07")*('Slaughterhouse IQC'!$B$6:$B$64="Parks Family Meats")*('Slaughterhouse IQC'!$F$6:$F$64="666541")*'Slaughterhouse IQC'!$I$6:$I$64)) | F9: =IF(SUMPRODUCT((LEFT('Slaughterhouse IQC'!$A$6:$A$64,7)="2026-08")*('Slaughterhouse IQC'!$B$6:$B$64="Parks Family Meats")*('Slaughterhouse IQC'!$F$6:$F$64="666541")*'Slaughterhouse IQC'!$I$6:$I$64)=0,"",SUMPRODUCT((LEFT('Slaughterhouse IQC'!$A$6:$A$64,7)="2026-08")*('Slaughterhouse IQC'!$B$6:$B$64="Parks Family Meats")*('Slaughterhouse IQC'!$F$6:$F$64="666541")*'Slaughterhouse IQC'!$J$6:$J$64)/SUMPRODUCT((LEFT('Slaughterhouse IQC'!$A$6:$A$64,7)="2026-08")*('Slaughterhouse IQC'!$B$6:$B$64="Parks Family Meats")*('Slaughterhouse IQC'!$F$6:$F$64="666541")*'Slaughterhouse IQC'!$I$6:$I$64)) -> 0.96969697 | G9: =IF(SUMPRODUCT(('Slaughterhouse IQC'!$B$6:$B$64="Parks Family Meats")*('Slaughterhouse IQC'!$F$6:$F$64="666541")*'Slaughterhouse IQC'!$I$6:$I$64)=0,"",SUMPRODUCT(('Slaughterhouse IQC'!$B$6:$B$64="Parks Family Meats")*('Slaughterhouse IQC'!$F$6:$F$64="666541")*'Slaughterhouse IQC'!$J$6:$J$64)/SUMPRODUCT(('Slaughterhouse IQC'!$B$6:$B$64="Parks Family Meats")*('Slaughterhouse IQC'!$F$6:$F$64="666541")*'Slaughterhouse IQC'!$I$6:$I$64)) -> 0.96969697
A10: Pelvic @ Nahunta · 666541 | B10: =IF(SUMPRODUCT((LEFT('Slaughterhouse IQC'!$A$6:$A$64,7)="2026-04")*('Slaughterhouse IQC'!$B$6:$B$64="Nahunta")*('Slaughterhouse IQC'!$F$6:$F$64="666541")*'Slaughterhouse IQC'!$I$6:$I$64)=0,"",SUMPRODUCT((LEFT('Slaughterhouse IQC'!$A$6:$A$64,7)="2026-04")*('Slaughterhouse IQC'!$B$6:$B$64="Nahunta")*('Slaughterhouse IQC'!$F$6:$F$64="666541")*'Slaughterhouse IQC'!$J$6:$J$64)/SUMPRODUCT((LEFT('Slaughterhouse IQC'!$A$6:$A$64,7)="2026-04")*('Slaughterhouse IQC'!$B$6:$B$64="Nahunta")*('Slaughterhouse IQC'!$F$6:$F$64="666541")*'Slaughterhouse IQC'!$I$6:$I$64)) | C10: =IF(SUMPRODUCT((LEFT('Slaughterhouse IQC'!$A$6:$A$64,7)="2026-05")*('Slaughterhouse IQC'!$B$6:$B$64="Nahunta")*('Slaughterhouse IQC'!$F$6:$F$64="666541")*'Slaughterhouse IQC'!$I$6:$I$64)=0,"",SUMPRODUCT((LEFT('Slaughterhouse IQC'!$A$6:$A$64,7)="2026-05")*('Slaughterhouse IQC'!$B$6:$B$64="Nahunta")*('Slaughterhouse IQC'!$F$6:$F$64="666541")*'Slaughterhouse IQC'!$J$6:$J$64)/SUMPRODUCT((LEFT('Slaughterhouse IQC'!$A$6:$A$64,7)="2026-05")*('Slaughterhouse IQC'!$B$6:$B$64="Nahunta")*('Slaughterhouse IQC'!$F$6:$F$64="666541")*'Slaughterhouse IQC'!$I$6:$I$64)) | D10: =IF(SUMPRODUCT((LEFT('Slaughterhouse IQC'!$A$6:$A$64,7)="2026-06")*('Slaughterhouse IQC'!$B$6:$B$64="Nahunta")*('Slaughterhouse IQC'!$F$6:$F$64="666541")*'Slaughterhouse IQC'!$I$6:$I$64)=0,"",SUMPRODUCT((LEFT('Slaughterhouse IQC'!$A$6:$A$64,7)="2026-06")*('Slaughterhouse IQC'!$B$6:$B$64="Nahunta")*('Slaughterhouse IQC'!$F$6:$F$64="666541")*'Slaughterhouse IQC'!$J$6:$J$64)/SUMPRODUCT((LEFT('Slaughterhouse IQC'!$A$6:$A$64,7)="2026-06")*('Slaughterhouse IQC'!$B$6:$B$64="Nahunta")*('Slaughterhouse IQC'!$F$6:$F$64="666541")*'Slaughterhouse IQC'!$I$6:$I$64)) | E10: =IF(SUMPRODUCT((LEFT('Slaughterhouse IQC'!$A$6:$A$64,7)="2026-07")*('Slaughterhouse IQC'!$B$6:$B$64="Nahunta")*('Slaughterhouse IQC'!$F$6:$F$64="666541")*'Slaughterhouse IQC'!$I$6:$I$64)=0,"",SUMPRODUCT((LEFT('Slaughterhouse IQC'!$A$6:$A$64,7)="2026-07")*('Slaughterhouse IQC'!$B$6:$B$64="Nahunta")*('Slaughterhouse IQC'!$F$6:$F$64="666541")*'Slaughterhouse IQC'!$J$6:$J$64)/SUMPRODUCT((LEFT('Slaughterhouse IQC'!$A$6:$A$64,7)="2026-07")*('Slaughterhouse IQC'!$B$6:$B$64="Nahunta")*('Slaughterhouse IQC'!$F$6:$F$64="666541")*'Slaughterhouse IQC'!$I$6:$I$64)) -> 1 | F10: =IF(SUMPRODUCT((LEFT('Slaughterhouse IQC'!$A$6:$A$64,7)="2026-08")*('Slaughterhouse IQC'!$B$6:$B$64="Nahunta")*('Slaughterhouse IQC'!$F$6:$F$64="666541")*'Slaughterhouse IQC'!$I$6:$I$64)=0,"",SUMPRODUCT((LEFT('Slaughterhouse IQC'!$A$6:$A$64,7)="2026-08")*('Slaughterhouse IQC'!$B$6:$B$64="Nahunta")*('Slaughterhouse IQC'!$F$6:$F$64="666541")*'Slaughterhouse IQC'!$J$6:$J$64)/SUMPRODUCT((LEFT('Slaughterhouse IQC'!$A$6:$A$64,7)="2026-08")*('Slaughterhouse IQC'!$B$6:$B$64="Nahunta")*('Slaughterhouse IQC'!$F$6:$F$64="666541")*'Slaughterhouse IQC'!$I$6:$I$64)) -> 0.076923077 | G10: =IF(SUMPRODUCT(('Slaughterhouse IQC'!$B$6:$B$64="Nahunta")*('Slaughterhouse IQC'!$F$6:$F$64="666541")*'Slaughterhouse IQC'!$I$6:$I$64)=0,"",SUMPRODUCT(('Slaughterhouse IQC'!$B$6:$B$64="Nahunta")*('Slaughterhouse IQC'!$F$6:$F$64="666541")*'Slaughterhouse IQC'!$J$6:$J$64)/SUMPRODUCT(('Slaughterhouse IQC'!$B$6:$B$64="Nahunta")*('Slaughterhouse IQC'!$F$6:$F$64="666541")*'Slaughterhouse IQC'!$I$6:$I$64)) -> 0.14285714
A11: Thoracic @ Nahunta · 666521 | B11: =IF(SUMPRODUCT((LEFT('Slaughterhouse IQC'!$A$6:$A$64,7)="2026-04")*('Slaughterhouse IQC'!$B$6:$B$64="Nahunta")*('Slaughterhouse IQC'!$F$6:$F$64="666521")*'Slaughterhouse IQC'!$I$6:$I$64)=0,"",SUMPRODUCT((LEFT('Slaughterhouse IQC'!$A$6:$A$64,7)="2026-04")*('Slaughterhouse IQC'!$B$6:$B$64="Nahunta")*('Slaughterhouse IQC'!$F$6:$F$64="666521")*'Slaughterhouse IQC'!$J$6:$J$64)/SUMPRODUCT((LEFT('Slaughterhouse IQC'!$A$6:$A$64,7)="2026-04")*('Slaughterhouse IQC'!$B$6:$B$64="Nahunta")*('Slaughterhouse IQC'!$F$6:$F$64="666521")*'Slaughterhouse IQC'!$I$6:$I$64)) | C11: =IF(SUMPRODUCT((LEFT('Slaughterhouse IQC'!$A$6:$A$64,7)="2026-05")*('Slaughterhouse IQC'!$B$6:$B$64="Nahunta")*('Slaughterhouse IQC'!$F$6:$F$64="666521")*'Slaughterhouse IQC'!$I$6:$I$64)=0,"",SUMPRODUCT((LEFT('Slaughterhouse IQC'!$A$6:$A$64,7)="2026-05")*('Slaughterhouse IQC'!$B$6:$B$64="Nahunta")*('Slaughterhouse IQC'!$F$6:$F$64="666521")*'Slaughterhouse IQC'!$J$6:$J$64)/SUMPRODUCT((LEFT('Slaughterhouse IQC'!$A$6:$A$64,7)="2026-05")*('Slaughterhouse IQC'!$B$6:$B$64="Nahunta")*('Slaughterhouse IQC'!$F$6:$F$64="666521")*'Slaughterhouse IQC'!$I$6:$I$64)) | D11: =IF(SUMPRODUCT((LEFT('Slaughterhouse IQC'!$A$6:$A$64,7)="2026-06")*('Slaughterhouse IQC'!$B$6:$B$64="Nahunta")*('Slaughterhouse IQC'!$F$6:$F$64="666521")*'Slaughterhouse IQC'!$I$6:$I$64)=0,"",SUMPRODUCT((LEFT('Slaughterhouse IQC'!$A$6:$A$64,7)="2026-06")*('Slaughterhouse IQC'!$B$6:$B$64="Nahunta")*('Slaughterhouse IQC'!$F$6:$F$64="666521")*'Slaughterhouse IQC'!$J$6:$J$64)/SUMPRODUCT((LEFT('Slaughterhouse IQC'!$A$6:$A$64,7)="2026-06")*('Slaughterhouse IQC'!$B$6:$B$64="Nahunta")*('Slaughterhouse IQC'!$F$6:$F$64="666521")*'Slaughterhouse IQC'!$I$6:$I$64)) | E11: =IF(SUMPRODUCT((LEFT('Slaughterhouse IQC'!$A$6:$A$64,7)="2026-07")*('Slaughterhouse IQC'!$B$6:$B$64="Nahunta")*('Slaughterhouse IQC'!$F$6:$F$64="666521")*'Slaughterhouse IQC'!$I$6:$I$64)=0,"",SUMPRODUCT((LEFT('Slaughterhouse IQC'!$A$6:$A$64,7)="2026-07")*('Slaughterhouse IQC'!$B$6:$B$64="Nahunta")*('Slaughterhouse IQC'!$F$6:$F$64="666521")*'Slaughterhouse IQC'!$J$6:$J$64)/SUMPRODUCT((LEFT('Slaughterhouse IQC'!$A$6:$A$64,7)="2026-07")*('Slaughterhouse IQC'!$B$6:$B$64="Nahunta")*('Slaughterhouse IQC'!$F$6:$F$64="666521")*'Slaughterhouse IQC'!$I$6:$I$64)) -> 0.31578947 | F11: =IF(SUMPRODUCT((LEFT('Slaughterhouse IQC'!$A$6:$A$64,7)="2026-08")*('Slaughterhouse IQC'!$B$6:$B$64="Nahunta")*('Slaughterhouse IQC'!$F$6:$F$64="666521")*'Slaughterhouse IQC'!$I$6:$I$64)=0,"",SUMPRODUCT((LEFT('Slaughterhouse IQC'!$A$6:$A$64,7)="2026-08")*('Slaughterhouse IQC'!$B$6:$B$64="Nahunta")*('Slaughterhouse IQC'!$F$6:$F$64="666521")*'Slaughterhouse IQC'!$J$6:$J$64)/SUMPRODUCT((LEFT('Slaughterhouse IQC'!$A$6:$A$64,7)="2026-08")*('Slaughterhouse IQC'!$B$6:$B$64="Nahunta")*('Slaughterhouse IQC'!$F$6:$F$64="666521")*'Slaughterhouse IQC'!$I$6:$I$64)) -> 0.14035088 | G11: =IF(SUMPRODUCT(('Slaughterhouse IQC'!$B$6:$B$64="Nahunta")*('Slaughterhouse IQC'!$F$6:$F$64="666521")*'Slaughterhouse IQC'!$I$6:$I$64)=0,"",SUMPRODUCT(('Slaughterhouse IQC'!$B$6:$B$64="Nahunta")*('Slaughterhouse IQC'!$F$6:$F$64="666521")*'Slaughterhouse IQC'!$J$6:$J$64)/SUMPRODUCT(('Slaughterhouse IQC'!$B$6:$B$64="Nahunta")*('Slaughterhouse IQC'!$F$6:$F$64="666521")*'Slaughterhouse IQC'!$I$6:$I$64)) -> 0.18421053
A13: OVERVIEW — ISSUES FOUND (# FAILED) BY MONTH
A14: Tissue @ SH · Part | B14: April | C14: May | D14: June | E14: July | F14: August | G14: Total
A15: Pelvic @ Martins · 666541 | B15: =IF(SUMPRODUCT((LEFT('Slaughterhouse IQC'!$A$6:$A$64,7)="2026-04")*('Slaughterhouse IQC'!$B$6:$B$64="Martins")*('Slaughterhouse IQC'!$F$6:$F$64="666541")*'Slaughterhouse IQC'!$I$6:$I$64)=0,"",SUMPRODUCT((LEFT('Slaughterhouse IQC'!$A$6:$A$64,7)="2026-04")*('Slaughterhouse IQC'!$B$6:$B$64="Martins")*('Slaughterhouse IQC'!$F$6:$F$64="666541")*'Slaughterhouse IQC'!$K$6:$K$64)) -> 6 | C15: =IF(SUMPRODUCT((LEFT('Slaughterhouse IQC'!$A$6:$A$64,7)="2026-05")*('Slaughterhouse IQC'!$B$6:$B$64="Martins")*('Slaughterhouse IQC'!$F$6:$F$64="666541")*'Slaughterhouse IQC'!$I$6:$I$64)=0,"",SUMPRODUCT((LEFT('Slaughterhouse IQC'!$A$6:$A$64,7)="2026-05")*('Slaughterhouse IQC'!$B$6:$B$64="Martins")*('Slaughterhouse IQC'!$F$6:$F$64="666541")*'Slaughterhouse IQC'!$K$6:$K$64)) -> 13 | D15: =IF(SUMPRODUCT((LEFT('Slaughterhouse IQC'!$A$6:$A$64,7)="2026-06")*('Slaughterhouse IQC'!$B$6:$B$64="Martins")*('Slaughterhouse IQC'!$F$6:$F$64="666541")*'Slaughterhouse IQC'!$I$6:$I$64)=0,"",SUMPRODUCT((LEFT('Slaughterhouse IQC'!$A$6:$A$64,7)="2026-06")*('Slaughterhouse IQC'!$B$6:$B$64="Martins")*('Slaughterhouse IQC'!$F$6:$F$64="666541")*'Slaughterhouse IQC'!$K$6:$K$64)) -> 8 | E15: =IF(SUMPRODUCT((LEFT('Slaughterhouse IQC'!$A$6:$A$64,7)="2026-07")*('Slaughterhouse IQC'!$B$6:$B$64="Martins")*('Slaughterhouse IQC'!$F$6:$F$64="666541")*'Slaughterhouse IQC'!$I$6:$I$64)=0,"",SUMPRODUCT((LEFT('Slaughterhouse IQC'!$A$6:$A$64,7)="2026-07")*('Slaughterhouse IQC'!$B$6:$B$64="Martins")*('Slaughterhouse IQC'!$F$6:$F$64="666541")*'Slaughterhouse IQC'!$K$6:$K$64)) -> 6 | F15: =IF(SUMPRODUCT((LEFT('Slaughterhouse IQC'!$A$6:$A$64,7)="2026-08")*('Slaughterhouse IQC'!$B$6:$B$64="Martins")*('Slaughterhouse IQC'!$F$6:$F$64="666541")*'Slaughterhouse IQC'!$I$6:$I$64)=0,"",SUMPRODUCT((LEFT('Slaughterhouse IQC'!$A$6:$A$64,7)="2026-08")*('Slaughterhouse IQC'!$B$6:$B$64="Martins")*('Slaughterhouse IQC'!$F$6:$F$64="666541")*'Slaughterhouse IQC'!$K$6:$K$64)) -> 5 | G15: =SUMPRODUCT(('Slaughterhouse IQC'!$B$6:$B$64="Martins")*('Slaughterhouse IQC'!$F$6:$F$64="666541")*'Slaughterhouse IQC'!$K$6:$K$64) -> 38
A16: Pelvic @ Martins · 666506 | B16: =IF(SUMPRODUCT((LEFT('Slaughterhouse IQC'!$A$6:$A$64,7)="2026-04")*('Slaughterhouse IQC'!$B$6:$B$64="Martins")*('Slaughterhouse IQC'!$F$6:$F$64="666506")*'Slaughterhouse IQC'!$I$6:$I$64)=0,"",SUMPRODUCT((LEFT('Slaughterhouse IQC'!$A$6:$A$64,7)="2026-04")*('Slaughterhouse IQC'!$B$6:$B$64="Martins")*('Slaughterhouse IQC'!$F$6:$F$64="666506")*'Slaughterhouse IQC'!$K$6:$K$64)) -> 4 | C16: =IF(SUMPRODUCT((LEFT('Slaughterhouse IQC'!$A$6:$A$64,7)="2026-05")*('Slaughterhouse IQC'!$B$6:$B$64="Martins")*('Slaughterhouse IQC'!$F$6:$F$64="666506")*'Slaughterhouse IQC'!$I$6:$I$64)=0,"",SUMPRODUCT((LEFT('Slaughterhouse IQC'!$A$6:$A$64,7)="2026-05")*('Slaughterhouse IQC'!$B$6:$B$64="Martins")*('Slaughterhouse IQC'!$F$6:$F$64="666506")*'Slaughterhouse IQC'!$K$6:$K$64)) -> 6 | D16: =IF(SUMPRODUCT((LEFT('Slaughterhouse IQC'!$A$6:$A$64,7)="2026-06")*('Slaughterhouse IQC'!$B$6:$B$64="Martins")*('Slaughterhouse IQC'!$F$6:$F$64="666506")*'Slaughterhouse IQC'!$I$6:$I$64)=0,"",SUMPRODUCT((LEFT('Slaughterhouse IQC'!$A$6:$A$64,7)="2026-06")*('Slaughterhouse IQC'!$B$6:$B$64="Martins")*('Slaughterhouse IQC'!$F$6:$F$64="666506")*'Slaughterhouse IQC'!$K$6:$K$64)) -> 1 | E16: =IF(SUMPRODUCT((LEFT('Slaughterhouse IQC'!$A$6:$A$64,7)="2026-07")*('Slaughterhouse IQC'!$B$6:$B$64="Martins")*('Slaughterhouse IQC'!$F$6:$F$64="666506")*'Slaughterhouse IQC'!$I$6:$I$64)=0,"",SUMPRODUCT((LEFT('Slaughterhouse IQC'!$A$6:$A$64,7)="2026-07")*('Slaughterhouse IQC'!$B$6:$B$64="Martins")*('Slaughterhouse IQC'!$F$6:$F$64="666506")*'Slaughterhouse IQC'!$K$6:$K$64)) -> 2 | F16: =IF(SUMPRODUCT((LEFT('Slaughterhouse IQC'!$A$6:$A$64,7)="2026-08")*('Slaughterhouse IQC'!$B$6:$B$64="Martins")*('Slaughterhouse IQC'!$F$6:$F$64="666506")*'Slaughterhouse IQC'!$I$6:$I$64)=0,"",SUMPRODUCT((LEFT('Slaughterhouse IQC'!$A$6:$A$64,7)="2026-08")*('Slaughterhouse IQC'!$B$6:$B$64="Martins")*('Slaughterhouse IQC'!$F$6:$F$64="666506")*'Slaughterhouse IQC'!$K$6:$K$64)) -> 0 | G16: =SUMPRODUCT(('Slaughterhouse IQC'!$B$6:$B$64="Martins")*('Slaughterhouse IQC'!$F$6:$F$64="666506")*'Slaughterhouse IQC'!$K$6:$K$64) -> 13
A17: Pelvic @ Parks · 666518 | B17: =IF(SUMPRODUCT((LEFT('Slaughterhouse IQC'!$A$6:$A$64,7)="2026-04")*('Slaughterhouse IQC'!$B$6:$B$64="Parks Family Meats")*('Slaughterhouse IQC'!$F$6:$F$64="666518")*'Slaughterhouse IQC'!$I$6:$I$64)=0,"",SUMPRODUCT((LEFT('Slaughterhouse IQC'!$A$6:$A$64,7)="2026-04")*('Slaughterhouse IQC'!$B$6:$B$64="Parks Family Meats")*('Slaughterhouse IQC'!$F$6:$F$64="666518")*'Slaughterhouse IQC'!$K$6:$K$64)) | C17: =IF(SUMPRODUCT((LEFT('Slaughterhouse IQC'!$A$6:$A$64,7)="2026-05")*('Slaughterhouse IQC'!$B$6:$B$64="Parks Family Meats")*('Slaughterhouse IQC'!$F$6:$F$64="666518")*'Slaughterhouse IQC'!$I$6:$I$64)=0,"",SUMPRODUCT((LEFT('Slaughterhouse IQC'!$A$6:$A$64,7)="2026-05")*('Slaughterhouse IQC'!$B$6:$B$64="Parks Family Meats")*('Slaughterhouse IQC'!$F$6:$F$64="666518")*'Slaughterhouse IQC'!$K$6:$K$64)) -> 5 | D17: =IF(SUMPRODUCT((LEFT('Slaughterhouse IQC'!$A$6:$A$64,7)="2026-06")*('Slaughterhouse IQC'!$B$6:$B$64="Parks Family Meats")*('Slaughterhouse IQC'!$F$6:$F$64="666518")*'Slaughterhouse IQC'!$I$6:$I$64)=0,"",SUMPRODUCT((LEFT('Slaughterhouse IQC'!$A$6:$A$64,7)="2026-06")*('Slaughterhouse IQC'!$B$6:$B$64="Parks Family Meats")*('Slaughterhouse IQC'!$F$6:$F$64="666518")*'Slaughterhouse IQC'!$K$6:$K$64)) -> 22 | E17: =IF(SUMPRODUCT((LEFT('Slaughterhouse IQC'!$A$6:$A$64,7)="2026-07")*('Slaughterhouse IQC'!$B$6:$B$64="Parks Family Meats")*('Slaughterhouse IQC'!$F$6:$F$64="666518")*'Slaughterhouse IQC'!$I$6:$I$64)=0,"",SUMPRODUCT((LEFT('Slaughterhouse IQC'!$A$6:$A$64,7)="2026-07")*('Slaughterhouse IQC'!$B$6:$B$64="Parks Family Meats")*('Slaughterhouse IQC'!$F$6:$F$64="666518")*'Slaughterhouse IQC'!$K$6:$K$64)) -> 13 | F17: =IF(SUMPRODUCT((LEFT('Slaughterhouse IQC'!$A$6:$A$64,7)="2026-08")*('Slaughterhouse IQC'!$B$6:$B$64="Parks Family Meats")*('Slaughterhouse IQC'!$F$6:$F$64="666518")*'Slaughterhouse IQC'!$I$6:$I$64)=0,"",SUMPRODUCT((LEFT('Slaughterhouse IQC'!$A$6:$A$64,7)="2026-08")*('Slaughterhouse IQC'!$B$6:$B$64="Parks Family Meats")*('Slaughterhouse IQC'!$F$6:$F$64="666518")*'Slaughterhouse IQC'!$K$6:$K$64)) | G17: =SUMPRODUCT(('Slaughterhouse IQC'!$B$6:$B$64="Parks Family Meats")*('Slaughterhouse IQC'!$F$6:$F$64="666518")*'Slaughterhouse IQC'!$K$6:$K$64) -> 40
A18: Pelvic @ Parks · 666541 | B18: =IF(SUMPRODUCT((LEFT('Slaughterhouse IQC'!$A$6:$A$64,7)="2026-04")*('Slaughterhouse IQC'!$B$6:$B$64="Parks Family Meats")*('Slaughterhouse IQC'!$F$6:$F$64="666541")*'Slaughterhouse IQC'!$I$6:$I$64)=0,"",SUMPRODUCT((LEFT('Slaughterhouse IQC'!$A$6:$A$64,7)="2026-04")*('Slaughterhouse IQC'!$B$6:$B$64="Parks Family Meats")*('Slaughterhouse IQC'!$F$6:$F$64="666541")*'Slaughterhouse IQC'!$K$6:$K$64)) | C18: =IF(SUMPRODUCT((LEFT('Slaughterhouse IQC'!$A$6:$A$64,7)="2026-05")*('Slaughterhouse IQC'!$B$6:$B$64="Parks Family Meats")*('Slaughterhouse IQC'!$F$6:$F$64="666541")*'Slaughterhouse IQC'!$I$6:$I$64)=0,"",SUMPRODUCT((LEFT('Slaughterhouse IQC'!$A$6:$A$64,7)="2026-05")*('Slaughterhouse IQC'!$B$6:$B$64="Parks Family Meats")*('Slaughterhouse IQC'!$F$6:$F$64="666541")*'Slaughterhouse IQC'!$K$6:$K$64)) | D18: =IF(SUMPRODUCT((LEFT('Slaughterhouse IQC'!$A$6:$A$64,7)="2026-06")*('Slaughterhouse IQC'!$B$6:$B$64="Parks Family Meats")*('Slaughterhouse IQC'!$F$6:$F$64="666541")*'Slaughterhouse IQC'!$I$6:$I$64)=0,"",SUMPRODUCT((LEFT('Slaughterhouse IQC'!$A$6:$A$64,7)="2026-06")*('Slaughterhouse IQC'!$B$6:$B$64="Parks Family Meats")*('Slaughterhouse IQC'!$F$6:$F$64="666541")*'Slaughterhouse IQC'!$K$6:$K$64)) | E18: =IF(SUMPRODUCT((LEFT('Slaughterhouse IQC'!$A$6:$A$64,7)="2026-07")*('Slaughterhouse IQC'!$B$6:$B$64="Parks Family Meats")*('Slaughterhouse IQC'!$F$6:$F$64="666541")*'Slaughterhouse IQC'!$I$6:$I$64)=0,"",SUMPRODUCT((LEFT('Slaughterhouse IQC'!$A$6:$A$64,7)="2026-07")*('Slaughterhouse IQC'!$B$6:$B$64="Parks Family Meats")*('Slaughterhouse IQC'!$F$6:$F$64="666541")*'Slaughterhouse IQC'!$K$6:$K$64)) | F18: =IF(SUMPRODUCT((LEFT('Slaughterhouse IQC'!$A$6:$A$64,7)="2026-08")*('Slaughterhouse IQC'!$B$6:$B$64="Parks Family Meats")*('Slaughterhouse IQC'!$F$6:$F$64="666541")*'Slaughterhouse IQC'!$I$6:$I$64)=0,"",SUMPRODUCT((LEFT('Slaughterhouse IQC'!$A$6:$A$64,7)="2026-08")*('Slaughterhouse IQC'!$B$6:$B$64="Parks Family Meats")*('Slaughterhouse IQC'!$F$6:$F$64="666541")*'Slaughterhouse IQC'!$K$6:$K$64)) -> 1 | G18: =SUMPRODUCT(('Slaughterhouse IQC'!$B$6:$B$64="Parks Family Meats")*('Slaughterhouse IQC'!$F$6:$F$64="666541")*'Slaughterhouse IQC'!$K$6:$K$64) -> 1
A19: Pelvic @ Nahunta · 666541 | B19: =IF(SUMPRODUCT((LEFT('Slaughterhouse IQC'!$A$6:$A$64,7)="2026-04")*('Slaughterhouse IQC'!$B$6:$B$64="Nahunta")*('Slaughterhouse IQC'!$F$6:$F$64="666541")*'Slaughterhouse IQC'!$I$6:$I$64)=0,"",SUMPRODUCT((LEFT('Slaughterhouse IQC'!$A$6:$A$64,7)="2026-04")*('Slaughterhouse IQC'!$B$6:$B$64="Nahunta")*('Slaughterhouse IQC'!$F$6:$F$64="666541")*'Slaughterhouse IQC'!$K$6:$K$64)) | C19: =IF(SUMPRODUCT((LEFT('Slaughterhouse IQC'!$A$6:$A$64,7)="2026-05")*('Slaughterhouse IQC'!$B$6:$B$64="Nahunta")*('Slaughterhouse IQC'!$F$6:$F$64="666541")*'Slaughterhouse IQC'!$I$6:$I$64)=0,"",SUMPRODUCT((LEFT('Slaughterhouse IQC'!$A$6:$A$64,7)="2026-05")*('Slaughterhouse IQC'!$B$6:$B$64="Nahunta")*('Slaughterhouse IQC'!$F$6:$F$64="666541")*'Slaughterhouse IQC'!$K$6:$K$64)) | D19: =IF(SUMPRODUCT((LEFT('Slaughterhouse IQC'!$A$6:$A$64,7)="2026-06")*('Slaughterhouse IQC'!$B$6:$B$64="Nahunta")*('Slaughterhouse IQC'!$F$6:$F$64="666541")*'Slaughterhouse IQC'!$I$6:$I$64)=0,"",SUMPRODUCT((LEFT('Slaughterhouse IQC'!$A$6:$A$64,7)="2026-06")*('Slaughterhouse IQC'!$B$6:$B$64="Nahunta")*('Slaughterhouse IQC'!$F$6:$F$64="666541")*'Slaughterhouse IQC'!$K$6:$K$64)) | E19: =IF(SUMPRODUCT((LEFT('Slaughterhouse IQC'!$A$6:$A$64,7)="2026-07")*('Slaughterhouse IQC'!$B$6:$B$64="Nahunta")*('Slaughterhouse IQC'!$F$6:$F$64="666541")*'Slaughterhouse IQC'!$I$6:$I$64)=0,"",SUMPRODUCT((LEFT('Slaughterhouse IQC'!$A$6:$A$64,7)="2026-07")*('Slaughterhouse IQC'!$B$6:$B$64="Nahunta")*('Slaughterhouse IQC'!$F$6:$F$64="666541")*'Slaughterhouse IQC'!$K$6:$K$64)) -> 0 | F19: =IF(SUMPRODUCT((LEFT('Slaughterhouse IQC'!$A$6:$A$64,7)="2026-08")*('Slaughterhouse IQC'!$B$6:$B$64="Nahunta")*('Slaughterhouse IQC'!$F$6:$F$64="666541")*'Slaughterhouse IQC'!$I$6:$I$64)=0,"",SUMPRODUCT((LEFT('Slaughterhouse IQC'!$A$6:$A$64,7)="2026-08")*('Slaughterhouse IQC'!$B$6:$B$64="Nahunta")*('Slaughterhouse IQC'!$F$6:$F$64="666541")*'Slaughterhouse IQC'!$K$6:$K$64)) -> 12 | G19: =SUMPRODUCT(('Slaughterhouse IQC'!$B$6:$B$64="Nahunta")*('Slaughterhouse IQC'!$F$6:$F$64="666541")*'Slaughterhouse IQC'!$K$6:$K$64) -> 12
A20: Thoracic @ Nahunta · 666521 | B20: =IF(SUMPRODUCT((LEFT('Slaughterhouse IQC'!$A$6:$A$64,7)="2026-04")*('Slaughterhouse IQC'!$B$6:$B$64="Nahunta")*('Slaughterhouse IQC'!$F$6:$F$64="666521")*'Slaughterhouse IQC'!$I$6:$I$64)=0,"",SUMPRODUCT((LEFT('Slaughterhouse IQC'!$A$6:$A$64,7)="2026-04")*('Slaughterhouse IQC'!$B$6:$B$64="Nahunta")*('Slaughterhouse IQC'!$F$6:$F$64="666521")*'Slaughterhouse IQC'!$K$6:$K$64)) | C20: =IF(SUMPRODUCT((LEFT('Slaughterhouse IQC'!$A$6:$A$64,7)="2026-05")*('Slaughterhouse IQC'!$B$6:$B$64="Nahunta")*('Slaughterhouse IQC'!$F$6:$F$64="666521")*'Slaughterhouse IQC'!$I$6:$I$64)=0,"",SUMPRODUCT((LEFT('Slaughterhouse IQC'!$A$6:$A$64,7)="2026-05")*('Slaughterhouse IQC'!$B$6:$B$64="Nahunta")*('Slaughterhouse IQC'!$F$6:$F$64="666521")*'Slaughterhouse IQC'!$K$6:$K$64)) | D20: =IF(SUMPRODUCT((LEFT('Slaughterhouse IQC'!$A$6:$A$64,7)="2026-06")*('Slaughterhouse IQC'!$B$6:$B$64="Nahunta")*('Slaughterhouse IQC'!$F$6:$F$64="666521")*'Slaughterhouse IQC'!$I$6:$I$64)=0,"",SUMPRODUCT((LEFT('Slaughterhouse IQC'!$A$6:$A$64,7)="2026-06")*('Slaughterhouse IQC'!$B$6:$B$64="Nahunta")*('Slaughterhouse IQC'!$F$6:$F$64="666521")*'Slaughterhouse IQC'!$K$6:$K$64)) | E20: =IF(SUMPRODUCT((LEFT('Slaughterhouse IQC'!$A$6:$A$64,7)="2026-07")*('Slaughterhouse IQC'!$B$6:$B$64="Nahunta")*('Slaughterhouse IQC'!$F$6:$F$64="666521")*'Slaughterhouse IQC'!$I$6:$I$64)=0,"",SUMPRODUCT((LEFT('Slaughterhouse IQC'!$A$6:$A$64,7)="2026-07")*('Slaughterhouse IQC'!$B$6:$B$64="Nahunta")*('Slaughterhouse IQC'!$F$6:$F$64="666521")*'Slaughterhouse IQC'!$K$6:$K$64)) -> 13 | F20: =IF(SUMPRODUCT((LEFT('Slaughterhouse IQC'!$A$6:$A$64,7)="2026-08")*('Slaughterhouse IQC'!$B$6:$B$64="Nahunta")*('Slaughterhouse IQC'!$F$6:$F$64="666521")*'Slaughterhouse IQC'!$I$6:$I$64)=0,"",SUMPRODUCT((LEFT('Slaughterhouse IQC'!$A$6:$A$64,7)="2026-08")*('Slaughterhouse IQC'!$B$6:$B$64="Nahunta")*('Slaughterhouse IQC'!$F$6:$F$64="666521")*'Slaughterhouse IQC'!$K$6:$K$64)) -> 49 | G20: =SUMPRODUCT(('Slaughterhouse IQC'!$B$6:$B$64="Nahunta")*('Slaughterhouse IQC'!$F$6:$F$64="666521")*'Slaughterhouse IQC'!$K$6:$K$64) -> 62
A22: PELVIC @ MARTINS — 666541 (intact)
A23: Metric | B23: April | C23: May | D23: June | E23: July | F23: August | G23: Total
A24: # Inspected | B24: =IF(SUMPRODUCT((LEFT('Slaughterhouse IQC'!$A$6:$A$64,7)="2026-04")*('Slaughterhouse IQC'!$B$6:$B$64="Martins")*('Slaughterhouse IQC'!$F$6:$F$64="666541")*'Slaughterhouse IQC'!$I$6:$I$64)=0,"",SUMPRODUCT((LEFT('Slaughterhouse IQC'!$A$6:$A$64,7)="2026-04")*('Slaughterhouse IQC'!$B$6:$B$64="Martins")*('Slaughterhouse IQC'!$F$6:$F$64="666541")*'Slaughterhouse IQC'!$I$6:$I$64)) -> 122 | C24: =IF(SUMPRODUCT((LEFT('Slaughterhouse IQC'!$A$6:$A$64,7)="2026-05")*('Slaughterhouse IQC'!$B$6:$B$64="Martins")*('Slaughterhouse IQC'!$F$6:$F$64="666541")*'Slaughterhouse IQC'!$I$6:$I$64)=0,"",SUMPRODUCT((LEFT('Slaughterhouse IQC'!$A$6:$A$64,7)="2026-05")*('Slaughterhouse IQC'!$B$6:$B$64="Martins")*('Slaughterhouse IQC'!$F$6:$F$64="666541")*'Slaughterhouse IQC'!$I$6:$I$64)) -> 194 | D24: =IF(SUMPRODUCT((LEFT('Slaughterhouse IQC'!$A$6:$A$64,7)="2026-06")*('Slaughterhouse IQC'!$B$6:$B$64="Martins")*('Slaughterhouse IQC'!$F$6:$F$64="666541")*'Slaughterhouse IQC'!$I$6:$I$64)=0,"",SUMPRODUCT((LEFT('Slaughterhouse IQC'!$A$6:$A$64,7)="2026-06")*('Slaughterhouse IQC'!$B$6:$B$64="Martins")*('Slaughterhouse IQC'!$F$6:$F$64="666541")*'Slaughterhouse IQC'!$I$6:$I$64)) -> 152 | E24: =IF(SUMPRODUCT((LEFT('Slaughterhouse IQC'!$A$6:$A$64,7)="2026-07")*('Slaughterhouse IQC'!$B$6:$B$64="Martins")*('Slaughterhouse IQC'!$F$6:$F$64="666541")*'Slaughterhouse IQC'!$I$6:$I$64)=0,"",SUMPRODUCT((LEFT('Slaughterhouse IQC'!$A$6:$A$64,7)="2026-07")*('Slaughterhouse IQC'!$B$6:$B$64="Martins")*('Slaughterhouse IQC'!$F$6:$F$64="666541")*'Slaughterhouse IQC'!$I$6:$I$64)) -> 161 | F24: =IF(SUMPRODUCT((LEFT('Slaughterhouse IQC'!$A$6:$A$64,7)="2026-08")*('Slaughterhouse IQC'!$B$6:$B$64="Martins")*('Slaughterhouse IQC'!$F$6:$F$64="666541")*'Slaughterhouse IQC'!$I$6:$I$64)=0,"",SUMPRODUCT((LEFT('Slaughterhouse IQC'!$A$6:$A$64,7)="2026-08")*('Slaughterhouse IQC'!$B$6:$B$64="Martins")*('Slaughterhouse IQC'!$F$6:$F$64="666541")*'Slaughterhouse IQC'!$I$6:$I$64)) -> 137 | G24: =SUM(B24:F24) -> 766
A25: # Pass | B25: =IF(SUMPRODUCT((LEFT('Slaughterhouse IQC'!$A$6:$A$64,7)="2026-04")*('Slaughterhouse IQC'!$B$6:$B$64="Martins")*('Slaughterhouse IQC'!$F$6:$F$64="666541")*'Slaughterhouse IQC'!$I$6:$I$64)=0,"",SUMPRODUCT((LEFT('Slaughterhouse IQC'!$A$6:$A$64,7)="2026-04")*('Slaughterhouse IQC'!$B$6:$B$64="Martins")*('Slaughterhouse IQC'!$F$6:$F$64="666541")*'Slaughterhouse IQC'!$J$6:$J$64)) -> 116 | C25: =IF(SUMPRODUCT((LEFT('Slaughterhouse IQC'!$A$6:$A$64,7)="2026-05")*('Slaughterhouse IQC'!$B$6:$B$64="Martins")*('Slaughterhouse IQC'!$F$6:$F$64="666541")*'Slaughterhouse IQC'!$I$6:$I$64)=0,"",SUMPRODUCT((LEFT('Slaughterhouse IQC'!$A$6:$A$64,7)="2026-05")*('Slaughterhouse IQC'!$B$6:$B$64="Martins")*('Slaughterhouse IQC'!$F$6:$F$64="666541")*'Slaughterhouse IQC'!$J$6:$J$64)) -> 181 | D25: =IF(SUMPRODUCT((LEFT('Slaughterhouse IQC'!$A$6:$A$64,7)="2026-06")*('Slaughterhouse IQC'!$B$6:$B$64="Martins")*('Slaughterhouse IQC'!$F$6:$F$64="666541")*'Slaughterhouse IQC'!$I$6:$I$64)=0,"",SUMPRODUCT((LEFT('Slaughterhouse IQC'!$A$6:$A$64,7)="2026-06")*('Slaughterhouse IQC'!$B$6:$B$64="Martins")*('Slaughterhouse IQC'!$F$6:$F$64="666541")*'Slaughterhouse IQC'!$J$6:$J$64)) -> 144 | E25: =IF(SUMPRODUCT((LEFT('Slaughterhouse IQC'!$A$6:$A$64,7)="2026-07")*('Slaughterhouse IQC'!$B$6:$B$64="Martins")*('Slaughterhouse IQC'!$F$6:$F$64="666541")*'Slaughterhouse IQC'!$I$6:$I$64)=0,"",SUMPRODUCT((LEFT('Slaughterhouse IQC'!$A$6:$A$64,7)="2026-07")*('Slaughterhouse IQC'!$B$6:$B$64="Martins")*('Slaughterhouse IQC'!$F$6:$F$64="666541")*'Slaughterhouse IQC'!$J$6:$J$64)) -> 155 | F25: =IF(SUMPRODUCT((LEFT('Slaughterhouse IQC'!$A$6:$A$64,7)="2026-08")*('Slaughterhouse IQC'!$B$6:$B$64="Martins")*('Slaughterhouse IQC'!$F$6:$F$64="666541")*'Slaughterhouse IQC'!$I$6:$I$64)=0,"",SUMPRODUCT((LEFT('Slaughterhouse IQC'!$A$6:$A$64,7)="2026-08")*('Slaughterhouse IQC'!$B$6:$B$64="Martins")*('Slaughterhouse IQC'!$F$6:$F$64="666541")*'Slaughterhouse IQC'!$J$6:$J$64)) -> 132 | G25: =SUM(B25:F25) -> 728
A26: # Fail | B26: =IF(SUMPRODUCT((LEFT('Slaughterhouse IQC'!$A$6:$A$64,7)="2026-04")*('Slaughterhouse IQC'!$B$6:$B$64="Martins")*('Slaughterhouse IQC'!$F$6:$F$64="666541")*'Slaughterhouse IQC'!$I$6:$I$64)=0,"",SUMPRODUCT((LEFT('Slaughterhouse IQC'!$A$6:$A$64,7)="2026-04")*('Slaughterhouse IQC'!$B$6:$B$64="Martins")*('Slaughterhouse IQC'!$F$6:$F$64="666541")*'Slaughterhouse IQC'!$K$6:$K$64)) -> 6 | C26: =IF(SUMPRODUCT((LEFT('Slaughterhouse IQC'!$A$6:$A$64,7)="2026-05")*('Slaughterhouse IQC'!$B$6:$B$64="Martins")*('Slaughterhouse IQC'!$F$6:$F$64="666541")*'Slaughterhouse IQC'!$I$6:$I$64)=0,"",SUMPRODUCT((LEFT('Slaughterhouse IQC'!$A$6:$A$64,7)="2026-05")*('Slaughterhouse IQC'!$B$6:$B$64="Martins")*('Slaughterhouse IQC'!$F$6:$F$64="666541")*'Slaughterhouse IQC'!$K$6:$K$64)) -> 13 | D26: =IF(SUMPRODUCT((LEFT('Slaughterhouse IQC'!$A$6:$A$64,7)="2026-06")*('Slaughterhouse IQC'!$B$6:$B$64="Martins")*('Slaughterhouse IQC'!$F$6:$F$64="666541")*'Slaughterhouse IQC'!$I$6:$I$64)=0,"",SUMPRODUCT((LEFT('Slaughterhouse IQC'!$A$6:$A$64,7)="2026-06")*('Slaughterhouse IQC'!$B$6:$B$64="Martins")*('Slaughterhouse IQC'!$F$6:$F$64="666541")*'Slaughterhouse IQC'!$K$6:$K$64)) -> 8 | E26: =IF(SUMPRODUCT((LEFT('Slaughterhouse IQC'!$A$6:$A$64,7)="2026-07")*('Slaughterhouse IQC'!$B$6:$B$64="Martins")*('Slaughterhouse IQC'!$F$6:$F$64="666541")*'Slaughterhouse IQC'!$I$6:$I$64)=0,"",SUMPRODUCT((LEFT('Slaughterhouse IQC'!$A$6:$A$64,7)="2026-07")*('Slaughterhouse IQC'!$B$6:$B$64="Martins")*('Slaughterhouse IQC'!$F$6:$F$64="666541")*'Slaughterhouse IQC'!$K$6:$K$64)) -> 6 | F26: =IF(SUMPRODUCT((LEFT('Slaughterhouse IQC'!$A$6:$A$64,7)="2026-08")*('Slaughterhouse IQC'!$B$6:$B$64="Martins")*('Slaughterhouse IQC'!$F$6:$F$64="666541")*'Slaughterhouse IQC'!$I$6:$I$64)=0,"",SUMPRODUCT((LEFT('Slaughterhouse IQC'!$A$6:$A$64,7)="2026-08")*('Slaughterhouse IQC'!$B$6:$B$64="Martins")*('Slaughterhouse IQC'!$F$6:$F$64="666541")*'Slaughterhouse IQC'!$K$6:$K$64)) -> 5 | G26: =SUM(B26:F26) -> 38
A27: First-Pass Yield | B27: =IF(B24="","",IF(B24=0,"",B25/B24)) -> 0.95081967 | C27: =IF(C24="","",IF(C24=0,"",C25/C24)) -> 0.93298969 | D27: =IF(D24="","",IF(D24=0,"",D25/D24)) -> 0.94736842 | E27: =IF(E24="","",IF(E24=0,"",E25/E24)) -> 0.96273292 | F27: =IF(F24="","",IF(F24=0,"",F25/F24)) -> 0.96350365 | G27: =IF(G24=0,"",G25/G24) -> 0.95039164
A28: Issues found (defect category counts)
A29: Urethra / bladder damage | B29: 2 | C29: 9 | D29: 4 | E29: 3 | F29: 2 | G29: 20
A30: Membrane damage | C30: 2 | D30: 3 | E30: 2 | F30: 1 | G30: 8
A31: Bowel damage / separation | B31: 2 | C31: 1 | D31: 1 | F31: 2 | G31: 6
A32: Short block / mesentery length | C32: 1 | G32: 1
A33: Other / unspecified | B33: 2 | E33: 1 | G33: 3
A34: Total issues | B34: =IF(SUM(B29:B33)=0,"",SUM(B29:B33)) -> 6 | C34: =IF(SUM(C29:C33)=0,"",SUM(C29:C33)) -> 13 | D34: =IF(SUM(D29:D33)=0,"",SUM(D29:D33)) -> 8 | E34: =IF(SUM(E29:E33)=0,"",SUM(E29:E33)) -> 6 | F34: =IF(SUM(F29:F33)=0,"",SUM(F29:F33)) -> 5 | G34: =SUM(G29:G33) -> 38
A36: PELVIC @ MARTINS — 666506 (non-intact)
A37: Metric | B37: April | C37: May | D37: June | E37: July | F37: August | G37: Total
A38: # Inspected | B38: =IF(SUMPRODUCT((LEFT('Slaughterhouse IQC'!$A$6:$A$64,7)="2026-04")*('Slaughterhouse IQC'!$B$6:$B$64="Martins")*('Slaughterhouse IQC'!$F$6:$F$64="666506")*'Slaughterhouse IQC'!$I$6:$I$64)=0,"",SUMPRODUCT((LEFT('Slaughterhouse IQC'!$A$6:$A$64,7)="2026-04")*('Slaughterhouse IQC'!$B$6:$B$64="Martins")*('Slaughterhouse IQC'!$F$6:$F$64="666506")*'Slaughterhouse IQC'!$I$6:$I$64)) -> 59 | C38: =IF(SUMPRODUCT((LEFT('Slaughterhouse IQC'!$A$6:$A$64,7)="2026-05")*('Slaughterhouse IQC'!$B$6:$B$64="Martins")*('Slaughterhouse IQC'!$F$6:$F$64="666506")*'Slaughterhouse IQC'!$I$6:$I$64)=0,"",SUMPRODUCT((LEFT('Slaughterhouse IQC'!$A$6:$A$64,7)="2026-05")*('Slaughterhouse IQC'!$B$6:$B$64="Martins")*('Slaughterhouse IQC'!$F$6:$F$64="666506")*'Slaughterhouse IQC'!$I$6:$I$64)) -> 118 | D38: =IF(SUMPRODUCT((LEFT('Slaughterhouse IQC'!$A$6:$A$64,7)="2026-06")*('Slaughterhouse IQC'!$B$6:$B$64="Martins")*('Slaughterhouse IQC'!$F$6:$F$64="666506")*'Slaughterhouse IQC'!$I$6:$I$64)=0,"",SUMPRODUCT((LEFT('Slaughterhouse IQC'!$A$6:$A$64,7)="2026-06")*('Slaughterhouse IQC'!$B$6:$B$64="Martins")*('Slaughterhouse IQC'!$F$6:$F$64="666506")*'Slaughterhouse IQC'!$I$6:$I$64)) -> 53 | E38: =IF(SUMPRODUCT((LEFT('Slaughterhouse IQC'!$A$6:$A$64,7)="2026-07")*('Slaughterhouse IQC'!$B$6:$B$64="Martins")*('Slaughterhouse IQC'!$F$6:$F$64="666506")*'Slaughterhouse IQC'!$I$6:$I$64)=0,"",SUMPRODUCT((LEFT('Slaughterhouse IQC'!$A$6:$A$64,7)="2026-07")*('Slaughterhouse IQC'!$B$6:$B$64="Martins")*('Slaughterhouse IQC'!$F$6:$F$64="666506")*'Slaughterhouse IQC'!$I$6:$I$64)) -> 79 | F38: =IF(SUMPRODUCT((LEFT('Slaughterhouse IQC'!$A$6:$A$64,7)="2026-08")*('Slaughterhouse IQC'!$B$6:$B$64="Martins")*('Slaughterhouse IQC'!$F$6:$F$64="666506")*'Slaughterhouse IQC'!$I$6:$I$64)=0,"",SUMPRODUCT((LEFT('Slaughterhouse IQC'!$A$6:$A$64,7)="2026-08")*('Slaughterhouse IQC'!$B$6:$B$64="Martins")*('Slaughterhouse IQC'!$F$6:$F$64="666506")*'Slaughterhouse IQC'!$I$6:$I$64)) -> 13 | G38: =SUM(B38:F38) -> 322
A39: # Pass | B39: =IF(SUMPRODUCT((LEFT('Slaughterhouse IQC'!$A$6:$A$64,7)="2026-04")*('Slaughterhouse IQC'!$B$6:$B$64="Martins")*('Slaughterhouse IQC'!$F$6:$F$64="666506")*'Slaughterhouse IQC'!$I$6:$I$64)=0,"",SUMPRODUCT((LEFT('Slaughterhouse IQC'!$A$6:$A$64,7)="2026-04")*('Slaughterhouse IQC'!$B$6:$B$64="Martins")*('Slaughterhouse IQC'!$F$6:$F$64="666506")*'Slaughterhouse IQC'!$J$6:$J$64)) -> 55 | C39: =IF(SUMPRODUCT((LEFT('Slaughterhouse IQC'!$A$6:$A$64,7)="2026-05")*('Slaughterhouse IQC'!$B$6:$B$64="Martins")*('Slaughterhouse IQC'!$F$6:$F$64="666506")*'Slaughterhouse IQC'!$I$6:$I$64)=0,"",SUMPRODUCT((LEFT('Slaughterhouse IQC'!$A$6:$A$64,7)="2026-05")*('Slaughterhouse IQC'!$B$6:$B$64="Martins")*('Slaughterhouse IQC'!$F$6:$F$64="666506")*'Slaughterhouse IQC'!$J$6:$J$64)) -> 112 | D39: =IF(SUMPRODUCT((LEFT('Slaughterhouse IQC'!$A$6:$A$64,7)="2026-06")*('Slaughterhouse IQC'!$B$6:$B$64="Martins")*('Slaughterhouse IQC'!$F$6:$F$64="666506")*'Slaughterhouse IQC'!$I$6:$I$64)=0,"",SUMPRODUCT((LEFT('Slaughterhouse IQC'!$A$6:$A$64,7)="2026-06")*('Slaughterhouse IQC'!$B$6:$B$64="Martins")*('Slaughterhouse IQC'!$F$6:$F$64="666506")*'Slaughterhouse IQC'!$J$6:$J$64)) -> 52 | E39: =IF(SUMPRODUCT((LEFT('Slaughterhouse IQC'!$A$6:$A$64,7)="2026-07")*('Slaughterhouse IQC'!$B$6:$B$64="Martins")*('Slaughterhouse IQC'!$F$6:$F$64="666506")*'Slaughterhouse IQC'!$I$6:$I$64)=0,"",SUMPRODUCT((LEFT('Slaughterhouse IQC'!$A$6:$A$64,7)="2026-07")*('Slaughterhouse IQC'!$B$6:$B$64="Martins")*('Slaughterhouse IQC'!$F$6:$F$64="666506")*'Slaughterhouse IQC'!$J$6:$J$64)) -> 77 | F39: =IF(SUMPRODUCT((LEFT('Slaughterhouse IQC'!$A$6:$A$64,7)="2026-08")*('Slaughterhouse IQC'!$B$6:$B$64="Martins")*('Slaughterhouse IQC'!$F$6:$F$64="666506")*'Slaughterhouse IQC'!$I$6:$I$64)=0,"",SUMPRODUCT((LEFT('Slaughterhouse IQC'!$A$6:$A$64,7)="2026-08")*('Slaughterhouse IQC'!$B$6:$B$64="Martins")*('Slaughterhouse IQC'!$F$6:$F$64="666506")*'Slaughterhouse IQC'!$J$6:$J$64)) -> 13 | G39: =SUM(B39:F39) -> 309
