Workbook
Name YLC: 'Yields-Labor-Cube'!$A$22:$O$54

Sheet Part_Model
A2: Part / Supplier Information | K2: Operations | T2: Quality | AO2: Relationship | AX2: Financial | BD2: Other:
K3: Capacity | T3: Certifications | X3: Part Quality | AC3: Compliance | BD3: Geopolitical | BH3: Distuption Risk | BL3: Cybersecurity
A4: Original_Part_Number | B4: Supplier_part_# | C4: Part_Description | D4: Supplier_Name | E4: Supplier_ATM# | F4: Intuitive# | G4: Material_Category | H4: Supplier_Status | K4: T-max | L4: Intuitive_Demand | M4: Non_Intuitive_Demand | N4: C_Utilization | O4: Headroom | P4: Procurement Lead time | Q4: Production Lead time | R4: Operational Notes | T4: ISO_9001 | U4: ISO 9001 expiration | V4: ISO_13485 | W4: ISO 13485 expiration | X4: Cpk_Index | Y4: Metrology_Tier | Z4: PPM_Actual_Defects | AA4: Quality_Trend | AB4: EOL_Risk | AC4: Inventory_Agreement | AD4: NDA | AE4: Rent_Agreement | AF4: SQA_Agreement | AG4: REACH_Compliant | AH4: Last_Audit_Date | AI4: Surveillance_Status | AJ4: Audit_Report_668522 (506) | AK4: Open_CAPAs | AL4: Quality_Notes | AO4: Relationship_Strength | AP4: Responsiveness | AQ4: Source_Dependency | AR4: Backup_Qualified | AS4: Replacement Time | AT4: Business_Years | AU4: Volume_Significance | AV4: Relationship_Notes | AX4: Annual_Spend | AY4: Business_Continuity | AZ4: Part_Price | BA4: Price_Sensitivity | BB4: Financial_Notes | BD4: Country | BE4: Region | BF4: Geographical_Risk | BG4: Geopolitical_Risk | BH4: Disruption_Risk | BI4: Cold_Chain Capable | BJ4: TTR_weeks | BK4: TTS_weeks | BL4: Data_access_level | BN4: Scoring after approved by Arsh
A5: 666438 | C5: LIQ,SB AQUEOUS MIXTURE | D5: SNP, inc | E5: 52 | G5: Non-Tissue: Significant
C6: LIQ,SB AQUEOUS MIXTURE | D6: Brentagg | H6: New
A7: 666800-01 | C7: PLATE,THERMOFORMED,KYDEX,UNIVERSAL | D7: Advanced Plastiform | E7: 45 | G7: Non-Tissue: Significant | L7: 8000 | P7: 8 weeks
C8: PLATE,THERMOFORMED,KYDEX,UNIVERSAL | D8: Midland Plastics | H8: New
D9: Fictiv
D10: Procision
C11: Touchstone 3d (very small) | E11: 6
C12: Xometry
O14: =IFERROR(IF(#REF!>0,((#REF!-$L14)+$L14)/$L14,""),"")
O15: =IFERROR(IF(#REF!>0,((#REF!-$L15)+$L15)/$L15,""),"")
O16: =IFERROR(IF(#REF!>0,((#REF!-$L16)+$L16)/$L16,""),"")
O17: =IFERROR(IF(#REF!>0,((#REF!-$L17)+$L17)/$L17,""),"")
O18: =IFERROR(IF(#REF!>0,((#REF!-$L18)+$L18)/$L18,""),"")
O19: =IFERROR(IF(#REF!>0,((#REF!-$L19)+$L19)/$L19,""),"")
O20: =IFERROR(IF(#REF!>0,((#REF!-$L20)+$L20)/$L20,""),"")
O21: =IFERROR(IF(#REF!>0,((#REF!-$L21)+$L21)/$L21,""),"")
O22: =IFERROR(IF(#REF!>0,((#REF!-$L22)+$L22)/$L22,""),"")
O23: =IFERROR(IF(#REF!>0,((#REF!-$L23)+$L23)/$L23,""),"")
O24: =IFERROR(IF(#REF!>0,((#REF!-$L24)+$L24)/$L24,""),"")
O25: =IFERROR(IF(#REF!>0,((#REF!-$L25)+$L25)/$L25,""),"")
... O52: =IFERROR(IF(#REF!>0,((#REF!-$L52)+$L52)/$L52,""),"")
N53: =IFERROR(IF(#REF!>0,((#REF!-#REF!)+#REF!)/#REF!,""),"")

Sheet Tissue_Model
A1: Q4'26 BP | K1: *Prone to changing over the year due to seasonality | N1: Bad part Time: | O1: 7
A2: Part / Supplier Information | L2: Size%*Gender% | O2: Yielded | AI2: Quality | AX2: Relationship | BI2: Financial | BO2: Other:
K3: Seasonality* | L3: Seasonality* | O3: Gross | X3: Quality Yield | AI3: Regulations | BO3: Geopolitical | BS3: Distuption Risk | BW3: Cybersecurity
A4: Original_Part_Number | B4: Supplier_part_# | C4: Part_Description | D4: Supplier_Name | E4: Supplier_ATM# | F4: Intuitive# | G4: Material_Category | H4: Supplier_Status | I4: Tier | J4: Weekly Harvest Net | K4: Kill Throughput | L4: SH Spec / Process Yield | M4: SH Gross Thru | N4: INT Harvesting yield | O4: Pigs Consumed | P4: Pigs Cap | Q4: Planned Labor | R4: Labor Cap | S4: Labor Utilization | T4: Freezer Cube | U4: Freezer Cap | V4: Trips | W4: Freezer Cap | X4: FreezeThaw Yield | Y4: Ops Ready Thru | Z4: HeadRoom Pigs | AA4: HeadRoom Labor | AB4: Headroom Freezer | AC4: Headroom | AI4: Specimen Permit valid? | AJ4: Specimen Permit Expiration | AK4: APHIS_Compliant | AL4: FSIS_Inspection_Level | AM4: ISO_9001 | AN4: ISO 9001 expiration | AO4: NDA | AP4: Rent_Agreement | AQ4: SQA_Agreement | AR4: Last_Audit_Date | AS4: Surveillance_Status | AT4: Audit_Report_668522 (506) | AU4: Open_CAPAs | AV4: Quality_Notes | AX4: Relationship_Strength | AY4: Responsiveness | AZ4: Source_Dependency | BA4: Backup_Qualified | BB4: Business_Years | BC4: Cost of Change | BD4: Volume_Significance | BE4: Relationship_Notes | BI4: Annual_Spend | BJ4: Business_Continuity | BK4: Part_Price | BL4: Price_Sensitivity | BM4: Financial_Notes | BO4: Country | BP4: Region | BQ4: Geographical_Risk | BR4: Geopolitical_Risk | BS4: Disruption_Risk | BT4: Cold_Chain Capable | BU4: TTR_weeks | BV4: TTS_weeks | BW4: Data_access_level
A5: =Martins!Y20 -> 666501 | B5: =IF(A5="", "", A5 & "/" & E5) -> 666501/28 | C5: =VLOOKUP(A5,YLC,2,FALSE) -> TISS,PORCINE,AORTA SEGMENTS | D5: Martins Pork Products | E5: 28 | G5: Tissue (APHIS) | H5: Approved | I5: =VLOOKUP(A5,YLC,5,FALSE) -> 3 | J5: =VLOOKUP(A5,Martins!$C$20:$O$44,9,FALSE) -> 217 | K5: =Martins!$D$6 -> 2500 | L5: =VLOOKUP(A5,Martins!$C$20:$AC$44,14,FALSE) -> 0.99 | M5: =K5*L5 -> 2475 | N5: =VLOOKUP(A5,Martins!$C$20:$AC$40,15,FALSE) -> 0.95 | O5: =ROUND($J5*VLOOKUP(A5,Martins!$C$20:$O$40,10,0)/N5,0) -> 228 | P5: =O5/M5 -> 0.092121212 | Q5: =$J5*VLOOKUP($A5,'Yields-Labor-Cube'!$A$24:$O$46,3,FALSE)/(60)+(O5-J5*VLOOKUP(A5,'Yields-Labor-Cube'!$A$22:$O$46,14,FALSE))*$O$1/360 -> 3.8305556 | R5: =Martins!$L$58*5 -> 36 | S5: =Q5/R5 -> 0.10640432 | T5: =$J5*VLOOKUP($A5,'Yields-Labor-Cube'!$A$22:$O$46,4,FALSE) -> 10.85 | U5: =Martins!$O$48 -> 240 | V5: 2 | W5: =T5/(U5*V5) -> 0.022604167 | X5: =VLOOKUP($A5,'Yields-Labor-Cube'!$A$22:$O$46,15,FALSE) -> 0.95 | Y5: =ROUND(X5*J5,0) -> 206 | Z5: =1/P5 -> 10.855263 | AA5: =1/S5 -> 9.3981146 | AB5: =1/W5 -> 44.239631 | AC5: =MIN(Z5:AB5) -> 9.3981146 | AI5: Yes | AK5: Yes | AL5: FDA FSIS Inspected | AM5: No | AO5: Yes | AP5: No | AQ5: No | AS5: Waived | AX5: 4 | AY5: 5 | AZ5: Multi | BA5: Yes | BB5: 3.5 | BD5: N/A | BI5: 200000 | BJ5: Yes | BL5: N/A | BO5: USA | BW5: None
A6: =Martins!Y21 -> 666541 | B6: =IF(A6="", "", A6 & "/" & E6) -> 666541/28 | C6: =VLOOKUP(A6,YLC,2,FALSE) -> FEMALE PELVIC BLOCK | D6: Martins Pork Products | E6: 28 | G6: Tissue (APHIS) | H6: Approved | I6: =VLOOKUP(A6,YLC,5,FALSE) -> 2 | J6: =VLOOKUP(A6,Martins!$C$20:$O$44,9,FALSE) -> 164 | K6: =Martins!$D$6 -> 2500 | L6: =VLOOKUP(A6,Martins!$C$20:$AC$44,14,FALSE) -> 0.45 | M6: =K6*L6 -> 1125 | N6: =VLOOKUP(A6,Martins!$C$20:$AC$40,15,FALSE) -> 0.25 | O6: =ROUND($J6*VLOOKUP(A6,Martins!$C$20:$O$40,10,0)/N6,0) -> 656 | P6: =SUM(O6)/M6 -> 0.58311111 | Q6: =$J6*VLOOKUP($A6,'Yields-Labor-Cube'!$A$24:$O$46,3,FALSE)/(60)+(O6-J6*VLOOKUP(A6,'Yields-Labor-Cube'!$A$22:$O$46,14,FALSE))*$O$1/360 -> 17.766667 | R6: =Martins!$L$58*5 -> 36 | S6: =SUM(Q5:Q6)/R6 -> 0.59992284 | T6: =$J6*VLOOKUP($A6,'Yields-Labor-Cube'!$A$22:$O$46,4,FALSE) -> 164 | U6: =Martins!$O$48 -> 240 | V6: 2 | W6: =SUM(T5:T6)/(U6*V6) -> 0.36427083 | X6: =VLOOKUP($A6,'Yields-Labor-Cube'!$A$22:$O$46,15,FALSE) -> 0.85 | Y6: =ROUND(X6*J6,0) -> 139 | Z6: =1/P6 -> 1.714939 | AA6: =1/S6 -> 1.666881 | AB6: =1/W6 -> 2.7452102 | AC6: =MIN(Z6:AB6) -> 1.666881 | AI6: Yes | AK6: Yes | AL6: FDA FSIS Inspected | AM6: No | AO6: Yes | AP6: Yes | AQ6: No | AS6: Waived | AX6: 2 | AY6: 2 | AZ6: Multi | BA6: Yes | BB6: 3.7 | BD6: N/A | BI6: 265000 | BJ6: Yes | BL6: N/A | BO6: USA | BS6: Due to Geopolitical or Geographic | BU6: Total weeks to recovery | BV6: Total weeks of safety stock | BW6: None
A7: =Martins!Y22 -> 666502 | B7: =IF(A7="", "", A7 & "/" & E7) -> 666502/28 | C7: =VLOOKUP(A7,YLC,2,FALSE) -> TISS,PORCINE,BARIATRIC BLOCK | D7: Martins Pork Products | E7: 28 | G7: Tissue (APHIS) | H7: Approved | I7: =VLOOKUP(A7,YLC,5,FALSE) -> 3 | J7: =VLOOKUP(A7,Martins!$C$20:$O$44,9,FALSE) -> 125 | K7: =Martins!$D$6 -> 2500 | L7: =VLOOKUP(A7,Martins!$C$20:$AC$44,14,FALSE) -> 0.8 | M7: =K7*L7 -> 2000 | N7: =VLOOKUP(A7,Martins!$C$20:$AC$40,15,FALSE) -> 0.95 | O7: =ROUND($J7*VLOOKUP(A7,Martins!$C$20:$O$40,10,0)/N7,0) -> 132 | P7: =SUM(O5,O7)/M7 -> 0.18 | Q7: =$J7*VLOOKUP($A7,'Yields-Labor-Cube'!$A$24:$O$46,3,FALSE)/(60)+(O7-J7*VLOOKUP(A7,'Yields-Labor-Cube'!$A$22:$O$46,14,FALSE))*$O$1/360 -> 7.4277778 | R7: =Martins!$L$58*5 -> 36 | S7: =SUM(Q5:Q8)/R8 -> 0.8304784 | T7: =$J7*VLOOKUP($A7,'Yields-Labor-Cube'!$A$22:$O$46,4,FALSE) -> 187.5 | U7: =Martins!$O$48 -> 240 | V7: 2 | W7: =SUM(T5:T7)/(U7*V7) -> 0.75489583 | X7: =VLOOKUP($A7,'Yields-Labor-Cube'!$A$22:$O$46,15,FALSE) -> 0.9 | Y7: =ROUND(X7*J7,0) -> 113 | Z7: =1/P7 -> 5.5555556 | AA7: =1/S7 -> 1.2041252 | AB7: =1/W7 -> 1.3246861 | AC7: =MIN(Z7:AB7) -> 1.2041252 | AI7: Yes | AK7: Yes | AL7: FDA FSIS Inspected | AM7: No | AO7: Yes | AP7: Yes | AQ7: No | AS7: Waived | AX7: 3 | AY7: 5 | AZ7: Dual | BA7: Yes | BB7: 3 | BD7: N/A | BI7: 120000 | BJ7: Yes | BL7: N/A | BO7: USA | BW7: None
A8: =Martins!Y23 -> 666522 | B8: =IF(A8="", "", A8 & "/" & E8) -> 666522/28 | C8: =VLOOKUP(A8,YLC,2,FALSE) -> TISS,PORCINE,URETER | D8: Martins Pork Products | E8: 28 | G8: Tissue (APHIS) | H8: Approved | I8: =VLOOKUP(A8,YLC,5,FALSE) -> 2 | J8: =VLOOKUP(A8,Martins!$C$20:$O$44,9,FALSE) -> 86 | K8: =Martins!$D$6 -> 2500 | L8: =VLOOKUP(A8,Martins!$C$20:$AC$44,14,FALSE) -> 0.99 | M8: =K8*L8 -> 2475 | N8: =VLOOKUP(A8,Martins!$C$20:$AC$40,15,FALSE) -> 0.85 | O8: =ROUND($J8*VLOOKUP(A8,Martins!$C$20:$O$40,10,0)/N8,0) -> 51 | P8: =SUM(O8,O6)/M8 -> 0.28565657 | Q8: =$J8*VLOOKUP($A8,'Yields-Labor-Cube'!$A$24:$O$46,3,FALSE)/(60)+(O8-J8*VLOOKUP(A8,'Yields-Labor-Cube'!$A$22:$O$46,14,FALSE))*$O$1/360 -> 0.87222222 | R8: =Martins!$L$58*5 -> 36 | S8: =SUM(Q5:Q8)/R8 -> 0.8304784 | T8: =$J8*VLOOKUP($A8,'Yields-Labor-Cube'!$A$22:$O$46,4,FALSE) -> 8.6 | U8: =Martins!$O$48 -> 240 | V8: 2 | W8: =SUM(T5:T8)/(U8*V8) -> 0.7728125 | X8: =VLOOKUP($A8,'Yields-Labor-Cube'!$A$22:$O$46,15,FALSE) -> 0.8 | Y8: =ROUND(X8*J8,0) -> 69 | Z8: =1/P8 -> 3.5007072 | AA8: =1/S8 -> 1.2041252 | AB8: =1/W8 -> 1.2939749 | AC8: =MIN(Z8:AB8) -> 1.2041252 | AI8: Yes | AK8: Yes | AL8: FDA FSIS Inspected | AM8: No | AO8: Yes | AP8: Yes | AQ8: No | AS8: Waived | AX8: 2 | AY8: 2 | AZ8: Dual | BA8: Yes | BB8: 3.7 | BD8: N/A | BI8: 265000 | BJ8: Yes | BL8: N/A | BO8: USA | BW8: None
A9: =Martins!Y24 -> 666506 | B9: =IF(A9="", "", A9 & "/" & E9) -> 666506/28 | C9: =VLOOKUP(A9,YLC,2,FALSE) -> TISS,PORCINE,PELVIC BLOCK | D9: Martins Pork Products | E9: 28 | G9: Tissue (APHIS) | H9: Approved | I9: =VLOOKUP(A9,YLC,5,FALSE) -> 2 | J9: =VLOOKUP(A9,Martins!$C$20:$O$44,9,FALSE) -> 52 | K9: =Martins!$D$6 -> 2500 | L9: =VLOOKUP(A9,Martins!$C$20:$AC$44,14,FALSE) -> 0.45 | M9: =K9*L9 -> 1125 | N9: =VLOOKUP(A9,Martins!$C$20:$AC$40,15,FALSE) -> 0.25 | O9: =ROUND($J9*VLOOKUP(A9,Martins!$C$20:$O$40,10,0)/N9,0) -> 208 | P9: =SUM(O8,O9,O6)/M9 -> 0.81333333 | Q9: =$J9*VLOOKUP($A9,'Yields-Labor-Cube'!$A$24:$O$46,3,FALSE)/(60)+(O9-J9*VLOOKUP(A9,'Yields-Labor-Cube'!$A$22:$O$46,14,FALSE))*$O$1/360 -> 5.6333333 | R9: =Martins!$L$58*5 -> 36 | S9: =SUM(Q5:Q9)/R9 -> 0.98695988 | T9: =$J9*VLOOKUP($A9,'Yields-Labor-Cube'!$A$22:$O$46,4,FALSE) -> 52 | U9: =Martins!$O$48 -> 240 | V9: 2 | W9: =SUM(T5:T9)/(U9*V9) -> 0.88114583 | X9: =VLOOKUP($A9,'Yields-Labor-Cube'!$A$22:$O$46,15,FALSE) -> 0.85 | Y9: =ROUND(X9*J9,0) -> 44 | Z9: =1/P9 -> 1.2295082 | AA9: =1/S9 -> 1.0132124 | AB9: =1/W9 -> 1.1348859 | AC9: =MIN(Z9:AB9) -> 1.0132124 | AI9: N/A | AK9: N/A | AL9: N/A | AM9: Yes | AO9: Yes | AP9: N/A | AQ9: Yes | AS9: Waived | AX9: 4 | AY9: 4 | AZ9: Single | BA9: No | BD9: Intuitive Demand/ Total Demand | BJ9: Yes | BK9: 23 | BL9: <50% | BO9: USA | BW9: Drawings
O13: Total: | P13: =MAX(P5:P10) -> 0.81333333 | S13: =MAX(S5:S10) -> 0.98695988 | W13: =MAX(W5:W10) -> 0.88114583
AY19: Lead time to find another supplier
A20: =Nahunta!Y20 -> 666522 | B20: =IF(A20="", "", A20 & "/" & E20) -> 666522/29 | C20: =VLOOKUP(A20,'Yields-Labor-Cube'!$A$24:$D$44,2,FALSE) -> TISS,PORCINE,URETER | D20: Nahunta | E20: 29 | G20: Tissue (APHIS) | H20: Approved | I20: =VLOOKUP(A20,'Yields-Labor-Cube'!$A$24:$E$46,5,FALSE) -> 2 | J20: =VLOOKUP(A20,Nahunta!$C$20:$O$44,9,FALSE) -> 57 | K20: 200 | L20: =VLOOKUP(A20,Nahunta!$C$20:$AC$44,14,FALSE) -> 0.99 | M20: =K20*L20 -> 198 | N20: =VLOOKUP(A20,Nahunta!$C$20:$AC$44,15,FALSE) -> 0.85 | O20: =ROUND($J20*VLOOKUP(A20,Nahunta!$C$20:$O$44,10,0)/N20,0) -> 34 | P20: =O20/M20 -> 0.17171717 | Q20: =$J20*VLOOKUP($A20,'Yields-Labor-Cube'!$A$24:$O$46,3,FALSE)/(60)+(O20-J20*VLOOKUP(A20,'Yields-Labor-Cube'!$A$22:$O$46,14,FALSE))*$O$1/360 -> 0.58194444 | R20: =Nahunta!$L$58*4 -> 21 | S20: =Q20/R20 -> 0.02771164 | T20: =$J20*VLOOKUP($A20,YLC,4,FALSE) -> 5.7 | U20: =Nahunta!$O$48 -> 240 | V20: 1 | W20: =T20/(U20*V20) -> 0.02375 | X20: =VLOOKUP($A20,'Yields-Labor-Cube'!$A$22:$O$46,15,FALSE) -> 0.8 | Y20: =ROUND(X20*J20,0) -> 46 | Z20: =1/P20 -> 5.8235294 | AA20: =1/S20 -> 36.085919 | AB20: =1/W20 -> 42.105263 | AC20: =MIN(Z20:AB20) -> 5.8235294 | AY20: Inventory insurance for change of supplier
A21: =Nahunta!Y21 -> 666509 | B21: =IF(A21="", "", A21 & "/" & E21) -> 666509/29 | C21: =VLOOKUP(A21,'Yields-Labor-Cube'!$A$24:$D$44,2,FALSE) -> TISS,PORCINE,JEJUNUM,6FT | D21: Nahunta | E21: 29 | G21: Tissue (APHIS) | H21: Approved | I21: =VLOOKUP(A21,'Yields-Labor-Cube'!$A$24:$E$46,5,FALSE) -> 1 | J21: =VLOOKUP(A21,Nahunta!$C$20:$O$44,9,FALSE) -> 32 | K21: 200 | L21: =VLOOKUP(A21,Nahunta!$C$20:$AC$44,14,FALSE) -> 0.95 | M21: =K21*L21 -> 190 | N21: =VLOOKUP(A21,Nahunta!$C$20:$AC$44,15,FALSE) -> 0.95 | O21: =ROUND($J21*VLOOKUP(A21,Nahunta!$C$20:$O$44,10,0)/N21,0) -> 17 | P21: =SUM(O21)/M21 -> 0.089473684 | Q21: =$J21*VLOOKUP($A21,'Yields-Labor-Cube'!$A$24:$O$46,3,FALSE)/(60)+(O21-J21*VLOOKUP(A21,'Yields-Labor-Cube'!$A$22:$O$46,14,FALSE))*$O$1/360 -> 2.1527778 | R21: =Nahunta!$L$58*4 -> 21 | S21: =SUM(Q20:Q21)/R21 -> 0.13022487 | T21: =$J21*VLOOKUP($A21,YLC,4,FALSE) -> 16 | U21: =Nahunta!$O$48 -> 240 | V21: 1 | W21: =SUM(T20:T21)/(U21*V21) -> 0.090416667 | X21: =VLOOKUP($A21,'Yields-Labor-Cube'!$A$22:$O$46,15,FALSE) -> 0.85 | Y21: =ROUND(X21*J21,0) -> 27 | Z21: =1/P21 -> 11.176471 | AA21: =1/S21 -> 7.6790249 | AB21: =1/W21 -> 11.059908 | AC21: =MIN(Z21:AB21) -> 7.6790249
A22: =Nahunta!Y22 -> 666501 | B22: =IF(A22="", "", A22 & "/" & E22) -> 666501/29 | C22: =VLOOKUP(A22,'Yields-Labor-Cube'!$A$24:$D$44,2,FALSE) -> TISS,PORCINE,AORTA SEGMENTS | D22: Nahunta | E22: 29 | G22: Tissue (APHIS) | H22: Approved | I22: =VLOOKUP(A22,'Yields-Labor-Cube'!$A$24:$E$46,5,FALSE) -> 3 | J22: =VLOOKUP(A22,Nahunta!$C$20:$O$44,9,FALSE) -> 23 | K22: 200 | L22: =VLOOKUP(A22,Nahunta!$C$20:$AC$44,14,FALSE) -> 0.99 | M22: =K22*L22 -> 198 | N22: =VLOOKUP(A22,Nahunta!$C$20:$AC$44,15,FALSE) -> 0.95 | O22: =ROUND($J22*VLOOKUP(A22,Nahunta!$C$20:$O$44,10,0)/N22,0) -> 24 | P22: =SUM(O22)/M22 -> 0.12121212 | Q22: =$J22*VLOOKUP($A22,'Yields-Labor-Cube'!$A$24:$O$46,3,FALSE)/(60)+(O22-J22*VLOOKUP(A22,'Yields-Labor-Cube'!$A$22:$O$46,14,FALSE))*$O$1/360 -> 0.40277778 | R22: =Nahunta!$L$58*4 -> 21 | S22: =SUM(Q20:Q22)/R22 -> 0.14940476 | T22: =$J22*VLOOKUP($A22,YLC,4,FALSE) -> 1.15 | U22: =Nahunta!$O$48 -> 240 | V22: 1 | W22: =SUM(T20:T22)/(U22*V22) -> 0.095208333 | X22: =VLOOKUP($A22,'Yields-Labor-Cube'!$A$22:$O$46,15,FALSE) -> 0.95 | Y22: =ROUND(X22*J22,0) -> 22 | Z22: =1/P22 -> 8.25 | AA22: =1/S22 -> 6.6932271 | AB22: =1/W22 -> 10.503282 | AC22: =MIN(Z22:AB22) -> 6.6932271
A23: =Nahunta!Y23 -> 666521 | B23: =IF(A23="", "", A23 & "/" & E23) -> 666521/29 | C23: =VLOOKUP(A23,'Yields-Labor-Cube'!$A$24:$D$44,2,FALSE) -> TISS,PORCINE,THORACIC BLOCK | D23: Nahunta | E23: 29 | G23: Tissue (APHIS) | H23: Approved | I23: =VLOOKUP(A23,'Yields-Labor-Cube'!$A$24:$E$46,5,FALSE) -> 3 | J23: =VLOOKUP(A23,Nahunta!$C$20:$O$44,9,FALSE) -> 21 | K23: 200 | L23: =VLOOKUP(A23,Nahunta!$C$20:$AC$44,14,FALSE) -> 0.6 | M23: =K23*L23 -> 120 | N23: =VLOOKUP(A23,Nahunta!$C$20:$AC$44,15,FALSE) -> 0.9 | O23: =ROUND($J23*VLOOKUP(A23,Nahunta!$C$20:$O$44,10,0)/N23,0) -> 23 | P23: =SUM(O22:O23)/M23 -> 0.39166667 | Q23: =$J23*VLOOKUP($A23,'Yields-Labor-Cube'!$A$24:$O$46,3,FALSE)/(60)+(O23-J23*VLOOKUP(A23,'Yields-Labor-Cube'!$A$22:$O$46,14,FALSE))*$O$1/360 -> 1.6138889 | R23: =Nahunta!$L$58*4 -> 21 | S23: =SUM(Q20:Q23)/R23 -> 0.22625661 | T23: =$J23*VLOOKUP($A23,YLC,4,FALSE) -> 37.8 | U23: =Nahunta!$O$48 -> 240 | V23: 1 | W23: =SUM(T20:T23)/(U23*V23) -> 0.25270833 | X23: =VLOOKUP($A23,'Yields-Labor-Cube'!$A$22:$O$46,15,FALSE) -> 0.9 | Y23: =ROUND(X23*J23,0) -> 19 | Z23: =1/P23 -> 2.5531915 | AA23: =1/S23 -> 4.4197603 | AB23: =1/W23 -> 3.9571311 | AC23: =MIN(Z23:AB23) -> 2.5531915
A24: =Nahunta!Y24 -> 666517 | B24: =IF(A24="", "", A24 & "/" & E24) -> 666517/29 | C24: =VLOOKUP(A24,'Yields-Labor-Cube'!$A$24:$D$44,2,FALSE) -> TISS,PORCINE,PANCREAS | D24: Nahunta | E24: 29 | G24: Tissue (APHIS) | H24: Approved | I24: =VLOOKUP(A24,'Yields-Labor-Cube'!$A$24:$E$46,5,FALSE) -> 3 | J24: =VLOOKUP(A24,Nahunta!$C$20:$O$44,9,FALSE) -> 17 | K24: 200 | L24: =VLOOKUP(A24,Nahunta!$C$20:$AC$44,14,FALSE) -> 0.9 | M24: =K24*L24 -> 180 | N24: =VLOOKUP(A24,Nahunta!$C$20:$AC$44,15,FALSE) -> 0.95 | O24: =ROUND($J24*VLOOKUP(A24,Nahunta!$C$20:$O$44,10,0)/N24,0) -> 18 | P24: =SUM(O22:O24)/M24 -> 0.36111111 | Q24: =$J24*VLOOKUP($A24,'Yields-Labor-Cube'!$A$24:$O$46,3,FALSE)/(60)+(O24-J24*VLOOKUP(A24,'Yields-Labor-Cube'!$A$22:$O$46,14,FALSE))*$O$1/360 -> 0.30277778 | R24: =Nahunta!$L$58*4 -> 21 | S24: =SUM(Q20:Q24)/R24 -> 0.2406746 | T24: =$J24*VLOOKUP($A24,YLC,4,FALSE) -> 3.4 | U24: =Nahunta!$O$48 -> 240 | V24: 1 | W24: =SUM(T20:T24)/(U24*V24) -> 0.266875 | X24: =VLOOKUP($A24,'Yields-Labor-Cube'!$A$22:$O$46,15,FALSE) -> 0.8 | Y24: =ROUND(X24*J24,0) -> 14 | Z24: =1/P24 -> 2.7692308 | AA24: =1/S24 -> 4.1549876 | AB24: =1/W24 -> 3.7470726 | AC24: =MIN(Z24:AB24) -> 2.7692308
A25: =Nahunta!Y25 -> 666516 | B25: =IF(A25="", "", A25 & "/" & E25) -> 666516/29 | C25: =VLOOKUP(A25,'Yields-Labor-Cube'!$A$24:$D$44,2,FALSE) -> TISS,PORCINE,OMENTUM | D25: Nahunta | E25: 29 | G25: Tissue (APHIS) | H25: Approved | I25: =VLOOKUP(A25,'Yields-Labor-Cube'!$A$24:$E$46,5,FALSE) -> 3 | J25: =VLOOKUP(A25,Nahunta!$C$20:$O$44,9,FALSE) -> 13 | K25: 200 | L25: =VLOOKUP(A25,Nahunta!$C$20:$AC$44,14,FALSE) -> 0.9 | M25: =K25*L25 -> 180 | N25: =VLOOKUP(A25,Nahunta!$C$20:$AC$44,15,FALSE) -> 0.95 | O25: =ROUND($J25*VLOOKUP(A25,Nahunta!$C$20:$O$44,10,0)/N25,0) -> 14 | P25: =SUM(O22:O25)/M25 -> 0.43888889 | Q25: =$J25*VLOOKUP($A25,'Yields-Labor-Cube'!$A$24:$O$46,3,FALSE)/(60)+(O25-J25*VLOOKUP(A25,'Yields-Labor-Cube'!$A$22:$O$46,14,FALSE))*$O$1/360 -> 0.23611111 | R25: =Nahunta!$L$58*4 -> 21 | S25: =SUM(Q20:Q25)/R25 -> 0.25191799 | T25: =$J25*VLOOKUP($A25,YLC,4,FALSE) -> 1.3 | U25: =Nahunta!$O$48 -> 240 | V25: 1 | W25: =SUM(T20:T25)/(U25*V25) -> 0.27229167 | X25: =VLOOKUP($A25,'Yields-Labor-Cube'!$A$22:$O$46,15,FALSE) -> 0.8 | Y25: =ROUND(X25*J25,0) -> 10 | Z25: =1/P25 -> 2.278481 | AA25: =1/S25 -> 3.9695458 | AB25: =1/W25 -> 3.6725325 | AC25: =MIN(Z25:AB25) -> 2.278481
A26: =Nahunta!Y26 -> 666519 | B26: =IF(A26="", "", A26 & "/" & E26) -> 666519/29 | C26: =VLOOKUP(A26,'Yields-Labor-Cube'!$A$24:$D$44,2,FALSE) -> TISS,PORCINE,SPLEEN | D26: Nahunta | E26: 29 | G26: Tissue (APHIS) | H26: Approved | I26: =VLOOKUP(A26,'Yields-Labor-Cube'!$A$24:$E$46,5,FALSE) -> 2 | J26: =VLOOKUP(A26,Nahunta!$C$20:$O$44,9,FALSE) -> 13 | K26: 200 | L26: =VLOOKUP(A26,Nahunta!$C$20:$AC$44,14,FALSE) -> 0.99 | M26: =K26*L26 -> 198 | N26: =VLOOKUP(A26,Nahunta!$C$20:$AC$44,15,FALSE) -> 0.95 | O26: =ROUND($J26*VLOOKUP(A26,Nahunta!$C$20:$O$44,10,0)/N26,0) -> 14 | P26: =SUM(O20,O26)/M26 -> 0.24242424 | Q26: =$J26*VLOOKUP($A26,'Yields-Labor-Cube'!$A$24:$O$46,3,FALSE)/(60)+(O26-J26*VLOOKUP(A26,'Yields-Labor-Cube'!$A$22:$O$46,14,FALSE))*$O$1/360 -> 0.23611111 | R26: =Nahunta!$L$58*4 -> 21 | S26: =SUM(Q20:Q26)/R26 -> 0.26316138 | T26: =$J26*VLOOKUP($A26,YLC,4,FALSE) -> 6.5 | U26: =Nahunta!$O$48 -> 240 | V26: 1 | W26: =SUM(T20:T26)/(U26*V26) -> 0.299375 | X26: =VLOOKUP($A26,'Yields-Labor-Cube'!$A$22:$O$46,15,FALSE) -> 0.95 | Y26: =ROUND(X26*J26,0) -> 12 | Z26: =1/P26 -> 4.125 | AA26: =1/S26 -> 3.7999497 | AB26: =1/W26 -> 3.3402923 | AC26: =MIN(Z26:AB26) -> 3.3402923
A27: =Nahunta!Y27 -> 666505 | B27: =IF(A27="", "", A27 & "/" & E27) -> 666505/29 | C27: =VLOOKUP(A27,'Yields-Labor-Cube'!$A$24:$D$44,2,FALSE) -> TISS,PORCINE,LIVER | D27: Nahunta | E27: 29 | G27: Tissue (APHIS) | H27: Approved | I27: =VLOOKUP(A27,'Yields-Labor-Cube'!$A$24:$E$46,5,FALSE) -> 1 | J27: =VLOOKUP(A27,Nahunta!$C$20:$O$44,9,FALSE) -> 8 | K27: 200 | L27: =VLOOKUP(A27,Nahunta!$C$20:$AC$44,14,FALSE) -> 0.9 | M27: =K27*L27 -> 180 | N27: =VLOOKUP(A27,Nahunta!$C$20:$AC$44,15,FALSE) -> 0.95 | O27: =ROUND($J27*VLOOKUP(A27,Nahunta!$C$20:$O$44,10,0)/N27,0) -> 4 | P27: =SUM(O27,O21)/M27 -> 0.11666667 | Q27: =$J27*VLOOKUP($A27,'Yields-Labor-Cube'!$A$24:$O$46,3,FALSE)/(60)+(O27-J27*VLOOKUP(A27,'Yields-Labor-Cube'!$A$22:$O$46,14,FALSE))*$O$1/360 -> 0.13333333 | R27: =Nahunta!$L$58*4 -> 21 | S27: =SUM(Q20:Q27)/R27 -> 0.26951058 | T27: =$J27*VLOOKUP($A27,YLC,4,FALSE) -> 1.6 | U27: =Nahunta!$O$48 -> 240 | V27: 1 | W27: =SUM(T20:T27)/(U27*V27) -> 0.30604167 | X27: =VLOOKUP($A27,'Yields-Labor-Cube'!$A$22:$O$46,15,FALSE) -> 0.95 | Y27: =ROUND(X27*J27,0) -> 8 | Z27: =1/P27 -> 8.5714286 | AA27: =1/S27 -> 3.7104294 | AB27: =1/W27 -> 3.2675289 | AC27: =MIN(Z27:AB27) -> 3.2675289
A28: =Nahunta!Y28 -> 666507 | B28: =IF(A28="", "", A28 & "/" & E28) -> 666507/29 | C28: =VLOOKUP(A28,'Yields-Labor-Cube'!$A$24:$D$44,2,FALSE) -> TISS,PORCINE,FULL THOR AND BARI BLOCK | D28: Nahunta | E28: 29 | G28: Tissue (APHIS) | H28: Approved | I28: =VLOOKUP(A28,'Yields-Labor-Cube'!$A$24:$E$46,5,FALSE) -> 3 | J28: =VLOOKUP(A28,Nahunta!$C$20:$O$44,9,FALSE) -> 8 | K28: 200 | L28: =VLOOKUP(A28,Nahunta!$C$20:$AC$44,14,FALSE) -> 0.6 | M28: =K28*L28 -> 120 | N28: =VLOOKUP(A28,Nahunta!$C$20:$AC$44,15,FALSE) -> 0.95 | O28: =ROUND($J28*VLOOKUP(A28,Nahunta!$C$20:$O$44,10,0)/N28,0) -> 8 | P28: =SUM(O22:O25,O28)/M28 -> 0.725 | Q28: =$J28*VLOOKUP($A28,'Yields-Labor-Cube'!$A$24:$O$46,3,FALSE)/(60)+(O28-J28*VLOOKUP(A28,'Yields-Labor-Cube'!$A$22:$O$46,14,FALSE))*$O$1/360 -> 0.66666667 | R28: =Nahunta!$L$58*4 -> 21 | S28: =SUM(Q20:Q28)/R28 -> 0.30125661 | T28: =$J28*VLOOKUP($A28,YLC,4,FALSE) -> 14.4 | U28: =Nahunta!$O$48 -> 240 | V28: 1 | W28: =SUM(T20:T28)/(U28*V28) -> 0.36604167 | X28: =VLOOKUP($A28,'Yields-Labor-Cube'!$A$22:$O$46,15,FALSE) -> 0.9 | Y28: =ROUND(X28*J28,0) -> 7 | Z28: =1/P28 -> 1.3793103 | AA28: =1/S28 -> 3.3194292 | AB28: =1/W28 -> 2.7319294 | AC28: =MIN(Z28:AB28) -> 1.3793103
A29: =Nahunta!Y29 -> 666510 | B29: =IF(A29="", "", A29 & "/" & E29) -> 666510/29 | C29: =VLOOKUP(A29,'Yields-Labor-Cube'!$A$24:$D$44,2,FALSE) -> TISS,PORCINE,JEJUNUM (3FT) | D29: Nahunta | E29: 29 | G29: Tissue (APHIS) | H29: Approved | I29: =VLOOKUP(A29,'Yields-Labor-Cube'!$A$24:$E$46,5,FALSE) -> 1 | J29: =VLOOKUP(A29,Nahunta!$C$20:$O$44,9,FALSE) -> 7 | K29: 200 | L29: =VLOOKUP(A29,Nahunta!$C$20:$AC$44,14,FALSE) -> 0.95 | M29: =K29*L29 -> 190 | N29: =VLOOKUP(A29,Nahunta!$C$20:$AC$44,15,FALSE) -> 0.95 | O29: =ROUND($J29*VLOOKUP(A29,Nahunta!$C$20:$O$44,10,0)/N29,0) -> 4 | P29: =SUM(O28:O29,O21)/M29 -> 0.15263158 | Q29: =$J29*VLOOKUP($A29,'Yields-Labor-Cube'!$A$24:$O$46,3,FALSE)/(60)+(O29-J29*VLOOKUP(A29,'Yields-Labor-Cube'!$A$22:$O$46,14,FALSE))*$O$1/360 -> 0.49952778 | R29: =Nahunta!$L$58*4 -> 21 | S29: =SUM(Q20:Q29)/R29 -> 0.32504365 | T29: =$J29*VLOOKUP($A29,YLC,4,FALSE) -> 2.1 | U29: =Nahunta!$O$48 -> 240 | V29: 1 | W29: =SUM(T20:T29)/(U29*V29) -> 0.37479167 | X29: =VLOOKUP($A29,'Yields-Labor-Cube'!$A$22:$O$46,15,FALSE) -> 0.85 | Y29: =ROUND(X29*J29,0) -> 6 | Z29: =1/P29 -> 6.5517241 | AA29: =1/S29 -> 3.0765099 | AB29: =1/W29 -> 2.668149 | AC29: =MIN(Z29:AB29) -> 2.668149
A30: =Nahunta!Y30 -> 666513 | B30: =IF(A30="", "", A30 & "/" & E30) -> 666513/29 | C30: =VLOOKUP(A30,'Yields-Labor-Cube'!$A$24:$D$44,2,FALSE) -> TISS,PORCINE,LIVER WITH GALLBLADDER | D30: Nahunta | E30: 29 | G30: Tissue (APHIS) | H30: Approved | I30: =VLOOKUP(A30,'Yields-Labor-Cube'!$A$24:$E$46,5,FALSE) -> 2 | J30: =VLOOKUP(A30,Nahunta!$C$20:$O$44,9,FALSE) -> 5 | K30: 200 | L30: =VLOOKUP(A30,Nahunta!$C$20:$AC$44,14,FALSE) -> 0.9 | M30: =K30*L30 -> 180 | N30: =VLOOKUP(A30,Nahunta!$C$20:$AC$44,15,FALSE) -> 0.95 | O30: =ROUND($J30*VLOOKUP(A30,Nahunta!$C$20:$O$44,10,0)/N30,0) -> 5 | P30: =SUM(O30,O26,O20)/M30 -> 0.29444444 | Q30: =$J30*VLOOKUP($A30,'Yields-Labor-Cube'!$A$24:$O$46,3,FALSE)/(60)+(O30-J30*VLOOKUP(A30,'Yields-Labor-Cube'!$A$22:$O$46,14,FALSE))*$O$1/360 -> 0.083333333 | R30: =Nahunta!$L$58*4 -> 21 | S30: =SUM(Q20:Q30)/R30 -> 0.3290119 | T30: =$J30*VLOOKUP($A30,YLC,4,FALSE) -> 2.5 | U30: =Nahunta!$O$48 -> 240 | V30: 1 | W30: =SUM(T20:T30)/(U30*V30) -> 0.38520833 | X30: =VLOOKUP($A30,'Yields-Labor-Cube'!$A$22:$O$46,15,FALSE) -> 0.85 | Y30: =ROUND(X30*J30,0) -> 4 | Z30: =1/P30 -> 3.3962264 | AA30: =1/S30 -> 3.0394037 | AB30: =1/W30 -> 2.5959978 | AC30: =MIN(Z30:AB30) -> 2.5959978
A31: =Nahunta!Y31 -> 666511 | B31: =IF(A31="", "", A31 & "/" & E31) -> 666511/29 | C31: =VLOOKUP(A31,'Yields-Labor-Cube'!$A$24:$D$44,2,FALSE) -> TISS,PORCINE,KIDNEY BLOCK | D31: Nahunta | E31: 29 | G31: Tissue (APHIS) | H31: Approved | I31: =VLOOKUP(A31,'Yields-Labor-Cube'!$A$24:$E$46,5,FALSE) -> 1 | J31: =VLOOKUP(A31,Nahunta!$C$20:$O$44,9,FALSE) -> 4 | K31: 200 | L31: =VLOOKUP(A31,Nahunta!$C$20:$AC$44,14,FALSE) -> 0.9 | M31: =K31*L31 -> 180 | N31: =VLOOKUP(A31,Nahunta!$C$20:$AC$44,15,FALSE) -> 0.95 | O31: =ROUND($J31*VLOOKUP(A31,Nahunta!$C$20:$O$44,10,0)/N31,0) -> 2 | P31: =SUM(O21,O28:O29,O31)/M31 -> 0.17222222 | Q31: =$J31*VLOOKUP($A31,'Yields-Labor-Cube'!$A$24:$O$46,3,FALSE)/(60)+(O31-J31*VLOOKUP(A31,'Yields-Labor-Cube'!$A$22:$O$46,14,FALSE))*$O$1/360 -> 0.066666667 | R31: =Nahunta!$L$58*4 -> 21 | S31: =SUM(Q20:Q31)/R31 -> 0.33218651 | T31: =$J31*VLOOKUP($A31,YLC,4,FALSE) -> 2 | U31: =Nahunta!$O$48 -> 240 | V31: 1 | W31: =SUM(T20:T31)/(U31*V31) -> 0.39354167 | X31: =VLOOKUP($A31,'Yields-Labor-Cube'!$A$22:$O$46,15,FALSE) -> 0.8 | Y31: =ROUND(X31*J31,0) -> 3 | Z31: =1/P31 -> 5.8064516 | AA31: =1/S31 -> 3.0103571 | AB31: =1/W31 -> 2.541027 | AC31: =MIN(Z31:AB31) -> 2.541027
A32: =Nahunta!Y32 -> 666531 | B32: =IF(A32="", "", A32 & "/" & E32) -> 666531/29 | C32: =VLOOKUP(A32,'Yields-Labor-Cube'!$A$24:$D$44,2,FALSE) -> TISS,PORCINE,DIAPHRAGM | D32: Nahunta | E32: 29 | G32: Tissue (APHIS) | H32: Approved | I32: =VLOOKUP(A32,'Yields-Labor-Cube'!$A$24:$E$46,5,FALSE) -> 1 | J32: =VLOOKUP(A32,Nahunta!$C$20:$O$44,9,FALSE) -> 2 | K32: 200 | L32: =VLOOKUP(A32,Nahunta!$C$20:$AC$44,14,FALSE) -> 0.95 | M32: =K32*L32 -> 190 | N32: =VLOOKUP(A32,Nahunta!$C$20:$AC$44,15,FALSE) -> 0.95 | O32: =ROUND($J32*VLOOKUP(A32,Nahunta!$C$20:$O$44,10,0)/N32,0) -> 2 | P32: =SUM(O21,O28:O29,O31:O32)/M32 -> 0.17368421 | Q32: =$J32*VLOOKUP($A32,'Yields-Labor-Cube'!$A$24:$O$46,3,FALSE)/(60)+(O32-J32*VLOOKUP(A32,'Yields-Labor-Cube'!$A$22:$O$46,14,FALSE))*$O$1/360 -> 0.033333333 | R32: =Nahunta!$L$58*4 -> 21 | S32: =SUM(Q20:Q32)/R32 -> 0.33377381 | T32: =$J32*VLOOKUP($A32,YLC,4,FALSE) -> 0.4 | U32: =Nahunta!$O$48 -> 240 | V32: 1 | W32: =SUM(T20:T32)/(U32*V32) -> 0.39520833 | X32: =VLOOKUP($A32,'Yields-Labor-Cube'!$A$22:$O$46,15,FALSE) -> 0.85 | Y32: =ROUND(X32*J32,0) -> 2 | Z32: =1/P32 -> 5.7575758 | AA32: =1/S32 -> 2.9960409 | AB32: =1/W32 -> 2.530311 | AC32: =MIN(Z32:AB32) -> 2.530311
A33: =Nahunta!Y33 -> 666536 | B33: =IF(A33="", "", A33 & "/" & E33) -> 666536/29 | C33: =VLOOKUP(A33,'Yields-Labor-Cube'!$A$24:$D$44,2,FALSE) -> TISS,PORCINE,THORACIC BLOCK, LARGE | D33: Nahunta | E33: 29 | G33: Tissue (APHIS) | H33: Approved | I33: =VLOOKUP(A33,'Yields-Labor-Cube'!$A$24:$E$46,5,FALSE) -> 4 | J33: =VLOOKUP(A33,Nahunta!$C$20:$O$44,9,FALSE) -> 2 | K33: 200 | L33: =VLOOKUP(A33,Nahunta!$C$20:$AC$44,14,FALSE) -> 0.05 | M33: =K33*L33 -> 10 | N33: =VLOOKUP(A33,Nahunta!$C$20:$AC$44,15,FALSE) -> 0.95 | O33: =ROUND($J33*VLOOKUP(A33,Nahunta!$C$20:$O$44,10,0)/N33,0) -> 2 | P33: =SUM(O33)/M33 -> 0.2 | Q33: =$J33*VLOOKUP($A33,'Yields-Labor-Cube'!$A$24:$O$46,3,FALSE)/(60)+(O33-J33*VLOOKUP(A33,'Yields-Labor-Cube'!$A$22:$O$46,14,FALSE))*$O$1/360 -> 0.16666667 | R33: =Nahunta!$L$58*4 -> 21 | S33: =SUM(Q20:Q33)/R33 -> 0.34171032 | T33: =$J33*VLOOKUP($A33,YLC,4,FALSE) -> 4 | U33: =Nahunta!$O$48 -> 240 | V33: 1 | W33: =SUM(T20:T33)/(U33*V33) -> 0.411875 | X33: =VLOOKUP($A33,'Yields-Labor-Cube'!$A$22:$O$46,15,FALSE) -> 0.9 | Y33: =ROUND(X33*J33,0) -> 2 | Z33: =1/P33 -> 5 | AA33: =1/S33 -> 2.9264554 | AB33: =1/W33 -> 2.4279211 | AC33: =MIN(Z33:AB33) -> 2.4279211
O34: Total: | P34: =MAX(P20:P33) -> 0.725 | S34: =S33 -> 0.34171032 | W34: =W33 -> 0.411875 | Z34: =1/P34 -> 1.3793103 | AA34: =1/S34 -> 2.9264554 | AB34: =1/W34 -> 2.4279211 | AC34: =MIN(Z34:AB34) -> 1.3793103
K39: 150
A40: =Customs!Y20 -> 666522 | B40: =IF(A40="", "", A40 & "/" & E40) -> 666522/49 | C40: =VLOOKUP(A40,YLC,2,FALSE) -> TISS,PORCINE,URETER | D40: Customs | E40: 49 | G40: Tissue (APHIS) | H40: Approved | I40: =VLOOKUP(A40,'Yields-Labor-Cube'!$A$24:$E$46,5,FALSE) -> 2 | J40: =VLOOKUP(A40,Customs!$C$20:$O$44,9,FALSE) -> 36 | K40: 150 | L40: =VLOOKUP(A40,Customs!$C$20:$AC$44,14,FALSE) -> 0.9 | M40: =K40*L40 -> 135 | N40: =VLOOKUP(A40,Customs!$C$20:$AC$44,15,FALSE) -> 0.85 | O40: =ROUND($J40*VLOOKUP(A40,Customs!$C$20:$O$44,10,0)/N40,0) -> 21 | P40: =O40/M40 -> 0.15555556 | Q40: =$J40*VLOOKUP($A40,'Yields-Labor-Cube'!$A$24:$O$46,3,FALSE)/(60)+(O40-J40*VLOOKUP(A40,'Yields-Labor-Cube'!$A$22:$O$46,14,FALSE))*$O$1/360 -> 0.35833333 | R40: =Customs!$L$58*2 -> 10.5 | S40: =Q40/R40 -> 0.034126984 | T40: =$J40*VLOOKUP($A40,YLC,4,FALSE) -> 3.6 | U40: =Customs!$O$48 -> 160 | V40: 1 | W40: =T40/(U40*V40) -> 0.0225 | X40: =VLOOKUP($A40,'Yields-Labor-Cube'!$A$22:$O$46,15,FALSE) -> 0.8 | Y40: =ROUND(X40*J40,0) -> 29 | Z40: =1/P40 -> 6.4285714 | AA40: =1/S40 -> 29.302326 | AB40: =1/W40 -> 44.444444 | AC40: =MIN(Z40:AB40) -> 6.4285714
A41: =Customs!Y21 -> 666502 | B41: =IF(A41="", "", A41 & "/" & E41) -> 666502/49 | C41: =VLOOKUP(A41,YLC,2,FALSE) -> TISS,PORCINE,BARIATRIC BLOCK | D41: Customs | E41: 49 | G41: Tissue (APHIS) | H41: Approved | I41: =VLOOKUP(A41,'Yields-Labor-Cube'!$A$24:$E$46,5,FALSE) -> 3 | J41: =VLOOKUP(A41,Customs!$C$20:$O$44,9,FALSE) -> 30 | K41: 150 | L41: =VLOOKUP(A41,Customs!$C$20:$AC$44,14,FALSE) -> 0.9 | M41: =K41*L41 -> 135 | N41: =VLOOKUP(A41,Customs!$C$20:$AC$44,15,FALSE) -> 0.7 | O41: =ROUND($J41*VLOOKUP(A41,Customs!$C$20:$O$44,10,0)/N41,0) -> 43 | P41: =SUM(O41)/M41 -> 0.31851852 | Q41: =$J41*VLOOKUP($A41,'Yields-Labor-Cube'!$A$24:$O$46,3,FALSE)/(60)+(O41-J41*VLOOKUP(A41,'Yields-Labor-Cube'!$A$22:$O$46,14,FALSE))*$O$1/360 -> 2.0027778 | R41: =Customs!$L$58*2 -> 10.5 | S41: =SUM(Q40:Q41)/R41 -> 0.22486772 | T41: =$J41*VLOOKUP($A41,YLC,4,FALSE) -> 45 | U41: =Customs!$O$48 -> 160 | V41: 1 | W41: =SUM(T40:T41)/(U41*V41) -> 0.30375 | X41: =VLOOKUP($A41,'Yields-Labor-Cube'!$A$22:$O$46,15,FALSE) -> 0.9 | Y41: =ROUND(X41*J41,0) -> 27 | Z41: =1/P41 -> 3.1395349 | AA41: =1/S41 -> 4.4470588 | AB41: =1/W41 -> 3.2921811 | AC41: =MIN(Z41:AB41) -> 3.1395349
A42: =Customs!Y22 -> 666501 | B42: =IF(A42="", "", A42 & "/" & E42) -> 666501/49 | C42: =VLOOKUP(A42,YLC,2,FALSE) -> TISS,PORCINE,AORTA SEGMENTS | D42: Customs | E42: 49 | G42: Tissue (APHIS) | H42: Approved | I42: =VLOOKUP(A42,'Yields-Labor-Cube'!$A$24:$E$46,5,FALSE) -> 3 | J42: =VLOOKUP(A42,Customs!$C$20:$O$44,9,FALSE) -> 21 | K42: 150 | L42: =VLOOKUP(A42,Customs!$C$20:$AC$44,14,FALSE) -> 0.99 | M42: =K42*L42 -> 148.5 | N42: =VLOOKUP(A42,Customs!$C$20:$AC$44,15,FALSE) -> 0.95 | O42: =ROUND($J42*VLOOKUP(A42,Customs!$C$20:$O$44,10,0)/N42,0) -> 22 | P42: =SUM(O41:O42)/M42 -> 0.43771044 | Q42: =$J42*VLOOKUP($A42,'Yields-Labor-Cube'!$A$24:$O$46,3,FALSE)/(60)+(O42-J42*VLOOKUP(A42,'Yields-Labor-Cube'!$A$22:$O$46,14,FALSE))*$O$1/360 -> 0.36944444 | R42: =Customs!$L$58*2 -> 10.5 | S42: =SUM(Q40:Q42)/R42 -> 0.26005291 | T42: =$J42*VLOOKUP($A42,YLC,4,FALSE) -> 1.05 | U42: =Customs!$O$48 -> 160 | V42: 1 | W42: =SUM(T40:T42)/(U42*V42) -> 0.3103125 | X42: =VLOOKUP($A42,'Yields-Labor-Cube'!$A$22:$O$46,15,FALSE) -> 0.95 | Y42: =ROUND(X42*J42,0) -> 20 | Z42: =1/P42 -> 2.2846154 | AA42: =1/S42 -> 3.8453713 | AB42: =1/W42 -> 3.2225579 | AC42: =MIN(Z42:AB42) -> 2.2846154
A43: =Customs!Y23 -> 666523 | B43: =IF(A43="", "", A43 & "/" & E43) -> 666523/49 | C43: =VLOOKUP(A43,YLC,2,FALSE) -> TISS,PORCINE,VENA CAVA | D43: Customs | E43: 49 | G43: Tissue (APHIS) | H43: Approved | I43: =VLOOKUP(A43,'Yields-Labor-Cube'!$A$24:$E$46,5,FALSE) -> 3 | J43: =VLOOKUP(A43,Customs!$C$20:$O$44,9,FALSE) -> 18 | K43: 150 | L43: =VLOOKUP(A43,Customs!$C$20:$AC$44,14,FALSE) -> 0.9 | M43: =K43*L43 -> 135 | N43: =VLOOKUP(A43,Customs!$C$20:$AC$44,15,FALSE) -> 0.95 | O43: =ROUND($J43*VLOOKUP(A43,Customs!$C$20:$O$44,10,0)/N43,0) -> 19 | P43: =SUM(O41:O43)/M43 -> 0.62222222 | Q43: =$J43*VLOOKUP($A43,'Yields-Labor-Cube'!$A$24:$O$46,3,FALSE)/(60)+(O43-J43*VLOOKUP(A43,'Yields-Labor-Cube'!$A$22:$O$46,14,FALSE))*$O$1/360 -> 0.31944444 | R43: =Customs!$L$58*2 -> 10.5 | S43: =SUM(Q40:Q43)/R43 -> 0.29047619 | T43: =$J43*VLOOKUP($A43,YLC,4,FALSE) -> 0.9 | U43: =Customs!$O$48 -> 160 | V43: 1 | W43: =SUM(T40:T43)/(U43*V43) -> 0.3159375 | X43: =VLOOKUP($A43,'Yields-Labor-Cube'!$A$22:$O$46,15,FALSE) -> 0.95 | Y43: =ROUND(X43*J43,0) -> 17 | Z43: =1/P43 -> 1.6071429 | AA43: =1/S43 -> 3.442623 | AB43: =1/W43 -> 3.165183 | AC43: =MIN(Z43:AB43) -> 1.6071429
A44: =Customs!Y24 -> 666505 | B44: =IF(A44="", "", A44 & "/" & E44) -> 666505/49 | C44: =VLOOKUP(A44,YLC,2,FALSE) -> TISS,PORCINE,LIVER | D44: Customs | E44: 49 | G44: Tissue (APHIS) | H44: Approved | I44: =VLOOKUP(A44,'Yields-Labor-Cube'!$A$24:$E$46,5,FALSE) -> 1 | J44: =VLOOKUP(A44,Customs!$C$20:$O$44,9,FALSE) -> 17 | K44: 150 | L44: =VLOOKUP(A44,Customs!$C$20:$AC$44,14,FALSE) -> 0.9 | M44: =K44*L44 -> 135 | N44: =VLOOKUP(A44,Customs!$C$20:$AC$44,15,FALSE) -> 0.95 | O44: =ROUND($J44*VLOOKUP(A44,Customs!$C$20:$O$44,10,0)/N44,0) -> 9 | P44: =SUM(O44)/M44 -> 0.066666667 | Q44: =$J44*VLOOKUP($A44,'Yields-Labor-Cube'!$A$24:$O$46,3,FALSE)/(60)+(O44-J44*VLOOKUP(A44,'Yields-Labor-Cube'!$A$22:$O$46,14,FALSE))*$O$1/360 -> 0.29305556 | R44: =Customs!$L$58*2 -> 10.5 | S44: =SUM(Q40:Q44)/R44 -> 0.31838624 | T44: =$J44*VLOOKUP($A44,YLC,4,FALSE) -> 3.4 | U44: =Customs!$O$48 -> 160 | V44: 1 | W44: =SUM(T40:T44)/(U44*V44) -> 0.3371875 | X44: =VLOOKUP($A44,'Yields-Labor-Cube'!$A$22:$O$46,15,FALSE) -> 0.95 | Y44: =ROUND(X44*J44,0) -> 16 | Z44: =1/P44 -> 15 | AA44: =1/S44 -> 3.1408392 | AB44: =1/W44 -> 2.965709 | AC44: =MIN(Z44:AB44) -> 2.965709
A45: =Customs!Y25 -> 666516 | B45: =IF(A45="", "", A45 & "/" & E45) -> 666516/49 | C45: =VLOOKUP(A45,YLC,2,FALSE) -> TISS,PORCINE,OMENTUM | D45: Customs | E45: 49 | G45: Tissue (APHIS) | H45: Approved | I45: =VLOOKUP(A45,'Yields-Labor-Cube'!$A$24:$E$46,5,FALSE) -> 3 | J45: =VLOOKUP(A45,Customs!$C$20:$O$44,9,FALSE) -> 13 | K45: 150 | L45: =VLOOKUP(A45,Customs!$C$20:$AC$44,14,FALSE) -> 0.9 | M45: =K45*L45 -> 135 | N45: =VLOOKUP(A45,Customs!$C$20:$AC$44,15,FALSE) -> 0.95 | O45: =ROUND($J45*VLOOKUP(A45,Customs!$C$20:$O$44,10,0)/N45,0) -> 14 | P45: =SUM(O41:O43,O45)/M45 -> 0.72592593 | Q45: =$J45*VLOOKUP($A45,'Yields-Labor-Cube'!$A$24:$O$46,3,FALSE)/(60)+(O45-J45*VLOOKUP(A45,'Yields-Labor-Cube'!$A$22:$O$46,14,FALSE))*$O$1/360 -> 0.23611111 | R45: =Customs!$L$58*2 -> 10.5 | S45: =SUM(Q40:Q45)/R45 -> 0.34087302 | T45: =$J45*VLOOKUP($A45,YLC,4,FALSE) -> 1.3 | U45: =Customs!$O$48 -> 160 | V45: 1 | W45: =SUM(T40:T45)/(U45*V45) -> 0.3453125 | X45: =VLOOKUP($A45,'Yields-Labor-Cube'!$A$22:$O$46,15,FALSE) -> 0.8 | Y45: =ROUND(X45*J45,0) -> 10 | Z45: =1/P45 -> 1.377551 | AA45: =1/S45 -> 2.9336438 | AB45: =1/W45 -> 2.8959276 | AC45: =MIN(Z45:AB45) -> 1.377551
A46: =Customs!Y26 -> 666519 | B46: =IF(A46="", "", A46 & "/" & E46) -> 666519/49 | C46: =VLOOKUP(A46,YLC,2,FALSE) -> TISS,PORCINE,SPLEEN | D46: Customs | E46: 49 | G46: Tissue (APHIS) | H46: Approved | I46: =VLOOKUP(A46,'Yields-Labor-Cube'!$A$24:$E$46,5,FALSE) -> 2 | J46: =VLOOKUP(A46,Customs!$C$20:$O$44,9,FALSE) -> 13 | K46: 150 | L46: =VLOOKUP(A46,Customs!$C$20:$AC$44,14,FALSE) -> 0.9 | M46: =K46*L46 -> 135 | N46: =VLOOKUP(A46,Customs!$C$20:$AC$44,15,FALSE) -> 0.95 | O46: =ROUND($J46*VLOOKUP(A46,Customs!$C$20:$O$44,10,0)/N46,0) -> 14 | P46: =SUM(O46,O40)/M46 -> 0.25925926 | Q46: =$J46*VLOOKUP($A46,'Yields-Labor-Cube'!$A$24:$O$46,3,FALSE)/(60)+(O46-J46*VLOOKUP(A46,'Yields-Labor-Cube'!$A$22:$O$46,14,FALSE))*$O$1/360 -> 0.23611111 | R46: =Customs!$L$58*2 -> 10.5 | S46: =SUM(Q40:Q46)/R46 -> 0.36335979 | T46: =$J46*VLOOKUP($A46,YLC,4,FALSE) -> 6.5 | U46: =Customs!$O$48 -> 160 | V46: 1 | W46: =SUM(T40:T46)/(U46*V46) -> 0.3859375 | X46: =VLOOKUP($A46,'Yields-Labor-Cube'!$A$22:$O$46,15,FALSE) -> 0.95 | Y46: =ROUND(X46*J46,0) -> 12 | Z46: =1/P46 -> 3.8571429 | AA46: =1/S46 -> 2.7520932 | AB46: =1/W46 -> 2.5910931 | AC46: =MIN(Z46:AB46) -> 2.5910931
A47: =Customs!Y27 -> 666545 | B47: =IF(A47="", "", A47 & "/" & E47) -> 666545/49 | C47: =VLOOKUP(A47,YLC,2,FALSE) -> TISS, Rectum | D47: Customs | E47: 49 | G47: Tissue (APHIS) | H47: Approved | I47: =VLOOKUP(A47,'Yields-Labor-Cube'!$A$24:$E$46,5,FALSE) -> 2 | J47: =VLOOKUP(A47,Customs!$C$20:$O$44,9,FALSE) -> 13 | K47: 150 | L47: =VLOOKUP(A47,Customs!$C$20:$AC$44,14,FALSE) -> 0.95 | M47: =K47*L47 -> 142.5 | N47: =VLOOKUP(A47,Customs!$C$20:$AC$44,15,FALSE) -> 0.95 | O47: =ROUND($J47*VLOOKUP(A47,Customs!$C$20:$O$44,10,0)/N47,0) -> 14 | P47: =SUM(O47,O46,O40)/M47 -> 0.34385965 | Q47: =$J47*VLOOKUP($A47,'Yields-Labor-Cube'!$A$24:$O$46,3,FALSE)/(60)+(O47-J47*VLOOKUP(A47,'Yields-Labor-Cube'!$A$22:$O$46,14,FALSE))*$O$1/360 -> 0.66944444 | R47: =Customs!$L$58*2 -> 10.5 | S47: =SUM(Q40:Q47)/R47 -> 0.4271164 | T47: =$J47*VLOOKUP($A47,YLC,4,FALSE) -> 1.3 | U47: =Customs!$O$48 -> 160 | V47: 1 | W47: =SUM(T40:T47)/(U47*V47) -> 0.3940625 | X47: =VLOOKUP($A47,'Yields-Labor-Cube'!$A$22:$O$46,15,FALSE) -> 0.95 | Y47: =ROUND(X47*J47,0) -> 12 | Z47: =1/P47 -> 2.9081633 | AA47: =1/S47 -> 2.3412821 | AB47: =1/W47 -> 2.5376685 | AC47: =MIN(Z47:AB47) -> 2.3412821
A48: =Customs!Y28 -> 666513 | B48: =IF(A48="", "", A48 & "/" & E48) -> 666513/49 | C48: =VLOOKUP(A48,YLC,2,FALSE) -> TISS,PORCINE,LIVER WITH GALLBLADDER | D48: Customs | E48: 49 | G48: Tissue (APHIS) | H48: Approved | I48: =VLOOKUP(A48,'Yields-Labor-Cube'!$A$24:$E$46,5,FALSE) -> 2 | J48: =VLOOKUP(A48,Customs!$C$20:$O$44,9,FALSE) -> 11 | K48: 150 | L48: =VLOOKUP(A48,Customs!$C$20:$AC$44,14,FALSE) -> 0.9 | M48: =K48*L48 -> 135 | N48: =VLOOKUP(A48,Customs!$C$20:$AC$44,15,FALSE) -> 0.95 | O48: =ROUND($J48*VLOOKUP(A48,Customs!$C$20:$O$44,10,0)/N48,0) -> 12 | P48: =SUM(O47:O48,O46,O40)/M48 -> 0.45185185 | Q48: =$J48*VLOOKUP($A48,'Yields-Labor-Cube'!$A$24:$O$46,3,FALSE)/(60)+(O48-J48*VLOOKUP(A48,'Yields-Labor-Cube'!$A$22:$O$46,14,FALSE))*$O$1/360 -> 0.20277778 | R48: =Customs!$L$58*2 -> 10.5 | S48: =SUM(Q40:Q48)/R48 -> 0.44642857 | T48: =$J48*VLOOKUP($A48,YLC,4,FALSE) -> 5.5 | U48: =Customs!$O$48 -> 160 | V48: 1 | W48: =SUM(T40:T48)/(U48*V48) -> 0.4284375 | X48: =VLOOKUP($A48,'Yields-Labor-Cube'!$A$22:$O$46,15,FALSE) -> 0.85 | Y48: =ROUND(X48*J48,0) -> 9 | Z48: =1/P48 -> 2.2131148 | AA48: =1/S48 -> 2.24 | AB48: =1/W48 -> 2.3340627 | AC48: =MIN(Z48:AB48) -> 2.2131148
A49: =Customs!Y29 -> 666517 | B49: =IF(A49="", "", A49 & "/" & E49) -> 666517/49 | C49: =VLOOKUP(A49,YLC,2,FALSE) -> TISS,PORCINE,PANCREAS | D49: Customs | E49: 49 | G49: Tissue (APHIS) | H49: Approved | I49: =VLOOKUP(A49,'Yields-Labor-Cube'!$A$24:$E$46,5,FALSE) -> 3 | J49: =VLOOKUP(A49,Customs!$C$20:$O$44,9,FALSE) -> 8 | K49: 150 | L49: =VLOOKUP(A49,Customs!$C$20:$AC$44,14,FALSE) -> 0.9 | M49: =K49*L49 -> 135 | N49: =VLOOKUP(A49,Customs!$C$20:$AC$44,15,FALSE) -> 0.95 | O49: =ROUND($J49*VLOOKUP(A49,Customs!$C$20:$O$44,10,0)/N49,0) -> 8 | P49: =SUM(O49,O45,O41:O43)/M49 -> 0.78518519 | Q49: =$J49*VLOOKUP($A49,'Yields-Labor-Cube'!$A$24:$O$46,3,FALSE)/(60)+(O49-J49*VLOOKUP(A49,'Yields-Labor-Cube'!$A$22:$O$46,14,FALSE))*$O$1/360 -> 0.13333333 | R49: =Customs!$L$58*2 -> 10.5 | S49: =SUM(Q40:Q49)/R49 -> 0.45912698 | T49: =$J49*VLOOKUP($A49,YLC,4,FALSE) -> 1.6 | U49: =Customs!$O$48 -> 160 | V49: 1 | W49: =SUM(T40:T49)/(U49*V49) -> 0.4384375 | X49: =VLOOKUP($A49,'Yields-Labor-Cube'!$A$22:$O$46,15,FALSE) -> 0.8 | Y49: =ROUND(X49*J49,0) -> 6 | Z49: =1/P49 -> 1.2735849 | AA49: =1/S49 -> 2.1780467 | AB49: =1/W49 -> 2.2808268 | AC49: =MIN(Z49:AB49) -> 1.2735849
A50: =Customs!Y30 -> 666510 | B50: =IF(A50="", "", A50 & "/" & E50) -> 666510/49 | C50: =VLOOKUP(A50,YLC,2,FALSE) -> TISS,PORCINE,JEJUNUM (3FT) | D50: Customs | E50: 49 | G50: Tissue (APHIS) | H50: Approved | I50: =VLOOKUP(A50,'Yields-Labor-Cube'!$A$24:$E$46,5,FALSE) -> 1 | J50: =VLOOKUP(A50,Customs!$C$20:$O$44,9,FALSE) -> 1 | K50: 150 | L50: =VLOOKUP(A50,Customs!$C$20:$AC$44,14,FALSE) -> 0.95 | M50: =K50*L50 -> 142.5 | N50: =VLOOKUP(A50,Customs!$C$20:$AC$44,15,FALSE) -> 0.95 | O50: =ROUND($J50*VLOOKUP(A50,Customs!$C$20:$O$44,10,0)/N50,0) -> 1 | P50: =SUM(O50,O44)/M50 -> 0.070175439 | Q50: =$J50*VLOOKUP($A50,'Yields-Labor-Cube'!$A$24:$O$46,3,FALSE)/(60)+(O50-J50*VLOOKUP(A50,'Yields-Labor-Cube'!$A$22:$O$46,14,FALSE))*$O$1/360 -> 0.079694444 | R50: =Customs!$L$58*2 -> 10.5 | S50: =SUM(Q40:Q50)/R50 -> 0.46671693 | T50: =$J50*VLOOKUP($A50,YLC,4,FALSE) -> 0.3 | U50: =Customs!$O$48 -> 160 | V50: 1 | W50: =SUM(T40:T50)/(U50*V50) -> 0.4403125 | X50: =VLOOKUP($A50,'Yields-Labor-Cube'!$A$22:$O$46,15,FALSE) -> 0.85 | Y50: =ROUND(X50*J50,0) -> 1 | Z50: =1/P50 -> 14.25 | AA50: =1/S50 -> 2.1426264 | AB50: =1/W50 -> 2.2711143 | AC50: =MIN(Z50:AB50) -> 2.1426264
A51: =Customs!Y31 -> 666531 | B51: =IF(A51="", "", A51 & "/" & E51) -> 666531/49 | C51: =VLOOKUP(A51,YLC,2,FALSE) -> TISS,PORCINE,DIAPHRAGM | D51: Customs | E51: 49 | G51: Tissue (APHIS) | H51: Approved | I51: =VLOOKUP(A51,'Yields-Labor-Cube'!$A$24:$E$46,5,FALSE) -> 1 | J51: =VLOOKUP(A51,Customs!$C$20:$O$44,9,FALSE) -> 1 | K51: 150 | L51: =VLOOKUP(A51,Customs!$C$20:$AC$44,14,FALSE) -> 0.9 | M51: =K51*L51 -> 135 | N51: =VLOOKUP(A51,Customs!$C$20:$AC$44,15,FALSE) -> 0.95 | O51: =ROUND($J51*VLOOKUP(A51,Customs!$C$20:$O$44,10,0)/N51,0) -> 1 | P51: =SUM(O50:O51,O44)/M51 -> 0.081481481 | Q51: =$J51*VLOOKUP($A51,'Yields-Labor-Cube'!$A$24:$O$46,3,FALSE)/(60)+(O51-J51*VLOOKUP(A51,'Yields-Labor-Cube'!$A$22:$O$46,14,FALSE))*$O$1/360 -> 0.016666667 | R51: =Customs!$L$58*2 -> 10.5 | S51: =SUM(Q40:Q51)/R51 -> 0.46830423 | T51: =$J51*VLOOKUP($A51,YLC,4,FALSE) -> 0.2 | U51: =Customs!$O$48 -> 160 | V51: 1 | W51: =SUM(T40:T51)/(U51*V51) -> 0.4415625 | X51: =VLOOKUP($A51,'Yields-Labor-Cube'!$A$22:$O$46,15,FALSE) -> 0.85 | Y51: =ROUND(X51*J51,0) -> 1 | Z51: =1/P51 -> 12.272727 | AA51: =1/S51 -> 2.135364 | AB51: =1/W51 -> 2.2646851 | AC51: =MIN(Z51:AB51) -> 2.135364
P53: =MAX(P40:P51) -> 0.78518519 | S53: =S51 -> 0.46830423 | W53: =W51 -> 0.4415625 | Z53: =1/P53 -> 1.2735849 | AA53: =1/S53 -> 2.135364 | AB53: =1/W53 -> 2.2646851 | AC53: =MIN(Z53:AB53) -> 1.2735849
...

Sheet Sheet1

Sheet Yields-Labor-Cube
A1: Supplier_Status | B1: Material_Category | C1: Yes_No_NA | D1: Yes_No_Unknown | E1: FSIS_Inspection | F1: Metrology_Tier | G1: Source_Dependency | H1: Switching_Cost | I1: Data_Access_Level | N1: Quality_Trend | O1: Surveillance_Status | P1: Data_Access_Level
A2: New | B2: Tissue (APHIS) | C2: Yes | D2: Yes | E2: FDA FSIS Inspected | F2: Accredited | G2: Sole | H2: High | I2: None | N2: Improving | O2: Current | P2: None
A3: Approved | B3: Tissue (Non-APHIS) | C3: No | D3: No | E3: State Inspected Only | F3: Advanced | G3: Single | H3: Medium | I3: Drawings | N3: Stable | O3: Expired | P3: Drawings
A4: Intuitive Corporate | B4: Non-Tissue: Significant | C4: N/A | D4: Unknown | E4: N/A | F4: Basic | G4: Dual | H4: Low | I4: Full IP | N4: Declining | O4: Waived | P4: Full IP
A5: Disapproved | B5: Non-Tissue: Moderate | F5: None | G5: Multi | O5: N/A
A6: Phase-Out | B6: Non-Tissue: Low (COTS) | F6: N/A
F20: 6 | J20: 10 | K20: 11 | L20: 12 | M20: 13
E22: Spec Yields | J22: Harvesting Yields | N22: Pigs consumed | O22: Quality Yield Freeze/Thaw
C23: Labor | D23: Cube | E23: Tier | F23: Martins_Yield | G23: Nahunta_Yield | H23: Customs_Yield | I23: Parks_Yield | J23: Martins_Yield | K23: Nahunta_Yield | L23: Customs_Yield | M23: Parks_Yield
A24: 666501 | B24: TISS,PORCINE,AORTA SEGMENTS | C24: 1 | D24: 0.05 | E24: 3 | F24: 0.99 | G24: 0.99 | H24: 0.99 | I24: 0.99 | J24: 0.95 | K24: 0.95 | L24: 0.95 | M24: 0.95 | N24: 1 | O24: 0.95
A25: 666502 | B25: TISS,PORCINE,BARIATRIC BLOCK | C25: 3.5 | D25: 1.5 | E25: 3 | F25: 0.8 | G25: 0.9 | H25: 0.9 | I25: 0.7 | J25: 0.95 | K25: 0.95 | L25: 0.7 | M25: 0.95 | N25: 1 | O25: 0.9
A26: 666505 | B26: TISS,PORCINE,LIVER | C26: 1 | D26: 0.2 | E26: 1 | F26: 0.9 | G26: 0.9 | H26: 0.9 | I26: 0.7 | J26: 0.95 | K26: 0.95 | L26: 0.95 | M26: 0.95 | N26: 0.5 | O26: 0.95
A27: 666506 | B27: TISS,PORCINE,PELVIC BLOCK | C27: 3 | D27: 1 | E27: 2 | F27: 0.45 | G27: 0.06 | H27: 0.45 | I27: 0.35 | J27: 0.25 | K27: 0.25 | L27: 0.25 | M27: 0.2 | N27: 1 | O27: 0.85
A28: 666507 | B28: TISS,PORCINE,FULL THOR AND BARI BLOCK | C28: 5 | D28: 1.8 | E28: 3 | F28: 0.8 | G28: 0.6 | H28: 0.7 | I28: 0.7 | J28: 0.95 | K28: 0.95 | L28: 0.95 | M28: 0.95 | N28: 1 | O28: 0.9
A29: 666509 | B29: TISS,PORCINE,JEJUNUM,6FT | C29: 4 | D29: 0.5 | E29: 1 | F29: 0.95 | G29: 0.95 | H29: 0.95 | I29: 0.7 | J29: 0.95 | K29: 0.95 | L29: 0.95 | M29: 0.95 | N29: 0.5 | O29: 0.85
A30: 666510 | B30: TISS,PORCINE,JEJUNUM (3FT) | C30: 4 | D30: 0.3 | E30: 1 | F30: 0.95 | G30: 0.95 | H30: 0.95 | I30: 0.7 | J30: 0.95 | K30: 0.95 | L30: 0.95 | M30: 0.95 | N30: 0.33 | O30: 0.85
A31: 666511 | B31: TISS,PORCINE,KIDNEY BLOCK | C31: 1 | D31: 0.5 | E31: 1 | F31: 0.9 | G31: 0.9 | H31: 0.9 | I31: 0.7 | J31: 0.95 | K31: 0.95 | L31: 0.95 | M31: 0.95 | N31: 0.5 | O31: 0.8
A32: 666513 | B32: TISS,PORCINE,LIVER WITH GALLBLADDER | C32: 1 | D32: 0.5 | E32: 2 | F32: 0.9 | G32: 0.9 | H32: 0.9 | I32: 0.7 | J32: 0.95 | K32: 0.95 | L32: 0.95 | M32: 0.95 | N32: 1 | O32: 0.85
A33: 666516 | B33: TISS,PORCINE,OMENTUM | C33: 1 | D33: 0.1 | E33: 3 | F33: 0.9 | G33: 0.9 | H33: 0.9 | I33: 0.7 | J33: 0.95 | K33: 0.95 | L33: 0.95 | M33: 0.95 | N33: 1 | O33: 0.8
A34: 666517 | B34: TISS,PORCINE,PANCREAS | C34: 1 | D34: 0.2 | E34: 3 | F34: 0.9 | G34: 0.9 | H34: 0.9 | I34: 0.7 | J34: 0.95 | K34: 0.95 | L34: 0.95 | M34: 0.95 | N34: 1 | O34: 0.8
A35: 666518 | B35: TISS,PORCINE,FEM,PELVIC BLOCK,INTACT,SM | C35: 3 | D35: 1 | E35: 2 | F35: 0.45 | G35: 0.06 | H35: 0.45 | I35: 0.35 | J35: 0.25 | K35: 0.25 | L35: 0.25 | M35: 0.2 | N35: 1 | O35: 0.85
... A46: 666545 | B46: TISS, Rectum | C46: 3 | D46: 0.1 | E46: 2 | F46: 0.95 | G46: 0.95 | H46: 0.95 | I46: 0.7 | J46: 0.95 | K46: 0.95 | L46: 0.95 | M46: 0.95 | N46: 1 | O46: 0.95

Sheet SHAllocations
G8: Weeks: | H8: 12
K10: 7 | N10: 10 | Q10: 13 | T10: 16
G11: Quarter Volume: | H11: Weekly: | I11: All% | K11: Nahunta | N11: Martins | Q11: Customs | T11: Parks
K12: % | L12: Volume | M12: Capacity | N12: % | O12: Volume | P12: Capacity | Q12: % | R12: Volume | S12: Capacity | T12: % | U12: Volume | V12: Capacity
E13: 666501 | F13: TISS,PORCINE,AORTA SEGMENTS | G13: =VLOOKUP(E13,ModelsDemand_ToTissue!$D$42:$H$85,5,FALSE) -> 3131 | H13: =IF(G13>0,ROUND(G13/$H$8,0),"") -> 261 | I13: =SUM(K13,N13,Q13,T13) -> 1 | K13: 0.09 | L13: =IFERROR(ROUND(K13*H13,0),"") -> 23 | N13: 0.83 | O13: =IFERROR(ROUND(N13*H13,0),"") -> 217 | Q13: 0.08 | R13: =IFERROR(ROUND(Q13*H13,0),"") -> 21 | T13: 0 | U13: =IFERROR(ROUND(T13*H13,0),"") -> 0
E14: 666502 | F14: TISS,PORCINE,BARIATRIC BLOCK | G14: =VLOOKUP(E14,ModelsDemand_ToTissue!$D$42:$H$85,5,FALSE) -> 1980 | H14: =IF(G14>0,ROUND(G14/$H$8,0),"") -> 165 | I14: =SUM(K14,N14,Q14,T14) -> 1 | K14: 0 | L14: =IFERROR(ROUND(K14*H14,0),"") -> 0 | N14: 0.76 | O14: =IFERROR(ROUND(N14*H14,0),"") -> 125 | Q14: 0.18 | R14: =IFERROR(ROUND(Q14*H14,0),"") -> 30 | T14: 0.06 | U14: =IFERROR(ROUND(T14*H14,0),"") -> 10
E15: 666505 | F15: TISS,PORCINE,LIVER | G15: =VLOOKUP(E15,ModelsDemand_ToTissue!$D$42:$H$85,5,FALSE) -> 303 | H15: =IF(G15>0,ROUND(G15/$H$8,0),"") -> 25 | I15: =SUM(K15,N15,Q15,T15) -> 1 | K15: 0.32 | L15: =IFERROR(ROUND(K15*H15,0),"") -> 8 | N15: 0 | O15: =IFERROR(ROUND(N15*H15,0),"") -> 0 | Q15: 0.68 | R15: =IFERROR(ROUND(Q15*H15,0),"") -> 17 | T15: 0 | U15: =IFERROR(ROUND(T15*H15,0),"") -> 0
E16: 666506 | F16: TISS,PORCINE,PELVIC BLOCK | G16: =VLOOKUP(E16,ModelsDemand_ToTissue!$D$42:$H$85,5,FALSE) -> 626 | H16: =IF(G16>0,ROUND(G16/$H$8,0),"") -> 52 | I16: =SUM(K16,N16,Q16,T16) -> 1 | K16: 0 | L16: =IFERROR(ROUND(K16*H16,0),"") -> 0 | N16: 1 | O16: =IFERROR(ROUND(N16*H16,0),"") -> 52 | Q16: 0 | R16: =IFERROR(ROUND(Q16*H16,0),"") -> 0 | T16: 0 | U16: =IFERROR(ROUND(T16*H16,0),"") -> 0
E17: 666507 | F17: TISS,PORCINE,FULL THOR AND BARI BLOCK | G17: =VLOOKUP(E17,ModelsDemand_ToTissue!$D$42:$H$85,5,FALSE) -> 99 | H17: =IF(G17>0,ROUND(G17/$H$8,0),"") -> 8 | I17: =SUM(K17,N17,Q17,T17) -> 1 | K17: 1 | L17: =IFERROR(ROUND(K17*H17,0),"") -> 8 | N17: 0 | O17: =IFERROR(ROUND(N17*H17,0),"") -> 0 | Q17: 0 | R17: =IFERROR(ROUND(Q17*H17,0),"") -> 0 | T17: 0 | U17: =IFERROR(ROUND(T17*H17,0),"") -> 0
E18: 666509 | F18: TISS,PORCINE,JEJUNUM,6FT | G18: =VLOOKUP(E18,ModelsDemand_ToTissue!$D$42:$H$85,5,FALSE) -> 402 | H18: =IF(G18>0,ROUND(G18/$H$8,0),"") -> 34 | I18: =SUM(K18,N18,Q18,T18) -> 1 | K18: 0.95 | L18: =IFERROR(ROUND(K18*H18,0),"") -> 32 | N18: 0 | O18: =IFERROR(ROUND(N18*H18,0),"") -> 0 | Q18: 0 | R18: =IFERROR(ROUND(Q18*H18,0),"") -> 0 | T18: 0.05 | U18: =IFERROR(ROUND(T18*H18,0),"") -> 2
E19: 666510 | F19: TISS,PORCINE,JEJUNUM (3FT) | G19: =VLOOKUP(E19,ModelsDemand_ToTissue!$D$42:$H$85,5,FALSE) -> 88 | H19: =IF(G19>0,ROUND(G19/$H$8,0),"") -> 7 | I19: =SUM(K19,N19,Q19,T19) -> 1 | K19: 0.9 | L19: =IFERROR(ROUND(K19*H19,0),"") -> 6 | N19: 0 | O19: =IFERROR(ROUND(N19*H19,0),"") -> 0 | Q19: 0.1 | R19: =IFERROR(ROUND(Q19*H19,0),"") -> 1 | T19: 0 | U19: =IFERROR(ROUND(T19*H19,0),"") -> 0
E20: 666511 | F20: TISS,PORCINE,KIDNEY BLOCK | G20: =VLOOKUP(E20,ModelsDemand_ToTissue!$D$42:$H$85,5,FALSE) -> 45 | H20: =IF(G20>0,ROUND(G20/$H$8,0),"") -> 4 | I20: =SUM(K20,N20,Q20,T20) -> 1 | K20: 1 | L20: =IFERROR(ROUND(K20*H20,0),"") -> 4 | N20: 0 | O20: =IFERROR(ROUND(N20*H20,0),"") -> 0 | Q20: 0 | R20: =IFERROR(ROUND(Q20*H20,0),"") -> 0 | T20: 0 | U20: =IFERROR(ROUND(T20*H20,0),"") -> 0
E21: 666513 | F21: TISS,PORCINE,LIVER WITH GALLBLADDER | G21: =VLOOKUP(E21,ModelsDemand_ToTissue!$D$42:$H$85,5,FALSE) -> 182 | H21: =IF(G21>0,ROUND(G21/$H$8,0),"") -> 15 | I21: =SUM(K21,N21,Q21,T21) -> 1 | K21: 0.3 | L21: =IFERROR(ROUND(K21*H21,0),"") -> 5 | N21: 0 | O21: =IFERROR(ROUND(N21*H21,0),"") -> 0 | Q21: 0.7 | R21: =IFERROR(ROUND(Q21*H21,0),"") -> 11 | T21: 0 | U21: =IFERROR(ROUND(T21*H21,0),"") -> 0
E22: 666516 | F22: TISS,PORCINE,OMENTUM | G22: =VLOOKUP(E22,ModelsDemand_ToTissue!$D$42:$H$85,5,FALSE) -> 303 | H22: =IF(G22>0,ROUND(G22/$H$8,0),"") -> 25 | I22: =SUM(K22,N22,Q22,T22) -> 1 | K22: 0.5 | L22: =IFERROR(ROUND(K22*H22,0),"") -> 13 | N22: 0 | O22: =IFERROR(ROUND(N22*H22,0),"") -> 0 | Q22: 0.5 | R22: =IFERROR(ROUND(Q22*H22,0),"") -> 13 | T22: 0 | U22: =IFERROR(ROUND(T22*H22,0),"") -> 0
E23: 666517 | F23: TISS,PORCINE,PANCREAS | G23: =VLOOKUP(E23,ModelsDemand_ToTissue!$D$42:$H$85,5,FALSE) -> 303 | H23: =IF(G23>0,ROUND(G23/$H$8,0),"") -> 25 | I23: =SUM(K23,N23,Q23,T23) -> 1 | K23: 0.69 | L23: =IFERROR(ROUND(K23*H23,0),"") -> 17 | N23: 0 | O23: =IFERROR(ROUND(N23*H23,0),"") -> 0 | Q23: 0.31 | R23: =IFERROR(ROUND(Q23*H23,0),"") -> 8 | T23: 0 | U23: =IFERROR(ROUND(T23*H23,0),"") -> 0
E24: 666518 | F24: TISS,PORCINE,FEM,PELVIC BLOCK,INTACT,SM | G24: =VLOOKUP(E24,ModelsDemand_ToTissue!$D$42:$H$85,5,FALSE) -> 0 | H24: =IF(G24>0,ROUND(G24/$H$8,0),"") | I24: =SUM(K24,N24,Q24,T24) -> 1 | K24: 0 | L24: =IFERROR(ROUND(K24*H24,0),"") | N24: 1 | O24: =IFERROR(ROUND(N24*H24,0),"") | Q24: 0 | R24: =IFERROR(ROUND(Q24*H24,0),"") | T24: 0 | U24: =IFERROR(ROUND(T24*H24,0),"")
... E35: 666545 | F35: TISS, Rectum | G35: =VLOOKUP(E35,ModelsDemand_ToTissue!$D$42:$H$85,5,FALSE) -> 158.5 | H35: =IF(G35>0,ROUND(G35/$H$8,0),"") -> 13 | I35: =SUM(K35,N35,Q35,T35) -> 1 | K35: 0 | L35: =IFERROR(ROUND(K35*H35,0),"") -> 0 | N35: 0 | O35: =IFERROR(ROUND(N35*H35,0),"") -> 0 | Q35: 1 | R35: =IFERROR(ROUND(Q35*H35,0),"") -> 13 | T35: 0 | U35: =IFERROR(ROUND(T35*H35,0),"") -> 0
E38: 666504 | F38: TISS,PORCINE,BELLY,LARGE | G38: =VLOOKUP(E38,ModelsDemand_ToTissue!$D$42:$H$85,5,FALSE) -> 700.5 | H38: =IF(G38>0,ROUND(G38/$H$8,0),"") -> 58
E39: 666512 | F39: TISS,PORCINE,LEAF FAT | G39: =VLOOKUP(E39,ModelsDemand_ToTissue!$D$42:$H$85,5,FALSE) -> 4246.5 | H39: =IF(G39>0,ROUND(G39/$H$8,0),"") -> 354
E40: 666534 | F40: TISS,PORCINE,BELLY,LARGE | G40: =VLOOKUP(E40,ModelsDemand_ToTissue!$D$42:$H$85,5,FALSE) -> #N/A
E46: 666357 | F46: S/A,TISS,BELLY,LARGE,PLANED | G46: =VLOOKUP(E46,ModelsDemand_ToTissue!$D$42:$H$85,5,FALSE) -> 2446 | H46: =IF(G46>0,ROUND(G46/$H$8,0),"") -> 204
E47: 666356 | F47: S/A,TISS,BELLY,PLANED,3/4IN | G47: =VLOOKUP(E47,ModelsDemand_ToTissue!$D$42:$H$85,5,FALSE) -> 975.8 | H47: =IF(G47>0,ROUND(G47/$H$8,0),"") -> 81
E48: 666371 | F48: S/A,TISS,BELLY,LARGE,MUSCLE SHELF | G48: =VLOOKUP(E48,ModelsDemand_ToTissue!$D$42:$H$85,5,FALSE) -> 303 | H48: =IF(G48>0,ROUND(G48/$H$8,0),"") -> 25
E49: 666360 | F49: S/A,TISS,LEAF FAT MEMBRANE | G49: =VLOOKUP(E49,ModelsDemand_ToTissue!$D$42:$H$85,5,FALSE) -> 75 | H49: =IF(G49>0,ROUND(G49/$H$8,0),"") -> 6
E50: 666363 | F50: S/A,TISS,LEAF FAT MEMBRANE,DYED | G50: =VLOOKUP(E50,ModelsDemand_ToTissue!$D$42:$H$85,5,FALSE) -> 952 | H50: =IF(G50>0,ROUND(G50/$H$8,0),"") -> 79
E51: 666372 | F51: S/A,TISS,BELLY,PLANED,SKINLESS,1/2IN | G51: =VLOOKUP(E51,ModelsDemand_ToTissue!$D$42:$H$85,5,FALSE) -> 168.5 | H51: =IF(G51>0,ROUND(G51/$H$8,0),"") -> 14
E52: 666362 | F52: S/A,TISS,LEAF FAT FAT,DYED | G52: =VLOOKUP(E52,ModelsDemand_ToTissue!$D$42:$H$85,5,FALSE) -> 760 | H52: =IF(G52>0,ROUND(G52/$H$8,0),"") -> 63
E53: 666361 | F53: S/A,TISS,SKIN | G53: =VLOOKUP(E53,ModelsDemand_ToTissue!$D$42:$H$85,5,FALSE) -> 117 | H53: =IF(G53>0,ROUND(G53/$H$8,0),"") -> 10
E54: 666433 | F54: S/A. TISS, LEAF FAT, INTACT, DYED | G54: =VLOOKUP(E54,ModelsDemand_ToTissue!$D$42:$H$85,5,FALSE) -> 1485 | H54: =IF(G54>0,ROUND(G54/$H$8,0),"") -> 124
E55: 666435 | F55: S/A. TISS, LEAF FAT, NON-INTACT, DYED | G55: =VLOOKUP(E55,ModelsDemand_ToTissue!$D$42:$H$85,5,FALSE) -> 1485 | H55: =IF(G55>0,ROUND(G55/$H$8,0),"") -> 124

Sheet Martins
C1: Martins Capacity Data
E2: *Figure out yields by parts, each part will have their own SPEC yield
E3: Sh Yield 2
E4: 0.9 | F4: *Each part/tissue should have its own yield
D5: Porks/Week | E5: SH Yield | F5: Harvesting Yield | G5: Freeze Thaw Yield
C6: T-max | D6: 2500 | E6: =D7/D6 -> 0.28 | F6: 1 | G6: 0.85
C7: Actual capacity (max recorded) | D7: 700
C8: Intuitive Load | E8: (Sum all pork equivalent parts from below)
C9: Other Demand | D9: 1500
C10: Labor utilization
C11: Freezer Utilization
D15: Constraint | E15: Labor | F15: Freezer Space | G15: Trips | H15: Pigs | I15: Space
H18: Quarter | J18: Quarter | K18: Weekly
E19: Labor (Mins) | F19: Freezer Volume | G19: Quality Yield Freeze/Thaw | H19: Q BP Tissues | I19: Allocation | J19: Weeks | K19: Tissues | L19: Pigs | M19: Pigs Consumed | N19: Labor Consumed | O19: Cube/Week consumed | P19: Spec yield | Q19: Harvesting Yield | S19: Code | T19: Weekly | U19: WkPigs | V19: WkLabor | W19: WkCube | Y19: Ordered and sorted by Weekly
C20: 666501 | D20: TISS,PORCINE,AORTA SEGMENTS | E20: =VLOOKUP($C20,'Yields-Labor-Cube'!$A$24:$P$48,3,FALSE) -> 1 | F20: =VLOOKUP($C20,'Yields-Labor-Cube'!$A$24:$P$48,4,FALSE) -> 0.05 | G20: =VLOOKUP($C20,'Yields-Labor-Cube'!$A$24:$P$48,15,FALSE) -> 0.95 | H20: =VLOOKUP($C20,ModelsDemand_ToTissue!$D$42:$H$78,5,0) -> 3131 | I20: =VLOOKUP(C20,SHAllocations!E13:V40,10,FALSE) -> 0.83 | J20: =SHAllocations!$H$8 -> 12 | K20: =ROUND(H20/J20*I20,0) -> 217 | L20: 1 | M20: =ROUND(K20*L20,0) -> 217 | N20: =E20*K20/(Q20*60) -> 3.8070175 | O20: =F20*K20 -> 10.85 | P20: =VLOOKUP(Martins!C20,'Yields-Labor-Cube'!$A$23:$I$47,6,FALSE) -> 0.99 | Q20: =VLOOKUP($C20,'Yields-Labor-Cube'!$A$24:$O$47,10,FALSE) -> 0.95 | S20: =C20 -> 666501 | T20: =K20 -> 217 | U20: =M20 -> 217 | V20: =N20 -> 3.8070175 | W20: =O20 -> 10.85 | Y20: {=_xlfn.SORTBY(S20:W42,T20:T42,-1)} -> 666501 | Z20: 217 | AA20: 217 | AB20: 3.8070175 | AC20: 10.85 | AD20: 10 seconds per bad part
C21: 666502 | D21: TISS,PORCINE,BARIATRIC BLOCK | E21: =VLOOKUP($C21,'Yields-Labor-Cube'!$A$24:$P$48,3,FALSE) -> 3.5 | F21: =VLOOKUP($C21,'Yields-Labor-Cube'!$A$24:$P$48,4,FALSE) -> 1.5 | G21: =VLOOKUP($C21,'Yields-Labor-Cube'!$A$24:$P$48,15,FALSE) -> 0.9 | H21: =VLOOKUP($C21,ModelsDemand_ToTissue!$D$42:$H$78,5,0) -> 1980 | I21: =VLOOKUP(C21,SHAllocations!E14:V41,10,FALSE) -> 0.76 | J21: =SHAllocations!$H$8 -> 12 | K21: =ROUND(H21/J21*I21,0) -> 125 | L21: 1 | M21: =ROUND(K21*L21,0) -> 125 | N21: =E21*K21/(Q21*60) -> 7.6754386 | O21: =F21*K21 -> 187.5 | P21: =VLOOKUP(Martins!C21,'Yields-Labor-Cube'!$A$23:$I$47,6,FALSE) -> 0.8 | Q21: =VLOOKUP($C21,'Yields-Labor-Cube'!$A$24:$O$47,10,FALSE) -> 0.95 | S21: =C21 -> 666502 | T21: =K21 -> 125 | U21: =M21 -> 125 | V21: =N21 -> 7.6754386 | W21: =O21 -> 187.5 | Y21: 666541 | Z21: 164 | AA21: 164 | AB21: 32.8 | AC21: 164
C22: 666505 | D22: TISS,PORCINE,LIVER | E22: =VLOOKUP($C22,'Yields-Labor-Cube'!$A$24:$P$48,3,FALSE) -> 1 | F22: =VLOOKUP($C22,'Yields-Labor-Cube'!$A$24:$P$48,4,FALSE) -> 0.2 | G22: =VLOOKUP($C22,'Yields-Labor-Cube'!$A$24:$P$48,15,FALSE) -> 0.95 | H22: =VLOOKUP($C22,ModelsDemand_ToTissue!$D$42:$H$78,5,0) -> 303 | I22: =VLOOKUP(C22,SHAllocations!E15:V42,10,FALSE) -> 0 | J22: =SHAllocations!$H$8 -> 12 | K22: =ROUND(H22/J22*I22,0) -> 0 | L22: 0.5 | M22: =ROUND(K22*L22,0) -> 0 | N22: =E22*K22/(Q22*60) -> 0 | O22: =F22*K22 -> 0 | P22: =VLOOKUP(Martins!C22,'Yields-Labor-Cube'!$A$23:$I$47,6,FALSE) -> 0.9 | Q22: =VLOOKUP($C22,'Yields-Labor-Cube'!$A$24:$O$47,10,FALSE) -> 0.95 | S22: =C22 -> 666505 | T22: =K22 -> 0 | U22: =M22 -> 0 | V22: =N22 -> 0 | W22: =O22 -> 0 | Y22: 666502 | Z22: 125 | AA22: 125 | AB22: 7.6754386 | AC22: 187.5
C23: 666506 | D23: TISS,PORCINE,PELVIC BLOCK | E23: =VLOOKUP($C23,'Yields-Labor-Cube'!$A$24:$P$48,3,FALSE) -> 3 | F23: =VLOOKUP($C23,'Yields-Labor-Cube'!$A$24:$P$48,4,FALSE) -> 1 | G23: =VLOOKUP($C23,'Yields-Labor-Cube'!$A$24:$P$48,15,FALSE) -> 0.85 | H23: =VLOOKUP($C23,ModelsDemand_ToTissue!$D$42:$H$78,5,0) -> 626 | I23: =VLOOKUP(C23,SHAllocations!E16:V43,10,FALSE) -> 1 | J23: =SHAllocations!$H$8 -> 12 | K23: =ROUND(H23/J23*I23,0) -> 52 | L23: 1 | M23: =ROUND(K23*L23,0) -> 52 | N23: =E23*K23/(Q23*60) -> 10.4 | O23: =F23*K23 -> 52 | P23: =VLOOKUP(Martins!C23,'Yields-Labor-Cube'!$A$23:$I$47,6,FALSE) -> 0.45 | Q23: =VLOOKUP($C23,'Yields-Labor-Cube'!$A$24:$O$47,10,FALSE) -> 0.25 | S23: =C23 -> 666506 | T23: =K23 -> 52 | U23: =M23 -> 52 | V23: =N23 -> 10.4 | W23: =O23 -> 52 | Y23: 666522 | Z23: 86 | AA23: 43 | AB23: 0.84313725 | AC23: 8.6
C24: 666507 | D24: TISS,PORCINE,FULL THOR AND BARI BLOCK | E24: =VLOOKUP($C24,'Yields-Labor-Cube'!$A$24:$P$48,3,FALSE) -> 5 | F24: =VLOOKUP($C24,'Yields-Labor-Cube'!$A$24:$P$48,4,FALSE) -> 1.8 | G24: =VLOOKUP($C24,'Yields-Labor-Cube'!$A$24:$P$48,15,FALSE) -> 0.9 | H24: =VLOOKUP($C24,ModelsDemand_ToTissue!$D$42:$H$78,5,0) -> 99 | I24: =VLOOKUP(C24,SHAllocations!E17:V44,10,FALSE) -> 0 | J24: =SHAllocations!$H$8 -> 12 | K24: =ROUND(H24/J24*I24,0) -> 0 | L24: 1 | M24: =ROUND(K24*L24,0) -> 0 | N24: =E24*K24/(Q24*60) -> 0 | O24: =F24*K24 -> 0 | P24: =VLOOKUP(Martins!C24,'Yields-Labor-Cube'!$A$23:$I$47,6,FALSE) -> 0.8 | Q24: =VLOOKUP($C24,'Yields-Labor-Cube'!$A$24:$O$47,10,FALSE) -> 0.95 | S24: =C24 -> 666507 | T24: =K24 -> 0 | U24: =M24 -> 0 | V24: =N24 -> 0 | W24: =O24 -> 0 | Y24: 666506 | Z24: 52 | AA24: 52 | AB24: 10.4 | AC24: 52
