Workbook

Sheet Attainment & Alloc Summary
A1: Attainment & Allocations — Selected-Weeks Summary
A2: Pick a week range and a mode below. Ask/Harvested columns show the AVERAGE per week or the TOTAL across the selected weeks (per Mode). "% of Ask" is each house's share of that tissue's total ask over the window (independent of mode). Ask/Attained use the recorded per-house tab figures (cols E-L). | P2: 46020 | Q2: 12_29_25
P3: 46027 | Q3: 01_05_26
A4: From week: | C4: 46020 | F4: Variables: Weeks, mode: Average or total | K4: =L11/C7 -> 10.0104 | P4: 46034 | Q4: 1_12_26
A5: To week: | C5: 46188 | P5: 46041 | Q5: 1_19_26
A6: Mode: | C6: Average | P6: 46048 | Q6: 1_26_26
A7: Weeks selected: | C7: =COUNTIFS($P$2:$P$26,">="&$C$4,$P$2:$P$26,"<="&$C$5) -> 25 | P7: 46055 | Q7: 02_02_26
P8: 46062 | Q8: 02_09_26
A9: PN | B9: Tissue | C9: Nahunta | F9: Martin | I9: Custom | L9: All SH | P9: 46069 | Q9: 02_16_26
C10: =IF($C$6="Total","Total Ask","Avg Ask/wk") -> Avg Ask/wk | D10: =IF($C$6="Total","Total Harv.","Avg Harv./wk") -> Avg Harv./wk | E10: % of Ask | F10: =IF($C$6="Total","Total Ask","Avg Ask/wk") -> Avg Ask/wk | G10: =IF($C$6="Total","Total Harv.","Avg Harv./wk") -> Avg Harv./wk | H10: % of Ask | I10: =IF($C$6="Total","Total Ask","Avg Ask/wk") -> Avg Ask/wk | J10: =IF($C$6="Total","Total Harv.","Avg Harv./wk") -> Avg Harv./wk | K10: % of Ask | L10: =IF($C$6="Total","Total Ask","Avg Ask/wk") -> Avg Ask/wk | M10: =IF($C$6="Total","Total Harv.","Avg Harv./wk") -> Avg Harv./wk | N10: Attainment % | P10: 46076 | Q10: 02_23_26
A11: 666501 | B11: Aorta | C11: =IF($C$6="Total",SUMIFS('PvA Data'!$F$2:$F$1577,'PvA Data'!$B$2:$B$1577,">="&$C$4,'PvA Data'!$B$2:$B$1577,"<="&$C$5,'PvA Data'!$C$2:$C$1577,"Nahunta",'PvA Data'!$E$2:$E$1577,$B11),IFERROR(AVERAGEIFS('PvA Data'!$F$2:$F$1577,'PvA Data'!$B$2:$B$1577,">="&$C$4,'PvA Data'!$B$2:$B$1577,"<="&$C$5,'PvA Data'!$C$2:$C$1577,"Nahunta",'PvA Data'!$E$2:$E$1577,$B11),0)) -> 22.2 | D11: =IF($C$6="Total",SUMIFS('PvA Data'!$G$2:$G$1577,'PvA Data'!$B$2:$B$1577,">="&$C$4,'PvA Data'!$B$2:$B$1577,"<="&$C$5,'PvA Data'!$C$2:$C$1577,"Nahunta",'PvA Data'!$E$2:$E$1577,$B11),IFERROR(AVERAGEIFS('PvA Data'!$G$2:$G$1577,'PvA Data'!$B$2:$B$1577,">="&$C$4,'PvA Data'!$B$2:$B$1577,"<="&$C$5,'PvA Data'!$C$2:$C$1577,"Nahunta",'PvA Data'!$E$2:$E$1577,$B11),0)) -> 22.44 | E11: =IFERROR(SUMIFS('PvA Data'!$F$2:$F$1577,'PvA Data'!$B$2:$B$1577,">="&$C$4,'PvA Data'!$B$2:$B$1577,"<="&$C$5,'PvA Data'!$C$2:$C$1577,"Nahunta",'PvA Data'!$E$2:$E$1577,$B11)/SUMIFS('PvA Data'!$F$2:$F$1577,'PvA Data'!$B$2:$B$1577,">="&$C$4,'PvA Data'!$B$2:$B$1577,"<="&$C$5,'PvA Data'!$E$2:$E$1577,$B11),"") -> 0.088707744 | F11: =IF($C$6="Total",SUMIFS('PvA Data'!$F$2:$F$1577,'PvA Data'!$B$2:$B$1577,">="&$C$4,'PvA Data'!$B$2:$B$1577,"<="&$C$5,'PvA Data'!$C$2:$C$1577,"Martin",'PvA Data'!$E$2:$E$1577,$B11),IFERROR(AVERAGEIFS('PvA Data'!$F$2:$F$1577,'PvA Data'!$B$2:$B$1577,">="&$C$4,'PvA Data'!$B$2:$B$1577,"<="&$C$5,'PvA Data'!$C$2:$C$1577,"Martin",'PvA Data'!$E$2:$E$1577,$B11),0)) -> 207.84 | G11: =IF($C$6="Total",SUMIFS('PvA Data'!$G$2:$G$1577,'PvA Data'!$B$2:$B$1577,">="&$C$4,'PvA Data'!$B$2:$B$1577,"<="&$C$5,'PvA Data'!$C$2:$C$1577,"Martin",'PvA Data'!$E$2:$E$1577,$B11),IFERROR(AVERAGEIFS('PvA Data'!$G$2:$G$1577,'PvA Data'!$B$2:$B$1577,">="&$C$4,'PvA Data'!$B$2:$B$1577,"<="&$C$5,'PvA Data'!$C$2:$C$1577,"Martin",'PvA Data'!$E$2:$E$1577,$B11),0)) -> 206.96 | H11: =IFERROR(SUMIFS('PvA Data'!$F$2:$F$1577,'PvA Data'!$B$2:$B$1577,">="&$C$4,'PvA Data'!$B$2:$B$1577,"<="&$C$5,'PvA Data'!$C$2:$C$1577,"Martin",'PvA Data'!$E$2:$E$1577,$B11)/SUMIFS('PvA Data'!$F$2:$F$1577,'PvA Data'!$B$2:$B$1577,">="&$C$4,'PvA Data'!$B$2:$B$1577,"<="&$C$5,'PvA Data'!$E$2:$E$1577,$B11),"") -> 0.83049628 | I11: =IF($C$6="Total",SUMIFS('PvA Data'!$F$2:$F$1577,'PvA Data'!$B$2:$B$1577,">="&$C$4,'PvA Data'!$B$2:$B$1577,"<="&$C$5,'PvA Data'!$C$2:$C$1577,"Custom",'PvA Data'!$E$2:$E$1577,$B11),IFERROR(AVERAGEIFS('PvA Data'!$F$2:$F$1577,'PvA Data'!$B$2:$B$1577,">="&$C$4,'PvA Data'!$B$2:$B$1577,"<="&$C$5,'PvA Data'!$C$2:$C$1577,"Custom",'PvA Data'!$E$2:$E$1577,$B11),0)) -> 20.22 | J11: =IF($C$6="Total",SUMIFS('PvA Data'!$G$2:$G$1577,'PvA Data'!$B$2:$B$1577,">="&$C$4,'PvA Data'!$B$2:$B$1577,"<="&$C$5,'PvA Data'!$C$2:$C$1577,"Custom",'PvA Data'!$E$2:$E$1577,$B11),IFERROR(AVERAGEIFS('PvA Data'!$G$2:$G$1577,'PvA Data'!$B$2:$B$1577,">="&$C$4,'PvA Data'!$B$2:$B$1577,"<="&$C$5,'PvA Data'!$C$2:$C$1577,"Custom",'PvA Data'!$E$2:$E$1577,$B11),0)) -> 18.96 | K11: =IFERROR(SUMIFS('PvA Data'!$F$2:$F$1577,'PvA Data'!$B$2:$B$1577,">="&$C$4,'PvA Data'!$B$2:$B$1577,"<="&$C$5,'PvA Data'!$C$2:$C$1577,"Custom",'PvA Data'!$E$2:$E$1577,$B11)/SUMIFS('PvA Data'!$F$2:$F$1577,'PvA Data'!$B$2:$B$1577,">="&$C$4,'PvA Data'!$B$2:$B$1577,"<="&$C$5,'PvA Data'!$E$2:$E$1577,$B11),"") -> 0.080795972 | L11: =C11+F11+I11 -> 250.26 | M11: =D11+G11+J11 -> 248.36 | N11: =IFERROR(M11/L11,"") -> 0.9924079 | P11: 46083 | Q11: 03_02_26
A12: 666502 | B12: Bariatric | C12: =IF($C$6="Total",SUMIFS('PvA Data'!$F$2:$F$1577,'PvA Data'!$B$2:$B$1577,">="&$C$4,'PvA Data'!$B$2:$B$1577,"<="&$C$5,'PvA Data'!$C$2:$C$1577,"Nahunta",'PvA Data'!$E$2:$E$1577,$B12),IFERROR(AVERAGEIFS('PvA Data'!$F$2:$F$1577,'PvA Data'!$B$2:$B$1577,">="&$C$4,'PvA Data'!$B$2:$B$1577,"<="&$C$5,'PvA Data'!$C$2:$C$1577,"Nahunta",'PvA Data'!$E$2:$E$1577,$B12),0)) -> 0 | D12: =IF($C$6="Total",SUMIFS('PvA Data'!$G$2:$G$1577,'PvA Data'!$B$2:$B$1577,">="&$C$4,'PvA Data'!$B$2:$B$1577,"<="&$C$5,'PvA Data'!$C$2:$C$1577,"Nahunta",'PvA Data'!$E$2:$E$1577,$B12),IFERROR(AVERAGEIFS('PvA Data'!$G$2:$G$1577,'PvA Data'!$B$2:$B$1577,">="&$C$4,'PvA Data'!$B$2:$B$1577,"<="&$C$5,'PvA Data'!$C$2:$C$1577,"Nahunta",'PvA Data'!$E$2:$E$1577,$B12),0)) -> 0 | E12: =IFERROR(SUMIFS('PvA Data'!$F$2:$F$1577,'PvA Data'!$B$2:$B$1577,">="&$C$4,'PvA Data'!$B$2:$B$1577,"<="&$C$5,'PvA Data'!$C$2:$C$1577,"Nahunta",'PvA Data'!$E$2:$E$1577,$B12)/SUMIFS('PvA Data'!$F$2:$F$1577,'PvA Data'!$B$2:$B$1577,">="&$C$4,'PvA Data'!$B$2:$B$1577,"<="&$C$5,'PvA Data'!$E$2:$E$1577,$B12),"") -> 0 | F12: =IF($C$6="Total",SUMIFS('PvA Data'!$F$2:$F$1577,'PvA Data'!$B$2:$B$1577,">="&$C$4,'PvA Data'!$B$2:$B$1577,"<="&$C$5,'PvA Data'!$C$2:$C$1577,"Martin",'PvA Data'!$E$2:$E$1577,$B12),IFERROR(AVERAGEIFS('PvA Data'!$F$2:$F$1577,'PvA Data'!$B$2:$B$1577,">="&$C$4,'PvA Data'!$B$2:$B$1577,"<="&$C$5,'PvA Data'!$C$2:$C$1577,"Martin",'PvA Data'!$E$2:$E$1577,$B12),0)) -> 138.04 | G12: =IF($C$6="Total",SUMIFS('PvA Data'!$G$2:$G$1577,'PvA Data'!$B$2:$B$1577,">="&$C$4,'PvA Data'!$B$2:$B$1577,"<="&$C$5,'PvA Data'!$C$2:$C$1577,"Martin",'PvA Data'!$E$2:$E$1577,$B12),IFERROR(AVERAGEIFS('PvA Data'!$G$2:$G$1577,'PvA Data'!$B$2:$B$1577,">="&$C$4,'PvA Data'!$B$2:$B$1577,"<="&$C$5,'PvA Data'!$C$2:$C$1577,"Martin",'PvA Data'!$E$2:$E$1577,$B12),0)) -> 126.92 | H12: =IFERROR(SUMIFS('PvA Data'!$F$2:$F$1577,'PvA Data'!$B$2:$B$1577,">="&$C$4,'PvA Data'!$B$2:$B$1577,"<="&$C$5,'PvA Data'!$C$2:$C$1577,"Martin",'PvA Data'!$E$2:$E$1577,$B12)/SUMIFS('PvA Data'!$F$2:$F$1577,'PvA Data'!$B$2:$B$1577,">="&$C$4,'PvA Data'!$B$2:$B$1577,"<="&$C$5,'PvA Data'!$E$2:$E$1577,$B12),"") -> 0.80032468 | I12: =IF($C$6="Total",SUMIFS('PvA Data'!$F$2:$F$1577,'PvA Data'!$B$2:$B$1577,">="&$C$4,'PvA Data'!$B$2:$B$1577,"<="&$C$5,'PvA Data'!$C$2:$C$1577,"Custom",'PvA Data'!$E$2:$E$1577,$B12),IFERROR(AVERAGEIFS('PvA Data'!$F$2:$F$1577,'PvA Data'!$B$2:$B$1577,">="&$C$4,'PvA Data'!$B$2:$B$1577,"<="&$C$5,'PvA Data'!$C$2:$C$1577,"Custom",'PvA Data'!$E$2:$E$1577,$B12),0)) -> 34.44 | J12: =IF($C$6="Total",SUMIFS('PvA Data'!$G$2:$G$1577,'PvA Data'!$B$2:$B$1577,">="&$C$4,'PvA Data'!$B$2:$B$1577,"<="&$C$5,'PvA Data'!$C$2:$C$1577,"Custom",'PvA Data'!$E$2:$E$1577,$B12),IFERROR(AVERAGEIFS('PvA Data'!$G$2:$G$1577,'PvA Data'!$B$2:$B$1577,">="&$C$4,'PvA Data'!$B$2:$B$1577,"<="&$C$5,'PvA Data'!$C$2:$C$1577,"Custom",'PvA Data'!$E$2:$E$1577,$B12),0)) -> 31.16 | K12: =IFERROR(SUMIFS('PvA Data'!$F$2:$F$1577,'PvA Data'!$B$2:$B$1577,">="&$C$4,'PvA Data'!$B$2:$B$1577,"<="&$C$5,'PvA Data'!$C$2:$C$1577,"Custom",'PvA Data'!$E$2:$E$1577,$B12)/SUMIFS('PvA Data'!$F$2:$F$1577,'PvA Data'!$B$2:$B$1577,">="&$C$4,'PvA Data'!$B$2:$B$1577,"<="&$C$5,'PvA Data'!$E$2:$E$1577,$B12),"") -> 0.19967532 | L12: =C12+F12+I12 -> 172.48 | M12: =D12+G12+J12 -> 158.08 | N12: =IFERROR(M12/L12,"") -> 0.91651206 | P12: 46090 | Q12: 03_09_26
A13: 666505 | B13: Liver | C13: =IF($C$6="Total",SUMIFS('PvA Data'!$F$2:$F$1577,'PvA Data'!$B$2:$B$1577,">="&$C$4,'PvA Data'!$B$2:$B$1577,"<="&$C$5,'PvA Data'!$C$2:$C$1577,"Nahunta",'PvA Data'!$E$2:$E$1577,$B13),IFERROR(AVERAGEIFS('PvA Data'!$F$2:$F$1577,'PvA Data'!$B$2:$B$1577,">="&$C$4,'PvA Data'!$B$2:$B$1577,"<="&$C$5,'PvA Data'!$C$2:$C$1577,"Nahunta",'PvA Data'!$E$2:$E$1577,$B13),0)) -> 9.06 | D13: =IF($C$6="Total",SUMIFS('PvA Data'!$G$2:$G$1577,'PvA Data'!$B$2:$B$1577,">="&$C$4,'PvA Data'!$B$2:$B$1577,"<="&$C$5,'PvA Data'!$C$2:$C$1577,"Nahunta",'PvA Data'!$E$2:$E$1577,$B13),IFERROR(AVERAGEIFS('PvA Data'!$G$2:$G$1577,'PvA Data'!$B$2:$B$1577,">="&$C$4,'PvA Data'!$B$2:$B$1577,"<="&$C$5,'PvA Data'!$C$2:$C$1577,"Nahunta",'PvA Data'!$E$2:$E$1577,$B13),0)) -> 9.32 | E13: =IFERROR(SUMIFS('PvA Data'!$F$2:$F$1577,'PvA Data'!$B$2:$B$1577,">="&$C$4,'PvA Data'!$B$2:$B$1577,"<="&$C$5,'PvA Data'!$C$2:$C$1577,"Nahunta",'PvA Data'!$E$2:$E$1577,$B13)/SUMIFS('PvA Data'!$F$2:$F$1577,'PvA Data'!$B$2:$B$1577,">="&$C$4,'PvA Data'!$B$2:$B$1577,"<="&$C$5,'PvA Data'!$E$2:$E$1577,$B13),"") -> 0.31901408 | F13: =IF($C$6="Total",SUMIFS('PvA Data'!$F$2:$F$1577,'PvA Data'!$B$2:$B$1577,">="&$C$4,'PvA Data'!$B$2:$B$1577,"<="&$C$5,'PvA Data'!$C$2:$C$1577,"Martin",'PvA Data'!$E$2:$E$1577,$B13),IFERROR(AVERAGEIFS('PvA Data'!$F$2:$F$1577,'PvA Data'!$B$2:$B$1577,">="&$C$4,'PvA Data'!$B$2:$B$1577,"<="&$C$5,'PvA Data'!$C$2:$C$1577,"Martin",'PvA Data'!$E$2:$E$1577,$B13),0)) -> 0 | G13: =IF($C$6="Total",SUMIFS('PvA Data'!$G$2:$G$1577,'PvA Data'!$B$2:$B$1577,">="&$C$4,'PvA Data'!$B$2:$B$1577,"<="&$C$5,'PvA Data'!$C$2:$C$1577,"Martin",'PvA Data'!$E$2:$E$1577,$B13),IFERROR(AVERAGEIFS('PvA Data'!$G$2:$G$1577,'PvA Data'!$B$2:$B$1577,">="&$C$4,'PvA Data'!$B$2:$B$1577,"<="&$C$5,'PvA Data'!$C$2:$C$1577,"Martin",'PvA Data'!$E$2:$E$1577,$B13),0)) -> 0 | H13: =IFERROR(SUMIFS('PvA Data'!$F$2:$F$1577,'PvA Data'!$B$2:$B$1577,">="&$C$4,'PvA Data'!$B$2:$B$1577,"<="&$C$5,'PvA Data'!$C$2:$C$1577,"Martin",'PvA Data'!$E$2:$E$1577,$B13)/SUMIFS('PvA Data'!$F$2:$F$1577,'PvA Data'!$B$2:$B$1577,">="&$C$4,'PvA Data'!$B$2:$B$1577,"<="&$C$5,'PvA Data'!$E$2:$E$1577,$B13),"") -> 0 | I13: =IF($C$6="Total",SUMIFS('PvA Data'!$F$2:$F$1577,'PvA Data'!$B$2:$B$1577,">="&$C$4,'PvA Data'!$B$2:$B$1577,"<="&$C$5,'PvA Data'!$C$2:$C$1577,"Custom",'PvA Data'!$E$2:$E$1577,$B13),IFERROR(AVERAGEIFS('PvA Data'!$F$2:$F$1577,'PvA Data'!$B$2:$B$1577,">="&$C$4,'PvA Data'!$B$2:$B$1577,"<="&$C$5,'PvA Data'!$C$2:$C$1577,"Custom",'PvA Data'!$E$2:$E$1577,$B13),0)) -> 19.34 | J13: =IF($C$6="Total",SUMIFS('PvA Data'!$G$2:$G$1577,'PvA Data'!$B$2:$B$1577,">="&$C$4,'PvA Data'!$B$2:$B$1577,"<="&$C$5,'PvA Data'!$C$2:$C$1577,"Custom",'PvA Data'!$E$2:$E$1577,$B13),IFERROR(AVERAGEIFS('PvA Data'!$G$2:$G$1577,'PvA Data'!$B$2:$B$1577,">="&$C$4,'PvA Data'!$B$2:$B$1577,"<="&$C$5,'PvA Data'!$C$2:$C$1577,"Custom",'PvA Data'!$E$2:$E$1577,$B13),0)) -> 18.2 | K13: =IFERROR(SUMIFS('PvA Data'!$F$2:$F$1577,'PvA Data'!$B$2:$B$1577,">="&$C$4,'PvA Data'!$B$2:$B$1577,"<="&$C$5,'PvA Data'!$C$2:$C$1577,"Custom",'PvA Data'!$E$2:$E$1577,$B13)/SUMIFS('PvA Data'!$F$2:$F$1577,'PvA Data'!$B$2:$B$1577,">="&$C$4,'PvA Data'!$B$2:$B$1577,"<="&$C$5,'PvA Data'!$E$2:$E$1577,$B13),"") -> 0.68098592 | L13: =C13+F13+I13 -> 28.4 | M13: =D13+G13+J13 -> 27.52 | N13: =IFERROR(M13/L13,"") -> 0.96901408 | P13: 46097 | Q13: 03_16_26
A14: 666506 | B14: Pelvic Block Non-Intact | C14: =IF($C$6="Total",SUMIFS('PvA Data'!$F$2:$F$1577,'PvA Data'!$B$2:$B$1577,">="&$C$4,'PvA Data'!$B$2:$B$1577,"<="&$C$5,'PvA Data'!$C$2:$C$1577,"Nahunta",'PvA Data'!$E$2:$E$1577,$B14),IFERROR(AVERAGEIFS('PvA Data'!$F$2:$F$1577,'PvA Data'!$B$2:$B$1577,">="&$C$4,'PvA Data'!$B$2:$B$1577,"<="&$C$5,'PvA Data'!$C$2:$C$1577,"Nahunta",'PvA Data'!$E$2:$E$1577,$B14),0)) -> 0 | D14: =IF($C$6="Total",SUMIFS('PvA Data'!$G$2:$G$1577,'PvA Data'!$B$2:$B$1577,">="&$C$4,'PvA Data'!$B$2:$B$1577,"<="&$C$5,'PvA Data'!$C$2:$C$1577,"Nahunta",'PvA Data'!$E$2:$E$1577,$B14),IFERROR(AVERAGEIFS('PvA Data'!$G$2:$G$1577,'PvA Data'!$B$2:$B$1577,">="&$C$4,'PvA Data'!$B$2:$B$1577,"<="&$C$5,'PvA Data'!$C$2:$C$1577,"Nahunta",'PvA Data'!$E$2:$E$1577,$B14),0)) -> 0 | E14: =IFERROR(SUMIFS('PvA Data'!$F$2:$F$1577,'PvA Data'!$B$2:$B$1577,">="&$C$4,'PvA Data'!$B$2:$B$1577,"<="&$C$5,'PvA Data'!$C$2:$C$1577,"Nahunta",'PvA Data'!$E$2:$E$1577,$B14)/SUMIFS('PvA Data'!$F$2:$F$1577,'PvA Data'!$B$2:$B$1577,">="&$C$4,'PvA Data'!$B$2:$B$1577,"<="&$C$5,'PvA Data'!$E$2:$E$1577,$B14),"") -> 0 | F14: =IF($C$6="Total",SUMIFS('PvA Data'!$F$2:$F$1577,'PvA Data'!$B$2:$B$1577,">="&$C$4,'PvA Data'!$B$2:$B$1577,"<="&$C$5,'PvA Data'!$C$2:$C$1577,"Martin",'PvA Data'!$E$2:$E$1577,$B14),IFERROR(AVERAGEIFS('PvA Data'!$F$2:$F$1577,'PvA Data'!$B$2:$B$1577,">="&$C$4,'PvA Data'!$B$2:$B$1577,"<="&$C$5,'PvA Data'!$C$2:$C$1577,"Martin",'PvA Data'!$E$2:$E$1577,$B14),0)) -> 122.92 | G14: =IF($C$6="Total",SUMIFS('PvA Data'!$G$2:$G$1577,'PvA Data'!$B$2:$B$1577,">="&$C$4,'PvA Data'!$B$2:$B$1577,"<="&$C$5,'PvA Data'!$C$2:$C$1577,"Martin",'PvA Data'!$E$2:$E$1577,$B14),IFERROR(AVERAGEIFS('PvA Data'!$G$2:$G$1577,'PvA Data'!$B$2:$B$1577,">="&$C$4,'PvA Data'!$B$2:$B$1577,"<="&$C$5,'PvA Data'!$C$2:$C$1577,"Martin",'PvA Data'!$E$2:$E$1577,$B14),0)) -> 74.6 | H14: =IFERROR(SUMIFS('PvA Data'!$F$2:$F$1577,'PvA Data'!$B$2:$B$1577,">="&$C$4,'PvA Data'!$B$2:$B$1577,"<="&$C$5,'PvA Data'!$C$2:$C$1577,"Martin",'PvA Data'!$E$2:$E$1577,$B14)/SUMIFS('PvA Data'!$F$2:$F$1577,'PvA Data'!$B$2:$B$1577,">="&$C$4,'PvA Data'!$B$2:$B$1577,"<="&$C$5,'PvA Data'!$E$2:$E$1577,$B14),"") -> 1 | I14: =IF($C$6="Total",SUMIFS('PvA Data'!$F$2:$F$1577,'PvA Data'!$B$2:$B$1577,">="&$C$4,'PvA Data'!$B$2:$B$1577,"<="&$C$5,'PvA Data'!$C$2:$C$1577,"Custom",'PvA Data'!$E$2:$E$1577,$B14),IFERROR(AVERAGEIFS('PvA Data'!$F$2:$F$1577,'PvA Data'!$B$2:$B$1577,">="&$C$4,'PvA Data'!$B$2:$B$1577,"<="&$C$5,'PvA Data'!$C$2:$C$1577,"Custom",'PvA Data'!$E$2:$E$1577,$B14),0)) -> 0 | J14: =IF($C$6="Total",SUMIFS('PvA Data'!$G$2:$G$1577,'PvA Data'!$B$2:$B$1577,">="&$C$4,'PvA Data'!$B$2:$B$1577,"<="&$C$5,'PvA Data'!$C$2:$C$1577,"Custom",'PvA Data'!$E$2:$E$1577,$B14),IFERROR(AVERAGEIFS('PvA Data'!$G$2:$G$1577,'PvA Data'!$B$2:$B$1577,">="&$C$4,'PvA Data'!$B$2:$B$1577,"<="&$C$5,'PvA Data'!$C$2:$C$1577,"Custom",'PvA Data'!$E$2:$E$1577,$B14),0)) -> 0 | K14: =IFERROR(SUMIFS('PvA Data'!$F$2:$F$1577,'PvA Data'!$B$2:$B$1577,">="&$C$4,'PvA Data'!$B$2:$B$1577,"<="&$C$5,'PvA Data'!$C$2:$C$1577,"Custom",'PvA Data'!$E$2:$E$1577,$B14)/SUMIFS('PvA Data'!$F$2:$F$1577,'PvA Data'!$B$2:$B$1577,">="&$C$4,'PvA Data'!$B$2:$B$1577,"<="&$C$5,'PvA Data'!$E$2:$E$1577,$B14),"") -> 0 | L14: =C14+F14+I14 -> 122.92 | M14: =D14+G14+J14 -> 74.6 | N14: =IFERROR(M14/L14,"") -> 0.6068988 | P14: 46104 | Q14: 03_23_26
A15: 666507 | B15: Full Body | C15: =IF($C$6="Total",SUMIFS('PvA Data'!$F$2:$F$1577,'PvA Data'!$B$2:$B$1577,">="&$C$4,'PvA Data'!$B$2:$B$1577,"<="&$C$5,'PvA Data'!$C$2:$C$1577,"Nahunta",'PvA Data'!$E$2:$E$1577,$B15),IFERROR(AVERAGEIFS('PvA Data'!$F$2:$F$1577,'PvA Data'!$B$2:$B$1577,">="&$C$4,'PvA Data'!$B$2:$B$1577,"<="&$C$5,'PvA Data'!$C$2:$C$1577,"Nahunta",'PvA Data'!$E$2:$E$1577,$B15),0)) -> 16.16 | D15: =IF($C$6="Total",SUMIFS('PvA Data'!$G$2:$G$1577,'PvA Data'!$B$2:$B$1577,">="&$C$4,'PvA Data'!$B$2:$B$1577,"<="&$C$5,'PvA Data'!$C$2:$C$1577,"Nahunta",'PvA Data'!$E$2:$E$1577,$B15),IFERROR(AVERAGEIFS('PvA Data'!$G$2:$G$1577,'PvA Data'!$B$2:$B$1577,">="&$C$4,'PvA Data'!$B$2:$B$1577,"<="&$C$5,'PvA Data'!$C$2:$C$1577,"Nahunta",'PvA Data'!$E$2:$E$1577,$B15),0)) -> 15.68 | E15: =IFERROR(SUMIFS('PvA Data'!$F$2:$F$1577,'PvA Data'!$B$2:$B$1577,">="&$C$4,'PvA Data'!$B$2:$B$1577,"<="&$C$5,'PvA Data'!$C$2:$C$1577,"Nahunta",'PvA Data'!$E$2:$E$1577,$B15)/SUMIFS('PvA Data'!$F$2:$F$1577,'PvA Data'!$B$2:$B$1577,">="&$C$4,'PvA Data'!$B$2:$B$1577,"<="&$C$5,'PvA Data'!$E$2:$E$1577,$B15),"") -> 1 | F15: =IF($C$6="Total",SUMIFS('PvA Data'!$F$2:$F$1577,'PvA Data'!$B$2:$B$1577,">="&$C$4,'PvA Data'!$B$2:$B$1577,"<="&$C$5,'PvA Data'!$C$2:$C$1577,"Martin",'PvA Data'!$E$2:$E$1577,$B15),IFERROR(AVERAGEIFS('PvA Data'!$F$2:$F$1577,'PvA Data'!$B$2:$B$1577,">="&$C$4,'PvA Data'!$B$2:$B$1577,"<="&$C$5,'PvA Data'!$C$2:$C$1577,"Martin",'PvA Data'!$E$2:$E$1577,$B15),0)) -> 0 | G15: =IF($C$6="Total",SUMIFS('PvA Data'!$G$2:$G$1577,'PvA Data'!$B$2:$B$1577,">="&$C$4,'PvA Data'!$B$2:$B$1577,"<="&$C$5,'PvA Data'!$C$2:$C$1577,"Martin",'PvA Data'!$E$2:$E$1577,$B15),IFERROR(AVERAGEIFS('PvA Data'!$G$2:$G$1577,'PvA Data'!$B$2:$B$1577,">="&$C$4,'PvA Data'!$B$2:$B$1577,"<="&$C$5,'PvA Data'!$C$2:$C$1577,"Martin",'PvA Data'!$E$2:$E$1577,$B15),0)) -> 0 | H15: =IFERROR(SUMIFS('PvA Data'!$F$2:$F$1577,'PvA Data'!$B$2:$B$1577,">="&$C$4,'PvA Data'!$B$2:$B$1577,"<="&$C$5,'PvA Data'!$C$2:$C$1577,"Martin",'PvA Data'!$E$2:$E$1577,$B15)/SUMIFS('PvA Data'!$F$2:$F$1577,'PvA Data'!$B$2:$B$1577,">="&$C$4,'PvA Data'!$B$2:$B$1577,"<="&$C$5,'PvA Data'!$E$2:$E$1577,$B15),"") -> 0 | I15: =IF($C$6="Total",SUMIFS('PvA Data'!$F$2:$F$1577,'PvA Data'!$B$2:$B$1577,">="&$C$4,'PvA Data'!$B$2:$B$1577,"<="&$C$5,'PvA Data'!$C$2:$C$1577,"Custom",'PvA Data'!$E$2:$E$1577,$B15),IFERROR(AVERAGEIFS('PvA Data'!$F$2:$F$1577,'PvA Data'!$B$2:$B$1577,">="&$C$4,'PvA Data'!$B$2:$B$1577,"<="&$C$5,'PvA Data'!$C$2:$C$1577,"Custom",'PvA Data'!$E$2:$E$1577,$B15),0)) -> 0 | J15: =IF($C$6="Total",SUMIFS('PvA Data'!$G$2:$G$1577,'PvA Data'!$B$2:$B$1577,">="&$C$4,'PvA Data'!$B$2:$B$1577,"<="&$C$5,'PvA Data'!$C$2:$C$1577,"Custom",'PvA Data'!$E$2:$E$1577,$B15),IFERROR(AVERAGEIFS('PvA Data'!$G$2:$G$1577,'PvA Data'!$B$2:$B$1577,">="&$C$4,'PvA Data'!$B$2:$B$1577,"<="&$C$5,'PvA Data'!$C$2:$C$1577,"Custom",'PvA Data'!$E$2:$E$1577,$B15),0)) -> 0 | K15: =IFERROR(SUMIFS('PvA Data'!$F$2:$F$1577,'PvA Data'!$B$2:$B$1577,">="&$C$4,'PvA Data'!$B$2:$B$1577,"<="&$C$5,'PvA Data'!$C$2:$C$1577,"Custom",'PvA Data'!$E$2:$E$1577,$B15)/SUMIFS('PvA Data'!$F$2:$F$1577,'PvA Data'!$B$2:$B$1577,">="&$C$4,'PvA Data'!$B$2:$B$1577,"<="&$C$5,'PvA Data'!$E$2:$E$1577,$B15),"") -> 0 | L15: =C15+F15+I15 -> 16.16 | M15: =D15+G15+J15 -> 15.68 | N15: =IFERROR(M15/L15,"") -> 0.97029703 | P15: 46111 | Q15: 03_30_26
A16: 666509 | B16: Jejunum 6' | C16: =IF($C$6="Total",SUMIFS('PvA Data'!$F$2:$F$1577,'PvA Data'!$B$2:$B$1577,">="&$C$4,'PvA Data'!$B$2:$B$1577,"<="&$C$5,'PvA Data'!$C$2:$C$1577,"Nahunta",'PvA Data'!$E$2:$E$1577,$B16),IFERROR(AVERAGEIFS('PvA Data'!$F$2:$F$1577,'PvA Data'!$B$2:$B$1577,">="&$C$4,'PvA Data'!$B$2:$B$1577,"<="&$C$5,'PvA Data'!$C$2:$C$1577,"Nahunta",'PvA Data'!$E$2:$E$1577,$B16),0)) -> 39 | D16: =IF($C$6="Total",SUMIFS('PvA Data'!$G$2:$G$1577,'PvA Data'!$B$2:$B$1577,">="&$C$4,'PvA Data'!$B$2:$B$1577,"<="&$C$5,'PvA Data'!$C$2:$C$1577,"Nahunta",'PvA Data'!$E$2:$E$1577,$B16),IFERROR(AVERAGEIFS('PvA Data'!$G$2:$G$1577,'PvA Data'!$B$2:$B$1577,">="&$C$4,'PvA Data'!$B$2:$B$1577,"<="&$C$5,'PvA Data'!$C$2:$C$1577,"Nahunta",'PvA Data'!$E$2:$E$1577,$B16),0)) -> 36.04 | E16: =IFERROR(SUMIFS('PvA Data'!$F$2:$F$1577,'PvA Data'!$B$2:$B$1577,">="&$C$4,'PvA Data'!$B$2:$B$1577,"<="&$C$5,'PvA Data'!$C$2:$C$1577,"Nahunta",'PvA Data'!$E$2:$E$1577,$B16)/SUMIFS('PvA Data'!$F$2:$F$1577,'PvA Data'!$B$2:$B$1577,">="&$C$4,'PvA Data'!$B$2:$B$1577,"<="&$C$5,'PvA Data'!$E$2:$E$1577,$B16),"") -> 1 | F16: =IF($C$6="Total",SUMIFS('PvA Data'!$F$2:$F$1577,'PvA Data'!$B$2:$B$1577,">="&$C$4,'PvA Data'!$B$2:$B$1577,"<="&$C$5,'PvA Data'!$C$2:$C$1577,"Martin",'PvA Data'!$E$2:$E$1577,$B16),IFERROR(AVERAGEIFS('PvA Data'!$F$2:$F$1577,'PvA Data'!$B$2:$B$1577,">="&$C$4,'PvA Data'!$B$2:$B$1577,"<="&$C$5,'PvA Data'!$C$2:$C$1577,"Martin",'PvA Data'!$E$2:$E$1577,$B16),0)) -> 0 | G16: =IF($C$6="Total",SUMIFS('PvA Data'!$G$2:$G$1577,'PvA Data'!$B$2:$B$1577,">="&$C$4,'PvA Data'!$B$2:$B$1577,"<="&$C$5,'PvA Data'!$C$2:$C$1577,"Martin",'PvA Data'!$E$2:$E$1577,$B16),IFERROR(AVERAGEIFS('PvA Data'!$G$2:$G$1577,'PvA Data'!$B$2:$B$1577,">="&$C$4,'PvA Data'!$B$2:$B$1577,"<="&$C$5,'PvA Data'!$C$2:$C$1577,"Martin",'PvA Data'!$E$2:$E$1577,$B16),0)) -> 0 | H16: =IFERROR(SUMIFS('PvA Data'!$F$2:$F$1577,'PvA Data'!$B$2:$B$1577,">="&$C$4,'PvA Data'!$B$2:$B$1577,"<="&$C$5,'PvA Data'!$C$2:$C$1577,"Martin",'PvA Data'!$E$2:$E$1577,$B16)/SUMIFS('PvA Data'!$F$2:$F$1577,'PvA Data'!$B$2:$B$1577,">="&$C$4,'PvA Data'!$B$2:$B$1577,"<="&$C$5,'PvA Data'!$E$2:$E$1577,$B16),"") -> 0 | I16: =IF($C$6="Total",SUMIFS('PvA Data'!$F$2:$F$1577,'PvA Data'!$B$2:$B$1577,">="&$C$4,'PvA Data'!$B$2:$B$1577,"<="&$C$5,'PvA Data'!$C$2:$C$1577,"Custom",'PvA Data'!$E$2:$E$1577,$B16),IFERROR(AVERAGEIFS('PvA Data'!$F$2:$F$1577,'PvA Data'!$B$2:$B$1577,">="&$C$4,'PvA Data'!$B$2:$B$1577,"<="&$C$5,'PvA Data'!$C$2:$C$1577,"Custom",'PvA Data'!$E$2:$E$1577,$B16),0)) -> 0 | J16: =IF($C$6="Total",SUMIFS('PvA Data'!$G$2:$G$1577,'PvA Data'!$B$2:$B$1577,">="&$C$4,'PvA Data'!$B$2:$B$1577,"<="&$C$5,'PvA Data'!$C$2:$C$1577,"Custom",'PvA Data'!$E$2:$E$1577,$B16),IFERROR(AVERAGEIFS('PvA Data'!$G$2:$G$1577,'PvA Data'!$B$2:$B$1577,">="&$C$4,'PvA Data'!$B$2:$B$1577,"<="&$C$5,'PvA Data'!$C$2:$C$1577,"Custom",'PvA Data'!$E$2:$E$1577,$B16),0)) -> 0 | K16: =IFERROR(SUMIFS('PvA Data'!$F$2:$F$1577,'PvA Data'!$B$2:$B$1577,">="&$C$4,'PvA Data'!$B$2:$B$1577,"<="&$C$5,'PvA Data'!$C$2:$C$1577,"Custom",'PvA Data'!$E$2:$E$1577,$B16)/SUMIFS('PvA Data'!$F$2:$F$1577,'PvA Data'!$B$2:$B$1577,">="&$C$4,'PvA Data'!$B$2:$B$1577,"<="&$C$5,'PvA Data'!$E$2:$E$1577,$B16),"") -> 0 | L16: =C16+F16+I16 -> 39 | M16: =D16+G16+J16 -> 36.04 | N16: =IFERROR(M16/L16,"") -> 0.92410256 | P16: 46118 | Q16: 04_06_26
A17: 666510 | B17: Jejunum 2' | C17: =IF($C$6="Total",SUMIFS('PvA Data'!$F$2:$F$1577,'PvA Data'!$B$2:$B$1577,">="&$C$4,'PvA Data'!$B$2:$B$1577,"<="&$C$5,'PvA Data'!$C$2:$C$1577,"Nahunta",'PvA Data'!$E$2:$E$1577,$B17),IFERROR(AVERAGEIFS('PvA Data'!$F$2:$F$1577,'PvA Data'!$B$2:$B$1577,">="&$C$4,'PvA Data'!$B$2:$B$1577,"<="&$C$5,'PvA Data'!$C$2:$C$1577,"Nahunta",'PvA Data'!$E$2:$E$1577,$B17),0)) -> 0 | D17: =IF($C$6="Total",SUMIFS('PvA Data'!$G$2:$G$1577,'PvA Data'!$B$2:$B$1577,">="&$C$4,'PvA Data'!$B$2:$B$1577,"<="&$C$5,'PvA Data'!$C$2:$C$1577,"Nahunta",'PvA Data'!$E$2:$E$1577,$B17),IFERROR(AVERAGEIFS('PvA Data'!$G$2:$G$1577,'PvA Data'!$B$2:$B$1577,">="&$C$4,'PvA Data'!$B$2:$B$1577,"<="&$C$5,'PvA Data'!$C$2:$C$1577,"Nahunta",'PvA Data'!$E$2:$E$1577,$B17),0)) -> 0 | E17: =IFERROR(SUMIFS('PvA Data'!$F$2:$F$1577,'PvA Data'!$B$2:$B$1577,">="&$C$4,'PvA Data'!$B$2:$B$1577,"<="&$C$5,'PvA Data'!$C$2:$C$1577,"Nahunta",'PvA Data'!$E$2:$E$1577,$B17)/SUMIFS('PvA Data'!$F$2:$F$1577,'PvA Data'!$B$2:$B$1577,">="&$C$4,'PvA Data'!$B$2:$B$1577,"<="&$C$5,'PvA Data'!$E$2:$E$1577,$B17),"") | F17: =IF($C$6="Total",SUMIFS('PvA Data'!$F$2:$F$1577,'PvA Data'!$B$2:$B$1577,">="&$C$4,'PvA Data'!$B$2:$B$1577,"<="&$C$5,'PvA Data'!$C$2:$C$1577,"Martin",'PvA Data'!$E$2:$E$1577,$B17),IFERROR(AVERAGEIFS('PvA Data'!$F$2:$F$1577,'PvA Data'!$B$2:$B$1577,">="&$C$4,'PvA Data'!$B$2:$B$1577,"<="&$C$5,'PvA Data'!$C$2:$C$1577,"Martin",'PvA Data'!$E$2:$E$1577,$B17),0)) -> 0 | G17: =IF($C$6="Total",SUMIFS('PvA Data'!$G$2:$G$1577,'PvA Data'!$B$2:$B$1577,">="&$C$4,'PvA Data'!$B$2:$B$1577,"<="&$C$5,'PvA Data'!$C$2:$C$1577,"Martin",'PvA Data'!$E$2:$E$1577,$B17),IFERROR(AVERAGEIFS('PvA Data'!$G$2:$G$1577,'PvA Data'!$B$2:$B$1577,">="&$C$4,'PvA Data'!$B$2:$B$1577,"<="&$C$5,'PvA Data'!$C$2:$C$1577,"Martin",'PvA Data'!$E$2:$E$1577,$B17),0)) -> 0 | H17: =IFERROR(SUMIFS('PvA Data'!$F$2:$F$1577,'PvA Data'!$B$2:$B$1577,">="&$C$4,'PvA Data'!$B$2:$B$1577,"<="&$C$5,'PvA Data'!$C$2:$C$1577,"Martin",'PvA Data'!$E$2:$E$1577,$B17)/SUMIFS('PvA Data'!$F$2:$F$1577,'PvA Data'!$B$2:$B$1577,">="&$C$4,'PvA Data'!$B$2:$B$1577,"<="&$C$5,'PvA Data'!$E$2:$E$1577,$B17),"") | I17: =IF($C$6="Total",SUMIFS('PvA Data'!$F$2:$F$1577,'PvA Data'!$B$2:$B$1577,">="&$C$4,'PvA Data'!$B$2:$B$1577,"<="&$C$5,'PvA Data'!$C$2:$C$1577,"Custom",'PvA Data'!$E$2:$E$1577,$B17),IFERROR(AVERAGEIFS('PvA Data'!$F$2:$F$1577,'PvA Data'!$B$2:$B$1577,">="&$C$4,'PvA Data'!$B$2:$B$1577,"<="&$C$5,'PvA Data'!$C$2:$C$1577,"Custom",'PvA Data'!$E$2:$E$1577,$B17),0)) -> 0 | J17: =IF($C$6="Total",SUMIFS('PvA Data'!$G$2:$G$1577,'PvA Data'!$B$2:$B$1577,">="&$C$4,'PvA Data'!$B$2:$B$1577,"<="&$C$5,'PvA Data'!$C$2:$C$1577,"Custom",'PvA Data'!$E$2:$E$1577,$B17),IFERROR(AVERAGEIFS('PvA Data'!$G$2:$G$1577,'PvA Data'!$B$2:$B$1577,">="&$C$4,'PvA Data'!$B$2:$B$1577,"<="&$C$5,'PvA Data'!$C$2:$C$1577,"Custom",'PvA Data'!$E$2:$E$1577,$B17),0)) -> 0 | K17: =IFERROR(SUMIFS('PvA Data'!$F$2:$F$1577,'PvA Data'!$B$2:$B$1577,">="&$C$4,'PvA Data'!$B$2:$B$1577,"<="&$C$5,'PvA Data'!$C$2:$C$1577,"Custom",'PvA Data'!$E$2:$E$1577,$B17)/SUMIFS('PvA Data'!$F$2:$F$1577,'PvA Data'!$B$2:$B$1577,">="&$C$4,'PvA Data'!$B$2:$B$1577,"<="&$C$5,'PvA Data'!$E$2:$E$1577,$B17),"") | L17: =C17+F17+I17 -> 0 | M17: =D17+G17+J17 -> 0 | N17: =IFERROR(M17/L17,"") | P17: 46125 | Q17: 04_13_26
A18: 666511 | B18: Kidney | C18: =IF($C$6="Total",SUMIFS('PvA Data'!$F$2:$F$1577,'PvA Data'!$B$2:$B$1577,">="&$C$4,'PvA Data'!$B$2:$B$1577,"<="&$C$5,'PvA Data'!$C$2:$C$1577,"Nahunta",'PvA Data'!$E$2:$E$1577,$B18),IFERROR(AVERAGEIFS('PvA Data'!$F$2:$F$1577,'PvA Data'!$B$2:$B$1577,">="&$C$4,'PvA Data'!$B$2:$B$1577,"<="&$C$5,'PvA Data'!$C$2:$C$1577,"Nahunta",'PvA Data'!$E$2:$E$1577,$B18),0)) -> 3.28 | D18: =IF($C$6="Total",SUMIFS('PvA Data'!$G$2:$G$1577,'PvA Data'!$B$2:$B$1577,">="&$C$4,'PvA Data'!$B$2:$B$1577,"<="&$C$5,'PvA Data'!$C$2:$C$1577,"Nahunta",'PvA Data'!$E$2:$E$1577,$B18),IFERROR(AVERAGEIFS('PvA Data'!$G$2:$G$1577,'PvA Data'!$B$2:$B$1577,">="&$C$4,'PvA Data'!$B$2:$B$1577,"<="&$C$5,'PvA Data'!$C$2:$C$1577,"Nahunta",'PvA Data'!$E$2:$E$1577,$B18),0)) -> 3.2 | E18: =IFERROR(SUMIFS('PvA Data'!$F$2:$F$1577,'PvA Data'!$B$2:$B$1577,">="&$C$4,'PvA Data'!$B$2:$B$1577,"<="&$C$5,'PvA Data'!$C$2:$C$1577,"Nahunta",'PvA Data'!$E$2:$E$1577,$B18)/SUMIFS('PvA Data'!$F$2:$F$1577,'PvA Data'!$B$2:$B$1577,">="&$C$4,'PvA Data'!$B$2:$B$1577,"<="&$C$5,'PvA Data'!$E$2:$E$1577,$B18),"") -> 1 | F18: =IF($C$6="Total",SUMIFS('PvA Data'!$F$2:$F$1577,'PvA Data'!$B$2:$B$1577,">="&$C$4,'PvA Data'!$B$2:$B$1577,"<="&$C$5,'PvA Data'!$C$2:$C$1577,"Martin",'PvA Data'!$E$2:$E$1577,$B18),IFERROR(AVERAGEIFS('PvA Data'!$F$2:$F$1577,'PvA Data'!$B$2:$B$1577,">="&$C$4,'PvA Data'!$B$2:$B$1577,"<="&$C$5,'PvA Data'!$C$2:$C$1577,"Martin",'PvA Data'!$E$2:$E$1577,$B18),0)) -> 0 | G18: =IF($C$6="Total",SUMIFS('PvA Data'!$G$2:$G$1577,'PvA Data'!$B$2:$B$1577,">="&$C$4,'PvA Data'!$B$2:$B$1577,"<="&$C$5,'PvA Data'!$C$2:$C$1577,"Martin",'PvA Data'!$E$2:$E$1577,$B18),IFERROR(AVERAGEIFS('PvA Data'!$G$2:$G$1577,'PvA Data'!$B$2:$B$1577,">="&$C$4,'PvA Data'!$B$2:$B$1577,"<="&$C$5,'PvA Data'!$C$2:$C$1577,"Martin",'PvA Data'!$E$2:$E$1577,$B18),0)) -> 0 | H18: =IFERROR(SUMIFS('PvA Data'!$F$2:$F$1577,'PvA Data'!$B$2:$B$1577,">="&$C$4,'PvA Data'!$B$2:$B$1577,"<="&$C$5,'PvA Data'!$C$2:$C$1577,"Martin",'PvA Data'!$E$2:$E$1577,$B18)/SUMIFS('PvA Data'!$F$2:$F$1577,'PvA Data'!$B$2:$B$1577,">="&$C$4,'PvA Data'!$B$2:$B$1577,"<="&$C$5,'PvA Data'!$E$2:$E$1577,$B18),"") -> 0 | I18: =IF($C$6="Total",SUMIFS('PvA Data'!$F$2:$F$1577,'PvA Data'!$B$2:$B$1577,">="&$C$4,'PvA Data'!$B$2:$B$1577,"<="&$C$5,'PvA Data'!$C$2:$C$1577,"Custom",'PvA Data'!$E$2:$E$1577,$B18),IFERROR(AVERAGEIFS('PvA Data'!$F$2:$F$1577,'PvA Data'!$B$2:$B$1577,">="&$C$4,'PvA Data'!$B$2:$B$1577,"<="&$C$5,'PvA Data'!$C$2:$C$1577,"Custom",'PvA Data'!$E$2:$E$1577,$B18),0)) -> 0 | J18: =IF($C$6="Total",SUMIFS('PvA Data'!$G$2:$G$1577,'PvA Data'!$B$2:$B$1577,">="&$C$4,'PvA Data'!$B$2:$B$1577,"<="&$C$5,'PvA Data'!$C$2:$C$1577,"Custom",'PvA Data'!$E$2:$E$1577,$B18),IFERROR(AVERAGEIFS('PvA Data'!$G$2:$G$1577,'PvA Data'!$B$2:$B$1577,">="&$C$4,'PvA Data'!$B$2:$B$1577,"<="&$C$5,'PvA Data'!$C$2:$C$1577,"Custom",'PvA Data'!$E$2:$E$1577,$B18),0)) -> 0 | K18: =IFERROR(SUMIFS('PvA Data'!$F$2:$F$1577,'PvA Data'!$B$2:$B$1577,">="&$C$4,'PvA Data'!$B$2:$B$1577,"<="&$C$5,'PvA Data'!$C$2:$C$1577,"Custom",'PvA Data'!$E$2:$E$1577,$B18)/SUMIFS('PvA Data'!$F$2:$F$1577,'PvA Data'!$B$2:$B$1577,">="&$C$4,'PvA Data'!$B$2:$B$1577,"<="&$C$5,'PvA Data'!$E$2:$E$1577,$B18),"") -> 0 | L18: =C18+F18+I18 -> 3.28 | M18: =D18+G18+J18 -> 3.2 | N18: =IFERROR(M18/L18,"") -> 0.97560976 | P18: 46132 | Q18: 04_20_26
A19: 666513 | B19: Liver w/GB | C19: =IF($C$6="Total",SUMIFS('PvA Data'!$F$2:$F$1577,'PvA Data'!$B$2:$B$1577,">="&$C$4,'PvA Data'!$B$2:$B$1577,"<="&$C$5,'PvA Data'!$C$2:$C$1577,"Nahunta",'PvA Data'!$E$2:$E$1577,$B19),IFERROR(AVERAGEIFS('PvA Data'!$F$2:$F$1577,'PvA Data'!$B$2:$B$1577,">="&$C$4,'PvA Data'!$B$2:$B$1577,"<="&$C$5,'PvA Data'!$C$2:$C$1577,"Nahunta",'PvA Data'!$E$2:$E$1577,$B19),0)) -> 2.76 | D19: =IF($C$6="Total",SUMIFS('PvA Data'!$G$2:$G$1577,'PvA Data'!$B$2:$B$1577,">="&$C$4,'PvA Data'!$B$2:$B$1577,"<="&$C$5,'PvA Data'!$C$2:$C$1577,"Nahunta",'PvA Data'!$E$2:$E$1577,$B19),IFERROR(AVERAGEIFS('PvA Data'!$G$2:$G$1577,'PvA Data'!$B$2:$B$1577,">="&$C$4,'PvA Data'!$B$2:$B$1577,"<="&$C$5,'PvA Data'!$C$2:$C$1577,"Nahunta",'PvA Data'!$E$2:$E$1577,$B19),0)) -> 3.04 | E19: =IFERROR(SUMIFS('PvA Data'!$F$2:$F$1577,'PvA Data'!$B$2:$B$1577,">="&$C$4,'PvA Data'!$B$2:$B$1577,"<="&$C$5,'PvA Data'!$C$2:$C$1577,"Nahunta",'PvA Data'!$E$2:$E$1577,$B19)/SUMIFS('PvA Data'!$F$2:$F$1577,'PvA Data'!$B$2:$B$1577,">="&$C$4,'PvA Data'!$B$2:$B$1577,"<="&$C$5,'PvA Data'!$E$2:$E$1577,$B19),"") -> 0.29487179 | F19: =IF($C$6="Total",SUMIFS('PvA Data'!$F$2:$F$1577,'PvA Data'!$B$2:$B$1577,">="&$C$4,'PvA Data'!$B$2:$B$1577,"<="&$C$5,'PvA Data'!$C$2:$C$1577,"Martin",'PvA Data'!$E$2:$E$1577,$B19),IFERROR(AVERAGEIFS('PvA Data'!$F$2:$F$1577,'PvA Data'!$B$2:$B$1577,">="&$C$4,'PvA Data'!$B$2:$B$1577,"<="&$C$5,'PvA Data'!$C$2:$C$1577,"Martin",'PvA Data'!$E$2:$E$1577,$B19),0)) -> 0 | G19: =IF($C$6="Total",SUMIFS('PvA Data'!$G$2:$G$1577,'PvA Data'!$B$2:$B$1577,">="&$C$4,'PvA Data'!$B$2:$B$1577,"<="&$C$5,'PvA Data'!$C$2:$C$1577,"Martin",'PvA Data'!$E$2:$E$1577,$B19),IFERROR(AVERAGEIFS('PvA Data'!$G$2:$G$1577,'PvA Data'!$B$2:$B$1577,">="&$C$4,'PvA Data'!$B$2:$B$1577,"<="&$C$5,'PvA Data'!$C$2:$C$1577,"Martin",'PvA Data'!$E$2:$E$1577,$B19),0)) -> 0 | H19: =IFERROR(SUMIFS('PvA Data'!$F$2:$F$1577,'PvA Data'!$B$2:$B$1577,">="&$C$4,'PvA Data'!$B$2:$B$1577,"<="&$C$5,'PvA Data'!$C$2:$C$1577,"Martin",'PvA Data'!$E$2:$E$1577,$B19)/SUMIFS('PvA Data'!$F$2:$F$1577,'PvA Data'!$B$2:$B$1577,">="&$C$4,'PvA Data'!$B$2:$B$1577,"<="&$C$5,'PvA Data'!$E$2:$E$1577,$B19),"") -> 0 | I19: =IF($C$6="Total",SUMIFS('PvA Data'!$F$2:$F$1577,'PvA Data'!$B$2:$B$1577,">="&$C$4,'PvA Data'!$B$2:$B$1577,"<="&$C$5,'PvA Data'!$C$2:$C$1577,"Custom",'PvA Data'!$E$2:$E$1577,$B19),IFERROR(AVERAGEIFS('PvA Data'!$F$2:$F$1577,'PvA Data'!$B$2:$B$1577,">="&$C$4,'PvA Data'!$B$2:$B$1577,"<="&$C$5,'PvA Data'!$C$2:$C$1577,"Custom",'PvA Data'!$E$2:$E$1577,$B19),0)) -> 6.6 | J19: =IF($C$6="Total",SUMIFS('PvA Data'!$G$2:$G$1577,'PvA Data'!$B$2:$B$1577,">="&$C$4,'PvA Data'!$B$2:$B$1577,"<="&$C$5,'PvA Data'!$C$2:$C$1577,"Custom",'PvA Data'!$E$2:$E$1577,$B19),IFERROR(AVERAGEIFS('PvA Data'!$G$2:$G$1577,'PvA Data'!$B$2:$B$1577,">="&$C$4,'PvA Data'!$B$2:$B$1577,"<="&$C$5,'PvA Data'!$C$2:$C$1577,"Custom",'PvA Data'!$E$2:$E$1577,$B19),0)) -> 5.44 | K19: =IFERROR(SUMIFS('PvA Data'!$F$2:$F$1577,'PvA Data'!$B$2:$B$1577,">="&$C$4,'PvA Data'!$B$2:$B$1577,"<="&$C$5,'PvA Data'!$C$2:$C$1577,"Custom",'PvA Data'!$E$2:$E$1577,$B19)/SUMIFS('PvA Data'!$F$2:$F$1577,'PvA Data'!$B$2:$B$1577,">="&$C$4,'PvA Data'!$B$2:$B$1577,"<="&$C$5,'PvA Data'!$E$2:$E$1577,$B19),"") -> 0.70512821 | L19: =C19+F19+I19 -> 9.36 | M19: =D19+G19+J19 -> 8.48 | N19: =IFERROR(M19/L19,"") -> 0.90598291 | P19: 46139 | Q19: 04_27_26
A20: 666516 | B20: Omentum | C20: =IF($C$6="Total",SUMIFS('PvA Data'!$F$2:$F$1577,'PvA Data'!$B$2:$B$1577,">="&$C$4,'PvA Data'!$B$2:$B$1577,"<="&$C$5,'PvA Data'!$C$2:$C$1577,"Nahunta",'PvA Data'!$E$2:$E$1577,$B20),IFERROR(AVERAGEIFS('PvA Data'!$F$2:$F$1577,'PvA Data'!$B$2:$B$1577,">="&$C$4,'PvA Data'!$B$2:$B$1577,"<="&$C$5,'PvA Data'!$C$2:$C$1577,"Nahunta",'PvA Data'!$E$2:$E$1577,$B20),0)) -> 12.28 | D20: =IF($C$6="Total",SUMIFS('PvA Data'!$G$2:$G$1577,'PvA Data'!$B$2:$B$1577,">="&$C$4,'PvA Data'!$B$2:$B$1577,"<="&$C$5,'PvA Data'!$C$2:$C$1577,"Nahunta",'PvA Data'!$E$2:$E$1577,$B20),IFERROR(AVERAGEIFS('PvA Data'!$G$2:$G$1577,'PvA Data'!$B$2:$B$1577,">="&$C$4,'PvA Data'!$B$2:$B$1577,"<="&$C$5,'PvA Data'!$C$2:$C$1577,"Nahunta",'PvA Data'!$E$2:$E$1577,$B20),0)) -> 12.6 | E20: =IFERROR(SUMIFS('PvA Data'!$F$2:$F$1577,'PvA Data'!$B$2:$B$1577,">="&$C$4,'PvA Data'!$B$2:$B$1577,"<="&$C$5,'PvA Data'!$C$2:$C$1577,"Nahunta",'PvA Data'!$E$2:$E$1577,$B20)/SUMIFS('PvA Data'!$F$2:$F$1577,'PvA Data'!$B$2:$B$1577,">="&$C$4,'PvA Data'!$B$2:$B$1577,"<="&$C$5,'PvA Data'!$E$2:$E$1577,$B20),"") -> 0.48422713 | F20: =IF($C$6="Total",SUMIFS('PvA Data'!$F$2:$F$1577,'PvA Data'!$B$2:$B$1577,">="&$C$4,'PvA Data'!$B$2:$B$1577,"<="&$C$5,'PvA Data'!$C$2:$C$1577,"Martin",'PvA Data'!$E$2:$E$1577,$B20),IFERROR(AVERAGEIFS('PvA Data'!$F$2:$F$1577,'PvA Data'!$B$2:$B$1577,">="&$C$4,'PvA Data'!$B$2:$B$1577,"<="&$C$5,'PvA Data'!$C$2:$C$1577,"Martin",'PvA Data'!$E$2:$E$1577,$B20),0)) -> 0 | G20: =IF($C$6="Total",SUMIFS('PvA Data'!$G$2:$G$1577,'PvA Data'!$B$2:$B$1577,">="&$C$4,'PvA Data'!$B$2:$B$1577,"<="&$C$5,'PvA Data'!$C$2:$C$1577,"Martin",'PvA Data'!$E$2:$E$1577,$B20),IFERROR(AVERAGEIFS('PvA Data'!$G$2:$G$1577,'PvA Data'!$B$2:$B$1577,">="&$C$4,'PvA Data'!$B$2:$B$1577,"<="&$C$5,'PvA Data'!$C$2:$C$1577,"Martin",'PvA Data'!$E$2:$E$1577,$B20),0)) -> 0 | H20: =IFERROR(SUMIFS('PvA Data'!$F$2:$F$1577,'PvA Data'!$B$2:$B$1577,">="&$C$4,'PvA Data'!$B$2:$B$1577,"<="&$C$5,'PvA Data'!$C$2:$C$1577,"Martin",'PvA Data'!$E$2:$E$1577,$B20)/SUMIFS('PvA Data'!$F$2:$F$1577,'PvA Data'!$B$2:$B$1577,">="&$C$4,'PvA Data'!$B$2:$B$1577,"<="&$C$5,'PvA Data'!$E$2:$E$1577,$B20),"") -> 0 | I20: =IF($C$6="Total",SUMIFS('PvA Data'!$F$2:$F$1577,'PvA Data'!$B$2:$B$1577,">="&$C$4,'PvA Data'!$B$2:$B$1577,"<="&$C$5,'PvA Data'!$C$2:$C$1577,"Custom",'PvA Data'!$E$2:$E$1577,$B20),IFERROR(AVERAGEIFS('PvA Data'!$F$2:$F$1577,'PvA Data'!$B$2:$B$1577,">="&$C$4,'PvA Data'!$B$2:$B$1577,"<="&$C$5,'PvA Data'!$C$2:$C$1577,"Custom",'PvA Data'!$E$2:$E$1577,$B20),0)) -> 13.08 | J20: =IF($C$6="Total",SUMIFS('PvA Data'!$G$2:$G$1577,'PvA Data'!$B$2:$B$1577,">="&$C$4,'PvA Data'!$B$2:$B$1577,"<="&$C$5,'PvA Data'!$C$2:$C$1577,"Custom",'PvA Data'!$E$2:$E$1577,$B20),IFERROR(AVERAGEIFS('PvA Data'!$G$2:$G$1577,'PvA Data'!$B$2:$B$1577,">="&$C$4,'PvA Data'!$B$2:$B$1577,"<="&$C$5,'PvA Data'!$C$2:$C$1577,"Custom",'PvA Data'!$E$2:$E$1577,$B20),0)) -> 11.48 | K20: =IFERROR(SUMIFS('PvA Data'!$F$2:$F$1577,'PvA Data'!$B$2:$B$1577,">="&$C$4,'PvA Data'!$B$2:$B$1577,"<="&$C$5,'PvA Data'!$C$2:$C$1577,"Custom",'PvA Data'!$E$2:$E$1577,$B20)/SUMIFS('PvA Data'!$F$2:$F$1577,'PvA Data'!$B$2:$B$1577,">="&$C$4,'PvA Data'!$B$2:$B$1577,"<="&$C$5,'PvA Data'!$E$2:$E$1577,$B20),"") -> 0.51577287 | L20: =C20+F20+I20 -> 25.36 | M20: =D20+G20+J20 -> 24.08 | N20: =IFERROR(M20/L20,"") -> 0.94952681 | P20: 46146 | Q20: 05_04_26
A21: 666517 | B21: Pancreas | C21: =IF($C$6="Total",SUMIFS('PvA Data'!$F$2:$F$1577,'PvA Data'!$B$2:$B$1577,">="&$C$4,'PvA Data'!$B$2:$B$1577,"<="&$C$5,'PvA Data'!$C$2:$C$1577,"Nahunta",'PvA Data'!$E$2:$E$1577,$B21),IFERROR(AVERAGEIFS('PvA Data'!$F$2:$F$1577,'PvA Data'!$B$2:$B$1577,">="&$C$4,'PvA Data'!$B$2:$B$1577,"<="&$C$5,'PvA Data'!$C$2:$C$1577,"Nahunta",'PvA Data'!$E$2:$E$1577,$B21),0)) -> 17.92 | D21: =IF($C$6="Total",SUMIFS('PvA Data'!$G$2:$G$1577,'PvA Data'!$B$2:$B$1577,">="&$C$4,'PvA Data'!$B$2:$B$1577,"<="&$C$5,'PvA Data'!$C$2:$C$1577,"Nahunta",'PvA Data'!$E$2:$E$1577,$B21),IFERROR(AVERAGEIFS('PvA Data'!$G$2:$G$1577,'PvA Data'!$B$2:$B$1577,">="&$C$4,'PvA Data'!$B$2:$B$1577,"<="&$C$5,'PvA Data'!$C$2:$C$1577,"Nahunta",'PvA Data'!$E$2:$E$1577,$B21),0)) -> 18.32 | E21: =IFERROR(SUMIFS('PvA Data'!$F$2:$F$1577,'PvA Data'!$B$2:$B$1577,">="&$C$4,'PvA Data'!$B$2:$B$1577,"<="&$C$5,'PvA Data'!$C$2:$C$1577,"Nahunta",'PvA Data'!$E$2:$E$1577,$B21)/SUMIFS('PvA Data'!$F$2:$F$1577,'PvA Data'!$B$2:$B$1577,">="&$C$4,'PvA Data'!$B$2:$B$1577,"<="&$C$5,'PvA Data'!$E$2:$E$1577,$B21),"") -> 0.69135802 | F21: =IF($C$6="Total",SUMIFS('PvA Data'!$F$2:$F$1577,'PvA Data'!$B$2:$B$1577,">="&$C$4,'PvA Data'!$B$2:$B$1577,"<="&$C$5,'PvA Data'!$C$2:$C$1577,"Martin",'PvA Data'!$E$2:$E$1577,$B21),IFERROR(AVERAGEIFS('PvA Data'!$F$2:$F$1577,'PvA Data'!$B$2:$B$1577,">="&$C$4,'PvA Data'!$B$2:$B$1577,"<="&$C$5,'PvA Data'!$C$2:$C$1577,"Martin",'PvA Data'!$E$2:$E$1577,$B21),0)) -> 0 | G21: =IF($C$6="Total",SUMIFS('PvA Data'!$G$2:$G$1577,'PvA Data'!$B$2:$B$1577,">="&$C$4,'PvA Data'!$B$2:$B$1577,"<="&$C$5,'PvA Data'!$C$2:$C$1577,"Martin",'PvA Data'!$E$2:$E$1577,$B21),IFERROR(AVERAGEIFS('PvA Data'!$G$2:$G$1577,'PvA Data'!$B$2:$B$1577,">="&$C$4,'PvA Data'!$B$2:$B$1577,"<="&$C$5,'PvA Data'!$C$2:$C$1577,"Martin",'PvA Data'!$E$2:$E$1577,$B21),0)) -> 0 | H21: =IFERROR(SUMIFS('PvA Data'!$F$2:$F$1577,'PvA Data'!$B$2:$B$1577,">="&$C$4,'PvA Data'!$B$2:$B$1577,"<="&$C$5,'PvA Data'!$C$2:$C$1577,"Martin",'PvA Data'!$E$2:$E$1577,$B21)/SUMIFS('PvA Data'!$F$2:$F$1577,'PvA Data'!$B$2:$B$1577,">="&$C$4,'PvA Data'!$B$2:$B$1577,"<="&$C$5,'PvA Data'!$E$2:$E$1577,$B21),"") -> 0 | I21: =IF($C$6="Total",SUMIFS('PvA Data'!$F$2:$F$1577,'PvA Data'!$B$2:$B$1577,">="&$C$4,'PvA Data'!$B$2:$B$1577,"<="&$C$5,'PvA Data'!$C$2:$C$1577,"Custom",'PvA Data'!$E$2:$E$1577,$B21),IFERROR(AVERAGEIFS('PvA Data'!$F$2:$F$1577,'PvA Data'!$B$2:$B$1577,">="&$C$4,'PvA Data'!$B$2:$B$1577,"<="&$C$5,'PvA Data'!$C$2:$C$1577,"Custom",'PvA Data'!$E$2:$E$1577,$B21),0)) -> 8 | J21: =IF($C$6="Total",SUMIFS('PvA Data'!$G$2:$G$1577,'PvA Data'!$B$2:$B$1577,">="&$C$4,'PvA Data'!$B$2:$B$1577,"<="&$C$5,'PvA Data'!$C$2:$C$1577,"Custom",'PvA Data'!$E$2:$E$1577,$B21),IFERROR(AVERAGEIFS('PvA Data'!$G$2:$G$1577,'PvA Data'!$B$2:$B$1577,">="&$C$4,'PvA Data'!$B$2:$B$1577,"<="&$C$5,'PvA Data'!$C$2:$C$1577,"Custom",'PvA Data'!$E$2:$E$1577,$B21),0)) -> 7.04 | K21: =IFERROR(SUMIFS('PvA Data'!$F$2:$F$1577,'PvA Data'!$B$2:$B$1577,">="&$C$4,'PvA Data'!$B$2:$B$1577,"<="&$C$5,'PvA Data'!$C$2:$C$1577,"Custom",'PvA Data'!$E$2:$E$1577,$B21)/SUMIFS('PvA Data'!$F$2:$F$1577,'PvA Data'!$B$2:$B$1577,">="&$C$4,'PvA Data'!$B$2:$B$1577,"<="&$C$5,'PvA Data'!$E$2:$E$1577,$B21),"") -> 0.30864198 | L21: =C21+F21+I21 -> 25.92 | M21: =D21+G21+J21 -> 25.36 | N21: =IFERROR(M21/L21,"") -> 0.97839506 | P21: 46153 | Q21: 05_11_26
A22: 666518 | B22: Pelvic Block SM Intact | C22: =IF($C$6="Total",SUMIFS('PvA Data'!$F$2:$F$1577,'PvA Data'!$B$2:$B$1577,">="&$C$4,'PvA Data'!$B$2:$B$1577,"<="&$C$5,'PvA Data'!$C$2:$C$1577,"Nahunta",'PvA Data'!$E$2:$E$1577,$B22),IFERROR(AVERAGEIFS('PvA Data'!$F$2:$F$1577,'PvA Data'!$B$2:$B$1577,">="&$C$4,'PvA Data'!$B$2:$B$1577,"<="&$C$5,'PvA Data'!$C$2:$C$1577,"Nahunta",'PvA Data'!$E$2:$E$1577,$B22),0)) -> 0 | D22: =IF($C$6="Total",SUMIFS('PvA Data'!$G$2:$G$1577,'PvA Data'!$B$2:$B$1577,">="&$C$4,'PvA Data'!$B$2:$B$1577,"<="&$C$5,'PvA Data'!$C$2:$C$1577,"Nahunta",'PvA Data'!$E$2:$E$1577,$B22),IFERROR(AVERAGEIFS('PvA Data'!$G$2:$G$1577,'PvA Data'!$B$2:$B$1577,">="&$C$4,'PvA Data'!$B$2:$B$1577,"<="&$C$5,'PvA Data'!$C$2:$C$1577,"Nahunta",'PvA Data'!$E$2:$E$1577,$B22),0)) -> 0 | E22: =IFERROR(SUMIFS('PvA Data'!$F$2:$F$1577,'PvA Data'!$B$2:$B$1577,">="&$C$4,'PvA Data'!$B$2:$B$1577,"<="&$C$5,'PvA Data'!$C$2:$C$1577,"Nahunta",'PvA Data'!$E$2:$E$1577,$B22)/SUMIFS('PvA Data'!$F$2:$F$1577,'PvA Data'!$B$2:$B$1577,">="&$C$4,'PvA Data'!$B$2:$B$1577,"<="&$C$5,'PvA Data'!$E$2:$E$1577,$B22),"") | F22: =IF($C$6="Total",SUMIFS('PvA Data'!$F$2:$F$1577,'PvA Data'!$B$2:$B$1577,">="&$C$4,'PvA Data'!$B$2:$B$1577,"<="&$C$5,'PvA Data'!$C$2:$C$1577,"Martin",'PvA Data'!$E$2:$E$1577,$B22),IFERROR(AVERAGEIFS('PvA Data'!$F$2:$F$1577,'PvA Data'!$B$2:$B$1577,">="&$C$4,'PvA Data'!$B$2:$B$1577,"<="&$C$5,'PvA Data'!$C$2:$C$1577,"Martin",'PvA Data'!$E$2:$E$1577,$B22),0)) -> 0 | G22: =IF($C$6="Total",SUMIFS('PvA Data'!$G$2:$G$1577,'PvA Data'!$B$2:$B$1577,">="&$C$4,'PvA Data'!$B$2:$B$1577,"<="&$C$5,'PvA Data'!$C$2:$C$1577,"Martin",'PvA Data'!$E$2:$E$1577,$B22),IFERROR(AVERAGEIFS('PvA Data'!$G$2:$G$1577,'PvA Data'!$B$2:$B$1577,">="&$C$4,'PvA Data'!$B$2:$B$1577,"<="&$C$5,'PvA Data'!$C$2:$C$1577,"Martin",'PvA Data'!$E$2:$E$1577,$B22),0)) -> 0 | H22: =IFERROR(SUMIFS('PvA Data'!$F$2:$F$1577,'PvA Data'!$B$2:$B$1577,">="&$C$4,'PvA Data'!$B$2:$B$1577,"<="&$C$5,'PvA Data'!$C$2:$C$1577,"Martin",'PvA Data'!$E$2:$E$1577,$B22)/SUMIFS('PvA Data'!$F$2:$F$1577,'PvA Data'!$B$2:$B$1577,">="&$C$4,'PvA Data'!$B$2:$B$1577,"<="&$C$5,'PvA Data'!$E$2:$E$1577,$B22),"") | I22: =IF($C$6="Total",SUMIFS('PvA Data'!$F$2:$F$1577,'PvA Data'!$B$2:$B$1577,">="&$C$4,'PvA Data'!$B$2:$B$1577,"<="&$C$5,'PvA Data'!$C$2:$C$1577,"Custom",'PvA Data'!$E$2:$E$1577,$B22),IFERROR(AVERAGEIFS('PvA Data'!$F$2:$F$1577,'PvA Data'!$B$2:$B$1577,">="&$C$4,'PvA Data'!$B$2:$B$1577,"<="&$C$5,'PvA Data'!$C$2:$C$1577,"Custom",'PvA Data'!$E$2:$E$1577,$B22),0)) -> 0 | J22: =IF($C$6="Total",SUMIFS('PvA Data'!$G$2:$G$1577,'PvA Data'!$B$2:$B$1577,">="&$C$4,'PvA Data'!$B$2:$B$1577,"<="&$C$5,'PvA Data'!$C$2:$C$1577,"Custom",'PvA Data'!$E$2:$E$1577,$B22),IFERROR(AVERAGEIFS('PvA Data'!$G$2:$G$1577,'PvA Data'!$B$2:$B$1577,">="&$C$4,'PvA Data'!$B$2:$B$1577,"<="&$C$5,'PvA Data'!$C$2:$C$1577,"Custom",'PvA Data'!$E$2:$E$1577,$B22),0)) -> 0 | K22: =IFERROR(SUMIFS('PvA Data'!$F$2:$F$1577,'PvA Data'!$B$2:$B$1577,">="&$C$4,'PvA Data'!$B$2:$B$1577,"<="&$C$5,'PvA Data'!$C$2:$C$1577,"Custom",'PvA Data'!$E$2:$E$1577,$B22)/SUMIFS('PvA Data'!$F$2:$F$1577,'PvA Data'!$B$2:$B$1577,">="&$C$4,'PvA Data'!$B$2:$B$1577,"<="&$C$5,'PvA Data'!$E$2:$E$1577,$B22),"") | L22: =C22+F22+I22 -> 0 | M22: =D22+G22+J22 -> 0 | N22: =IFERROR(M22/L22,"") | P22: 46160 | Q22: 05_18_26
... A26: 666523 | B26: Vena Cava | C26: =IF($C$6="Total",SUMIFS('PvA Data'!$F$2:$F$1577,'PvA Data'!$B$2:$B$1577,">="&$C$4,'PvA Data'!$B$2:$B$1577,"<="&$C$5,'PvA Data'!$C$2:$C$1577,"Nahunta",'PvA Data'!$E$2:$E$1577,$B26),IFERROR(AVERAGEIFS('PvA Data'!$F$2:$F$1577,'PvA Data'!$B$2:$B$1577,">="&$C$4,'PvA Data'!$B$2:$B$1577,"<="&$C$5,'PvA Data'!$C$2:$C$1577,"Nahunta",'PvA Data'!$E$2:$E$1577,$B26),0)) -> 0 | D26: =IF($C$6="Total",SUMIFS('PvA Data'!$G$2:$G$1577,'PvA Data'!$B$2:$B$1577,">="&$C$4,'PvA Data'!$B$2:$B$1577,"<="&$C$5,'PvA Data'!$C$2:$C$1577,"Nahunta",'PvA Data'!$E$2:$E$1577,$B26),IFERROR(AVERAGEIFS('PvA Data'!$G$2:$G$1577,'PvA Data'!$B$2:$B$1577,">="&$C$4,'PvA Data'!$B$2:$B$1577,"<="&$C$5,'PvA Data'!$C$2:$C$1577,"Nahunta",'PvA Data'!$E$2:$E$1577,$B26),0)) -> 0 | E26: =IFERROR(SUMIFS('PvA Data'!$F$2:$F$1577,'PvA Data'!$B$2:$B$1577,">="&$C$4,'PvA Data'!$B$2:$B$1577,"<="&$C$5,'PvA Data'!$C$2:$C$1577,"Nahunta",'PvA Data'!$E$2:$E$1577,$B26)/SUMIFS('PvA Data'!$F$2:$F$1577,'PvA Data'!$B$2:$B$1577,">="&$C$4,'PvA Data'!$B$2:$B$1577,"<="&$C$5,'PvA Data'!$E$2:$E$1577,$B26),"") -> 0 | F26: =IF($C$6="Total",SUMIFS('PvA Data'!$F$2:$F$1577,'PvA Data'!$B$2:$B$1577,">="&$C$4,'PvA Data'!$B$2:$B$1577,"<="&$C$5,'PvA Data'!$C$2:$C$1577,"Martin",'PvA Data'!$E$2:$E$1577,$B26),IFERROR(AVERAGEIFS('PvA Data'!$F$2:$F$1577,'PvA Data'!$B$2:$B$1577,">="&$C$4,'PvA Data'!$B$2:$B$1577,"<="&$C$5,'PvA Data'!$C$2:$C$1577,"Martin",'PvA Data'!$E$2:$E$1577,$B26),0)) -> 14.96 | G26: =IF($C$6="Total",SUMIFS('PvA Data'!$G$2:$G$1577,'PvA Data'!$B$2:$B$1577,">="&$C$4,'PvA Data'!$B$2:$B$1577,"<="&$C$5,'PvA Data'!$C$2:$C$1577,"Martin",'PvA Data'!$E$2:$E$1577,$B26),IFERROR(AVERAGEIFS('PvA Data'!$G$2:$G$1577,'PvA Data'!$B$2:$B$1577,">="&$C$4,'PvA Data'!$B$2:$B$1577,"<="&$C$5,'PvA Data'!$C$2:$C$1577,"Martin",'PvA Data'!$E$2:$E$1577,$B26),0)) -> 14.96 | H26: =IFERROR(SUMIFS('PvA Data'!$F$2:$F$1577,'PvA Data'!$B$2:$B$1577,">="&$C$4,'PvA Data'!$B$2:$B$1577,"<="&$C$5,'PvA Data'!$C$2:$C$1577,"Martin",'PvA Data'!$E$2:$E$1577,$B26)/SUMIFS('PvA Data'!$F$2:$F$1577,'PvA Data'!$B$2:$B$1577,">="&$C$4,'PvA Data'!$B$2:$B$1577,"<="&$C$5,'PvA Data'!$E$2:$E$1577,$B26),"") -> 0.56495468 | I26: =IF($C$6="Total",SUMIFS('PvA Data'!$F$2:$F$1577,'PvA Data'!$B$2:$B$1577,">="&$C$4,'PvA Data'!$B$2:$B$1577,"<="&$C$5,'PvA Data'!$C$2:$C$1577,"Custom",'PvA Data'!$E$2:$E$1577,$B26),IFERROR(AVERAGEIFS('PvA Data'!$F$2:$F$1577,'PvA Data'!$B$2:$B$1577,">="&$C$4,'PvA Data'!$B$2:$B$1577,"<="&$C$5,'PvA Data'!$C$2:$C$1577,"Custom",'PvA Data'!$E$2:$E$1577,$B26),0)) -> 11.52 | J26: =IF($C$6="Total",SUMIFS('PvA Data'!$G$2:$G$1577,'PvA Data'!$B$2:$B$1577,">="&$C$4,'PvA Data'!$B$2:$B$1577,"<="&$C$5,'PvA Data'!$C$2:$C$1577,"Custom",'PvA Data'!$E$2:$E$1577,$B26),IFERROR(AVERAGEIFS('PvA Data'!$G$2:$G$1577,'PvA Data'!$B$2:$B$1577,">="&$C$4,'PvA Data'!$B$2:$B$1577,"<="&$C$5,'PvA Data'!$C$2:$C$1577,"Custom",'PvA Data'!$E$2:$E$1577,$B26),0)) -> 10.6 | K26: =IFERROR(SUMIFS('PvA Data'!$F$2:$F$1577,'PvA Data'!$B$2:$B$1577,">="&$C$4,'PvA Data'!$B$2:$B$1577,"<="&$C$5,'PvA Data'!$C$2:$C$1577,"Custom",'PvA Data'!$E$2:$E$1577,$B26)/SUMIFS('PvA Data'!$F$2:$F$1577,'PvA Data'!$B$2:$B$1577,">="&$C$4,'PvA Data'!$B$2:$B$1577,"<="&$C$5,'PvA Data'!$E$2:$E$1577,$B26),"") -> 0.43504532 | L26: =C26+F26+I26 -> 26.48 | M26: =D26+G26+J26 -> 25.56 | N26: =IFERROR(M26/L26,"") -> 0.9652568 | P26: 46188 | Q26: 06_15_26
A27: 666530 | B27: Stomach | C27: =IF($C$6="Total",SUMIFS('PvA Data'!$F$2:$F$1577,'PvA Data'!$B$2:$B$1577,">="&$C$4,'PvA Data'!$B$2:$B$1577,"<="&$C$5,'PvA Data'!$C$2:$C$1577,"Nahunta",'PvA Data'!$E$2:$E$1577,$B27),IFERROR(AVERAGEIFS('PvA Data'!$F$2:$F$1577,'PvA Data'!$B$2:$B$1577,">="&$C$4,'PvA Data'!$B$2:$B$1577,"<="&$C$5,'PvA Data'!$C$2:$C$1577,"Nahunta",'PvA Data'!$E$2:$E$1577,$B27),0)) -> 1.36 | D27: =IF($C$6="Total",SUMIFS('PvA Data'!$G$2:$G$1577,'PvA Data'!$B$2:$B$1577,">="&$C$4,'PvA Data'!$B$2:$B$1577,"<="&$C$5,'PvA Data'!$C$2:$C$1577,"Nahunta",'PvA Data'!$E$2:$E$1577,$B27),IFERROR(AVERAGEIFS('PvA Data'!$G$2:$G$1577,'PvA Data'!$B$2:$B$1577,">="&$C$4,'PvA Data'!$B$2:$B$1577,"<="&$C$5,'PvA Data'!$C$2:$C$1577,"Nahunta",'PvA Data'!$E$2:$E$1577,$B27),0)) -> 1.36 | E27: =IFERROR(SUMIFS('PvA Data'!$F$2:$F$1577,'PvA Data'!$B$2:$B$1577,">="&$C$4,'PvA Data'!$B$2:$B$1577,"<="&$C$5,'PvA Data'!$C$2:$C$1577,"Nahunta",'PvA Data'!$E$2:$E$1577,$B27)/SUMIFS('PvA Data'!$F$2:$F$1577,'PvA Data'!$B$2:$B$1577,">="&$C$4,'PvA Data'!$B$2:$B$1577,"<="&$C$5,'PvA Data'!$E$2:$E$1577,$B27),"") -> 0.136 | F27: =IF($C$6="Total",SUMIFS('PvA Data'!$F$2:$F$1577,'PvA Data'!$B$2:$B$1577,">="&$C$4,'PvA Data'!$B$2:$B$1577,"<="&$C$5,'PvA Data'!$C$2:$C$1577,"Martin",'PvA Data'!$E$2:$E$1577,$B27),IFERROR(AVERAGEIFS('PvA Data'!$F$2:$F$1577,'PvA Data'!$B$2:$B$1577,">="&$C$4,'PvA Data'!$B$2:$B$1577,"<="&$C$5,'PvA Data'!$C$2:$C$1577,"Martin",'PvA Data'!$E$2:$E$1577,$B27),0)) -> 0 | G27: =IF($C$6="Total",SUMIFS('PvA Data'!$G$2:$G$1577,'PvA Data'!$B$2:$B$1577,">="&$C$4,'PvA Data'!$B$2:$B$1577,"<="&$C$5,'PvA Data'!$C$2:$C$1577,"Martin",'PvA Data'!$E$2:$E$1577,$B27),IFERROR(AVERAGEIFS('PvA Data'!$G$2:$G$1577,'PvA Data'!$B$2:$B$1577,">="&$C$4,'PvA Data'!$B$2:$B$1577,"<="&$C$5,'PvA Data'!$C$2:$C$1577,"Martin",'PvA Data'!$E$2:$E$1577,$B27),0)) -> 0 | H27: =IFERROR(SUMIFS('PvA Data'!$F$2:$F$1577,'PvA Data'!$B$2:$B$1577,">="&$C$4,'PvA Data'!$B$2:$B$1577,"<="&$C$5,'PvA Data'!$C$2:$C$1577,"Martin",'PvA Data'!$E$2:$E$1577,$B27)/SUMIFS('PvA Data'!$F$2:$F$1577,'PvA Data'!$B$2:$B$1577,">="&$C$4,'PvA Data'!$B$2:$B$1577,"<="&$C$5,'PvA Data'!$E$2:$E$1577,$B27),"") -> 0 | I27: =IF($C$6="Total",SUMIFS('PvA Data'!$F$2:$F$1577,'PvA Data'!$B$2:$B$1577,">="&$C$4,'PvA Data'!$B$2:$B$1577,"<="&$C$5,'PvA Data'!$C$2:$C$1577,"Custom",'PvA Data'!$E$2:$E$1577,$B27),IFERROR(AVERAGEIFS('PvA Data'!$F$2:$F$1577,'PvA Data'!$B$2:$B$1577,">="&$C$4,'PvA Data'!$B$2:$B$1577,"<="&$C$5,'PvA Data'!$C$2:$C$1577,"Custom",'PvA Data'!$E$2:$E$1577,$B27),0)) -> 8.64 | J27: =IF($C$6="Total",SUMIFS('PvA Data'!$G$2:$G$1577,'PvA Data'!$B$2:$B$1577,">="&$C$4,'PvA Data'!$B$2:$B$1577,"<="&$C$5,'PvA Data'!$C$2:$C$1577,"Custom",'PvA Data'!$E$2:$E$1577,$B27),IFERROR(AVERAGEIFS('PvA Data'!$G$2:$G$1577,'PvA Data'!$B$2:$B$1577,">="&$C$4,'PvA Data'!$B$2:$B$1577,"<="&$C$5,'PvA Data'!$C$2:$C$1577,"Custom",'PvA Data'!$E$2:$E$1577,$B27),0)) -> 7.56 | K27: =IFERROR(SUMIFS('PvA Data'!$F$2:$F$1577,'PvA Data'!$B$2:$B$1577,">="&$C$4,'PvA Data'!$B$2:$B$1577,"<="&$C$5,'PvA Data'!$C$2:$C$1577,"Custom",'PvA Data'!$E$2:$E$1577,$B27)/SUMIFS('PvA Data'!$F$2:$F$1577,'PvA Data'!$B$2:$B$1577,">="&$C$4,'PvA Data'!$B$2:$B$1577,"<="&$C$5,'PvA Data'!$E$2:$E$1577,$B27),"") -> 0.864 | L27: =C27+F27+I27 -> 10 | M27: =D27+G27+J27 -> 8.92 | N27: =IFERROR(M27/L27,"") -> 0.892
A28: 666531 | B28: Diaphragms | C28: =IF($C$6="Total",SUMIFS('PvA Data'!$F$2:$F$1577,'PvA Data'!$B$2:$B$1577,">="&$C$4,'PvA Data'!$B$2:$B$1577,"<="&$C$5,'PvA Data'!$C$2:$C$1577,"Nahunta",'PvA Data'!$E$2:$E$1577,$B28),IFERROR(AVERAGEIFS('PvA Data'!$F$2:$F$1577,'PvA Data'!$B$2:$B$1577,">="&$C$4,'PvA Data'!$B$2:$B$1577,"<="&$C$5,'PvA Data'!$C$2:$C$1577,"Nahunta",'PvA Data'!$E$2:$E$1577,$B28),0)) -> 9.28 | D28: =IF($C$6="Total",SUMIFS('PvA Data'!$G$2:$G$1577,'PvA Data'!$B$2:$B$1577,">="&$C$4,'PvA Data'!$B$2:$B$1577,"<="&$C$5,'PvA Data'!$C$2:$C$1577,"Nahunta",'PvA Data'!$E$2:$E$1577,$B28),IFERROR(AVERAGEIFS('PvA Data'!$G$2:$G$1577,'PvA Data'!$B$2:$B$1577,">="&$C$4,'PvA Data'!$B$2:$B$1577,"<="&$C$5,'PvA Data'!$C$2:$C$1577,"Nahunta",'PvA Data'!$E$2:$E$1577,$B28),0)) -> 9.32 | E28: =IFERROR(SUMIFS('PvA Data'!$F$2:$F$1577,'PvA Data'!$B$2:$B$1577,">="&$C$4,'PvA Data'!$B$2:$B$1577,"<="&$C$5,'PvA Data'!$C$2:$C$1577,"Nahunta",'PvA Data'!$E$2:$E$1577,$B28)/SUMIFS('PvA Data'!$F$2:$F$1577,'PvA Data'!$B$2:$B$1577,">="&$C$4,'PvA Data'!$B$2:$B$1577,"<="&$C$5,'PvA Data'!$E$2:$E$1577,$B28),"") -> 0.7030303 | F28: =IF($C$6="Total",SUMIFS('PvA Data'!$F$2:$F$1577,'PvA Data'!$B$2:$B$1577,">="&$C$4,'PvA Data'!$B$2:$B$1577,"<="&$C$5,'PvA Data'!$C$2:$C$1577,"Martin",'PvA Data'!$E$2:$E$1577,$B28),IFERROR(AVERAGEIFS('PvA Data'!$F$2:$F$1577,'PvA Data'!$B$2:$B$1577,">="&$C$4,'PvA Data'!$B$2:$B$1577,"<="&$C$5,'PvA Data'!$C$2:$C$1577,"Martin",'PvA Data'!$E$2:$E$1577,$B28),0)) -> 0 | G28: =IF($C$6="Total",SUMIFS('PvA Data'!$G$2:$G$1577,'PvA Data'!$B$2:$B$1577,">="&$C$4,'PvA Data'!$B$2:$B$1577,"<="&$C$5,'PvA Data'!$C$2:$C$1577,"Martin",'PvA Data'!$E$2:$E$1577,$B28),IFERROR(AVERAGEIFS('PvA Data'!$G$2:$G$1577,'PvA Data'!$B$2:$B$1577,">="&$C$4,'PvA Data'!$B$2:$B$1577,"<="&$C$5,'PvA Data'!$C$2:$C$1577,"Martin",'PvA Data'!$E$2:$E$1577,$B28),0)) -> 0 | H28: =IFERROR(SUMIFS('PvA Data'!$F$2:$F$1577,'PvA Data'!$B$2:$B$1577,">="&$C$4,'PvA Data'!$B$2:$B$1577,"<="&$C$5,'PvA Data'!$C$2:$C$1577,"Martin",'PvA Data'!$E$2:$E$1577,$B28)/SUMIFS('PvA Data'!$F$2:$F$1577,'PvA Data'!$B$2:$B$1577,">="&$C$4,'PvA Data'!$B$2:$B$1577,"<="&$C$5,'PvA Data'!$E$2:$E$1577,$B28),"") -> 0 | I28: =IF($C$6="Total",SUMIFS('PvA Data'!$F$2:$F$1577,'PvA Data'!$B$2:$B$1577,">="&$C$4,'PvA Data'!$B$2:$B$1577,"<="&$C$5,'PvA Data'!$C$2:$C$1577,"Custom",'PvA Data'!$E$2:$E$1577,$B28),IFERROR(AVERAGEIFS('PvA Data'!$F$2:$F$1577,'PvA Data'!$B$2:$B$1577,">="&$C$4,'PvA Data'!$B$2:$B$1577,"<="&$C$5,'PvA Data'!$C$2:$C$1577,"Custom",'PvA Data'!$E$2:$E$1577,$B28),0)) -> 3.92 | J28: =IF($C$6="Total",SUMIFS('PvA Data'!$G$2:$G$1577,'PvA Data'!$B$2:$B$1577,">="&$C$4,'PvA Data'!$B$2:$B$1577,"<="&$C$5,'PvA Data'!$C$2:$C$1577,"Custom",'PvA Data'!$E$2:$E$1577,$B28),IFERROR(AVERAGEIFS('PvA Data'!$G$2:$G$1577,'PvA Data'!$B$2:$B$1577,">="&$C$4,'PvA Data'!$B$2:$B$1577,"<="&$C$5,'PvA Data'!$C$2:$C$1577,"Custom",'PvA Data'!$E$2:$E$1577,$B28),0)) -> 3.44 | K28: =IFERROR(SUMIFS('PvA Data'!$F$2:$F$1577,'PvA Data'!$B$2:$B$1577,">="&$C$4,'PvA Data'!$B$2:$B$1577,"<="&$C$5,'PvA Data'!$C$2:$C$1577,"Custom",'PvA Data'!$E$2:$E$1577,$B28)/SUMIFS('PvA Data'!$F$2:$F$1577,'PvA Data'!$B$2:$B$1577,">="&$C$4,'PvA Data'!$B$2:$B$1577,"<="&$C$5,'PvA Data'!$E$2:$E$1577,$B28),"") -> 0.2969697 | L28: =C28+F28+I28 -> 13.2 | M28: =D28+G28+J28 -> 12.76 | N28: =IFERROR(M28/L28,"") -> 0.96666667
A29: 666540 | B29: Male Pelvic | C29: =IF($C$6="Total",SUMIFS('PvA Data'!$F$2:$F$1577,'PvA Data'!$B$2:$B$1577,">="&$C$4,'PvA Data'!$B$2:$B$1577,"<="&$C$5,'PvA Data'!$C$2:$C$1577,"Nahunta",'PvA Data'!$E$2:$E$1577,$B29),IFERROR(AVERAGEIFS('PvA Data'!$F$2:$F$1577,'PvA Data'!$B$2:$B$1577,">="&$C$4,'PvA Data'!$B$2:$B$1577,"<="&$C$5,'PvA Data'!$C$2:$C$1577,"Nahunta",'PvA Data'!$E$2:$E$1577,$B29),0)) -> 0 | D29: =IF($C$6="Total",SUMIFS('PvA Data'!$G$2:$G$1577,'PvA Data'!$B$2:$B$1577,">="&$C$4,'PvA Data'!$B$2:$B$1577,"<="&$C$5,'PvA Data'!$C$2:$C$1577,"Nahunta",'PvA Data'!$E$2:$E$1577,$B29),IFERROR(AVERAGEIFS('PvA Data'!$G$2:$G$1577,'PvA Data'!$B$2:$B$1577,">="&$C$4,'PvA Data'!$B$2:$B$1577,"<="&$C$5,'PvA Data'!$C$2:$C$1577,"Nahunta",'PvA Data'!$E$2:$E$1577,$B29),0)) -> 0 | E29: =IFERROR(SUMIFS('PvA Data'!$F$2:$F$1577,'PvA Data'!$B$2:$B$1577,">="&$C$4,'PvA Data'!$B$2:$B$1577,"<="&$C$5,'PvA Data'!$C$2:$C$1577,"Nahunta",'PvA Data'!$E$2:$E$1577,$B29)/SUMIFS('PvA Data'!$F$2:$F$1577,'PvA Data'!$B$2:$B$1577,">="&$C$4,'PvA Data'!$B$2:$B$1577,"<="&$C$5,'PvA Data'!$E$2:$E$1577,$B29),"") -> 0 | F29: =IF($C$6="Total",SUMIFS('PvA Data'!$F$2:$F$1577,'PvA Data'!$B$2:$B$1577,">="&$C$4,'PvA Data'!$B$2:$B$1577,"<="&$C$5,'PvA Data'!$C$2:$C$1577,"Martin",'PvA Data'!$E$2:$E$1577,$B29),IFERROR(AVERAGEIFS('PvA Data'!$F$2:$F$1577,'PvA Data'!$B$2:$B$1577,">="&$C$4,'PvA Data'!$B$2:$B$1577,"<="&$C$5,'PvA Data'!$C$2:$C$1577,"Martin",'PvA Data'!$E$2:$E$1577,$B29),0)) -> 56 | G29: =IF($C$6="Total",SUMIFS('PvA Data'!$G$2:$G$1577,'PvA Data'!$B$2:$B$1577,">="&$C$4,'PvA Data'!$B$2:$B$1577,"<="&$C$5,'PvA Data'!$C$2:$C$1577,"Martin",'PvA Data'!$E$2:$E$1577,$B29),IFERROR(AVERAGEIFS('PvA Data'!$G$2:$G$1577,'PvA Data'!$B$2:$B$1577,">="&$C$4,'PvA Data'!$B$2:$B$1577,"<="&$C$5,'PvA Data'!$C$2:$C$1577,"Martin",'PvA Data'!$E$2:$E$1577,$B29),0)) -> 9.68 | H29: =IFERROR(SUMIFS('PvA Data'!$F$2:$F$1577,'PvA Data'!$B$2:$B$1577,">="&$C$4,'PvA Data'!$B$2:$B$1577,"<="&$C$5,'PvA Data'!$C$2:$C$1577,"Martin",'PvA Data'!$E$2:$E$1577,$B29)/SUMIFS('PvA Data'!$F$2:$F$1577,'PvA Data'!$B$2:$B$1577,">="&$C$4,'PvA Data'!$B$2:$B$1577,"<="&$C$5,'PvA Data'!$E$2:$E$1577,$B29),"") -> 1 | I29: =IF($C$6="Total",SUMIFS('PvA Data'!$F$2:$F$1577,'PvA Data'!$B$2:$B$1577,">="&$C$4,'PvA Data'!$B$2:$B$1577,"<="&$C$5,'PvA Data'!$C$2:$C$1577,"Custom",'PvA Data'!$E$2:$E$1577,$B29),IFERROR(AVERAGEIFS('PvA Data'!$F$2:$F$1577,'PvA Data'!$B$2:$B$1577,">="&$C$4,'PvA Data'!$B$2:$B$1577,"<="&$C$5,'PvA Data'!$C$2:$C$1577,"Custom",'PvA Data'!$E$2:$E$1577,$B29),0)) -> 0 | J29: =IF($C$6="Total",SUMIFS('PvA Data'!$G$2:$G$1577,'PvA Data'!$B$2:$B$1577,">="&$C$4,'PvA Data'!$B$2:$B$1577,"<="&$C$5,'PvA Data'!$C$2:$C$1577,"Custom",'PvA Data'!$E$2:$E$1577,$B29),IFERROR(AVERAGEIFS('PvA Data'!$G$2:$G$1577,'PvA Data'!$B$2:$B$1577,">="&$C$4,'PvA Data'!$B$2:$B$1577,"<="&$C$5,'PvA Data'!$C$2:$C$1577,"Custom",'PvA Data'!$E$2:$E$1577,$B29),0)) -> 0 | K29: =IFERROR(SUMIFS('PvA Data'!$F$2:$F$1577,'PvA Data'!$B$2:$B$1577,">="&$C$4,'PvA Data'!$B$2:$B$1577,"<="&$C$5,'PvA Data'!$C$2:$C$1577,"Custom",'PvA Data'!$E$2:$E$1577,$B29)/SUMIFS('PvA Data'!$F$2:$F$1577,'PvA Data'!$B$2:$B$1577,">="&$C$4,'PvA Data'!$B$2:$B$1577,"<="&$C$5,'PvA Data'!$E$2:$E$1577,$B29),"") -> 0 | L29: =C29+F29+I29 -> 56 | M29: =D29+G29+J29 -> 9.68 | N29: =IFERROR(M29/L29,"") -> 0.17285714
A30: 666541 | B30: Female Pelvic | C30: =IF($C$6="Total",SUMIFS('PvA Data'!$F$2:$F$1577,'PvA Data'!$B$2:$B$1577,">="&$C$4,'PvA Data'!$B$2:$B$1577,"<="&$C$5,'PvA Data'!$C$2:$C$1577,"Nahunta",'PvA Data'!$E$2:$E$1577,$B30),IFERROR(AVERAGEIFS('PvA Data'!$F$2:$F$1577,'PvA Data'!$B$2:$B$1577,">="&$C$4,'PvA Data'!$B$2:$B$1577,"<="&$C$5,'PvA Data'!$C$2:$C$1577,"Nahunta",'PvA Data'!$E$2:$E$1577,$B30),0)) -> 0 | D30: =IF($C$6="Total",SUMIFS('PvA Data'!$G$2:$G$1577,'PvA Data'!$B$2:$B$1577,">="&$C$4,'PvA Data'!$B$2:$B$1577,"<="&$C$5,'PvA Data'!$C$2:$C$1577,"Nahunta",'PvA Data'!$E$2:$E$1577,$B30),IFERROR(AVERAGEIFS('PvA Data'!$G$2:$G$1577,'PvA Data'!$B$2:$B$1577,">="&$C$4,'PvA Data'!$B$2:$B$1577,"<="&$C$5,'PvA Data'!$C$2:$C$1577,"Nahunta",'PvA Data'!$E$2:$E$1577,$B30),0)) -> 0 | E30: =IFERROR(SUMIFS('PvA Data'!$F$2:$F$1577,'PvA Data'!$B$2:$B$1577,">="&$C$4,'PvA Data'!$B$2:$B$1577,"<="&$C$5,'PvA Data'!$C$2:$C$1577,"Nahunta",'PvA Data'!$E$2:$E$1577,$B30)/SUMIFS('PvA Data'!$F$2:$F$1577,'PvA Data'!$B$2:$B$1577,">="&$C$4,'PvA Data'!$B$2:$B$1577,"<="&$C$5,'PvA Data'!$E$2:$E$1577,$B30),"") -> 0 | F30: =IF($C$6="Total",SUMIFS('PvA Data'!$F$2:$F$1577,'PvA Data'!$B$2:$B$1577,">="&$C$4,'PvA Data'!$B$2:$B$1577,"<="&$C$5,'PvA Data'!$C$2:$C$1577,"Martin",'PvA Data'!$E$2:$E$1577,$B30),IFERROR(AVERAGEIFS('PvA Data'!$F$2:$F$1577,'PvA Data'!$B$2:$B$1577,">="&$C$4,'PvA Data'!$B$2:$B$1577,"<="&$C$5,'PvA Data'!$C$2:$C$1577,"Martin",'PvA Data'!$E$2:$E$1577,$B30),0)) -> 244.4 | G30: =IF($C$6="Total",SUMIFS('PvA Data'!$G$2:$G$1577,'PvA Data'!$B$2:$B$1577,">="&$C$4,'PvA Data'!$B$2:$B$1577,"<="&$C$5,'PvA Data'!$C$2:$C$1577,"Martin",'PvA Data'!$E$2:$E$1577,$B30),IFERROR(AVERAGEIFS('PvA Data'!$G$2:$G$1577,'PvA Data'!$B$2:$B$1577,">="&$C$4,'PvA Data'!$B$2:$B$1577,"<="&$C$5,'PvA Data'!$C$2:$C$1577,"Martin",'PvA Data'!$E$2:$E$1577,$B30),0)) -> 177.2 | H30: =IFERROR(SUMIFS('PvA Data'!$F$2:$F$1577,'PvA Data'!$B$2:$B$1577,">="&$C$4,'PvA Data'!$B$2:$B$1577,"<="&$C$5,'PvA Data'!$C$2:$C$1577,"Martin",'PvA Data'!$E$2:$E$1577,$B30)/SUMIFS('PvA Data'!$F$2:$F$1577,'PvA Data'!$B$2:$B$1577,">="&$C$4,'PvA Data'!$B$2:$B$1577,"<="&$C$5,'PvA Data'!$E$2:$E$1577,$B30),"") -> 1 | I30: =IF($C$6="Total",SUMIFS('PvA Data'!$F$2:$F$1577,'PvA Data'!$B$2:$B$1577,">="&$C$4,'PvA Data'!$B$2:$B$1577,"<="&$C$5,'PvA Data'!$C$2:$C$1577,"Custom",'PvA Data'!$E$2:$E$1577,$B30),IFERROR(AVERAGEIFS('PvA Data'!$F$2:$F$1577,'PvA Data'!$B$2:$B$1577,">="&$C$4,'PvA Data'!$B$2:$B$1577,"<="&$C$5,'PvA Data'!$C$2:$C$1577,"Custom",'PvA Data'!$E$2:$E$1577,$B30),0)) -> 0 | J30: =IF($C$6="Total",SUMIFS('PvA Data'!$G$2:$G$1577,'PvA Data'!$B$2:$B$1577,">="&$C$4,'PvA Data'!$B$2:$B$1577,"<="&$C$5,'PvA Data'!$C$2:$C$1577,"Custom",'PvA Data'!$E$2:$E$1577,$B30),IFERROR(AVERAGEIFS('PvA Data'!$G$2:$G$1577,'PvA Data'!$B$2:$B$1577,">="&$C$4,'PvA Data'!$B$2:$B$1577,"<="&$C$5,'PvA Data'!$C$2:$C$1577,"Custom",'PvA Data'!$E$2:$E$1577,$B30),0)) -> 0 | K30: =IFERROR(SUMIFS('PvA Data'!$F$2:$F$1577,'PvA Data'!$B$2:$B$1577,">="&$C$4,'PvA Data'!$B$2:$B$1577,"<="&$C$5,'PvA Data'!$C$2:$C$1577,"Custom",'PvA Data'!$E$2:$E$1577,$B30)/SUMIFS('PvA Data'!$F$2:$F$1577,'PvA Data'!$B$2:$B$1577,">="&$C$4,'PvA Data'!$B$2:$B$1577,"<="&$C$5,'PvA Data'!$E$2:$E$1577,$B30),"") -> 0 | L30: =C30+F30+I30 -> 244.4 | M30: =D30+G30+J30 -> 177.2 | N30: =IFERROR(M30/L30,"") -> 0.72504092
