Workbook

Sheet README
A1: PELVIC BLOCK IQC — PARETO & ROOT-CAUSE FRAMEWORK
A2: Incoming Quality Control of rejected porcine femoral pelvic blocks | Purpose: pinpoint where defects originate at the supplier and drive corrective action upstream
A5: PURPOSE
A6: Ingest IQC results for rejected pelvic blocks, sort defects with a Pareto (the few defects causing most loss), and map every defect back to the
A7: point in the SUPPLIER's process where it is created — so corrective action can be taken BEFORE the tissue block reaches us.
A9: THE PROCESS (where a defect can be born) — everything up to 'Delivered to us' is the supplier's to control
A10: Live animal -> S1 Sticking/Bleeding -> S2 Bung dropping/Rodding -> S3 Evisceration (knife + gut pull) -> S4 Carcass splitting (saw) -> S5 Handling & Pit drop -> Delivered to us
A11: OUR side -> Harvest techs receive block from pit -> spec-out / accept -> IQC inspection (this data)
A13: THE SHEETS
A14: 1. Inspection Log Master data — ONE ROW PER BLOCK. Each free-text scrap reason is normalized into 1/0 flags against the defect taxonomy. Append future batches here.
A15: 2. Defect Taxonomy Controlled vocabulary (D1–D11) + root-cause map: each defect -> process step, supplier station, 6M cause, mechanism, corrective action.
A16: 3. Pareto Auto-calculating defect Pareto (bar + cumulative line) and a rollup by SUPPLIER STATION — the key view for the supplier conversation.
... A34: IQC Tally Sheets — SH: Martins. Originals kept as source_*.xlsx in this folder.

Sheet Inspection Log
A1: INSPECTION LOG (master data — one row per inspected block)
A2: Append future inspections below. Put 1 in each defect column that applies. Pareto/Dashboard update automatically.
A4: Block ID | B4: Insp. Date | C4: Kill Date | D4: Harvest Date | E4: Slaughterhouse | F4: SH Tech | G4: Inspector | H4: Batch/Lot | I4: Part Name | J4: Result | K4: Verbatim Scrap Reason | L4: D1 | M4: D2 | N4: D3 | O4: D4 | P4: D5 | Q4: D6 | R4: D7 | S4: D8 | T4: D9 | U4: D10 | V4: D11 | W4: D12 | X4: D13 | Y4: # Defects | Z4: Notes / Disposition
A5: B001 | B5: 2026-05-27 | C5: 2026-05-27 | E5: Martins | I5: Pelvic block | J5: Fail | K5: hole in the distal end of the colon | S5: 1 | Y5: =SUM(L5:X5)
A6: B002 | B6: 2026-05-27 | C6: 2026-05-27 | E6: Martins | I6: Pelvic block | J6: Fail | K6: hole in the distal end of the colon | S6: 1 | Y6: =SUM(L6:X6)
A7: B003 | B7: 2026-05-27 | C7: 2026-05-27 | E7: Martins | I7: Pelvic block | J7: Fail | K7: hole in the distal end of the colon | S7: 1 | Y7: =SUM(L7:X7)
A8: B004 | B8: 2026-05-27 | C8: 2026-05-27 | E8: Martins | I8: Pelvic block | J8: Fail | K8: hole in the distal end of the urethra and bladder neck separation | P8: 1 | V8: 1 | Y8: =SUM(L8:X8)
A9: B005 | B9: 2026-05-27 | C9: 2026-05-27 | E9: Martins | I9: Pelvic block | J9: Pass | K9: 8" hole in the bladder suspencery ligamant. ureter still intact??? | Y9: =SUM(L9:X9) | Z9: QUESTIONABLE - pending ME/DE determination (per sheet note). If reclassified Fail -> D4 (suspensory ligament).
A10: B006 | B10: 2026-05-27 | C10: 2026-05-27 | E10: Martins | I10: Pelvic block | J10: Pass | K10: 8" hole in the bladder suspencery ligamant. ureter still intact??? | Y10: =SUM(L10:X10) | Z10: QUESTIONABLE - pending ME/DE determination (per sheet note). If reclassified Fail -> D4 (suspensory ligament).
A11: B007 | B11: 2026-05-27 | C11: 2026-05-27 | E11: Martins | I11: Pelvic block | J11: Pass | K11: 8" hole in the bladder suspencery ligamant. ureter still intact??? | Y11: =SUM(L11:X11) | Z11: QUESTIONABLE - pending ME/DE determination (per sheet note). If reclassified Fail -> D4 (suspensory ligament).
A12: B008 | B12: 2026-05-27 | C12: 2026-05-27 | E12: Martins | I12: Pelvic block | J12: Pass | K12: 8" hole in the bladder suspencery ligamant. ureter still intact??? | Y12: =SUM(L12:X12) | Z12: QUESTIONABLE - pending ME/DE determination (per sheet note). If reclassified Fail -> D4 (suspensory ligament).
A13: B009 | B13: 2026-05-27 | C13: 2026-05-27 | E13: Martins | I13: Pelvic block | J13: Pass | K13: 8" hole in the bladder suspencery ligamant. ureter still intact??? | Y13: =SUM(L13:X13) | Z13: QUESTIONABLE - pending ME/DE determination (per sheet note). If reclassified Fail -> D4 (suspensory ligament).
A14: B010 | B14: 2026-05-27 | C14: 2026-05-27 | E14: Martins | I14: Pelvic block | J14: Pass | K14: no damage found | Y14: =SUM(L14:X14)
A15: B011 | B15: 2026-05-27 | C15: 2026-05-27 | E15: Martins | I15: Pelvic block | J15: Pass | K15: no damage found | Y15: =SUM(L15:X15)
A16: B012 | B16: 2026-05-27 | C16: 2026-05-27 | E16: Martins | I16: Pelvic block | J16: Fail | K16: ureter cut off | M16: 1 | Y16: =SUM(L16:X16)
A17: B013 | B17: 2026-05-27 | C17: 2026-05-27 | E17: Martins | I17: Pelvic block | J17: Fail | K17: hole in mesentary membrane in critical area greater than 1.5" | Q17: 1 | Y17: =SUM(L17:X17)
A18: B014 | B18: 2026-05-27 | C18: 2026-05-27 | E18: Martins | I18: Pelvic block | J18: Fail | K18: hole in mesentary membrane in critical area greater than 1.5" | Q18: 1 | Y18: =SUM(L18:X18)
A19: B015 | B19: 2026-05-27 | C19: 2026-05-27 | E19: Martins | I19: Pelvic block | J19: Fail | K19: hole in mesentary membrane in critical area greater than 1.5" | Q19: 1 | Y19: =SUM(L19:X19)
A20: B016 | B20: 2026-05-27 | C20: 2026-05-27 | E20: Martins | I20: Pelvic block | J20: Fail | K20: hole in mesentary membrane in critical area greater than 1.5" | Q20: 1 | Y20: =SUM(L20:X20)
A21: B017 | B21: 2026-05-27 | C21: 2026-05-27 | E21: Martins | I21: Pelvic block | J21: Fail | K21: hole in mesentary membrane in critical area greater than 1.5" | Q21: 1 | Y21: =SUM(L21:X21)
A22: B018 | B22: 2026-05-27 | C22: 2026-05-27 | E22: Martins | I22: Pelvic block | J22: Fail | K22: hole in mesentary membrane in critical area greater than 1.5" | Q22: 1 | Y22: =SUM(L22:X22)
A23: B019 | B23: 2026-05-27 | C23: 2026-05-27 | E23: Martins | I23: Pelvic block | J23: Fail | K23: hole in mesentary membrane in critical area greater than 1.5" | Q23: 1 | Y23: =SUM(L23:X23)
A24: B020 | B24: 2026-05-27 | C24: 2026-05-27 | E24: Martins | I24: Pelvic block | J24: Fail | K24: hole in mesentary membrane in critical area greater than 1.5" | Q24: 1 | Y24: =SUM(L24:X24)
A25: B021 | B25: 2026-05-27 | C25: 2026-05-27 | E25: Martins | I25: Pelvic block | J25: Fail | K25: hole in mesentary membrane in critical area greater than 1.5" | Q25: 1 | Y25: =SUM(L25:X25)
A26: B022 | B26: 2026-05-27 | C26: 2026-05-27 | E26: Martins | I26: Pelvic block | J26: Fail | K26: hole in mesentary membrane in critical area greater than 1.5" | Q26: 1 | Y26: =SUM(L26:X26)
A27: B023 | B27: 2026-05-27 | C27: 2026-05-27 | E27: Martins | I27: Pelvic block | J27: Fail | K27: hole in mesentary membrane in critical area greater than 1.5" | Q27: 1 | Y27: =SUM(L27:X27)
A28: B024 | B28: 2026-05-27 | C28: 2026-05-27 | E28: Martins | I28: Pelvic block | J28: Fail | K28: hole in mesentary membrane in critical area greater than 1.5" | Q28: 1 | Y28: =SUM(L28:X28)
... A30: B026 | B30: 2026-05-27 | C30: 2026-05-27 | E30: Martins | I30: Pelvic block | J30: Fail | K30: hole in mesentary membrane in critical area greater than 1.5" | Q30: 1 | Y30: =SUM(L30:X30)
A31: B027 | B31: 2026-05-27 | C31: 2026-05-27 | E31: Martins | I31: Pelvic block | J31: Fail | K31: rectum seperation | S31: 1 | Y31: =SUM(L31:X31)
A32: B028 | B32: 2026-05-27 | C32: 2026-05-27 | E32: Martins | I32: Pelvic block | J32: Fail | K32: laceration in urethra | P32: 1 | Y32: =SUM(L32:X32)
A33: B029 | B33: 2026-05-27 | C33: 2026-05-27 | E33: Martins | I33: Pelvic block | J33: Fail | K33: laceration in urethra | P33: 1 | Y33: =SUM(L33:X33)
A34: B030 | B34: 2026-05-27 | C34: 2026-05-27 | E34: Martins | I34: Pelvic block | J34: Fail | K34: hole in the distal end of the urethra and hole in mesentary membrane in critical area greater than 1.5" | P34: 1 | Q34: 1 | Y34: =SUM(L34:X34)
A35: B031 | B35: 2026-05-27 | C35: 2026-05-27 | E35: Martins | I35: Pelvic block | J35: Pass | K35: hole in the distal end of the colon passed the template | Y35: =SUM(L35:X35) | Z35: Colon hole small enough to pass template.
A36: B032 | B36: 2026-07-10 | C36: 2026-07-08 | D36: 2026-07-08 | E36: Martins | H36: 12:30 PM - 12:45 PM | I36: Tiss, porcine, fem, Pelvic block | J36: Fail | K36: Large hole near right broad ligament and membrane causing seperation of bowel and ureters. | Q36: 1 | S36: 1 | U36: 1 | Y36: =SUM(L36:X36)
A37: B033 | B37: 2026-07-10 | C37: 2026-07-08 | D37: 2026-07-08 | E37: Martins | H37: 12:30 PM - 12:45 PM | I37: Tiss, porcine, fem, Pelvic block | J37: Fail | K37: 2 inch damage on membrane seperating bowel in critical area | Q37: 1 | S37: 1 | Y37: =SUM(L37:X37)
A38: B034 | B38: 2026-07-10 | C38: 2026-07-08 | D38: 2026-07-08 | E38: Martins | H38: 12:30 PM - 12:45 PM | I38: Tiss, porcine, fem, Pelvic block | J38: Fail | K38: urethra is cut | P38: 1 | Y38: =SUM(L38:X38)
A39: B035 | B39: 2026-07-10 | C39: 2026-07-08 | D39: 2026-07-08 | E39: Martins | H39: 12:30 PM - 12:45 PM | I39: Tiss, porcine, fem, Pelvic block | J39: Fail | K39: bladder deformed 12 inch deformed attachment | R39: 1 | Y39: =SUM(L39:X39)
A40: B036 | B40: 2026-07-10 | C40: 2026-07-08 | D40: 2026-07-08 | E40: Martins | H40: 12:30 PM - 12:45 PM | I40: Tiss, porcine, fem, Pelvic block | J40: Fail | K40: suspensory ligaments damaged, ureters not embedded | L40: 1 | O40: 1 | Y40: =SUM(L40:X40)
A41: B037 | B41: 2026-07-10 | C41: 2026-07-08 | D41: 2026-07-08 | E41: Martins | H41: 12:30 PM - 12:45 PM | I41: Tiss, porcine, fem, Pelvic block | J41: Fail | K41: ureters not embedded, suspensory ligaments damaged, cut urethra | L41: 1 | O41: 1 | P41: 1 | Y41: =SUM(L41:X41)
A42: B038 | B42: 2026-07-10 | C42: 2026-07-08 | D42: 2026-07-08 | E42: Martins | H42: 12:30 PM - 12:45 PM | I42: Tiss, porcine, fem, Pelvic block | J42: Fail | K42: ureters not embedded and cut, suspensory ligaments damaged, cut urethra | L42: 1 | M42: 1 | O42: 1 | P42: 1 | Y42: =SUM(L42:X42)
...

Sheet Defect Taxonomy
A1: DEFECT TAXONOMY & ROOT-CAUSE MAP
A2: The controlled vocabulary. Every scrap reason maps to a code here — the point where a defect is traced back to the supplier's process.
A4: Code | B4: Defect Mode | C4: Definition | D4: Severity | E4: Likely Process Step (where it's born) | F4: Supplier Station | G4: Root-Cause Category (6M) | H4: Likely Mechanism | I4: Recommended Corrective Action (to supplier) | J4: Lessons Learned (fill in over time)
A5: D1 | B5: Ureters not embedded | C5: Ureter(s) dislodged/stripped from the surrounding pelvic fat & fascia; no longer seated in tissue. | D5: Major | E5: Gut/pluck removal (traction) + pit handling | F5: S3 Evisceration | G5: Method / Handling | H5: Tensile traction: block pulled/stripped so fascia separates from ureter; over-trim. | I5: Standardize gut-pull technique & pull-force; reduce stripping of perirenal fat; gentler drop to pit.
A6: D2 | B6: Ureter cut / severed | C6: Ureter partially or fully transected / cut off (sharp cut edge). | D6: Major | E6: Evisceration knife / splitting saw | F6: S3 Evisceration | G6: Machine / Method | H6: Sharp laceration by evisceration knife or off-line pelvic saw path. | I6: Retrain knife path around pelvic organs; verify saw alignment through symphysis.
A7: D3 | B7: Ureter missing | C7: One ureter (left or right) absent from the block. | D7: Major | E7: Bung dropping / splitting (over-cut) or lost in handling | F7: S2 Bung dropping | G7: Method / Handling | H7: Over-aggressive bung/pelvic cut removes ureter, or ureter lost during drop/collection. | I7: Tighten bung-dropping cut boundary; audit pit collection for detached tissue.
A8: D4 | B8: Suspensory ligaments damaged | C8: Suspensory ligament(s) torn/frayed or holed (incl. bladder suspensory ligament). | D8: Major | E8: Gut pull (traction) + handling | F8: S3 Evisceration | G8: Method / Handling | H8: Excessive pull force / rough handling tears ligament attachments. | I8: Control pull-force & angle on gut set removal; handle block by support surface, not by ligaments.
A9: D5 | B9: Urethra breach (cut / laceration / hole / separation) | C9: Urethra transected, lacerated, perforated or separated (incl. hole in distal urethra). | D9: Major | E9: Carcass splitting saw / bung dropping | F9: S4 Carcass splitting | G9: Machine / Method | H9: Splitting saw off-center through pelvis, or bung-drop cut catches/perforates urethra. | I9: Center pelvic split on symphysis; calibrate/align splitting saw; slow through pelvic zone.
A10: D6 | B10: Membrane damage in critical area | C10: Hole/tear in the mesentery membrane separating bowel from pelvic organs, in the critical zone (>1.5"). | D10: Critical | E10: Evisceration knife technique / bung dropping | F10: S3 Evisceration | G10: Method / Man | H10: Knife nick or tensile tear of membrane during gut removal / bung loosening. | I10: Retrain evisceration knife depth & path; slow line in pelvic zone; blunt-dissect where possible.
A11: D7 | B11: Bladder deformed / deformed attachment | C11: Bladder misshapen or attachment distorted. | D11: Minor | E11: Live-animal fill state / handling pressure | F11: S6 Live / physiology | G11: Material / Handling | H11: Distended (full) bladder at slaughter, or compression during handling. | I11: Manage lairage/feed-water timing to reduce bladder fill; avoid compressing block.
A12: D8 | B12: Bowel / colon / rectum breach | C12: Bowel integrity breached - cut, hole, or separation of colon/rectum. FOOD-SAFETY / contamination risk. | D12: Critical | E12: Evisceration / bung dropping | F12: S3 Evisceration | G12: Method / Man | H12: Knife slip or aggressive bung separation opens/severs colon or rectum. | I12: Reinforce bung-bagging/tie-off; retrain knife path; treat as contamination CCP at supplier.
A13: D9 | B13: Blood clots | C13: Retained blood clots in the tissue block. | D13: Minor | E13: Sticking / bleeding efficiency | F13: S1 Sticking / Bleeding | G13: Method | H13: Incomplete exsanguination (stick placement / stun-to-stick interval / bleed time). | I13: Verify stick placement & bleed-out time; check stun-to-stick interval.
A14: D10 | B14: Broad ligament hole / tear | C14: Large hole/tear in the broad ligament. | D14: Major | E14: Evisceration / bung dropping | F14: S3 Evisceration | G14: Method / Handling | H14: Traction tear or knife nick near broad ligament during gut removal. | I14: Control pull-force; retrain knife path near broad ligament.
A15: D11 | B15: Bladder neck separation | C15: Bladder detached/separated at the neck (bladder-urethra junction at the pelvic floor). | D15: Major | E15: Carcass splitting saw / pelvic outlet cut | F15: S4 Carcass splitting | G15: Machine / Method | H15: Saw path or traction at the pelvic floor separates the bladder neck from the urethra. | I15: Center pelvic split; protect bladder neck at the pelvic outlet; control traction.
A16: D12 | B16: Bladder cut / hole (breach) | C16: Bladder wall cut open or holed. Urine-contamination risk. Distinct from D7 (deformed) & D11 (neck separation). | D16: Major | E16: Evisceration knife / splitting saw | F16: S3 Evisceration | G16: Machine / Method | H16: Knife nick or saw path opens the bladder; or over-distended bladder ruptures under handling. | I16: Protect bladder during gut removal; verify saw path; manage bladder fill (lairage/water timing).
A17: D13 | B17: Block too short / undersized | C17: Harvested pelvic block dimensionally too short / fails the length template (insufficient tissue retained). | D17: Major | E17: Pelvic-block separation cut (cut-boundary placement) | F17: S3 Evisceration | G17: Method / Man | H17: Separation cut placed too close; insufficient block length retained vs template/spec. | I17: Define & train pelvic-block cut boundaries / minimum length; cut to template; provide a length gauge.

Sheet Pareto
A1: PARETO — DEFECT FREQUENCY & SUPPLIER-STATION ROLLUP
A2: Counts pull live from the Inspection Log (all batches). Fix the 'vital few' (cumulative line to ~80%) first. Re-sort high->low if ranking changes.
A4: A. DEFECT PARETO (by occurrence across all inspected blocks, all batches)
A5: Rank | B5: Code | C5: Defect Mode | D5: Count | E5: % of Total | F5: Cumulative % | N5: 80% target
A6: 1 | B6: D6 | C6: Membrane damage in critical area | D6: =SUM('Inspection Log'!Q5:Q503) | E6: =D6/SUM('Inspection Log'!L5:X503) | F6: =E6 | M6: D6 · Membrane dmg | N6: 0.8
A7: 2 | B7: D1 | C7: Ureters not embedded | D7: =SUM('Inspection Log'!L5:L503) | E7: =D7/SUM('Inspection Log'!L5:X503) | F7: =F6+E7 | M7: D1 · Ureters n/e | N7: 0.8
A8: 3 | B8: D5 | C8: Urethra breach (cut / laceration / hole / separation) | D8: =SUM('Inspection Log'!P5:P503) | E8: =D8/SUM('Inspection Log'!L5:X503) | F8: =F7+E8 | M8: D5 · Urethra breach | N8: 0.8
A9: 4 | B9: D8 | C9: Bowel / colon / rectum breach | D9: =SUM('Inspection Log'!S5:S503) | E9: =D9/SUM('Inspection Log'!L5:X503) | F9: =F8+E9 | M9: D8 · Bowel/colon | N9: 0.8
A10: 5 | B10: D4 | C10: Suspensory ligaments damaged | D10: =SUM('Inspection Log'!O5:O503) | E10: =D10/SUM('Inspection Log'!L5:X503) | F10: =F9+E10 | M10: D4 · Susp. ligament | N10: 0.8
A11: 6 | B11: D2 | C11: Ureter cut / severed | D11: =SUM('Inspection Log'!M5:M503) | E11: =D11/SUM('Inspection Log'!L5:X503) | F11: =F10+E11 | M11: D2 · Ureter cut | N11: 0.8
A12: 7 | B12: D13 | C12: Block too short / undersized | D12: =SUM('Inspection Log'!X5:X503) | E12: =D12/SUM('Inspection Log'!L5:X503) | F12: =F11+E12 | M12: D13 · Block too short | N12: 0.8
A13: 8 | B13: D12 | C13: Bladder cut / hole (breach) | D13: =SUM('Inspection Log'!W5:W503) | E13: =D13/SUM('Inspection Log'!L5:X503) | F13: =F12+E13 | M13: D12 · Bladder breach | N13: 0.8
A14: 9 | B14: D3 | C14: Ureter missing | D14: =SUM('Inspection Log'!N5:N503) | E14: =D14/SUM('Inspection Log'!L5:X503) | F14: =F13+E14 | M14: D3 · Ureter missing | N14: 0.8
A15: 10 | B15: D7 | C15: Bladder deformed / deformed attachment | D15: =SUM('Inspection Log'!R5:R503) | E15: =D15/SUM('Inspection Log'!L5:X503) | F15: =F14+E15 | M15: D7 · Bladder def. | N15: 0.8
A16: 11 | B16: D9 | C16: Blood clots | D16: =SUM('Inspection Log'!T5:T503) | E16: =D16/SUM('Inspection Log'!L5:X503) | F16: =F15+E16 | M16: D9 · Blood clots | N16: 0.8
A17: 12 | B17: D10 | C17: Broad ligament hole / tear | D17: =SUM('Inspection Log'!U5:U503) | E17: =D17/SUM('Inspection Log'!L5:X503) | F17: =F16+E17 | M17: D10 · Broad ligament | N17: 0.8
A18: 13 | B18: D11 | C18: Bladder neck separation | D18: =SUM('Inspection Log'!V5:V503) | E18: =D18/SUM('Inspection Log'!L5:X503) | F18: =F17+E18 | M18: D11 · Bladder neck sep. | N18: 0.8
C19: TOTAL | D19: =SUM(D6:D18) | E19: =D19/SUM('Inspection Log'!L5:X503)
A22: B. ROLLUP BY SUPPLIER STATION (which station to fix first)
A23: Station | B23: Station Name | C23: Defect Count | D23: % of Total | E23: Defect Codes
A24: S3 | B24: Evisceration | C24: =SUM('Inspection Log'!L5:L503)+SUM('Inspection Log'!M5:M503)+SUM('Inspection Log'!O5:O503)+SUM('Inspection Log'!Q5:Q503)+SUM('Inspection Log'!S5:S503)+SUM('Inspection Log'!U5:U503)+SUM('Inspection Log'!W5:W503)+SUM('Inspection Log'!X5:X503) | D24: =C24/SUM('Inspection Log'!L5:X503) | E24: D1, D2, D4, D6, D8, D10, D12, D13
A25: S4 | B25: Carcass splitting | C25: =SUM('Inspection Log'!P5:P503)+SUM('Inspection Log'!V5:V503) | D25: =C25/SUM('Inspection Log'!L5:X503) | E25: D5, D11
A26: S2 | B26: Bung dropping | C26: =SUM('Inspection Log'!N5:N503) | D26: =C26/SUM('Inspection Log'!L5:X503) | E26: D3
A27: S6 | B27: Live / physiology | C27: =SUM('Inspection Log'!R5:R503) | D27: =C27/SUM('Inspection Log'!L5:X503) | E27: D7
A28: S1 | B28: Sticking / Bleeding | C28: =SUM('Inspection Log'!T5:T503) | D28: =C28/SUM('Inspection Log'!L5:X503) | E28: D9

Sheet Root Cause 5-Why
A1: ROOT CAUSE — 5-WHY WORKSHEET
A2: Seeded with a starting hypothesis chain for the vital-few defects. Drive each to a true root cause with the supplier, then log the countermeasure & lesson.
A4: Code | B4: Defect Mode | C4: Why 1 | D4: Why 2 | E4: Why 3 | F4: Why 4 | G4: Why 5 (root cause) | H4: Countermeasure (at supplier) | I4: Owner | J4: Target Date | K4: Status | L4: Lessons Learned
A5: D6 | B5: Membrane damage in critical area | C5: Membrane torn/holed in critical area (>1.5") | D5: Knife path too deep / tensile tear during gut pull | E5: Evisceration technique not standardized for pelvic zone | F5: No defined knife depth/path SOP + line-speed pressure | G5: (confirm w/ supplier) training + line-speed control gap | H5: Retrain knife depth & path in pelvic zone; blunt-dissect; slow line through pelvic cut | I5: SH Martins - Evisceration lead | K5: Open
A6: D1 | B6: Ureters not embedded | C6: Ureters not embedded in tissue | D6: Fascia/perirenal fat stripped away from ureter | E6: Excessive pull force / over-trim during gut set removal | F6: Pull technique & trim spec not controlled | G6: (confirm) handling standard missing | H6: Standardize pull-force & angle; limit fat stripping; gentler pit drop | I6: SH Martins - Evisceration lead | K6: Open
A7: D5 | B7: Urethra breach (cut / laceration / hole / separation) | C7: Urethra cut / laceration / hole | D7: Sharp transection or perforation through pelvic zone | E7: Splitting saw off-center / bung-drop cut catches urethra | F7: Saw alignment & pelvic-split centering not verified | G7: (confirm) saw calibration + technique gap | H7: Center split on symphysis; calibrate/align saw; slow through pelvic zone | I7: SH Martins - Splitting lead | K7: Open
A8: D4 | B8: Suspensory ligaments damaged | C8: Suspensory ligaments torn/frayed/holed | D8: Block pulled/handled by the ligaments | E8: Rough handling + high traction on removal | F8: No 'support-surface' handling rule | G8: (confirm) handling standard missing | H8: Handle block by support surface, not ligaments; control pull force | I8: SH Martins - Evisceration lead | K8: Open
A9: D8 | B9: Bowel / colon / rectum breach | C9: Bowel/colon/rectum breached (FOOD SAFETY) | D9: Knife slip or aggressive bung separation opens colon/rectum | E9: Bung not adequately bagged/tied before cut | F9: Bung-dropping CCP not robust | G9: (confirm) contamination-control gap at bung station | H9: Reinforce bung bag/tie-off; retrain knife path; treat as contamination CCP | I9: SH Martins - Bung/Evisc. lead | K9: Open

Sheet Dashboard
A1: DASHBOARD — SUMMARY
A2: SH: Martins | 4 inspection sheets across 3 kill dates (2026-05-27, 2026-07-08, 2026-07-28)
A4: KEY METRICS (all batches)
A5: Blocks Inspected | B5: =COUNTIF('Inspection Log'!J5:J503,"Pass")+COUNTIF('Inspection Log'!J5:J503,"Fail")
A6: Pass | B6: =COUNTIF('Inspection Log'!J5:J503,"Pass")
A7: Fail | B7: =COUNTIF('Inspection Log'!J5:J503,"Fail")
A8: First Pass Yield | B8: =IFERROR(COUNTIF('Inspection Log'!J5:J503,"Pass")/(COUNTIF('Inspection Log'!J5:J503,"Pass")+COUNTIF('Inspection Log'!J5:J503,"Fail")),0)
A9: Total Defect Occurrences | B9: =SUM('Inspection Log'!L5:X503)
A10: Defects per Failed Block | B10: =IFERROR(SUM('Inspection Log'!L5:X503)/COUNTIF('Inspection Log'!J5:J503,"Fail"),0)
A12: PER-BATCH BREAKDOWN (watch the trend)
A13: Kill Date | B13: Inspected | C13: Pass | D13: Fail | E13: First Pass Yield | F13: Top Defect (this batch)
A14: 2026-05-27 | B14: =COUNTIF('Inspection Log'!C5:C503,"2026-05-27") | C14: =COUNTIFS('Inspection Log'!C5:C503,"2026-05-27",'Inspection Log'!J5:J503,"Pass") | D14: =COUNTIFS('Inspection Log'!C5:C503,"2026-05-27",'Inspection Log'!J5:J503,"Fail") | E14: =IFERROR(C14/B14,0) | F14: D6 Membrane damage in critical area (15)
A15: 2026-07-08 | B15: =COUNTIF('Inspection Log'!C5:C503,"2026-07-08") | C15: =COUNTIFS('Inspection Log'!C5:C503,"2026-07-08",'Inspection Log'!J5:J503,"Pass") | D15: =COUNTIFS('Inspection Log'!C5:C503,"2026-07-08",'Inspection Log'!J5:J503,"Fail") | E15: =IFERROR(C15/B15,0) | F15: D6 Membrane damage in critical area (16)
A16: 2026-07-28 | B16: =COUNTIF('Inspection Log'!C5:C503,"2026-07-28") | C16: =COUNTIFS('Inspection Log'!C5:C503,"2026-07-28",'Inspection Log'!J5:J503,"Pass") | D16: =COUNTIFS('Inspection Log'!C5:C503,"2026-07-28",'Inspection Log'!J5:J503,"Fail") | E16: =IFERROR(C16/B16,0) | F16: D6 Membrane damage in critical area (18)
A18: Top defect (all batches)
A19: D6 Membrane damage in critical area
A20: Dominant supplier station
A21: S3 Evisceration -> primary target for corrective action
A23: Critical / food-safety defect occurrences | B23: =SUM('Inspection Log'!Q5:Q503)+SUM('Inspection Log'!S5:S503)
A24: (Critical codes: D6, D8 — membrane damage & bowel/colon/rectum breach)
A26: OPEN ITEMS
A27: 1) 5 blocks (kill 2026-05-27), 8" hole in bladder suspensory ligament, recorded as PASS pending ME/DE determination. If confirmed Fail -> tag D4.
A28: 2) Rasmin 07-28 sheet: handwritten total read '1 Pass / 22 failures', but the per-row entries sum to 29 fails — the granular rows were used. Confirm with inspector.
