Workbook

Sheet GoalLens
A1: Goal Lens — pick a goal, see everything that serves it
A3: Pick a goal → | B3: G1 | C3: =IFERROR(INDEX(Goals!$B$2:$B$20,MATCH($B$3,Goals!$A$2:$A$20,0)),"") -> Reduce supplier defect rate (PPM) by 30% | G3: Owner: | H3: =IFERROR(INDEX(Stakeholders!$B$2:$B$50,MATCH(INDEX(Goals!$C$2:$C$20,MATCH($B$3,Goals!$A$2:$A$20,0)),Stakeholders!$A$2:$A$50,0)),"") -> Leia Organa
A5: Required flows | B5: Covered | C5: Coverage | D5: Defects | E5: Meetings claiming w/o contributing | F5: Unclaimed contributors
A6: =COUNTIFS(Flows!$B$2:$B$400,"required",Flows!$L$2:$L$400,$B$3) -> 6 | B6: =COUNTIFS(Flows!$B$2:$B$400,"required",Flows!$L$2:$L$400,$B$3,Flows!$T$2:$T$400,"covered") -> 4 | C6: =IF($A$6=0,0,$B$6/$A$6) -> 0.66666667 | D6: =$A$6-$B$6 -> 2 | E6: =COUNTIFS(Alignment!$A$2:$A$50,$B$3,Alignment!$J$2:$J$50,"claims_no_contribution") -> 1 | F6: =COUNTIFS(Alignment!$A$2:$A$50,$B$3,Alignment!$J$2:$J$50,"unclaimed_contributor") -> 0
A7: =IF($A$6=0,"No required flows defined for this goal yet — add them on the Flows sheet.",IF($B$6=$A$6,"Every required flow for this goal has a working communication channel."&IF($E$6>0," But "&TEXT($E$6,"0")&" meeting(s) claim this goal without contributing — see below.",""),TEXT($B$6,"0")&" of "&TEXT($A$6,"0")&" required flows have a working channel — "&TEXT($D$6,"0")&" defect(s) listed below.")) -> 4 of 6 required flows have a working channel — 2 defect(s) listed below.
A9: OPERATIONS / TOPICS THAT DERIVE FROM THIS GOAL
A10: topic_id | B10: operation | C10: topic | D10: required flows | E10: covered
A11: =IFERROR(INDEX(Topics!$A$2:$A$100,MATCH(ROWS($A$11:$A11),Topics!$F$2:$F$100,0)),"") -> T1 | B11: =IF($A11="","",INDEX(Topics!$D$2:$D$100,MATCH($A11,Topics!$A$2:$A$100,0))) -> quality monitoring | C11: =IF($A11="","",INDEX(Topics!$B$2:$B$100,MATCH($A11,Topics!$A$2:$A$100,0))) -> incoming_inspection_results | D11: =IF($A11="","",COUNTIFS(Flows!$C$2:$C$400,$A11,Flows!$B$2:$B$400,"required")) -> 2 | E11: =IF($A11="","",COUNTIFS(Flows!$C$2:$C$400,$A11,Flows!$B$2:$B$400,"required",Flows!$T$2:$T$400,"covered")) -> 1
A12: =IFERROR(INDEX(Topics!$A$2:$A$100,MATCH(ROWS($A$11:$A12),Topics!$F$2:$F$100,0)),"") -> T4 | B12: =IF($A12="","",INDEX(Topics!$D$2:$D$100,MATCH($A12,Topics!$A$2:$A$100,0))) -> change control | C12: =IF($A12="","",INDEX(Topics!$B$2:$B$100,MATCH($A12,Topics!$A$2:$A$100,0))) -> design_change_notice | D12: =IF($A12="","",COUNTIFS(Flows!$C$2:$C$400,$A12,Flows!$B$2:$B$400,"required")) -> 1 | E12: =IF($A12="","",COUNTIFS(Flows!$C$2:$C$400,$A12,Flows!$B$2:$B$400,"required",Flows!$T$2:$T$400,"covered")) -> 0
A13: =IFERROR(INDEX(Topics!$A$2:$A$100,MATCH(ROWS($A$11:$A13),Topics!$F$2:$F$100,0)),"") -> T5 | B13: =IF($A13="","",INDEX(Topics!$D$2:$D$100,MATCH($A13,Topics!$A$2:$A$100,0))) -> supplier performance mgmt | C13: =IF($A13="","",INDEX(Topics!$B$2:$B$100,MATCH($A13,Topics!$A$2:$A$100,0))) -> supplier_scorecard | D13: =IF($A13="","",COUNTIFS(Flows!$C$2:$C$400,$A13,Flows!$B$2:$B$400,"required")) -> 2 | E13: =IF($A13="","",COUNTIFS(Flows!$C$2:$C$400,$A13,Flows!$B$2:$B$400,"required",Flows!$T$2:$T$400,"covered")) -> 2
A14: =IFERROR(INDEX(Topics!$A$2:$A$100,MATCH(ROWS($A$11:$A14),Topics!$F$2:$F$100,0)),"") -> T9 | B14: =IF($A14="","",INDEX(Topics!$D$2:$D$100,MATCH($A14,Topics!$A$2:$A$100,0))) -> quality monitoring | C14: =IF($A14="","",INDEX(Topics!$B$2:$B$100,MATCH($A14,Topics!$A$2:$A$100,0))) -> production_line_defects | D14: =IF($A14="","",COUNTIFS(Flows!$C$2:$C$400,$A14,Flows!$B$2:$B$400,"required")) -> 1 | E14: =IF($A14="","",COUNTIFS(Flows!$C$2:$C$400,$A14,Flows!$B$2:$B$400,"required",Flows!$T$2:$T$400,"covered")) -> 1
A15: =IFERROR(INDEX(Topics!$A$2:$A$100,MATCH(ROWS($A$11:$A15),Topics!$F$2:$F$100,0)),"") | B15: =IF($A15="","",INDEX(Topics!$D$2:$D$100,MATCH($A15,Topics!$A$2:$A$100,0))) | C15: =IF($A15="","",INDEX(Topics!$B$2:$B$100,MATCH($A15,Topics!$A$2:$A$100,0))) | D15: =IF($A15="","",COUNTIFS(Flows!$C$2:$C$400,$A15,Flows!$B$2:$B$400,"required")) | E15: =IF($A15="","",COUNTIFS(Flows!$C$2:$C$400,$A15,Flows!$B$2:$B$400,"required",Flows!$T$2:$T$400,"covered"))
A16: =IFERROR(INDEX(Topics!$A$2:$A$100,MATCH(ROWS($A$11:$A16),Topics!$F$2:$F$100,0)),"") | B16: =IF($A16="","",INDEX(Topics!$D$2:$D$100,MATCH($A16,Topics!$A$2:$A$100,0))) | C16: =IF($A16="","",INDEX(Topics!$B$2:$B$100,MATCH($A16,Topics!$A$2:$A$100,0))) | D16: =IF($A16="","",COUNTIFS(Flows!$C$2:$C$400,$A16,Flows!$B$2:$B$400,"required")) | E16: =IF($A16="","",COUNTIFS(Flows!$C$2:$C$400,$A16,Flows!$B$2:$B$400,"required",Flows!$T$2:$T$400,"covered"))
A18: REQUIRED FLOWS FOR THIS GOAL — status computed from the data sheets
A19: flow_id | B19: topic | C19: from (required) | D19: to | E19: crit | F19: status | G19: priority | H19: carriers found
A20: =IFERROR(INDEX(Flows!$A$2:$A$400,MATCH(ROWS($A$20:$A20),Flows!$V$2:$V$400,0)),"") -> FR01 | B20: =IF($A20="","",INDEX(Topics!$B$2:$B$100,MATCH(INDEX(Flows!$C$2:$C$400,MATCH($A20,Flows!$A$2:$A$400,0)),Topics!$A$2:$A$100,0))) -> incoming_inspection_results | C20: =IF($A20="","",IFERROR(INDEX(Stakeholders!$B$2:$B$50,MATCH(INDEX(Flows!$D$2:$D$400,MATCH($A20,Flows!$A$2:$A$400,0)),Stakeholders!$A$2:$A$50,0)),"")) -> Gimli | D20: =IF($A20="","",IFERROR(INDEX(Stakeholders!$B$2:$B$50,MATCH(INDEX(Flows!$E$2:$E$400,MATCH($A20,Flows!$A$2:$A$400,0)),Stakeholders!$A$2:$A$50,0)),"")) -> Frodo Baggins | E20: =IF($A20="","",INDEX(Flows!$F$2:$F$400,MATCH($A20,Flows!$A$2:$A$400,0))) -> 4 | F20: =IF($A20="","",INDEX(Flows!$T$2:$T$400,MATCH($A20,Flows!$A$2:$A$400,0))) -> covered | G20: =IF($A20="","",INDEX(Flows!$U$2:$U$400,MATCH($A20,Flows!$A$2:$A$400,0))) -> 0 | H20: =IF($A20="","",INDEX(Flows!$O$2:$O$400,MATCH($A20,Flows!$A$2:$A$400,0))) -> 2
A21: =IFERROR(INDEX(Flows!$A$2:$A$400,MATCH(ROWS($A$20:$A21),Flows!$V$2:$V$400,0)),"") -> FR02 | B21: =IF($A21="","",INDEX(Topics!$B$2:$B$100,MATCH(INDEX(Flows!$C$2:$C$400,MATCH($A21,Flows!$A$2:$A$400,0)),Topics!$A$2:$A$100,0))) -> incoming_inspection_results | C21: =IF($A21="","",IFERROR(INDEX(Stakeholders!$B$2:$B$50,MATCH(INDEX(Flows!$D$2:$D$400,MATCH($A21,Flows!$A$2:$A$400,0)),Stakeholders!$A$2:$A$50,0)),"")) -> Gimli | D21: =IF($A21="","",IFERROR(INDEX(Stakeholders!$B$2:$B$50,MATCH(INDEX(Flows!$E$2:$E$400,MATCH($A21,Flows!$A$2:$A$400,0)),Stakeholders!$A$2:$A$50,0)),"")) -> Leia Organa | E21: =IF($A21="","",INDEX(Flows!$F$2:$F$400,MATCH($A21,Flows!$A$2:$A$400,0))) -> 3 | F21: =IF($A21="","",INDEX(Flows!$T$2:$T$400,MATCH($A21,Flows!$A$2:$A$400,0))) -> wrong_producer | G21: =IF($A21="","",INDEX(Flows!$U$2:$U$400,MATCH($A21,Flows!$A$2:$A$400,0))) -> 6 | H21: =IF($A21="","",INDEX(Flows!$O$2:$O$400,MATCH($A21,Flows!$A$2:$A$400,0))) -> 1
A22: =IFERROR(INDEX(Flows!$A$2:$A$400,MATCH(ROWS($A$20:$A22),Flows!$V$2:$V$400,0)),"") -> FR03 | B22: =IF($A22="","",INDEX(Topics!$B$2:$B$100,MATCH(INDEX(Flows!$C$2:$C$400,MATCH($A22,Flows!$A$2:$A$400,0)),Topics!$A$2:$A$100,0))) -> production_line_defects | C22: =IF($A22="","",IFERROR(INDEX(Stakeholders!$B$2:$B$50,MATCH(INDEX(Flows!$D$2:$D$400,MATCH($A22,Flows!$A$2:$A$400,0)),Stakeholders!$A$2:$A$50,0)),"")) -> Aragorn | D22: =IF($A22="","",IFERROR(INDEX(Stakeholders!$B$2:$B$50,MATCH(INDEX(Flows!$E$2:$E$400,MATCH($A22,Flows!$A$2:$A$400,0)),Stakeholders!$A$2:$A$50,0)),"")) -> Samwise Gamgee | E22: =IF($A22="","",INDEX(Flows!$F$2:$F$400,MATCH($A22,Flows!$A$2:$A$400,0))) -> 3 | F22: =IF($A22="","",INDEX(Flows!$T$2:$T$400,MATCH($A22,Flows!$A$2:$A$400,0))) -> covered | G22: =IF($A22="","",INDEX(Flows!$U$2:$U$400,MATCH($A22,Flows!$A$2:$A$400,0))) -> 0 | H22: =IF($A22="","",INDEX(Flows!$O$2:$O$400,MATCH($A22,Flows!$A$2:$A$400,0))) -> 1
A23: =IFERROR(INDEX(Flows!$A$2:$A$400,MATCH(ROWS($A$20:$A23),Flows!$V$2:$V$400,0)),"") -> FR04 | B23: =IF($A23="","",INDEX(Topics!$B$2:$B$100,MATCH(INDEX(Flows!$C$2:$C$400,MATCH($A23,Flows!$A$2:$A$400,0)),Topics!$A$2:$A$100,0))) -> design_change_notice | C23: =IF($A23="","",IFERROR(INDEX(Stakeholders!$B$2:$B$50,MATCH(INDEX(Flows!$D$2:$D$400,MATCH($A23,Flows!$A$2:$A$400,0)),Stakeholders!$A$2:$A$50,0)),"")) -> Gandalf | D23: =IF($A23="","",IFERROR(INDEX(Stakeholders!$B$2:$B$50,MATCH(INDEX(Flows!$E$2:$E$400,MATCH($A23,Flows!$A$2:$A$400,0)),Stakeholders!$A$2:$A$50,0)),"")) -> Frodo Baggins | E23: =IF($A23="","",INDEX(Flows!$F$2:$F$400,MATCH($A23,Flows!$A$2:$A$400,0))) -> 5 | F23: =IF($A23="","",INDEX(Flows!$T$2:$T$400,MATCH($A23,Flows!$A$2:$A$400,0))) -> missing | G23: =IF($A23="","",INDEX(Flows!$U$2:$U$400,MATCH($A23,Flows!$A$2:$A$400,0))) -> 15 | H23: =IF($A23="","",INDEX(Flows!$O$2:$O$400,MATCH($A23,Flows!$A$2:$A$400,0))) -> 0
A24: =IFERROR(INDEX(Flows!$A$2:$A$400,MATCH(ROWS($A$20:$A24),Flows!$V$2:$V$400,0)),"") -> FR05 | B24: =IF($A24="","",INDEX(Topics!$B$2:$B$100,MATCH(INDEX(Flows!$C$2:$C$400,MATCH($A24,Flows!$A$2:$A$400,0)),Topics!$A$2:$A$100,0))) -> supplier_scorecard | C24: =IF($A24="","",IFERROR(INDEX(Stakeholders!$B$2:$B$50,MATCH(INDEX(Flows!$D$2:$D$400,MATCH($A24,Flows!$A$2:$A$400,0)),Stakeholders!$A$2:$A$50,0)),"")) -> Frodo Baggins | D24: =IF($A24="","",IFERROR(INDEX(Stakeholders!$B$2:$B$50,MATCH(INDEX(Flows!$E$2:$E$400,MATCH($A24,Flows!$A$2:$A$400,0)),Stakeholders!$A$2:$A$50,0)),"")) -> Han Solo | E24: =IF($A24="","",INDEX(Flows!$F$2:$F$400,MATCH($A24,Flows!$A$2:$A$400,0))) -> 3 | F24: =IF($A24="","",INDEX(Flows!$T$2:$T$400,MATCH($A24,Flows!$A$2:$A$400,0))) -> covered | G24: =IF($A24="","",INDEX(Flows!$U$2:$U$400,MATCH($A24,Flows!$A$2:$A$400,0))) -> 0 | H24: =IF($A24="","",INDEX(Flows!$O$2:$O$400,MATCH($A24,Flows!$A$2:$A$400,0))) -> 1
A25: =IFERROR(INDEX(Flows!$A$2:$A$400,MATCH(ROWS($A$20:$A25),Flows!$V$2:$V$400,0)),"") -> FR06 | B25: =IF($A25="","",INDEX(Topics!$B$2:$B$100,MATCH(INDEX(Flows!$C$2:$C$400,MATCH($A25,Flows!$A$2:$A$400,0)),Topics!$A$2:$A$100,0))) -> supplier_scorecard | C25: =IF($A25="","",IFERROR(INDEX(Stakeholders!$B$2:$B$50,MATCH(INDEX(Flows!$D$2:$D$400,MATCH($A25,Flows!$A$2:$A$400,0)),Stakeholders!$A$2:$A$50,0)),"")) -> Frodo Baggins | D25: =IF($A25="","",IFERROR(INDEX(Stakeholders!$B$2:$B$50,MATCH(INDEX(Flows!$E$2:$E$400,MATCH($A25,Flows!$A$2:$A$400,0)),Stakeholders!$A$2:$A$50,0)),"")) -> Lando Calrissian (Cloud City) | E25: =IF($A25="","",INDEX(Flows!$F$2:$F$400,MATCH($A25,Flows!$A$2:$A$400,0))) -> 4 | F25: =IF($A25="","",INDEX(Flows!$T$2:$T$400,MATCH($A25,Flows!$A$2:$A$400,0))) -> covered | G25: =IF($A25="","",INDEX(Flows!$U$2:$U$400,MATCH($A25,Flows!$A$2:$A$400,0))) -> 0 | H25: =IF($A25="","",INDEX(Flows!$O$2:$O$400,MATCH($A25,Flows!$A$2:$A$400,0))) -> 1
A26: =IFERROR(INDEX(Flows!$A$2:$A$400,MATCH(ROWS($A$20:$A26),Flows!$V$2:$V$400,0)),"") | B26: =IF($A26="","",INDEX(Topics!$B$2:$B$100,MATCH(INDEX(Flows!$C$2:$C$400,MATCH($A26,Flows!$A$2:$A$400,0)),Topics!$A$2:$A$100,0))) | C26: =IF($A26="","",IFERROR(INDEX(Stakeholders!$B$2:$B$50,MATCH(INDEX(Flows!$D$2:$D$400,MATCH($A26,Flows!$A$2:$A$400,0)),Stakeholders!$A$2:$A$50,0)),"")) | D26: =IF($A26="","",IFERROR(INDEX(Stakeholders!$B$2:$B$50,MATCH(INDEX(Flows!$E$2:$E$400,MATCH($A26,Flows!$A$2:$A$400,0)),Stakeholders!$A$2:$A$50,0)),"")) | E26: =IF($A26="","",INDEX(Flows!$F$2:$F$400,MATCH($A26,Flows!$A$2:$A$400,0))) | F26: =IF($A26="","",INDEX(Flows!$T$2:$T$400,MATCH($A26,Flows!$A$2:$A$400,0))) | G26: =IF($A26="","",INDEX(Flows!$U$2:$U$400,MATCH($A26,Flows!$A$2:$A$400,0))) | H26: =IF($A26="","",INDEX(Flows!$O$2:$O$400,MATCH($A26,Flows!$A$2:$A$400,0)))
A27: =IFERROR(INDEX(Flows!$A$2:$A$400,MATCH(ROWS($A$20:$A27),Flows!$V$2:$V$400,0)),"") | B27: =IF($A27="","",INDEX(Topics!$B$2:$B$100,MATCH(INDEX(Flows!$C$2:$C$400,MATCH($A27,Flows!$A$2:$A$400,0)),Topics!$A$2:$A$100,0))) | C27: =IF($A27="","",IFERROR(INDEX(Stakeholders!$B$2:$B$50,MATCH(INDEX(Flows!$D$2:$D$400,MATCH($A27,Flows!$A$2:$A$400,0)),Stakeholders!$A$2:$A$50,0)),"")) | D27: =IF($A27="","",IFERROR(INDEX(Stakeholders!$B$2:$B$50,MATCH(INDEX(Flows!$E$2:$E$400,MATCH($A27,Flows!$A$2:$A$400,0)),Stakeholders!$A$2:$A$50,0)),"")) | E27: =IF($A27="","",INDEX(Flows!$F$2:$F$400,MATCH($A27,Flows!$A$2:$A$400,0))) | F27: =IF($A27="","",INDEX(Flows!$T$2:$T$400,MATCH($A27,Flows!$A$2:$A$400,0))) | G27: =IF($A27="","",INDEX(Flows!$U$2:$U$400,MATCH($A27,Flows!$A$2:$A$400,0))) | H27: =IF($A27="","",INDEX(Flows!$O$2:$O$400,MATCH($A27,Flows!$A$2:$A$400,0)))
A28: =IFERROR(INDEX(Flows!$A$2:$A$400,MATCH(ROWS($A$20:$A28),Flows!$V$2:$V$400,0)),"") | B28: =IF($A28="","",INDEX(Topics!$B$2:$B$100,MATCH(INDEX(Flows!$C$2:$C$400,MATCH($A28,Flows!$A$2:$A$400,0)),Topics!$A$2:$A$100,0))) | C28: =IF($A28="","",IFERROR(INDEX(Stakeholders!$B$2:$B$50,MATCH(INDEX(Flows!$D$2:$D$400,MATCH($A28,Flows!$A$2:$A$400,0)),Stakeholders!$A$2:$A$50,0)),"")) | D28: =IF($A28="","",IFERROR(INDEX(Stakeholders!$B$2:$B$50,MATCH(INDEX(Flows!$E$2:$E$400,MATCH($A28,Flows!$A$2:$A$400,0)),Stakeholders!$A$2:$A$50,0)),"")) | E28: =IF($A28="","",INDEX(Flows!$F$2:$F$400,MATCH($A28,Flows!$A$2:$A$400,0))) | F28: =IF($A28="","",INDEX(Flows!$T$2:$T$400,MATCH($A28,Flows!$A$2:$A$400,0))) | G28: =IF($A28="","",INDEX(Flows!$U$2:$U$400,MATCH($A28,Flows!$A$2:$A$400,0))) | H28: =IF($A28="","",INDEX(Flows!$O$2:$O$400,MATCH($A28,Flows!$A$2:$A$400,0)))
A29: =IFERROR(INDEX(Flows!$A$2:$A$400,MATCH(ROWS($A$20:$A29),Flows!$V$2:$V$400,0)),"") | B29: =IF($A29="","",INDEX(Topics!$B$2:$B$100,MATCH(INDEX(Flows!$C$2:$C$400,MATCH($A29,Flows!$A$2:$A$400,0)),Topics!$A$2:$A$100,0))) | C29: =IF($A29="","",IFERROR(INDEX(Stakeholders!$B$2:$B$50,MATCH(INDEX(Flows!$D$2:$D$400,MATCH($A29,Flows!$A$2:$A$400,0)),Stakeholders!$A$2:$A$50,0)),"")) | D29: =IF($A29="","",IFERROR(INDEX(Stakeholders!$B$2:$B$50,MATCH(INDEX(Flows!$E$2:$E$400,MATCH($A29,Flows!$A$2:$A$400,0)),Stakeholders!$A$2:$A$50,0)),"")) | E29: =IF($A29="","",INDEX(Flows!$F$2:$F$400,MATCH($A29,Flows!$A$2:$A$400,0))) | F29: =IF($A29="","",INDEX(Flows!$T$2:$T$400,MATCH($A29,Flows!$A$2:$A$400,0))) | G29: =IF($A29="","",INDEX(Flows!$U$2:$U$400,MATCH($A29,Flows!$A$2:$A$400,0))) | H29: =IF($A29="","",INDEX(Flows!$O$2:$O$400,MATCH($A29,Flows!$A$2:$A$400,0)))
A31: REQUIRED STAKEHOLDERS OF THIS GOAL
A32: stakeholder | B32: role | C32: group | D32: power | E32: status for this goal
A33: =IFERROR(INDEX(Stakeholders!$B$2:$B$50,MATCH(ROWS($A$33:$A33),Stakeholders!$N$2:$N$50,0)),"") -> Leia Organa | B33: =IF($A33="","",INDEX(Stakeholders!$C$2:$C$50,MATCH(ROWS($A$33:$A33),Stakeholders!$N$2:$N$50,0))) -> Quality Manager | C33: =IF($A33="","",INDEX(Stakeholders!$D$2:$D$50,MATCH(ROWS($A$33:$A33),Stakeholders!$N$2:$N$50,0))) -> Quality | D33: =IF($A33="","",INDEX(Stakeholders!$F$2:$F$50,MATCH(ROWS($A$33:$A33),Stakeholders!$N$2:$N$50,0))) -> 4 | E33: =IF($A33="","",IF(INDEX(Stakeholders!$M$2:$M$50,MATCH(ROWS($A$33:$A33),Stakeholders!$N$2:$N$50,0))=1,"⚠ affected by a defect","ok")) -> ⚠ affected by a defect
A34: =IFERROR(INDEX(Stakeholders!$B$2:$B$50,MATCH(ROWS($A$33:$A34),Stakeholders!$N$2:$N$50,0)),"") -> Frodo Baggins | B34: =IF($A34="","",INDEX(Stakeholders!$C$2:$C$50,MATCH(ROWS($A$33:$A34),Stakeholders!$N$2:$N$50,0))) -> Supplier Quality Engineer Lead | C34: =IF($A34="","",INDEX(Stakeholders!$D$2:$D$50,MATCH(ROWS($A$33:$A34),Stakeholders!$N$2:$N$50,0))) -> Quality | D34: =IF($A34="","",INDEX(Stakeholders!$F$2:$F$50,MATCH(ROWS($A$33:$A34),Stakeholders!$N$2:$N$50,0))) -> 3 | E34: =IF($A34="","",IF(INDEX(Stakeholders!$M$2:$M$50,MATCH(ROWS($A$33:$A34),Stakeholders!$N$2:$N$50,0))=1,"⚠ affected by a defect","ok")) -> ⚠ affected by a defect
A35: =IFERROR(INDEX(Stakeholders!$B$2:$B$50,MATCH(ROWS($A$33:$A35),Stakeholders!$N$2:$N$50,0)),"") -> Samwise Gamgee | B35: =IF($A35="","",INDEX(Stakeholders!$C$2:$C$50,MATCH(ROWS($A$33:$A35),Stakeholders!$N$2:$N$50,0))) -> Supplier Quality Engineer | C35: =IF($A35="","",INDEX(Stakeholders!$D$2:$D$50,MATCH(ROWS($A$33:$A35),Stakeholders!$N$2:$N$50,0))) -> Quality | D35: =IF($A35="","",INDEX(Stakeholders!$F$2:$F$50,MATCH(ROWS($A$33:$A35),Stakeholders!$N$2:$N$50,0))) -> 2 | E35: =IF($A35="","",IF(INDEX(Stakeholders!$M$2:$M$50,MATCH(ROWS($A$33:$A35),Stakeholders!$N$2:$N$50,0))=1,"⚠ affected by a defect","ok")) -> ok
A36: =IFERROR(INDEX(Stakeholders!$B$2:$B$50,MATCH(ROWS($A$33:$A36),Stakeholders!$N$2:$N$50,0)),"") -> Han Solo | B36: =IF($A36="","",INDEX(Stakeholders!$C$2:$C$50,MATCH(ROWS($A$33:$A36),Stakeholders!$N$2:$N$50,0))) -> Procurement Lead | C36: =IF($A36="","",INDEX(Stakeholders!$D$2:$D$50,MATCH(ROWS($A$33:$A36),Stakeholders!$N$2:$N$50,0))) -> Supply Chain | D36: =IF($A36="","",INDEX(Stakeholders!$F$2:$F$50,MATCH(ROWS($A$33:$A36),Stakeholders!$N$2:$N$50,0))) -> 4 | E36: =IF($A36="","",IF(INDEX(Stakeholders!$M$2:$M$50,MATCH(ROWS($A$33:$A36),Stakeholders!$N$2:$N$50,0))=1,"⚠ affected by a defect","ok")) -> ok
A37: =IFERROR(INDEX(Stakeholders!$B$2:$B$50,MATCH(ROWS($A$33:$A37),Stakeholders!$N$2:$N$50,0)),"") -> Gimli | B37: =IF($A37="","",INDEX(Stakeholders!$C$2:$C$50,MATCH(ROWS($A$33:$A37),Stakeholders!$N$2:$N$50,0))) -> Incoming Inspection Lead | C37: =IF($A37="","",INDEX(Stakeholders!$D$2:$D$50,MATCH(ROWS($A$33:$A37),Stakeholders!$N$2:$N$50,0))) -> Quality | D37: =IF($A37="","",INDEX(Stakeholders!$F$2:$F$50,MATCH(ROWS($A$33:$A37),Stakeholders!$N$2:$N$50,0))) -> 2 | E37: =IF($A37="","",IF(INDEX(Stakeholders!$M$2:$M$50,MATCH(ROWS($A$33:$A37),Stakeholders!$N$2:$N$50,0))=1,"⚠ affected by a defect","ok")) -> ⚠ affected by a defect
A38: =IFERROR(INDEX(Stakeholders!$B$2:$B$50,MATCH(ROWS($A$33:$A38),Stakeholders!$N$2:$N$50,0)),"") -> Aragorn | B38: =IF($A38="","",INDEX(Stakeholders!$C$2:$C$50,MATCH(ROWS($A$33:$A38),Stakeholders!$N$2:$N$50,0))) -> Production Supervisor | C38: =IF($A38="","",INDEX(Stakeholders!$D$2:$D$50,MATCH(ROWS($A$33:$A38),Stakeholders!$N$2:$N$50,0))) -> Operations | D38: =IF($A38="","",INDEX(Stakeholders!$F$2:$F$50,MATCH(ROWS($A$33:$A38),Stakeholders!$N$2:$N$50,0))) -> 3 | E38: =IF($A38="","",IF(INDEX(Stakeholders!$M$2:$M$50,MATCH(ROWS($A$33:$A38),Stakeholders!$N$2:$N$50,0))=1,"⚠ affected by a defect","ok")) -> ok
A39: =IFERROR(INDEX(Stakeholders!$B$2:$B$50,MATCH(ROWS($A$33:$A39),Stakeholders!$N$2:$N$50,0)),"") -> Gandalf | B39: =IF($A39="","",INDEX(Stakeholders!$C$2:$C$50,MATCH(ROWS($A$33:$A39),Stakeholders!$N$2:$N$50,0))) -> Design Engineer | C39: =IF($A39="","",INDEX(Stakeholders!$D$2:$D$50,MATCH(ROWS($A$33:$A39),Stakeholders!$N$2:$N$50,0))) -> Engineering | D39: =IF($A39="","",INDEX(Stakeholders!$F$2:$F$50,MATCH(ROWS($A$33:$A39),Stakeholders!$N$2:$N$50,0))) -> 3 | E39: =IF($A39="","",IF(INDEX(Stakeholders!$M$2:$M$50,MATCH(ROWS($A$33:$A39),Stakeholders!$N$2:$N$50,0))=1,"⚠ affected by a defect","ok")) -> ⚠ affected by a defect
A40: =IFERROR(INDEX(Stakeholders!$B$2:$B$50,MATCH(ROWS($A$33:$A40),Stakeholders!$N$2:$N$50,0)),"") -> Lando Calrissian (Cloud City) | B40: =IF($A40="","",INDEX(Stakeholders!$C$2:$C$50,MATCH(ROWS($A$33:$A40),Stakeholders!$N$2:$N$50,0))) -> Supplier Account Manager | C40: =IF($A40="","",INDEX(Stakeholders!$D$2:$D$50,MATCH(ROWS($A$33:$A40),Stakeholders!$N$2:$N$50,0))) -> External | D40: =IF($A40="","",INDEX(Stakeholders!$F$2:$F$50,MATCH(ROWS($A$33:$A40),Stakeholders!$N$2:$N$50,0))) -> 3 | E40: =IF($A40="","",IF(INDEX(Stakeholders!$M$2:$M$50,MATCH(ROWS($A$33:$A40),Stakeholders!$N$2:$N$50,0))=1,"⚠ affected by a defect","ok")) -> ok
A41: =IFERROR(INDEX(Stakeholders!$B$2:$B$50,MATCH(ROWS($A$33:$A41),Stakeholders!$N$2:$N$50,0)),"") | B41: =IF($A41="","",INDEX(Stakeholders!$C$2:$C$50,MATCH(ROWS($A$33:$A41),Stakeholders!$N$2:$N$50,0))) | C41: =IF($A41="","",INDEX(Stakeholders!$D$2:$D$50,MATCH(ROWS($A$33:$A41),Stakeholders!$N$2:$N$50,0))) | D41: =IF($A41="","",INDEX(Stakeholders!$F$2:$F$50,MATCH(ROWS($A$33:$A41),Stakeholders!$N$2:$N$50,0))) | E41: =IF($A41="","",IF(INDEX(Stakeholders!$M$2:$M$50,MATCH(ROWS($A$33:$A41),Stakeholders!$N$2:$N$50,0))=1,"⚠ affected by a defect","ok"))
A42: =IFERROR(INDEX(Stakeholders!$B$2:$B$50,MATCH(ROWS($A$33:$A42),Stakeholders!$N$2:$N$50,0)),"") | B42: =IF($A42="","",INDEX(Stakeholders!$C$2:$C$50,MATCH(ROWS($A$33:$A42),Stakeholders!$N$2:$N$50,0))) | C42: =IF($A42="","",INDEX(Stakeholders!$D$2:$D$50,MATCH(ROWS($A$33:$A42),Stakeholders!$N$2:$N$50,0))) | D42: =IF($A42="","",INDEX(Stakeholders!$F$2:$F$50,MATCH(ROWS($A$33:$A42),Stakeholders!$N$2:$N$50,0))) | E42: =IF($A42="","",IF(INDEX(Stakeholders!$M$2:$M$50,MATCH(ROWS($A$33:$A42),Stakeholders!$N$2:$N$50,0))=1,"⚠ affected by a defect","ok"))
A43: =IFERROR(INDEX(Stakeholders!$B$2:$B$50,MATCH(ROWS($A$33:$A43),Stakeholders!$N$2:$N$50,0)),"") | B43: =IF($A43="","",INDEX(Stakeholders!$C$2:$C$50,MATCH(ROWS($A$33:$A43),Stakeholders!$N$2:$N$50,0))) | C43: =IF($A43="","",INDEX(Stakeholders!$D$2:$D$50,MATCH(ROWS($A$33:$A43),Stakeholders!$N$2:$N$50,0))) | D43: =IF($A43="","",INDEX(Stakeholders!$F$2:$F$50,MATCH(ROWS($A$33:$A43),Stakeholders!$N$2:$N$50,0))) | E43: =IF($A43="","",IF(INDEX(Stakeholders!$M$2:$M$50,MATCH(ROWS($A$33:$A43),Stakeholders!$N$2:$N$50,0))=1,"⚠ affected by a defect","ok"))
A44: =IFERROR(INDEX(Stakeholders!$B$2:$B$50,MATCH(ROWS($A$33:$A44),Stakeholders!$N$2:$N$50,0)),"") | B44: =IF($A44="","",INDEX(Stakeholders!$C$2:$C$50,MATCH(ROWS($A$33:$A44),Stakeholders!$N$2:$N$50,0))) | C44: =IF($A44="","",INDEX(Stakeholders!$D$2:$D$50,MATCH(ROWS($A$33:$A44),Stakeholders!$N$2:$N$50,0))) | D44: =IF($A44="","",INDEX(Stakeholders!$F$2:$F$50,MATCH(ROWS($A$33:$A44),Stakeholders!$N$2:$N$50,0))) | E44: =IF($A44="","",IF(INDEX(Stakeholders!$M$2:$M$50,MATCH(ROWS($A$33:$A44),Stakeholders!$N$2:$N$50,0))=1,"⚠ affected by a defect","ok"))
A46: MEETINGS SERVING (OR CLAIMING) THIS GOAL — claimed vs computed
...

Sheet Findings
A1: Findings — the readout
A2: Computed live from the data sheets. Every finding traces to a goal: defect → required flow → topic → goal. Details on Flows, Alignment, Decisions; goal-first view on GoalLens.
A4: Coverage | B4: Open defects | C4: Theater claims | D4: Unclaimed | E4: Decision defects | G4: Disputed
A5: =IF(COUNTIFS(Flows!$B$2:$B$400,"required")=0,0,COUNTIFS(Flows!$B$2:$B$400,"required",Flows!$T$2:$T$400,"covered")/COUNTIFS(Flows!$B$2:$B$400,"required")) -> 0.58823529 | B5: =COUNTIFS(Flows!$B$2:$B$400,"required",Flows!$T$2:$T$400,"<>covered",Flows!$T$2:$T$400,"<>") -> 7 | C5: =COUNTIF(Alignment!$J$2:$J$50,"claims_no_contribution") -> 2 | D5: =COUNTIF(Alignment!$J$2:$J$50,"unclaimed_contributor") -> 1 | E5: =SUMPRODUCT((Decisions!$L$2:$L$50<>"aligned")*(Decisions!$L$2:$L$50<>"")) -> 3 | G5: =COUNTIFS(Flows!$B$2:$B$400,"actual",Flows!$I$2:$I$400,"disputed") -> 1
A7: BY GOAL — where each goal stands (all findings below roll up to these rows) → open
A8: goal | B8: name | D8: required | E8: covered | F8: open | G8: theater | H8: unclaimed
A9: =IF(Goals!$A2="","",Goals!$A2) -> G1 | B9: =IF($A9="","",INDEX(Goals!$B$2:$B$20,MATCH($A9,Goals!$A$2:$A$20,0))) -> Reduce supplier defect rate (PPM) by 30% | D9: =IF($A9="","",COUNTIFS(Flows!$B$2:$B$400,"required",Flows!$L$2:$L$400,$A9)) -> 6 | E9: =IF($A9="","",COUNTIFS(Flows!$B$2:$B$400,"required",Flows!$L$2:$L$400,$A9,Flows!$T$2:$T$400,"covered")) -> 4 | F9: =IF($A9="","",$D9-$E9) -> 2 | G9: =IF($A9="","",COUNTIFS(Alignment!$A$2:$A$50,$A9,Alignment!$J$2:$J$50,"claims_no_contribution")) -> 1 | H9: =IF($A9="","",COUNTIFS(Alignment!$A$2:$A$50,$A9,Alignment!$J$2:$J$50,"unclaimed_contributor")) -> 0
A10: =IF(Goals!$A3="","",Goals!$A3) -> G2 | B10: =IF($A10="","",INDEX(Goals!$B$2:$B$20,MATCH($A10,Goals!$A$2:$A$20,0))) -> Cut NCR resolution time to under 10 days | D10: =IF($A10="","",COUNTIFS(Flows!$B$2:$B$400,"required",Flows!$L$2:$L$400,$A10)) -> 5 | E10: =IF($A10="","",COUNTIFS(Flows!$B$2:$B$400,"required",Flows!$L$2:$L$400,$A10,Flows!$T$2:$T$400,"covered")) -> 2 | F10: =IF($A10="","",$D10-$E10) -> 3 | G10: =IF($A10="","",COUNTIFS(Alignment!$A$2:$A$50,$A10,Alignment!$J$2:$J$50,"claims_no_contribution")) -> 0 | H10: =IF($A10="","",COUNTIFS(Alignment!$A$2:$A$50,$A10,Alignment!$J$2:$J$50,"unclaimed_contributor")) -> 1
A11: =IF(Goals!$A4="","",Goals!$A4) -> G3 | B11: =IF($A11="","",INDEX(Goals!$B$2:$B$20,MATCH($A11,Goals!$A$2:$A$20,0))) -> Qualify two second-source suppliers for critical components | D11: =IF($A11="","",COUNTIFS(Flows!$B$2:$B$400,"required",Flows!$L$2:$L$400,$A11)) -> 2 | E11: =IF($A11="","",COUNTIFS(Flows!$B$2:$B$400,"required",Flows!$L$2:$L$400,$A11,Flows!$T$2:$T$400,"covered")) -> 2 | F11: =IF($A11="","",$D11-$E11) -> 0 | G11: =IF($A11="","",COUNTIFS(Alignment!$A$2:$A$50,$A11,Alignment!$J$2:$J$50,"claims_no_contribution")) -> 1 | H11: =IF($A11="","",COUNTIFS(Alignment!$A$2:$A$50,$A11,Alignment!$J$2:$J$50,"unclaimed_contributor")) -> 0
A12: =IF(Goals!$A5="","",Goals!$A5) -> G4 | B12: =IF($A12="","",INDEX(Goals!$B$2:$B$20,MATCH($A12,Goals!$A$2:$A$20,0))) -> Pass ISO 9001 surveillance audit with zero major findings | D12: =IF($A12="","",COUNTIFS(Flows!$B$2:$B$400,"required",Flows!$L$2:$L$400,$A12)) -> 2 | E12: =IF($A12="","",COUNTIFS(Flows!$B$2:$B$400,"required",Flows!$L$2:$L$400,$A12,Flows!$T$2:$T$400,"covered")) -> 1 | F12: =IF($A12="","",$D12-$E12) -> 1 | G12: =IF($A12="","",COUNTIFS(Alignment!$A$2:$A$50,$A12,Alignment!$J$2:$J$50,"claims_no_contribution")) -> 0 | H12: =IF($A12="","",COUNTIFS(Alignment!$A$2:$A$50,$A12,Alignment!$J$2:$J$50,"unclaimed_contributor")) -> 0
A13: =IF(Goals!$A6="","",Goals!$A6) -> G5 | B13: =IF($A13="","",INDEX(Goals!$B$2:$B$20,MATCH($A13,Goals!$A$2:$A$20,0))) -> Build SQE bench strength: two engineers certified as supplier auditors | D13: =IF($A13="","",COUNTIFS(Flows!$B$2:$B$400,"required",Flows!$L$2:$L$400,$A13)) -> 2 | E13: =IF($A13="","",COUNTIFS(Flows!$B$2:$B$400,"required",Flows!$L$2:$L$400,$A13,Flows!$T$2:$T$400,"covered")) -> 1 | F13: =IF($A13="","",$D13-$E13) -> 1 | G13: =IF($A13="","",COUNTIFS(Alignment!$A$2:$A$50,$A13,Alignment!$J$2:$J$50,"claims_no_contribution")) -> 0 | H13: =IF($A13="","",COUNTIFS(Alignment!$A$2:$A$50,$A13,Alignment!$J$2:$J$50,"unclaimed_contributor")) -> 0
A14: =IF(Goals!$A7="","",Goals!$A7) | B14: =IF($A14="","",INDEX(Goals!$B$2:$B$20,MATCH($A14,Goals!$A$2:$A$20,0))) | D14: =IF($A14="","",COUNTIFS(Flows!$B$2:$B$400,"required",Flows!$L$2:$L$400,$A14)) | E14: =IF($A14="","",COUNTIFS(Flows!$B$2:$B$400,"required",Flows!$L$2:$L$400,$A14,Flows!$T$2:$T$400,"covered")) | F14: =IF($A14="","",$D14-$E14) | G14: =IF($A14="","",COUNTIFS(Alignment!$A$2:$A$50,$A14,Alignment!$J$2:$J$50,"claims_no_contribution")) | H14: =IF($A14="","",COUNTIFS(Alignment!$A$2:$A$50,$A14,Alignment!$J$2:$J$50,"unclaimed_contributor"))
A16: TOP DEFECTS — required flows, ranked by priority (criticality × status weight) → open
A17: # | B17: goal | C17: topic | D17: from (required) | E17: to | F17: crit | G17: status | H17: priority | I17: carriers / note | J17: why it matters (owner-signed rationale)
A18: =IF(ISNA(MATCH(ROWS($A$18:$A18),Flows!$Y$2:$Y$400,0)),"",ROWS($A$18:$A18)) -> 1 | B18: =IFERROR(INDEX(Flows!$L$2:$L$400,MATCH(ROWS($A$18:$A18),Flows!$Y$2:$Y$400,0)),"") -> G1 | C18: =IFERROR(INDEX(Topics!$B$2:$B$100,MATCH(INDEX(Flows!$C$2:$C$400,MATCH(ROWS($A$18:$A18),Flows!$Y$2:$Y$400,0)),Topics!$A$2:$A$100,0)),"") -> design_change_notice | D18: =IFERROR(INDEX(Stakeholders!$B$2:$B$50,MATCH(INDEX(Flows!$D$2:$D$400,MATCH(ROWS($A$18:$A18),Flows!$Y$2:$Y$400,0)),Stakeholders!$A$2:$A$50,0)),"") -> Gandalf | E18: =IFERROR(INDEX(Stakeholders!$B$2:$B$50,MATCH(INDEX(Flows!$E$2:$E$400,MATCH(ROWS($A$18:$A18),Flows!$Y$2:$Y$400,0)),Stakeholders!$A$2:$A$50,0)),"") -> Frodo Baggins | F18: =IFERROR(INDEX(Flows!$F$2:$F$400,MATCH(ROWS($A$18:$A18),Flows!$Y$2:$Y$400,0)),"") -> 5 | G18: =IFERROR(INDEX(Flows!$T$2:$T$400,MATCH(ROWS($A$18:$A18),Flows!$Y$2:$Y$400,0)),"") -> missing | H18: =IFERROR(INDEX(Flows!$U$2:$U$400,MATCH(ROWS($A$18:$A18),Flows!$Y$2:$Y$400,0)),"") -> 15 | I18: =IF($G18="","",IF($G18="missing","no carrier — create the flow",INDEX(Flows!$O$2:$O$400,MATCH(ROWS($A$18:$A18),Flows!$Y$2:$Y$400,0))&" carrier link(s) — see Flows")) -> no carrier — create the flow | J18: =IFERROR(INDEX(Flows!$K$2:$K$400,MATCH(ROWS($A$18:$A18),Flows!$Y$2:$Y$400,0)),"") -> Supplier parts must match current spec; late ECN notice causes mass NCRs
A19: =IF(ISNA(MATCH(ROWS($A$18:$A19),Flows!$Y$2:$Y$400,0)),"",ROWS($A$18:$A19)) -> 2 | B19: =IFERROR(INDEX(Flows!$L$2:$L$400,MATCH(ROWS($A$18:$A19),Flows!$Y$2:$Y$400,0)),"") -> G2 | C19: =IFERROR(INDEX(Topics!$B$2:$B$100,MATCH(INDEX(Flows!$C$2:$C$400,MATCH(ROWS($A$18:$A19),Flows!$Y$2:$Y$400,0)),Topics!$A$2:$A$100,0)),"") -> containment_actions | D19: =IFERROR(INDEX(Stakeholders!$B$2:$B$50,MATCH(INDEX(Flows!$D$2:$D$400,MATCH(ROWS($A$18:$A19),Flows!$Y$2:$Y$400,0)),Stakeholders!$A$2:$A$50,0)),"") -> Frodo Baggins | E19: =IFERROR(INDEX(Stakeholders!$B$2:$B$50,MATCH(INDEX(Flows!$E$2:$E$400,MATCH(ROWS($A$18:$A19),Flows!$Y$2:$Y$400,0)),Stakeholders!$A$2:$A$50,0)),"") -> Aragorn | F19: =IFERROR(INDEX(Flows!$F$2:$F$400,MATCH(ROWS($A$18:$A19),Flows!$Y$2:$Y$400,0)),"") -> 5 | G19: =IFERROR(INDEX(Flows!$T$2:$T$400,MATCH(ROWS($A$18:$A19),Flows!$Y$2:$Y$400,0)),"") -> latency_gap | H19: =IFERROR(INDEX(Flows!$U$2:$U$400,MATCH(ROWS($A$18:$A19),Flows!$Y$2:$Y$400,0)),"") -> 10 | I19: =IF($G19="","",IF($G19="missing","no carrier — create the flow",INDEX(Flows!$O$2:$O$400,MATCH(ROWS($A$18:$A19),Flows!$Y$2:$Y$400,0))&" carrier link(s) — see Flows")) -> 1 carrier link(s) — see Flows | J19: =IFERROR(INDEX(Flows!$K$2:$K$400,MATCH(ROWS($A$18:$A19),Flows!$Y$2:$Y$400,0)),"") -> Containment must reach the line same-day during incidents
A20: =IF(ISNA(MATCH(ROWS($A$18:$A20),Flows!$Y$2:$Y$400,0)),"",ROWS($A$18:$A20)) -> 3 | B20: =IFERROR(INDEX(Flows!$L$2:$L$400,MATCH(ROWS($A$18:$A20),Flows!$Y$2:$Y$400,0)),"") -> G4 | C20: =IFERROR(INDEX(Topics!$B$2:$B$100,MATCH(INDEX(Flows!$C$2:$C$400,MATCH(ROWS($A$18:$A20),Flows!$Y$2:$Y$400,0)),Topics!$A$2:$A$100,0)),"") -> audit_readiness | D20: =IFERROR(INDEX(Stakeholders!$B$2:$B$50,MATCH(INDEX(Flows!$D$2:$D$400,MATCH(ROWS($A$18:$A20),Flows!$Y$2:$Y$400,0)),Stakeholders!$A$2:$A$50,0)),"") -> C-3PO | E20: =IFERROR(INDEX(Stakeholders!$B$2:$B$50,MATCH(INDEX(Flows!$E$2:$E$400,MATCH(ROWS($A$18:$A20),Flows!$Y$2:$Y$400,0)),Stakeholders!$A$2:$A$50,0)),"") -> Aragorn | F20: =IFERROR(INDEX(Flows!$F$2:$F$400,MATCH(ROWS($A$18:$A20),Flows!$Y$2:$Y$400,0)),"") -> 3 | G20: =IFERROR(INDEX(Flows!$T$2:$T$400,MATCH(ROWS($A$18:$A20),Flows!$Y$2:$Y$400,0)),"") -> missing | H20: =IFERROR(INDEX(Flows!$U$2:$U$400,MATCH(ROWS($A$18:$A20),Flows!$Y$2:$Y$400,0)),"") -> 9 | I20: =IF($G20="","",IF($G20="missing","no carrier — create the flow",INDEX(Flows!$O$2:$O$400,MATCH(ROWS($A$18:$A20),Flows!$Y$2:$Y$400,0))&" carrier link(s) — see Flows")) -> no carrier — create the flow | J20: =IFERROR(INDEX(Flows!$K$2:$K$400,MATCH(ROWS($A$18:$A20),Flows!$Y$2:$Y$400,0)),"") -> Ops owns physical corrective items; needs findings that touch the floor
A21: =IF(ISNA(MATCH(ROWS($A$18:$A21),Flows!$Y$2:$Y$400,0)),"",ROWS($A$18:$A21)) -> 4 | B21: =IFERROR(INDEX(Flows!$L$2:$L$400,MATCH(ROWS($A$18:$A21),Flows!$Y$2:$Y$400,0)),"") -> G2 | C21: =IFERROR(INDEX(Topics!$B$2:$B$100,MATCH(INDEX(Flows!$C$2:$C$400,MATCH(ROWS($A$18:$A21),Flows!$Y$2:$Y$400,0)),Topics!$A$2:$A$100,0)),"") -> containment_actions | D21: =IFERROR(INDEX(Stakeholders!$B$2:$B$50,MATCH(INDEX(Flows!$D$2:$D$400,MATCH(ROWS($A$18:$A21),Flows!$Y$2:$Y$400,0)),Stakeholders!$A$2:$A$50,0)),"") -> Frodo Baggins | E21: =IFERROR(INDEX(Stakeholders!$B$2:$B$50,MATCH(INDEX(Flows!$E$2:$E$400,MATCH(ROWS($A$18:$A21),Flows!$Y$2:$Y$400,0)),Stakeholders!$A$2:$A$50,0)),"") -> Gimli | F21: =IFERROR(INDEX(Flows!$F$2:$F$400,MATCH(ROWS($A$18:$A21),Flows!$Y$2:$Y$400,0)),"") -> 5 | G21: =IFERROR(INDEX(Flows!$T$2:$T$400,MATCH(ROWS($A$18:$A21),Flows!$Y$2:$Y$400,0)),"") -> channel_mismatch | H21: =IFERROR(INDEX(Flows!$U$2:$U$400,MATCH(ROWS($A$18:$A21),Flows!$Y$2:$Y$400,0)),"") -> 7.5 | I21: =IF($G21="","",IF($G21="missing","no carrier — create the flow",INDEX(Flows!$O$2:$O$400,MATCH(ROWS($A$18:$A21),Flows!$Y$2:$Y$400,0))&" carrier link(s) — see Flows")) -> 1 carrier link(s) — see Flows | J21: =IFERROR(INDEX(Flows!$K$2:$K$400,MATCH(ROWS($A$18:$A21),Flows!$Y$2:$Y$400,0)),"") -> Containment must reach incoming inspection same-day during incidents
A22: =IF(ISNA(MATCH(ROWS($A$18:$A22),Flows!$Y$2:$Y$400,0)),"",ROWS($A$18:$A22)) -> 5 | B22: =IFERROR(INDEX(Flows!$L$2:$L$400,MATCH(ROWS($A$18:$A22),Flows!$Y$2:$Y$400,0)),"") -> G1 | C22: =IFERROR(INDEX(Topics!$B$2:$B$100,MATCH(INDEX(Flows!$C$2:$C$400,MATCH(ROWS($A$18:$A22),Flows!$Y$2:$Y$400,0)),Topics!$A$2:$A$100,0)),"") -> incoming_inspection_results | D22: =IFERROR(INDEX(Stakeholders!$B$2:$B$50,MATCH(INDEX(Flows!$D$2:$D$400,MATCH(ROWS($A$18:$A22),Flows!$Y$2:$Y$400,0)),Stakeholders!$A$2:$A$50,0)),"") -> Gimli | E22: =IFERROR(INDEX(Stakeholders!$B$2:$B$50,MATCH(INDEX(Flows!$E$2:$E$400,MATCH(ROWS($A$18:$A22),Flows!$Y$2:$Y$400,0)),Stakeholders!$A$2:$A$50,0)),"") -> Leia Organa | F22: =IFERROR(INDEX(Flows!$F$2:$F$400,MATCH(ROWS($A$18:$A22),Flows!$Y$2:$Y$400,0)),"") -> 3 | G22: =IFERROR(INDEX(Flows!$T$2:$T$400,MATCH(ROWS($A$18:$A22),Flows!$Y$2:$Y$400,0)),"") -> wrong_producer | H22: =IFERROR(INDEX(Flows!$U$2:$U$400,MATCH(ROWS($A$18:$A22),Flows!$Y$2:$Y$400,0)),"") -> 6 | I22: =IF($G22="","",IF($G22="missing","no carrier — create the flow",INDEX(Flows!$O$2:$O$400,MATCH(ROWS($A$18:$A22),Flows!$Y$2:$Y$400,0))&" carrier link(s) — see Flows")) -> 1 carrier link(s) — see Flows | J22: =IFERROR(INDEX(Flows!$K$2:$K$400,MATCH(ROWS($A$18:$A22),Flows!$Y$2:$Y$400,0)),"") -> QM needs inspection summary from the source for goal tracking
A23: =IF(ISNA(MATCH(ROWS($A$18:$A23),Flows!$Y$2:$Y$400,0)),"",ROWS($A$18:$A23)) -> 6 | B23: =IFERROR(INDEX(Flows!$L$2:$L$400,MATCH(ROWS($A$18:$A23),Flows!$Y$2:$Y$400,0)),"") -> G2 | C23: =IFERROR(INDEX(Topics!$B$2:$B$100,MATCH(INDEX(Flows!$C$2:$C$400,MATCH(ROWS($A$18:$A23),Flows!$Y$2:$Y$400,0)),Topics!$A$2:$A$100,0)),"") -> ncr_status | D23: =IFERROR(INDEX(Stakeholders!$B$2:$B$50,MATCH(INDEX(Flows!$D$2:$D$400,MATCH(ROWS($A$18:$A23),Flows!$Y$2:$Y$400,0)),Stakeholders!$A$2:$A$50,0)),"") -> Samwise Gamgee | E23: =IFERROR(INDEX(Stakeholders!$B$2:$B$50,MATCH(INDEX(Flows!$E$2:$E$400,MATCH(ROWS($A$18:$A23),Flows!$Y$2:$Y$400,0)),Stakeholders!$A$2:$A$50,0)),"") -> Han Solo | F23: =IFERROR(INDEX(Flows!$F$2:$F$400,MATCH(ROWS($A$18:$A23),Flows!$Y$2:$Y$400,0)),"") -> 3 | G23: =IFERROR(INDEX(Flows!$T$2:$T$400,MATCH(ROWS($A$18:$A23),Flows!$Y$2:$Y$400,0)),"") -> latency_gap | H23: =IFERROR(INDEX(Flows!$U$2:$U$400,MATCH(ROWS($A$18:$A23),Flows!$Y$2:$Y$400,0)),"") -> 6 | I23: =IF($G23="","",IF($G23="missing","no carrier — create the flow",INDEX(Flows!$O$2:$O$400,MATCH(ROWS($A$18:$A23),Flows!$Y$2:$Y$400,0))&" carrier link(s) — see Flows")) -> 1 carrier link(s) — see Flows | J23: =IFERROR(INDEX(Flows!$K$2:$K$400,MATCH(ROWS($A$18:$A23),Flows!$Y$2:$Y$400,0)),"") -> Procurement needs weekly NCR aging to pressure suppliers in-cycle
A24: =IF(ISNA(MATCH(ROWS($A$18:$A24),Flows!$Y$2:$Y$400,0)),"",ROWS($A$18:$A24)) -> 7 | B24: =IFERROR(INDEX(Flows!$L$2:$L$400,MATCH(ROWS($A$18:$A24),Flows!$Y$2:$Y$400,0)),"") -> G5 | C24: =IFERROR(INDEX(Topics!$B$2:$B$100,MATCH(INDEX(Flows!$C$2:$C$400,MATCH(ROWS($A$18:$A24),Flows!$Y$2:$Y$400,0)),Topics!$A$2:$A$100,0)),"") -> supplier_auditor_training_status | D24: =IFERROR(INDEX(Stakeholders!$B$2:$B$50,MATCH(INDEX(Flows!$D$2:$D$400,MATCH(ROWS($A$18:$A24),Flows!$Y$2:$Y$400,0)),Stakeholders!$A$2:$A$50,0)),"") -> Frodo Baggins | E24: =IFERROR(INDEX(Stakeholders!$B$2:$B$50,MATCH(INDEX(Flows!$E$2:$E$400,MATCH(ROWS($A$18:$A24),Flows!$Y$2:$Y$400,0)),Stakeholders!$A$2:$A$50,0)),"") -> The Fellowship | F24: =IFERROR(INDEX(Flows!$F$2:$F$400,MATCH(ROWS($A$18:$A24),Flows!$Y$2:$Y$400,0)),"") -> 2 | G24: =IFERROR(INDEX(Flows!$T$2:$T$400,MATCH(ROWS($A$18:$A24),Flows!$Y$2:$Y$400,0)),"") -> missing | H24: =IFERROR(INDEX(Flows!$U$2:$U$400,MATCH(ROWS($A$18:$A24),Flows!$Y$2:$Y$400,0)),"") -> 6 | I24: =IF($G24="","",IF($G24="missing","no carrier — create the flow",INDEX(Flows!$O$2:$O$400,MATCH(ROWS($A$18:$A24),Flows!$Y$2:$Y$400,0))&" carrier link(s) — see Flows")) -> no carrier — create the flow | J24: =IFERROR(INDEX(Flows!$K$2:$K$400,MATCH(ROWS($A$18:$A24),Flows!$Y$2:$Y$400,0)),"") -> Plant manager needs training progress for capacity planning
A25: =IF(ISNA(MATCH(ROWS($A$18:$A25),Flows!$Y$2:$Y$400,0)),"",ROWS($A$18:$A25)) | B25: =IFERROR(INDEX(Flows!$L$2:$L$400,MATCH(ROWS($A$18:$A25),Flows!$Y$2:$Y$400,0)),"") | C25: =IFERROR(INDEX(Topics!$B$2:$B$100,MATCH(INDEX(Flows!$C$2:$C$400,MATCH(ROWS($A$18:$A25),Flows!$Y$2:$Y$400,0)),Topics!$A$2:$A$100,0)),"") | D25: =IFERROR(INDEX(Stakeholders!$B$2:$B$50,MATCH(INDEX(Flows!$D$2:$D$400,MATCH(ROWS($A$18:$A25),Flows!$Y$2:$Y$400,0)),Stakeholders!$A$2:$A$50,0)),"") | E25: =IFERROR(INDEX(Stakeholders!$B$2:$B$50,MATCH(INDEX(Flows!$E$2:$E$400,MATCH(ROWS($A$18:$A25),Flows!$Y$2:$Y$400,0)),Stakeholders!$A$2:$A$50,0)),"") | F25: =IFERROR(INDEX(Flows!$F$2:$F$400,MATCH(ROWS($A$18:$A25),Flows!$Y$2:$Y$400,0)),"") | G25: =IFERROR(INDEX(Flows!$T$2:$T$400,MATCH(ROWS($A$18:$A25),Flows!$Y$2:$Y$400,0)),"") | H25: =IFERROR(INDEX(Flows!$U$2:$U$400,MATCH(ROWS($A$18:$A25),Flows!$Y$2:$Y$400,0)),"") | I25: =IF($G25="","",IF($G25="missing","no carrier — create the flow",INDEX(Flows!$O$2:$O$400,MATCH(ROWS($A$18:$A25),Flows!$Y$2:$Y$400,0))&" carrier link(s) — see Flows")) | J25: =IFERROR(INDEX(Flows!$K$2:$K$400,MATCH(ROWS($A$18:$A25),Flows!$Y$2:$Y$400,0)),"")
A27: ALIGNMENT THEATER — meetings claiming a goal they do nothing for → open
B28: goal | C28: meeting | D28: stakeholders present | F28: criteria score
B29: =IFERROR(INDEX(Alignment!$A$2:$A$50,MATCH(ROWS($A$29:$A29),Alignment!$L$2:$L$50,0)),"") -> G1 | C29: =IFERROR(INDEX(Alignment!$C$2:$C$50,MATCH(ROWS($A$29:$A29),Alignment!$L$2:$L$50,0)),"") -> Monthly Ops Status Meeting | D29: =IF($C29="","",INDEX(Alignment!$H$2:$H$50,MATCH(ROWS($A$29:$A29),Alignment!$L$2:$L$50,0))) -> 0.38 | F29: =IF($C29="","",INDEX(Alignment!$I$2:$I$50,MATCH(ROWS($A$29:$A29),Alignment!$L$2:$L$50,0))) -> 0.16666667
B30: =IFERROR(INDEX(Alignment!$A$2:$A$50,MATCH(ROWS($A$29:$A30),Alignment!$L$2:$L$50,0)),"") -> G3 | C30: =IFERROR(INDEX(Alignment!$C$2:$C$50,MATCH(ROWS($A$29:$A30),Alignment!$L$2:$L$50,0)),"") -> Monthly Ops Status Meeting | D30: =IF($C30="","",INDEX(Alignment!$H$2:$H$50,MATCH(ROWS($A$29:$A30),Alignment!$L$2:$L$50,0))) -> 0.67 | F30: =IF($C30="","",INDEX(Alignment!$I$2:$I$50,MATCH(ROWS($A$29:$A30),Alignment!$L$2:$L$50,0))) -> 0.16666667
B31: =IFERROR(INDEX(Alignment!$A$2:$A$50,MATCH(ROWS($A$29:$A31),Alignment!$L$2:$L$50,0)),"") | C31: =IFERROR(INDEX(Alignment!$C$2:$C$50,MATCH(ROWS($A$29:$A31),Alignment!$L$2:$L$50,0)),"") | D31: =IF($C31="","",INDEX(Alignment!$H$2:$H$50,MATCH(ROWS($A$29:$A31),Alignment!$L$2:$L$50,0))) | F31: =IF($C31="","",INDEX(Alignment!$I$2:$I$50,MATCH(ROWS($A$29:$A31),Alignment!$L$2:$L$50,0)))
B32: =IFERROR(INDEX(Alignment!$A$2:$A$50,MATCH(ROWS($A$29:$A32),Alignment!$L$2:$L$50,0)),"") | C32: =IFERROR(INDEX(Alignment!$C$2:$C$50,MATCH(ROWS($A$29:$A32),Alignment!$L$2:$L$50,0)),"") | D32: =IF($C32="","",INDEX(Alignment!$H$2:$H$50,MATCH(ROWS($A$29:$A32),Alignment!$L$2:$L$50,0))) | F32: =IF($C32="","",INDEX(Alignment!$I$2:$I$50,MATCH(ROWS($A$29:$A32),Alignment!$L$2:$L$50,0)))
A34: UNCLAIMED CONTRIBUTORS — real dependency, missing paperwork (update goal_ids) → open
B35: goal | C35: meeting | D35: contribution
B36: =IFERROR(INDEX(Alignment!$A$2:$A$50,MATCH(ROWS($A$36:$A36),Alignment!$M$2:$M$50,0)),"") -> G2 | C36: =IFERROR(INDEX(Alignment!$C$2:$C$50,MATCH(ROWS($A$36:$A36),Alignment!$M$2:$M$50,0)),"") -> Monthly Supplier Business Review | D36: =IF($C36="","","carries "&INDEX(Alignment!$E$2:$E$50,MATCH(ROWS($A$36:$A36),Alignment!$M$2:$M$50,0))&" flow(s)") -> carries 1 flow(s)
B37: =IFERROR(INDEX(Alignment!$A$2:$A$50,MATCH(ROWS($A$36:$A37),Alignment!$M$2:$M$50,0)),"") | C37: =IFERROR(INDEX(Alignment!$C$2:$C$50,MATCH(ROWS($A$36:$A37),Alignment!$M$2:$M$50,0)),"") | D37: =IF($C37="","","carries "&INDEX(Alignment!$E$2:$E$50,MATCH(ROWS($A$36:$A37),Alignment!$M$2:$M$50,0))&" flow(s)")
B38: =IFERROR(INDEX(Alignment!$A$2:$A$50,MATCH(ROWS($A$36:$A38),Alignment!$M$2:$M$50,0)),"") | C38: =IFERROR(INDEX(Alignment!$C$2:$C$50,MATCH(ROWS($A$36:$A38),Alignment!$M$2:$M$50,0)),"") | D38: =IF($C38="","","carries "&INDEX(Alignment!$E$2:$E$50,MATCH(ROWS($A$36:$A38),Alignment!$M$2:$M$50,0))&" flow(s)")
A39: DECISION DEFECTS — rights on paper vs where deciding actually happens → open
B40: goal | C40: decision | D40: defect | E40: owner | G40: actual venue
B41: =IFERROR(INDEX(Decisions!$D$2:$D$50,MATCH(ROWS($A$41:$A41),Decisions!$M$2:$M$50,0)),"") -> G1 | C41: =IFERROR(INDEX(Decisions!$B$2:$B$50,MATCH(ROWS($A$41:$A41),Decisions!$M$2:$M$50,0)),"") -> Supplier disqualification / new-business hold | D41: =IFERROR(INDEX(Decisions!$L$2:$L$50,MATCH(ROWS($A$41:$A41),Decisions!$M$2:$M$50,0)),"") -> a_absent | E41: =IF($C41="","",IFERROR(INDEX(Stakeholders!$B$2:$B$50,MATCH(INDEX(Decisions!$E$2:$E$50,MATCH(ROWS($A$41:$A41),Decisions!$M$2:$M$50,0)),Stakeholders!$A$2:$A$50,0)),"— none —")) -> Han Solo | G41: =IF($C41="","",IF(INDEX(Decisions!$I$2:$I$50,MATCH(ROWS($A$41:$A41),Decisions!$M$2:$M$50,0))="ritual",IFERROR(INDEX(Rituals!$B$2:$B$50,MATCH(INDEX(Decisions!$J$2:$J$50,MATCH(ROWS($A$41:$A41),Decisions!$M$2:$M$50,0)),Rituals!$A$2:$A$50,0)),""),INDEX(Decisions!$I$2:$I$50,MATCH(ROWS($A$41:$A41),Decisions!$M$2:$M$50,0)))) -> Weekly Supplier Quality Review
B42: =IFERROR(INDEX(Decisions!$D$2:$D$50,MATCH(ROWS($A$41:$A42),Decisions!$M$2:$M$50,0)),"") -> G2 | C42: =IFERROR(INDEX(Decisions!$B$2:$B$50,MATCH(ROWS($A$41:$A42),Decisions!$M$2:$M$50,0)),"") -> CAPA closure acceptance | D42: =IFERROR(INDEX(Decisions!$L$2:$L$50,MATCH(ROWS($A$41:$A42),Decisions!$M$2:$M$50,0)),"") -> none_observed | E42: =IF($C42="","",IFERROR(INDEX(Stakeholders!$B$2:$B$50,MATCH(INDEX(Decisions!$E$2:$E$50,MATCH(ROWS($A$41:$A42),Decisions!$M$2:$M$50,0)),Stakeholders!$A$2:$A$50,0)),"— none —")) -> Frodo Baggins | G42: =IF($C42="","",IF(INDEX(Decisions!$I$2:$I$50,MATCH(ROWS($A$41:$A42),Decisions!$M$2:$M$50,0))="ritual",IFERROR(INDEX(Rituals!$B$2:$B$50,MATCH(INDEX(Decisions!$J$2:$J$50,MATCH(ROWS($A$41:$A42),Decisions!$M$2:$M$50,0)),Rituals!$A$2:$A$50,0)),""),INDEX(Decisions!$I$2:$I$50,MATCH(ROWS($A$41:$A42),Decisions!$M$2:$M$50,0)))) -> none_observed
B43: =IFERROR(INDEX(Decisions!$D$2:$D$50,MATCH(ROWS($A$41:$A43),Decisions!$M$2:$M$50,0)),"") -> G3 | C43: =IFERROR(INDEX(Decisions!$B$2:$B$50,MATCH(ROWS($A$41:$A43),Decisions!$M$2:$M$50,0)),"") -> Second-source qualification go/no-go | D43: =IFERROR(INDEX(Decisions!$L$2:$L$50,MATCH(ROWS($A$41:$A43),Decisions!$M$2:$M$50,0)),"") -> no_accountable | E43: =IF($C43="","",IFERROR(INDEX(Stakeholders!$B$2:$B$50,MATCH(INDEX(Decisions!$E$2:$E$50,MATCH(ROWS($A$41:$A43),Decisions!$M$2:$M$50,0)),Stakeholders!$A$2:$A$50,0)),"— none —")) -> — none — | G43: =IF($C43="","",IF(INDEX(Decisions!$I$2:$I$50,MATCH(ROWS($A$41:$A43),Decisions!$M$2:$M$50,0))="ritual",IFERROR(INDEX(Rituals!$B$2:$B$50,MATCH(INDEX(Decisions!$J$2:$J$50,MATCH(ROWS($A$41:$A43),Decisions!$M$2:$M$50,0)),Rituals!$A$2:$A$50,0)),""),INDEX(Decisions!$I$2:$I$50,MATCH(ROWS($A$41:$A43),Decisions!$M$2:$M$50,0)))) -> Monthly Supplier Business Review
B44: =IFERROR(INDEX(Decisions!$D$2:$D$50,MATCH(ROWS($A$41:$A44),Decisions!$M$2:$M$50,0)),"") | C44: =IFERROR(INDEX(Decisions!$B$2:$B$50,MATCH(ROWS($A$41:$A44),Decisions!$M$2:$M$50,0)),"") | D44: =IFERROR(INDEX(Decisions!$L$2:$L$50,MATCH(ROWS($A$41:$A44),Decisions!$M$2:$M$50,0)),"") | E44: =IF($C44="","",IFERROR(INDEX(Stakeholders!$B$2:$B$50,MATCH(INDEX(Decisions!$E$2:$E$50,MATCH(ROWS($A$41:$A44),Decisions!$M$2:$M$50,0)),Stakeholders!$A$2:$A$50,0)),"— none —")) | G44: =IF($C44="","",IF(INDEX(Decisions!$I$2:$I$50,MATCH(ROWS($A$41:$A44),Decisions!$M$2:$M$50,0))="ritual",IFERROR(INDEX(Rituals!$B$2:$B$50,MATCH(INDEX(Decisions!$J$2:$J$50,MATCH(ROWS($A$41:$A44),Decisions!$M$2:$M$50,0)),Rituals!$A$2:$A$50,0)),""),INDEX(Decisions!$I$2:$I$50,MATCH(ROWS($A$41:$A44),Decisions!$M$2:$M$50,0))))
A46: SINGLE-CARRIER RISKS — critical flows with one source and no system of record → open
...

Sheet WhiteSpace
A1: White-space matrix — required flows between functions (Rummler & Brache view)
A3: from \ to | B3: Engineering | C3: Quality | D3: Operations | E3: Supply Chain | F3: External
A4: Engineering | B4: =IF(COUNTIFS(Flows!$B$2:$B$400,"required",Flows!$W$2:$W$400,$A4,Flows!$X$2:$X$400,B$3)=0,"—",TEXT(COUNTIFS(Flows!$B$2:$B$400,"required",Flows!$W$2:$W$400,$A4,Flows!$X$2:$X$400,B$3),"0")&" req · "&TEXT(COUNTIFS(Flows!$B$2:$B$400,"required",Flows!$W$2:$W$400,$A4,Flows!$X$2:$X$400,B$3,Flows!$T$2:$T$400,"covered"),"0")&" ok"&IF(COUNTIFS(Flows!$B$2:$B$400,"required",Flows!$W$2:$W$400,$A4,Flows!$X$2:$X$400,B$3)-COUNTIFS(Flows!$B$2:$B$400,"required",Flows!$W$2:$W$400,$A4,Flows!$X$2:$X$400,B$3,Flows!$T$2:$T$400,"covered")>0," · "&TEXT(COUNTIFS(Flows!$B$2:$B$400,"required",Flows!$W$2:$W$400,$A4,Flows!$X$2:$X$400,B$3)-COUNTIFS(Flows!$B$2:$B$400,"required",Flows!$W$2:$W$400,$A4,Flows!$X$2:$X$400,B$3,Flows!$T$2:$T$400,"covered"),"0")&" DEFECT","")) -> — | C4: =IF(COUNTIFS(Flows!$B$2:$B$400,"required",Flows!$W$2:$W$400,$A4,Flows!$X$2:$X$400,C$3)=0,"—",TEXT(COUNTIFS(Flows!$B$2:$B$400,"required",Flows!$W$2:$W$400,$A4,Flows!$X$2:$X$400,C$3),"0")&" req · "&TEXT(COUNTIFS(Flows!$B$2:$B$400,"required",Flows!$W$2:$W$400,$A4,Flows!$X$2:$X$400,C$3,Flows!$T$2:$T$400,"covered"),"0")&" ok"&IF(COUNTIFS(Flows!$B$2:$B$400,"required",Flows!$W$2:$W$400,$A4,Flows!$X$2:$X$400,C$3)-COUNTIFS(Flows!$B$2:$B$400,"required",Flows!$W$2:$W$400,$A4,Flows!$X$2:$X$400,C$3,Flows!$T$2:$T$400,"covered")>0," · "&TEXT(COUNTIFS(Flows!$B$2:$B$400,"required",Flows!$W$2:$W$400,$A4,Flows!$X$2:$X$400,C$3)-COUNTIFS(Flows!$B$2:$B$400,"required",Flows!$W$2:$W$400,$A4,Flows!$X$2:$X$400,C$3,Flows!$T$2:$T$400,"covered"),"0")&" DEFECT","")) -> 1 req · 0 ok · 1 DEFECT | D4: =IF(COUNTIFS(Flows!$B$2:$B$400,"required",Flows!$W$2:$W$400,$A4,Flows!$X$2:$X$400,D$3)=0,"—",TEXT(COUNTIFS(Flows!$B$2:$B$400,"required",Flows!$W$2:$W$400,$A4,Flows!$X$2:$X$400,D$3),"0")&" req · "&TEXT(COUNTIFS(Flows!$B$2:$B$400,"required",Flows!$W$2:$W$400,$A4,Flows!$X$2:$X$400,D$3,Flows!$T$2:$T$400,"covered"),"0")&" ok"&IF(COUNTIFS(Flows!$B$2:$B$400,"required",Flows!$W$2:$W$400,$A4,Flows!$X$2:$X$400,D$3)-COUNTIFS(Flows!$B$2:$B$400,"required",Flows!$W$2:$W$400,$A4,Flows!$X$2:$X$400,D$3,Flows!$T$2:$T$400,"covered")>0," · "&TEXT(COUNTIFS(Flows!$B$2:$B$400,"required",Flows!$W$2:$W$400,$A4,Flows!$X$2:$X$400,D$3)-COUNTIFS(Flows!$B$2:$B$400,"required",Flows!$W$2:$W$400,$A4,Flows!$X$2:$X$400,D$3,Flows!$T$2:$T$400,"covered"),"0")&" DEFECT","")) -> — | E4: =IF(COUNTIFS(Flows!$B$2:$B$400,"required",Flows!$W$2:$W$400,$A4,Flows!$X$2:$X$400,E$3)=0,"—",TEXT(COUNTIFS(Flows!$B$2:$B$400,"required",Flows!$W$2:$W$400,$A4,Flows!$X$2:$X$400,E$3),"0")&" req · "&TEXT(COUNTIFS(Flows!$B$2:$B$400,"required",Flows!$W$2:$W$400,$A4,Flows!$X$2:$X$400,E$3,Flows!$T$2:$T$400,"covered"),"0")&" ok"&IF(COUNTIFS(Flows!$B$2:$B$400,"required",Flows!$W$2:$W$400,$A4,Flows!$X$2:$X$400,E$3)-COUNTIFS(Flows!$B$2:$B$400,"required",Flows!$W$2:$W$400,$A4,Flows!$X$2:$X$400,E$3,Flows!$T$2:$T$400,"covered")>0," · "&TEXT(COUNTIFS(Flows!$B$2:$B$400,"required",Flows!$W$2:$W$400,$A4,Flows!$X$2:$X$400,E$3)-COUNTIFS(Flows!$B$2:$B$400,"required",Flows!$W$2:$W$400,$A4,Flows!$X$2:$X$400,E$3,Flows!$T$2:$T$400,"covered"),"0")&" DEFECT","")) -> — | F4: =IF(COUNTIFS(Flows!$B$2:$B$400,"required",Flows!$W$2:$W$400,$A4,Flows!$X$2:$X$400,F$3)=0,"—",TEXT(COUNTIFS(Flows!$B$2:$B$400,"required",Flows!$W$2:$W$400,$A4,Flows!$X$2:$X$400,F$3),"0")&" req · "&TEXT(COUNTIFS(Flows!$B$2:$B$400,"required",Flows!$W$2:$W$400,$A4,Flows!$X$2:$X$400,F$3,Flows!$T$2:$T$400,"covered"),"0")&" ok"&IF(COUNTIFS(Flows!$B$2:$B$400,"required",Flows!$W$2:$W$400,$A4,Flows!$X$2:$X$400,F$3)-COUNTIFS(Flows!$B$2:$B$400,"required",Flows!$W$2:$W$400,$A4,Flows!$X$2:$X$400,F$3,Flows!$T$2:$T$400,"covered")>0," · "&TEXT(COUNTIFS(Flows!$B$2:$B$400,"required",Flows!$W$2:$W$400,$A4,Flows!$X$2:$X$400,F$3)-COUNTIFS(Flows!$B$2:$B$400,"required",Flows!$W$2:$W$400,$A4,Flows!$X$2:$X$400,F$3,Flows!$T$2:$T$400,"covered"),"0")&" DEFECT","")) -> —
A5: Quality | B5: =IF(COUNTIFS(Flows!$B$2:$B$400,"required",Flows!$W$2:$W$400,$A5,Flows!$X$2:$X$400,B$3)=0,"—",TEXT(COUNTIFS(Flows!$B$2:$B$400,"required",Flows!$W$2:$W$400,$A5,Flows!$X$2:$X$400,B$3),"0")&" req · "&TEXT(COUNTIFS(Flows!$B$2:$B$400,"required",Flows!$W$2:$W$400,$A5,Flows!$X$2:$X$400,B$3,Flows!$T$2:$T$400,"covered"),"0")&" ok"&IF(COUNTIFS(Flows!$B$2:$B$400,"required",Flows!$W$2:$W$400,$A5,Flows!$X$2:$X$400,B$3)-COUNTIFS(Flows!$B$2:$B$400,"required",Flows!$W$2:$W$400,$A5,Flows!$X$2:$X$400,B$3,Flows!$T$2:$T$400,"covered")>0," · "&TEXT(COUNTIFS(Flows!$B$2:$B$400,"required",Flows!$W$2:$W$400,$A5,Flows!$X$2:$X$400,B$3)-COUNTIFS(Flows!$B$2:$B$400,"required",Flows!$W$2:$W$400,$A5,Flows!$X$2:$X$400,B$3,Flows!$T$2:$T$400,"covered"),"0")&" DEFECT","")) -> — | C5: =IF(COUNTIFS(Flows!$B$2:$B$400,"required",Flows!$W$2:$W$400,$A5,Flows!$X$2:$X$400,C$3)=0,"—",TEXT(COUNTIFS(Flows!$B$2:$B$400,"required",Flows!$W$2:$W$400,$A5,Flows!$X$2:$X$400,C$3),"0")&" req · "&TEXT(COUNTIFS(Flows!$B$2:$B$400,"required",Flows!$W$2:$W$400,$A5,Flows!$X$2:$X$400,C$3,Flows!$T$2:$T$400,"covered"),"0")&" ok"&IF(COUNTIFS(Flows!$B$2:$B$400,"required",Flows!$W$2:$W$400,$A5,Flows!$X$2:$X$400,C$3)-COUNTIFS(Flows!$B$2:$B$400,"required",Flows!$W$2:$W$400,$A5,Flows!$X$2:$X$400,C$3,Flows!$T$2:$T$400,"covered")>0," · "&TEXT(COUNTIFS(Flows!$B$2:$B$400,"required",Flows!$W$2:$W$400,$A5,Flows!$X$2:$X$400,C$3)-COUNTIFS(Flows!$B$2:$B$400,"required",Flows!$W$2:$W$400,$A5,Flows!$X$2:$X$400,C$3,Flows!$T$2:$T$400,"covered"),"0")&" DEFECT","")) -> 6 req · 4 ok · 2 DEFECT | D5: =IF(COUNTIFS(Flows!$B$2:$B$400,"required",Flows!$W$2:$W$400,$A5,Flows!$X$2:$X$400,D$3)=0,"—",TEXT(COUNTIFS(Flows!$B$2:$B$400,"required",Flows!$W$2:$W$400,$A5,Flows!$X$2:$X$400,D$3),"0")&" req · "&TEXT(COUNTIFS(Flows!$B$2:$B$400,"required",Flows!$W$2:$W$400,$A5,Flows!$X$2:$X$400,D$3,Flows!$T$2:$T$400,"covered"),"0")&" ok"&IF(COUNTIFS(Flows!$B$2:$B$400,"required",Flows!$W$2:$W$400,$A5,Flows!$X$2:$X$400,D$3)-COUNTIFS(Flows!$B$2:$B$400,"required",Flows!$W$2:$W$400,$A5,Flows!$X$2:$X$400,D$3,Flows!$T$2:$T$400,"covered")>0," · "&TEXT(COUNTIFS(Flows!$B$2:$B$400,"required",Flows!$W$2:$W$400,$A5,Flows!$X$2:$X$400,D$3)-COUNTIFS(Flows!$B$2:$B$400,"required",Flows!$W$2:$W$400,$A5,Flows!$X$2:$X$400,D$3,Flows!$T$2:$T$400,"covered"),"0")&" DEFECT","")) -> 3 req · 0 ok · 3 DEFECT | E5: =IF(COUNTIFS(Flows!$B$2:$B$400,"required",Flows!$W$2:$W$400,$A5,Flows!$X$2:$X$400,E$3)=0,"—",TEXT(COUNTIFS(Flows!$B$2:$B$400,"required",Flows!$W$2:$W$400,$A5,Flows!$X$2:$X$400,E$3),"0")&" req · "&TEXT(COUNTIFS(Flows!$B$2:$B$400,"required",Flows!$W$2:$W$400,$A5,Flows!$X$2:$X$400,E$3,Flows!$T$2:$T$400,"covered"),"0")&" ok"&IF(COUNTIFS(Flows!$B$2:$B$400,"required",Flows!$W$2:$W$400,$A5,Flows!$X$2:$X$400,E$3)-COUNTIFS(Flows!$B$2:$B$400,"required",Flows!$W$2:$W$400,$A5,Flows!$X$2:$X$400,E$3,Flows!$T$2:$T$400,"covered")>0," · "&TEXT(COUNTIFS(Flows!$B$2:$B$400,"required",Flows!$W$2:$W$400,$A5,Flows!$X$2:$X$400,E$3)-COUNTIFS(Flows!$B$2:$B$400,"required",Flows!$W$2:$W$400,$A5,Flows!$X$2:$X$400,E$3,Flows!$T$2:$T$400,"covered"),"0")&" DEFECT","")) -> 3 req · 2 ok · 1 DEFECT | F5: =IF(COUNTIFS(Flows!$B$2:$B$400,"required",Flows!$W$2:$W$400,$A5,Flows!$X$2:$X$400,F$3)=0,"—",TEXT(COUNTIFS(Flows!$B$2:$B$400,"required",Flows!$W$2:$W$400,$A5,Flows!$X$2:$X$400,F$3),"0")&" req · "&TEXT(COUNTIFS(Flows!$B$2:$B$400,"required",Flows!$W$2:$W$400,$A5,Flows!$X$2:$X$400,F$3,Flows!$T$2:$T$400,"covered"),"0")&" ok"&IF(COUNTIFS(Flows!$B$2:$B$400,"required",Flows!$W$2:$W$400,$A5,Flows!$X$2:$X$400,F$3)-COUNTIFS(Flows!$B$2:$B$400,"required",Flows!$W$2:$W$400,$A5,Flows!$X$2:$X$400,F$3,Flows!$T$2:$T$400,"covered")>0," · "&TEXT(COUNTIFS(Flows!$B$2:$B$400,"required",Flows!$W$2:$W$400,$A5,Flows!$X$2:$X$400,F$3)-COUNTIFS(Flows!$B$2:$B$400,"required",Flows!$W$2:$W$400,$A5,Flows!$X$2:$X$400,F$3,Flows!$T$2:$T$400,"covered"),"0")&" DEFECT","")) -> 1 req · 1 ok
A6: Operations | B6: =IF(COUNTIFS(Flows!$B$2:$B$400,"required",Flows!$W$2:$W$400,$A6,Flows!$X$2:$X$400,B$3)=0,"—",TEXT(COUNTIFS(Flows!$B$2:$B$400,"required",Flows!$W$2:$W$400,$A6,Flows!$X$2:$X$400,B$3),"0")&" req · "&TEXT(COUNTIFS(Flows!$B$2:$B$400,"required",Flows!$W$2:$W$400,$A6,Flows!$X$2:$X$400,B$3,Flows!$T$2:$T$400,"covered"),"0")&" ok"&IF(COUNTIFS(Flows!$B$2:$B$400,"required",Flows!$W$2:$W$400,$A6,Flows!$X$2:$X$400,B$3)-COUNTIFS(Flows!$B$2:$B$400,"required",Flows!$W$2:$W$400,$A6,Flows!$X$2:$X$400,B$3,Flows!$T$2:$T$400,"covered")>0," · "&TEXT(COUNTIFS(Flows!$B$2:$B$400,"required",Flows!$W$2:$W$400,$A6,Flows!$X$2:$X$400,B$3)-COUNTIFS(Flows!$B$2:$B$400,"required",Flows!$W$2:$W$400,$A6,Flows!$X$2:$X$400,B$3,Flows!$T$2:$T$400,"covered"),"0")&" DEFECT","")) -> — | C6: =IF(COUNTIFS(Flows!$B$2:$B$400,"required",Flows!$W$2:$W$400,$A6,Flows!$X$2:$X$400,C$3)=0,"—",TEXT(COUNTIFS(Flows!$B$2:$B$400,"required",Flows!$W$2:$W$400,$A6,Flows!$X$2:$X$400,C$3),"0")&" req · "&TEXT(COUNTIFS(Flows!$B$2:$B$400,"required",Flows!$W$2:$W$400,$A6,Flows!$X$2:$X$400,C$3,Flows!$T$2:$T$400,"covered"),"0")&" ok"&IF(COUNTIFS(Flows!$B$2:$B$400,"required",Flows!$W$2:$W$400,$A6,Flows!$X$2:$X$400,C$3)-COUNTIFS(Flows!$B$2:$B$400,"required",Flows!$W$2:$W$400,$A6,Flows!$X$2:$X$400,C$3,Flows!$T$2:$T$400,"covered")>0," · "&TEXT(COUNTIFS(Flows!$B$2:$B$400,"required",Flows!$W$2:$W$400,$A6,Flows!$X$2:$X$400,C$3)-COUNTIFS(Flows!$B$2:$B$400,"required",Flows!$W$2:$W$400,$A6,Flows!$X$2:$X$400,C$3,Flows!$T$2:$T$400,"covered"),"0")&" DEFECT","")) -> 1 req · 1 ok | D6: =IF(COUNTIFS(Flows!$B$2:$B$400,"required",Flows!$W$2:$W$400,$A6,Flows!$X$2:$X$400,D$3)=0,"—",TEXT(COUNTIFS(Flows!$B$2:$B$400,"required",Flows!$W$2:$W$400,$A6,Flows!$X$2:$X$400,D$3),"0")&" req · "&TEXT(COUNTIFS(Flows!$B$2:$B$400,"required",Flows!$W$2:$W$400,$A6,Flows!$X$2:$X$400,D$3,Flows!$T$2:$T$400,"covered"),"0")&" ok"&IF(COUNTIFS(Flows!$B$2:$B$400,"required",Flows!$W$2:$W$400,$A6,Flows!$X$2:$X$400,D$3)-COUNTIFS(Flows!$B$2:$B$400,"required",Flows!$W$2:$W$400,$A6,Flows!$X$2:$X$400,D$3,Flows!$T$2:$T$400,"covered")>0," · "&TEXT(COUNTIFS(Flows!$B$2:$B$400,"required",Flows!$W$2:$W$400,$A6,Flows!$X$2:$X$400,D$3)-COUNTIFS(Flows!$B$2:$B$400,"required",Flows!$W$2:$W$400,$A6,Flows!$X$2:$X$400,D$3,Flows!$T$2:$T$400,"covered"),"0")&" DEFECT","")) -> — | E6: =IF(COUNTIFS(Flows!$B$2:$B$400,"required",Flows!$W$2:$W$400,$A6,Flows!$X$2:$X$400,E$3)=0,"—",TEXT(COUNTIFS(Flows!$B$2:$B$400,"required",Flows!$W$2:$W$400,$A6,Flows!$X$2:$X$400,E$3),"0")&" req · "&TEXT(COUNTIFS(Flows!$B$2:$B$400,"required",Flows!$W$2:$W$400,$A6,Flows!$X$2:$X$400,E$3,Flows!$T$2:$T$400,"covered"),"0")&" ok"&IF(COUNTIFS(Flows!$B$2:$B$400,"required",Flows!$W$2:$W$400,$A6,Flows!$X$2:$X$400,E$3)-COUNTIFS(Flows!$B$2:$B$400,"required",Flows!$W$2:$W$400,$A6,Flows!$X$2:$X$400,E$3,Flows!$T$2:$T$400,"covered")>0," · "&TEXT(COUNTIFS(Flows!$B$2:$B$400,"required",Flows!$W$2:$W$400,$A6,Flows!$X$2:$X$400,E$3)-COUNTIFS(Flows!$B$2:$B$400,"required",Flows!$W$2:$W$400,$A6,Flows!$X$2:$X$400,E$3,Flows!$T$2:$T$400,"covered"),"0")&" DEFECT","")) -> — | F6: =IF(COUNTIFS(Flows!$B$2:$B$400,"required",Flows!$W$2:$W$400,$A6,Flows!$X$2:$X$400,F$3)=0,"—",TEXT(COUNTIFS(Flows!$B$2:$B$400,"required",Flows!$W$2:$W$400,$A6,Flows!$X$2:$X$400,F$3),"0")&" req · "&TEXT(COUNTIFS(Flows!$B$2:$B$400,"required",Flows!$W$2:$W$400,$A6,Flows!$X$2:$X$400,F$3,Flows!$T$2:$T$400,"covered"),"0")&" ok"&IF(COUNTIFS(Flows!$B$2:$B$400,"required",Flows!$W$2:$W$400,$A6,Flows!$X$2:$X$400,F$3)-COUNTIFS(Flows!$B$2:$B$400,"required",Flows!$W$2:$W$400,$A6,Flows!$X$2:$X$400,F$3,Flows!$T$2:$T$400,"covered")>0," · "&TEXT(COUNTIFS(Flows!$B$2:$B$400,"required",Flows!$W$2:$W$400,$A6,Flows!$X$2:$X$400,F$3)-COUNTIFS(Flows!$B$2:$B$400,"required",Flows!$W$2:$W$400,$A6,Flows!$X$2:$X$400,F$3,Flows!$T$2:$T$400,"covered"),"0")&" DEFECT","")) -> —
A7: Supply Chain | B7: =IF(COUNTIFS(Flows!$B$2:$B$400,"required",Flows!$W$2:$W$400,$A7,Flows!$X$2:$X$400,B$3)=0,"—",TEXT(COUNTIFS(Flows!$B$2:$B$400,"required",Flows!$W$2:$W$400,$A7,Flows!$X$2:$X$400,B$3),"0")&" req · "&TEXT(COUNTIFS(Flows!$B$2:$B$400,"required",Flows!$W$2:$W$400,$A7,Flows!$X$2:$X$400,B$3,Flows!$T$2:$T$400,"covered"),"0")&" ok"&IF(COUNTIFS(Flows!$B$2:$B$400,"required",Flows!$W$2:$W$400,$A7,Flows!$X$2:$X$400,B$3)-COUNTIFS(Flows!$B$2:$B$400,"required",Flows!$W$2:$W$400,$A7,Flows!$X$2:$X$400,B$3,Flows!$T$2:$T$400,"covered")>0," · "&TEXT(COUNTIFS(Flows!$B$2:$B$400,"required",Flows!$W$2:$W$400,$A7,Flows!$X$2:$X$400,B$3)-COUNTIFS(Flows!$B$2:$B$400,"required",Flows!$W$2:$W$400,$A7,Flows!$X$2:$X$400,B$3,Flows!$T$2:$T$400,"covered"),"0")&" DEFECT","")) -> — | C7: =IF(COUNTIFS(Flows!$B$2:$B$400,"required",Flows!$W$2:$W$400,$A7,Flows!$X$2:$X$400,C$3)=0,"—",TEXT(COUNTIFS(Flows!$B$2:$B$400,"required",Flows!$W$2:$W$400,$A7,Flows!$X$2:$X$400,C$3),"0")&" req · "&TEXT(COUNTIFS(Flows!$B$2:$B$400,"required",Flows!$W$2:$W$400,$A7,Flows!$X$2:$X$400,C$3,Flows!$T$2:$T$400,"covered"),"0")&" ok"&IF(COUNTIFS(Flows!$B$2:$B$400,"required",Flows!$W$2:$W$400,$A7,Flows!$X$2:$X$400,C$3)-COUNTIFS(Flows!$B$2:$B$400,"required",Flows!$W$2:$W$400,$A7,Flows!$X$2:$X$400,C$3,Flows!$T$2:$T$400,"covered")>0," · "&TEXT(COUNTIFS(Flows!$B$2:$B$400,"required",Flows!$W$2:$W$400,$A7,Flows!$X$2:$X$400,C$3)-COUNTIFS(Flows!$B$2:$B$400,"required",Flows!$W$2:$W$400,$A7,Flows!$X$2:$X$400,C$3,Flows!$T$2:$T$400,"covered"),"0")&" DEFECT","")) -> — | D7: =IF(COUNTIFS(Flows!$B$2:$B$400,"required",Flows!$W$2:$W$400,$A7,Flows!$X$2:$X$400,D$3)=0,"—",TEXT(COUNTIFS(Flows!$B$2:$B$400,"required",Flows!$W$2:$W$400,$A7,Flows!$X$2:$X$400,D$3),"0")&" req · "&TEXT(COUNTIFS(Flows!$B$2:$B$400,"required",Flows!$W$2:$W$400,$A7,Flows!$X$2:$X$400,D$3,Flows!$T$2:$T$400,"covered"),"0")&" ok"&IF(COUNTIFS(Flows!$B$2:$B$400,"required",Flows!$W$2:$W$400,$A7,Flows!$X$2:$X$400,D$3)-COUNTIFS(Flows!$B$2:$B$400,"required",Flows!$W$2:$W$400,$A7,Flows!$X$2:$X$400,D$3,Flows!$T$2:$T$400,"covered")>0," · "&TEXT(COUNTIFS(Flows!$B$2:$B$400,"required",Flows!$W$2:$W$400,$A7,Flows!$X$2:$X$400,D$3)-COUNTIFS(Flows!$B$2:$B$400,"required",Flows!$W$2:$W$400,$A7,Flows!$X$2:$X$400,D$3,Flows!$T$2:$T$400,"covered"),"0")&" DEFECT","")) -> 1 req · 1 ok | E7: =IF(COUNTIFS(Flows!$B$2:$B$400,"required",Flows!$W$2:$W$400,$A7,Flows!$X$2:$X$400,E$3)=0,"—",TEXT(COUNTIFS(Flows!$B$2:$B$400,"required",Flows!$W$2:$W$400,$A7,Flows!$X$2:$X$400,E$3),"0")&" req · "&TEXT(COUNTIFS(Flows!$B$2:$B$400,"required",Flows!$W$2:$W$400,$A7,Flows!$X$2:$X$400,E$3,Flows!$T$2:$T$400,"covered"),"0")&" ok"&IF(COUNTIFS(Flows!$B$2:$B$400,"required",Flows!$W$2:$W$400,$A7,Flows!$X$2:$X$400,E$3)-COUNTIFS(Flows!$B$2:$B$400,"required",Flows!$W$2:$W$400,$A7,Flows!$X$2:$X$400,E$3,Flows!$T$2:$T$400,"covered")>0," · "&TEXT(COUNTIFS(Flows!$B$2:$B$400,"required",Flows!$W$2:$W$400,$A7,Flows!$X$2:$X$400,E$3)-COUNTIFS(Flows!$B$2:$B$400,"required",Flows!$W$2:$W$400,$A7,Flows!$X$2:$X$400,E$3,Flows!$T$2:$T$400,"covered"),"0")&" DEFECT","")) -> — | F7: =IF(COUNTIFS(Flows!$B$2:$B$400,"required",Flows!$W$2:$W$400,$A7,Flows!$X$2:$X$400,F$3)=0,"—",TEXT(COUNTIFS(Flows!$B$2:$B$400,"required",Flows!$W$2:$W$400,$A7,Flows!$X$2:$X$400,F$3),"0")&" req · "&TEXT(COUNTIFS(Flows!$B$2:$B$400,"required",Flows!$W$2:$W$400,$A7,Flows!$X$2:$X$400,F$3,Flows!$T$2:$T$400,"covered"),"0")&" ok"&IF(COUNTIFS(Flows!$B$2:$B$400,"required",Flows!$W$2:$W$400,$A7,Flows!$X$2:$X$400,F$3)-COUNTIFS(Flows!$B$2:$B$400,"required",Flows!$W$2:$W$400,$A7,Flows!$X$2:$X$400,F$3,Flows!$T$2:$T$400,"covered")>0," · "&TEXT(COUNTIFS(Flows!$B$2:$B$400,"required",Flows!$W$2:$W$400,$A7,Flows!$X$2:$X$400,F$3)-COUNTIFS(Flows!$B$2:$B$400,"required",Flows!$W$2:$W$400,$A7,Flows!$X$2:$X$400,F$3,Flows!$T$2:$T$400,"covered"),"0")&" DEFECT","")) -> —
