Workbook

Sheet GUIDE
B1: PART-SUPPLIER RISK MODEL
B2: One simple tool: decompose each model into its parts (tissue and non-tissue), link every part to its supplier, and score the risk of each part-supplier combination.
B5: HOW TO USE (4 steps)
B6: 1. MODELS - add the model / project (one row). A model may have tissue parts, non-tissue parts, or both.
B7: 2. SUPPLIERS - add the supplier and give it its two 1-5 scores (Supplier Stability, External & Location). You do this once per supplier.
B8: 3. PART_RISK - one row per part-supplier combo: pick the model, type the part, pick the type and supplier, score the three part criteria (1-5), score Impact (1-5), and set a Red Flag only if one applies. Likelihood, Risk and Band calculate automatically.
B9: 4. DASHBOARD - select a model to see its decomposition ranked by risk; review the Top 10 across all models; write mitigations back into the Notes column of PART_RISK.
B11: HOW THE SCORE WORKS
B12: Likelihood (1-5) = weighted average of: Sourcing & Backup 25%, Quality & Compliance 25%, Capacity & Delivery 20%, Supplier Stability 20%, External & Location 10%.
B13: Risk (1-25) = Likelihood x Impact. Bands: >= 15 CRITICAL (act now) | 7 - 14.9 MONITOR (watch + contingency) | < 7 LOW (routine).
B14: A Red Flag forces CRITICAL regardless of the numbers (e.g. APHIS/permit lapse on a tissue part, EOL on a COTS part). Full anchors and definitions: SCORING_GUIDE sheet.
B16: LEGEND
... B22: Score new part-supplier combos at sourcing time; re-score CRITICAL quarterly, MONITOR twice a year, LOW yearly, and any time a red-flag event happens. Update Last_Reviewed every time - a dated, ongoing monitoring record is what ISO 13485 / FDA QMSR supplier controls expect.

Sheet DASHBOARD
A1: PART-SUPPLIER RISK DASHBOARD
A2: Everything updates automatically from PART_RISK, SUPPLIERS and MODELS. The only input here is the yellow model selector below.
B4: Part-supplier combos | C4: Critical | D4: Monitor | E4: Low | F4: Not scored | G4: Models | H4: Suppliers
B5: =COUNTIF(PART_RISK!$E$5:$E$304,"?*") -> 6 | C5: =COUNTIF(PART_RISK!$O$5:$O$304,"CRITICAL*") -> 2 | D5: =COUNTIF(PART_RISK!$O$5:$O$304,"MONITOR") -> 3 | E5: =COUNTIF(PART_RISK!$O$5:$O$304,"LOW") -> 1 | F5: =COUNTIF(PART_RISK!$O$5:$O$304,"NOT SCORED") -> 0 | G5: =COUNTIF(MODELS!$A$4:$A$28,"?*") -> 2 | H5: =COUNTIF(SUPPLIERS!$A$4:$A$63,"?*") -> 6
A7: RISK BY MODEL
B8: Model | C8: Parts | D8: Tissue? | E8: Critical | F8: Monitor | G8: Low | H8: Not scored | I8: Max risk | J8: Band
B9: =IF(MODELS!$A4="","",MODELS!$A4) -> Model A - Tissue Trainer (EXAMPLE) | C9: =IF($B9="","",MODELS!$D4) -> 4 | D9: =IF($B9="","",MODELS!$C4) -> Yes | E9: =IF($B9="","",MODELS!$E4) -> 2 | F9: =IF($B9="","",MODELS!$F4) -> 1 | G9: =IF($B9="","",MODELS!$G4) -> 1 | H9: =IF($B9="","",MODELS!$H4) -> 0 | I9: =IF($B9="","",MODELS!$I4) -> 20.5 | J9: =IF($B9="","",MODELS!$J4) -> CRITICAL
B10: =IF(MODELS!$A5="","",MODELS!$A5) -> Model B - Non-Tissue Kit (EXAMPLE) | C10: =IF($B10="","",MODELS!$D5) -> 2 | D10: =IF($B10="","",MODELS!$C5) -> No | E10: =IF($B10="","",MODELS!$E5) -> 0 | F10: =IF($B10="","",MODELS!$F5) -> 2 | G10: =IF($B10="","",MODELS!$G5) -> 0 | H10: =IF($B10="","",MODELS!$H5) -> 0 | I10: =IF($B10="","",MODELS!$I5) -> 11.6 | J10: =IF($B10="","",MODELS!$J5) -> MONITOR
B11: =IF(MODELS!$A6="","",MODELS!$A6) | C11: =IF($B11="","",MODELS!$D6) | D11: =IF($B11="","",MODELS!$C6) | E11: =IF($B11="","",MODELS!$E6) | F11: =IF($B11="","",MODELS!$F6) | G11: =IF($B11="","",MODELS!$G6) | H11: =IF($B11="","",MODELS!$H6) | I11: =IF($B11="","",MODELS!$I6) | J11: =IF($B11="","",MODELS!$J6)
B12: =IF(MODELS!$A7="","",MODELS!$A7) | C12: =IF($B12="","",MODELS!$D7) | D12: =IF($B12="","",MODELS!$C7) | E12: =IF($B12="","",MODELS!$E7) | F12: =IF($B12="","",MODELS!$F7) | G12: =IF($B12="","",MODELS!$G7) | H12: =IF($B12="","",MODELS!$H7) | I12: =IF($B12="","",MODELS!$I7) | J12: =IF($B12="","",MODELS!$J7)
B13: =IF(MODELS!$A8="","",MODELS!$A8) | C13: =IF($B13="","",MODELS!$D8) | D13: =IF($B13="","",MODELS!$C8) | E13: =IF($B13="","",MODELS!$E8) | F13: =IF($B13="","",MODELS!$F8) | G13: =IF($B13="","",MODELS!$G8) | H13: =IF($B13="","",MODELS!$H8) | I13: =IF($B13="","",MODELS!$I8) | J13: =IF($B13="","",MODELS!$J8)
B14: =IF(MODELS!$A9="","",MODELS!$A9) | C14: =IF($B14="","",MODELS!$D9) | D14: =IF($B14="","",MODELS!$C9) | E14: =IF($B14="","",MODELS!$E9) | F14: =IF($B14="","",MODELS!$F9) | G14: =IF($B14="","",MODELS!$G9) | H14: =IF($B14="","",MODELS!$H9) | I14: =IF($B14="","",MODELS!$I9) | J14: =IF($B14="","",MODELS!$J9)
B15: =IF(MODELS!$A10="","",MODELS!$A10) | C15: =IF($B15="","",MODELS!$D10) | D15: =IF($B15="","",MODELS!$C10) | E15: =IF($B15="","",MODELS!$E10) | F15: =IF($B15="","",MODELS!$F10) | G15: =IF($B15="","",MODELS!$G10) | H15: =IF($B15="","",MODELS!$H10) | I15: =IF($B15="","",MODELS!$I10) | J15: =IF($B15="","",MODELS!$J10)
B16: =IF(MODELS!$A11="","",MODELS!$A11) | C16: =IF($B16="","",MODELS!$D11) | D16: =IF($B16="","",MODELS!$C11) | E16: =IF($B16="","",MODELS!$E11) | F16: =IF($B16="","",MODELS!$F11) | G16: =IF($B16="","",MODELS!$G11) | H16: =IF($B16="","",MODELS!$H11) | I16: =IF($B16="","",MODELS!$I11) | J16: =IF($B16="","",MODELS!$J11)
B17: =IF(MODELS!$A12="","",MODELS!$A12) | C17: =IF($B17="","",MODELS!$D12) | D17: =IF($B17="","",MODELS!$C12) | E17: =IF($B17="","",MODELS!$E12) | F17: =IF($B17="","",MODELS!$F12) | G17: =IF($B17="","",MODELS!$G12) | H17: =IF($B17="","",MODELS!$H12) | I17: =IF($B17="","",MODELS!$I12) | J17: =IF($B17="","",MODELS!$J12)
B18: =IF(MODELS!$A13="","",MODELS!$A13) | C18: =IF($B18="","",MODELS!$D13) | D18: =IF($B18="","",MODELS!$C13) | E18: =IF($B18="","",MODELS!$E13) | F18: =IF($B18="","",MODELS!$F13) | G18: =IF($B18="","",MODELS!$G13) | H18: =IF($B18="","",MODELS!$H13) | I18: =IF($B18="","",MODELS!$I13) | J18: =IF($B18="","",MODELS!$J13)
B19: =IF(MODELS!$A14="","",MODELS!$A14) | C19: =IF($B19="","",MODELS!$D14) | D19: =IF($B19="","",MODELS!$C14) | E19: =IF($B19="","",MODELS!$E14) | F19: =IF($B19="","",MODELS!$F14) | G19: =IF($B19="","",MODELS!$G14) | H19: =IF($B19="","",MODELS!$H14) | I19: =IF($B19="","",MODELS!$I14) | J19: =IF($B19="","",MODELS!$J14)
B20: =IF(MODELS!$A15="","",MODELS!$A15) | C20: =IF($B20="","",MODELS!$D15) | D20: =IF($B20="","",MODELS!$C15) | E20: =IF($B20="","",MODELS!$E15) | F20: =IF($B20="","",MODELS!$F15) | G20: =IF($B20="","",MODELS!$G15) | H20: =IF($B20="","",MODELS!$H15) | I20: =IF($B20="","",MODELS!$I15) | J20: =IF($B20="","",MODELS!$J15)
... B23: =IF(MODELS!$A18="","",MODELS!$A18) | C23: =IF($B23="","",MODELS!$D18) | D23: =IF($B23="","",MODELS!$C18) | E23: =IF($B23="","",MODELS!$E18) | F23: =IF($B23="","",MODELS!$F18) | G23: =IF($B23="","",MODELS!$G18) | H23: =IF($B23="","",MODELS!$H18) | I23: =IF($B23="","",MODELS!$I18) | J23: =IF($B23="","",MODELS!$J18)
A25: MODEL DETAIL
A26: Select model: | B26: Model A - Tissue Trainer (EXAMPLE) | E26: Parts of the selected model, highest risk first (red flags always on top).
A28: # | B28: Part number | C28: Description | D28: Type | E28: Supplier | F28: Impact | G28: Likelihood | H28: Risk | I28: Band | J28: Top driver | K28: Red flag
A29: 1 | B29: =IF($M29="","",IF(INDEX(PART_RISK!$B$5:$B$304,$M29)="","",INDEX(PART_RISK!$B$5:$B$304,$M29))) -> QOS-1113 | C29: =IF($M29="","",IF(INDEX(PART_RISK!$C$5:$C$304,$M29)="","",INDEX(PART_RISK!$C$5:$C$304,$M29))) -> Fluid connector, luer | D29: =IF($M29="","",IF(INDEX(PART_RISK!$D$5:$D$304,$M29)="","",INDEX(PART_RISK!$D$5:$D$304,$M29))) -> Non-Tissue: COTS | E29: =IF($M29="","",IF(INDEX(PART_RISK!$E$5:$E$304,$M29)="","",INDEX(PART_RISK!$E$5:$E$304,$M29))) -> Qosina Corp. | F29: =IF($M29="","",IF(INDEX(PART_RISK!$K$5:$K$304,$M29)="","",INDEX(PART_RISK!$K$5:$K$304,$M29))) -> 2 | G29: =IF($M29="","",IF(INDEX(PART_RISK!$M$5:$M$304,$M29)="","",INDEX(PART_RISK!$M$5:$M$304,$M29))) -> 1.1 | H29: =IF($M29="","",IF(INDEX(PART_RISK!$N$5:$N$304,$M29)="","",INDEX(PART_RISK!$N$5:$N$304,$M29))) -> 2.2 | I29: =IF($M29="","",IF(INDEX(PART_RISK!$O$5:$O$304,$M29)="","",INDEX(PART_RISK!$O$5:$O$304,$M29))) -> CRITICAL (FLAG) | J29: =IF($M29="","",IF(INDEX(PART_RISK!$P$5:$P$304,$M29)="","",INDEX(PART_RISK!$P$5:$P$304,$M29))) -> External & Location | K29: =IF($M29="","",IF(INDEX(PART_RISK!$L$5:$L$304,$M29)="","",INDEX(PART_RISK!$L$5:$L$304,$M29))) -> EOL / obsolescence announced (COTS) | M29: =IFERROR(MATCH(LARGE(PART_RISK!$T$5:$T$304,$A29),PART_RISK!$T$5:$T$304,0),"") -> 4
A30: 2 | B30: =IF($M30="","",IF(INDEX(PART_RISK!$B$5:$B$304,$M30)="","",INDEX(PART_RISK!$B$5:$B$304,$M30))) -> 666534 | C30: =IF($M30="","",IF(INDEX(PART_RISK!$C$5:$C$304,$M30)="","",INDEX(PART_RISK!$C$5:$C$304,$M30))) -> Large Pork Belly | D30: =IF($M30="","",IF(INDEX(PART_RISK!$D$5:$D$304,$M30)="","",INDEX(PART_RISK!$D$5:$D$304,$M30))) -> Tissue (APHIS) | E30: =IF($M30="","",IF(INDEX(PART_RISK!$E$5:$E$304,$M30)="","",INDEX(PART_RISK!$E$5:$E$304,$M30))) -> Martin's Pork Products | F30: =IF($M30="","",IF(INDEX(PART_RISK!$K$5:$K$304,$M30)="","",INDEX(PART_RISK!$K$5:$K$304,$M30))) -> 5 | G30: =IF($M30="","",IF(INDEX(PART_RISK!$M$5:$M$304,$M30)="","",INDEX(PART_RISK!$M$5:$M$304,$M30))) -> 4.1 | H30: =IF($M30="","",IF(INDEX(PART_RISK!$N$5:$N$304,$M30)="","",INDEX(PART_RISK!$N$5:$N$304,$M30))) -> 20.5 | I30: =IF($M30="","",IF(INDEX(PART_RISK!$O$5:$O$304,$M30)="","",INDEX(PART_RISK!$O$5:$O$304,$M30))) -> CRITICAL | J30: =IF($M30="","",IF(INDEX(PART_RISK!$P$5:$P$304,$M30)="","",INDEX(PART_RISK!$P$5:$P$304,$M30))) -> Sourcing & Backup | K30: =IF($M30="","",IF(INDEX(PART_RISK!$L$5:$L$304,$M30)="","",INDEX(PART_RISK!$L$5:$L$304,$M30))) | M30: =IFERROR(MATCH(LARGE(PART_RISK!$T$5:$T$304,$A30),PART_RISK!$T$5:$T$304,0),"") -> 2
A31: 3 | B31: =IF($M31="","",IF(INDEX(PART_RISK!$B$5:$B$304,$M31)="","",INDEX(PART_RISK!$B$5:$B$304,$M31))) -> 666512 | C31: =IF($M31="","",IF(INDEX(PART_RISK!$C$5:$C$304,$M31)="","",INDEX(PART_RISK!$C$5:$C$304,$M31))) -> Leaf Fat, porcine | D31: =IF($M31="","",IF(INDEX(PART_RISK!$D$5:$D$304,$M31)="","",INDEX(PART_RISK!$D$5:$D$304,$M31))) -> Tissue (APHIS) | E31: =IF($M31="","",IF(INDEX(PART_RISK!$E$5:$E$304,$M31)="","",INDEX(PART_RISK!$E$5:$E$304,$M31))) -> Parks Family Meats | F31: =IF($M31="","",IF(INDEX(PART_RISK!$K$5:$K$304,$M31)="","",INDEX(PART_RISK!$K$5:$K$304,$M31))) -> 3 | G31: =IF($M31="","",IF(INDEX(PART_RISK!$M$5:$M$304,$M31)="","",INDEX(PART_RISK!$M$5:$M$304,$M31))) -> 2.7 | H31: =IF($M31="","",IF(INDEX(PART_RISK!$N$5:$N$304,$M31)="","",INDEX(PART_RISK!$N$5:$N$304,$M31))) -> 8.1 | I31: =IF($M31="","",IF(INDEX(PART_RISK!$O$5:$O$304,$M31)="","",INDEX(PART_RISK!$O$5:$O$304,$M31))) -> MONITOR | J31: =IF($M31="","",IF(INDEX(PART_RISK!$P$5:$P$304,$M31)="","",INDEX(PART_RISK!$P$5:$P$304,$M31))) -> External & Location | K31: =IF($M31="","",IF(INDEX(PART_RISK!$L$5:$L$304,$M31)="","",INDEX(PART_RISK!$L$5:$L$304,$M31))) | M31: =IFERROR(MATCH(LARGE(PART_RISK!$T$5:$T$304,$A31),PART_RISK!$T$5:$T$304,0),"") -> 1
A32: 4 | B32: =IF($M32="","",IF(INDEX(PART_RISK!$B$5:$B$304,$M32)="","",INDEX(PART_RISK!$B$5:$B$304,$M32))) -> 666800-01 | C32: =IF($M32="","",IF(INDEX(PART_RISK!$C$5:$C$304,$M32)="","",INDEX(PART_RISK!$C$5:$C$304,$M32))) -> Plate, thermoformed, Kydex | D32: =IF($M32="","",IF(INDEX(PART_RISK!$D$5:$D$304,$M32)="","",INDEX(PART_RISK!$D$5:$D$304,$M32))) -> Non-Tissue: Custom | E32: =IF($M32="","",IF(INDEX(PART_RISK!$E$5:$E$304,$M32)="","",INDEX(PART_RISK!$E$5:$E$304,$M32))) -> Advanced Plastiform | F32: =IF($M32="","",IF(INDEX(PART_RISK!$K$5:$K$304,$M32)="","",INDEX(PART_RISK!$K$5:$K$304,$M32))) -> 3 | G32: =IF($M32="","",IF(INDEX(PART_RISK!$M$5:$M$304,$M32)="","",INDEX(PART_RISK!$M$5:$M$304,$M32))) -> 2.2 | H32: =IF($M32="","",IF(INDEX(PART_RISK!$N$5:$N$304,$M32)="","",INDEX(PART_RISK!$N$5:$N$304,$M32))) -> 6.6 | I32: =IF($M32="","",IF(INDEX(PART_RISK!$O$5:$O$304,$M32)="","",INDEX(PART_RISK!$O$5:$O$304,$M32))) -> LOW | J32: =IF($M32="","",IF(INDEX(PART_RISK!$P$5:$P$304,$M32)="","",INDEX(PART_RISK!$P$5:$P$304,$M32))) -> Capacity & Delivery | K32: =IF($M32="","",IF(INDEX(PART_RISK!$L$5:$L$304,$M32)="","",INDEX(PART_RISK!$L$5:$L$304,$M32))) | M32: =IFERROR(MATCH(LARGE(PART_RISK!$T$5:$T$304,$A32),PART_RISK!$T$5:$T$304,0),"") -> 3
A33: 5 | B33: =IF($M33="","",IF(INDEX(PART_RISK!$B$5:$B$304,$M33)="","",INDEX(PART_RISK!$B$5:$B$304,$M33))) | C33: =IF($M33="","",IF(INDEX(PART_RISK!$C$5:$C$304,$M33)="","",INDEX(PART_RISK!$C$5:$C$304,$M33))) | D33: =IF($M33="","",IF(INDEX(PART_RISK!$D$5:$D$304,$M33)="","",INDEX(PART_RISK!$D$5:$D$304,$M33))) | E33: =IF($M33="","",IF(INDEX(PART_RISK!$E$5:$E$304,$M33)="","",INDEX(PART_RISK!$E$5:$E$304,$M33))) | F33: =IF($M33="","",IF(INDEX(PART_RISK!$K$5:$K$304,$M33)="","",INDEX(PART_RISK!$K$5:$K$304,$M33))) | G33: =IF($M33="","",IF(INDEX(PART_RISK!$M$5:$M$304,$M33)="","",INDEX(PART_RISK!$M$5:$M$304,$M33))) | H33: =IF($M33="","",IF(INDEX(PART_RISK!$N$5:$N$304,$M33)="","",INDEX(PART_RISK!$N$5:$N$304,$M33))) | I33: =IF($M33="","",IF(INDEX(PART_RISK!$O$5:$O$304,$M33)="","",INDEX(PART_RISK!$O$5:$O$304,$M33))) | J33: =IF($M33="","",IF(INDEX(PART_RISK!$P$5:$P$304,$M33)="","",INDEX(PART_RISK!$P$5:$P$304,$M33))) | K33: =IF($M33="","",IF(INDEX(PART_RISK!$L$5:$L$304,$M33)="","",INDEX(PART_RISK!$L$5:$L$304,$M33))) | M33: =IFERROR(MATCH(LARGE(PART_RISK!$T$5:$T$304,$A33),PART_RISK!$T$5:$T$304,0),"")
A34: 6 | B34: =IF($M34="","",IF(INDEX(PART_RISK!$B$5:$B$304,$M34)="","",INDEX(PART_RISK!$B$5:$B$304,$M34))) | C34: =IF($M34="","",IF(INDEX(PART_RISK!$C$5:$C$304,$M34)="","",INDEX(PART_RISK!$C$5:$C$304,$M34))) | D34: =IF($M34="","",IF(INDEX(PART_RISK!$D$5:$D$304,$M34)="","",INDEX(PART_RISK!$D$5:$D$304,$M34))) | E34: =IF($M34="","",IF(INDEX(PART_RISK!$E$5:$E$304,$M34)="","",INDEX(PART_RISK!$E$5:$E$304,$M34))) | F34: =IF($M34="","",IF(INDEX(PART_RISK!$K$5:$K$304,$M34)="","",INDEX(PART_RISK!$K$5:$K$304,$M34))) | G34: =IF($M34="","",IF(INDEX(PART_RISK!$M$5:$M$304,$M34)="","",INDEX(PART_RISK!$M$5:$M$304,$M34))) | H34: =IF($M34="","",IF(INDEX(PART_RISK!$N$5:$N$304,$M34)="","",INDEX(PART_RISK!$N$5:$N$304,$M34))) | I34: =IF($M34="","",IF(INDEX(PART_RISK!$O$5:$O$304,$M34)="","",INDEX(PART_RISK!$O$5:$O$304,$M34))) | J34: =IF($M34="","",IF(INDEX(PART_RISK!$P$5:$P$304,$M34)="","",INDEX(PART_RISK!$P$5:$P$304,$M34))) | K34: =IF($M34="","",IF(INDEX(PART_RISK!$L$5:$L$304,$M34)="","",INDEX(PART_RISK!$L$5:$L$304,$M34))) | M34: =IFERROR(MATCH(LARGE(PART_RISK!$T$5:$T$304,$A34),PART_RISK!$T$5:$T$304,0),"")
A35: 7 | B35: =IF($M35="","",IF(INDEX(PART_RISK!$B$5:$B$304,$M35)="","",INDEX(PART_RISK!$B$5:$B$304,$M35))) | C35: =IF($M35="","",IF(INDEX(PART_RISK!$C$5:$C$304,$M35)="","",INDEX(PART_RISK!$C$5:$C$304,$M35))) | D35: =IF($M35="","",IF(INDEX(PART_RISK!$D$5:$D$304,$M35)="","",INDEX(PART_RISK!$D$5:$D$304,$M35))) | E35: =IF($M35="","",IF(INDEX(PART_RISK!$E$5:$E$304,$M35)="","",INDEX(PART_RISK!$E$5:$E$304,$M35))) | F35: =IF($M35="","",IF(INDEX(PART_RISK!$K$5:$K$304,$M35)="","",INDEX(PART_RISK!$K$5:$K$304,$M35))) | G35: =IF($M35="","",IF(INDEX(PART_RISK!$M$5:$M$304,$M35)="","",INDEX(PART_RISK!$M$5:$M$304,$M35))) | H35: =IF($M35="","",IF(INDEX(PART_RISK!$N$5:$N$304,$M35)="","",INDEX(PART_RISK!$N$5:$N$304,$M35))) | I35: =IF($M35="","",IF(INDEX(PART_RISK!$O$5:$O$304,$M35)="","",INDEX(PART_RISK!$O$5:$O$304,$M35))) | J35: =IF($M35="","",IF(INDEX(PART_RISK!$P$5:$P$304,$M35)="","",INDEX(PART_RISK!$P$5:$P$304,$M35))) | K35: =IF($M35="","",IF(INDEX(PART_RISK!$L$5:$L$304,$M35)="","",INDEX(PART_RISK!$L$5:$L$304,$M35))) | M35: =IFERROR(MATCH(LARGE(PART_RISK!$T$5:$T$304,$A35),PART_RISK!$T$5:$T$304,0),"")
A36: 8 | B36: =IF($M36="","",IF(INDEX(PART_RISK!$B$5:$B$304,$M36)="","",INDEX(PART_RISK!$B$5:$B$304,$M36))) | C36: =IF($M36="","",IF(INDEX(PART_RISK!$C$5:$C$304,$M36)="","",INDEX(PART_RISK!$C$5:$C$304,$M36))) | D36: =IF($M36="","",IF(INDEX(PART_RISK!$D$5:$D$304,$M36)="","",INDEX(PART_RISK!$D$5:$D$304,$M36))) | E36: =IF($M36="","",IF(INDEX(PART_RISK!$E$5:$E$304,$M36)="","",INDEX(PART_RISK!$E$5:$E$304,$M36))) | F36: =IF($M36="","",IF(INDEX(PART_RISK!$K$5:$K$304,$M36)="","",INDEX(PART_RISK!$K$5:$K$304,$M36))) | G36: =IF($M36="","",IF(INDEX(PART_RISK!$M$5:$M$304,$M36)="","",INDEX(PART_RISK!$M$5:$M$304,$M36))) | H36: =IF($M36="","",IF(INDEX(PART_RISK!$N$5:$N$304,$M36)="","",INDEX(PART_RISK!$N$5:$N$304,$M36))) | I36: =IF($M36="","",IF(INDEX(PART_RISK!$O$5:$O$304,$M36)="","",INDEX(PART_RISK!$O$5:$O$304,$M36))) | J36: =IF($M36="","",IF(INDEX(PART_RISK!$P$5:$P$304,$M36)="","",INDEX(PART_RISK!$P$5:$P$304,$M36))) | K36: =IF($M36="","",IF(INDEX(PART_RISK!$L$5:$L$304,$M36)="","",INDEX(PART_RISK!$L$5:$L$304,$M36))) | M36: =IFERROR(MATCH(LARGE(PART_RISK!$T$5:$T$304,$A36),PART_RISK!$T$5:$T$304,0),"")
A37: 9 | B37: =IF($M37="","",IF(INDEX(PART_RISK!$B$5:$B$304,$M37)="","",INDEX(PART_RISK!$B$5:$B$304,$M37))) | C37: =IF($M37="","",IF(INDEX(PART_RISK!$C$5:$C$304,$M37)="","",INDEX(PART_RISK!$C$5:$C$304,$M37))) | D37: =IF($M37="","",IF(INDEX(PART_RISK!$D$5:$D$304,$M37)="","",INDEX(PART_RISK!$D$5:$D$304,$M37))) | E37: =IF($M37="","",IF(INDEX(PART_RISK!$E$5:$E$304,$M37)="","",INDEX(PART_RISK!$E$5:$E$304,$M37))) | F37: =IF($M37="","",IF(INDEX(PART_RISK!$K$5:$K$304,$M37)="","",INDEX(PART_RISK!$K$5:$K$304,$M37))) | G37: =IF($M37="","",IF(INDEX(PART_RISK!$M$5:$M$304,$M37)="","",INDEX(PART_RISK!$M$5:$M$304,$M37))) | H37: =IF($M37="","",IF(INDEX(PART_RISK!$N$5:$N$304,$M37)="","",INDEX(PART_RISK!$N$5:$N$304,$M37))) | I37: =IF($M37="","",IF(INDEX(PART_RISK!$O$5:$O$304,$M37)="","",INDEX(PART_RISK!$O$5:$O$304,$M37))) | J37: =IF($M37="","",IF(INDEX(PART_RISK!$P$5:$P$304,$M37)="","",INDEX(PART_RISK!$P$5:$P$304,$M37))) | K37: =IF($M37="","",IF(INDEX(PART_RISK!$L$5:$L$304,$M37)="","",INDEX(PART_RISK!$L$5:$L$304,$M37))) | M37: =IFERROR(MATCH(LARGE(PART_RISK!$T$5:$T$304,$A37),PART_RISK!$T$5:$T$304,0),"")
A38: 10 | B38: =IF($M38="","",IF(INDEX(PART_RISK!$B$5:$B$304,$M38)="","",INDEX(PART_RISK!$B$5:$B$304,$M38))) | C38: =IF($M38="","",IF(INDEX(PART_RISK!$C$5:$C$304,$M38)="","",INDEX(PART_RISK!$C$5:$C$304,$M38))) | D38: =IF($M38="","",IF(INDEX(PART_RISK!$D$5:$D$304,$M38)="","",INDEX(PART_RISK!$D$5:$D$304,$M38))) | E38: =IF($M38="","",IF(INDEX(PART_RISK!$E$5:$E$304,$M38)="","",INDEX(PART_RISK!$E$5:$E$304,$M38))) | F38: =IF($M38="","",IF(INDEX(PART_RISK!$K$5:$K$304,$M38)="","",INDEX(PART_RISK!$K$5:$K$304,$M38))) | G38: =IF($M38="","",IF(INDEX(PART_RISK!$M$5:$M$304,$M38)="","",INDEX(PART_RISK!$M$5:$M$304,$M38))) | H38: =IF($M38="","",IF(INDEX(PART_RISK!$N$5:$N$304,$M38)="","",INDEX(PART_RISK!$N$5:$N$304,$M38))) | I38: =IF($M38="","",IF(INDEX(PART_RISK!$O$5:$O$304,$M38)="","",INDEX(PART_RISK!$O$5:$O$304,$M38))) | J38: =IF($M38="","",IF(INDEX(PART_RISK!$P$5:$P$304,$M38)="","",INDEX(PART_RISK!$P$5:$P$304,$M38))) | K38: =IF($M38="","",IF(INDEX(PART_RISK!$L$5:$L$304,$M38)="","",INDEX(PART_RISK!$L$5:$L$304,$M38))) | M38: =IFERROR(MATCH(LARGE(PART_RISK!$T$5:$T$304,$A38),PART_RISK!$T$5:$T$304,0),"")
A39: 11 | B39: =IF($M39="","",IF(INDEX(PART_RISK!$B$5:$B$304,$M39)="","",INDEX(PART_RISK!$B$5:$B$304,$M39))) | C39: =IF($M39="","",IF(INDEX(PART_RISK!$C$5:$C$304,$M39)="","",INDEX(PART_RISK!$C$5:$C$304,$M39))) | D39: =IF($M39="","",IF(INDEX(PART_RISK!$D$5:$D$304,$M39)="","",INDEX(PART_RISK!$D$5:$D$304,$M39))) | E39: =IF($M39="","",IF(INDEX(PART_RISK!$E$5:$E$304,$M39)="","",INDEX(PART_RISK!$E$5:$E$304,$M39))) | F39: =IF($M39="","",IF(INDEX(PART_RISK!$K$5:$K$304,$M39)="","",INDEX(PART_RISK!$K$5:$K$304,$M39))) | G39: =IF($M39="","",IF(INDEX(PART_RISK!$M$5:$M$304,$M39)="","",INDEX(PART_RISK!$M$5:$M$304,$M39))) | H39: =IF($M39="","",IF(INDEX(PART_RISK!$N$5:$N$304,$M39)="","",INDEX(PART_RISK!$N$5:$N$304,$M39))) | I39: =IF($M39="","",IF(INDEX(PART_RISK!$O$5:$O$304,$M39)="","",INDEX(PART_RISK!$O$5:$O$304,$M39))) | J39: =IF($M39="","",IF(INDEX(PART_RISK!$P$5:$P$304,$M39)="","",INDEX(PART_RISK!$P$5:$P$304,$M39))) | K39: =IF($M39="","",IF(INDEX(PART_RISK!$L$5:$L$304,$M39)="","",INDEX(PART_RISK!$L$5:$L$304,$M39))) | M39: =IFERROR(MATCH(LARGE(PART_RISK!$T$5:$T$304,$A39),PART_RISK!$T$5:$T$304,0),"")
A40: 12 | B40: =IF($M40="","",IF(INDEX(PART_RISK!$B$5:$B$304,$M40)="","",INDEX(PART_RISK!$B$5:$B$304,$M40))) | C40: =IF($M40="","",IF(INDEX(PART_RISK!$C$5:$C$304,$M40)="","",INDEX(PART_RISK!$C$5:$C$304,$M40))) | D40: =IF($M40="","",IF(INDEX(PART_RISK!$D$5:$D$304,$M40)="","",INDEX(PART_RISK!$D$5:$D$304,$M40))) | E40: =IF($M40="","",IF(INDEX(PART_RISK!$E$5:$E$304,$M40)="","",INDEX(PART_RISK!$E$5:$E$304,$M40))) | F40: =IF($M40="","",IF(INDEX(PART_RISK!$K$5:$K$304,$M40)="","",INDEX(PART_RISK!$K$5:$K$304,$M40))) | G40: =IF($M40="","",IF(INDEX(PART_RISK!$M$5:$M$304,$M40)="","",INDEX(PART_RISK!$M$5:$M$304,$M40))) | H40: =IF($M40="","",IF(INDEX(PART_RISK!$N$5:$N$304,$M40)="","",INDEX(PART_RISK!$N$5:$N$304,$M40))) | I40: =IF($M40="","",IF(INDEX(PART_RISK!$O$5:$O$304,$M40)="","",INDEX(PART_RISK!$O$5:$O$304,$M40))) | J40: =IF($M40="","",IF(INDEX(PART_RISK!$P$5:$P$304,$M40)="","",INDEX(PART_RISK!$P$5:$P$304,$M40))) | K40: =IF($M40="","",IF(INDEX(PART_RISK!$L$5:$L$304,$M40)="","",INDEX(PART_RISK!$L$5:$L$304,$M40))) | M40: =IFERROR(MATCH(LARGE(PART_RISK!$T$5:$T$304,$A40),PART_RISK!$T$5:$T$304,0),"")
... A48: 20 | B48: =IF($M48="","",IF(INDEX(PART_RISK!$B$5:$B$304,$M48)="","",INDEX(PART_RISK!$B$5:$B$304,$M48))) | C48: =IF($M48="","",IF(INDEX(PART_RISK!$C$5:$C$304,$M48)="","",INDEX(PART_RISK!$C$5:$C$304,$M48))) | D48: =IF($M48="","",IF(INDEX(PART_RISK!$D$5:$D$304,$M48)="","",INDEX(PART_RISK!$D$5:$D$304,$M48))) | E48: =IF($M48="","",IF(INDEX(PART_RISK!$E$5:$E$304,$M48)="","",INDEX(PART_RISK!$E$5:$E$304,$M48))) | F48: =IF($M48="","",IF(INDEX(PART_RISK!$K$5:$K$304,$M48)="","",INDEX(PART_RISK!$K$5:$K$304,$M48))) | G48: =IF($M48="","",IF(INDEX(PART_RISK!$M$5:$M$304,$M48)="","",INDEX(PART_RISK!$M$5:$M$304,$M48))) | H48: =IF($M48="","",IF(INDEX(PART_RISK!$N$5:$N$304,$M48)="","",INDEX(PART_RISK!$N$5:$N$304,$M48))) | I48: =IF($M48="","",IF(INDEX(PART_RISK!$O$5:$O$304,$M48)="","",INDEX(PART_RISK!$O$5:$O$304,$M48))) | J48: =IF($M48="","",IF(INDEX(PART_RISK!$P$5:$P$304,$M48)="","",INDEX(PART_RISK!$P$5:$P$304,$M48))) | K48: =IF($M48="","",IF(INDEX(PART_RISK!$L$5:$L$304,$M48)="","",INDEX(PART_RISK!$L$5:$L$304,$M48))) | M48: =IFERROR(MATCH(LARGE(PART_RISK!$T$5:$T$304,$A48),PART_RISK!$T$5:$T$304,0),"")
A50: TOP 10 RISKS - ALL MODELS
A51: # | B51: Model | C51: Part number | D51: Supplier | E51: Risk | F51: Band | G51: Top driver
A52: 1 | B52: =IF($M52="","",IF(INDEX(PART_RISK!$A$5:$A$304,$M52)="","",INDEX(PART_RISK!$A$5:$A$304,$M52))) -> Model A - Tissue Trainer (EXAMPLE) | C52: =IF($M52="","",IF(INDEX(PART_RISK!$B$5:$B$304,$M52)="","",INDEX(PART_RISK!$B$5:$B$304,$M52))) -> QOS-1113 | D52: =IF($M52="","",IF(INDEX(PART_RISK!$E$5:$E$304,$M52)="","",INDEX(PART_RISK!$E$5:$E$304,$M52))) -> Qosina Corp. | E52: =IF($M52="","",IF(INDEX(PART_RISK!$N$5:$N$304,$M52)="","",INDEX(PART_RISK!$N$5:$N$304,$M52))) -> 2.2 | F52: =IF($M52="","",IF(INDEX(PART_RISK!$O$5:$O$304,$M52)="","",INDEX(PART_RISK!$O$5:$O$304,$M52))) -> CRITICAL (FLAG) | G52: =IF($M52="","",IF(INDEX(PART_RISK!$P$5:$P$304,$M52)="","",INDEX(PART_RISK!$P$5:$P$304,$M52))) -> External & Location | M52: =IFERROR(MATCH(LARGE(PART_RISK!$S$5:$S$304,$A52),PART_RISK!$S$5:$S$304,0),"") -> 4
A53: 2 | B53: =IF($M53="","",IF(INDEX(PART_RISK!$A$5:$A$304,$M53)="","",INDEX(PART_RISK!$A$5:$A$304,$M53))) -> Model A - Tissue Trainer (EXAMPLE) | C53: =IF($M53="","",IF(INDEX(PART_RISK!$B$5:$B$304,$M53)="","",INDEX(PART_RISK!$B$5:$B$304,$M53))) -> 666534 | D53: =IF($M53="","",IF(INDEX(PART_RISK!$E$5:$E$304,$M53)="","",INDEX(PART_RISK!$E$5:$E$304,$M53))) -> Martin's Pork Products | E53: =IF($M53="","",IF(INDEX(PART_RISK!$N$5:$N$304,$M53)="","",INDEX(PART_RISK!$N$5:$N$304,$M53))) -> 20.5 | F53: =IF($M53="","",IF(INDEX(PART_RISK!$O$5:$O$304,$M53)="","",INDEX(PART_RISK!$O$5:$O$304,$M53))) -> CRITICAL | G53: =IF($M53="","",IF(INDEX(PART_RISK!$P$5:$P$304,$M53)="","",INDEX(PART_RISK!$P$5:$P$304,$M53))) -> Sourcing & Backup | M53: =IFERROR(MATCH(LARGE(PART_RISK!$S$5:$S$304,$A53),PART_RISK!$S$5:$S$304,0),"") -> 2
A54: 3 | B54: =IF($M54="","",IF(INDEX(PART_RISK!$A$5:$A$304,$M54)="","",INDEX(PART_RISK!$A$5:$A$304,$M54))) -> Model B - Non-Tissue Kit (EXAMPLE) | C54: =IF($M54="","",IF(INDEX(PART_RISK!$B$5:$B$304,$M54)="","",INDEX(PART_RISK!$B$5:$B$304,$M54))) -> 666438 | D54: =IF($M54="","",IF(INDEX(PART_RISK!$E$5:$E$304,$M54)="","",INDEX(PART_RISK!$E$5:$E$304,$M54))) -> SNP, Inc. | E54: =IF($M54="","",IF(INDEX(PART_RISK!$N$5:$N$304,$M54)="","",INDEX(PART_RISK!$N$5:$N$304,$M54))) -> 11.6 | F54: =IF($M54="","",IF(INDEX(PART_RISK!$O$5:$O$304,$M54)="","",INDEX(PART_RISK!$O$5:$O$304,$M54))) -> MONITOR | G54: =IF($M54="","",IF(INDEX(PART_RISK!$P$5:$P$304,$M54)="","",INDEX(PART_RISK!$P$5:$P$304,$M54))) -> Sourcing & Backup | M54: =IFERROR(MATCH(LARGE(PART_RISK!$S$5:$S$304,$A54),PART_RISK!$S$5:$S$304,0),"") -> 5
...

Sheet PART_RISK
A1: PART-SUPPLIER RISK REGISTER
A2: One row per part-supplier combination. Cream = you enter/select. Gray = automatic. Score 1 (low risk) to 5 (high risk) using the SCORING_GUIDE anchors. A red flag forces the band to CRITICAL.
A3: 1. IDENTIFY THE PART | F3: 2. SCORE THE PART (1-5) | I3: 3. SUPPLIER SCORES (auto) | K3: 4. IMPACT | L3: 5. RED FLAG | M3: RESULT (auto) | Q3: 6. ACTIONS & REVIEW
A4: Model | B4: Part_Number | C4: Part_Description | D4: Part_Type | E4: Supplier | F4: Sourcing_Backup | G4: Quality_Compliance | H4: Capacity_Delivery | I4: Supplier_Stability | J4: External_Location | K4: Impact (1-5) | L4: Red_Flag | M4: Likelihood | N4: Risk_Score | O4: Risk_Band | P4: Top_Driver | Q4: Mitigation / Notes | R4: Last_Reviewed | S4: srt | T4: sel
A5: Model A - Tissue Trainer (EXAMPLE) | B5: 666512 | C5: Leaf Fat, porcine | D5: Tissue (APHIS) | E5: Parks Family Meats | F5: 2 | G5: 3 | H5: 2 | I5: =IF($E5="","",IFERROR(IF(INDEX(SUPPLIERS!$D$4:$D$63,MATCH($E5,SUPPLIERS!$A$4:$A$63,0))="","",INDEX(SUPPLIERS!$D$4:$D$63,MATCH($E5,SUPPLIERS!$A$4:$A$63,0))),"")) -> 3 | J5: =IF($E5="","",IFERROR(IF(INDEX(SUPPLIERS!$E$4:$E$63,MATCH($E5,SUPPLIERS!$A$4:$A$63,0))="","",INDEX(SUPPLIERS!$E$4:$E$63,MATCH($E5,SUPPLIERS!$A$4:$A$63,0))),"")) -> 4 | K5: 3 | M5: =IF(COUNT($F5:$J5)<5,"",ROUND($F5*W_SRC+$G5*W_QC+$H5*W_CAP+$I5*W_SUP+$J5*W_EXT,1)) -> 2.7 | N5: =IF(OR($M5="",$K5=""),"",ROUND($M5*$K5,1)) -> 8.1 | O5: =IF($E5="","",IF($L5<>"","CRITICAL (FLAG)",IF(OR($M5="",$K5=""),"NOT SCORED",IF($N5>=T_CRIT,"CRITICAL",IF($N5>=T_MON,"MONITOR","LOW"))))) -> MONITOR | P5: =IF($M5="","",INDEX(DriverNames,MATCH(MAX($F5:$J5),$F5:$J5,0))) -> External & Location | Q5: EXAMPLE - replace with real data. Multi-sourced; permits current; watch defect rate (improving). | R5: 46241 | S5: =IF($O5="","",IF($L5<>"",100,0)+IF($N5="",0,$N5)+ROW()/100000) -> 8.10005 | T5: =IF($S5="","",IF($A5=SEL_MODEL,$S5,"")) -> 8.10005
A6: Model A - Tissue Trainer (EXAMPLE) | B6: 666534 | C6: Large Pork Belly | D6: Tissue (APHIS) | E6: Martin's Pork Products | F6: 5 | G6: 4 | H6: 3 | I6: =IF($E6="","",IFERROR(IF(INDEX(SUPPLIERS!$D$4:$D$63,MATCH($E6,SUPPLIERS!$A$4:$A$63,0))="","",INDEX(SUPPLIERS!$D$4:$D$63,MATCH($E6,SUPPLIERS!$A$4:$A$63,0))),"")) -> 4 | J6: =IF($E6="","",IFERROR(IF(INDEX(SUPPLIERS!$E$4:$E$63,MATCH($E6,SUPPLIERS!$A$4:$A$63,0))="","",INDEX(SUPPLIERS!$E$4:$E$63,MATCH($E6,SUPPLIERS!$A$4:$A$63,0))),"")) -> 4 | K6: 5 | M6: =IF(COUNT($F6:$J6)<5,"",ROUND($F6*W_SRC+$G6*W_QC+$H6*W_CAP+$I6*W_SUP+$J6*W_EXT,1)) -> 4.1 | N6: =IF(OR($M6="",$K6=""),"",ROUND($M6*$K6,1)) -> 20.5 | O6: =IF($E6="","",IF($L6<>"","CRITICAL (FLAG)",IF(OR($M6="",$K6=""),"NOT SCORED",IF($N6>=T_CRIT,"CRITICAL",IF($N6>=T_MON,"MONITOR","LOW"))))) -> CRITICAL | P6: =IF($M6="","",INDEX(DriverNames,MATCH(MAX($F6:$J6),$F6:$J6,0))) -> Sourcing & Backup | Q6: EXAMPLE - replace with real data. Sole source, declining quality trend: qualify backup harvest supplier, raise safety stock. | R6: 46241 | S6: =IF($O6="","",IF($L6<>"",100,0)+IF($N6="",0,$N6)+ROW()/100000) -> 20.50006 | T6: =IF($S6="","",IF($A6=SEL_MODEL,$S6,"")) -> 20.50006
A7: Model A - Tissue Trainer (EXAMPLE) | B7: 666800-01 | C7: Plate, thermoformed, Kydex | D7: Non-Tissue: Custom | E7: Advanced Plastiform | F7: 2 | G7: 2 | H7: 3 | I7: =IF($E7="","",IFERROR(IF(INDEX(SUPPLIERS!$D$4:$D$63,MATCH($E7,SUPPLIERS!$A$4:$A$63,0))="","",INDEX(SUPPLIERS!$D$4:$D$63,MATCH($E7,SUPPLIERS!$A$4:$A$63,0))),"")) -> 2 | J7: =IF($E7="","",IFERROR(IF(INDEX(SUPPLIERS!$E$4:$E$63,MATCH($E7,SUPPLIERS!$A$4:$A$63,0))="","",INDEX(SUPPLIERS!$E$4:$E$63,MATCH($E7,SUPPLIERS!$A$4:$A$63,0))),"")) -> 2 | K7: 3 | M7: =IF(COUNT($F7:$J7)<5,"",ROUND($F7*W_SRC+$G7*W_QC+$H7*W_CAP+$I7*W_SUP+$J7*W_EXT,1)) -> 2.2 | N7: =IF(OR($M7="",$K7=""),"",ROUND($M7*$K7,1)) -> 6.6 | O7: =IF($E7="","",IF($L7<>"","CRITICAL (FLAG)",IF(OR($M7="",$K7=""),"NOT SCORED",IF($N7>=T_CRIT,"CRITICAL",IF($N7>=T_MON,"MONITOR","LOW"))))) -> LOW | P7: =IF($M7="","",INDEX(DriverNames,MATCH(MAX($F7:$J7),$F7:$J7,0))) -> Capacity & Delivery | Q7: EXAMPLE - replace with real data. Alternates identified (Fictiv, Xometry); 8-week lead time. | R7: 46241 | S7: =IF($O7="","",IF($L7<>"",100,0)+IF($N7="",0,$N7)+ROW()/100000) -> 6.60007 | T7: =IF($S7="","",IF($A7=SEL_MODEL,$S7,"")) -> 6.60007
A8: Model A - Tissue Trainer (EXAMPLE) | B8: QOS-1113 | C8: Fluid connector, luer | D8: Non-Tissue: COTS | E8: Qosina Corp. | F8: 1 | G8: 1 | H8: 1 | I8: =IF($E8="","",IFERROR(IF(INDEX(SUPPLIERS!$D$4:$D$63,MATCH($E8,SUPPLIERS!$A$4:$A$63,0))="","",INDEX(SUPPLIERS!$D$4:$D$63,MATCH($E8,SUPPLIERS!$A$4:$A$63,0))),"")) -> 1 | J8: =IF($E8="","",IFERROR(IF(INDEX(SUPPLIERS!$E$4:$E$63,MATCH($E8,SUPPLIERS!$A$4:$A$63,0))="","",INDEX(SUPPLIERS!$E$4:$E$63,MATCH($E8,SUPPLIERS!$A$4:$A$63,0))),"")) -> 2 | K8: 2 | L8: EOL / obsolescence announced (COTS) | M8: =IF(COUNT($F8:$J8)<5,"",ROUND($F8*W_SRC+$G8*W_QC+$H8*W_CAP+$I8*W_SUP+$J8*W_EXT,1)) -> 1.1 | N8: =IF(OR($M8="",$K8=""),"",ROUND($M8*$K8,1)) -> 2.2 | O8: =IF($E8="","",IF($L8<>"","CRITICAL (FLAG)",IF(OR($M8="",$K8=""),"NOT SCORED",IF($N8>=T_CRIT,"CRITICAL",IF($N8>=T_MON,"MONITOR","LOW"))))) -> CRITICAL (FLAG) | P8: =IF($M8="","",INDEX(DriverNames,MATCH(MAX($F8:$J8),$F8:$J8,0))) -> External & Location | Q8: EXAMPLE - replace with real data. Connector discontinued by OEM: last-time buy placed, replacement in qualification. | R8: 46241 | S8: =IF($O8="","",IF($L8<>"",100,0)+IF($N8="",0,$N8)+ROW()/100000) -> 102.20008 | T8: =IF($S8="","",IF($A8=SEL_MODEL,$S8,"")) -> 102.20008
A9: Model B - Non-Tissue Kit (EXAMPLE) | B9: 666438 | C9: Liquid, SB aqueous mixture | D9: Non-Tissue: Custom | E9: SNP, Inc. | F9: 4 | G9: 2 | H9: 3 | I9: =IF($E9="","",IFERROR(IF(INDEX(SUPPLIERS!$D$4:$D$63,MATCH($E9,SUPPLIERS!$A$4:$A$63,0))="","",INDEX(SUPPLIERS!$D$4:$D$63,MATCH($E9,SUPPLIERS!$A$4:$A$63,0))),"")) -> 3 | J9: =IF($E9="","",IFERROR(IF(INDEX(SUPPLIERS!$E$4:$E$63,MATCH($E9,SUPPLIERS!$A$4:$A$63,0))="","",INDEX(SUPPLIERS!$E$4:$E$63,MATCH($E9,SUPPLIERS!$A$4:$A$63,0))),"")) -> 2 | K9: 4 | M9: =IF(COUNT($F9:$J9)<5,"",ROUND($F9*W_SRC+$G9*W_QC+$H9*W_CAP+$I9*W_SUP+$J9*W_EXT,1)) -> 2.9 | N9: =IF(OR($M9="",$K9=""),"",ROUND($M9*$K9,1)) -> 11.6 | O9: =IF($E9="","",IF($L9<>"","CRITICAL (FLAG)",IF(OR($M9="",$K9=""),"NOT SCORED",IF($N9>=T_CRIT,"CRITICAL",IF($N9>=T_MON,"MONITOR","LOW"))))) -> MONITOR | P9: =IF($M9="","",INDEX(DriverNames,MATCH(MAX($F9:$J9),$F9:$J9,0))) -> Sourcing & Backup | Q9: EXAMPLE - replace with real data. Single source; second supplier (Brenntag) in qualification. | R9: 46241 | S9: =IF($O9="","",IF($L9<>"",100,0)+IF($N9="",0,$N9)+ROW()/100000) -> 11.60009 | T9: =IF($S9="","",IF($A9=SEL_MODEL,$S9,""))
A10: Model B - Non-Tissue Kit (EXAMPLE) | B10: 666800-01 | C10: Plate, thermoformed, Kydex | D10: Non-Tissue: Custom | E10: Midland Plastics | F10: 3 | G10: 3 | H10: 2 | I10: =IF($E10="","",IFERROR(IF(INDEX(SUPPLIERS!$D$4:$D$63,MATCH($E10,SUPPLIERS!$A$4:$A$63,0))="","",INDEX(SUPPLIERS!$D$4:$D$63,MATCH($E10,SUPPLIERS!$A$4:$A$63,0))),"")) -> 3 | J10: =IF($E10="","",IFERROR(IF(INDEX(SUPPLIERS!$E$4:$E$63,MATCH($E10,SUPPLIERS!$A$4:$A$63,0))="","",INDEX(SUPPLIERS!$E$4:$E$63,MATCH($E10,SUPPLIERS!$A$4:$A$63,0))),"")) -> 2 | K10: 3 | M10: =IF(COUNT($F10:$J10)<5,"",ROUND($F10*W_SRC+$G10*W_QC+$H10*W_CAP+$I10*W_SUP+$J10*W_EXT,1)) -> 2.7 | N10: =IF(OR($M10="",$K10=""),"",ROUND($M10*$K10,1)) -> 8.1 | O10: =IF($E10="","",IF($L10<>"","CRITICAL (FLAG)",IF(OR($M10="",$K10=""),"NOT SCORED",IF($N10>=T_CRIT,"CRITICAL",IF($N10>=T_MON,"MONITOR","LOW"))))) -> MONITOR | P10: =IF($M10="","",INDEX(DriverNames,MATCH(MAX($F10:$J10),$F10:$J10,0))) -> Sourcing & Backup | Q10: EXAMPLE - replace with real data. New supplier - initial audit pending. | R10: 46241 | S10: =IF($O10="","",IF($L10<>"",100,0)+IF($N10="",0,$N10)+ROW()/100000) -> 8.1001 | T10: =IF($S10="","",IF($A10=SEL_MODEL,$S10,""))
I11: =IF($E11="","",IFERROR(IF(INDEX(SUPPLIERS!$D$4:$D$63,MATCH($E11,SUPPLIERS!$A$4:$A$63,0))="","",INDEX(SUPPLIERS!$D$4:$D$63,MATCH($E11,SUPPLIERS!$A$4:$A$63,0))),"")) | J11: =IF($E11="","",IFERROR(IF(INDEX(SUPPLIERS!$E$4:$E$63,MATCH($E11,SUPPLIERS!$A$4:$A$63,0))="","",INDEX(SUPPLIERS!$E$4:$E$63,MATCH($E11,SUPPLIERS!$A$4:$A$63,0))),"")) | M11: =IF(COUNT($F11:$J11)<5,"",ROUND($F11*W_SRC+$G11*W_QC+$H11*W_CAP+$I11*W_SUP+$J11*W_EXT,1)) | N11: =IF(OR($M11="",$K11=""),"",ROUND($M11*$K11,1)) | O11: =IF($E11="","",IF($L11<>"","CRITICAL (FLAG)",IF(OR($M11="",$K11=""),"NOT SCORED",IF($N11>=T_CRIT,"CRITICAL",IF($N11>=T_MON,"MONITOR","LOW"))))) | P11: =IF($M11="","",INDEX(DriverNames,MATCH(MAX($F11:$J11),$F11:$J11,0))) | S11: =IF($O11="","",IF($L11<>"",100,0)+IF($N11="",0,$N11)+ROW()/100000) | T11: =IF($S11="","",IF($A11=SEL_MODEL,$S11,""))
I12: =IF($E12="","",IFERROR(IF(INDEX(SUPPLIERS!$D$4:$D$63,MATCH($E12,SUPPLIERS!$A$4:$A$63,0))="","",INDEX(SUPPLIERS!$D$4:$D$63,MATCH($E12,SUPPLIERS!$A$4:$A$63,0))),"")) | J12: =IF($E12="","",IFERROR(IF(INDEX(SUPPLIERS!$E$4:$E$63,MATCH($E12,SUPPLIERS!$A$4:$A$63,0))="","",INDEX(SUPPLIERS!$E$4:$E$63,MATCH($E12,SUPPLIERS!$A$4:$A$63,0))),"")) | M12: =IF(COUNT($F12:$J12)<5,"",ROUND($F12*W_SRC+$G12*W_QC+$H12*W_CAP+$I12*W_SUP+$J12*W_EXT,1)) | N12: =IF(OR($M12="",$K12=""),"",ROUND($M12*$K12,1)) | O12: =IF($E12="","",IF($L12<>"","CRITICAL (FLAG)",IF(OR($M12="",$K12=""),"NOT SCORED",IF($N12>=T_CRIT,"CRITICAL",IF($N12>=T_MON,"MONITOR","LOW"))))) | P12: =IF($M12="","",INDEX(DriverNames,MATCH(MAX($F12:$J12),$F12:$J12,0))) | S12: =IF($O12="","",IF($L12<>"",100,0)+IF($N12="",0,$N12)+ROW()/100000) | T12: =IF($S12="","",IF($A12=SEL_MODEL,$S12,""))
I13: =IF($E13="","",IFERROR(IF(INDEX(SUPPLIERS!$D$4:$D$63,MATCH($E13,SUPPLIERS!$A$4:$A$63,0))="","",INDEX(SUPPLIERS!$D$4:$D$63,MATCH($E13,SUPPLIERS!$A$4:$A$63,0))),"")) | J13: =IF($E13="","",IFERROR(IF(INDEX(SUPPLIERS!$E$4:$E$63,MATCH($E13,SUPPLIERS!$A$4:$A$63,0))="","",INDEX(SUPPLIERS!$E$4:$E$63,MATCH($E13,SUPPLIERS!$A$4:$A$63,0))),"")) | M13: =IF(COUNT($F13:$J13)<5,"",ROUND($F13*W_SRC+$G13*W_QC+$H13*W_CAP+$I13*W_SUP+$J13*W_EXT,1)) | N13: =IF(OR($M13="",$K13=""),"",ROUND($M13*$K13,1)) | O13: =IF($E13="","",IF($L13<>"","CRITICAL (FLAG)",IF(OR($M13="",$K13=""),"NOT SCORED",IF($N13>=T_CRIT,"CRITICAL",IF($N13>=T_MON,"MONITOR","LOW"))))) | P13: =IF($M13="","",INDEX(DriverNames,MATCH(MAX($F13:$J13),$F13:$J13,0))) | S13: =IF($O13="","",IF($L13<>"",100,0)+IF($N13="",0,$N13)+ROW()/100000) | T13: =IF($S13="","",IF($A13=SEL_MODEL,$S13,""))
I14: =IF($E14="","",IFERROR(IF(INDEX(SUPPLIERS!$D$4:$D$63,MATCH($E14,SUPPLIERS!$A$4:$A$63,0))="","",INDEX(SUPPLIERS!$D$4:$D$63,MATCH($E14,SUPPLIERS!$A$4:$A$63,0))),"")) | J14: =IF($E14="","",IFERROR(IF(INDEX(SUPPLIERS!$E$4:$E$63,MATCH($E14,SUPPLIERS!$A$4:$A$63,0))="","",INDEX(SUPPLIERS!$E$4:$E$63,MATCH($E14,SUPPLIERS!$A$4:$A$63,0))),"")) | M14: =IF(COUNT($F14:$J14)<5,"",ROUND($F14*W_SRC+$G14*W_QC+$H14*W_CAP+$I14*W_SUP+$J14*W_EXT,1)) | N14: =IF(OR($M14="",$K14=""),"",ROUND($M14*$K14,1)) | O14: =IF($E14="","",IF($L14<>"","CRITICAL (FLAG)",IF(OR($M14="",$K14=""),"NOT SCORED",IF($N14>=T_CRIT,"CRITICAL",IF($N14>=T_MON,"MONITOR","LOW"))))) | P14: =IF($M14="","",INDEX(DriverNames,MATCH(MAX($F14:$J14),$F14:$J14,0))) | S14: =IF($O14="","",IF($L14<>"",100,0)+IF($N14="",0,$N14)+ROW()/100000) | T14: =IF($S14="","",IF($A14=SEL_MODEL,$S14,""))
I15: =IF($E15="","",IFERROR(IF(INDEX(SUPPLIERS!$D$4:$D$63,MATCH($E15,SUPPLIERS!$A$4:$A$63,0))="","",INDEX(SUPPLIERS!$D$4:$D$63,MATCH($E15,SUPPLIERS!$A$4:$A$63,0))),"")) | J15: =IF($E15="","",IFERROR(IF(INDEX(SUPPLIERS!$E$4:$E$63,MATCH($E15,SUPPLIERS!$A$4:$A$63,0))="","",INDEX(SUPPLIERS!$E$4:$E$63,MATCH($E15,SUPPLIERS!$A$4:$A$63,0))),"")) | M15: =IF(COUNT($F15:$J15)<5,"",ROUND($F15*W_SRC+$G15*W_QC+$H15*W_CAP+$I15*W_SUP+$J15*W_EXT,1)) | N15: =IF(OR($M15="",$K15=""),"",ROUND($M15*$K15,1)) | O15: =IF($E15="","",IF($L15<>"","CRITICAL (FLAG)",IF(OR($M15="",$K15=""),"NOT SCORED",IF($N15>=T_CRIT,"CRITICAL",IF($N15>=T_MON,"MONITOR","LOW"))))) | P15: =IF($M15="","",INDEX(DriverNames,MATCH(MAX($F15:$J15),$F15:$J15,0))) | S15: =IF($O15="","",IF($L15<>"",100,0)+IF($N15="",0,$N15)+ROW()/100000) | T15: =IF($S15="","",IF($A15=SEL_MODEL,$S15,""))
I16: =IF($E16="","",IFERROR(IF(INDEX(SUPPLIERS!$D$4:$D$63,MATCH($E16,SUPPLIERS!$A$4:$A$63,0))="","",INDEX(SUPPLIERS!$D$4:$D$63,MATCH($E16,SUPPLIERS!$A$4:$A$63,0))),"")) | J16: =IF($E16="","",IFERROR(IF(INDEX(SUPPLIERS!$E$4:$E$63,MATCH($E16,SUPPLIERS!$A$4:$A$63,0))="","",INDEX(SUPPLIERS!$E$4:$E$63,MATCH($E16,SUPPLIERS!$A$4:$A$63,0))),"")) | M16: =IF(COUNT($F16:$J16)<5,"",ROUND($F16*W_SRC+$G16*W_QC+$H16*W_CAP+$I16*W_SUP+$J16*W_EXT,1)) | N16: =IF(OR($M16="",$K16=""),"",ROUND($M16*$K16,1)) | O16: =IF($E16="","",IF($L16<>"","CRITICAL (FLAG)",IF(OR($M16="",$K16=""),"NOT SCORED",IF($N16>=T_CRIT,"CRITICAL",IF($N16>=T_MON,"MONITOR","LOW"))))) | P16: =IF($M16="","",INDEX(DriverNames,MATCH(MAX($F16:$J16),$F16:$J16,0))) | S16: =IF($O16="","",IF($L16<>"",100,0)+IF($N16="",0,$N16)+ROW()/100000) | T16: =IF($S16="","",IF($A16=SEL_MODEL,$S16,""))
I17: =IF($E17="","",IFERROR(IF(INDEX(SUPPLIERS!$D$4:$D$63,MATCH($E17,SUPPLIERS!$A$4:$A$63,0))="","",INDEX(SUPPLIERS!$D$4:$D$63,MATCH($E17,SUPPLIERS!$A$4:$A$63,0))),"")) | J17: =IF($E17="","",IFERROR(IF(INDEX(SUPPLIERS!$E$4:$E$63,MATCH($E17,SUPPLIERS!$A$4:$A$63,0))="","",INDEX(SUPPLIERS!$E$4:$E$63,MATCH($E17,SUPPLIERS!$A$4:$A$63,0))),"")) | M17: =IF(COUNT($F17:$J17)<5,"",ROUND($F17*W_SRC+$G17*W_QC+$H17*W_CAP+$I17*W_SUP+$J17*W_EXT,1)) | N17: =IF(OR($M17="",$K17=""),"",ROUND($M17*$K17,1)) | O17: =IF($E17="","",IF($L17<>"","CRITICAL (FLAG)",IF(OR($M17="",$K17=""),"NOT SCORED",IF($N17>=T_CRIT,"CRITICAL",IF($N17>=T_MON,"MONITOR","LOW"))))) | P17: =IF($M17="","",INDEX(DriverNames,MATCH(MAX($F17:$J17),$F17:$J17,0))) | S17: =IF($O17="","",IF($L17<>"",100,0)+IF($N17="",0,$N17)+ROW()/100000) | T17: =IF($S17="","",IF($A17=SEL_MODEL,$S17,""))
I18: =IF($E18="","",IFERROR(IF(INDEX(SUPPLIERS!$D$4:$D$63,MATCH($E18,SUPPLIERS!$A$4:$A$63,0))="","",INDEX(SUPPLIERS!$D$4:$D$63,MATCH($E18,SUPPLIERS!$A$4:$A$63,0))),"")) | J18: =IF($E18="","",IFERROR(IF(INDEX(SUPPLIERS!$E$4:$E$63,MATCH($E18,SUPPLIERS!$A$4:$A$63,0))="","",INDEX(SUPPLIERS!$E$4:$E$63,MATCH($E18,SUPPLIERS!$A$4:$A$63,0))),"")) | M18: =IF(COUNT($F18:$J18)<5,"",ROUND($F18*W_SRC+$G18*W_QC+$H18*W_CAP+$I18*W_SUP+$J18*W_EXT,1)) | N18: =IF(OR($M18="",$K18=""),"",ROUND($M18*$K18,1)) | O18: =IF($E18="","",IF($L18<>"","CRITICAL (FLAG)",IF(OR($M18="",$K18=""),"NOT SCORED",IF($N18>=T_CRIT,"CRITICAL",IF($N18>=T_MON,"MONITOR","LOW"))))) | P18: =IF($M18="","",INDEX(DriverNames,MATCH(MAX($F18:$J18),$F18:$J18,0))) | S18: =IF($O18="","",IF($L18<>"",100,0)+IF($N18="",0,$N18)+ROW()/100000) | T18: =IF($S18="","",IF($A18=SEL_MODEL,$S18,""))
I19: =IF($E19="","",IFERROR(IF(INDEX(SUPPLIERS!$D$4:$D$63,MATCH($E19,SUPPLIERS!$A$4:$A$63,0))="","",INDEX(SUPPLIERS!$D$4:$D$63,MATCH($E19,SUPPLIERS!$A$4:$A$63,0))),"")) | J19: =IF($E19="","",IFERROR(IF(INDEX(SUPPLIERS!$E$4:$E$63,MATCH($E19,SUPPLIERS!$A$4:$A$63,0))="","",INDEX(SUPPLIERS!$E$4:$E$63,MATCH($E19,SUPPLIERS!$A$4:$A$63,0))),"")) | M19: =IF(COUNT($F19:$J19)<5,"",ROUND($F19*W_SRC+$G19*W_QC+$H19*W_CAP+$I19*W_SUP+$J19*W_EXT,1)) | N19: =IF(OR($M19="",$K19=""),"",ROUND($M19*$K19,1)) | O19: =IF($E19="","",IF($L19<>"","CRITICAL (FLAG)",IF(OR($M19="",$K19=""),"NOT SCORED",IF($N19>=T_CRIT,"CRITICAL",IF($N19>=T_MON,"MONITOR","LOW"))))) | P19: =IF($M19="","",INDEX(DriverNames,MATCH(MAX($F19:$J19),$F19:$J19,0))) | S19: =IF($O19="","",IF($L19<>"",100,0)+IF($N19="",0,$N19)+ROW()/100000) | T19: =IF($S19="","",IF($A19=SEL_MODEL,$S19,""))
I20: =IF($E20="","",IFERROR(IF(INDEX(SUPPLIERS!$D$4:$D$63,MATCH($E20,SUPPLIERS!$A$4:$A$63,0))="","",INDEX(SUPPLIERS!$D$4:$D$63,MATCH($E20,SUPPLIERS!$A$4:$A$63,0))),"")) | J20: =IF($E20="","",IFERROR(IF(INDEX(SUPPLIERS!$E$4:$E$63,MATCH($E20,SUPPLIERS!$A$4:$A$63,0))="","",INDEX(SUPPLIERS!$E$4:$E$63,MATCH($E20,SUPPLIERS!$A$4:$A$63,0))),"")) | M20: =IF(COUNT($F20:$J20)<5,"",ROUND($F20*W_SRC+$G20*W_QC+$H20*W_CAP+$I20*W_SUP+$J20*W_EXT,1)) | N20: =IF(OR($M20="",$K20=""),"",ROUND($M20*$K20,1)) | O20: =IF($E20="","",IF($L20<>"","CRITICAL (FLAG)",IF(OR($M20="",$K20=""),"NOT SCORED",IF($N20>=T_CRIT,"CRITICAL",IF($N20>=T_MON,"MONITOR","LOW"))))) | P20: =IF($M20="","",INDEX(DriverNames,MATCH(MAX($F20:$J20),$F20:$J20,0))) | S20: =IF($O20="","",IF($L20<>"",100,0)+IF($N20="",0,$N20)+ROW()/100000) | T20: =IF($S20="","",IF($A20=SEL_MODEL,$S20,""))
I21: =IF($E21="","",IFERROR(IF(INDEX(SUPPLIERS!$D$4:$D$63,MATCH($E21,SUPPLIERS!$A$4:$A$63,0))="","",INDEX(SUPPLIERS!$D$4:$D$63,MATCH($E21,SUPPLIERS!$A$4:$A$63,0))),"")) | J21: =IF($E21="","",IFERROR(IF(INDEX(SUPPLIERS!$E$4:$E$63,MATCH($E21,SUPPLIERS!$A$4:$A$63,0))="","",INDEX(SUPPLIERS!$E$4:$E$63,MATCH($E21,SUPPLIERS!$A$4:$A$63,0))),"")) | M21: =IF(COUNT($F21:$J21)<5,"",ROUND($F21*W_SRC+$G21*W_QC+$H21*W_CAP+$I21*W_SUP+$J21*W_EXT,1)) | N21: =IF(OR($M21="",$K21=""),"",ROUND($M21*$K21,1)) | O21: =IF($E21="","",IF($L21<>"","CRITICAL (FLAG)",IF(OR($M21="",$K21=""),"NOT SCORED",IF($N21>=T_CRIT,"CRITICAL",IF($N21>=T_MON,"MONITOR","LOW"))))) | P21: =IF($M21="","",INDEX(DriverNames,MATCH(MAX($F21:$J21),$F21:$J21,0))) | S21: =IF($O21="","",IF($L21<>"",100,0)+IF($N21="",0,$N21)+ROW()/100000) | T21: =IF($S21="","",IF($A21=SEL_MODEL,$S21,""))
I22: =IF($E22="","",IFERROR(IF(INDEX(SUPPLIERS!$D$4:$D$63,MATCH($E22,SUPPLIERS!$A$4:$A$63,0))="","",INDEX(SUPPLIERS!$D$4:$D$63,MATCH($E22,SUPPLIERS!$A$4:$A$63,0))),"")) | J22: =IF($E22="","",IFERROR(IF(INDEX(SUPPLIERS!$E$4:$E$63,MATCH($E22,SUPPLIERS!$A$4:$A$63,0))="","",INDEX(SUPPLIERS!$E$4:$E$63,MATCH($E22,SUPPLIERS!$A$4:$A$63,0))),"")) | M22: =IF(COUNT($F22:$J22)<5,"",ROUND($F22*W_SRC+$G22*W_QC+$H22*W_CAP+$I22*W_SUP+$J22*W_EXT,1)) | N22: =IF(OR($M22="",$K22=""),"",ROUND($M22*$K22,1)) | O22: =IF($E22="","",IF($L22<>"","CRITICAL (FLAG)",IF(OR($M22="",$K22=""),"NOT SCORED",IF($N22>=T_CRIT,"CRITICAL",IF($N22>=T_MON,"MONITOR","LOW"))))) | P22: =IF($M22="","",INDEX(DriverNames,MATCH(MAX($F22:$J22),$F22:$J22,0))) | S22: =IF($O22="","",IF($L22<>"",100,0)+IF($N22="",0,$N22)+ROW()/100000) | T22: =IF($S22="","",IF($A22=SEL_MODEL,$S22,""))
... I304: =IF($E304="","",IFERROR(IF(INDEX(SUPPLIERS!$D$4:$D$63,MATCH($E304,SUPPLIERS!$A$4:$A$63,0))="","",INDEX(SUPPLIERS!$D$4:$D$63,MATCH($E304,SUPPLIERS!$A$4:$A$63,0))),"")) | J304: =IF($E304="","",IFERROR(IF(INDEX(SUPPLIERS!$E$4:$E$63,MATCH($E304,SUPPLIERS!$A$4:$A$63,0))="","",INDEX(SUPPLIERS!$E$4:$E$63,MATCH($E304,SUPPLIERS!$A$4:$A$63,0))),"")) | M304: =IF(COUNT($F304:$J304)<5,"",ROUND($F304*W_SRC+$G304*W_QC+$H304*W_CAP+$I304*W_SUP+$J304*W_EXT,1)) | N304: =IF(OR($M304="",$K304=""),"",ROUND($M304*$K304,1)) | O304: =IF($E304="","",IF($L304<>"","CRITICAL (FLAG)",IF(OR($M304="",$K304=""),"NOT SCORED",IF($N304>=T_CRIT,"CRITICAL",IF($N304>=T_MON,"MONITOR","LOW"))))) | P304: =IF($M304="","",INDEX(DriverNames,MATCH(MAX($F304:$J304),$F304:$J304,0))) | S304: =IF($O304="","",IF($L304<>"",100,0)+IF($N304="",0,$N304)+ROW()/100000) | T304: =IF($S304="","",IF($A304=SEL_MODEL,$S304,""))

Sheet SUPPLIERS
A1: SUPPLIERS
A2: Score each supplier ONCE (two 1-5 scores). Every part linked to this supplier inherits these scores automatically on PART_RISK.
A3: Supplier_Name | B3: Location (City/State, Country) | C3: Status | D3: Supplier_Stability (1-5) | E3: External_Location (1-5) | F3: Certs / Permits (info) | G3: Notes | H3: Parts_Linked | I3: Worst_Band
A4: Parks Family Meats | B4: Warsaw, NC, USA | C4: Approved | D4: 3 | E4: 4 | F4: APHIS specimen permit (exp 12/2026); FDA FSIS | G4: EXAMPLE - small local slaughterhouse; strong relationship. | H4: =IF($A4="","",COUNTIF(PART_RISK!$E$5:$E$304,$A4)) -> 1 | I4: =IF($A4="","",IF(COUNTIFS(PART_RISK!$E$5:$E$304,$A4,PART_RISK!$O$5:$O$304,"CRITICAL*")>0,"CRITICAL",IF(COUNTIFS(PART_RISK!$E$5:$E$304,$A4,PART_RISK!$O$5:$O$304,"MONITOR")>0,"MONITOR",IF(COUNTIFS(PART_RISK!$E$5:$E$304,$A4,PART_RISK!$O$5:$O$304,"LOW")>0,"LOW","NOT SCORED")))) -> MONITOR
A5: Martin's Pork Products | B5: Falcon, NC, USA | C5: Approved | D5: 4 | E5: 4 | F5: APHIS specimen permit (exp 5/2026); FDA FSIS | G5: EXAMPLE - small family business; past power/sanitation issues; flood-prone area. | H5: =IF($A5="","",COUNTIF(PART_RISK!$E$5:$E$304,$A5)) -> 1 | I5: =IF($A5="","",IF(COUNTIFS(PART_RISK!$E$5:$E$304,$A5,PART_RISK!$O$5:$O$304,"CRITICAL*")>0,"CRITICAL",IF(COUNTIFS(PART_RISK!$E$5:$E$304,$A5,PART_RISK!$O$5:$O$304,"MONITOR")>0,"MONITOR",IF(COUNTIFS(PART_RISK!$E$5:$E$304,$A5,PART_RISK!$O$5:$O$304,"LOW")>0,"LOW","NOT SCORED")))) -> CRITICAL
A6: Advanced Plastiform | B6: NC, USA | C6: Approved | D6: 2 | E6: 2 | F6: ISO 9001 | G6: EXAMPLE - established plastics former. | H6: =IF($A6="","",COUNTIF(PART_RISK!$E$5:$E$304,$A6)) -> 1 | I6: =IF($A6="","",IF(COUNTIFS(PART_RISK!$E$5:$E$304,$A6,PART_RISK!$O$5:$O$304,"CRITICAL*")>0,"CRITICAL",IF(COUNTIFS(PART_RISK!$E$5:$E$304,$A6,PART_RISK!$O$5:$O$304,"MONITOR")>0,"MONITOR",IF(COUNTIFS(PART_RISK!$E$5:$E$304,$A6,PART_RISK!$O$5:$O$304,"LOW")>0,"LOW","NOT SCORED")))) -> LOW
A7: Midland Plastics | B7: WI, USA | C7: New | D7: 3 | E7: 2 | F7: ISO 9001 (to verify) | G7: EXAMPLE - new supplier, audit pending. | H7: =IF($A7="","",COUNTIF(PART_RISK!$E$5:$E$304,$A7)) -> 1 | I7: =IF($A7="","",IF(COUNTIFS(PART_RISK!$E$5:$E$304,$A7,PART_RISK!$O$5:$O$304,"CRITICAL*")>0,"CRITICAL",IF(COUNTIFS(PART_RISK!$E$5:$E$304,$A7,PART_RISK!$O$5:$O$304,"MONITOR")>0,"MONITOR",IF(COUNTIFS(PART_RISK!$E$5:$E$304,$A7,PART_RISK!$O$5:$O$304,"LOW")>0,"LOW","NOT SCORED")))) -> MONITOR
A8: Qosina Corp. | B8: Ronkonkoma, NY, USA | C8: Intuitive Corporate | D8: 1 | E8: 2 | F8: ISO 9001, ISO 13485 | G8: EXAMPLE - large catalog distributor. | H8: =IF($A8="","",COUNTIF(PART_RISK!$E$5:$E$304,$A8)) -> 1 | I8: =IF($A8="","",IF(COUNTIFS(PART_RISK!$E$5:$E$304,$A8,PART_RISK!$O$5:$O$304,"CRITICAL*")>0,"CRITICAL",IF(COUNTIFS(PART_RISK!$E$5:$E$304,$A8,PART_RISK!$O$5:$O$304,"MONITOR")>0,"MONITOR",IF(COUNTIFS(PART_RISK!$E$5:$E$304,$A8,PART_RISK!$O$5:$O$304,"LOW")>0,"LOW","NOT SCORED")))) -> CRITICAL
A9: SNP, Inc. | B9: USA | C9: Approved | D9: 3 | E9: 2 | F9: ISO 9001 | G9: EXAMPLE - chemical blender; single site. | H9: =IF($A9="","",COUNTIF(PART_RISK!$E$5:$E$304,$A9)) -> 1 | I9: =IF($A9="","",IF(COUNTIFS(PART_RISK!$E$5:$E$304,$A9,PART_RISK!$O$5:$O$304,"CRITICAL*")>0,"CRITICAL",IF(COUNTIFS(PART_RISK!$E$5:$E$304,$A9,PART_RISK!$O$5:$O$304,"MONITOR")>0,"MONITOR",IF(COUNTIFS(PART_RISK!$E$5:$E$304,$A9,PART_RISK!$O$5:$O$304,"LOW")>0,"LOW","NOT SCORED")))) -> MONITOR
H10: =IF($A10="","",COUNTIF(PART_RISK!$E$5:$E$304,$A10)) | I10: =IF($A10="","",IF(COUNTIFS(PART_RISK!$E$5:$E$304,$A10,PART_RISK!$O$5:$O$304,"CRITICAL*")>0,"CRITICAL",IF(COUNTIFS(PART_RISK!$E$5:$E$304,$A10,PART_RISK!$O$5:$O$304,"MONITOR")>0,"MONITOR",IF(COUNTIFS(PART_RISK!$E$5:$E$304,$A10,PART_RISK!$O$5:$O$304,"LOW")>0,"LOW","NOT SCORED"))))
H11: =IF($A11="","",COUNTIF(PART_RISK!$E$5:$E$304,$A11)) | I11: =IF($A11="","",IF(COUNTIFS(PART_RISK!$E$5:$E$304,$A11,PART_RISK!$O$5:$O$304,"CRITICAL*")>0,"CRITICAL",IF(COUNTIFS(PART_RISK!$E$5:$E$304,$A11,PART_RISK!$O$5:$O$304,"MONITOR")>0,"MONITOR",IF(COUNTIFS(PART_RISK!$E$5:$E$304,$A11,PART_RISK!$O$5:$O$304,"LOW")>0,"LOW","NOT SCORED"))))
H12: =IF($A12="","",COUNTIF(PART_RISK!$E$5:$E$304,$A12)) | I12: =IF($A12="","",IF(COUNTIFS(PART_RISK!$E$5:$E$304,$A12,PART_RISK!$O$5:$O$304,"CRITICAL*")>0,"CRITICAL",IF(COUNTIFS(PART_RISK!$E$5:$E$304,$A12,PART_RISK!$O$5:$O$304,"MONITOR")>0,"MONITOR",IF(COUNTIFS(PART_RISK!$E$5:$E$304,$A12,PART_RISK!$O$5:$O$304,"LOW")>0,"LOW","NOT SCORED"))))
H13: =IF($A13="","",COUNTIF(PART_RISK!$E$5:$E$304,$A13)) | I13: =IF($A13="","",IF(COUNTIFS(PART_RISK!$E$5:$E$304,$A13,PART_RISK!$O$5:$O$304,"CRITICAL*")>0,"CRITICAL",IF(COUNTIFS(PART_RISK!$E$5:$E$304,$A13,PART_RISK!$O$5:$O$304,"MONITOR")>0,"MONITOR",IF(COUNTIFS(PART_RISK!$E$5:$E$304,$A13,PART_RISK!$O$5:$O$304,"LOW")>0,"LOW","NOT SCORED"))))
H14: =IF($A14="","",COUNTIF(PART_RISK!$E$5:$E$304,$A14)) | I14: =IF($A14="","",IF(COUNTIFS(PART_RISK!$E$5:$E$304,$A14,PART_RISK!$O$5:$O$304,"CRITICAL*")>0,"CRITICAL",IF(COUNTIFS(PART_RISK!$E$5:$E$304,$A14,PART_RISK!$O$5:$O$304,"MONITOR")>0,"MONITOR",IF(COUNTIFS(PART_RISK!$E$5:$E$304,$A14,PART_RISK!$O$5:$O$304,"LOW")>0,"LOW","NOT SCORED"))))
H15: =IF($A15="","",COUNTIF(PART_RISK!$E$5:$E$304,$A15)) | I15: =IF($A15="","",IF(COUNTIFS(PART_RISK!$E$5:$E$304,$A15,PART_RISK!$O$5:$O$304,"CRITICAL*")>0,"CRITICAL",IF(COUNTIFS(PART_RISK!$E$5:$E$304,$A15,PART_RISK!$O$5:$O$304,"MONITOR")>0,"MONITOR",IF(COUNTIFS(PART_RISK!$E$5:$E$304,$A15,PART_RISK!$O$5:$O$304,"LOW")>0,"LOW","NOT SCORED"))))
H16: =IF($A16="","",COUNTIF(PART_RISK!$E$5:$E$304,$A16)) | I16: =IF($A16="","",IF(COUNTIFS(PART_RISK!$E$5:$E$304,$A16,PART_RISK!$O$5:$O$304,"CRITICAL*")>0,"CRITICAL",IF(COUNTIFS(PART_RISK!$E$5:$E$304,$A16,PART_RISK!$O$5:$O$304,"MONITOR")>0,"MONITOR",IF(COUNTIFS(PART_RISK!$E$5:$E$304,$A16,PART_RISK!$O$5:$O$304,"LOW")>0,"LOW","NOT SCORED"))))
H17: =IF($A17="","",COUNTIF(PART_RISK!$E$5:$E$304,$A17)) | I17: =IF($A17="","",IF(COUNTIFS(PART_RISK!$E$5:$E$304,$A17,PART_RISK!$O$5:$O$304,"CRITICAL*")>0,"CRITICAL",IF(COUNTIFS(PART_RISK!$E$5:$E$304,$A17,PART_RISK!$O$5:$O$304,"MONITOR")>0,"MONITOR",IF(COUNTIFS(PART_RISK!$E$5:$E$304,$A17,PART_RISK!$O$5:$O$304,"LOW")>0,"LOW","NOT SCORED"))))
H18: =IF($A18="","",COUNTIF(PART_RISK!$E$5:$E$304,$A18)) | I18: =IF($A18="","",IF(COUNTIFS(PART_RISK!$E$5:$E$304,$A18,PART_RISK!$O$5:$O$304,"CRITICAL*")>0,"CRITICAL",IF(COUNTIFS(PART_RISK!$E$5:$E$304,$A18,PART_RISK!$O$5:$O$304,"MONITOR")>0,"MONITOR",IF(COUNTIFS(PART_RISK!$E$5:$E$304,$A18,PART_RISK!$O$5:$O$304,"LOW")>0,"LOW","NOT SCORED"))))
H19: =IF($A19="","",COUNTIF(PART_RISK!$E$5:$E$304,$A19)) | I19: =IF($A19="","",IF(COUNTIFS(PART_RISK!$E$5:$E$304,$A19,PART_RISK!$O$5:$O$304,"CRITICAL*")>0,"CRITICAL",IF(COUNTIFS(PART_RISK!$E$5:$E$304,$A19,PART_RISK!$O$5:$O$304,"MONITOR")>0,"MONITOR",IF(COUNTIFS(PART_RISK!$E$5:$E$304,$A19,PART_RISK!$O$5:$O$304,"LOW")>0,"LOW","NOT SCORED"))))
H20: =IF($A20="","",COUNTIF(PART_RISK!$E$5:$E$304,$A20)) | I20: =IF($A20="","",IF(COUNTIFS(PART_RISK!$E$5:$E$304,$A20,PART_RISK!$O$5:$O$304,"CRITICAL*")>0,"CRITICAL",IF(COUNTIFS(PART_RISK!$E$5:$E$304,$A20,PART_RISK!$O$5:$O$304,"MONITOR")>0,"MONITOR",IF(COUNTIFS(PART_RISK!$E$5:$E$304,$A20,PART_RISK!$O$5:$O$304,"LOW")>0,"LOW","NOT SCORED"))))
H21: =IF($A21="","",COUNTIF(PART_RISK!$E$5:$E$304,$A21)) | I21: =IF($A21="","",IF(COUNTIFS(PART_RISK!$E$5:$E$304,$A21,PART_RISK!$O$5:$O$304,"CRITICAL*")>0,"CRITICAL",IF(COUNTIFS(PART_RISK!$E$5:$E$304,$A21,PART_RISK!$O$5:$O$304,"MONITOR")>0,"MONITOR",IF(COUNTIFS(PART_RISK!$E$5:$E$304,$A21,PART_RISK!$O$5:$O$304,"LOW")>0,"LOW","NOT SCORED"))))
... H63: =IF($A63="","",COUNTIF(PART_RISK!$E$5:$E$304,$A63)) | I63: =IF($A63="","",IF(COUNTIFS(PART_RISK!$E$5:$E$304,$A63,PART_RISK!$O$5:$O$304,"CRITICAL*")>0,"CRITICAL",IF(COUNTIFS(PART_RISK!$E$5:$E$304,$A63,PART_RISK!$O$5:$O$304,"MONITOR")>0,"MONITOR",IF(COUNTIFS(PART_RISK!$E$5:$E$304,$A63,PART_RISK!$O$5:$O$304,"LOW")>0,"LOW","NOT SCORED"))))

Sheet MODELS
A1: MODELS
A2: Add one row per model / project. Everything except the first two columns fills in automatically from PART_RISK.
A3: Model_Name | B3: Description | C3: Has_Tissue_Parts | D3: Parts | E3: Critical | F3: Monitor | G3: Low | H3: Not_Scored | I3: Max_Risk | J3: Model_Band
A4: Model A - Tissue Trainer (EXAMPLE) | B4: Example model containing tissue and non-tissue parts. | C4: =IF($A4="","",IF(COUNTIFS(PART_RISK!$D$5:$D$304,"Tissue*",PART_RISK!$A$5:$A$304,$A4)>0,"Yes","No")) -> Yes | D4: =IF($A4="","",COUNTIF(PART_RISK!$A$5:$A$304,$A4)) -> 4 | E4: =IF($A4="","",COUNTIFS(PART_RISK!$A$5:$A$304,$A4,PART_RISK!$O$5:$O$304,"CRITICAL*")) -> 2 | F4: =IF($A4="","",COUNTIFS(PART_RISK!$A$5:$A$304,$A4,PART_RISK!$O$5:$O$304,"MONITOR")) -> 1 | G4: =IF($A4="","",COUNTIFS(PART_RISK!$A$5:$A$304,$A4,PART_RISK!$O$5:$O$304,"LOW")) -> 1 | H4: =IF($A4="","",COUNTIFS(PART_RISK!$A$5:$A$304,$A4,PART_RISK!$O$5:$O$304,"NOT SCORED")) -> 0 | I4: =IF($A4="","",IF($E4+$F4+$G4=0,"",_xlfn.MAXIFS(PART_RISK!$N$5:$N$304,PART_RISK!$A$5:$A$304,$A4))) -> 20.5 | J4: =IF($A4="","",IF($E4>0,"CRITICAL",IF($F4>0,"MONITOR",IF($G4>0,"LOW","NOT SCORED")))) -> CRITICAL
A5: Model B - Non-Tissue Kit (EXAMPLE) | B5: Example model containing non-tissue parts only. | C5: =IF($A5="","",IF(COUNTIFS(PART_RISK!$D$5:$D$304,"Tissue*",PART_RISK!$A$5:$A$304,$A5)>0,"Yes","No")) -> No | D5: =IF($A5="","",COUNTIF(PART_RISK!$A$5:$A$304,$A5)) -> 2 | E5: =IF($A5="","",COUNTIFS(PART_RISK!$A$5:$A$304,$A5,PART_RISK!$O$5:$O$304,"CRITICAL*")) -> 0 | F5: =IF($A5="","",COUNTIFS(PART_RISK!$A$5:$A$304,$A5,PART_RISK!$O$5:$O$304,"MONITOR")) -> 2 | G5: =IF($A5="","",COUNTIFS(PART_RISK!$A$5:$A$304,$A5,PART_RISK!$O$5:$O$304,"LOW")) -> 0 | H5: =IF($A5="","",COUNTIFS(PART_RISK!$A$5:$A$304,$A5,PART_RISK!$O$5:$O$304,"NOT SCORED")) -> 0 | I5: =IF($A5="","",IF($E5+$F5+$G5=0,"",_xlfn.MAXIFS(PART_RISK!$N$5:$N$304,PART_RISK!$A$5:$A$304,$A5))) -> 11.6 | J5: =IF($A5="","",IF($E5>0,"CRITICAL",IF($F5>0,"MONITOR",IF($G5>0,"LOW","NOT SCORED")))) -> MONITOR
C6: =IF($A6="","",IF(COUNTIFS(PART_RISK!$D$5:$D$304,"Tissue*",PART_RISK!$A$5:$A$304,$A6)>0,"Yes","No")) | D6: =IF($A6="","",COUNTIF(PART_RISK!$A$5:$A$304,$A6)) | E6: =IF($A6="","",COUNTIFS(PART_RISK!$A$5:$A$304,$A6,PART_RISK!$O$5:$O$304,"CRITICAL*")) | F6: =IF($A6="","",COUNTIFS(PART_RISK!$A$5:$A$304,$A6,PART_RISK!$O$5:$O$304,"MONITOR")) | G6: =IF($A6="","",COUNTIFS(PART_RISK!$A$5:$A$304,$A6,PART_RISK!$O$5:$O$304,"LOW")) | H6: =IF($A6="","",COUNTIFS(PART_RISK!$A$5:$A$304,$A6,PART_RISK!$O$5:$O$304,"NOT SCORED")) | I6: =IF($A6="","",IF($E6+$F6+$G6=0,"",_xlfn.MAXIFS(PART_RISK!$N$5:$N$304,PART_RISK!$A$5:$A$304,$A6))) | J6: =IF($A6="","",IF($E6>0,"CRITICAL",IF($F6>0,"MONITOR",IF($G6>0,"LOW","NOT SCORED"))))
C7: =IF($A7="","",IF(COUNTIFS(PART_RISK!$D$5:$D$304,"Tissue*",PART_RISK!$A$5:$A$304,$A7)>0,"Yes","No")) | D7: =IF($A7="","",COUNTIF(PART_RISK!$A$5:$A$304,$A7)) | E7: =IF($A7="","",COUNTIFS(PART_RISK!$A$5:$A$304,$A7,PART_RISK!$O$5:$O$304,"CRITICAL*")) | F7: =IF($A7="","",COUNTIFS(PART_RISK!$A$5:$A$304,$A7,PART_RISK!$O$5:$O$304,"MONITOR")) | G7: =IF($A7="","",COUNTIFS(PART_RISK!$A$5:$A$304,$A7,PART_RISK!$O$5:$O$304,"LOW")) | H7: =IF($A7="","",COUNTIFS(PART_RISK!$A$5:$A$304,$A7,PART_RISK!$O$5:$O$304,"NOT SCORED")) | I7: =IF($A7="","",IF($E7+$F7+$G7=0,"",_xlfn.MAXIFS(PART_RISK!$N$5:$N$304,PART_RISK!$A$5:$A$304,$A7))) | J7: =IF($A7="","",IF($E7>0,"CRITICAL",IF($F7>0,"MONITOR",IF($G7>0,"LOW","NOT SCORED"))))
C8: =IF($A8="","",IF(COUNTIFS(PART_RISK!$D$5:$D$304,"Tissue*",PART_RISK!$A$5:$A$304,$A8)>0,"Yes","No")) | D8: =IF($A8="","",COUNTIF(PART_RISK!$A$5:$A$304,$A8)) | E8: =IF($A8="","",COUNTIFS(PART_RISK!$A$5:$A$304,$A8,PART_RISK!$O$5:$O$304,"CRITICAL*")) | F8: =IF($A8="","",COUNTIFS(PART_RISK!$A$5:$A$304,$A8,PART_RISK!$O$5:$O$304,"MONITOR")) | G8: =IF($A8="","",COUNTIFS(PART_RISK!$A$5:$A$304,$A8,PART_RISK!$O$5:$O$304,"LOW")) | H8: =IF($A8="","",COUNTIFS(PART_RISK!$A$5:$A$304,$A8,PART_RISK!$O$5:$O$304,"NOT SCORED")) | I8: =IF($A8="","",IF($E8+$F8+$G8=0,"",_xlfn.MAXIFS(PART_RISK!$N$5:$N$304,PART_RISK!$A$5:$A$304,$A8))) | J8: =IF($A8="","",IF($E8>0,"CRITICAL",IF($F8>0,"MONITOR",IF($G8>0,"LOW","NOT SCORED"))))
C9: =IF($A9="","",IF(COUNTIFS(PART_RISK!$D$5:$D$304,"Tissue*",PART_RISK!$A$5:$A$304,$A9)>0,"Yes","No")) | D9: =IF($A9="","",COUNTIF(PART_RISK!$A$5:$A$304,$A9)) | E9: =IF($A9="","",COUNTIFS(PART_RISK!$A$5:$A$304,$A9,PART_RISK!$O$5:$O$304,"CRITICAL*")) | F9: =IF($A9="","",COUNTIFS(PART_RISK!$A$5:$A$304,$A9,PART_RISK!$O$5:$O$304,"MONITOR")) | G9: =IF($A9="","",COUNTIFS(PART_RISK!$A$5:$A$304,$A9,PART_RISK!$O$5:$O$304,"LOW")) | H9: =IF($A9="","",COUNTIFS(PART_RISK!$A$5:$A$304,$A9,PART_RISK!$O$5:$O$304,"NOT SCORED")) | I9: =IF($A9="","",IF($E9+$F9+$G9=0,"",_xlfn.MAXIFS(PART_RISK!$N$5:$N$304,PART_RISK!$A$5:$A$304,$A9))) | J9: =IF($A9="","",IF($E9>0,"CRITICAL",IF($F9>0,"MONITOR",IF($G9>0,"LOW","NOT SCORED"))))
C10: =IF($A10="","",IF(COUNTIFS(PART_RISK!$D$5:$D$304,"Tissue*",PART_RISK!$A$5:$A$304,$A10)>0,"Yes","No")) | D10: =IF($A10="","",COUNTIF(PART_RISK!$A$5:$A$304,$A10)) | E10: =IF($A10="","",COUNTIFS(PART_RISK!$A$5:$A$304,$A10,PART_RISK!$O$5:$O$304,"CRITICAL*")) | F10: =IF($A10="","",COUNTIFS(PART_RISK!$A$5:$A$304,$A10,PART_RISK!$O$5:$O$304,"MONITOR")) | G10: =IF($A10="","",COUNTIFS(PART_RISK!$A$5:$A$304,$A10,PART_RISK!$O$5:$O$304,"LOW")) | H10: =IF($A10="","",COUNTIFS(PART_RISK!$A$5:$A$304,$A10,PART_RISK!$O$5:$O$304,"NOT SCORED")) | I10: =IF($A10="","",IF($E10+$F10+$G10=0,"",_xlfn.MAXIFS(PART_RISK!$N$5:$N$304,PART_RISK!$A$5:$A$304,$A10))) | J10: =IF($A10="","",IF($E10>0,"CRITICAL",IF($F10>0,"MONITOR",IF($G10>0,"LOW","NOT SCORED"))))
C11: =IF($A11="","",IF(COUNTIFS(PART_RISK!$D$5:$D$304,"Tissue*",PART_RISK!$A$5:$A$304,$A11)>0,"Yes","No")) | D11: =IF($A11="","",COUNTIF(PART_RISK!$A$5:$A$304,$A11)) | E11: =IF($A11="","",COUNTIFS(PART_RISK!$A$5:$A$304,$A11,PART_RISK!$O$5:$O$304,"CRITICAL*")) | F11: =IF($A11="","",COUNTIFS(PART_RISK!$A$5:$A$304,$A11,PART_RISK!$O$5:$O$304,"MONITOR")) | G11: =IF($A11="","",COUNTIFS(PART_RISK!$A$5:$A$304,$A11,PART_RISK!$O$5:$O$304,"LOW")) | H11: =IF($A11="","",COUNTIFS(PART_RISK!$A$5:$A$304,$A11,PART_RISK!$O$5:$O$304,"NOT SCORED")) | I11: =IF($A11="","",IF($E11+$F11+$G11=0,"",_xlfn.MAXIFS(PART_RISK!$N$5:$N$304,PART_RISK!$A$5:$A$304,$A11))) | J11: =IF($A11="","",IF($E11>0,"CRITICAL",IF($F11>0,"MONITOR",IF($G11>0,"LOW","NOT SCORED"))))
C12: =IF($A12="","",IF(COUNTIFS(PART_RISK!$D$5:$D$304,"Tissue*",PART_RISK!$A$5:$A$304,$A12)>0,"Yes","No")) | D12: =IF($A12="","",COUNTIF(PART_RISK!$A$5:$A$304,$A12)) | E12: =IF($A12="","",COUNTIFS(PART_RISK!$A$5:$A$304,$A12,PART_RISK!$O$5:$O$304,"CRITICAL*")) | F12: =IF($A12="","",COUNTIFS(PART_RISK!$A$5:$A$304,$A12,PART_RISK!$O$5:$O$304,"MONITOR")) | G12: =IF($A12="","",COUNTIFS(PART_RISK!$A$5:$A$304,$A12,PART_RISK!$O$5:$O$304,"LOW")) | H12: =IF($A12="","",COUNTIFS(PART_RISK!$A$5:$A$304,$A12,PART_RISK!$O$5:$O$304,"NOT SCORED")) | I12: =IF($A12="","",IF($E12+$F12+$G12=0,"",_xlfn.MAXIFS(PART_RISK!$N$5:$N$304,PART_RISK!$A$5:$A$304,$A12))) | J12: =IF($A12="","",IF($E12>0,"CRITICAL",IF($F12>0,"MONITOR",IF($G12>0,"LOW","NOT SCORED"))))
C13: =IF($A13="","",IF(COUNTIFS(PART_RISK!$D$5:$D$304,"Tissue*",PART_RISK!$A$5:$A$304,$A13)>0,"Yes","No")) | D13: =IF($A13="","",COUNTIF(PART_RISK!$A$5:$A$304,$A13)) | E13: =IF($A13="","",COUNTIFS(PART_RISK!$A$5:$A$304,$A13,PART_RISK!$O$5:$O$304,"CRITICAL*")) | F13: =IF($A13="","",COUNTIFS(PART_RISK!$A$5:$A$304,$A13,PART_RISK!$O$5:$O$304,"MONITOR")) | G13: =IF($A13="","",COUNTIFS(PART_RISK!$A$5:$A$304,$A13,PART_RISK!$O$5:$O$304,"LOW")) | H13: =IF($A13="","",COUNTIFS(PART_RISK!$A$5:$A$304,$A13,PART_RISK!$O$5:$O$304,"NOT SCORED")) | I13: =IF($A13="","",IF($E13+$F13+$G13=0,"",_xlfn.MAXIFS(PART_RISK!$N$5:$N$304,PART_RISK!$A$5:$A$304,$A13))) | J13: =IF($A13="","",IF($E13>0,"CRITICAL",IF($F13>0,"MONITOR",IF($G13>0,"LOW","NOT SCORED"))))
C14: =IF($A14="","",IF(COUNTIFS(PART_RISK!$D$5:$D$304,"Tissue*",PART_RISK!$A$5:$A$304,$A14)>0,"Yes","No")) | D14: =IF($A14="","",COUNTIF(PART_RISK!$A$5:$A$304,$A14)) | E14: =IF($A14="","",COUNTIFS(PART_RISK!$A$5:$A$304,$A14,PART_RISK!$O$5:$O$304,"CRITICAL*")) | F14: =IF($A14="","",COUNTIFS(PART_RISK!$A$5:$A$304,$A14,PART_RISK!$O$5:$O$304,"MONITOR")) | G14: =IF($A14="","",COUNTIFS(PART_RISK!$A$5:$A$304,$A14,PART_RISK!$O$5:$O$304,"LOW")) | H14: =IF($A14="","",COUNTIFS(PART_RISK!$A$5:$A$304,$A14,PART_RISK!$O$5:$O$304,"NOT SCORED")) | I14: =IF($A14="","",IF($E14+$F14+$G14=0,"",_xlfn.MAXIFS(PART_RISK!$N$5:$N$304,PART_RISK!$A$5:$A$304,$A14))) | J14: =IF($A14="","",IF($E14>0,"CRITICAL",IF($F14>0,"MONITOR",IF($G14>0,"LOW","NOT SCORED"))))
