Workbook

Sheet Read Me
A1: Supplier Scorecard — how to use
A3: What this workbook does
A4: Logs every project you run with a supplier, scores it on Cost, Quality, Lead time and Responsiveness (1–5), and rolls it all up so you can see what each supplier is giving you — overall and per process.
A6: Logging a project (Score Log tab)
A7: 1. One row per project / PO. Enter the date, project name, and pick Supplier and Process from the dropdowns.
A8: 2. Score the four criteria 1–5 — the Rubric tab defines what each number means. Each score has its own notes column; use it for the 'why'.
A9: 3. Overall is calculated automatically from the weights in Settings (defaults: Quality 30%, Cost 25%, Lead time 25%, Responsiveness 20% — edit the yellow cells anytime).
A10: 4. Cost data and Delivery data columns are optional — leave them blank when you don't have the numbers. When filled, the sheet computes cost variance, days late, and on-time %.
A12: Reading the Dashboard tab
A13: Supplier scorecard: one line per supplier — project count, average score per criterion, weighted overall, on-time %, average cost variance, and the date last used. The chart compares overall averages.
A14: By-process comparison: average overall score for each supplier × process pairing, so you can see who is strongest at injection molding vs 3D printing vs thermoforming.
A16: Color legend
... A26: Built with Claude, 2026-07-25. Example data and default weights were set for illustration — every assumption is editable.

Sheet Score Log
A1: Supplier Score Log | E1: One row per project. White cells = you type; gray columns = automatic. Gray italic rows are examples — replace them. Rubric tab defines the 1–5 scale.
A2: Project info | F2: Scores 1–5 & notes (Overall is automatic) | O2: Cost data (optional) | R2: Delivery data (optional)
A3: Date | B3: Project | C3: Supplier | D3: Process / part type | E3: Part description | F3: Cost (1–5) | G3: Cost notes | H3: Quality (1–5) | I3: Quality notes | J3: Lead time (1–5) | K3: Lead time notes | L3: Responsiveness (1–5) | M3: Responsiveness notes | N3: Overall (auto) | O3: Quoted cost | P3: Actual cost | Q3: Cost var % (auto) | R3: Promised delivery | S3: Actual delivery | T3: Days late (auto) | U3: On time? (auto) | V3: General notes
A4: 46174 | B4: Gyn 2.0 | C4: Fictiv | D4: Injection molding | E4: Uterus Insert | F4: 4 | G4: 35% (average) under comparable quotes | H4: 5 | I4: Zero rejects at incoming inspection | J4: 4 | K4: Parts came on time. | L4: 5 | M4: 24 hours spam of replies and thorough. | N4: =IF(COUNT(F4,H4,J4,L4)<4,"",ROUND(F4*Settings!$B$4+H4*Settings!$B$5+J4*Settings!$B$6+L4*Settings!$B$7,2)) -> 4.5 | O4: 20585.77 | P4: 6939 | Q4: =IF(OR(O4="",P4="",O4=0),"",(P4-O4)/O4) -> -0.66292249 | R4: 46216 | S4: 46216 | T4: =IF(OR(R4="",S4=""),"",S4-R4) -> 0 | U4: =IF(T4="","",IF(T4<=0,"Yes","No")) -> Yes | V4: Good quality overall, communications, lead time and responsiveness
A5: 46174 | B5: Gyn 2.0 | C5: Fictiv | D5: Injection molding | E5: End Plate | F5: 4 | G5: 35% (average) under comparable quotes | H5: 5 | I5: Zero rejects at incoming inspection | J5: 4 | K5: Parts came on time. | L5: 5 | M5: 24 hours spam of replies and thorough. | N5: =IF(COUNT(F5,H5,J5,L5)<4,"",ROUND(F5*Settings!$B$4+H5*Settings!$B$5+J5*Settings!$B$6+L5*Settings!$B$7,2)) -> 4.5 | O5: 20585.77 | P5: 6939 | Q5: =IF(OR(O5="",P5="",O5=0),"",(P5-O5)/O5) -> -0.66292249 | R5: 46216 | S5: 46216 | T5: =IF(OR(R5="",S5=""),"",S5-R5) -> 0 | U5: =IF(T5="","",IF(T5<=0,"Yes","No")) -> Yes | V5: Good quality overall, communications, lead time and responsiveness
A6: 46027 | C6: Advanced Plastiform | D6: Thermoforming | E6: Suppine chest base | M6: Responsive to inquiries and provided revised timelines, but Intuitive frequently had to request status updates
N10: =IF(COUNT(F10,H10,J10,L10)<4,"",ROUND(F10*Settings!$B$4+H10*Settings!$B$5+J10*Settings!$B$6+L10*Settings!$B$7,2)) | Q10: =IF(OR(O10="",P10="",O10=0),"",(P10-O10)/O10) | T10: =IF(OR(R10="",S10=""),"",S10-R10) | U10: =IF(T10="","",IF(T10<=0,"Yes","No"))
N11: =IF(COUNT(F11,H11,J11,L11)<4,"",ROUND(F11*Settings!$B$4+H11*Settings!$B$5+J11*Settings!$B$6+L11*Settings!$B$7,2)) | Q11: =IF(OR(O11="",P11="",O11=0),"",(P11-O11)/O11) | T11: =IF(OR(R11="",S11=""),"",S11-R11) | U11: =IF(T11="","",IF(T11<=0,"Yes","No"))
N12: =IF(COUNT(F12,H12,J12,L12)<4,"",ROUND(F12*Settings!$B$4+H12*Settings!$B$5+J12*Settings!$B$6+L12*Settings!$B$7,2)) | Q12: =IF(OR(O12="",P12="",O12=0),"",(P12-O12)/O12) | T12: =IF(OR(R12="",S12=""),"",S12-R12) | U12: =IF(T12="","",IF(T12<=0,"Yes","No"))
N13: =IF(COUNT(F13,H13,J13,L13)<4,"",ROUND(F13*Settings!$B$4+H13*Settings!$B$5+J13*Settings!$B$6+L13*Settings!$B$7,2)) | Q13: =IF(OR(O13="",P13="",O13=0),"",(P13-O13)/O13) | T13: =IF(OR(R13="",S13=""),"",S13-R13) | U13: =IF(T13="","",IF(T13<=0,"Yes","No"))
N14: =IF(COUNT(F14,H14,J14,L14)<4,"",ROUND(F14*Settings!$B$4+H14*Settings!$B$5+J14*Settings!$B$6+L14*Settings!$B$7,2)) | Q14: =IF(OR(O14="",P14="",O14=0),"",(P14-O14)/O14) | T14: =IF(OR(R14="",S14=""),"",S14-R14) | U14: =IF(T14="","",IF(T14<=0,"Yes","No"))
N15: =IF(COUNT(F15,H15,J15,L15)<4,"",ROUND(F15*Settings!$B$4+H15*Settings!$B$5+J15*Settings!$B$6+L15*Settings!$B$7,2)) | Q15: =IF(OR(O15="",P15="",O15=0),"",(P15-O15)/O15) | T15: =IF(OR(R15="",S15=""),"",S15-R15) | U15: =IF(T15="","",IF(T15<=0,"Yes","No"))
N16: =IF(COUNT(F16,H16,J16,L16)<4,"",ROUND(F16*Settings!$B$4+H16*Settings!$B$5+J16*Settings!$B$6+L16*Settings!$B$7,2)) | Q16: =IF(OR(O16="",P16="",O16=0),"",(P16-O16)/O16) | T16: =IF(OR(R16="",S16=""),"",S16-R16) | U16: =IF(T16="","",IF(T16<=0,"Yes","No"))
N17: =IF(COUNT(F17,H17,J17,L17)<4,"",ROUND(F17*Settings!$B$4+H17*Settings!$B$5+J17*Settings!$B$6+L17*Settings!$B$7,2)) | Q17: =IF(OR(O17="",P17="",O17=0),"",(P17-O17)/O17) | T17: =IF(OR(R17="",S17=""),"",S17-R17) | U17: =IF(T17="","",IF(T17<=0,"Yes","No"))
N18: =IF(COUNT(F18,H18,J18,L18)<4,"",ROUND(F18*Settings!$B$4+H18*Settings!$B$5+J18*Settings!$B$6+L18*Settings!$B$7,2)) | Q18: =IF(OR(O18="",P18="",O18=0),"",(P18-O18)/O18) | T18: =IF(OR(R18="",S18=""),"",S18-R18) | U18: =IF(T18="","",IF(T18<=0,"Yes","No"))
N19: =IF(COUNT(F19,H19,J19,L19)<4,"",ROUND(F19*Settings!$B$4+H19*Settings!$B$5+J19*Settings!$B$6+L19*Settings!$B$7,2)) | Q19: =IF(OR(O19="",P19="",O19=0),"",(P19-O19)/O19) | T19: =IF(OR(R19="",S19=""),"",S19-R19) | U19: =IF(T19="","",IF(T19<=0,"Yes","No"))
N20: =IF(COUNT(F20,H20,J20,L20)<4,"",ROUND(F20*Settings!$B$4+H20*Settings!$B$5+J20*Settings!$B$6+L20*Settings!$B$7,2)) | Q20: =IF(OR(O20="",P20="",O20=0),"",(P20-O20)/O20) | T20: =IF(OR(R20="",S20=""),"",S20-R20) | U20: =IF(T20="","",IF(T20<=0,"Yes","No"))
N21: =IF(COUNT(F21,H21,J21,L21)<4,"",ROUND(F21*Settings!$B$4+H21*Settings!$B$5+J21*Settings!$B$6+L21*Settings!$B$7,2)) | Q21: =IF(OR(O21="",P21="",O21=0),"",(P21-O21)/O21) | T21: =IF(OR(R21="",S21=""),"",S21-R21) | U21: =IF(T21="","",IF(T21<=0,"Yes","No"))
... N204: =IF(COUNT(F204,H204,J204,L204)<4,"",ROUND(F204*Settings!$B$4+H204*Settings!$B$5+J204*Settings!$B$6+L204*Settings!$B$7,2)) | Q204: =IF(OR(O204="",P204="",O204=0),"",(P204-O204)/O204) | T204: =IF(OR(R204="",S204=""),"",S204-R204) | U204: =IF(T204="","",IF(T204<=0,"Yes","No"))

Sheet Dashboard
A1: Supplier Dashboard
A2: Everything on this tab is automatic — it updates as you log projects. '–' means no data yet.
A3: Supplier scorecard
A4: Supplier | B4: Projects | C4: Avg Cost | D4: Avg Quality | E4: Avg Lead time | F4: Avg Responsiveness | G4: Avg Overall | H4: On-time % | I4: Avg cost var % | J4: Last project
A5: =IF(Suppliers!A3="","",Suppliers!A3) -> Fictiv | B5: =IF($A5="","",COUNTIFS('Score Log'!$C$4:$C$204,$A5)) -> 2 | C5: =IF($A5="","",IFERROR(ROUND(AVERAGEIFS('Score Log'!$F$4:$F$204,'Score Log'!$C$4:$C$204,$A5),2),"–")) -> 4 | D5: =IF($A5="","",IFERROR(ROUND(AVERAGEIFS('Score Log'!$H$4:$H$204,'Score Log'!$C$4:$C$204,$A5),2),"–")) -> 5 | E5: =IF($A5="","",IFERROR(ROUND(AVERAGEIFS('Score Log'!$J$4:$J$204,'Score Log'!$C$4:$C$204,$A5),2),"–")) -> 4 | F5: =IF($A5="","",IFERROR(ROUND(AVERAGEIFS('Score Log'!$L$4:$L$204,'Score Log'!$C$4:$C$204,$A5),2),"–")) -> 5 | G5: =IF($A5="","",IFERROR(ROUND(AVERAGEIFS('Score Log'!$N$4:$N$204,'Score Log'!$C$4:$C$204,$A5),2),"–")) -> 4.5 | H5: =IF($A5="","",IFERROR(COUNTIFS('Score Log'!$C$4:$C$204,$A5,'Score Log'!$U$4:$U$204,"Yes")/(COUNTIFS('Score Log'!$C$4:$C$204,$A5,'Score Log'!$U$4:$U$204,"Yes")+COUNTIFS('Score Log'!$C$4:$C$204,$A5,'Score Log'!$U$4:$U$204,"No")),"–")) -> 1 | I5: =IF($A5="","",IFERROR(AVERAGEIFS('Score Log'!$Q$4:$Q$204,'Score Log'!$C$4:$C$204,$A5),"–")) -> -0.66292249 | J5: =IF($A5="","",IF($B5=0,"–",_xlfn.MAXIFS('Score Log'!$A$4:$A$204,'Score Log'!$C$4:$C$204,$A5))) -> 46174
A6: =IF(Suppliers!A4="","",Suppliers!A4) -> Advanced Plastiform | B6: =IF($A6="","",COUNTIFS('Score Log'!$C$4:$C$204,$A6)) -> 1 | C6: =IF($A6="","",IFERROR(ROUND(AVERAGEIFS('Score Log'!$F$4:$F$204,'Score Log'!$C$4:$C$204,$A6),2),"–")) -> – | D6: =IF($A6="","",IFERROR(ROUND(AVERAGEIFS('Score Log'!$H$4:$H$204,'Score Log'!$C$4:$C$204,$A6),2),"–")) -> – | E6: =IF($A6="","",IFERROR(ROUND(AVERAGEIFS('Score Log'!$J$4:$J$204,'Score Log'!$C$4:$C$204,$A6),2),"–")) -> – | F6: =IF($A6="","",IFERROR(ROUND(AVERAGEIFS('Score Log'!$L$4:$L$204,'Score Log'!$C$4:$C$204,$A6),2),"–")) -> – | G6: =IF($A6="","",IFERROR(ROUND(AVERAGEIFS('Score Log'!$N$4:$N$204,'Score Log'!$C$4:$C$204,$A6),2),"–")) -> – | H6: =IF($A6="","",IFERROR(COUNTIFS('Score Log'!$C$4:$C$204,$A6,'Score Log'!$U$4:$U$204,"Yes")/(COUNTIFS('Score Log'!$C$4:$C$204,$A6,'Score Log'!$U$4:$U$204,"Yes")+COUNTIFS('Score Log'!$C$4:$C$204,$A6,'Score Log'!$U$4:$U$204,"No")),"–")) -> – | I6: =IF($A6="","",IFERROR(AVERAGEIFS('Score Log'!$Q$4:$Q$204,'Score Log'!$C$4:$C$204,$A6),"–")) -> – | J6: =IF($A6="","",IF($B6=0,"–",_xlfn.MAXIFS('Score Log'!$A$4:$A$204,'Score Log'!$C$4:$C$204,$A6))) -> 46027
A7: =IF(Suppliers!A5="","",Suppliers!A5) | B7: =IF($A7="","",COUNTIFS('Score Log'!$C$4:$C$204,$A7)) | C7: =IF($A7="","",IFERROR(ROUND(AVERAGEIFS('Score Log'!$F$4:$F$204,'Score Log'!$C$4:$C$204,$A7),2),"–")) | D7: =IF($A7="","",IFERROR(ROUND(AVERAGEIFS('Score Log'!$H$4:$H$204,'Score Log'!$C$4:$C$204,$A7),2),"–")) | E7: =IF($A7="","",IFERROR(ROUND(AVERAGEIFS('Score Log'!$J$4:$J$204,'Score Log'!$C$4:$C$204,$A7),2),"–")) | F7: =IF($A7="","",IFERROR(ROUND(AVERAGEIFS('Score Log'!$L$4:$L$204,'Score Log'!$C$4:$C$204,$A7),2),"–")) | G7: =IF($A7="","",IFERROR(ROUND(AVERAGEIFS('Score Log'!$N$4:$N$204,'Score Log'!$C$4:$C$204,$A7),2),"–")) | H7: =IF($A7="","",IFERROR(COUNTIFS('Score Log'!$C$4:$C$204,$A7,'Score Log'!$U$4:$U$204,"Yes")/(COUNTIFS('Score Log'!$C$4:$C$204,$A7,'Score Log'!$U$4:$U$204,"Yes")+COUNTIFS('Score Log'!$C$4:$C$204,$A7,'Score Log'!$U$4:$U$204,"No")),"–")) | I7: =IF($A7="","",IFERROR(AVERAGEIFS('Score Log'!$Q$4:$Q$204,'Score Log'!$C$4:$C$204,$A7),"–")) | J7: =IF($A7="","",IF($B7=0,"–",_xlfn.MAXIFS('Score Log'!$A$4:$A$204,'Score Log'!$C$4:$C$204,$A7)))
A8: =IF(Suppliers!A6="","",Suppliers!A6) | B8: =IF($A8="","",COUNTIFS('Score Log'!$C$4:$C$204,$A8)) | C8: =IF($A8="","",IFERROR(ROUND(AVERAGEIFS('Score Log'!$F$4:$F$204,'Score Log'!$C$4:$C$204,$A8),2),"–")) | D8: =IF($A8="","",IFERROR(ROUND(AVERAGEIFS('Score Log'!$H$4:$H$204,'Score Log'!$C$4:$C$204,$A8),2),"–")) | E8: =IF($A8="","",IFERROR(ROUND(AVERAGEIFS('Score Log'!$J$4:$J$204,'Score Log'!$C$4:$C$204,$A8),2),"–")) | F8: =IF($A8="","",IFERROR(ROUND(AVERAGEIFS('Score Log'!$L$4:$L$204,'Score Log'!$C$4:$C$204,$A8),2),"–")) | G8: =IF($A8="","",IFERROR(ROUND(AVERAGEIFS('Score Log'!$N$4:$N$204,'Score Log'!$C$4:$C$204,$A8),2),"–")) | H8: =IF($A8="","",IFERROR(COUNTIFS('Score Log'!$C$4:$C$204,$A8,'Score Log'!$U$4:$U$204,"Yes")/(COUNTIFS('Score Log'!$C$4:$C$204,$A8,'Score Log'!$U$4:$U$204,"Yes")+COUNTIFS('Score Log'!$C$4:$C$204,$A8,'Score Log'!$U$4:$U$204,"No")),"–")) | I8: =IF($A8="","",IFERROR(AVERAGEIFS('Score Log'!$Q$4:$Q$204,'Score Log'!$C$4:$C$204,$A8),"–")) | J8: =IF($A8="","",IF($B8=0,"–",_xlfn.MAXIFS('Score Log'!$A$4:$A$204,'Score Log'!$C$4:$C$204,$A8)))
A9: =IF(Suppliers!A7="","",Suppliers!A7) | B9: =IF($A9="","",COUNTIFS('Score Log'!$C$4:$C$204,$A9)) | C9: =IF($A9="","",IFERROR(ROUND(AVERAGEIFS('Score Log'!$F$4:$F$204,'Score Log'!$C$4:$C$204,$A9),2),"–")) | D9: =IF($A9="","",IFERROR(ROUND(AVERAGEIFS('Score Log'!$H$4:$H$204,'Score Log'!$C$4:$C$204,$A9),2),"–")) | E9: =IF($A9="","",IFERROR(ROUND(AVERAGEIFS('Score Log'!$J$4:$J$204,'Score Log'!$C$4:$C$204,$A9),2),"–")) | F9: =IF($A9="","",IFERROR(ROUND(AVERAGEIFS('Score Log'!$L$4:$L$204,'Score Log'!$C$4:$C$204,$A9),2),"–")) | G9: =IF($A9="","",IFERROR(ROUND(AVERAGEIFS('Score Log'!$N$4:$N$204,'Score Log'!$C$4:$C$204,$A9),2),"–")) | H9: =IF($A9="","",IFERROR(COUNTIFS('Score Log'!$C$4:$C$204,$A9,'Score Log'!$U$4:$U$204,"Yes")/(COUNTIFS('Score Log'!$C$4:$C$204,$A9,'Score Log'!$U$4:$U$204,"Yes")+COUNTIFS('Score Log'!$C$4:$C$204,$A9,'Score Log'!$U$4:$U$204,"No")),"–")) | I9: =IF($A9="","",IFERROR(AVERAGEIFS('Score Log'!$Q$4:$Q$204,'Score Log'!$C$4:$C$204,$A9),"–")) | J9: =IF($A9="","",IF($B9=0,"–",_xlfn.MAXIFS('Score Log'!$A$4:$A$204,'Score Log'!$C$4:$C$204,$A9)))
A10: =IF(Suppliers!A8="","",Suppliers!A8) | B10: =IF($A10="","",COUNTIFS('Score Log'!$C$4:$C$204,$A10)) | C10: =IF($A10="","",IFERROR(ROUND(AVERAGEIFS('Score Log'!$F$4:$F$204,'Score Log'!$C$4:$C$204,$A10),2),"–")) | D10: =IF($A10="","",IFERROR(ROUND(AVERAGEIFS('Score Log'!$H$4:$H$204,'Score Log'!$C$4:$C$204,$A10),2),"–")) | E10: =IF($A10="","",IFERROR(ROUND(AVERAGEIFS('Score Log'!$J$4:$J$204,'Score Log'!$C$4:$C$204,$A10),2),"–")) | F10: =IF($A10="","",IFERROR(ROUND(AVERAGEIFS('Score Log'!$L$4:$L$204,'Score Log'!$C$4:$C$204,$A10),2),"–")) | G10: =IF($A10="","",IFERROR(ROUND(AVERAGEIFS('Score Log'!$N$4:$N$204,'Score Log'!$C$4:$C$204,$A10),2),"–")) | H10: =IF($A10="","",IFERROR(COUNTIFS('Score Log'!$C$4:$C$204,$A10,'Score Log'!$U$4:$U$204,"Yes")/(COUNTIFS('Score Log'!$C$4:$C$204,$A10,'Score Log'!$U$4:$U$204,"Yes")+COUNTIFS('Score Log'!$C$4:$C$204,$A10,'Score Log'!$U$4:$U$204,"No")),"–")) | I10: =IF($A10="","",IFERROR(AVERAGEIFS('Score Log'!$Q$4:$Q$204,'Score Log'!$C$4:$C$204,$A10),"–")) | J10: =IF($A10="","",IF($B10=0,"–",_xlfn.MAXIFS('Score Log'!$A$4:$A$204,'Score Log'!$C$4:$C$204,$A10)))
A11: =IF(Suppliers!A9="","",Suppliers!A9) | B11: =IF($A11="","",COUNTIFS('Score Log'!$C$4:$C$204,$A11)) | C11: =IF($A11="","",IFERROR(ROUND(AVERAGEIFS('Score Log'!$F$4:$F$204,'Score Log'!$C$4:$C$204,$A11),2),"–")) | D11: =IF($A11="","",IFERROR(ROUND(AVERAGEIFS('Score Log'!$H$4:$H$204,'Score Log'!$C$4:$C$204,$A11),2),"–")) | E11: =IF($A11="","",IFERROR(ROUND(AVERAGEIFS('Score Log'!$J$4:$J$204,'Score Log'!$C$4:$C$204,$A11),2),"–")) | F11: =IF($A11="","",IFERROR(ROUND(AVERAGEIFS('Score Log'!$L$4:$L$204,'Score Log'!$C$4:$C$204,$A11),2),"–")) | G11: =IF($A11="","",IFERROR(ROUND(AVERAGEIFS('Score Log'!$N$4:$N$204,'Score Log'!$C$4:$C$204,$A11),2),"–")) | H11: =IF($A11="","",IFERROR(COUNTIFS('Score Log'!$C$4:$C$204,$A11,'Score Log'!$U$4:$U$204,"Yes")/(COUNTIFS('Score Log'!$C$4:$C$204,$A11,'Score Log'!$U$4:$U$204,"Yes")+COUNTIFS('Score Log'!$C$4:$C$204,$A11,'Score Log'!$U$4:$U$204,"No")),"–")) | I11: =IF($A11="","",IFERROR(AVERAGEIFS('Score Log'!$Q$4:$Q$204,'Score Log'!$C$4:$C$204,$A11),"–")) | J11: =IF($A11="","",IF($B11=0,"–",_xlfn.MAXIFS('Score Log'!$A$4:$A$204,'Score Log'!$C$4:$C$204,$A11)))
A12: =IF(Suppliers!A10="","",Suppliers!A10) | B12: =IF($A12="","",COUNTIFS('Score Log'!$C$4:$C$204,$A12)) | C12: =IF($A12="","",IFERROR(ROUND(AVERAGEIFS('Score Log'!$F$4:$F$204,'Score Log'!$C$4:$C$204,$A12),2),"–")) | D12: =IF($A12="","",IFERROR(ROUND(AVERAGEIFS('Score Log'!$H$4:$H$204,'Score Log'!$C$4:$C$204,$A12),2),"–")) | E12: =IF($A12="","",IFERROR(ROUND(AVERAGEIFS('Score Log'!$J$4:$J$204,'Score Log'!$C$4:$C$204,$A12),2),"–")) | F12: =IF($A12="","",IFERROR(ROUND(AVERAGEIFS('Score Log'!$L$4:$L$204,'Score Log'!$C$4:$C$204,$A12),2),"–")) | G12: =IF($A12="","",IFERROR(ROUND(AVERAGEIFS('Score Log'!$N$4:$N$204,'Score Log'!$C$4:$C$204,$A12),2),"–")) | H12: =IF($A12="","",IFERROR(COUNTIFS('Score Log'!$C$4:$C$204,$A12,'Score Log'!$U$4:$U$204,"Yes")/(COUNTIFS('Score Log'!$C$4:$C$204,$A12,'Score Log'!$U$4:$U$204,"Yes")+COUNTIFS('Score Log'!$C$4:$C$204,$A12,'Score Log'!$U$4:$U$204,"No")),"–")) | I12: =IF($A12="","",IFERROR(AVERAGEIFS('Score Log'!$Q$4:$Q$204,'Score Log'!$C$4:$C$204,$A12),"–")) | J12: =IF($A12="","",IF($B12=0,"–",_xlfn.MAXIFS('Score Log'!$A$4:$A$204,'Score Log'!$C$4:$C$204,$A12)))
A13: =IF(Suppliers!A11="","",Suppliers!A11) | B13: =IF($A13="","",COUNTIFS('Score Log'!$C$4:$C$204,$A13)) | C13: =IF($A13="","",IFERROR(ROUND(AVERAGEIFS('Score Log'!$F$4:$F$204,'Score Log'!$C$4:$C$204,$A13),2),"–")) | D13: =IF($A13="","",IFERROR(ROUND(AVERAGEIFS('Score Log'!$H$4:$H$204,'Score Log'!$C$4:$C$204,$A13),2),"–")) | E13: =IF($A13="","",IFERROR(ROUND(AVERAGEIFS('Score Log'!$J$4:$J$204,'Score Log'!$C$4:$C$204,$A13),2),"–")) | F13: =IF($A13="","",IFERROR(ROUND(AVERAGEIFS('Score Log'!$L$4:$L$204,'Score Log'!$C$4:$C$204,$A13),2),"–")) | G13: =IF($A13="","",IFERROR(ROUND(AVERAGEIFS('Score Log'!$N$4:$N$204,'Score Log'!$C$4:$C$204,$A13),2),"–")) | H13: =IF($A13="","",IFERROR(COUNTIFS('Score Log'!$C$4:$C$204,$A13,'Score Log'!$U$4:$U$204,"Yes")/(COUNTIFS('Score Log'!$C$4:$C$204,$A13,'Score Log'!$U$4:$U$204,"Yes")+COUNTIFS('Score Log'!$C$4:$C$204,$A13,'Score Log'!$U$4:$U$204,"No")),"–")) | I13: =IF($A13="","",IFERROR(AVERAGEIFS('Score Log'!$Q$4:$Q$204,'Score Log'!$C$4:$C$204,$A13),"–")) | J13: =IF($A13="","",IF($B13=0,"–",_xlfn.MAXIFS('Score Log'!$A$4:$A$204,'Score Log'!$C$4:$C$204,$A13)))
A14: =IF(Suppliers!A12="","",Suppliers!A12) | B14: =IF($A14="","",COUNTIFS('Score Log'!$C$4:$C$204,$A14)) | C14: =IF($A14="","",IFERROR(ROUND(AVERAGEIFS('Score Log'!$F$4:$F$204,'Score Log'!$C$4:$C$204,$A14),2),"–")) | D14: =IF($A14="","",IFERROR(ROUND(AVERAGEIFS('Score Log'!$H$4:$H$204,'Score Log'!$C$4:$C$204,$A14),2),"–")) | E14: =IF($A14="","",IFERROR(ROUND(AVERAGEIFS('Score Log'!$J$4:$J$204,'Score Log'!$C$4:$C$204,$A14),2),"–")) | F14: =IF($A14="","",IFERROR(ROUND(AVERAGEIFS('Score Log'!$L$4:$L$204,'Score Log'!$C$4:$C$204,$A14),2),"–")) | G14: =IF($A14="","",IFERROR(ROUND(AVERAGEIFS('Score Log'!$N$4:$N$204,'Score Log'!$C$4:$C$204,$A14),2),"–")) | H14: =IF($A14="","",IFERROR(COUNTIFS('Score Log'!$C$4:$C$204,$A14,'Score Log'!$U$4:$U$204,"Yes")/(COUNTIFS('Score Log'!$C$4:$C$204,$A14,'Score Log'!$U$4:$U$204,"Yes")+COUNTIFS('Score Log'!$C$4:$C$204,$A14,'Score Log'!$U$4:$U$204,"No")),"–")) | I14: =IF($A14="","",IFERROR(AVERAGEIFS('Score Log'!$Q$4:$Q$204,'Score Log'!$C$4:$C$204,$A14),"–")) | J14: =IF($A14="","",IF($B14=0,"–",_xlfn.MAXIFS('Score Log'!$A$4:$A$204,'Score Log'!$C$4:$C$204,$A14)))
A15: =IF(Suppliers!A13="","",Suppliers!A13) | B15: =IF($A15="","",COUNTIFS('Score Log'!$C$4:$C$204,$A15)) | C15: =IF($A15="","",IFERROR(ROUND(AVERAGEIFS('Score Log'!$F$4:$F$204,'Score Log'!$C$4:$C$204,$A15),2),"–")) | D15: =IF($A15="","",IFERROR(ROUND(AVERAGEIFS('Score Log'!$H$4:$H$204,'Score Log'!$C$4:$C$204,$A15),2),"–")) | E15: =IF($A15="","",IFERROR(ROUND(AVERAGEIFS('Score Log'!$J$4:$J$204,'Score Log'!$C$4:$C$204,$A15),2),"–")) | F15: =IF($A15="","",IFERROR(ROUND(AVERAGEIFS('Score Log'!$L$4:$L$204,'Score Log'!$C$4:$C$204,$A15),2),"–")) | G15: =IF($A15="","",IFERROR(ROUND(AVERAGEIFS('Score Log'!$N$4:$N$204,'Score Log'!$C$4:$C$204,$A15),2),"–")) | H15: =IF($A15="","",IFERROR(COUNTIFS('Score Log'!$C$4:$C$204,$A15,'Score Log'!$U$4:$U$204,"Yes")/(COUNTIFS('Score Log'!$C$4:$C$204,$A15,'Score Log'!$U$4:$U$204,"Yes")+COUNTIFS('Score Log'!$C$4:$C$204,$A15,'Score Log'!$U$4:$U$204,"No")),"–")) | I15: =IF($A15="","",IFERROR(AVERAGEIFS('Score Log'!$Q$4:$Q$204,'Score Log'!$C$4:$C$204,$A15),"–")) | J15: =IF($A15="","",IF($B15=0,"–",_xlfn.MAXIFS('Score Log'!$A$4:$A$204,'Score Log'!$C$4:$C$204,$A15)))
A16: =IF(Suppliers!A14="","",Suppliers!A14) | B16: =IF($A16="","",COUNTIFS('Score Log'!$C$4:$C$204,$A16)) | C16: =IF($A16="","",IFERROR(ROUND(AVERAGEIFS('Score Log'!$F$4:$F$204,'Score Log'!$C$4:$C$204,$A16),2),"–")) | D16: =IF($A16="","",IFERROR(ROUND(AVERAGEIFS('Score Log'!$H$4:$H$204,'Score Log'!$C$4:$C$204,$A16),2),"–")) | E16: =IF($A16="","",IFERROR(ROUND(AVERAGEIFS('Score Log'!$J$4:$J$204,'Score Log'!$C$4:$C$204,$A16),2),"–")) | F16: =IF($A16="","",IFERROR(ROUND(AVERAGEIFS('Score Log'!$L$4:$L$204,'Score Log'!$C$4:$C$204,$A16),2),"–")) | G16: =IF($A16="","",IFERROR(ROUND(AVERAGEIFS('Score Log'!$N$4:$N$204,'Score Log'!$C$4:$C$204,$A16),2),"–")) | H16: =IF($A16="","",IFERROR(COUNTIFS('Score Log'!$C$4:$C$204,$A16,'Score Log'!$U$4:$U$204,"Yes")/(COUNTIFS('Score Log'!$C$4:$C$204,$A16,'Score Log'!$U$4:$U$204,"Yes")+COUNTIFS('Score Log'!$C$4:$C$204,$A16,'Score Log'!$U$4:$U$204,"No")),"–")) | I16: =IF($A16="","",IFERROR(AVERAGEIFS('Score Log'!$Q$4:$Q$204,'Score Log'!$C$4:$C$204,$A16),"–")) | J16: =IF($A16="","",IF($B16=0,"–",_xlfn.MAXIFS('Score Log'!$A$4:$A$204,'Score Log'!$C$4:$C$204,$A16)))
... A34: =IF(Suppliers!A32="","",Suppliers!A32) | B34: =IF($A34="","",COUNTIFS('Score Log'!$C$4:$C$204,$A34)) | C34: =IF($A34="","",IFERROR(ROUND(AVERAGEIFS('Score Log'!$F$4:$F$204,'Score Log'!$C$4:$C$204,$A34),2),"–")) | D34: =IF($A34="","",IFERROR(ROUND(AVERAGEIFS('Score Log'!$H$4:$H$204,'Score Log'!$C$4:$C$204,$A34),2),"–")) | E34: =IF($A34="","",IFERROR(ROUND(AVERAGEIFS('Score Log'!$J$4:$J$204,'Score Log'!$C$4:$C$204,$A34),2),"–")) | F34: =IF($A34="","",IFERROR(ROUND(AVERAGEIFS('Score Log'!$L$4:$L$204,'Score Log'!$C$4:$C$204,$A34),2),"–")) | G34: =IF($A34="","",IFERROR(ROUND(AVERAGEIFS('Score Log'!$N$4:$N$204,'Score Log'!$C$4:$C$204,$A34),2),"–")) | H34: =IF($A34="","",IFERROR(COUNTIFS('Score Log'!$C$4:$C$204,$A34,'Score Log'!$U$4:$U$204,"Yes")/(COUNTIFS('Score Log'!$C$4:$C$204,$A34,'Score Log'!$U$4:$U$204,"Yes")+COUNTIFS('Score Log'!$C$4:$C$204,$A34,'Score Log'!$U$4:$U$204,"No")),"–")) | I34: =IF($A34="","",IFERROR(AVERAGEIFS('Score Log'!$Q$4:$Q$204,'Score Log'!$C$4:$C$204,$A34),"–")) | J34: =IF($A34="","",IF($B34=0,"–",_xlfn.MAXIFS('Score Log'!$A$4:$A$204,'Score Log'!$C$4:$C$204,$A34)))
A38: By-process comparison — average overall score
A39: Rows mirror the process list in Settings (first 20); columns mirror the first 10 suppliers. Blank = no projects yet for that pairing.
A41: Process / part type | B41: Projects | C41: =IF(A5="","",A5) -> Fictiv | D41: =IF(A6="","",A6) -> Advanced Plastiform | E41: =IF(A7="","",A7) | F41: =IF(A8="","",A8) | G41: =IF(A9="","",A9) | H41: =IF(A10="","",A10) | I41: =IF(A11="","",A11) | J41: =IF(A12="","",A12) | K41: =IF(A13="","",A13) | L41: =IF(A14="","",A14)
A42: =IF(Settings!D4="","",Settings!D4) -> Thermoforming | B42: =IF($A42="","",COUNTIFS('Score Log'!$D$4:$D$204,$A42)) -> 1 | C42: =IF(OR(C$41="",$A42=""),"",IFERROR(ROUND(AVERAGEIFS('Score Log'!$N$4:$N$204,'Score Log'!$C$4:$C$204,C$41,'Score Log'!$D$4:$D$204,$A42),2),"")) | D42: =IF(OR(D$41="",$A42=""),"",IFERROR(ROUND(AVERAGEIFS('Score Log'!$N$4:$N$204,'Score Log'!$C$4:$C$204,D$41,'Score Log'!$D$4:$D$204,$A42),2),"")) | E42: =IF(OR(E$41="",$A42=""),"",IFERROR(ROUND(AVERAGEIFS('Score Log'!$N$4:$N$204,'Score Log'!$C$4:$C$204,E$41,'Score Log'!$D$4:$D$204,$A42),2),"")) | F42: =IF(OR(F$41="",$A42=""),"",IFERROR(ROUND(AVERAGEIFS('Score Log'!$N$4:$N$204,'Score Log'!$C$4:$C$204,F$41,'Score Log'!$D$4:$D$204,$A42),2),"")) | G42: =IF(OR(G$41="",$A42=""),"",IFERROR(ROUND(AVERAGEIFS('Score Log'!$N$4:$N$204,'Score Log'!$C$4:$C$204,G$41,'Score Log'!$D$4:$D$204,$A42),2),"")) | H42: =IF(OR(H$41="",$A42=""),"",IFERROR(ROUND(AVERAGEIFS('Score Log'!$N$4:$N$204,'Score Log'!$C$4:$C$204,H$41,'Score Log'!$D$4:$D$204,$A42),2),"")) | I42: =IF(OR(I$41="",$A42=""),"",IFERROR(ROUND(AVERAGEIFS('Score Log'!$N$4:$N$204,'Score Log'!$C$4:$C$204,I$41,'Score Log'!$D$4:$D$204,$A42),2),"")) | J42: =IF(OR(J$41="",$A42=""),"",IFERROR(ROUND(AVERAGEIFS('Score Log'!$N$4:$N$204,'Score Log'!$C$4:$C$204,J$41,'Score Log'!$D$4:$D$204,$A42),2),"")) | ... L42: =IF(OR(L$41="",$A42=""),"",IFERROR(ROUND(AVERAGEIFS('Score Log'!$N$4:$N$204,'Score Log'!$C$4:$C$204,L$41,'Score Log'!$D$4:$D$204,$A42),2),""))
A43: =IF(Settings!D5="","",Settings!D5) -> Injection molding | B43: =IF($A43="","",COUNTIFS('Score Log'!$D$4:$D$204,$A43)) -> 2 | C43: =IF(OR(C$41="",$A43=""),"",IFERROR(ROUND(AVERAGEIFS('Score Log'!$N$4:$N$204,'Score Log'!$C$4:$C$204,C$41,'Score Log'!$D$4:$D$204,$A43),2),"")) -> 4.5 | D43: =IF(OR(D$41="",$A43=""),"",IFERROR(ROUND(AVERAGEIFS('Score Log'!$N$4:$N$204,'Score Log'!$C$4:$C$204,D$41,'Score Log'!$D$4:$D$204,$A43),2),"")) | E43: =IF(OR(E$41="",$A43=""),"",IFERROR(ROUND(AVERAGEIFS('Score Log'!$N$4:$N$204,'Score Log'!$C$4:$C$204,E$41,'Score Log'!$D$4:$D$204,$A43),2),"")) | F43: =IF(OR(F$41="",$A43=""),"",IFERROR(ROUND(AVERAGEIFS('Score Log'!$N$4:$N$204,'Score Log'!$C$4:$C$204,F$41,'Score Log'!$D$4:$D$204,$A43),2),"")) | G43: =IF(OR(G$41="",$A43=""),"",IFERROR(ROUND(AVERAGEIFS('Score Log'!$N$4:$N$204,'Score Log'!$C$4:$C$204,G$41,'Score Log'!$D$4:$D$204,$A43),2),"")) | H43: =IF(OR(H$41="",$A43=""),"",IFERROR(ROUND(AVERAGEIFS('Score Log'!$N$4:$N$204,'Score Log'!$C$4:$C$204,H$41,'Score Log'!$D$4:$D$204,$A43),2),"")) | I43: =IF(OR(I$41="",$A43=""),"",IFERROR(ROUND(AVERAGEIFS('Score Log'!$N$4:$N$204,'Score Log'!$C$4:$C$204,I$41,'Score Log'!$D$4:$D$204,$A43),2),"")) | J43: =IF(OR(J$41="",$A43=""),"",IFERROR(ROUND(AVERAGEIFS('Score Log'!$N$4:$N$204,'Score Log'!$C$4:$C$204,J$41,'Score Log'!$D$4:$D$204,$A43),2),"")) | ... L43: =IF(OR(L$41="",$A43=""),"",IFERROR(ROUND(AVERAGEIFS('Score Log'!$N$4:$N$204,'Score Log'!$C$4:$C$204,L$41,'Score Log'!$D$4:$D$204,$A43),2),""))
A44: =IF(Settings!D6="","",Settings!D6) -> 3D printing (FDM) | B44: =IF($A44="","",COUNTIFS('Score Log'!$D$4:$D$204,$A44)) -> 0 | C44: =IF(OR(C$41="",$A44=""),"",IFERROR(ROUND(AVERAGEIFS('Score Log'!$N$4:$N$204,'Score Log'!$C$4:$C$204,C$41,'Score Log'!$D$4:$D$204,$A44),2),"")) | D44: =IF(OR(D$41="",$A44=""),"",IFERROR(ROUND(AVERAGEIFS('Score Log'!$N$4:$N$204,'Score Log'!$C$4:$C$204,D$41,'Score Log'!$D$4:$D$204,$A44),2),"")) | E44: =IF(OR(E$41="",$A44=""),"",IFERROR(ROUND(AVERAGEIFS('Score Log'!$N$4:$N$204,'Score Log'!$C$4:$C$204,E$41,'Score Log'!$D$4:$D$204,$A44),2),"")) | F44: =IF(OR(F$41="",$A44=""),"",IFERROR(ROUND(AVERAGEIFS('Score Log'!$N$4:$N$204,'Score Log'!$C$4:$C$204,F$41,'Score Log'!$D$4:$D$204,$A44),2),"")) | G44: =IF(OR(G$41="",$A44=""),"",IFERROR(ROUND(AVERAGEIFS('Score Log'!$N$4:$N$204,'Score Log'!$C$4:$C$204,G$41,'Score Log'!$D$4:$D$204,$A44),2),"")) | H44: =IF(OR(H$41="",$A44=""),"",IFERROR(ROUND(AVERAGEIFS('Score Log'!$N$4:$N$204,'Score Log'!$C$4:$C$204,H$41,'Score Log'!$D$4:$D$204,$A44),2),"")) | I44: =IF(OR(I$41="",$A44=""),"",IFERROR(ROUND(AVERAGEIFS('Score Log'!$N$4:$N$204,'Score Log'!$C$4:$C$204,I$41,'Score Log'!$D$4:$D$204,$A44),2),"")) | J44: =IF(OR(J$41="",$A44=""),"",IFERROR(ROUND(AVERAGEIFS('Score Log'!$N$4:$N$204,'Score Log'!$C$4:$C$204,J$41,'Score Log'!$D$4:$D$204,$A44),2),"")) | ... L44: =IF(OR(L$41="",$A44=""),"",IFERROR(ROUND(AVERAGEIFS('Score Log'!$N$4:$N$204,'Score Log'!$C$4:$C$204,L$41,'Score Log'!$D$4:$D$204,$A44),2),""))
A45: =IF(Settings!D7="","",Settings!D7) -> 3D printing (SLA) | B45: =IF($A45="","",COUNTIFS('Score Log'!$D$4:$D$204,$A45)) -> 0 | C45: =IF(OR(C$41="",$A45=""),"",IFERROR(ROUND(AVERAGEIFS('Score Log'!$N$4:$N$204,'Score Log'!$C$4:$C$204,C$41,'Score Log'!$D$4:$D$204,$A45),2),"")) | D45: =IF(OR(D$41="",$A45=""),"",IFERROR(ROUND(AVERAGEIFS('Score Log'!$N$4:$N$204,'Score Log'!$C$4:$C$204,D$41,'Score Log'!$D$4:$D$204,$A45),2),"")) | E45: =IF(OR(E$41="",$A45=""),"",IFERROR(ROUND(AVERAGEIFS('Score Log'!$N$4:$N$204,'Score Log'!$C$4:$C$204,E$41,'Score Log'!$D$4:$D$204,$A45),2),"")) | F45: =IF(OR(F$41="",$A45=""),"",IFERROR(ROUND(AVERAGEIFS('Score Log'!$N$4:$N$204,'Score Log'!$C$4:$C$204,F$41,'Score Log'!$D$4:$D$204,$A45),2),"")) | G45: =IF(OR(G$41="",$A45=""),"",IFERROR(ROUND(AVERAGEIFS('Score Log'!$N$4:$N$204,'Score Log'!$C$4:$C$204,G$41,'Score Log'!$D$4:$D$204,$A45),2),"")) | H45: =IF(OR(H$41="",$A45=""),"",IFERROR(ROUND(AVERAGEIFS('Score Log'!$N$4:$N$204,'Score Log'!$C$4:$C$204,H$41,'Score Log'!$D$4:$D$204,$A45),2),"")) | I45: =IF(OR(I$41="",$A45=""),"",IFERROR(ROUND(AVERAGEIFS('Score Log'!$N$4:$N$204,'Score Log'!$C$4:$C$204,I$41,'Score Log'!$D$4:$D$204,$A45),2),"")) | J45: =IF(OR(J$41="",$A45=""),"",IFERROR(ROUND(AVERAGEIFS('Score Log'!$N$4:$N$204,'Score Log'!$C$4:$C$204,J$41,'Score Log'!$D$4:$D$204,$A45),2),"")) | ... L45: =IF(OR(L$41="",$A45=""),"",IFERROR(ROUND(AVERAGEIFS('Score Log'!$N$4:$N$204,'Score Log'!$C$4:$C$204,L$41,'Score Log'!$D$4:$D$204,$A45),2),""))
A46: =IF(Settings!D8="","",Settings!D8) -> 3D printing (SLS) | B46: =IF($A46="","",COUNTIFS('Score Log'!$D$4:$D$204,$A46)) -> 0 | C46: =IF(OR(C$41="",$A46=""),"",IFERROR(ROUND(AVERAGEIFS('Score Log'!$N$4:$N$204,'Score Log'!$C$4:$C$204,C$41,'Score Log'!$D$4:$D$204,$A46),2),"")) | D46: =IF(OR(D$41="",$A46=""),"",IFERROR(ROUND(AVERAGEIFS('Score Log'!$N$4:$N$204,'Score Log'!$C$4:$C$204,D$41,'Score Log'!$D$4:$D$204,$A46),2),"")) | E46: =IF(OR(E$41="",$A46=""),"",IFERROR(ROUND(AVERAGEIFS('Score Log'!$N$4:$N$204,'Score Log'!$C$4:$C$204,E$41,'Score Log'!$D$4:$D$204,$A46),2),"")) | F46: =IF(OR(F$41="",$A46=""),"",IFERROR(ROUND(AVERAGEIFS('Score Log'!$N$4:$N$204,'Score Log'!$C$4:$C$204,F$41,'Score Log'!$D$4:$D$204,$A46),2),"")) | G46: =IF(OR(G$41="",$A46=""),"",IFERROR(ROUND(AVERAGEIFS('Score Log'!$N$4:$N$204,'Score Log'!$C$4:$C$204,G$41,'Score Log'!$D$4:$D$204,$A46),2),"")) | H46: =IF(OR(H$41="",$A46=""),"",IFERROR(ROUND(AVERAGEIFS('Score Log'!$N$4:$N$204,'Score Log'!$C$4:$C$204,H$41,'Score Log'!$D$4:$D$204,$A46),2),"")) | I46: =IF(OR(I$41="",$A46=""),"",IFERROR(ROUND(AVERAGEIFS('Score Log'!$N$4:$N$204,'Score Log'!$C$4:$C$204,I$41,'Score Log'!$D$4:$D$204,$A46),2),"")) | J46: =IF(OR(J$41="",$A46=""),"",IFERROR(ROUND(AVERAGEIFS('Score Log'!$N$4:$N$204,'Score Log'!$C$4:$C$204,J$41,'Score Log'!$D$4:$D$204,$A46),2),"")) | ... L46: =IF(OR(L$41="",$A46=""),"",IFERROR(ROUND(AVERAGEIFS('Score Log'!$N$4:$N$204,'Score Log'!$C$4:$C$204,L$41,'Score Log'!$D$4:$D$204,$A46),2),""))
A47: =IF(Settings!D9="","",Settings!D9) -> PVA | B47: =IF($A47="","",COUNTIFS('Score Log'!$D$4:$D$204,$A47)) -> 0 | C47: =IF(OR(C$41="",$A47=""),"",IFERROR(ROUND(AVERAGEIFS('Score Log'!$N$4:$N$204,'Score Log'!$C$4:$C$204,C$41,'Score Log'!$D$4:$D$204,$A47),2),"")) | D47: =IF(OR(D$41="",$A47=""),"",IFERROR(ROUND(AVERAGEIFS('Score Log'!$N$4:$N$204,'Score Log'!$C$4:$C$204,D$41,'Score Log'!$D$4:$D$204,$A47),2),"")) | E47: =IF(OR(E$41="",$A47=""),"",IFERROR(ROUND(AVERAGEIFS('Score Log'!$N$4:$N$204,'Score Log'!$C$4:$C$204,E$41,'Score Log'!$D$4:$D$204,$A47),2),"")) | F47: =IF(OR(F$41="",$A47=""),"",IFERROR(ROUND(AVERAGEIFS('Score Log'!$N$4:$N$204,'Score Log'!$C$4:$C$204,F$41,'Score Log'!$D$4:$D$204,$A47),2),"")) | G47: =IF(OR(G$41="",$A47=""),"",IFERROR(ROUND(AVERAGEIFS('Score Log'!$N$4:$N$204,'Score Log'!$C$4:$C$204,G$41,'Score Log'!$D$4:$D$204,$A47),2),"")) | H47: =IF(OR(H$41="",$A47=""),"",IFERROR(ROUND(AVERAGEIFS('Score Log'!$N$4:$N$204,'Score Log'!$C$4:$C$204,H$41,'Score Log'!$D$4:$D$204,$A47),2),"")) | I47: =IF(OR(I$41="",$A47=""),"",IFERROR(ROUND(AVERAGEIFS('Score Log'!$N$4:$N$204,'Score Log'!$C$4:$C$204,I$41,'Score Log'!$D$4:$D$204,$A47),2),"")) | J47: =IF(OR(J$41="",$A47=""),"",IFERROR(ROUND(AVERAGEIFS('Score Log'!$N$4:$N$204,'Score Log'!$C$4:$C$204,J$41,'Score Log'!$D$4:$D$204,$A47),2),"")) | ... L47: =IF(OR(L$41="",$A47=""),"",IFERROR(ROUND(AVERAGEIFS('Score Log'!$N$4:$N$204,'Score Log'!$C$4:$C$204,L$41,'Score Log'!$D$4:$D$204,$A47),2),""))
A48: =IF(Settings!D10="","",Settings!D10) -> CNC machining | B48: =IF($A48="","",COUNTIFS('Score Log'!$D$4:$D$204,$A48)) -> 0 | C48: =IF(OR(C$41="",$A48=""),"",IFERROR(ROUND(AVERAGEIFS('Score Log'!$N$4:$N$204,'Score Log'!$C$4:$C$204,C$41,'Score Log'!$D$4:$D$204,$A48),2),"")) | D48: =IF(OR(D$41="",$A48=""),"",IFERROR(ROUND(AVERAGEIFS('Score Log'!$N$4:$N$204,'Score Log'!$C$4:$C$204,D$41,'Score Log'!$D$4:$D$204,$A48),2),"")) | E48: =IF(OR(E$41="",$A48=""),"",IFERROR(ROUND(AVERAGEIFS('Score Log'!$N$4:$N$204,'Score Log'!$C$4:$C$204,E$41,'Score Log'!$D$4:$D$204,$A48),2),"")) | F48: =IF(OR(F$41="",$A48=""),"",IFERROR(ROUND(AVERAGEIFS('Score Log'!$N$4:$N$204,'Score Log'!$C$4:$C$204,F$41,'Score Log'!$D$4:$D$204,$A48),2),"")) | G48: =IF(OR(G$41="",$A48=""),"",IFERROR(ROUND(AVERAGEIFS('Score Log'!$N$4:$N$204,'Score Log'!$C$4:$C$204,G$41,'Score Log'!$D$4:$D$204,$A48),2),"")) | H48: =IF(OR(H$41="",$A48=""),"",IFERROR(ROUND(AVERAGEIFS('Score Log'!$N$4:$N$204,'Score Log'!$C$4:$C$204,H$41,'Score Log'!$D$4:$D$204,$A48),2),"")) | I48: =IF(OR(I$41="",$A48=""),"",IFERROR(ROUND(AVERAGEIFS('Score Log'!$N$4:$N$204,'Score Log'!$C$4:$C$204,I$41,'Score Log'!$D$4:$D$204,$A48),2),"")) | J48: =IF(OR(J$41="",$A48=""),"",IFERROR(ROUND(AVERAGEIFS('Score Log'!$N$4:$N$204,'Score Log'!$C$4:$C$204,J$41,'Score Log'!$D$4:$D$204,$A48),2),"")) | ... L48: =IF(OR(L$41="",$A48=""),"",IFERROR(ROUND(AVERAGEIFS('Score Log'!$N$4:$N$204,'Score Log'!$C$4:$C$204,L$41,'Score Log'!$D$4:$D$204,$A48),2),""))
A49: =IF(Settings!D11="","",Settings!D11) -> Vacuum casting | B49: =IF($A49="","",COUNTIFS('Score Log'!$D$4:$D$204,$A49)) -> 0 | C49: =IF(OR(C$41="",$A49=""),"",IFERROR(ROUND(AVERAGEIFS('Score Log'!$N$4:$N$204,'Score Log'!$C$4:$C$204,C$41,'Score Log'!$D$4:$D$204,$A49),2),"")) | D49: =IF(OR(D$41="",$A49=""),"",IFERROR(ROUND(AVERAGEIFS('Score Log'!$N$4:$N$204,'Score Log'!$C$4:$C$204,D$41,'Score Log'!$D$4:$D$204,$A49),2),"")) | E49: =IF(OR(E$41="",$A49=""),"",IFERROR(ROUND(AVERAGEIFS('Score Log'!$N$4:$N$204,'Score Log'!$C$4:$C$204,E$41,'Score Log'!$D$4:$D$204,$A49),2),"")) | F49: =IF(OR(F$41="",$A49=""),"",IFERROR(ROUND(AVERAGEIFS('Score Log'!$N$4:$N$204,'Score Log'!$C$4:$C$204,F$41,'Score Log'!$D$4:$D$204,$A49),2),"")) | G49: =IF(OR(G$41="",$A49=""),"",IFERROR(ROUND(AVERAGEIFS('Score Log'!$N$4:$N$204,'Score Log'!$C$4:$C$204,G$41,'Score Log'!$D$4:$D$204,$A49),2),"")) | H49: =IF(OR(H$41="",$A49=""),"",IFERROR(ROUND(AVERAGEIFS('Score Log'!$N$4:$N$204,'Score Log'!$C$4:$C$204,H$41,'Score Log'!$D$4:$D$204,$A49),2),"")) | I49: =IF(OR(I$41="",$A49=""),"",IFERROR(ROUND(AVERAGEIFS('Score Log'!$N$4:$N$204,'Score Log'!$C$4:$C$204,I$41,'Score Log'!$D$4:$D$204,$A49),2),"")) | J49: =IF(OR(J$41="",$A49=""),"",IFERROR(ROUND(AVERAGEIFS('Score Log'!$N$4:$N$204,'Score Log'!$C$4:$C$204,J$41,'Score Log'!$D$4:$D$204,$A49),2),"")) | ... L49: =IF(OR(L$41="",$A49=""),"",IFERROR(ROUND(AVERAGEIFS('Score Log'!$N$4:$N$204,'Score Log'!$C$4:$C$204,L$41,'Score Log'!$D$4:$D$204,$A49),2),""))
A50: =IF(Settings!D12="","",Settings!D12) -> Sheet metal | B50: =IF($A50="","",COUNTIFS('Score Log'!$D$4:$D$204,$A50)) -> 0 | C50: =IF(OR(C$41="",$A50=""),"",IFERROR(ROUND(AVERAGEIFS('Score Log'!$N$4:$N$204,'Score Log'!$C$4:$C$204,C$41,'Score Log'!$D$4:$D$204,$A50),2),"")) | D50: =IF(OR(D$41="",$A50=""),"",IFERROR(ROUND(AVERAGEIFS('Score Log'!$N$4:$N$204,'Score Log'!$C$4:$C$204,D$41,'Score Log'!$D$4:$D$204,$A50),2),"")) | E50: =IF(OR(E$41="",$A50=""),"",IFERROR(ROUND(AVERAGEIFS('Score Log'!$N$4:$N$204,'Score Log'!$C$4:$C$204,E$41,'Score Log'!$D$4:$D$204,$A50),2),"")) | F50: =IF(OR(F$41="",$A50=""),"",IFERROR(ROUND(AVERAGEIFS('Score Log'!$N$4:$N$204,'Score Log'!$C$4:$C$204,F$41,'Score Log'!$D$4:$D$204,$A50),2),"")) | G50: =IF(OR(G$41="",$A50=""),"",IFERROR(ROUND(AVERAGEIFS('Score Log'!$N$4:$N$204,'Score Log'!$C$4:$C$204,G$41,'Score Log'!$D$4:$D$204,$A50),2),"")) | H50: =IF(OR(H$41="",$A50=""),"",IFERROR(ROUND(AVERAGEIFS('Score Log'!$N$4:$N$204,'Score Log'!$C$4:$C$204,H$41,'Score Log'!$D$4:$D$204,$A50),2),"")) | I50: =IF(OR(I$41="",$A50=""),"",IFERROR(ROUND(AVERAGEIFS('Score Log'!$N$4:$N$204,'Score Log'!$C$4:$C$204,I$41,'Score Log'!$D$4:$D$204,$A50),2),"")) | J50: =IF(OR(J$41="",$A50=""),"",IFERROR(ROUND(AVERAGEIFS('Score Log'!$N$4:$N$204,'Score Log'!$C$4:$C$204,J$41,'Score Log'!$D$4:$D$204,$A50),2),"")) | ... L50: =IF(OR(L$41="",$A50=""),"",IFERROR(ROUND(AVERAGEIFS('Score Log'!$N$4:$N$204,'Score Log'!$C$4:$C$204,L$41,'Score Log'!$D$4:$D$204,$A50),2),""))
A51: =IF(Settings!D13="","",Settings!D13) -> Extrusion | B51: =IF($A51="","",COUNTIFS('Score Log'!$D$4:$D$204,$A51)) -> 0 | C51: =IF(OR(C$41="",$A51=""),"",IFERROR(ROUND(AVERAGEIFS('Score Log'!$N$4:$N$204,'Score Log'!$C$4:$C$204,C$41,'Score Log'!$D$4:$D$204,$A51),2),"")) | D51: =IF(OR(D$41="",$A51=""),"",IFERROR(ROUND(AVERAGEIFS('Score Log'!$N$4:$N$204,'Score Log'!$C$4:$C$204,D$41,'Score Log'!$D$4:$D$204,$A51),2),"")) | E51: =IF(OR(E$41="",$A51=""),"",IFERROR(ROUND(AVERAGEIFS('Score Log'!$N$4:$N$204,'Score Log'!$C$4:$C$204,E$41,'Score Log'!$D$4:$D$204,$A51),2),"")) | F51: =IF(OR(F$41="",$A51=""),"",IFERROR(ROUND(AVERAGEIFS('Score Log'!$N$4:$N$204,'Score Log'!$C$4:$C$204,F$41,'Score Log'!$D$4:$D$204,$A51),2),"")) | G51: =IF(OR(G$41="",$A51=""),"",IFERROR(ROUND(AVERAGEIFS('Score Log'!$N$4:$N$204,'Score Log'!$C$4:$C$204,G$41,'Score Log'!$D$4:$D$204,$A51),2),"")) | H51: =IF(OR(H$41="",$A51=""),"",IFERROR(ROUND(AVERAGEIFS('Score Log'!$N$4:$N$204,'Score Log'!$C$4:$C$204,H$41,'Score Log'!$D$4:$D$204,$A51),2),"")) | I51: =IF(OR(I$41="",$A51=""),"",IFERROR(ROUND(AVERAGEIFS('Score Log'!$N$4:$N$204,'Score Log'!$C$4:$C$204,I$41,'Score Log'!$D$4:$D$204,$A51),2),"")) | J51: =IF(OR(J$41="",$A51=""),"",IFERROR(ROUND(AVERAGEIFS('Score Log'!$N$4:$N$204,'Score Log'!$C$4:$C$204,J$41,'Score Log'!$D$4:$D$204,$A51),2),"")) | ... L51: =IF(OR(L$41="",$A51=""),"",IFERROR(ROUND(AVERAGEIFS('Score Log'!$N$4:$N$204,'Score Log'!$C$4:$C$204,L$41,'Score Log'!$D$4:$D$204,$A51),2),""))
A52: =IF(Settings!D14="","",Settings!D14) -> Casting | B52: =IF($A52="","",COUNTIFS('Score Log'!$D$4:$D$204,$A52)) -> 0 | C52: =IF(OR(C$41="",$A52=""),"",IFERROR(ROUND(AVERAGEIFS('Score Log'!$N$4:$N$204,'Score Log'!$C$4:$C$204,C$41,'Score Log'!$D$4:$D$204,$A52),2),"")) | D52: =IF(OR(D$41="",$A52=""),"",IFERROR(ROUND(AVERAGEIFS('Score Log'!$N$4:$N$204,'Score Log'!$C$4:$C$204,D$41,'Score Log'!$D$4:$D$204,$A52),2),"")) | E52: =IF(OR(E$41="",$A52=""),"",IFERROR(ROUND(AVERAGEIFS('Score Log'!$N$4:$N$204,'Score Log'!$C$4:$C$204,E$41,'Score Log'!$D$4:$D$204,$A52),2),"")) | F52: =IF(OR(F$41="",$A52=""),"",IFERROR(ROUND(AVERAGEIFS('Score Log'!$N$4:$N$204,'Score Log'!$C$4:$C$204,F$41,'Score Log'!$D$4:$D$204,$A52),2),"")) | G52: =IF(OR(G$41="",$A52=""),"",IFERROR(ROUND(AVERAGEIFS('Score Log'!$N$4:$N$204,'Score Log'!$C$4:$C$204,G$41,'Score Log'!$D$4:$D$204,$A52),2),"")) | H52: =IF(OR(H$41="",$A52=""),"",IFERROR(ROUND(AVERAGEIFS('Score Log'!$N$4:$N$204,'Score Log'!$C$4:$C$204,H$41,'Score Log'!$D$4:$D$204,$A52),2),"")) | I52: =IF(OR(I$41="",$A52=""),"",IFERROR(ROUND(AVERAGEIFS('Score Log'!$N$4:$N$204,'Score Log'!$C$4:$C$204,I$41,'Score Log'!$D$4:$D$204,$A52),2),"")) | J52: =IF(OR(J$41="",$A52=""),"",IFERROR(ROUND(AVERAGEIFS('Score Log'!$N$4:$N$204,'Score Log'!$C$4:$C$204,J$41,'Score Log'!$D$4:$D$204,$A52),2),"")) | ... L52: =IF(OR(L$41="",$A52=""),"",IFERROR(ROUND(AVERAGEIFS('Score Log'!$N$4:$N$204,'Score Log'!$C$4:$C$204,L$41,'Score Log'!$D$4:$D$204,$A52),2),""))
A53: =IF(Settings!D15="","",Settings!D15) -> Other | B53: =IF($A53="","",COUNTIFS('Score Log'!$D$4:$D$204,$A53)) -> 0 | C53: =IF(OR(C$41="",$A53=""),"",IFERROR(ROUND(AVERAGEIFS('Score Log'!$N$4:$N$204,'Score Log'!$C$4:$C$204,C$41,'Score Log'!$D$4:$D$204,$A53),2),"")) | D53: =IF(OR(D$41="",$A53=""),"",IFERROR(ROUND(AVERAGEIFS('Score Log'!$N$4:$N$204,'Score Log'!$C$4:$C$204,D$41,'Score Log'!$D$4:$D$204,$A53),2),"")) | E53: =IF(OR(E$41="",$A53=""),"",IFERROR(ROUND(AVERAGEIFS('Score Log'!$N$4:$N$204,'Score Log'!$C$4:$C$204,E$41,'Score Log'!$D$4:$D$204,$A53),2),"")) | F53: =IF(OR(F$41="",$A53=""),"",IFERROR(ROUND(AVERAGEIFS('Score Log'!$N$4:$N$204,'Score Log'!$C$4:$C$204,F$41,'Score Log'!$D$4:$D$204,$A53),2),"")) | G53: =IF(OR(G$41="",$A53=""),"",IFERROR(ROUND(AVERAGEIFS('Score Log'!$N$4:$N$204,'Score Log'!$C$4:$C$204,G$41,'Score Log'!$D$4:$D$204,$A53),2),"")) | H53: =IF(OR(H$41="",$A53=""),"",IFERROR(ROUND(AVERAGEIFS('Score Log'!$N$4:$N$204,'Score Log'!$C$4:$C$204,H$41,'Score Log'!$D$4:$D$204,$A53),2),"")) | I53: =IF(OR(I$41="",$A53=""),"",IFERROR(ROUND(AVERAGEIFS('Score Log'!$N$4:$N$204,'Score Log'!$C$4:$C$204,I$41,'Score Log'!$D$4:$D$204,$A53),2),"")) | J53: =IF(OR(J$41="",$A53=""),"",IFERROR(ROUND(AVERAGEIFS('Score Log'!$N$4:$N$204,'Score Log'!$C$4:$C$204,J$41,'Score Log'!$D$4:$D$204,$A53),2),"")) | ... L53: =IF(OR(L$41="",$A53=""),"",IFERROR(ROUND(AVERAGEIFS('Score Log'!$N$4:$N$204,'Score Log'!$C$4:$C$204,L$41,'Score Log'!$D$4:$D$204,$A53),2),""))
... A61: =IF(Settings!D23="","",Settings!D23) | B61: =IF($A61="","",COUNTIFS('Score Log'!$D$4:$D$204,$A61)) | C61: =IF(OR(C$41="",$A61=""),"",IFERROR(ROUND(AVERAGEIFS('Score Log'!$N$4:$N$204,'Score Log'!$C$4:$C$204,C$41,'Score Log'!$D$4:$D$204,$A61),2),"")) | D61: =IF(OR(D$41="",$A61=""),"",IFERROR(ROUND(AVERAGEIFS('Score Log'!$N$4:$N$204,'Score Log'!$C$4:$C$204,D$41,'Score Log'!$D$4:$D$204,$A61),2),"")) | E61: =IF(OR(E$41="",$A61=""),"",IFERROR(ROUND(AVERAGEIFS('Score Log'!$N$4:$N$204,'Score Log'!$C$4:$C$204,E$41,'Score Log'!$D$4:$D$204,$A61),2),"")) | F61: =IF(OR(F$41="",$A61=""),"",IFERROR(ROUND(AVERAGEIFS('Score Log'!$N$4:$N$204,'Score Log'!$C$4:$C$204,F$41,'Score Log'!$D$4:$D$204,$A61),2),"")) | G61: =IF(OR(G$41="",$A61=""),"",IFERROR(ROUND(AVERAGEIFS('Score Log'!$N$4:$N$204,'Score Log'!$C$4:$C$204,G$41,'Score Log'!$D$4:$D$204,$A61),2),"")) | H61: =IF(OR(H$41="",$A61=""),"",IFERROR(ROUND(AVERAGEIFS('Score Log'!$N$4:$N$204,'Score Log'!$C$4:$C$204,H$41,'Score Log'!$D$4:$D$204,$A61),2),"")) | I61: =IF(OR(I$41="",$A61=""),"",IFERROR(ROUND(AVERAGEIFS('Score Log'!$N$4:$N$204,'Score Log'!$C$4:$C$204,I$41,'Score Log'!$D$4:$D$204,$A61),2),"")) | J61: =IF(OR(J$41="",$A61=""),"",IFERROR(ROUND(AVERAGEIFS('Score Log'!$N$4:$N$204,'Score Log'!$C$4:$C$204,J$41,'Score Log'!$D$4:$D$204,$A61),2),"")) | ... L61: =IF(OR(L$41="",$A61=""),"",IFERROR(ROUND(AVERAGEIFS('Score Log'!$N$4:$N$204,'Score Log'!$C$4:$C$204,L$41,'Score Log'!$D$4:$D$204,$A61),2),""))

Sheet Risk Suggestions
A1: Risk Suggestions - feed for the Part-Supplier Risk Model
A2: FULLY AUTOMATIC: every distinct Part + Supplier pair in the Score Log gets exactly one line here, in order of first appearance - log projects one row per part and combos appear by themselves. Translation: risk = 6 - average performance (scorecard 5 = excellent -> risk 1 = low), rounded and clamped to 1-5. Type the suggested values into the PART_RISK tab of Part_Supplier_Risk_Model - a starting point, not an override.
A3: PART-SUPPLIER COMBOS (auto from Score Log) | D3: SCORECARD PERFORMANCE FOR THE COMBO (auto, 5 = excellent) | K3: SUGGESTED RISK ENTRIES FOR PART_RISK (1 = low risk ... 5 = high) | AA3: first | AB3: ord
A4: Part (from Score Log) | B4: Supplier | C4: Process / part type | D4: Projects | E4: Avg Cost | F4: Avg Quality | G4: Avg Lead time | H4: Avg Responsiveness | I4: Avg Overall | J4: On-time % | K4: Quality_Compliance (suggest) | L4: Capacity (suggest) | M4: Supplier_Stability (suggest) | O4: cA | P4: rA | Q4: lr | AA4: =IF(OR('Score Log'!$C4="",'Score Log'!$E4=""),0,IF(COUNTIFS('Score Log'!$C$4:$C4,'Score Log'!$C4,'Score Log'!$E$4:$E4,'Score Log'!$E4)=1,1,0)) -> 1 | AB4: =IF($AA4=1,SUM($AA$4:$AA4),"") -> 1
A5: =IF($Q5="","",INDEX('Score Log'!$E:$E,$Q5)) -> Uterus Insert | B5: =IF($Q5="","",INDEX('Score Log'!$C:$C,$Q5)) -> Fictiv | C5: =IF($Q5="","",IF(INDEX('Score Log'!$D:$D,$Q5)="","",INDEX('Score Log'!$D:$D,$Q5))) -> Injection molding | D5: =IF($B5="","",COUNTIFS('Score Log'!$C$4:$C$203,$B5,'Score Log'!$E$4:$E$203,$A5)) -> 1 | E5: =IF($B5="","",IFERROR(ROUND(AVERAGEIFS('Score Log'!$F$4:$F$203,'Score Log'!$C$4:$C$203,$B5,'Score Log'!$E$4:$E$203,$A5),1),"-")) -> 4 | F5: =IF($B5="","",IFERROR(ROUND(AVERAGEIFS('Score Log'!$H$4:$H$203,'Score Log'!$C$4:$C$203,$B5,'Score Log'!$E$4:$E$203,$A5),1),"-")) -> 5 | G5: =IF($B5="","",IFERROR(ROUND(AVERAGEIFS('Score Log'!$J$4:$J$203,'Score Log'!$C$4:$C$203,$B5,'Score Log'!$E$4:$E$203,$A5),1),"-")) -> 4 | H5: =IF($B5="","",IFERROR(ROUND(AVERAGEIFS('Score Log'!$L$4:$L$203,'Score Log'!$C$4:$C$203,$B5,'Score Log'!$E$4:$E$203,$A5),1),"-")) -> 5 | I5: =IF($B5="","",IFERROR(ROUND(AVERAGEIFS('Score Log'!$N$4:$N$203,'Score Log'!$C$4:$C$203,$B5,'Score Log'!$E$4:$E$203,$A5),1),"-")) -> 4.5 | J5: =IF(OR($B5="",$D5=0),"",IFERROR(COUNTIFS('Score Log'!$C$4:$C$203,$B5,'Score Log'!$E$4:$E$203,$A5,'Score Log'!$U$4:$U$203,"Yes")/$D5,"-")) -> 1 | K5: =IF($B5="","",IF(ISNUMBER($F5),MAX(1,MIN(5,ROUND(6-$F5,0))),"-")) -> 1 | L5: =IF($B5="","",IF(ISNUMBER($G5),MAX(1,MIN(5,ROUND(6-$G5,0))),"-")) -> 2 | M5: =IF($B5="","",IF(AND(ISNUMBER($P5),ISNUMBER($O5)),MAX(1,MIN(5,ROUND(6-AVERAGE($P5,$O5),0))),IF(ISNUMBER($P5),MAX(1,MIN(5,ROUND(6-$P5,0))),"-"))) -> 2 | O5: =IF($B5="","",IFERROR(AVERAGEIFS('Score Log'!$F$4:$F$203,'Score Log'!$C$4:$C$203,$B5),"")) -> 4 | P5: =IF($B5="","",IFERROR(AVERAGEIFS('Score Log'!$L$4:$L$203,'Score Log'!$C$4:$C$203,$B5),"")) -> 5 | Q5: =IFERROR(MATCH(ROW()-4,$AB$4:$AB$203,0)+3,"") -> 4 | AA5: =IF(OR('Score Log'!$C5="",'Score Log'!$E5=""),0,IF(COUNTIFS('Score Log'!$C$4:$C5,'Score Log'!$C5,'Score Log'!$E$4:$E5,'Score Log'!$E5)=1,1,0)) -> 1 | AB5: =IF($AA5=1,SUM($AA$4:$AA5),"") -> 2
A6: =IF($Q6="","",INDEX('Score Log'!$E:$E,$Q6)) -> End Plate | B6: =IF($Q6="","",INDEX('Score Log'!$C:$C,$Q6)) -> Fictiv | C6: =IF($Q6="","",IF(INDEX('Score Log'!$D:$D,$Q6)="","",INDEX('Score Log'!$D:$D,$Q6))) -> Injection molding | D6: =IF($B6="","",COUNTIFS('Score Log'!$C$4:$C$203,$B6,'Score Log'!$E$4:$E$203,$A6)) -> 1 | E6: =IF($B6="","",IFERROR(ROUND(AVERAGEIFS('Score Log'!$F$4:$F$203,'Score Log'!$C$4:$C$203,$B6,'Score Log'!$E$4:$E$203,$A6),1),"-")) -> 4 | F6: =IF($B6="","",IFERROR(ROUND(AVERAGEIFS('Score Log'!$H$4:$H$203,'Score Log'!$C$4:$C$203,$B6,'Score Log'!$E$4:$E$203,$A6),1),"-")) -> 5 | G6: =IF($B6="","",IFERROR(ROUND(AVERAGEIFS('Score Log'!$J$4:$J$203,'Score Log'!$C$4:$C$203,$B6,'Score Log'!$E$4:$E$203,$A6),1),"-")) -> 4 | H6: =IF($B6="","",IFERROR(ROUND(AVERAGEIFS('Score Log'!$L$4:$L$203,'Score Log'!$C$4:$C$203,$B6,'Score Log'!$E$4:$E$203,$A6),1),"-")) -> 5 | I6: =IF($B6="","",IFERROR(ROUND(AVERAGEIFS('Score Log'!$N$4:$N$203,'Score Log'!$C$4:$C$203,$B6,'Score Log'!$E$4:$E$203,$A6),1),"-")) -> 4.5 | J6: =IF(OR($B6="",$D6=0),"",IFERROR(COUNTIFS('Score Log'!$C$4:$C$203,$B6,'Score Log'!$E$4:$E$203,$A6,'Score Log'!$U$4:$U$203,"Yes")/$D6,"-")) -> 1 | K6: =IF($B6="","",IF(ISNUMBER($F6),MAX(1,MIN(5,ROUND(6-$F6,0))),"-")) -> 1 | L6: =IF($B6="","",IF(ISNUMBER($G6),MAX(1,MIN(5,ROUND(6-$G6,0))),"-")) -> 2 | M6: =IF($B6="","",IF(AND(ISNUMBER($P6),ISNUMBER($O6)),MAX(1,MIN(5,ROUND(6-AVERAGE($P6,$O6),0))),IF(ISNUMBER($P6),MAX(1,MIN(5,ROUND(6-$P6,0))),"-"))) -> 2 | O6: =IF($B6="","",IFERROR(AVERAGEIFS('Score Log'!$F$4:$F$203,'Score Log'!$C$4:$C$203,$B6),"")) -> 4 | P6: =IF($B6="","",IFERROR(AVERAGEIFS('Score Log'!$L$4:$L$203,'Score Log'!$C$4:$C$203,$B6),"")) -> 5 | Q6: =IFERROR(MATCH(ROW()-4,$AB$4:$AB$203,0)+3,"") -> 5 | AA6: =IF(OR('Score Log'!$C6="",'Score Log'!$E6=""),0,IF(COUNTIFS('Score Log'!$C$4:$C6,'Score Log'!$C6,'Score Log'!$E$4:$E6,'Score Log'!$E6)=1,1,0)) -> 1 | AB6: =IF($AA6=1,SUM($AA$4:$AA6),"") -> 3
A7: =IF($Q7="","",INDEX('Score Log'!$E:$E,$Q7)) -> Suppine chest base | B7: =IF($Q7="","",INDEX('Score Log'!$C:$C,$Q7)) -> Advanced Plastiform | C7: =IF($Q7="","",IF(INDEX('Score Log'!$D:$D,$Q7)="","",INDEX('Score Log'!$D:$D,$Q7))) -> Thermoforming | D7: =IF($B7="","",COUNTIFS('Score Log'!$C$4:$C$203,$B7,'Score Log'!$E$4:$E$203,$A7)) -> 1 | E7: =IF($B7="","",IFERROR(ROUND(AVERAGEIFS('Score Log'!$F$4:$F$203,'Score Log'!$C$4:$C$203,$B7,'Score Log'!$E$4:$E$203,$A7),1),"-")) -> - | F7: =IF($B7="","",IFERROR(ROUND(AVERAGEIFS('Score Log'!$H$4:$H$203,'Score Log'!$C$4:$C$203,$B7,'Score Log'!$E$4:$E$203,$A7),1),"-")) -> - | G7: =IF($B7="","",IFERROR(ROUND(AVERAGEIFS('Score Log'!$J$4:$J$203,'Score Log'!$C$4:$C$203,$B7,'Score Log'!$E$4:$E$203,$A7),1),"-")) -> - | H7: =IF($B7="","",IFERROR(ROUND(AVERAGEIFS('Score Log'!$L$4:$L$203,'Score Log'!$C$4:$C$203,$B7,'Score Log'!$E$4:$E$203,$A7),1),"-")) -> - | I7: =IF($B7="","",IFERROR(ROUND(AVERAGEIFS('Score Log'!$N$4:$N$203,'Score Log'!$C$4:$C$203,$B7,'Score Log'!$E$4:$E$203,$A7),1),"-")) -> - | J7: =IF(OR($B7="",$D7=0),"",IFERROR(COUNTIFS('Score Log'!$C$4:$C$203,$B7,'Score Log'!$E$4:$E$203,$A7,'Score Log'!$U$4:$U$203,"Yes")/$D7,"-")) -> 0 | K7: =IF($B7="","",IF(ISNUMBER($F7),MAX(1,MIN(5,ROUND(6-$F7,0))),"-")) -> - | L7: =IF($B7="","",IF(ISNUMBER($G7),MAX(1,MIN(5,ROUND(6-$G7,0))),"-")) -> - | M7: =IF($B7="","",IF(AND(ISNUMBER($P7),ISNUMBER($O7)),MAX(1,MIN(5,ROUND(6-AVERAGE($P7,$O7),0))),IF(ISNUMBER($P7),MAX(1,MIN(5,ROUND(6-$P7,0))),"-"))) -> - | O7: =IF($B7="","",IFERROR(AVERAGEIFS('Score Log'!$F$4:$F$203,'Score Log'!$C$4:$C$203,$B7),"")) | P7: =IF($B7="","",IFERROR(AVERAGEIFS('Score Log'!$L$4:$L$203,'Score Log'!$C$4:$C$203,$B7),"")) | Q7: =IFERROR(MATCH(ROW()-4,$AB$4:$AB$203,0)+3,"") -> 6 | AA7: =IF(OR('Score Log'!$C7="",'Score Log'!$E7=""),0,IF(COUNTIFS('Score Log'!$C$4:$C7,'Score Log'!$C7,'Score Log'!$E$4:$E7,'Score Log'!$E7)=1,1,0)) -> 0 | AB7: =IF($AA7=1,SUM($AA$4:$AA7),"")
A8: =IF($Q8="","",INDEX('Score Log'!$E:$E,$Q8)) | B8: =IF($Q8="","",INDEX('Score Log'!$C:$C,$Q8)) | C8: =IF($Q8="","",IF(INDEX('Score Log'!$D:$D,$Q8)="","",INDEX('Score Log'!$D:$D,$Q8))) | D8: =IF($B8="","",COUNTIFS('Score Log'!$C$4:$C$203,$B8,'Score Log'!$E$4:$E$203,$A8)) | E8: =IF($B8="","",IFERROR(ROUND(AVERAGEIFS('Score Log'!$F$4:$F$203,'Score Log'!$C$4:$C$203,$B8,'Score Log'!$E$4:$E$203,$A8),1),"-")) | F8: =IF($B8="","",IFERROR(ROUND(AVERAGEIFS('Score Log'!$H$4:$H$203,'Score Log'!$C$4:$C$203,$B8,'Score Log'!$E$4:$E$203,$A8),1),"-")) | G8: =IF($B8="","",IFERROR(ROUND(AVERAGEIFS('Score Log'!$J$4:$J$203,'Score Log'!$C$4:$C$203,$B8,'Score Log'!$E$4:$E$203,$A8),1),"-")) | H8: =IF($B8="","",IFERROR(ROUND(AVERAGEIFS('Score Log'!$L$4:$L$203,'Score Log'!$C$4:$C$203,$B8,'Score Log'!$E$4:$E$203,$A8),1),"-")) | I8: =IF($B8="","",IFERROR(ROUND(AVERAGEIFS('Score Log'!$N$4:$N$203,'Score Log'!$C$4:$C$203,$B8,'Score Log'!$E$4:$E$203,$A8),1),"-")) | J8: =IF(OR($B8="",$D8=0),"",IFERROR(COUNTIFS('Score Log'!$C$4:$C$203,$B8,'Score Log'!$E$4:$E$203,$A8,'Score Log'!$U$4:$U$203,"Yes")/$D8,"-")) | K8: =IF($B8="","",IF(ISNUMBER($F8),MAX(1,MIN(5,ROUND(6-$F8,0))),"-")) | L8: =IF($B8="","",IF(ISNUMBER($G8),MAX(1,MIN(5,ROUND(6-$G8,0))),"-")) | M8: =IF($B8="","",IF(AND(ISNUMBER($P8),ISNUMBER($O8)),MAX(1,MIN(5,ROUND(6-AVERAGE($P8,$O8),0))),IF(ISNUMBER($P8),MAX(1,MIN(5,ROUND(6-$P8,0))),"-"))) | O8: =IF($B8="","",IFERROR(AVERAGEIFS('Score Log'!$F$4:$F$203,'Score Log'!$C$4:$C$203,$B8),"")) | P8: =IF($B8="","",IFERROR(AVERAGEIFS('Score Log'!$L$4:$L$203,'Score Log'!$C$4:$C$203,$B8),"")) | Q8: =IFERROR(MATCH(ROW()-4,$AB$4:$AB$203,0)+3,"") | AA8: =IF(OR('Score Log'!$C8="",'Score Log'!$E8=""),0,IF(COUNTIFS('Score Log'!$C$4:$C8,'Score Log'!$C8,'Score Log'!$E$4:$E8,'Score Log'!$E8)=1,1,0)) -> 0 | AB8: =IF($AA8=1,SUM($AA$4:$AA8),"")
A9: =IF($Q9="","",INDEX('Score Log'!$E:$E,$Q9)) | B9: =IF($Q9="","",INDEX('Score Log'!$C:$C,$Q9)) | C9: =IF($Q9="","",IF(INDEX('Score Log'!$D:$D,$Q9)="","",INDEX('Score Log'!$D:$D,$Q9))) | D9: =IF($B9="","",COUNTIFS('Score Log'!$C$4:$C$203,$B9,'Score Log'!$E$4:$E$203,$A9)) | E9: =IF($B9="","",IFERROR(ROUND(AVERAGEIFS('Score Log'!$F$4:$F$203,'Score Log'!$C$4:$C$203,$B9,'Score Log'!$E$4:$E$203,$A9),1),"-")) | F9: =IF($B9="","",IFERROR(ROUND(AVERAGEIFS('Score Log'!$H$4:$H$203,'Score Log'!$C$4:$C$203,$B9,'Score Log'!$E$4:$E$203,$A9),1),"-")) | G9: =IF($B9="","",IFERROR(ROUND(AVERAGEIFS('Score Log'!$J$4:$J$203,'Score Log'!$C$4:$C$203,$B9,'Score Log'!$E$4:$E$203,$A9),1),"-")) | H9: =IF($B9="","",IFERROR(ROUND(AVERAGEIFS('Score Log'!$L$4:$L$203,'Score Log'!$C$4:$C$203,$B9,'Score Log'!$E$4:$E$203,$A9),1),"-")) | I9: =IF($B9="","",IFERROR(ROUND(AVERAGEIFS('Score Log'!$N$4:$N$203,'Score Log'!$C$4:$C$203,$B9,'Score Log'!$E$4:$E$203,$A9),1),"-")) | J9: =IF(OR($B9="",$D9=0),"",IFERROR(COUNTIFS('Score Log'!$C$4:$C$203,$B9,'Score Log'!$E$4:$E$203,$A9,'Score Log'!$U$4:$U$203,"Yes")/$D9,"-")) | K9: =IF($B9="","",IF(ISNUMBER($F9),MAX(1,MIN(5,ROUND(6-$F9,0))),"-")) | L9: =IF($B9="","",IF(ISNUMBER($G9),MAX(1,MIN(5,ROUND(6-$G9,0))),"-")) | M9: =IF($B9="","",IF(AND(ISNUMBER($P9),ISNUMBER($O9)),MAX(1,MIN(5,ROUND(6-AVERAGE($P9,$O9),0))),IF(ISNUMBER($P9),MAX(1,MIN(5,ROUND(6-$P9,0))),"-"))) | O9: =IF($B9="","",IFERROR(AVERAGEIFS('Score Log'!$F$4:$F$203,'Score Log'!$C$4:$C$203,$B9),"")) | P9: =IF($B9="","",IFERROR(AVERAGEIFS('Score Log'!$L$4:$L$203,'Score Log'!$C$4:$C$203,$B9),"")) | Q9: =IFERROR(MATCH(ROW()-4,$AB$4:$AB$203,0)+3,"") | AA9: =IF(OR('Score Log'!$C9="",'Score Log'!$E9=""),0,IF(COUNTIFS('Score Log'!$C$4:$C9,'Score Log'!$C9,'Score Log'!$E$4:$E9,'Score Log'!$E9)=1,1,0)) -> 0 | AB9: =IF($AA9=1,SUM($AA$4:$AA9),"")
A10: =IF($Q10="","",INDEX('Score Log'!$E:$E,$Q10)) | B10: =IF($Q10="","",INDEX('Score Log'!$C:$C,$Q10)) | C10: =IF($Q10="","",IF(INDEX('Score Log'!$D:$D,$Q10)="","",INDEX('Score Log'!$D:$D,$Q10))) | D10: =IF($B10="","",COUNTIFS('Score Log'!$C$4:$C$203,$B10,'Score Log'!$E$4:$E$203,$A10)) | E10: =IF($B10="","",IFERROR(ROUND(AVERAGEIFS('Score Log'!$F$4:$F$203,'Score Log'!$C$4:$C$203,$B10,'Score Log'!$E$4:$E$203,$A10),1),"-")) | F10: =IF($B10="","",IFERROR(ROUND(AVERAGEIFS('Score Log'!$H$4:$H$203,'Score Log'!$C$4:$C$203,$B10,'Score Log'!$E$4:$E$203,$A10),1),"-")) | G10: =IF($B10="","",IFERROR(ROUND(AVERAGEIFS('Score Log'!$J$4:$J$203,'Score Log'!$C$4:$C$203,$B10,'Score Log'!$E$4:$E$203,$A10),1),"-")) | H10: =IF($B10="","",IFERROR(ROUND(AVERAGEIFS('Score Log'!$L$4:$L$203,'Score Log'!$C$4:$C$203,$B10,'Score Log'!$E$4:$E$203,$A10),1),"-")) | I10: =IF($B10="","",IFERROR(ROUND(AVERAGEIFS('Score Log'!$N$4:$N$203,'Score Log'!$C$4:$C$203,$B10,'Score Log'!$E$4:$E$203,$A10),1),"-")) | J10: =IF(OR($B10="",$D10=0),"",IFERROR(COUNTIFS('Score Log'!$C$4:$C$203,$B10,'Score Log'!$E$4:$E$203,$A10,'Score Log'!$U$4:$U$203,"Yes")/$D10,"-")) | K10: =IF($B10="","",IF(ISNUMBER($F10),MAX(1,MIN(5,ROUND(6-$F10,0))),"-")) | L10: =IF($B10="","",IF(ISNUMBER($G10),MAX(1,MIN(5,ROUND(6-$G10,0))),"-")) | M10: =IF($B10="","",IF(AND(ISNUMBER($P10),ISNUMBER($O10)),MAX(1,MIN(5,ROUND(6-AVERAGE($P10,$O10),0))),IF(ISNUMBER($P10),MAX(1,MIN(5,ROUND(6-$P10,0))),"-"))) | O10: =IF($B10="","",IFERROR(AVERAGEIFS('Score Log'!$F$4:$F$203,'Score Log'!$C$4:$C$203,$B10),"")) | P10: =IF($B10="","",IFERROR(AVERAGEIFS('Score Log'!$L$4:$L$203,'Score Log'!$C$4:$C$203,$B10),"")) | Q10: =IFERROR(MATCH(ROW()-4,$AB$4:$AB$203,0)+3,"") | AA10: =IF(OR('Score Log'!$C10="",'Score Log'!$E10=""),0,IF(COUNTIFS('Score Log'!$C$4:$C10,'Score Log'!$C10,'Score Log'!$E$4:$E10,'Score Log'!$E10)=1,1,0)) -> 0 | AB10: =IF($AA10=1,SUM($AA$4:$AA10),"")
A11: =IF($Q11="","",INDEX('Score Log'!$E:$E,$Q11)) | B11: =IF($Q11="","",INDEX('Score Log'!$C:$C,$Q11)) | C11: =IF($Q11="","",IF(INDEX('Score Log'!$D:$D,$Q11)="","",INDEX('Score Log'!$D:$D,$Q11))) | D11: =IF($B11="","",COUNTIFS('Score Log'!$C$4:$C$203,$B11,'Score Log'!$E$4:$E$203,$A11)) | E11: =IF($B11="","",IFERROR(ROUND(AVERAGEIFS('Score Log'!$F$4:$F$203,'Score Log'!$C$4:$C$203,$B11,'Score Log'!$E$4:$E$203,$A11),1),"-")) | F11: =IF($B11="","",IFERROR(ROUND(AVERAGEIFS('Score Log'!$H$4:$H$203,'Score Log'!$C$4:$C$203,$B11,'Score Log'!$E$4:$E$203,$A11),1),"-")) | G11: =IF($B11="","",IFERROR(ROUND(AVERAGEIFS('Score Log'!$J$4:$J$203,'Score Log'!$C$4:$C$203,$B11,'Score Log'!$E$4:$E$203,$A11),1),"-")) | H11: =IF($B11="","",IFERROR(ROUND(AVERAGEIFS('Score Log'!$L$4:$L$203,'Score Log'!$C$4:$C$203,$B11,'Score Log'!$E$4:$E$203,$A11),1),"-")) | I11: =IF($B11="","",IFERROR(ROUND(AVERAGEIFS('Score Log'!$N$4:$N$203,'Score Log'!$C$4:$C$203,$B11,'Score Log'!$E$4:$E$203,$A11),1),"-")) | J11: =IF(OR($B11="",$D11=0),"",IFERROR(COUNTIFS('Score Log'!$C$4:$C$203,$B11,'Score Log'!$E$4:$E$203,$A11,'Score Log'!$U$4:$U$203,"Yes")/$D11,"-")) | K11: =IF($B11="","",IF(ISNUMBER($F11),MAX(1,MIN(5,ROUND(6-$F11,0))),"-")) | L11: =IF($B11="","",IF(ISNUMBER($G11),MAX(1,MIN(5,ROUND(6-$G11,0))),"-")) | M11: =IF($B11="","",IF(AND(ISNUMBER($P11),ISNUMBER($O11)),MAX(1,MIN(5,ROUND(6-AVERAGE($P11,$O11),0))),IF(ISNUMBER($P11),MAX(1,MIN(5,ROUND(6-$P11,0))),"-"))) | O11: =IF($B11="","",IFERROR(AVERAGEIFS('Score Log'!$F$4:$F$203,'Score Log'!$C$4:$C$203,$B11),"")) | P11: =IF($B11="","",IFERROR(AVERAGEIFS('Score Log'!$L$4:$L$203,'Score Log'!$C$4:$C$203,$B11),"")) | Q11: =IFERROR(MATCH(ROW()-4,$AB$4:$AB$203,0)+3,"") | AA11: =IF(OR('Score Log'!$C11="",'Score Log'!$E11=""),0,IF(COUNTIFS('Score Log'!$C$4:$C11,'Score Log'!$C11,'Score Log'!$E$4:$E11,'Score Log'!$E11)=1,1,0)) -> 0 | AB11: =IF($AA11=1,SUM($AA$4:$AA11),"")
A12: =IF($Q12="","",INDEX('Score Log'!$E:$E,$Q12)) | B12: =IF($Q12="","",INDEX('Score Log'!$C:$C,$Q12)) | C12: =IF($Q12="","",IF(INDEX('Score Log'!$D:$D,$Q12)="","",INDEX('Score Log'!$D:$D,$Q12))) | D12: =IF($B12="","",COUNTIFS('Score Log'!$C$4:$C$203,$B12,'Score Log'!$E$4:$E$203,$A12)) | E12: =IF($B12="","",IFERROR(ROUND(AVERAGEIFS('Score Log'!$F$4:$F$203,'Score Log'!$C$4:$C$203,$B12,'Score Log'!$E$4:$E$203,$A12),1),"-")) | F12: =IF($B12="","",IFERROR(ROUND(AVERAGEIFS('Score Log'!$H$4:$H$203,'Score Log'!$C$4:$C$203,$B12,'Score Log'!$E$4:$E$203,$A12),1),"-")) | G12: =IF($B12="","",IFERROR(ROUND(AVERAGEIFS('Score Log'!$J$4:$J$203,'Score Log'!$C$4:$C$203,$B12,'Score Log'!$E$4:$E$203,$A12),1),"-")) | H12: =IF($B12="","",IFERROR(ROUND(AVERAGEIFS('Score Log'!$L$4:$L$203,'Score Log'!$C$4:$C$203,$B12,'Score Log'!$E$4:$E$203,$A12),1),"-")) | I12: =IF($B12="","",IFERROR(ROUND(AVERAGEIFS('Score Log'!$N$4:$N$203,'Score Log'!$C$4:$C$203,$B12,'Score Log'!$E$4:$E$203,$A12),1),"-")) | J12: =IF(OR($B12="",$D12=0),"",IFERROR(COUNTIFS('Score Log'!$C$4:$C$203,$B12,'Score Log'!$E$4:$E$203,$A12,'Score Log'!$U$4:$U$203,"Yes")/$D12,"-")) | K12: =IF($B12="","",IF(ISNUMBER($F12),MAX(1,MIN(5,ROUND(6-$F12,0))),"-")) | L12: =IF($B12="","",IF(ISNUMBER($G12),MAX(1,MIN(5,ROUND(6-$G12,0))),"-")) | M12: =IF($B12="","",IF(AND(ISNUMBER($P12),ISNUMBER($O12)),MAX(1,MIN(5,ROUND(6-AVERAGE($P12,$O12),0))),IF(ISNUMBER($P12),MAX(1,MIN(5,ROUND(6-$P12,0))),"-"))) | O12: =IF($B12="","",IFERROR(AVERAGEIFS('Score Log'!$F$4:$F$203,'Score Log'!$C$4:$C$203,$B12),"")) | P12: =IF($B12="","",IFERROR(AVERAGEIFS('Score Log'!$L$4:$L$203,'Score Log'!$C$4:$C$203,$B12),"")) | Q12: =IFERROR(MATCH(ROW()-4,$AB$4:$AB$203,0)+3,"") | AA12: =IF(OR('Score Log'!$C12="",'Score Log'!$E12=""),0,IF(COUNTIFS('Score Log'!$C$4:$C12,'Score Log'!$C12,'Score Log'!$E$4:$E12,'Score Log'!$E12)=1,1,0)) -> 0 | AB12: =IF($AA12=1,SUM($AA$4:$AA12),"")
A13: =IF($Q13="","",INDEX('Score Log'!$E:$E,$Q13)) | B13: =IF($Q13="","",INDEX('Score Log'!$C:$C,$Q13)) | C13: =IF($Q13="","",IF(INDEX('Score Log'!$D:$D,$Q13)="","",INDEX('Score Log'!$D:$D,$Q13))) | D13: =IF($B13="","",COUNTIFS('Score Log'!$C$4:$C$203,$B13,'Score Log'!$E$4:$E$203,$A13)) | E13: =IF($B13="","",IFERROR(ROUND(AVERAGEIFS('Score Log'!$F$4:$F$203,'Score Log'!$C$4:$C$203,$B13,'Score Log'!$E$4:$E$203,$A13),1),"-")) | F13: =IF($B13="","",IFERROR(ROUND(AVERAGEIFS('Score Log'!$H$4:$H$203,'Score Log'!$C$4:$C$203,$B13,'Score Log'!$E$4:$E$203,$A13),1),"-")) | G13: =IF($B13="","",IFERROR(ROUND(AVERAGEIFS('Score Log'!$J$4:$J$203,'Score Log'!$C$4:$C$203,$B13,'Score Log'!$E$4:$E$203,$A13),1),"-")) | H13: =IF($B13="","",IFERROR(ROUND(AVERAGEIFS('Score Log'!$L$4:$L$203,'Score Log'!$C$4:$C$203,$B13,'Score Log'!$E$4:$E$203,$A13),1),"-")) | I13: =IF($B13="","",IFERROR(ROUND(AVERAGEIFS('Score Log'!$N$4:$N$203,'Score Log'!$C$4:$C$203,$B13,'Score Log'!$E$4:$E$203,$A13),1),"-")) | J13: =IF(OR($B13="",$D13=0),"",IFERROR(COUNTIFS('Score Log'!$C$4:$C$203,$B13,'Score Log'!$E$4:$E$203,$A13,'Score Log'!$U$4:$U$203,"Yes")/$D13,"-")) | K13: =IF($B13="","",IF(ISNUMBER($F13),MAX(1,MIN(5,ROUND(6-$F13,0))),"-")) | L13: =IF($B13="","",IF(ISNUMBER($G13),MAX(1,MIN(5,ROUND(6-$G13,0))),"-")) | M13: =IF($B13="","",IF(AND(ISNUMBER($P13),ISNUMBER($O13)),MAX(1,MIN(5,ROUND(6-AVERAGE($P13,$O13),0))),IF(ISNUMBER($P13),MAX(1,MIN(5,ROUND(6-$P13,0))),"-"))) | O13: =IF($B13="","",IFERROR(AVERAGEIFS('Score Log'!$F$4:$F$203,'Score Log'!$C$4:$C$203,$B13),"")) | P13: =IF($B13="","",IFERROR(AVERAGEIFS('Score Log'!$L$4:$L$203,'Score Log'!$C$4:$C$203,$B13),"")) | Q13: =IFERROR(MATCH(ROW()-4,$AB$4:$AB$203,0)+3,"") | AA13: =IF(OR('Score Log'!$C13="",'Score Log'!$E13=""),0,IF(COUNTIFS('Score Log'!$C$4:$C13,'Score Log'!$C13,'Score Log'!$E$4:$E13,'Score Log'!$E13)=1,1,0)) -> 0 | AB13: =IF($AA13=1,SUM($AA$4:$AA13),"")
