Workbook

Sheet README
B2: Prompt Template Configurator
B3: v1.1 · August 2026 · owner Oscar Penny · generated from prompt-library/taxonomy/ (the source of truth — edit there, rebuild with src/build_configurator_xlsx.py)
B5: How to use
B6: START ON THE Tasks SHEET: pick one of the five course tasks, mark the requirements you need Yes, edit the yellow wording, and copy the assembled prompt (or the course prompt directly). The sheets below are the advanced, element-level builder.
B7: 1. Advanced: open Builder_Gen (chat prompts) or Builder_Agent (agent mission briefs).
B8: 2. Fill the YELLOW cells only: pick options from the dropdowns; add or override with custom text. Attributes marked "choice 1/2/3" accept several picks.
B9: 3. The prompt assembles itself on Prompt_Gen / Prompt_Agent — copy cell A4 into your AI tool.
B10: 4. Search the assembled prompt for {{ before you run — placeholders left unfilled mean you are not done.
B12: Legend
B13: YELLOW fill = cells you edit (dropdown choice, custom text). Everything else is generated — leave it.
B14: ★ next to an element name = keep this element; it is what makes the prompt reliable.
B15: The Options sheet is the full menu with guidance (core + extended); Taxonomy defines every element.
... B20: Companion tools: Prompt_Template_Creator.html (the interactive builder — same taxonomy, richer experience) · Prompt_Element_Taxonomy_Reference.pdf (the printed ontology).

Sheet Tasks
A1: THE FIVE COURSE TASKS — mark Include? = Yes, edit the yellow wording, copy the ASSEMBLED PROMPT (column E). A simple task needs only a few rows.
A3: ANALYZE SPREADSHEET DATA
B4: The course prompt (copy-ready): | C4: Use Course_Workbook.xlsx, Data tab, detail rows only — exclude the TOTAL row (144 rows; one Inspection_Hours cell is "n/a": treat it as missing, not zero, and disclose it). One row = one month × site × supplier; period 2025-09 to 2026-08 inclusive. Question: which supplier has the highest RETURN RATE, defined as total Units_Returned ÷ total Units_Shipped per supplier over the full period — computed from sums, never by averaging monthly percentages. Keep Defects_Found separate from returns; do not add them together. Rank the three suppliers showing numerator and denominator, reconcile total shipped and returned against the TOTAL row, and state one limitation of the comparison. Then stop.
B5: Your task line (edit): | C5: Help [reader] decide [decision] using [file / sheet], period [range], detail rows only.
A6: Include? | B6: Requirement type | C6: Your instruction (edit) | D6: How to check it
A7: No | B7: Row grain | C7: State that each detail row is a month–site–supplier observation. | D7: Confirm grouping keys before aggregation. | F7: =IF(AND($A7="Yes",$C7<>""),"- "&$C7,"") | G7: =IF($A7="Yes","- "&$D7,"")
A8: No | B8: Reporting period | C8: Use an explicit inclusive month range from Month. | D8: Check the first and last included months. | F8: =IF(AND($A8="Yes",$C8<>""),"- "&$C8,"") | G8: =IF($A8="Yes","- "&$D8,"")
A9: No | B9: Field types and units | C9: Treat Month as a month; identify counts, percentages, hours, and currency. | D9: Check parsing and unit labels. | F9: =IF(AND($A9="Yes",$C9<>""),"- "&$C9,"") | G9: =IF($A9="Yes","- "&$D9,"")
A10: No | B10: Duplicates and summary rows | C10: Exclude the existing TOTAL row and investigate duplicate keys. | D10: Compare row counts and a duplicate-key report. | F10: =IF(AND($A10="Yes",$C10<>""),"- "&$C10,"") | G10: =IF($A10="Yes","- "&$D10,"")
A11: No | B11: Metric definition | C11: Define return rate as sum of Units_Returned divided by sum of Units_Shipped. | D11: Recompute the numerator, denominator, and displayed rate. | F11: =IF(AND($A11="Yes",$C11<>""),"- "&$C11,"") | G11: =IF($A11="Yes","- "&$D11,"")
A12: No | B12: Weighting and denominators | C12: Do not infer overall on-time delivery from monthly percentages without delivery counts. | D12: Flag the missing denominator instead of claiming an overall rate. | F12: =IF(AND($A12="Yes",$C12<>""),"- "&$C12,"") | G12: =IF($A12="Yes","- "&$D12,"")
A13: No | B13: Missing and invalid values | C13: Retain the missing Inspection_Hours value; disclose any exclusion. | D13: Inspect missing-value counts and affected calculations. | F13: =IF(AND($A13="Yes",$C13<>""),"- "&$C13,"") | G13: =IF($A13="Yes","- "&$D13,"")
A14: No | B14: Segmentation and comparison | C14: Compare suppliers on the same selected period and sites. | D14: Confirm equal filter scope for each comparison. | F14: =IF(AND($A14="Yes",$C14<>""),"- "&$C14,"") | G14: =IF($A14="Yes","- "&$D14,"")
A15: No | B15: Rounding and number formats | C15: Display return rates to three decimal places while retaining calculation precision. | D15: Check displayed 0.348% against the underlying ratio. | F15: =IF(AND($A15="Yes",$C15<>""),"- "&$C15,"") | G15: =IF($A15="Yes","- "&$D15,"")
A16: No | B16: Formula traceability | C16: Use inspectable formulas or an included calculation log. | D16: Trace one output to its input rows. | F16: =IF(AND($A16="Yes",$C16<>""),"- "&$C16,"") | G16: =IF($A16="Yes","- "&$D16,"")
A17: No | B17: Structure and usability | C17: Provide a scorecard tab and a definitions tab with meaningful headers. | D17: Open both tabs and identify the measure without outside explanation. | F17: =IF(AND($A17="Yes",$C17<>""),"- "&$C17,"") | G17: =IF($A17="Yes","- "&$D17,"")
A18: No | B18: Verification and limitations | C18: Reconcile counts and sums; distinguish association from a causal explanation. | D18: Compare totals and challenge unsupported explanations. | F18: =IF(AND($A18="Yes",$C18<>""),"- "&$C18,"") | G18: =IF($A18="Yes","- "&$D18,"")
A19: No | B19: Delivery and portability | C19: Deliver an editable Excel workbook (.xlsx) with no broken external references. | D19: Open the file in the intended spreadsheet application. | F19: =IF(AND($A19="Yes",$C19<>""),"- "&$C19,"") | G19: =IF($A19="Yes","- "&$D19,"")
B20: Free-form additions (optional):
B21: ASSEMBLED PROMPT → | E21: =_xlfn.TEXTJOIN(CHAR(10)&CHAR(10),TRUE(),C5,IF(_xlfn.TEXTJOIN(CHAR(10),TRUE(),F7:F19)="","","Requirements:"&CHAR(10)&_xlfn.TEXTJOIN(CHAR(10),TRUE(),F7:F19)),IF(C20="","","Also:"&CHAR(10)&C20),IF(_xlfn.TEXTJOIN(CHAR(10),TRUE(),G7:G19)="","","How I will check the result:"&CHAR(10)&_xlfn.TEXTJOIN(CHAR(10),TRUE(),G7:G19))) -> Help [reader] decide [decision] using [file / sheet], period [range], detail rows only.
A23: BUILD AN INTERACTIVE DASHBOARD
B24: The course prompt (copy-ready): | C24: From the attached data file, build ONE self-contained HTML file that works offline from disk. Views: summary tiles, one chart, and a sortable table of the records — data embedded, every number computed from the embedded records, metric definitions and the snapshot date in the footer. Controls, wired so one selection re-scopes every view: a month-range selector with inclusive endpoints · category multi-select filters · a comparison switch · a monthly/quarterly granularity switch · a metric selector · drill-down from a chart segment to its underlying records · ranking on the selected measure · Reset. Show active selections; an empty selection says "no matching records"; missing values stay blank; a zero denominator shows "—". Label the file a static data snapshot with its date.
B25: Your task line (edit): | C25: A self-contained offline dashboard for [audience] to explore [data] and answer [question].
A26: Include? | B26: Requirement type | C26: Your instruction (edit) | D26: How to check it
A27: No | B27: Input contract | C27: Embed the checked supplier detail data and identify the snapshot date. | D27: Compare record count and source identifiers. | F27: =IF(AND($A27="Yes",$C27<>""),"- "&$C27,"") | G27: =IF($A27="Yes","- "&$D27,"")
A28: No | B28: Date range | C28: Use month selectors matching the source granularity; include both endpoints. | D28: Test a single month and the full range. | F28: =IF(AND($A28="Yes",$C28<>""),"- "&$C28,"") | G28: =IF($A28="Yes","- "&$D28,"")
A29: No | B29: Category controls | C29: Offer Supplier and Site multi-select controls; Type or Class requires a real source field. | D29: Compare each option with actual distinct values. | F29: =IF(AND($A29="Yes",$C29<>""),"- "&$C29,"") | G29: =IF($A29="Yes","- "&$D29,"")
A30: No | B30: Grouping and granularity | C30: Allow grouping by supplier, site, or month when relevant to the decision. | D30: Check counts and totals after changing the grouping. | F30: =IF(AND($A30="Yes",$C30<>""),"- "&$C30,"") | G30: =IF($A30="Yes","- "&$D30,"")
A31: No | B31: Metric selection | C31: Offer named measures with definitions and units. | D31: Verify that labels, scales, and calculations all change together. | F31: =IF(AND($A31="Yes",$C31<>""),"- "&$C31,"") | G31: =IF($A31="Yes","- "&$D31,"")
A32: No | B32: Filter combination | C32: Apply selected filters consistently, with an explicit AND/OR rule. | D32: Use a known intersection and compare included records. | F32: =IF(AND($A32="Yes",$C32<>""),"- "&$C32,"") | G32: =IF($A32="Yes","- "&$D32,"")
A33: No | B33: Coordinated views | C33: Charts, totals, and tables must represent the same selected records. | D33: Reconcile a chart total with its underlying table. | F33: =IF(AND($A33="Yes",$C33<>""),"- "&$C33,"") | G33: =IF($A33="Yes","- "&$D33,"")
A34: No | B34: Sorting and drill-down | C34: Sort numerically and allow inspection of supporting rows. | D34: Compare sorted order and inspect a selected group. | F34: =IF(AND($A34="Yes",$C34<>""),"- "&$C34,"") | G34: =IF($A34="Yes","- "&$D34,"")
A35: No | B35: Empty, missing, and zero states | C35: Distinguish no matching records from a valid zero; avoid division by zero. | D35: Exercise all three cases. | F35: =IF(AND($A35="Yes",$C35<>""),"- "&$C35,"") | G35: =IF($A35="Yes","- "&$D35,"")
A36: No | B36: Reset and visible state | C36: Show active selections and restore the default state with Reset. | D36: Change multiple controls, reset, and compare the initial view. | F36: =IF(AND($A36="Yes",$C36<>""),"- "&$C36,"") | G36: =IF($A36="Yes","- "&$D36,"")
A37: No | B37: Accessibility and layout | C37: Use labeled controls, visible focus, readable contrast, and a usable narrow layout. | D37: Navigate by keyboard and test a smaller window. | F37: =IF(AND($A37="Yes",$C37<>""),"- "&$C37,"") | G37: =IF($A37="Yes","- "&$D37,"")
A38: No | B38: Portability and dependencies | C38: Deliver one self-contained HyperText Markup Language (.html) file with embedded data and no required network calls. | D38: Open offline and inspect for missing assets. | F38: =IF(AND($A38="Yes",$C38<>""),"- "&$C38,"") | G38: =IF($A38="Yes","- "&$D38,"")
... A40: No | B40: Export and reconciliation | C40: If export is needed, export the filtered data and retain the chosen scope. | D40: Compare exported rows with the displayed selection. | F40: =IF(AND($A40="Yes",$C40<>""),"- "&$C40,"") | G40: =IF($A40="Yes","- "&$D40,"")
B41: Free-form additions (optional):
B42: ASSEMBLED PROMPT → | E42: =_xlfn.TEXTJOIN(CHAR(10)&CHAR(10),TRUE(),C25,IF(_xlfn.TEXTJOIN(CHAR(10),TRUE(),F27:F40)="","","Requirements:"&CHAR(10)&_xlfn.TEXTJOIN(CHAR(10),TRUE(),F27:F40)),IF(C41="","","Also:"&CHAR(10)&C41),IF(_xlfn.TEXTJOIN(CHAR(10),TRUE(),G27:G40)="","","How I will check the result:"&CHAR(10)&_xlfn.TEXTJOIN(CHAR(10),TRUE(),G27:G40))) -> A self-contained offline dashboard for [audience] to explore [data] and answer [question].
A44: PREPARE A PRESENTATION
...

Sheet Options
A1: Mode | B1: Element | C1: Attribute | D1: Option | E1: Pick when | F1: Emits into the prompt | G1: Tier
A2: generative | B2: Role | C2: Identity / posture | D2: Careful analyst | E2: numbers, data, trends | F2: You are a careful analyst. | G2: core
A3: generative | B3: Role | C3: Identity / posture | D3: Precise editor | E3: improving text you supply | F3: You are a precise editor. | G3: core
A4: generative | B4: Role | C4: Identity / posture | D4: Demanding reviewer | E4: grading, evaluating, comparing | F4: You are a demanding but fair reviewer. | G4: core
A5: generative | B5: Role | C5: Identity / posture | D5: Executive presentation writer | E5: decks, summaries for leadership | F5: You are a presentation writer for executives. | G5: core
A6: generative | B6: Role | C6: Identity / posture | D6: Patient explainer | E6: teaching, onboarding material | F6: You are a patient explainer who never condescends. | G6: core
A7: generative | B7: Role | C7: Identity / posture | D7: Devil's advocate | E7: stress-testing a plan or decision | F7: You are a devil's advocate. | G7: core
A8: generative | B8: Role | C8: Identity / posture | D8: Meticulous document processor | E8: extraction, comparison, forms | F8: You are a meticulous document processor. | G8: core
A9: generative | B9: Role | C9: Identity / posture | D9: Cited researcher | E9: web/document research | F9: You are a researcher who cites every claim. | G9: core
A10: generative | B10: Role | C10: Identity / posture | D10: Business writer | E10: emails, memos, announcements | F10: You are an experienced business writer. | G10: extended
A11: generative | B11: Role | C11: Identity / posture | D11: Technical writer | E11: procedures, specs, documentation | F11: You are a technical writer who values precision over polish. | G11: extended
A12: generative | B12: Role | C12: Identity / posture | D12: Facilitator | E12: synthesizing group input, agendas | F12: You are a neutral facilitator. | G12: extended
... A288: agentic | B288: Reporting | C288: Report discipline | D288: Evidence required | E288: always | F288: Claims of success carry evidence: the command run and its output, or the re-opened file. | G288: core

Sheet Builder_Gen
A1: Element | B1: Attribute | C1: Guidance | D1: Your choice (dropdown) | E1: Custom text (overrides/adds) | F1: Emitted text (auto)
A2: Role | B2: Who is answering: identity, expertise posture, and checkable behavioral commitments.
B3: Identity / posture | C3: Pick the professional posture. It sets vocabulary, caution level, and what gets foregrounded — not IQ. WHY IT MATTERS: Sets the register the answer is written in — vocabulary, caution level, what gets foregrounded. Expert personas measurably improve domain description tasks, but a 162-persona study found no accuracy gain on factual questions: identity buys voice and focus, not IQ. (Salewski et al. 2023; Zheng et al. 2024) | D3: Careful analyst | F3: =IF($E3<>"",$E3,IF($D3="","",IFERROR(INDEX(Options!$F$2:$F$20,MATCH($D3,Options!$D$2:$D$20,0)),""))) -> You are a careful analyst.
B4: Domain expertise | C4: Name the field so the right vocabulary and priorities surface. This foregrounds knowledge — it does not create it. WHY IT MATTERS: Naming the field surfaces its vocabulary, defaults, and priorities — the answer starts from the right corner of the model's training instead of the generic middle. It foregrounds knowledge the model already has; it cannot create knowledge it lacks. (Salewski et al. 2023; vendor role guidance) | F4: =$E4 -> 0
B5: Behavioral commitments · choice 1 | C5: The checkable rules — the part of Role that actually changes output. Pick from the three families below. WHY IT MATTERS: The part of Role that measurably changes output: a behavioral rule is checkable line-by-line in the result, where a title is a vibe. Grounding-style rules are the documented lever for drastically reducing invented content. (Anthropic reduce-hallucinations guidance) | F5: =$E5 -> 0
B6: Behavioral commitments · choice 2 | F6: =$E6 -> 0
B7: Accuracy behaviors · choice 1 | C7: For anything with facts and numbers. WHY IT MATTERS: Training rewards a confident guess over an honest blank, so guessing is the default; accuracy rules re-open the abstain option. Compute-via-code exists because model arithmetic degrades sharply as numbers grow. (OpenAI 2025, why LMs hallucinate; Faith & Fate, NeurIPS 2023) | D7: Never invent | F7: =IF($E7<>"",$E7,IF($D7="","",IFERROR(INDEX(Options!$F$21:$F$25,MATCH($D7,Options!$D$21:$D$25,0)),""))) -> You never invent facts or numbers — missing is missing.
B8: Accuracy behaviors · choice 2 | F8: =IF($E8<>"",$E8,IF($D8="","",IFERROR(INDEX(Options!$F$21:$F$25,MATCH($D8,Options!$D$21:$D$25,0)),"")))
B9: Accuracy behaviors · choice 3 | F9: =IF($E9<>"",$E9,IF($D9="","",IFERROR(INDEX(Options!$F$21:$F$25,MATCH($D9,Options!$D$21:$D$25,0)),"")))
B10: Transparency behaviors · choice 1 | C10: Make the work auditable. WHY IT MATTERS: Stated assumptions and shown work convert an answer you must trust into one you can audit — errors surface at review, not downstream. Self-checking works only against concrete criteria like these; a bare 'are you sure?' can make answers worse. (Anthropic self-check guidance; Huang et al. 2024) | F10: =IF($E10<>"",$E10,IF($D10="","",IFERROR(INDEX(Options!$F$26:$F$30,MATCH($D10,Options!$D$26:$D$30,0)),"")))
B11: Transparency behaviors · choice 2 | F11: =IF($E11<>"",$E11,IF($D11="","",IFERROR(INDEX(Options!$F$26:$F$30,MATCH($D11,Options!$D$26:$D$30,0)),"")))
B12: Transparency behaviors · choice 3 | F12: =IF($E12<>"",$E12,IF($D12="","",IFERROR(INDEX(Options!$F$26:$F$30,MATCH($D12,Options!$D$26:$D$30,0)),"")))
B13: Style behaviors · choice 1 | C13: How it writes, stated as rules. WHY IT MATTERS: Style stated as rules survives; style stated as adjectives drifts. 'One idea per sentence' is enforceable and checkable in the output — 'write clearly' is re-interpreted on every run. (vendor format guidance; prompt-sensitivity research) | F13: =IF($E13<>"",$E13,IF($D13="","",IFERROR(INDEX(Options!$F$31:$F$34,MATCH($D13,Options!$D$31:$D$34,0)),"")))
B14: Style behaviors · choice 2 | F14: =IF($E14<>"",$E14,IF($D14="","",IFERROR(INDEX(Options!$F$31:$F$34,MATCH($D14,Options!$D$31:$D$34,0)),"")))
B15: Style behaviors · choice 3 | F15: =IF($E15<>"",$E15,IF($D15="","",IFERROR(INDEX(Options!$F$31:$F$34,MATCH($D15,Options!$D$31:$D$34,0)),"")))
B16: Stance | C16: The critical posture. Blind the model to your preference — it mirrors any side you reveal. WHY IT MATTERS: Models affirm users ~49% more than humans do and mirror whichever side you reveal — a single flattering exchange measurably raises the user's conviction. Declaring a neutral or adversarial stance up front pre-empts the mirror before it engages. (Cheng et al., Science 2026; Sharma et al. 2023) | F16: =IF($E16<>"",$E16,IF($D16="","",IFERROR(INDEX(Options!$F$35:$F$39,MATCH($D16,Options!$D$35:$D$39,0)),"")))
A17: Task ★ | B17: The single clear ask: verb + object + audience + success criterion.
B18: Action starter | C18: Each verb is a mini-template — pick one and fill its {{slots}}, or write your own statement below. WHY IT MATTERS: The verb is the operation: it selects what transformation runs on your material and what 'done' looks like. Google's guidance calls the task verb 'the most important component of a prompt' — vague verbs produce exploration instead of answers. (Google Workspace prompting guide) | D18: Analyze | F18: =IF($E18<>"",$E18,IF($D18="","",IFERROR(INDEX(Options!$F$40:$F$55,MATCH($D18,Options!$D$40:$D$55,0)),""))) -> Answer: {{the question, with metric and period — e.g., "what is X by group for Q2 vs the target"}}?
B19: Task statement | C19: Or write the ask yourself — one task, one sentence if you can manage it. WHY IT MATTERS: One task in one sentence is the highest-leverage clarity move: current reasoning models pay a real cost for ambiguity — they burn thinking tokens trying to reconcile vague or conflicting instructions instead of answering. (OpenAI GPT-5 guide; Anthropic 'be clear and direct') | E19: Example (replace): what is the return rate by site for Q2 vs the 2.0% target? | F19: =$E19 -> Example (replace): what is the return rate by site for Q2 vs the 2.0% target?
B20: Audience | C20: Who receives this and what they already know. It sets altitude and vocabulary. WHY IT MATTERS: Audience re-ranks and re-words the same content: what leads, what gets cut, which terms need expansion. Without one, the model writes for nobody in particular — the mid-distribution reader who doesn't exist in your building. (vendor Persona/Context frameworks) | F20: =IF($E20<>"",$E20,IF($D20="","",IFERROR(INDEX(Options!$F$56:$F$61,MATCH($D20,Options!$D$56:$D$61,0)),"")))
B21: Reader's time budget | C21: How long they'll actually give it — the honest constraint. WHY IT MATTERS: The honest constraint that forces compression: a 30-second reader gets the number and the ask; a 10-minute reader gets the reasoning. Left uncapped, models default to thorough — which the reader experiences as long. (practitioner consensus; length is a vendor API dial for this reason) | F21: =IF($E21<>"",$E21,IF($D21="","",IFERROR(INDEX(Options!$F$62:$F$64,MATCH($D21,Options!$D$62:$D$64,0)),"")))
B22: Reading level | C22: The Canvas-style slider, as options. Plain-language guidance targets 6th–8th grade for general audiences. WHY IT MATTERS: Vocabulary altitude is a dial the model follows reliably — and its default sits well above general-audience reading. Plain-language practice targets 6th–8th grade for mixed audiences; say the level and it lands there. (plain-language standards; style-prompting research) | F22: =IF($E22<>"",$E22,IF($D22="","",IFERROR(INDEX(Options!$F$65:$F$69,MATCH($D22,Options!$D$65:$D$69,0)),"")))
B23: Success criterion | C23: The task's own completion test — what must be true of the output. WHY IT MATTERS: A stated completion test gives the model a target to optimize toward and gives you a check to run afterward — the same mechanism that makes self-verification work: concrete criteria catch errors reliably; vague quality asks don't. (Anthropic self-check guidance) | F23: =IF($E23<>"",$E23,IF($D23="","",IFERROR(INDEX(Options!$F$70:$F$73,MATCH($D23,Options!$D$70:$D$73,0)),"")))
B24: Purpose — why it matters | C24: The decision or event this feeds. Models generalize from reasons — and it filters what matters. WHY IT MATTERS: Models generalize from reasons: 'no ellipses — this will be read aloud by text-to-speech' outperforms the bare rule, because the model extends the spirit to cases you didn't list. Purpose also filters relevance — it now knows what matters to the decision. (Anthropic explain-why guidance) | F24: =$E24 -> 0
B25: Sense check | C25: Have the model confirm understanding before doing the work — cheapest error catch there is. WHY IT MATTERS: A restate-before-work step catches a misread task at the cheapest possible point — before any output exists. It is the generative version of the agentic Phase-0 intake gate: pennies to fix here, a full redo after a polished wrong answer. (plan-approval gate pattern) | F25: =IF($E25<>"",$E25,IF($D25="","",IFERROR(INDEX(Options!$F$74:$F$76,MATCH($D25,Options!$D$74:$D$76,0)),"")))
A26: Context | B26: Everything true in your world that isn't in the training data — material, definitions, quirks, constraints, and the reasons behind rules.
B27: Raw material | C27: The stuff to work from. Long documents go FIRST in the final prompt, instructions after — and delimit so material is never mistaken for instructions. WHY IT MATTERS: Placement measurably matters: long documents at the TOP with the question at the END improved answers by up to ~30% in vendor testing, and accuracy sags for content buried in the middle of a long context. (Anthropic long-context guidance; Liu et al. 2023, lost in the middle) | F27: =IF($E27<>"",$E27,IF($D27="","",IFERROR(INDEX(Options!$F$77:$F$79,MATCH($D27,Options!$D$77:$D$79,0)),"")))
B28: Glossary — controlled vocabulary · choice 1 | C28: Terms with local meaning. For metrics: numerator, denominator, grain, inclusions/exclusions — or the model will compute its own version. WHY IT MATTERS: The model resolves every undefined term to its most common global meaning — not your local one. A metric card (numerator, denominator, grain, exclusions) replaces the single biggest source of wrong analytical answers: a guessed denominator. (hallucination mechanics; data-analysis field practice) | F28: =IF($E28<>"",$E28,IF($D28="","",IFERROR(INDEX(Options!$F$80:$F$80,MATCH($D28,Options!$D$80:$D$80,0)),"")))
B29: Glossary — controlled vocabulary · choice 2 | F29: =IF($E29<>"",$E29,IF($D29="","",IFERROR(INDEX(Options!$F$80:$F$80,MATCH($D29,Options!$D$80:$D$80,0)),"")))
B30: Known quirks → rules · choice 1 | C30: Every quirk you don't write down becomes a silent 'fix' the model invents. Pair each with its rule. WHY IT MATTERS: Every quirk you don't write down becomes a silent 'fix' the model invents — plausibility fills the gap, fluently. A quirk paired with its rule converts a hidden landmine into a followed instruction. (OpenAI 2025, why LMs hallucinate) | F30: =IF($E30<>"",$E30,IF($D30="","",IFERROR(INDEX(Options!$F$81:$F$87,MATCH($D30,Options!$D$81:$D$87,0)),"")))
B31: Known quirks → rules · choice 2 | F31: =IF($E31<>"",$E31,IF($D31="","",IFERROR(INDEX(Options!$F$81:$F$87,MATCH($D31,Options!$D$81:$D$87,0)),"")))
B32: Known quirks → rules · choice 3 | F32: =IF($E32<>"",$E32,IF($D32="","",IFERROR(INDEX(Options!$F$81:$F$87,MATCH($D32,Options!$D$81:$D$87,0)),"")))
B33: Constraints & sensitivities · choice 1 | C33: What must not happen — stated positively where possible, with the reason where it isn't obvious. WHY IT MATTERS: Positively-phrased constraints are followed more reliably than prohibitions — earlier models showed inverse scaling on negated instructions, and current vendor guidance remains 'tell it what TO do.' When you must forbid, attach the reason. (Anthropic guidance; Jang et al. 2022) | F33: =IF($E33<>"",$E33,IF($D33="","",IFERROR(INDEX(Options!$F$88:$F$92,MATCH($D33,Options!$D$88:$D$92,0)),"")))
B34: Constraints & sensitivities · choice 2 | F34: =IF($E34<>"",$E34,IF($D34="","",IFERROR(INDEX(Options!$F$88:$F$92,MATCH($D34,Options!$D$88:$D$92,0)),"")))
B35: Constraints & sensitivities · choice 3 | F35: =IF($E35<>"",$E35,IF($D35="","",IFERROR(INDEX(Options!$F$88:$F$92,MATCH($D35,Options!$D$88:$D$92,0)),"")))
B36: The why behind the rules | C36: Explain any non-obvious rule — "this will be read aloud, so no ellipses" outperforms "no ellipses." Models generalize from reasons. WHY IT MATTERS: The reason behind a rule is itself an instruction: models apply explained rules in spirit, not just letter, extending them to cases you didn't enumerate — the vendor docs state this generalization effect verbatim. (Anthropic best practices) | F36: =$E36 -> 0
A37: Format | B37: The output contract: shape, length, tone, and what must be in or out.
B38: Output type | C38: The deliverable's shape. Name the columns for tables, the sections for documents. WHY IT MATTERS: Naming the deliverable's shape — a table with these columns, a memo with these sections — removes the largest degree of freedom the model would otherwise spend guessing, and makes output land ready to use instead of ready to reformat. (all four vendor frameworks: Format / Expectations) | F38: =IF($E38<>"",$E38,IF($D38="","",IFERROR(INDEX(Options!$F$93:$F$107,MATCH($D38,Options!$D$93:$D$107,0)),"")))
B39: Structure rules · choice 1 | C39: The internal skeleton — where the answer sits, what every section carries. WHY IT MATTERS: Trivial format differences swing measured accuracy by up to 76 points across phrasings — structure is not cosmetic. A fixed, tested skeleton removes that variance and puts the answer where the reader looks first. (Sclar et al., ICLR 2024) | F39: =IF($E39<>"",$E39,IF($D39="","",IFERROR(INDEX(Options!$F$108:$F$113,MATCH($D39,Options!$D$108:$D$113,0)),"")))
B40: Structure rules · choice 2 | F40: =IF($E40<>"",$E40,IF($D40="","",IFERROR(INDEX(Options!$F$108:$F$113,MATCH($D40,Options!$D$108:$D$113,0)),"")))
...

Sheet Builder_Agent
A1: Element | B1: Attribute | C1: Guidance | D1: Your choice (dropdown) | E1: Custom text (overrides/adds) | F1: Emitted text (auto)
A2: Role | B2: The standing behavioral contract — biases hundreds of unsupervised decisions, not one answer.
B3: Working posture | C3: The job-shaped identity. Compound postures (engineer + analyst + writer) prevent single-lens blind spots. WHY IT MATTERS: An agent's posture persists across hundreds of unsupervised decisions, so it must be job-shaped, not title-shaped. Compound postures (engineer + analyst + writer) prevent the single-lens failure where every problem gets one discipline's answer. (agent-design practice; Anthropic agent guidance) | F3: =IF($E3<>"",$E3,IF($D3="","",IFERROR(INDEX(Options!$F$176:$F$180,MATCH($D3,Options!$D$176:$D$180,0)),"")))
B4: Standing behaviors · choice 1 | C4: The rules that must survive hour three of a long run. WHY IT MATTERS: Long runs outlive their own context — what was said in minute one has faded by hour three. Standing behaviors are the conduct that must hold when nothing recent reinforces it, which is why harness guidance bakes rules into re-read files rather than conversation. (Anthropic long-running-agents harness) | F4: =IF($E4<>"",$E4,IF($D4="","",IFERROR(INDEX(Options!$F$181:$F$186,MATCH($D4,Options!$D$181:$D$186,0)),"")))
B5: Standing behaviors · choice 2 | F5: =IF($E5<>"",$E5,IF($D5="","",IFERROR(INDEX(Options!$F$181:$F$186,MATCH($D5,Options!$D$181:$D$186,0)),"")))
B6: Standing behaviors · choice 3 | F6: =IF($E6<>"",$E6,IF($D6="","",IFERROR(INDEX(Options!$F$181:$F$186,MATCH($D6,Options!$D$181:$D$186,0)),"")))
B7: Standing behaviors · choice 4 | F7: =IF($E7<>"",$E7,IF($D7="","",IFERROR(INDEX(Options!$F$181:$F$186,MATCH($D7,Options!$D$181:$D$186,0)),"")))
A8: Mission ★ | B8: The goal and the definition of done — the loop's exit condition.
B9: Goal | C9: One sentence: the question to answer or the thing to produce. WHY IT MATTERS: One goal sentence is the loop's objective function: gather → act → verify → repeat runs 'until the goal is met.' Two goals in one brief make every prioritization a coin-flip you never see. (Anthropic agent-loop framing) | F9: =$E9 -> 0
B10: Decision it supports | C10: What someone will do differently depending on the answer — filters everything downstream. WHY IT MATTERS: Naming the decision the work supports filters everything downstream — which findings matter, what precision suffices, what is noise. It is the brief-level relevance guardrail: scope drift dies here. (OpenAI relevance-guardrail concept; mission-brief practice) | F10: =$E10 -> 0
B11: Audience & deadline | C11: Who sees it, how long they'll give it, and when it's due. WHY IT MATTERS: Audience and deadline set the depth-versus-speed tradeoffs the agent will otherwise make for you, silently. A 30-second executive read and a hard due date change method choices all the way down the pipeline. (practitioner consensus) | F11: =$E11 -> 0
B12: Cadence | C12: One-off or recurring changes the economics: recurring jobs get standing briefs. WHY IT MATTERS: One-off versus recurring changes the economics of the whole brief: recurring jobs justify standing briefs, delta reporting, and versioned definitions — where agentic prompting pays compound interest. (reuse-by-diff pattern; AGENTS.md practice) | F12: =IF($E12<>"",$E12,IF($D12="","",IFERROR(INDEX(Options!$F$187:$F$188,MATCH($D12,Options!$D$187:$D$188,0)),"")))
B13: Done looks like | C13: The deliverables in one line — exact and countable. WHY IT MATTERS: The loop needs an exit condition it can evaluate. 'Done looks like: three files, named thus' is countable; without it agents stop early or run forever — the documented failure that structured task lists with pass flags exist to prevent. (Anthropic harness: feature-list pattern) | F13: =$E13 -> 0
B14: Verifiable by · choice 1 | C14: The check the agent can actually run to know it's done — the single highest-leverage line in an agentic prompt. WHY IT MATTERS: The single highest-leverage line in a brief. The vendor's own rule for long-running agents: mark work complete 'only after end-to-end verification confirms it works, not when the code is written.' A done-check the agent can run converts 'I finished' into 'it passed.' (Anthropic memory-tool guidance, verbatim) | F14: =IF($E14<>"",$E14,IF($D14="","",IFERROR(INDEX(Options!$F$189:$F$193,MATCH($D14,Options!$D$189:$D$193,0)),"")))
B15: Verifiable by · choice 2 | F15: =IF($E15<>"",$E15,IF($D15="","",IFERROR(INDEX(Options!$F$189:$F$193,MATCH($D15,Options!$D$189:$D$193,0)),"")))
B16: Verifiable by · choice 3 | F16: =IF($E16<>"",$E16,IF($D16="","",IFERROR(INDEX(Options!$F$189:$F$193,MATCH($D16,Options!$D$189:$D$193,0)),"")))
A17: Context | B17: Tribal knowledge, written down — the agent steps on every unstated quirk.
B18: Domain in three sentences | C18: The process, the actors, what 'good' means. WHY IT MATTERS: Three sentences of process, actors, and what 'good' means give every downstream judgment a frame. Without them the agent optimizes for generic best practice — generically right, specifically wrong for your operation. (context-element mechanics) | F18: =$E18 -> 0
B19: Glossary (controlled vocabulary) · choice 1 | C19: Every metric as a card: numerator, denominator, grain, inclusions, exclusions. The agent will otherwise compute three subtly different versions. WHY IT MATTERS: An agent touches every source repeatedly: a guessed denominator doesn't make one wrong sentence — it propagates through every transformation, chart, and slide of the run. Metric cards make definitions load-bearing once and correct everywhere. (source-register discipline; pipeline field practice) | F19: =IF($E19<>"",$E19,IF($D19="","",IFERROR(INDEX(Options!$F$194:$F$194,MATCH($D19,Options!$D$194:$D$194,0)),"")))
B20: Glossary (controlled vocabulary) · choice 2 | F20: =IF($E20<>"",$E20,IF($D20="","",IFERROR(INDEX(Options!$F$194:$F$194,MATCH($D20,Options!$D$194:$D$194,0)),"")))
B21: Entities & identifiers | C21: Part numbers, site names, aliases, vendor codes — spelled the way the audience spells them. WHY IT MATTERS: Exact identifiers, spelled the way the audience spells them, prevent silent fuzzy matching — the join on 'almost the same part number' that poisons a dataset without raising an error. Enumerated entities turn matching into lookup. (data-pipeline practice) | F21: =$E21 -> 0
B22: Known quirks → rules · choice 1 | C22: Things that have bitten before, each with the rule that disarms it. WHY IT MATTERS: Each known quirk with its disarming rule converts institutional scar tissue into instructions. Undocumented, the same quirk gets 'fixed' differently every run — plausibly, silently, and sometimes destructively. (hallucination mechanics applied to data) | F22: =IF($E22<>"",$E22,IF($D22="","",IFERROR(INDEX(Options!$F$195:$F$198,MATCH($D22,Options!$D$195:$D$198,0)),"")))
B23: Known quirks → rules · choice 2 | F23: =IF($E23<>"",$E23,IF($D23="","",IFERROR(INDEX(Options!$F$195:$F$198,MATCH($D23,Options!$D$195:$D$198,0)),"")))
B24: Targets & prior work | C24: Thresholds that matter, and files or decisions the output must stay consistent with. WHY IT MATTERS: Thresholds and previously-published numbers are the run's consistency constraints: they anchor new output to figures the organization already trusts and make drift a detectable event instead of a surprise in a meeting. (reconciliation-anchor family) | F24: =$E24 -> 0
A25: Environment ★ | B25: The workspace contract: where the agent may read, where it must write, what is forbidden.
B26: Workspace | C26: Repo/folder and branch. One initiative, one folder. WHY IT MATTERS: One initiative, one folder is blast-radius design: everything the run touches is enumerable, backupable, revertable. It also makes sessions reproducible — harness practice starts every session by re-reading the same workspace. (Anthropic harness: per-session ritual) | F26: =$E26 -> 0
B27: Read/write boundaries · choice 1 | C27: The three-zone layout: immutable inputs, versioned outputs, regenerable scratch. WHY IT MATTERS: The three-zone layout engineers reversibility in before any action runs: immutable inputs can't be corrupted, versioned outputs can't be silently overwritten, scratch is disposable by contract. Vendor tooling enforces the same idea as protected paths and blocked destructive commands. (Claude Code permission modes; git-revert harness practice) | F27: =IF($E27<>"",$E27,IF($D27="","",IFERROR(INDEX(Options!$F$199:$F$201,MATCH($D27,Options!$D$199:$D$201,0)),"")))
B28: Read/write boundaries · choice 2 | F28: =IF($E28<>"",$E28,IF($D28="","",IFERROR(INDEX(Options!$F$199:$F$201,MATCH($D28,Options!$D$199:$D$201,0)),"")))
B29: Tools allowed · choice 1 | C29: Name what exists. Anything unnamed is a guess. WHY IT MATTERS: Least privilege starts with naming what exists — anything unnamed is a guess the agent may make for you. Published guidance risk-rates every tool (low/medium/high) by write access, reversibility, and impact; the allowed list is where that rating lives. (OpenAI practical guide, tool safeguards) | F29: =IF($E29<>"",$E29,IF($D29="","",IFERROR(INDEX(Options!$F$202:$F$206,MATCH($D29,Options!$D$202:$D$206,0)),"")))
B30: Tools allowed · choice 2 | F30: =IF($E30<>"",$E30,IF($D30="","",IFERROR(INDEX(Options!$F$202:$F$206,MATCH($D30,Options!$D$202:$D$206,0)),"")))
B31: Tools allowed · choice 3 | F31: =IF($E31<>"",$E31,IF($D31="","",IFERROR(INDEX(Options!$F$202:$F$206,MATCH($D31,Options!$D$202:$D$206,0)),"")))
B32: Forbidden actions · choice 1 | C32: The explicit denylist — name what would be assumed available otherwise. WHY IT MATTERS: An explicit denylist beats an implied one because evaluation order is deny-first: what is forbidden stays forbidden regardless of what else allows it. Name what would otherwise be assumed available — email, deletion, posting. (permission-rule precedence: deny > ask > allow) | F32: =IF($E32<>"",$E32,IF($D32="","",IFERROR(INDEX(Options!$F$207:$F$212,MATCH($D32,Options!$D$207:$D$212,0)),"")))
B33: Forbidden actions · choice 2 | F33: =IF($E33<>"",$E33,IF($D33="","",IFERROR(INDEX(Options!$F$207:$F$212,MATCH($D33,Options!$D$207:$D$212,0)),"")))
B34: Forbidden actions · choice 3 | F34: =IF($E34<>"",$E34,IF($D34="","",IFERROR(INDEX(Options!$F$207:$F$212,MATCH($D34,Options!$D$207:$D$212,0)),"")))
B35: Confidentiality · choice 1 | C35: What may leave the workspace, and in what form. WHY IT MATTERS: The documented exfiltration pattern needs three legs at once: private data, untrusted content, and an outbound channel. The confidentiality clause removes or narrows the outbound leg — say what may leave the workspace, and in what form. (lethal-trifecta analysis; PII-filter guardrails) | F35: =IF($E35<>"",$E35,IF($D35="","",IFERROR(INDEX(Options!$F$213:$F$215,MATCH($D35,Options!$D$213:$D$215,0)),"")))
B36: Confidentiality · choice 2 | F36: =IF($E36<>"",$E36,IF($D36="","",IFERROR(INDEX(Options!$F$213:$F$215,MATCH($D36,Options!$D$213:$D$215,0)),"")))
B37: Action risk policy · choice 1 | C37: How actions are triaged by consequence — the published patterns. WHY IT MATTERS: Triaging actions by consequence is the published pattern on both major stacks: reversible proceeds, irreversible asks — operationalized as low/medium/high tool ratings and never/maybe/always-irreversible action classes. (OpenAI practical guide; Magentic-UI action guards) | F37: =IF($E37<>"",$E37,IF($D37="","",IFERROR(INDEX(Options!$F$216:$F$218,MATCH($D37,Options!$D$216:$D$218,0)),"")))
B38: Action risk policy · choice 2 | F38: =IF($E38<>"",$E38,IF($D38="","",IFERROR(INDEX(Options!$F$216:$F$218,MATCH($D38,Options!$D$216:$D$218,0)),"")))
A39: Inputs | B39: The source register: each source's location, format, grain, trust level, and known issues.
B40: Source register | C40: One block per source. The skeleton below is the discipline — fill every line or write UNKNOWN. WHY IT MATTERS: A source register makes every input's location, format, grain, and meaning explicit before anything is computed — profiling before processing. Skipped, the first wrong assumption about what one row means propagates through the entire run. (ETL discipline) | F40: =$E40 -> 0
...

Sheet Prompt_Gen
A1: ASSEMBLED GENERATIVE PROMPT — copy cell A4 (it recalculates from Builder_Gen)
A2: Fill the yellow cells on the builder sheet; blank rows are skipped automatically. Search the result for {{ — unfilled placeholders mean you are not done.
A4: =_xlfn.TEXTJOIN(CHAR(10)&CHAR(10),TRUE(),$C$4,$C$5,$C$6,$C$7,$C$8,$C$9,$C$10) -> <role> You are a careful analyst. You never invent facts or numbers — missing is missing. </role> <task> Answer: {{the question, with metric and period — e.g., "what is X by group for Q2 vs the target"}}? Example (replace): what is the return rate by site for Q2 vs the 2.0% target? </task> | C4: =IF(_xlfn.TEXTJOIN(CHAR(10),TRUE(),Builder_Gen!$F$2:$F$16)="","","<role>"&CHAR(10)&_xlfn.TEXTJOIN(CHAR(10),TRUE(),Builder_Gen!$F$2:$F$16)&CHAR(10)&"</role>") -> <role> You are a careful analyst. You never invent facts or numbers — missing is missing. </role>
C5: =IF(_xlfn.TEXTJOIN(CHAR(10),TRUE(),Builder_Gen!$F$17:$F$25)="","","<task>"&CHAR(10)&_xlfn.TEXTJOIN(CHAR(10),TRUE(),Builder_Gen!$F$17:$F$25)&CHAR(10)&"</task>") -> <task> Answer: {{the question, with metric and period — e.g., "what is X by group for Q2 vs the target"}}? Example (replace): what is the return rate by site for Q2 vs the 2.0% target? </task>
C6: =IF(_xlfn.TEXTJOIN(CHAR(10),TRUE(),Builder_Gen!$F$26:$F$36)="","","<context>"&CHAR(10)&_xlfn.TEXTJOIN(CHAR(10),TRUE(),Builder_Gen!$F$26:$F$36)&CHAR(10)&"</context>")
C7: =IF(_xlfn.TEXTJOIN(CHAR(10),TRUE(),Builder_Gen!$F$37:$F$52)="","","<format>"&CHAR(10)&_xlfn.TEXTJOIN(CHAR(10),TRUE(),Builder_Gen!$F$37:$F$52)&CHAR(10)&"</format>")
C8: =IF(_xlfn.TEXTJOIN(CHAR(10),TRUE(),Builder_Gen!$F$53:$F$58)="","","<examples>"&CHAR(10)&_xlfn.TEXTJOIN(CHAR(10),TRUE(),Builder_Gen!$F$53:$F$58)&CHAR(10)&"</examples>")
C9: =IF(_xlfn.TEXTJOIN(CHAR(10),TRUE(),Builder_Gen!$F$59:$F$63)="","","<uncertainty_rules>"&CHAR(10)&_xlfn.TEXTJOIN(CHAR(10),TRUE(),Builder_Gen!$F$59:$F$63)&CHAR(10)&"</uncertainty_rules>")
C10: =IF(_xlfn.TEXTJOIN(CHAR(10),TRUE(),Builder_Gen!$F$64:$F$67)="","","<scope>"&CHAR(10)&_xlfn.TEXTJOIN(CHAR(10),TRUE(),Builder_Gen!$F$64:$F$67)&CHAR(10)&"</scope>")

Sheet Prompt_Agent
A1: ASSEMBLED AGENTIC PROMPT — copy cell A4 (it recalculates from Builder_Agent)
A2: Fill the yellow cells on the builder sheet; blank rows are skipped automatically. Search the result for {{ — unfilled placeholders mean you are not done.
A4: =_xlfn.TEXTJOIN(CHAR(10)&CHAR(10),TRUE(),$C$4,$C$5,$C$6,$C$7,$C$8,$C$9,$C$10,$C$11,$C$12,$C$13,$C$14,$C$15) | C4: =IF(_xlfn.TEXTJOIN(CHAR(10),TRUE(),Builder_Agent!$F$2:$F$7)="","","<role>"&CHAR(10)&_xlfn.TEXTJOIN(CHAR(10),TRUE(),Builder_Agent!$F$2:$F$7)&CHAR(10)&"</role>")
C5: =IF(_xlfn.TEXTJOIN(CHAR(10),TRUE(),Builder_Agent!$F$8:$F$16)="","","<mission>"&CHAR(10)&_xlfn.TEXTJOIN(CHAR(10),TRUE(),Builder_Agent!$F$8:$F$16)&CHAR(10)&"</mission>")
C6: =IF(_xlfn.TEXTJOIN(CHAR(10),TRUE(),Builder_Agent!$F$17:$F$24)="","","<context>"&CHAR(10)&_xlfn.TEXTJOIN(CHAR(10),TRUE(),Builder_Agent!$F$17:$F$24)&CHAR(10)&"</context>")
C7: =IF(_xlfn.TEXTJOIN(CHAR(10),TRUE(),Builder_Agent!$F$25:$F$38)="","","<environment>"&CHAR(10)&_xlfn.TEXTJOIN(CHAR(10),TRUE(),Builder_Agent!$F$25:$F$38)&CHAR(10)&"</environment>")
C8: =IF(_xlfn.TEXTJOIN(CHAR(10),TRUE(),Builder_Agent!$F$39:$F$43)="","","<inputs>"&CHAR(10)&_xlfn.TEXTJOIN(CHAR(10),TRUE(),Builder_Agent!$F$39:$F$43)&CHAR(10)&"</inputs>")
C9: =IF(_xlfn.TEXTJOIN(CHAR(10),TRUE(),Builder_Agent!$F$44:$F$51)="","","<plan>"&CHAR(10)&_xlfn.TEXTJOIN(CHAR(10),TRUE(),Builder_Agent!$F$44:$F$51)&CHAR(10)&"</plan>")
C10: =IF(_xlfn.TEXTJOIN(CHAR(10),TRUE(),Builder_Agent!$F$52:$F$60)="","","<checks>"&CHAR(10)&_xlfn.TEXTJOIN(CHAR(10),TRUE(),Builder_Agent!$F$52:$F$60)&CHAR(10)&"</checks>")
C11: =IF(_xlfn.TEXTJOIN(CHAR(10),TRUE(),Builder_Agent!$F$61:$F$66)="","","<outputs>"&CHAR(10)&_xlfn.TEXTJOIN(CHAR(10),TRUE(),Builder_Agent!$F$61:$F$66)&CHAR(10)&"</outputs>")
C12: =IF(_xlfn.TEXTJOIN(CHAR(10),TRUE(),Builder_Agent!$F$67:$F$76)="","","<process>"&CHAR(10)&_xlfn.TEXTJOIN(CHAR(10),TRUE(),Builder_Agent!$F$67:$F$76)&CHAR(10)&"</process>")
C13: =IF(_xlfn.TEXTJOIN(CHAR(10),TRUE(),Builder_Agent!$F$77:$F$81)="","","<rules>"&CHAR(10)&_xlfn.TEXTJOIN(CHAR(10),TRUE(),Builder_Agent!$F$77:$F$81)&CHAR(10)&"</rules>")
C14: =IF(_xlfn.TEXTJOIN(CHAR(10),TRUE(),Builder_Agent!$F$82:$F$85)="","","<quality_bar>"&CHAR(10)&_xlfn.TEXTJOIN(CHAR(10),TRUE(),Builder_Agent!$F$82:$F$85)&CHAR(10)&"</quality_bar>")
C15: =IF(_xlfn.TEXTJOIN(CHAR(10),TRUE(),Builder_Agent!$F$86:$F$92)="","","<reporting>"&CHAR(10)&_xlfn.TEXTJOIN(CHAR(10),TRUE(),Builder_Agent!$F$86:$F$92)&CHAR(10)&"</reporting>")

Sheet Taxonomy
A1: Mode | B1: Element | C1: OOP | D1: Definition | E1: Prevents
A2: generative | B2: Role | C2: class Role extends PromptElement | D2: Who is answering: identity, expertise posture, and checkable behavioral commitments. | E2: the generic-assistant voice; mid-distribution, hedge-everything output.
A3: generative | B3: Task | C3: class Task extends PromptElement | D3: The single clear ask: verb + object + audience + success criterion. | E3: wandering output — ten observations and no answer.
A4: generative | B4: Context | C4: class Context extends PromptElement | D4: Everything true in your world that isn't in the training data — material, definitions, quirks, constraints, and the reasons behind rules. | E4: generically-right, specifically-wrong output — the plausible number with your company's name on it.
A5: generative | B5: Format | C5: class Format extends PromptElement | D5: The output contract: shape, length, tone, and what must be in or out. | E5: the 3×-too-long draft; the buried answer; output you must re-shape by hand.
A6: generative | B6: Examples | C6: class Examples extends PromptElement | D6: 3–5 realistic demonstrations of the task done right — the strongest steering signal there is. | E6: the model guessing your standard from the internet's average; format drift across runs.
A7: generative | B7: The Out | C7: class TheOut extends SafetyValve | D7: The escape route for missing information: name the condition, the honest move, and how gaps surface — so the model never has to choose between obeying you and being honest. | E7: confident invention — the signature failure of factual work.
A8: generative | B8: The Stop | C8: class TheStop extends SafetyValve | D8: The scope boundary — converts open-ended capability into bounded work. | E8: scope sprawl; work continuing past the point of usefulness.
A9: agentic | B9: Role | C9: class AgentRole extends Role | D9: The standing behavioral contract — biases hundreds of unsupervised decisions, not one answer. | E9: an agent that improvises its professional standards mid-run.
A10: agentic | B10: Mission | C10: class Mission extends Task // + definitionOfDone | D10: The goal and the definition of done — the loop's exit condition. | E10: the agent deciding for itself what finished means — plausible activity, indefinitely.
A11: agentic | B11: Context | C11: class AgentContext extends Context // coverage pressure | D11: Tribal knowledge, written down — the agent steps on every unstated quirk. | E11: silent invented fixes — the most expensive agent error, because they look like diligence.
A12: agentic | B12: Environment | C12: class Environment extends PromptElement // NEW IN KIND | D12: The workspace contract: where the agent may read, where it must write, what is forbidden. | E12: the agent 'helpfully' editing your master file or wandering outside its folder.
... A20: agentic | B20: Reporting | C20: class Reporting extends Format // the interface back to you | D20: The fixed shape of the final message: status, headline, evidence, open items — under 25 lines. | E20: a narrative essay where a status should be.
