Workbook

Sheet Simple Schedule
A1: 6-Month Schedule — 24 × 27 in cut mesh
A2: ="1 roll = "&TEXT('Order Cadence'!B6,"#,##0")&" pcs · we use "&TEXT(Inputs!B26,"#,##0")&" pcs/week · order when on-hand + on-order ≤ "&TEXT('Order Cadence'!B16,"#,##0")&" · Trotter: "&Inputs!B28&" days at their end, "&Inputs!B30&" days door to door" -> 1 roll = 1,300 pcs · we use 250 pcs/week · order when on-hand + on-order ≤ 1,000 · Trotter: 14 days at their end, 20 days door to door
A3: ="TODAY "&TEXT(Inputs!B42,"m/d")&": "&TEXT(Inputs!B47,"#,##0")&" pcs on hand → RELEASE PO-0 NOW. At the standard turnaround it lands "&TEXT(Inputs!B57,"ddd m/d")&" with ~"&TEXT(Inputs!B60,"0")&" days of cover left — ask Trotter for the first available cut slot." -> TODAY 9/24: 937 pcs on hand → RELEASE PO-0 NOW. At the standard turnaround it lands Mon 10/19 with ~2 days of cover left — ask Trotter for the first available cut slot.
A5: Week of (Mon) | B5: Beginning inventory | C5: ORDER (release PO) | D5: TROTTER CUTS | E5: Roll received (pcs) | F5: Ending inventory | G5: Note
A6: ='6-Month Forecast'!B14 -> 46293 | B6: ='6-Month Forecast'!C14 -> 837 | C6: =IF('6-Month Forecast'!H14>0,"▲ Release PO-"&COUNTIF('6-Month Forecast'!$H$14:H14,">0")&" (1 roll)","") | D6: ='6-Month Forecast'!L14 | E6: =IF('6-Month Forecast'!D14>0,'6-Month Forecast'!D14,"") | F6: ='6-Month Forecast'!G14 -> 587 | G6: =IF('6-Month Forecast'!G14<0,"STOCKOUT",IF('6-Month Forecast'!G14<Inputs!$B$26,"⚠ under a week of cover — PO-0 must land by here",IF('6-Month Forecast'!D14>0,"Roll arrives (credited to this Monday)","")))
A7: ='6-Month Forecast'!B15 -> 46300 | B7: ='6-Month Forecast'!C15 -> 587 | C7: =IF('6-Month Forecast'!H15>0,"▲ Release PO-"&COUNTIF('6-Month Forecast'!$H$14:H15,">0")&" (1 roll)","") | D7: ='6-Month Forecast'!L15 | E7: =IF('6-Month Forecast'!D15>0,'6-Month Forecast'!D15,"") | F7: ='6-Month Forecast'!G15 -> 337 | G7: =IF('6-Month Forecast'!G15<0,"STOCKOUT",IF('6-Month Forecast'!G15<Inputs!$B$26,"⚠ under a week of cover — PO-0 must land by here",IF('6-Month Forecast'!D15>0,"Roll arrives (credited to this Monday)","")))
A8: ='6-Month Forecast'!B16 -> 46307 | B8: ='6-Month Forecast'!C16 -> 337 | C8: =IF('6-Month Forecast'!H16>0,"▲ Release PO-"&COUNTIF('6-Month Forecast'!$H$14:H16,">0")&" (1 roll)","") | D8: ='6-Month Forecast'!L16 -> ▶ PO-0 cut at Trotter | E8: =IF('6-Month Forecast'!D16>0,'6-Month Forecast'!D16,"") | F8: ='6-Month Forecast'!G16 -> 87 | G8: =IF('6-Month Forecast'!G16<0,"STOCKOUT",IF('6-Month Forecast'!G16<Inputs!$B$26,"⚠ under a week of cover — PO-0 must land by here",IF('6-Month Forecast'!D16>0,"Roll arrives (credited to this Monday)",""))) -> ⚠ under a week of cover — PO-0 must land by here
A9: ='6-Month Forecast'!B17 -> 46314 | B9: ='6-Month Forecast'!C17 -> 87 | C9: =IF('6-Month Forecast'!H17>0,"▲ Release PO-"&COUNTIF('6-Month Forecast'!$H$14:H17,">0")&" (1 roll)","") | D9: ='6-Month Forecast'!L17 | E9: =IF('6-Month Forecast'!D17>0,'6-Month Forecast'!D17,"") -> 1300 | F9: ='6-Month Forecast'!G17 -> 1137 | G9: =IF('6-Month Forecast'!G17<0,"STOCKOUT",IF('6-Month Forecast'!G17<Inputs!$B$26,"⚠ under a week of cover — PO-0 must land by here",IF('6-Month Forecast'!D17>0,"Roll arrives (credited to this Monday)",""))) -> Roll arrives (credited to this Monday)
A10: ='6-Month Forecast'!B18 -> 46321 | B10: ='6-Month Forecast'!C18 -> 1137 | C10: =IF('6-Month Forecast'!H18>0,"▲ Release PO-"&COUNTIF('6-Month Forecast'!$H$14:H18,">0")&" (1 roll)","") -> ▲ Release PO-1 (1 roll) | D10: ='6-Month Forecast'!L18 | E10: =IF('6-Month Forecast'!D18>0,'6-Month Forecast'!D18,"") | F10: ='6-Month Forecast'!G18 -> 887 | G10: =IF('6-Month Forecast'!G18<0,"STOCKOUT",IF('6-Month Forecast'!G18<Inputs!$B$26,"⚠ under a week of cover — PO-0 must land by here",IF('6-Month Forecast'!D18>0,"Roll arrives (credited to this Monday)","")))
A11: ='6-Month Forecast'!B19 -> 46328 | B11: ='6-Month Forecast'!C19 -> 887 | C11: =IF('6-Month Forecast'!H19>0,"▲ Release PO-"&COUNTIF('6-Month Forecast'!$H$14:H19,">0")&" (1 roll)","") | D11: ='6-Month Forecast'!L19 | E11: =IF('6-Month Forecast'!D19>0,'6-Month Forecast'!D19,"") | F11: ='6-Month Forecast'!G19 -> 637 | G11: =IF('6-Month Forecast'!G19<0,"STOCKOUT",IF('6-Month Forecast'!G19<Inputs!$B$26,"⚠ under a week of cover — PO-0 must land by here",IF('6-Month Forecast'!D19>0,"Roll arrives (credited to this Monday)","")))
A12: ='6-Month Forecast'!B20 -> 46335 | B12: ='6-Month Forecast'!C20 -> 637 | C12: =IF('6-Month Forecast'!H20>0,"▲ Release PO-"&COUNTIF('6-Month Forecast'!$H$14:H20,">0")&" (1 roll)","") | D12: ='6-Month Forecast'!L20 -> ▶ PO-1 cut at Trotter | E12: =IF('6-Month Forecast'!D20>0,'6-Month Forecast'!D20,"") | F12: ='6-Month Forecast'!G20 -> 387 | G12: =IF('6-Month Forecast'!G20<0,"STOCKOUT",IF('6-Month Forecast'!G20<Inputs!$B$26,"⚠ under a week of cover — PO-0 must land by here",IF('6-Month Forecast'!D20>0,"Roll arrives (credited to this Monday)","")))
A13: ='6-Month Forecast'!B21 -> 46342 | B13: ='6-Month Forecast'!C21 -> 387 | C13: =IF('6-Month Forecast'!H21>0,"▲ Release PO-"&COUNTIF('6-Month Forecast'!$H$14:H21,">0")&" (1 roll)","") | D13: ='6-Month Forecast'!L21 | E13: =IF('6-Month Forecast'!D21>0,'6-Month Forecast'!D21,"") -> 1300 | F13: ='6-Month Forecast'!G21 -> 1437 | G13: =IF('6-Month Forecast'!G21<0,"STOCKOUT",IF('6-Month Forecast'!G21<Inputs!$B$26,"⚠ under a week of cover — PO-0 must land by here",IF('6-Month Forecast'!D21>0,"Roll arrives (credited to this Monday)",""))) -> Roll arrives (credited to this Monday)
A14: ='6-Month Forecast'!B22 -> 46349 | B14: ='6-Month Forecast'!C22 -> 1437 | C14: =IF('6-Month Forecast'!H22>0,"▲ Release PO-"&COUNTIF('6-Month Forecast'!$H$14:H22,">0")&" (1 roll)","") | D14: ='6-Month Forecast'!L22 | E14: =IF('6-Month Forecast'!D22>0,'6-Month Forecast'!D22,"") | F14: ='6-Month Forecast'!G22 -> 1187 | G14: =IF('6-Month Forecast'!G22<0,"STOCKOUT",IF('6-Month Forecast'!G22<Inputs!$B$26,"⚠ under a week of cover — PO-0 must land by here",IF('6-Month Forecast'!D22>0,"Roll arrives (credited to this Monday)","")))
A15: ='6-Month Forecast'!B23 -> 46356 | B15: ='6-Month Forecast'!C23 -> 1187 | C15: =IF('6-Month Forecast'!H23>0,"▲ Release PO-"&COUNTIF('6-Month Forecast'!$H$14:H23,">0")&" (1 roll)","") -> ▲ Release PO-2 (1 roll) | D15: ='6-Month Forecast'!L23 | E15: =IF('6-Month Forecast'!D23>0,'6-Month Forecast'!D23,"") | F15: ='6-Month Forecast'!G23 -> 937 | G15: =IF('6-Month Forecast'!G23<0,"STOCKOUT",IF('6-Month Forecast'!G23<Inputs!$B$26,"⚠ under a week of cover — PO-0 must land by here",IF('6-Month Forecast'!D23>0,"Roll arrives (credited to this Monday)","")))
A16: ='6-Month Forecast'!B24 -> 46363 | B16: ='6-Month Forecast'!C24 -> 937 | C16: =IF('6-Month Forecast'!H24>0,"▲ Release PO-"&COUNTIF('6-Month Forecast'!$H$14:H24,">0")&" (1 roll)","") | D16: ='6-Month Forecast'!L24 | E16: =IF('6-Month Forecast'!D24>0,'6-Month Forecast'!D24,"") | F16: ='6-Month Forecast'!G24 -> 687 | G16: =IF('6-Month Forecast'!G24<0,"STOCKOUT",IF('6-Month Forecast'!G24<Inputs!$B$26,"⚠ under a week of cover — PO-0 must land by here",IF('6-Month Forecast'!D24>0,"Roll arrives (credited to this Monday)","")))
A17: ='6-Month Forecast'!B25 -> 46370 | B17: ='6-Month Forecast'!C25 -> 687 | C17: =IF('6-Month Forecast'!H25>0,"▲ Release PO-"&COUNTIF('6-Month Forecast'!$H$14:H25,">0")&" (1 roll)","") | D17: ='6-Month Forecast'!L25 -> ▶ PO-2 cut at Trotter | E17: =IF('6-Month Forecast'!D25>0,'6-Month Forecast'!D25,"") | F17: ='6-Month Forecast'!G25 -> 437 | G17: =IF('6-Month Forecast'!G25<0,"STOCKOUT",IF('6-Month Forecast'!G25<Inputs!$B$26,"⚠ under a week of cover — PO-0 must land by here",IF('6-Month Forecast'!D25>0,"Roll arrives (credited to this Monday)","")))
... A31: ='6-Month Forecast'!B39 -> 46468 | B31: ='6-Month Forecast'!C39 -> 1087 | C31: =IF('6-Month Forecast'!H39>0,"▲ Release PO-"&COUNTIF('6-Month Forecast'!$H$14:H39,">0")&" (1 roll)","") -> ▲ Release PO-5 (1 roll) | D31: ='6-Month Forecast'!L39 | E31: =IF('6-Month Forecast'!D39>0,'6-Month Forecast'!D39,"") | F31: ='6-Month Forecast'!G39 -> 837 | G31: =IF('6-Month Forecast'!G39<0,"STOCKOUT",IF('6-Month Forecast'!G39<Inputs!$B$26,"⚠ under a week of cover — PO-0 must land by here",IF('6-Month Forecast'!D39>0,"Roll arrives (credited to this Monday)","")))
A33: PO-0 (released today, 9/24) is not in the ORDER column because it goes out before the schedule starts; its cut week and receipt are shown. Detail behind every number: 6-Month Forecast, Cycle Time and PO Schedule tabs.

Sheet Handoff Summary
A1: Mesh Production Handoff — 24 × 27 in Cut Mesh
A2: Prepared Sep 24, 2026 (v5, pre-meeting) · Supplier: Trotter · Green values recalc live from the other tabs — this page is the one-screen brief for whoever owns replenishment. Cycle-time legs and dated PO milestones: Cycle Time and PO Schedule tabs.
A4: THE PART
A5: Piece (finished good) | B5: =Inputs!B5&" × "&Inputs!B6&" in cut mesh" -> 24 × 27 in cut mesh | D5: Part number TO BE CREATED in SAP — see Assumptions & Notes action items
A6: Price per piece | B6: =Inputs!B20 -> 0.41 | D6: Supplier quote; $106.60 invoice on the 150 ft delivery cross-checks exactly
A7: Supplier | B7: Trotter | D7: Cuts the pieces and slits the roll on their end
A8: Raw roll | B8: =Inputs!B10&" ft × "&Inputs!B12&" in" -> 750 ft × 101 in | D8: Cut as Orientation A (24″ across): 4 across × 333 along — best cut at 101″ width
A10: REQUIREMENTS
A11: Weekly production (pieces) | B11: ='Order Cadence'!B5 -> 250 | D11: ASSUMPTION — review at the supplier meeting; every number below scales with it
A12: Planning pieces per roll | B12: ='Yield per Roll'!B13 -> 1300 | D12: =TEXT('Yield per Roll'!B10,"#,##0")&" theoretical × "&TEXT(Inputs!B37,"0.0%")&" realized yield — backtracked from the 1,300-pc batch (last PO, one roll)" -> 1,332 theoretical × 97.6% realized yield — backtracked from the 1,300-pc batch (last PO, one roll)
A13: Coverage per roll (weeks) | B13: ='Order Cadence'!B8 -> 5.2
A14: YEARLY REQUIREMENT (pieces) | B14: ='Order Cadence'!B5*52 -> 13000
A15: Yearly requirement (rolls / POs) | B15: ='Order Cadence'!B10 -> 10
A16: Yearly spend (pieces) | B16: ='Order Cadence'!B5*52*Inputs!B20 -> 5330
A17: NEXT 6 MONTHS (pieces) | B17: ='Order Cadence'!B5*26 -> 6500
A18: Next 6 months (POs) | B18: ='6-Month Forecast'!B42 -> 5 | D18: Week-by-week schedule on the 6-Month Forecast tab; plus PO-0 released 9/24 (PO Schedule tab)
A20: REORDER POLICY
A21: Reorder point (pieces) | B21: ='Order Cadence'!B16 -> 1000 | D21: Release a PO when on-hand + on-order ≤ this (≈ 4 weeks of production)
A22: Order quantity (1 roll) | B22: ='Order Cadence'!B6 -> 1300
A23: Lead time | B23: =Inputs!B30&" days" -> 20 days | D23: ="Legs: "&Inputs!B27&" roll→Trotter + "&Inputs!B28&" at Trotter + "&Inputs!B29&" to us & put away = "&Inputs!B30&" days, planned as "&Inputs!B31&" wks · scenario: "&'Cycle Time'!B5&" — see Cycle Time & PO Schedule tabs" -> Legs: 3 roll→Trotter + 14 at Trotter + 3 to us & put away = 20 days, planned as 3 wks · scenario: Supplier standard — see Cycle Time & PO Schedule tabs
A24: Safety stock (pieces) | B24: =Inputs!B26*Inputs!B32 -> 250
A26: SUPPLIER (TROTTER) PROVIDED INFORMATION — email 9/24/2026
A27: Standard turnaround | B27: 2 weeks | D27: Their standard TAT — matches the 14-day leg of our lead time
A28: Last purchase order | B28: ="1,300 units of "&Inputs!B5&"x"&Inputs!B6 -> 1,300 units of 24x27 | D28: ≈ one roll; used as the default starting on-hand in the forecast
A29: Actual cutting time | B29: ~1 day per roll, incl. slitting | D29: The 2-week TAT is queue time, not machine time — expedites are realistic; ~11 machine-days/yr
A31: OPEN ITEMS AT HANDOFF
A32: • SAP reorder-point trigger — TO DO (field values ready on Assumptions & Notes)
A33: • SAP part number for the cut piece — TO DO; raw-roll part number — DECIDE
A34: ="• Physical count "&TEXT(Inputs!B42,"m/d")&": "&TEXT(Inputs!B47,"#,##0")&" pcs ("&Inputs!B43&" loose + "&Inputs!B44&" boxes) — "&IF(Inputs!B47<'Order Cadence'!B16,"BELOW the "&TEXT('Order Cadence'!B16,"#,##0")&" reorder point → release PO-0 now; ~"&TEXT(Inputs!B60,"0.0")&" days of cover left when it lands "&TEXT(Inputs!B57,"m/d")&" at the standard turnaround → ask Trotter to expedite it","above the reorder point") -> • Physical count 9/24: 937 pcs (70 loose + 2 boxes) — BELOW the 1,000 reorder point → release PO-0 now; ~1.7 days of cover left when it lands 10/19 at the standard turnaround → ask Trotter to expedite it
A35: • Confirm 270 pcs/week internally — every quantity in this file scales with it

Sheet Inputs
A1: Mesh Cutting — Supply Planning Inputs
A2: Edit ONLY the yellow cells (blue text). Everything else recalculates. Green text = value pulled from another tab. Lead-time legs now live on the Cycle Time tab.
A4: PIECE (cut part)
A5: Piece width (in) | B5: 24 | D5: Spec — part drawing
A6: Piece height (in) | B6: 27 | D6: Spec — part drawing (check for a grain/weave direction callout)
A7: Piece area (sq in) | B7: =B5*B6 -> 648
A9: FUTURE ROLL (planning basis)
A10: Roll length (ft) | B10: 750 | D10: Confirmed by Oscar 2026-08-03: 750 ft × 101″ wide. Enter FEET here.
A11: Roll length (in) | B11: =B10*12 -> 9000
A12: Roll width (in) | B12: 101 | D12: Corrected 2026-08-03: 101″, not the 110″ the old file assumed — this flips the best orientation to A
A13: Roll area (sq in) | B13: =B11*B12 -> 909000
A15: FIRST DELIVERY (reference — the 150 ft roll)
A16: Delivered roll length (ft) | B16: 150 | D16: Actual — what the supplier cut
A17: Delivered roll length (in) | B17: =B16*12 -> 1800
A18: Delivered roll width (in) | B18: 101 | D18: Width correction doesn't change that roll's theoretical max (264) or the yield — 4 pieces still fit across
A19: Pieces delivered | B19: 260 | D19: Actual — supplier count
A20: Price per piece ($) | B20: 0.41 | D20: Actual — supplier quote
A21: Invoice total ($) | B21: =B19*B20 -> 106.6 | D21: Cross-check: matches the $106.60 quote
A22: Theoretical max, that roll (Orient A) | B22: =INT(B18/B5)*INT(B17/B6) -> 264 | D22: Supplier cut Orientation A (24″ across the width): 4 across × 66 along
A23: Realized process yield | B23: =B19/B22 -> 0.98484848 | D23: Derived: 260 ÷ 264 on the first delivery. Kept as a cross-check; planning now uses the yield backtracked from the 1,300-piece batch (below).
A25: PRODUCTION & LEAD TIME
A26: Weekly production / usage (pieces) | B26: 250 | D26: Set to 250 on 9/24/2026 (call day) — CONFIRM against the build plan
A27: Leg 1 — roll to Trotter (days) | B27: ='Cycle Time'!F14 -> 3 | D27: LINKED to the Cycle Time tab (selected scenario): PO ack + roll transit. Edit the legs there.
A28: Legs 2 + 3 — at Trotter: receive, queue, cut, pack (days) | B28: ='Cycle Time'!F19+'Cycle Time'!F24 -> 14 | D28: LINKED to the Cycle Time tab. SUPPLIER CONFIRMED 9/24/2026: standard turnaround 2 weeks; actual cut ≈ 1 day incl. slitting — the rest is queue.
A29: Leg 4 — ship to Intuitive + dock-to-stock (days) | B29: ='Cycle Time'!F29 -> 3 | D29: LINKED to the Cycle Time tab: transit + our own receiving.
A30: Total lead time (days) | B30: =SUM(B27:B29) -> 20
A31: Planning lead time (weeks) | B31: =CEILING(B30/7,1) -> 3 | D31: Rounded up for planning
A32: Safety stock (weeks) | B32: 1 | D32: Policy choice — buffer for demand/lead-time variability
A34: PLANNING BATCH — the 750 ft roll actual (last PO)
A35: Batch quantity per roll — last PO actual (pieces) | B35: 1300 | D35: SUPPLIER (Trotter) email 9/24/2026: 'your last purchase order for 1,300 units of 24x27' — one 750 ft roll, cut in ~1 day. This is the planning order quantity (1 roll = 1 PO).
A36: Theoretical max, 750 ft roll (Orient A) | B36: ='Yield per Roll'!B10 -> 1332 | D36: 4 across × 333 along at 101 in width (Yield per Roll tab)
A37: Realized yield — backtracked from the batch | B37: =B35/B36 -> 0.97597598 | D37: Batch ÷ theoretical = 1,300 ÷ 1,332. THIS is the yield factor planning uses (drives Yield per Roll → Order Cadence → Forecast).
A38: Cross-check: first-delivery yield (150 ft roll) | B38: =B23 -> 0.98484848 | D38: 260 ÷ 264 on the first delivery — the two data points agree within a point
A39: Material not turned into pieces, per roll (pcs equiv.) | B39: =B36-B35 -> 32 | D39: ASK Trotter: is 1,300 the full yield of a roll, or the PO quantity with remnant left over? Should the PO read 'one full roll (≈1,300 pcs)' instead of a fixed count?
A41: CURRENT INVENTORY — physical count (feeds the 6-Month Forecast start)
A42: Count date | B42: 46289 | D42: Count per Oscar, 9/24/2026 (day of the Trotter call)
A43: Loose pieces on hand | B43: 70
A44: Full boxes on hand | B44: 2
A45: Boxes per delivery (last PO shipped in) | B45: 3 | D45: Trotter shipped the 1,300-piece batch in 3 boxes
A46: Pieces per box | B46: =B35/B45 -> 433.33333 | D46: 1,300 ÷ 3 = 433.3 — not a whole number: boxes hold 433 / 433 / 434, so the count is ±1. ASK Trotter to print the piece count on each box label.
...

Sheet Cycle Time
A1: Replenishment Cycle Time — PO Release to Pieces on Our Shelf
A2: Leg-by-leg lead time for the pull system, in CALENDAR days (10 business days = 14 calendar days). Yellow = editable. The selector in B5 picks the scenario that drives Inputs → Order Cadence → 6-Month Forecast → PO Schedule.
A4: 1. PLANNING SCENARIO — which column drives the plan
A5: Scenario driving the plan | B5: Supplier standard | D5: Supplier standard = Trotter's quoted 2-week turnaround, sequenced after the roll arrives — RECOMMENDED basis until the call fills column D. Confirmed on call = what Trotter tells us today (blank cells fall back to Supplier standard, so it is safe to select early). Conservative = buffered for holidays, freight and queue slips.
A6: Selected column (helper — do not edit) | B6: =MATCH(B5,$C$10:$E$10,0) -> 1 | D6: 1 = Supplier standard · 2 = Confirmed on call · 3 = Conservative
A7: Trotter's standard turnaround (days) | B7: 14 | D7: Supplier email 9/24/2026: 'our standard 2-week turnaround time'. Used for the fit check below and on the PO Schedule tab.
A8: 2. THE REPLENISHMENT CYCLE, LEG BY LEG (calendar days)
A9: Type Trotter's answers into column D during the call — column F and every downstream tab recalculate. Column H holds the question to ask for each step.
A10: Leg / step | B10: What happens | C10: Supplier standard | D10: Confirmed on call | E10: Conservative | F10: SELECTED (plan) | G10: Owner | H10: Status / question for the 9/24 call | J10: helper — PO sequence (do not edit)
A11: LEG 1 — Mosquito-net roll gets to Trotter | J11: Fcst wk | K11: PO #
A12: 1a. PO released → PO acknowledged; roll pulled or ordered | B12: Admin step: Trotter receives our PO and releases the raw roll for the job | C12: 1 | E12: 2 | F12: =IF(INDEX($C12:$E12,1,$B$6)="",$C12,INDEX($C12:$E12,1,$B$6)) -> 1 | G12: Intuitive → Trotter | H12: ASK: How quickly is a PO acknowledged? Is a 750 ft × 101 in roll held in stock at Trotter, or ordered per PO — and from whom? | J12: ='6-Month Forecast'!A14 -> 1 | K12: =IF('6-Month Forecast'!H14>0,COUNTIF('6-Month Forecast'!$H$14:H14,">0"),"")
A13: 1b. Roll in transit to Trotter's dock | B13: Mesh roll ships from its source and arrives at Trotter | C13: 2 | E13: 5 | F13: =IF(INDEX($C13:$E13,1,$B$6)="",$C13,INDEX($C13:$E13,1,$B$6)) -> 2 | G13: Mesh source / carrier | H13: ASK: Where does the roll ship from, how many days door-to-door, who books the freight? Could one roll be pre-positioned at Trotter so this leg drops out of the cycle? | J13: ='6-Month Forecast'!A15 -> 2 | K13: =IF('6-Month Forecast'!H15>0,COUNTIF('6-Month Forecast'!$H$14:H15,">0"),"")
A14: LEG 1 total | C14: =SUM(C12:C13) -> 3 | D14: =IF(D12="",C12,D12)+IF(D13="",C13,D13) -> 3 | E14: =SUM(E12:E13) -> 7 | F14: =SUM(F12:F13) -> 3 | H14: Was a single 3-day assumption in the prior file — unchanged until confirmed | J14: ='6-Month Forecast'!A16 -> 3 | K14: =IF('6-Month Forecast'!H16>0,COUNTIF('6-Month Forecast'!$H$14:H16,">0"),"")
J15: ='6-Month Forecast'!A17 -> 4 | K15: =IF('6-Month Forecast'!H17>0,COUNTIF('6-Month Forecast'!$H$14:H17,">0"),"")
A16: LEG 2 — Trotter receives the roll and puts it into production | J16: ='6-Month Forecast'!A18 -> 5 | K16: =IF('6-Month Forecast'!H18>0,COUNTIF('6-Month Forecast'!$H$14:H18,">0"),"") -> 1
A17: 2a. Receive, inspect and log the roll | B17: Dock receipt, width/defect check, release to the floor | C17: 1 | E17: 2 | F17: =IF(INDEX($C17:$E17,1,$B$6)="",$C17,INDEX($C17:$E17,1,$B$6)) -> 1 | G17: Trotter | H17: ASK: Do you inspect incoming rolls (width, defects)? Any hold time before release to the floor? | J17: ='6-Month Forecast'!A19 -> 6 | K17: =IF('6-Month Forecast'!H19>0,COUNTIF('6-Month Forecast'!$H$14:H19,">0"),"")
A18: 2b. Queue / scheduling wait until the cut is slotted | B18: The job waits for a machine slot | C18: 11 | E18: 12 | F18: =IF(INDEX($C18:$E18,1,$B$6)="",$C18,INDEX($C18:$E18,1,$B$6)) -> 11 | G18: Trotter | H18: Most of the 2-week standard lives here — actual cutting is 1 day. ASK: When does your 2-week clock start — at PO receipt or at roll receipt? What is the realistic wait to slot a 1-day job? | J18: ='6-Month Forecast'!A20 -> 7 | K18: =IF('6-Month Forecast'!H20>0,COUNTIF('6-Month Forecast'!$H$14:H20,">0"),"")
A19: LEG 2 total | C19: =SUM(C17:C18) -> 12 | D19: =IF(D17="",C17,D17)+IF(D18="",C18,D18) -> 12 | E19: =SUM(E17:E18) -> 14 | F19: =SUM(F17:F18) -> 12 | H19: Legs 2 + 3 = 14 days in the Supplier standard column = their quoted 2 weeks | J19: ='6-Month Forecast'!A21 -> 8 | K19: =IF('6-Month Forecast'!H21>0,COUNTIF('6-Month Forecast'!$H$14:H21,">0"),"")
J20: ='6-Month Forecast'!A22 -> 9 | K20: =IF('6-Month Forecast'!H22>0,COUNTIF('6-Month Forecast'!$H$14:H22,">0"),"")
A21: LEG 3 — Slit, cut and package | J21: ='6-Month Forecast'!A23 -> 10 | K21: =IF('6-Month Forecast'!H23>0,COUNTIF('6-Month Forecast'!$H$14:H23,">0"),"") -> 2
A22: 3a. Slit the roll and cut the 24 × 27 in pieces | B22: Slitting to width + piece cutting; one 750 ft roll = the 1,300-piece batch | C22: 1 | D22: 1 | E22: 1 | F22: =IF(INDEX($C22:$E22,1,$B$6)="",$C22,INDEX($C22:$E22,1,$B$6)) -> 1 | G22: Trotter | H22: SUPPLIER CONFIRMED 9/24/2026 (Todd): the 1,300-piece PO took ~1 day to cut, including slitting the roll on their end | J22: ='6-Month Forecast'!A24 -> 11 | K22: =IF('6-Month Forecast'!H24>0,COUNTIF('6-Month Forecast'!$H$14:H24,">0"),"")
A23: 3b. Count, package, label, stage for pickup | B23: Piece count, bundling/boxing, labels, carrier pickup | C23: 1 | E23: 2 | F23: =IF(INDEX($C23:$E23,1,$B$6)="",$C23,INDEX($C23:$E23,1,$B$6)) -> 1 | G23: Trotter | H23: ASK: Pieces per bundle or box? Count verification? Same-day carrier pickup or next day? | J23: ='6-Month Forecast'!A25 -> 12 | K23: =IF('6-Month Forecast'!H25>0,COUNTIF('6-Month Forecast'!$H$14:H25,">0"),"")
A24: LEG 3 total | C24: =SUM(C22:C23) -> 2 | D24: =IF(D22="",C22,D22)+IF(D23="",C23,D23) -> 2 | E24: =SUM(E22:E23) -> 3 | F24: =SUM(F22:F23) -> 2 | J24: ='6-Month Forecast'!A26 -> 13 | K24: =IF('6-Month Forecast'!H26>0,COUNTIF('6-Month Forecast'!$H$14:H26,">0"),"")
J25: ='6-Month Forecast'!A27 -> 14 | K25: =IF('6-Month Forecast'!H27>0,COUNTIF('6-Month Forecast'!$H$14:H27,">0"),"")
A26: LEG 4 — Pieces travel to Intuitive and are put away | J26: ='6-Month Forecast'!A28 -> 15 | K26: =IF('6-Month Forecast'!H28>0,COUNTIF('6-Month Forecast'!$H$14:H28,">0"),"") -> 3
A27: 4a. Transit Trotter → Intuitive dock | B27: Outbound freight | C27: 2 | E27: 3 | F27: =IF(INDEX($C27:$E27,1,$B$6)="",$C27,INDEX($C27:$E27,1,$B$6)) -> 2 | G27: Trotter / carrier | H27: ASK: Carrier and service level? Ship terms — who pays freight? Ship notice with piece count so receiving can plan? | J27: ='6-Month Forecast'!A29 -> 16 | K27: =IF('6-Month Forecast'!H29>0,COUNTIF('6-Month Forecast'!$H$14:H29,">0"),"")
A28: 4b. Receiving, inspection, put-away at Intuitive (dock-to-stock) | B28: Our own goods receipt | C28: 1 | E28: 2 | F28: =IF(INDEX($C28:$E28,1,$B$6)="",$C28,INDEX($C28:$E28,1,$B$6)) -> 1 | G28: Intuitive | H28: INTERNAL — confirm with our receiving team; not a supplier question. In SAP this is the goods-receipt processing time. | J28: ='6-Month Forecast'!A30 -> 17 | K28: =IF('6-Month Forecast'!H30>0,COUNTIF('6-Month Forecast'!$H$14:H30,">0"),"")
A29: LEG 4 total | C29: =SUM(C27:C28) -> 3 | D29: =IF(D27="",C27,D27)+IF(D28="",C28,D28) -> 3 | E29: =SUM(E27:E28) -> 5 | F29: =SUM(F27:F28) -> 3 | J29: ='6-Month Forecast'!A31 -> 18 | K29: =IF('6-Month Forecast'!H31>0,COUNTIF('6-Month Forecast'!$H$14:H31,">0"),"")
J30: ='6-Month Forecast'!A32 -> 19 | K30: =IF('6-Month Forecast'!H32>0,COUNTIF('6-Month Forecast'!$H$14:H32,">0"),"")
A31: TOTAL CYCLE TIME — PO release → pieces available (days) | C31: =C14+C19+C24+C29 -> 20 | D31: =D14+D19+D24+D29 -> 20 | E31: =E14+E19+E24+E29 -> 29 | F31: =F14+F19+F24+F29 -> 20 | H31: Feeds Inputs!B30 → planning lead time → reorder point → 6-Month Forecast → PO Schedule | J31: ='6-Month Forecast'!A33 -> 20 | K31: =IF('6-Month Forecast'!H33>0,COUNTIF('6-Month Forecast'!$H$14:H33,">0"),"")
A32: Planning lead time (weeks, rounded up) | C32: =CEILING(C31/7,1) -> 3 | D32: =CEILING(D31/7,1) -> 3 | E32: =CEILING(E31/7,1) -> 5 | F32: =CEILING(F31/7,1) -> 3 | H32: The forecast plans in whole weeks; anything from 15 to 21 days is 3 weeks | J32: ='6-Month Forecast'!A34 -> 21 | K32: =IF('6-Month Forecast'!H34>0,COUNTIF('6-Month Forecast'!$H$14:H34,">0"),"") -> 4
A33: Rounding cushion inside the planned weeks (days) | C33: =C32*7-C31 -> 1 | D33: =D32*7-D31 -> 1 | E33: =E32*7-E31 -> 6 | F33: =F32*7-F31 -> 1 | J33: ='6-Month Forecast'!A35 -> 22 | K33: =IF('6-Month Forecast'!H35>0,COUNTIF('6-Month Forecast'!$H$14:H35,">0"),"")
A34: Trotter's portion — legs 2 + 3 (days) | C34: =C19+C24 -> 14 | D34: =D19+D24 -> 14 | E34: =E19+E24 -> 17 | F34: =F19+F24 -> 14 | H34: The number to reconcile with their 'standard 2-week turnaround' | J34: ='6-Month Forecast'!A36 -> 23 | K34: =IF('6-Month Forecast'!H36>0,COUNTIF('6-Month Forecast'!$H$14:H36,">0"),"")
A35: vs. Trotter's standard turnaround (B7) | C35: =IF(C34<=$B$7,"Within standard ("&($B$7-C34)&" d spare)","Exceeds by "&(C34-$B$7)&" d") -> Within standard (0 d spare) | D35: =IF(D34<=$B$7,"Within standard ("&($B$7-D34)&" d spare)","Exceeds by "&(D34-$B$7)&" d") -> Within standard (0 d spare) | E35: =IF(E34<=$B$7,"Within standard ("&($B$7-E34)&" d spare)","Exceeds by "&(E34-$B$7)&" d") -> Exceeds by 3 d | F35: =IF(F34<=$B$7,"Within standard ("&($B$7-F34)&" d spare)","Exceeds by "&(F34-$B$7)&" d") -> Within standard (0 d spare) | J35: ='6-Month Forecast'!A37 -> 24 | K35: =IF('6-Month Forecast'!H37>0,COUNTIF('6-Month Forecast'!$H$14:H37,">0"),"")
A36: SAP planned delivery time — legs 1 → 4a (days) | C36: =C31-C28 -> 19 | D36: =D31-D28 -> 20 | E36: =E31-E28 -> 27 | F36: =F31-F28 -> 19 | H36: SAP material master: planned delivery time excludes our own goods-receipt processing | J36: ='6-Month Forecast'!A38 -> 25 | K36: =IF('6-Month Forecast'!H38>0,COUNTIF('6-Month Forecast'!$H$14:H38,">0"),"")
A37: SAP goods-receipt processing time — leg 4b (days) | C37: =C28 -> 1 | D37: =D28 -> 0 | E37: =E28 -> 2 | F37: =F28 -> 1 | J37: ='6-Month Forecast'!A39 -> 26 | K37: =IF('6-Month Forecast'!H39>0,COUNTIF('6-Month Forecast'!$H$14:H39,">0"),"") -> 5
A39: 3. WHAT EACH SCENARIO MEANS FOR THE PULL SYSTEM
A40: Metric | B40: How it is computed | C40: =C10 -> Supplier standard | D40: =D10 -> Confirmed on call | E40: =E10 -> Conservative | F40: SELECTED (plan) | H40: Note
A41: Total cycle time (days) | B41: Sum of the four legs | C41: =C31 -> 20 | D41: =D31 -> 20 | E41: =E31 -> 29 | F41: =F31 -> 20
A42: Planning lead time (weeks) | B42: Rounded up to whole weeks | C42: =C32 -> 3 | D42: =D32 -> 3 | E42: =E32 -> 5 | F42: =F32 -> 3
...

Sheet PO Schedule
A1: 6-Month PO Schedule — Milestone Dates to Review with Trotter
A2: PO-0 (the PO released before the horizon, from the Inputs tab) plus every PO the 6-Month Forecast releases, with dated legs from the Cycle Time tab's selected scenario. PO release = Monday of the release week; a milestone that lands on a weekend rolls to the next business day. Share this view to confirm each ship-by date fits Trotter's standard turnaround.
A4: SCHEDULE BASIS — all pulled from the Cycle Time and Inputs tabs
A5: Scenario in use | B5: ='Cycle Time'!B5 -> Supplier standard | D5: Change it on the Cycle Time tab (cell B5)
A6: Total cycle time (days) | B6: ='Cycle Time'!F31 -> 20
A7: Planning lead time (weeks) | B7: =Inputs!B31 -> 3
A8: Trotter's standard turnaround (days) | B8: ='Cycle Time'!B7 -> 14
A9: Weekly production (pcs) | B9: =Inputs!B26 -> 250
A10: PO release timing | B10: Monday of the release week | D10: The forecast works in weekly buckets: treat the Monday as the release date, and the 'Fcst receipt week' Monday as the day the pieces must be on our shelf.
A12: PO MILESTONE SCHEDULE — Oct 2026 through Mar 2027 (auto-generated from the 6-Month Forecast)
A13: PO | B13: Release (Mon of wk) | C13: Roll due at Trotter | D13: Cut can start | E13: Planned ship | F13: Arrive our dock | G13: On our shelf | H13: Fcst receipt week | I13: Latest ship to hold plan | J13: Window: PO → latest ship (d) | K13: Window: roll at Trotter → latest ship (d) | L13: Fits standard TAT from roll arrival? | M13: Slack: latest − planned ship (d) | N13: Cover left at landing (d) — PO-0 day-level, others weekly model | O13: Holiday check (roll due → ship) | P13: Qty (pcs) | Q13: Value ($)
A14: 0 | B14: =IF(Inputs!$B$56>0,Inputs!$B$55,"") -> 46289 | C14: =IF($B14="","",WORKDAY($B14+'Cycle Time'!$F$14-1,1)) -> 46293 | D14: =IF($B14="","",WORKDAY(C14+'Cycle Time'!$F$19-1,1)) -> 46307 | E14: =IF($B14="","",WORKDAY(D14+'Cycle Time'!$F$24-1,1)) -> 46309 | F14: =IF($B14="","",WORKDAY(E14+'Cycle Time'!$F$27-1,1)) -> 46311 | G14: =IF($B14="","",WORKDAY(F14+'Cycle Time'!$F$28-1,1)) -> 46314 | H14: =IF($B14="","",'6-Month Forecast'!$B$5+(Inputs!$B$58-1)*7) -> 46314 | I14: =IF($B14="","",$H14-'Cycle Time'!$F$29) -> 46311 | J14: =IF($B14="","",I14-$B14) -> 22 | K14: =IF($B14="","",I14-C14) -> 18 | L14: =IF($B14="","",IF(K14>=$B$8,"Yes — "&(K14-$B$8)&" d margin","NO — short "&($B$8-K14)&" d")) -> Yes — 4 d margin | M14: =IF($B14="","",I14-E14) -> 2 | N14: =IF($B14="","",Inputs!$B$60) -> 1.74 | O14: =IF($B14="","",IF(SUMPRODUCT(($B$29:$B$32<>"")*($B$29:$B$32<=E14)*($C$29:$C$32>=C14))>0,"⚠ holiday in window","clear")) -> clear | P14: =IF($B14="","",Inputs!$B$56) -> 1300 | Q14: =IF($B14="","",P14*Inputs!$B$20) -> 533
A15: 1 | B15: =IFERROR(INDEX('6-Month Forecast'!$B$14:$B$39,MATCH($A15,'Cycle Time'!$K$12:$K$37,0)),"") -> 46321 | C15: =IF($B15="","",WORKDAY($B15+'Cycle Time'!$F$14-1,1)) -> 46324 | D15: =IF($B15="","",WORKDAY(C15+'Cycle Time'!$F$19-1,1)) -> 46336 | E15: =IF($B15="","",WORKDAY(D15+'Cycle Time'!$F$24-1,1)) -> 46338 | F15: =IF($B15="","",WORKDAY(E15+'Cycle Time'!$F$27-1,1)) -> 46342 | G15: =IF($B15="","",WORKDAY(F15+'Cycle Time'!$F$28-1,1)) -> 46343 | H15: =IF($B15="","",$B15+$B$7*7) -> 46342 | I15: =IF($B15="","",$H15-'Cycle Time'!$F$29) -> 46339 | J15: =IF($B15="","",I15-$B15) -> 18 | K15: =IF($B15="","",I15-C15) -> 15 | L15: =IF($B15="","",IF(K15>=$B$8,"Yes — "&(K15-$B$8)&" d margin","NO — short "&($B$8-K15)&" d")) -> Yes — 1 d margin | M15: =IF($B15="","",I15-E15) -> 1 | N15: =IF($B15="","",IFERROR(INDEX('6-Month Forecast'!$C$14:$C$39,MATCH($A15,'Cycle Time'!$K$12:$K$37,0)+$B$7)/$B$9*7,"beyond horizon")) -> 10.836 | O15: =IF($B15="","",IF(SUMPRODUCT(($B$29:$B$32<>"")*($B$29:$B$32<=E15)*($C$29:$C$32>=C15))>0,"⚠ holiday in window","clear")) -> clear | P15: =IF($B15="","",INDEX('6-Month Forecast'!$H$14:$H$39,MATCH($A15,'Cycle Time'!$K$12:$K$37,0))) -> 1300 | Q15: =IF($B15="","",P15*Inputs!$B$20) -> 533
A16: 2 | B16: =IFERROR(INDEX('6-Month Forecast'!$B$14:$B$39,MATCH($A16,'Cycle Time'!$K$12:$K$37,0)),"") -> 46356 | C16: =IF($B16="","",WORKDAY($B16+'Cycle Time'!$F$14-1,1)) -> 46359 | D16: =IF($B16="","",WORKDAY(C16+'Cycle Time'!$F$19-1,1)) -> 46371 | E16: =IF($B16="","",WORKDAY(D16+'Cycle Time'!$F$24-1,1)) -> 46373 | F16: =IF($B16="","",WORKDAY(E16+'Cycle Time'!$F$27-1,1)) -> 46377 | G16: =IF($B16="","",WORKDAY(F16+'Cycle Time'!$F$28-1,1)) -> 46378 | H16: =IF($B16="","",$B16+$B$7*7) -> 46377 | I16: =IF($B16="","",$H16-'Cycle Time'!$F$29) -> 46374 | J16: =IF($B16="","",I16-$B16) -> 18 | K16: =IF($B16="","",I16-C16) -> 15 | L16: =IF($B16="","",IF(K16>=$B$8,"Yes — "&(K16-$B$8)&" d margin","NO — short "&($B$8-K16)&" d")) -> Yes — 1 d margin | M16: =IF($B16="","",I16-E16) -> 1 | N16: =IF($B16="","",IFERROR(INDEX('6-Month Forecast'!$C$14:$C$39,MATCH($A16,'Cycle Time'!$K$12:$K$37,0)+$B$7)/$B$9*7,"beyond horizon")) -> 12.236 | O16: =IF($B16="","",IF(SUMPRODUCT(($B$29:$B$32<>"")*($B$29:$B$32<=E16)*($C$29:$C$32>=C16))>0,"⚠ holiday in window","clear")) -> clear | P16: =IF($B16="","",INDEX('6-Month Forecast'!$H$14:$H$39,MATCH($A16,'Cycle Time'!$K$12:$K$37,0))) -> 1300 | Q16: =IF($B16="","",P16*Inputs!$B$20) -> 533
A17: 3 | B17: =IFERROR(INDEX('6-Month Forecast'!$B$14:$B$39,MATCH($A17,'Cycle Time'!$K$12:$K$37,0)),"") -> 46391 | C17: =IF($B17="","",WORKDAY($B17+'Cycle Time'!$F$14-1,1)) -> 46394 | D17: =IF($B17="","",WORKDAY(C17+'Cycle Time'!$F$19-1,1)) -> 46406 | E17: =IF($B17="","",WORKDAY(D17+'Cycle Time'!$F$24-1,1)) -> 46408 | F17: =IF($B17="","",WORKDAY(E17+'Cycle Time'!$F$27-1,1)) -> 46412 | G17: =IF($B17="","",WORKDAY(F17+'Cycle Time'!$F$28-1,1)) -> 46413 | H17: =IF($B17="","",$B17+$B$7*7) -> 46412 | I17: =IF($B17="","",$H17-'Cycle Time'!$F$29) -> 46409 | J17: =IF($B17="","",I17-$B17) -> 18 | K17: =IF($B17="","",I17-C17) -> 15 | L17: =IF($B17="","",IF(K17>=$B$8,"Yes — "&(K17-$B$8)&" d margin","NO — short "&($B$8-K17)&" d")) -> Yes — 1 d margin | M17: =IF($B17="","",I17-E17) -> 1 | N17: =IF($B17="","",IFERROR(INDEX('6-Month Forecast'!$C$14:$C$39,MATCH($A17,'Cycle Time'!$K$12:$K$37,0)+$B$7)/$B$9*7,"beyond horizon")) -> 13.636 | O17: =IF($B17="","",IF(SUMPRODUCT(($B$29:$B$32<>"")*($B$29:$B$32<=E17)*($C$29:$C$32>=C17))>0,"⚠ holiday in window","clear")) -> clear | P17: =IF($B17="","",INDEX('6-Month Forecast'!$H$14:$H$39,MATCH($A17,'Cycle Time'!$K$12:$K$37,0))) -> 1300 | Q17: =IF($B17="","",P17*Inputs!$B$20) -> 533
A18: 4 | B18: =IFERROR(INDEX('6-Month Forecast'!$B$14:$B$39,MATCH($A18,'Cycle Time'!$K$12:$K$37,0)),"") -> 46433 | C18: =IF($B18="","",WORKDAY($B18+'Cycle Time'!$F$14-1,1)) -> 46436 | D18: =IF($B18="","",WORKDAY(C18+'Cycle Time'!$F$19-1,1)) -> 46448 | E18: =IF($B18="","",WORKDAY(D18+'Cycle Time'!$F$24-1,1)) -> 46450 | F18: =IF($B18="","",WORKDAY(E18+'Cycle Time'!$F$27-1,1)) -> 46454 | G18: =IF($B18="","",WORKDAY(F18+'Cycle Time'!$F$28-1,1)) -> 46455 | H18: =IF($B18="","",$B18+$B$7*7) -> 46454 | I18: =IF($B18="","",$H18-'Cycle Time'!$F$29) -> 46451 | J18: =IF($B18="","",I18-$B18) -> 18 | K18: =IF($B18="","",I18-C18) -> 15 | L18: =IF($B18="","",IF(K18>=$B$8,"Yes — "&(K18-$B$8)&" d margin","NO — short "&($B$8-K18)&" d")) -> Yes — 1 d margin | M18: =IF($B18="","",I18-E18) -> 1 | N18: =IF($B18="","",IFERROR(INDEX('6-Month Forecast'!$C$14:$C$39,MATCH($A18,'Cycle Time'!$K$12:$K$37,0)+$B$7)/$B$9*7,"beyond horizon")) -> 8.036 | O18: =IF($B18="","",IF(SUMPRODUCT(($B$29:$B$32<>"")*($B$29:$B$32<=E18)*($C$29:$C$32>=C18))>0,"⚠ holiday in window","clear")) -> clear | P18: =IF($B18="","",INDEX('6-Month Forecast'!$H$14:$H$39,MATCH($A18,'Cycle Time'!$K$12:$K$37,0))) -> 1300 | Q18: =IF($B18="","",P18*Inputs!$B$20) -> 533
A19: 5 | B19: =IFERROR(INDEX('6-Month Forecast'!$B$14:$B$39,MATCH($A19,'Cycle Time'!$K$12:$K$37,0)),"") -> 46468 | C19: =IF($B19="","",WORKDAY($B19+'Cycle Time'!$F$14-1,1)) -> 46471 | D19: =IF($B19="","",WORKDAY(C19+'Cycle Time'!$F$19-1,1)) -> 46483 | E19: =IF($B19="","",WORKDAY(D19+'Cycle Time'!$F$24-1,1)) -> 46485 | F19: =IF($B19="","",WORKDAY(E19+'Cycle Time'!$F$27-1,1)) -> 46489 | G19: =IF($B19="","",WORKDAY(F19+'Cycle Time'!$F$28-1,1)) -> 46490 | H19: =IF($B19="","",$B19+$B$7*7) -> 46489 | I19: =IF($B19="","",$H19-'Cycle Time'!$F$29) -> 46486 | J19: =IF($B19="","",I19-$B19) -> 18 | K19: =IF($B19="","",I19-C19) -> 15 | L19: =IF($B19="","",IF(K19>=$B$8,"Yes — "&(K19-$B$8)&" d margin","NO — short "&($B$8-K19)&" d")) -> Yes — 1 d margin | M19: =IF($B19="","",I19-E19) -> 1 | N19: =IF($B19="","",IFERROR(INDEX('6-Month Forecast'!$C$14:$C$39,MATCH($A19,'Cycle Time'!$K$12:$K$37,0)+$B$7)/$B$9*7,"beyond horizon")) -> beyond horizon | O19: =IF($B19="","",IF(SUMPRODUCT(($B$29:$B$32<>"")*($B$29:$B$32<=E19)*($C$29:$C$32>=C19))>0,"⚠ holiday in window","clear")) -> clear | P19: =IF($B19="","",INDEX('6-Month Forecast'!$H$14:$H$39,MATCH($A19,'Cycle Time'!$K$12:$K$37,0))) -> 1300 | Q19: =IF($B19="","",P19*Inputs!$B$20) -> 533
A20: 6 | B20: =IFERROR(INDEX('6-Month Forecast'!$B$14:$B$39,MATCH($A20,'Cycle Time'!$K$12:$K$37,0)),"") | C20: =IF($B20="","",WORKDAY($B20+'Cycle Time'!$F$14-1,1)) | D20: =IF($B20="","",WORKDAY(C20+'Cycle Time'!$F$19-1,1)) | E20: =IF($B20="","",WORKDAY(D20+'Cycle Time'!$F$24-1,1)) | F20: =IF($B20="","",WORKDAY(E20+'Cycle Time'!$F$27-1,1)) | G20: =IF($B20="","",WORKDAY(F20+'Cycle Time'!$F$28-1,1)) | H20: =IF($B20="","",$B20+$B$7*7) | I20: =IF($B20="","",$H20-'Cycle Time'!$F$29) | J20: =IF($B20="","",I20-$B20) | K20: =IF($B20="","",I20-C20) | L20: =IF($B20="","",IF(K20>=$B$8,"Yes — "&(K20-$B$8)&" d margin","NO — short "&($B$8-K20)&" d")) | M20: =IF($B20="","",I20-E20) | N20: =IF($B20="","",IFERROR(INDEX('6-Month Forecast'!$C$14:$C$39,MATCH($A20,'Cycle Time'!$K$12:$K$37,0)+$B$7)/$B$9*7,"beyond horizon")) | O20: =IF($B20="","",IF(SUMPRODUCT(($B$29:$B$32<>"")*($B$29:$B$32<=E20)*($C$29:$C$32>=C20))>0,"⚠ holiday in window","clear")) | P20: =IF($B20="","",INDEX('6-Month Forecast'!$H$14:$H$39,MATCH($A20,'Cycle Time'!$K$12:$K$37,0))) | Q20: =IF($B20="","",P20*Inputs!$B$20)
A21: 7 | B21: =IFERROR(INDEX('6-Month Forecast'!$B$14:$B$39,MATCH($A21,'Cycle Time'!$K$12:$K$37,0)),"") | C21: =IF($B21="","",WORKDAY($B21+'Cycle Time'!$F$14-1,1)) | D21: =IF($B21="","",WORKDAY(C21+'Cycle Time'!$F$19-1,1)) | E21: =IF($B21="","",WORKDAY(D21+'Cycle Time'!$F$24-1,1)) | F21: =IF($B21="","",WORKDAY(E21+'Cycle Time'!$F$27-1,1)) | G21: =IF($B21="","",WORKDAY(F21+'Cycle Time'!$F$28-1,1)) | H21: =IF($B21="","",$B21+$B$7*7) | I21: =IF($B21="","",$H21-'Cycle Time'!$F$29) | J21: =IF($B21="","",I21-$B21) | K21: =IF($B21="","",I21-C21) | L21: =IF($B21="","",IF(K21>=$B$8,"Yes — "&(K21-$B$8)&" d margin","NO — short "&($B$8-K21)&" d")) | M21: =IF($B21="","",I21-E21) | N21: =IF($B21="","",IFERROR(INDEX('6-Month Forecast'!$C$14:$C$39,MATCH($A21,'Cycle Time'!$K$12:$K$37,0)+$B$7)/$B$9*7,"beyond horizon")) | O21: =IF($B21="","",IF(SUMPRODUCT(($B$29:$B$32<>"")*($B$29:$B$32<=E21)*($C$29:$C$32>=C21))>0,"⚠ holiday in window","clear")) | P21: =IF($B21="","",INDEX('6-Month Forecast'!$H$14:$H$39,MATCH($A21,'Cycle Time'!$K$12:$K$37,0))) | Q21: =IF($B21="","",P21*Inputs!$B$20)
A22: 8 | B22: =IFERROR(INDEX('6-Month Forecast'!$B$14:$B$39,MATCH($A22,'Cycle Time'!$K$12:$K$37,0)),"") | C22: =IF($B22="","",WORKDAY($B22+'Cycle Time'!$F$14-1,1)) | D22: =IF($B22="","",WORKDAY(C22+'Cycle Time'!$F$19-1,1)) | E22: =IF($B22="","",WORKDAY(D22+'Cycle Time'!$F$24-1,1)) | F22: =IF($B22="","",WORKDAY(E22+'Cycle Time'!$F$27-1,1)) | G22: =IF($B22="","",WORKDAY(F22+'Cycle Time'!$F$28-1,1)) | H22: =IF($B22="","",$B22+$B$7*7) | I22: =IF($B22="","",$H22-'Cycle Time'!$F$29) | J22: =IF($B22="","",I22-$B22) | K22: =IF($B22="","",I22-C22) | L22: =IF($B22="","",IF(K22>=$B$8,"Yes — "&(K22-$B$8)&" d margin","NO — short "&($B$8-K22)&" d")) | M22: =IF($B22="","",I22-E22) | N22: =IF($B22="","",IFERROR(INDEX('6-Month Forecast'!$C$14:$C$39,MATCH($A22,'Cycle Time'!$K$12:$K$37,0)+$B$7)/$B$9*7,"beyond horizon")) | O22: =IF($B22="","",IF(SUMPRODUCT(($B$29:$B$32<>"")*($B$29:$B$32<=E22)*($C$29:$C$32>=C22))>0,"⚠ holiday in window","clear")) | P22: =IF($B22="","",INDEX('6-Month Forecast'!$H$14:$H$39,MATCH($A22,'Cycle Time'!$K$12:$K$37,0))) | Q22: =IF($B22="","",P22*Inputs!$B$20)
A23: TOTAL IN HORIZON | B23: =COUNT(B14:B22) -> 6 | P23: =SUM(P14:P22) -> 7800 | Q23: =SUM(Q14:Q22) -> 3198
A25: How to read: 'Latest ship to hold plan' is the last day Trotter can ship and still have pieces on our shelf by the forecast receipt Monday. 'Cover left at landing' is how many days of production remain on hand that Monday — i.e., how late a delivery can run before the line stops. 'Slack' is planned ship vs. latest ship: negative means the plan itself is late. 'Fits standard TAT' measures Trotter's window from the day the roll is at their dock — the strict reading of their 2 weeks.
A27: HOLIDAY / SHUTDOWN WINDOWS — drive the holiday check (edit the yellow dates)
A28: Window | B28: Start | C28: End | D28: Note
A29: Thanksgiving (US) | B29: 46352 | C29: 46353 | D29: Trotter likely closed Thu–Fri
A30: Christmas – New Year | B30: 46380 | C30: 46388 | D30: ASK: plant shutdown dates? PO-3 cuts and ships in this window
A31: Trotter plant shutdown (ASK) | D31: Fill in from the call
A32: Intuitive receiving closed (internal) | D32: Fill in from our own calendar

Sheet Yield per Roll
A1: Yield per Roll — Corrected Math, Both Orientations
A2: PLAN = Orientation A (24″ across the roll width) — the supplier's current cut and, at 101″ width, also the higher-yield cut. ALT = Orientation B (27″ across) — loses a full column at this width.
A4: Metric | B4: PLAN — Orientation A | C4: ALT — Orientation B | D4: Note
A5: Cut footprint (across × along, in) | B5: =Inputs!B5&" × "&Inputs!B6 -> 24 × 27 | C5: =Inputs!B6&" × "&Inputs!B5 -> 27 × 24 | D5: Which piece dimension runs across the 101″ roll width
A6: Pieces across roll width | B6: =INT(Inputs!$B$12/Inputs!$B$5) -> 4 | C6: =INT(Inputs!$B$12/Inputs!$B$6) -> 3
A7: Width scrap per row (in) | B7: =Inputs!$B$12-B6*Inputs!$B$5 -> 5 | C7: =Inputs!$B$12-C6*Inputs!$B$6 -> 20 | D7: A wastes only 5″ of width; B wastes 20″ — a 4th 27″ column needs 108″ and the roll is 101″
A8: Pieces along roll length | B8: =INT(Inputs!$B$11/Inputs!$B$6) -> 333 | C8: =INT(Inputs!$B$11/Inputs!$B$5) -> 375
A9: End-of-roll scrap (in) | B9: =Inputs!$B$11-B8*Inputs!$B$6 -> 9 | C9: =Inputs!$B$11-C8*Inputs!$B$5 -> 0
A10: Theoretical pieces per roll | B10: =B6*B8 -> 1332 | C10: =C6*C8 -> 1125 | D10: Perfect packing, no losses
A11: Material utilization (theoretical) | B11: =B10*Inputs!$B$7/Inputs!$B$13 -> 0.94954455 | C11: =C10*Inputs!$B$7/Inputs!$B$13 -> 0.8019802
A12: Realized yield factor | B12: =Inputs!$B$37 -> 0.97597598 | C12: =Inputs!$B$37 -> 0.97597598 | D12: Backtracked from the 1,300-piece batch cut from one 750 ft roll (Inputs tab, B37)
A13: PLANNING PIECES PER ROLL | B13: =ROUND(B10*B12,0) -> 1300 | C13: =ROUND(C10*C12,0) -> 1098 | D13: Use these for ordering — drives the Order Cadence tab
A14: Value per roll at current piece price | B14: =B13*Inputs!$B$20 -> 533 | C14: =C13*Inputs!$B$20 -> 450.18
A15: A advantage — extra pieces per roll | B15: =B13-C13 -> 202
A16: A advantage (%) | B16: =B13/C13-1 -> 0.18397086
A18: ✓ Good news: at 101″ width the supplier's current cut (A) is also the best possible cut — nothing to renegotiate. The old file's 'B is +13%' conclusion only held at the assumed 110″ width; the break-even is 108″ (4 × 27″).

Sheet Order Cadence
A1: Order Cadence — How Often to Get Rolls
A2: All values recalc from the Inputs tab. PLAN = Orientation A (supplier's current cut, best at 101″ width); B shown as the alternate.
A4: REQUIREMENT RATE
A5: Weekly production (pieces) | B5: =Inputs!B26 -> 250
A6: Planning pieces per roll — A | B6: ='Yield per Roll'!B13 -> 1300
A7: Planning pieces per roll — B (alt) | B7: ='Yield per Roll'!C13 -> 1098
A8: COVERAGE PER ROLL — A (weeks) | B8: =B6/B5 -> 5.2 | D8: One roll ≈ 4.9 weeks of production — this IS the natural reorder cadence
A9: Coverage per roll — B (alt, weeks) | B9: =B7/B5 -> 4.392
A10: Rolls needed per year — A (52 wks) | B10: =ROUNDUP(B5*52/B6,0) -> 10
A11: Rolls needed per year — B (alt) | B11: =ROUNDUP(B5*52/B7,0) -> 12
A13: REORDER POLICY (pull system)
A14: Planning lead time (weeks) | B14: =Inputs!B31 -> 3
A15: Safety stock (weeks) | B15: =Inputs!B32 -> 1
A16: REORDER POINT (pieces) | B16: =(B14+B15)*B5 -> 1000 | D16: Release the next PO when on-hand + on-order ≤ this (≈ 4 weeks of production)
A17: Rolls per PO | B17: 1 | D17: Lever — see the batching table below before changing
A18: Avg weeks between POs | B18: =B17*B6/B5 -> 5.2
A19: POs per year | B19: =ROUNDUP(B5*52/(B17*B6),0) -> 10
A21: BATCHING OPTIONS — rolls per PO vs inventory carried
A22: Rolls per PO | B22: Pieces per delivery | C22: Coverage per delivery (wks) | D22: Value per delivery ($) | E22: POs per year | F22: Peak inventory (pcs) | G22: Peak (weeks of prod.) | H22: Coverage if cut as B (wks)
A23: 1 | B23: =A23*$B$6 -> 1300 | C23: =B23/$B$5 -> 5.2 | D23: =B23*Inputs!$B$20 -> 533 | E23: =ROUNDUP($B$5*52/B23,0) -> 10 | F23: =Inputs!$B$32*$B$5+B23 -> 1550 | G23: =F23/$B$5 -> 6.2 | H23: =A23*$B$7/$B$5 -> 4.392
A24: 2 | B24: =A24*$B$6 -> 2600 | C24: =B24/$B$5 -> 10.4 | D24: =B24*Inputs!$B$20 -> 1066 | E24: =ROUNDUP($B$5*52/B24,0) -> 5 | F24: =Inputs!$B$32*$B$5+B24 -> 2850 | G24: =F24/$B$5 -> 11.4 | H24: =A24*$B$7/$B$5 -> 8.784
A25: 3 | B25: =A25*$B$6 -> 3900 | C25: =B25/$B$5 -> 15.6 | D25: =B25*Inputs!$B$20 -> 1599 | E25: =ROUNDUP($B$5*52/B25,0) -> 4 | F25: =Inputs!$B$32*$B$5+B25 -> 4150 | G25: =F25/$B$5 -> 16.6 | H25: =A25*$B$7/$B$5 -> 13.176
A26: 4 | B26: =A26*$B$6 -> 5200 | C26: =B26/$B$5 -> 20.8 | D26: =B26*Inputs!$B$20 -> 2132 | E26: =ROUNDUP($B$5*52/B26,0) -> 3 | F26: =Inputs!$B$32*$B$5+B26 -> 5450 | G26: =F26/$B$5 -> 21.8 | H26: =A26*$B$7/$B$5 -> 17.568
A28: ="RECOMMENDED: order "&B17&" roll per PO. Release a PO when inventory position ≤ "&TEXT(B16,"#,##0")&" pieces — in steady state that fires about every "&TEXT(B18,"0.0")&" weeks ("&B19&" POs/year, "&TEXT(B6,"#,##0")&" pieces per delivery). If cut as "&"Orientation B instead: a PO about every "&TEXT(B7/B5,"0.0")&" weeks, "&B11&" POs/year." -> RECOMMENDED: order 1 roll per PO. Release a PO when inventory position ≤ 1,000 pieces — in steady state that fires about every 5.2 weeks (10 POs/year, 1,300 pieces per delivery). If cut as Orientation B instead: a PO about every 4.4 weeks, 12 POs/year.
A30: IF PRODUCTION CHANGES — sensitivity (edit the yellow rates)
A31: Weekly production | B31: Coverage per roll — A (wks) | C31: Avg weeks between POs — A | D31: POs per year — A | E31: POs per year — B (alt)
A32: 200 | B32: =$B$6/A32 -> 6.5 | C32: =$B$17*$B$6/A32 -> 6.5 | D32: =ROUNDUP(A32*52/($B$17*$B$6),0) -> 8 | E32: =ROUNDUP(A32*52/($B$17*$B$7),0) -> 10
A33: 225 | B33: =$B$6/A33 -> 5.7777778 | C33: =$B$17*$B$6/A33 -> 5.7777778 | D33: =ROUNDUP(A33*52/($B$17*$B$6),0) -> 9 | E33: =ROUNDUP(A33*52/($B$17*$B$7),0) -> 11
A34: 250 | B34: =$B$6/A34 -> 5.2 | C34: =$B$17*$B$6/A34 -> 5.2 | D34: =ROUNDUP(A34*52/($B$17*$B$6),0) -> 10 | E34: =ROUNDUP(A34*52/($B$17*$B$7),0) -> 12
A35: 270 | B35: =$B$6/A35 -> 4.8148148 | C35: =$B$17*$B$6/A35 -> 4.8148148 | D35: =ROUNDUP(A35*52/($B$17*$B$6),0) -> 11 | E35: =ROUNDUP(A35*52/($B$17*$B$7),0) -> 13
A36: 300 | B36: =$B$6/A36 -> 4.3333333 | C36: =$B$17*$B$6/A36 -> 4.3333333 | D36: =ROUNDUP(A36*52/($B$17*$B$6),0) -> 12 | E36: =ROUNDUP(A36*52/($B$17*$B$7),0) -> 15
A37: 325 | B37: =$B$6/A37 -> 4 | C37: =$B$17*$B$6/A37 -> 4 | D37: =ROUNDUP(A37*52/($B$17*$B$6),0) -> 13 | E37: =ROUNDUP(A37*52/($B$17*$B$7),0) -> 16
A38: 350 | B38: =$B$6/A38 -> 3.7142857 | C38: =$B$17*$B$6/A38 -> 3.7142857 | D38: =ROUNDUP(A38*52/($B$17*$B$6),0) -> 14 | E38: =ROUNDUP(A38*52/($B$17*$B$7),0) -> 17
A40: Note: above ~325 pcs/week one roll (1,300) covers less than the 4-week reorder window (lead time + safety) — move to 2-roll POs or trim safety stock at that point.

Sheet 6-Month Forecast
A1: 6-Month Forecast — Oct 2026 through Mar 2027
A2: 26 weekly buckets starting Mon 9/28/2026, driven by the reorder-point pull policy. Starting on-hand comes from the physical count and PO-0 from the Inputs tab. Column L marks the week Trotter cuts each PO (dates from the PO Schedule tab).
A4: FORECAST INPUTS
A5: Forecast start (Monday) | B5: 46293 | D5: First full week of the outlook
A6: Starting on-hand (pieces) | B6: =Inputs!B52 -> 837 | D6: ="LINKED — Inputs rows 41–52: "&TEXT(Inputs!B47,"#,##0")&" pcs counted "&TEXT(Inputs!B42,"m/d")&" ("&Inputs!B43&" loose + "&Inputs!B44&" boxes) less "&TEXT(Inputs!B51,"#,##0")&" consumed before the horizon starts" -> LINKED — Inputs rows 41–52: 937 pcs counted 9/24 (70 loose + 2 boxes) less 100 consumed before the horizon starts
A7: Weekly demand (pieces) | B7: =Inputs!B26 -> 250
A8: Reorder point (pieces) | B8: ='Order Cadence'!B16 -> 1000
A9: Order quantity (1 roll) | B9: ='Order Cadence'!B6 -> 1300
A10: Lead time (weeks) | B10: =Inputs!B31 -> 3
A11: PO-0 open at start (pieces) | B11: =Inputs!B56 -> 1300 | D11: ="Released "&TEXT(Inputs!B55,"m/d/yy")&", credited to week "&Inputs!B58&" (arrives "&TEXT(Inputs!B57,"m/d/yy")&") — Inputs rows 54–61" -> Released 9/24/26, credited to week 4 (arrives 10/19/26) — Inputs rows 54–61
A12: WEEKLY SCHEDULE (auto-generated from the policy)
A13: Wk | B13: Week of | C13: Beg Inv | D13: Receipts | E13: Avail | F13: Demand | G13: End Inv | H13: PO Released | I13: On Order | J13: Inv Position | K13: Status | L13: Trotter cut week
A14: 1 | B14: =$B$5+(A14-1)*7 -> 46293 | C14: =$B$6 -> 837 | D14: =IF(A14>$B$10, INDEX($H$14:$H$39, A14-$B$10), 0)+IF(A14=Inputs!$B$58,Inputs!$B$56,0) -> 0 | E14: =C14+D14 -> 837 | F14: =$B$7 -> 250 | G14: =E14-F14 -> 587 | H14: =IF(G14+(Inputs!$B$56-D14)<$B$8, $B$9, 0) -> 0 | I14: =Inputs!$B$56+H14-D14 -> 1300 | J14: =G14+I14 -> 1887 | K14: =IF(G14<0,"STOCKOUT",IF(TRIM(IF(H14>0,"PO released ","")&IF(D14>0,"Delivery ","")&IF(G14<$B$7,"⚠ LOW <1 wk",""))="","OK",TRIM(IF(H14>0,"PO released ","")&IF(D14>0,"Delivery ","")&IF(G14<$B$7,"⚠ LOW <1 wk","")))) -> OK | L14: =IF(SUMPRODUCT(('PO Schedule'!$D$14:$D$22<>"")*('PO Schedule'!$D$14:$D$22<=B14+6)*('PO Schedule'!$E$14:$E$22>=B14))>0,"▶ PO-"&(SUMPRODUCT(('PO Schedule'!$D$14:$D$22<>"")*('PO Schedule'!$D$14:$D$22<=B14+6)*('PO Schedule'!$E$14:$E$22>=B14)*('PO Schedule'!$A$14:$A$22+1))-1)&" cut at Trotter","")
A15: 2 | B15: =$B$5+(A15-1)*7 -> 46300 | C15: =G14 -> 587 | D15: =IF(A15>$B$10, INDEX($H$14:$H$39, A15-$B$10), 0)+IF(A15=Inputs!$B$58,Inputs!$B$56,0) -> 0 | E15: =C15+D15 -> 587 | F15: =$B$7 -> 250 | G15: =E15-F15 -> 337 | H15: =IF(G15+(I14-D15)<$B$8, $B$9, 0) -> 0 | I15: =I14-D15+H15 -> 1300 | J15: =G15+I15 -> 1637 | K15: =IF(G15<0,"STOCKOUT",IF(TRIM(IF(H15>0,"PO released ","")&IF(D15>0,"Delivery ","")&IF(G15<$B$7,"⚠ LOW <1 wk",""))="","OK",TRIM(IF(H15>0,"PO released ","")&IF(D15>0,"Delivery ","")&IF(G15<$B$7,"⚠ LOW <1 wk","")))) -> OK | L15: =IF(SUMPRODUCT(('PO Schedule'!$D$14:$D$22<>"")*('PO Schedule'!$D$14:$D$22<=B15+6)*('PO Schedule'!$E$14:$E$22>=B15))>0,"▶ PO-"&(SUMPRODUCT(('PO Schedule'!$D$14:$D$22<>"")*('PO Schedule'!$D$14:$D$22<=B15+6)*('PO Schedule'!$E$14:$E$22>=B15)*('PO Schedule'!$A$14:$A$22+1))-1)&" cut at Trotter","")
A16: 3 | B16: =$B$5+(A16-1)*7 -> 46307 | C16: =G15 -> 337 | D16: =IF(A16>$B$10, INDEX($H$14:$H$39, A16-$B$10), 0)+IF(A16=Inputs!$B$58,Inputs!$B$56,0) -> 0 | E16: =C16+D16 -> 337 | F16: =$B$7 -> 250 | G16: =E16-F16 -> 87 | H16: =IF(G16+(I15-D16)<$B$8, $B$9, 0) -> 0 | I16: =I15-D16+H16 -> 1300 | J16: =G16+I16 -> 1387 | K16: =IF(G16<0,"STOCKOUT",IF(TRIM(IF(H16>0,"PO released ","")&IF(D16>0,"Delivery ","")&IF(G16<$B$7,"⚠ LOW <1 wk",""))="","OK",TRIM(IF(H16>0,"PO released ","")&IF(D16>0,"Delivery ","")&IF(G16<$B$7,"⚠ LOW <1 wk","")))) -> ⚠ LOW <1 wk | L16: =IF(SUMPRODUCT(('PO Schedule'!$D$14:$D$22<>"")*('PO Schedule'!$D$14:$D$22<=B16+6)*('PO Schedule'!$E$14:$E$22>=B16))>0,"▶ PO-"&(SUMPRODUCT(('PO Schedule'!$D$14:$D$22<>"")*('PO Schedule'!$D$14:$D$22<=B16+6)*('PO Schedule'!$E$14:$E$22>=B16)*('PO Schedule'!$A$14:$A$22+1))-1)&" cut at Trotter","") -> ▶ PO-0 cut at Trotter
A17: 4 | B17: =$B$5+(A17-1)*7 -> 46314 | C17: =G16 -> 87 | D17: =IF(A17>$B$10, INDEX($H$14:$H$39, A17-$B$10), 0)+IF(A17=Inputs!$B$58,Inputs!$B$56,0) -> 1300 | E17: =C17+D17 -> 1387 | F17: =$B$7 -> 250 | G17: =E17-F17 -> 1137 | H17: =IF(G17+(I16-D17)<$B$8, $B$9, 0) -> 0 | I17: =I16-D17+H17 -> 0 | J17: =G17+I17 -> 1137 | K17: =IF(G17<0,"STOCKOUT",IF(TRIM(IF(H17>0,"PO released ","")&IF(D17>0,"Delivery ","")&IF(G17<$B$7,"⚠ LOW <1 wk",""))="","OK",TRIM(IF(H17>0,"PO released ","")&IF(D17>0,"Delivery ","")&IF(G17<$B$7,"⚠ LOW <1 wk","")))) -> Delivery | L17: =IF(SUMPRODUCT(('PO Schedule'!$D$14:$D$22<>"")*('PO Schedule'!$D$14:$D$22<=B17+6)*('PO Schedule'!$E$14:$E$22>=B17))>0,"▶ PO-"&(SUMPRODUCT(('PO Schedule'!$D$14:$D$22<>"")*('PO Schedule'!$D$14:$D$22<=B17+6)*('PO Schedule'!$E$14:$E$22>=B17)*('PO Schedule'!$A$14:$A$22+1))-1)&" cut at Trotter","")
A18: 5 | B18: =$B$5+(A18-1)*7 -> 46321 | C18: =G17 -> 1137 | D18: =IF(A18>$B$10, INDEX($H$14:$H$39, A18-$B$10), 0)+IF(A18=Inputs!$B$58,Inputs!$B$56,0) -> 0 | E18: =C18+D18 -> 1137 | F18: =$B$7 -> 250 | G18: =E18-F18 -> 887 | H18: =IF(G18+(I17-D18)<$B$8, $B$9, 0) -> 1300 | I18: =I17-D18+H18 -> 1300 | J18: =G18+I18 -> 2187 | K18: =IF(G18<0,"STOCKOUT",IF(TRIM(IF(H18>0,"PO released ","")&IF(D18>0,"Delivery ","")&IF(G18<$B$7,"⚠ LOW <1 wk",""))="","OK",TRIM(IF(H18>0,"PO released ","")&IF(D18>0,"Delivery ","")&IF(G18<$B$7,"⚠ LOW <1 wk","")))) -> PO released | L18: =IF(SUMPRODUCT(('PO Schedule'!$D$14:$D$22<>"")*('PO Schedule'!$D$14:$D$22<=B18+6)*('PO Schedule'!$E$14:$E$22>=B18))>0,"▶ PO-"&(SUMPRODUCT(('PO Schedule'!$D$14:$D$22<>"")*('PO Schedule'!$D$14:$D$22<=B18+6)*('PO Schedule'!$E$14:$E$22>=B18)*('PO Schedule'!$A$14:$A$22+1))-1)&" cut at Trotter","")
A19: 6 | B19: =$B$5+(A19-1)*7 -> 46328 | C19: =G18 -> 887 | D19: =IF(A19>$B$10, INDEX($H$14:$H$39, A19-$B$10), 0)+IF(A19=Inputs!$B$58,Inputs!$B$56,0) -> 0 | E19: =C19+D19 -> 887 | F19: =$B$7 -> 250 | G19: =E19-F19 -> 637 | H19: =IF(G19+(I18-D19)<$B$8, $B$9, 0) -> 0 | I19: =I18-D19+H19 -> 1300 | J19: =G19+I19 -> 1937 | K19: =IF(G19<0,"STOCKOUT",IF(TRIM(IF(H19>0,"PO released ","")&IF(D19>0,"Delivery ","")&IF(G19<$B$7,"⚠ LOW <1 wk",""))="","OK",TRIM(IF(H19>0,"PO released ","")&IF(D19>0,"Delivery ","")&IF(G19<$B$7,"⚠ LOW <1 wk","")))) -> OK | L19: =IF(SUMPRODUCT(('PO Schedule'!$D$14:$D$22<>"")*('PO Schedule'!$D$14:$D$22<=B19+6)*('PO Schedule'!$E$14:$E$22>=B19))>0,"▶ PO-"&(SUMPRODUCT(('PO Schedule'!$D$14:$D$22<>"")*('PO Schedule'!$D$14:$D$22<=B19+6)*('PO Schedule'!$E$14:$E$22>=B19)*('PO Schedule'!$A$14:$A$22+1))-1)&" cut at Trotter","")
A20: 7 | B20: =$B$5+(A20-1)*7 -> 46335 | C20: =G19 -> 637 | D20: =IF(A20>$B$10, INDEX($H$14:$H$39, A20-$B$10), 0)+IF(A20=Inputs!$B$58,Inputs!$B$56,0) -> 0 | E20: =C20+D20 -> 637 | F20: =$B$7 -> 250 | G20: =E20-F20 -> 387 | H20: =IF(G20+(I19-D20)<$B$8, $B$9, 0) -> 0 | I20: =I19-D20+H20 -> 1300 | J20: =G20+I20 -> 1687 | K20: =IF(G20<0,"STOCKOUT",IF(TRIM(IF(H20>0,"PO released ","")&IF(D20>0,"Delivery ","")&IF(G20<$B$7,"⚠ LOW <1 wk",""))="","OK",TRIM(IF(H20>0,"PO released ","")&IF(D20>0,"Delivery ","")&IF(G20<$B$7,"⚠ LOW <1 wk","")))) -> OK | L20: =IF(SUMPRODUCT(('PO Schedule'!$D$14:$D$22<>"")*('PO Schedule'!$D$14:$D$22<=B20+6)*('PO Schedule'!$E$14:$E$22>=B20))>0,"▶ PO-"&(SUMPRODUCT(('PO Schedule'!$D$14:$D$22<>"")*('PO Schedule'!$D$14:$D$22<=B20+6)*('PO Schedule'!$E$14:$E$22>=B20)*('PO Schedule'!$A$14:$A$22+1))-1)&" cut at Trotter","") -> ▶ PO-1 cut at Trotter
A21: 8 | B21: =$B$5+(A21-1)*7 -> 46342 | C21: =G20 -> 387 | D21: =IF(A21>$B$10, INDEX($H$14:$H$39, A21-$B$10), 0)+IF(A21=Inputs!$B$58,Inputs!$B$56,0) -> 1300 | E21: =C21+D21 -> 1687 | F21: =$B$7 -> 250 | G21: =E21-F21 -> 1437 | H21: =IF(G21+(I20-D21)<$B$8, $B$9, 0) -> 0 | I21: =I20-D21+H21 -> 0 | J21: =G21+I21 -> 1437 | K21: =IF(G21<0,"STOCKOUT",IF(TRIM(IF(H21>0,"PO released ","")&IF(D21>0,"Delivery ","")&IF(G21<$B$7,"⚠ LOW <1 wk",""))="","OK",TRIM(IF(H21>0,"PO released ","")&IF(D21>0,"Delivery ","")&IF(G21<$B$7,"⚠ LOW <1 wk","")))) -> Delivery | L21: =IF(SUMPRODUCT(('PO Schedule'!$D$14:$D$22<>"")*('PO Schedule'!$D$14:$D$22<=B21+6)*('PO Schedule'!$E$14:$E$22>=B21))>0,"▶ PO-"&(SUMPRODUCT(('PO Schedule'!$D$14:$D$22<>"")*('PO Schedule'!$D$14:$D$22<=B21+6)*('PO Schedule'!$E$14:$E$22>=B21)*('PO Schedule'!$A$14:$A$22+1))-1)&" cut at Trotter","")
A22: 9 | B22: =$B$5+(A22-1)*7 -> 46349 | C22: =G21 -> 1437 | D22: =IF(A22>$B$10, INDEX($H$14:$H$39, A22-$B$10), 0)+IF(A22=Inputs!$B$58,Inputs!$B$56,0) -> 0 | E22: =C22+D22 -> 1437 | F22: =$B$7 -> 250 | G22: =E22-F22 -> 1187 | H22: =IF(G22+(I21-D22)<$B$8, $B$9, 0) -> 0 | I22: =I21-D22+H22 -> 0 | J22: =G22+I22 -> 1187 | K22: =IF(G22<0,"STOCKOUT",IF(TRIM(IF(H22>0,"PO released ","")&IF(D22>0,"Delivery ","")&IF(G22<$B$7,"⚠ LOW <1 wk",""))="","OK",TRIM(IF(H22>0,"PO released ","")&IF(D22>0,"Delivery ","")&IF(G22<$B$7,"⚠ LOW <1 wk","")))) -> OK | L22: =IF(SUMPRODUCT(('PO Schedule'!$D$14:$D$22<>"")*('PO Schedule'!$D$14:$D$22<=B22+6)*('PO Schedule'!$E$14:$E$22>=B22))>0,"▶ PO-"&(SUMPRODUCT(('PO Schedule'!$D$14:$D$22<>"")*('PO Schedule'!$D$14:$D$22<=B22+6)*('PO Schedule'!$E$14:$E$22>=B22)*('PO Schedule'!$A$14:$A$22+1))-1)&" cut at Trotter","")
A23: 10 | B23: =$B$5+(A23-1)*7 -> 46356 | C23: =G22 -> 1187 | D23: =IF(A23>$B$10, INDEX($H$14:$H$39, A23-$B$10), 0)+IF(A23=Inputs!$B$58,Inputs!$B$56,0) -> 0 | E23: =C23+D23 -> 1187 | F23: =$B$7 -> 250 | G23: =E23-F23 -> 937 | H23: =IF(G23+(I22-D23)<$B$8, $B$9, 0) -> 1300 | I23: =I22-D23+H23 -> 1300 | J23: =G23+I23 -> 2237 | K23: =IF(G23<0,"STOCKOUT",IF(TRIM(IF(H23>0,"PO released ","")&IF(D23>0,"Delivery ","")&IF(G23<$B$7,"⚠ LOW <1 wk",""))="","OK",TRIM(IF(H23>0,"PO released ","")&IF(D23>0,"Delivery ","")&IF(G23<$B$7,"⚠ LOW <1 wk","")))) -> PO released | L23: =IF(SUMPRODUCT(('PO Schedule'!$D$14:$D$22<>"")*('PO Schedule'!$D$14:$D$22<=B23+6)*('PO Schedule'!$E$14:$E$22>=B23))>0,"▶ PO-"&(SUMPRODUCT(('PO Schedule'!$D$14:$D$22<>"")*('PO Schedule'!$D$14:$D$22<=B23+6)*('PO Schedule'!$E$14:$E$22>=B23)*('PO Schedule'!$A$14:$A$22+1))-1)&" cut at Trotter","")
A24: 11 | B24: =$B$5+(A24-1)*7 -> 46363 | C24: =G23 -> 937 | D24: =IF(A24>$B$10, INDEX($H$14:$H$39, A24-$B$10), 0)+IF(A24=Inputs!$B$58,Inputs!$B$56,0) -> 0 | E24: =C24+D24 -> 937 | F24: =$B$7 -> 250 | G24: =E24-F24 -> 687 | H24: =IF(G24+(I23-D24)<$B$8, $B$9, 0) -> 0 | I24: =I23-D24+H24 -> 1300 | J24: =G24+I24 -> 1987 | K24: =IF(G24<0,"STOCKOUT",IF(TRIM(IF(H24>0,"PO released ","")&IF(D24>0,"Delivery ","")&IF(G24<$B$7,"⚠ LOW <1 wk",""))="","OK",TRIM(IF(H24>0,"PO released ","")&IF(D24>0,"Delivery ","")&IF(G24<$B$7,"⚠ LOW <1 wk","")))) -> OK | L24: =IF(SUMPRODUCT(('PO Schedule'!$D$14:$D$22<>"")*('PO Schedule'!$D$14:$D$22<=B24+6)*('PO Schedule'!$E$14:$E$22>=B24))>0,"▶ PO-"&(SUMPRODUCT(('PO Schedule'!$D$14:$D$22<>"")*('PO Schedule'!$D$14:$D$22<=B24+6)*('PO Schedule'!$E$14:$E$22>=B24)*('PO Schedule'!$A$14:$A$22+1))-1)&" cut at Trotter","")
A25: 12 | B25: =$B$5+(A25-1)*7 -> 46370 | C25: =G24 -> 687 | D25: =IF(A25>$B$10, INDEX($H$14:$H$39, A25-$B$10), 0)+IF(A25=Inputs!$B$58,Inputs!$B$56,0) -> 0 | E25: =C25+D25 -> 687 | F25: =$B$7 -> 250 | G25: =E25-F25 -> 437 | H25: =IF(G25+(I24-D25)<$B$8, $B$9, 0) -> 0 | I25: =I24-D25+H25 -> 1300 | J25: =G25+I25 -> 1737 | K25: =IF(G25<0,"STOCKOUT",IF(TRIM(IF(H25>0,"PO released ","")&IF(D25>0,"Delivery ","")&IF(G25<$B$7,"⚠ LOW <1 wk",""))="","OK",TRIM(IF(H25>0,"PO released ","")&IF(D25>0,"Delivery ","")&IF(G25<$B$7,"⚠ LOW <1 wk","")))) -> OK | L25: =IF(SUMPRODUCT(('PO Schedule'!$D$14:$D$22<>"")*('PO Schedule'!$D$14:$D$22<=B25+6)*('PO Schedule'!$E$14:$E$22>=B25))>0,"▶ PO-"&(SUMPRODUCT(('PO Schedule'!$D$14:$D$22<>"")*('PO Schedule'!$D$14:$D$22<=B25+6)*('PO Schedule'!$E$14:$E$22>=B25)*('PO Schedule'!$A$14:$A$22+1))-1)&" cut at Trotter","") -> ▶ PO-2 cut at Trotter
